{"kind":"decision","recorded_ms":1789998880056,"S":1789998600,"age":280,"rebound":1,"favorite":0,"signal":{"rsi14":65.74585184883227,"volume_ratio":1.3156223664114743,"taker_buy_fraction":0.5039315374549336,"volume5":380.7162,"return1":-29.492432705614007,"return5":8.614636152149066,"return15":59.5851517934704,"bollinger_z":0.8119777962825319,"bar_close_ms":1789998839999,"ref":85346.42241923072,"reference_received_ms":1789998601650,"spot":85376.81873251,"twap":85474.26358963098,"sigma":12.49553774866695,"spot_z":0.5446894222839042,"twap_z":2.2908611517987376,"momentum":-0.9019606062003002,"decision_ms":1789998880055,"momentum30":-1.4568120416496126,"momentum60":-1.758518150448656,"spot_twap_gap":-1.0067655520824548,"range60":1.9176895028568675,"final_mean":85419.03298224755,"final_z":6.779624998171705,"final_up_prob":0.9999999999939756,"final_drift_up_prob":0.9999999931250014,"final_known_seconds":40,"final_sd":10.710114945356496,"final_drift_shift":-11.81488103374394},"books":[{"bid":0.999,"ask":null,"asks":[],"received_ms":1789998880055,"observed_ms":1789998880019,"hash":"7ee788ed797db18ed86c6850b50ef16f7d445179"},{"bid":null,"ask":0.001,"asks":[[0.001,7993.29]],"received_ms":1789998880051,"observed_ms":1789998880019,"hash":"20c478fa2bfad64bf1e4cefdde8921428141d215"}],"book_errors":[null,null],"decision_ms":1789998880056,"feature_cutoff_ms":1789998880055,"request_ms":1789998880023,"http_ms":32,"schedule_lag_ms":56,"bars_received_ms":1789998845269}
{"kind":"execution","recorded_ms":1789998880339,"S":1789998600,"age":280,"rebound":1,"favorite":0,"execution_books":[{"bid":0.999,"ask":null,"asks":[],"received_ms":1789998880334,"observed_ms":1789998880323,"hash":"3d8439d4bc3f44b7d032d8b09394c2e1aede2cc3"},{"bid":null,"ask":0.001,"asks":[[0.001,8057.51]],"received_ms":1789998880338,"observed_ms":1789998880323,"hash":"95f390e7c568ddf617d93fc57aee25d19f85e956"}],"book_errors":[null,null],"costs":[null,[0.005,0.00035]],"cost_errors":["insufficient ask depth",null],"execution_ms":1789998880339,"request_ms":1789998880306,"delay_ms":283,"http_ms":33,"fee_schedule":{"exponent":1,"rate":0.07,"takerOnly":true,"rebateRate":0.2},"qty":5.0}
{"kind":"decision","recorded_ms":1789999180048,"S":1789998900,"age":280,"rebound":null,"favorite":1,"signal":{"rsi14":64.41545655919258,"volume_ratio":0.5529454232126533,"taker_buy_fraction":0.42105863541891986,"volume5":151.21901,"return1":-12.46219319861753,"return5":3.668240836387052,"return15":44.09492181418385,"bollinger_z":0.517069039937145,"bar_close_ms":1789999139999,"ref":85426.38316465008,"reference_received_ms":1789998901464,"spot":85392.80809228576,"twap":85416.66607749683,"sigma":6.9749199108246716,"spot_z":-1.0776398186678595,"twap_z":-0.3118837667474678,"momentum":0.07410468519159674,"decision_ms":1789999180047,"momentum30":-0.35122828871804374,"momentum60":-0.46244748688217696,"spot_twap_gap":-0.44158967929814497,"range60":1.2425841227848515,"final_mean":85401.95409072193,"final_z":-4.08382713286954,"final_up_prob":2.2149995577147585e-05,"final_drift_up_prob":3.2597276056534064e-05,"final_known_seconds":40,"final_sd":5.981906954758146,"final_drift_shift":0.5422755879821174},"books":[{"bid":null,"ask":0.01,"asks":[[0.01,13893.13]],"received_ms":1789999180041,"observed_ms":1789999180029,"hash":"92b6146cd4060e308f4e5a3686ce4b4ca9f010ad"},{"bid":0.99,"ask":null,"asks":[],"received_ms":1789999180046,"observed_ms":1789999180035,"hash":"0a9864ce537985014de672b229329fab08e9092e"}],"book_errors":[null,null],"decision_ms":1789999180048,"feature_cutoff_ms":1789999180047,"request_ms":1789999180011,"http_ms":36,"schedule_lag_ms":48,"bars_received_ms":1789999145229}
{"kind":"execution","recorded_ms":1789999180336,"S":1789998900,"age":280,"rebound":null,"favorite":1,"execution_books":[{"bid":null,"ask":0.01,"asks":[[0.01,13997.47]],"received_ms":1789999180336,"observed_ms":1789999180326,"hash":"d67964006a1ec541025354ef4956eb1035d4d7d2"},{"bid":0.99,"ask":null,"asks":[],"received_ms":1789999180320,"observed_ms":1789999180312,"hash":"5ba523499f7a76b6957b369358713181f8ecf76b"}],"book_errors":[null,null],"costs":[[0.05,0.00347],null],"cost_errors":[null,"insufficient ask depth"],"execution_ms":1789999180336,"request_ms":1789999180298,"delay_ms":288,"http_ms":38,"fee_schedule":{"exponent":1,"rate":0.07,"takerOnly":true,"rebateRate":0.2},"qty":5.0}
{"kind":"decision","recorded_ms":1789999470081,"S":1789999200,"age":270,"rebound":null,"favorite":1,"signal":{"rsi14":45.77581585472102,"volume_ratio":0.7119080045917344,"taker_buy_fraction":0.4907973924664762,"volume5":131.45296,"return1":-19.538607644253215,"return5":-17.19163126575625,"return15":-4.890803496677345,"bollinger_z":-0.8298489595463041,"bar_close_ms":1789999439999,"ref":85408.50237928922,"reference_received_ms":1789999201674,"spot":85277.17722483148,"twap":85319.31962285616,"sigma":8.664156779533341,"spot_z":-2.771027417047455,"twap_z":-1.8818014280988797,"momentum":-1.351720793329363,"decision_ms":1789999470080,"momentum30":-0.5828434020514297,"momentum60":-1.2053039811114001,"spot_twap_gap":-0.6279387976310639,"range60":1.2609631873817342,"final_mean":85287.73714361718,"final_z":-8.850852905985445,"final_up_prob":0.0,"final_drift_up_prob":0.0,"final_known_seconds":30,"final_sd":13.644474374934786,"final_drift_shift":-27.628367961542573},"books":[{"bid":null,"ask":0.01,"asks":[[0.01,37029.04]],"received_ms":1789999470080,"observed_ms":1789999470065,"hash":"9b94cdc0c2fa4afa037e58edf34dc14d8798a86d"},{"bid":0.99,"ask":null,"asks":[],"received_ms":1789999470045,"observed_ms":1789999470029,"hash":"3f97f469471b5d847100ff25cd7b8e0e080c47e4"}],"book_errors":[null,null],"decision_ms":1789999470081,"feature_cutoff_ms":1789999470080,"request_ms":1789999470016,"http_ms":64,"schedule_lag_ms":81,"bars_received_ms":1789999445266}
{"kind":"execution","recorded_ms":1789999470391,"S":1789999200,"age":270,"rebound":null,"favorite":1,"execution_books":[{"bid":null,"ask":0.01,"asks":[[0.01,36941.28]],"received_ms":1789999470385,"observed_ms":1789999470375,"hash":"4874e041c0ee541ef22bac8231fa7ac2d15df62d"},{"bid":0.99,"ask":null,"asks":[],"received_ms":1789999470390,"observed_ms":1789999470375,"hash":"8858e7abc750f6198ac03a5b4001d4837856cef9"}],"book_errors":[null,null],"costs":[[0.05,0.00347],null],"cost_errors":[null,"insufficient ask depth"],"execution_ms":1789999470390,"request_ms":1789999470331,"delay_ms":309,"http_ms":59,"fee_schedule":{"exponent":1,"rate":0.07,"takerOnly":true,"rebateRate":0.2},"qty":5.0}
{"kind":"decision","recorded_ms":1789999480046,"S":1789999200,"age":280,"rebound":null,"favorite":1,"signal":{"rsi14":45.77581585472102,"volume_ratio":0.7119080045917344,"taker_buy_fraction":0.4907973924664762,"volume5":131.45296,"return1":-19.538607644253215,"return5":-17.19163126575625,"return15":-4.890803496677345,"bollinger_z":-0.8298489595463041,"bar_close_ms":1789999439999,"ref":85408.50237928922,"reference_received_ms":1789999201674,"spot":85307.03152799311,"twap":85304.90704111286,"sigma":8.846210617467863,"spot_z":-2.5677820790468684,"twap_z":-2.6215435215555805,"momentum":0.5901997014232129,"decision_ms":1789999480045,"momentum30":0.13929292803856522,"momentum60":-0.5107023111178419,"spot_twap_gap":0.031004244499829293,"range60":1.0009024931078108,"final_mean":85301.26540354776,"final_z":-14.132583644729552,"final_up_prob":0.0,"final_drift_up_prob":0.0,"final_known_seconds":40,"final_sd":7.587924362396965,"final_drift_shift":5.478712051396851},"books":[{"bid":null,"ask":0.01,"asks":[[0.01,49735.19]],"received_ms":1789999480042,"observed_ms":1789999479994,"hash":"9687a3236a54aa82ec983ca879a02e602d68ab24"},{"bid":0.99,"ask":null,"asks":[],"received_ms":1789999480045,"observed_ms":1789999479994,"hash":"21c6816f4e0b3158f94adeec914b6eedfcbf2647"}],"book_errors":[null,null],"decision_ms":1789999480046,"feature_cutoff_ms":1789999480045,"request_ms":1789999480010,"http_ms":35,"schedule_lag_ms":46,"bars_received_ms":1789999445266}
{"kind":"execution","recorded_ms":1789999480330,"S":1789999200,"age":280,"rebound":null,"favorite":1,"execution_books":[{"bid":null,"ask":0.01,"asks":[[0.01,49786.02]],"received_ms":1789999480329,"observed_ms":1789999480320,"hash":"bcd13286599b65e8e8ff420e1180ab5ed0fde40b"},{"bid":0.99,"ask":null,"asks":[],"received_ms":1789999480328,"observed_ms":1789999480308,"hash":"d00b2bf420c892aa8511180d46228989bf872810"}],"book_errors":[null,null],"costs":[[0.05,0.00347],null],"cost_errors":[null,"insufficient ask depth"],"execution_ms":1789999480330,"request_ms":1789999480296,"delay_ms":284,"http_ms":34,"fee_schedule":{"exponent":1,"rate":0.07,"takerOnly":true,"rebateRate":0.2},"qty":5.0}
{"kind":"decision","recorded_ms":1789999740076,"S":1789999500,"age":240,"rebound":0,"favorite":1,"signal":{"rsi14":33.75179683756651,"volume_ratio":0.781671155058929,"taker_buy_fraction":0.38478636132650407,"volume5":186.61111,"return1":-7.019492808456192,"return5":-45.875175678227535,"return15":-69.44774859900902,"bollinger_z":-1.8638238705644126,"bar_close_ms":1789999679999,"ref":85287.01946901706,"reference_received_ms":1789999501188,"spot":85156.33690112643,"twap":85106.31000221371,"sigma":10.488997025295955,"spot_z":-1.6094446740418713,"twap_z":-2.225559947207413,"momentum":1.1220738383940683,"decision_ms":1789999740074,"momentum30":0.7577985673081794,"momentum60":0.784580779954455,"spot_twap_gap":0.6157352188015199,"range60":1.075071080019021,"final_mean":85156.33690112643,"final_z":-2.7910822767185848,"final_up_prob":0.0026266058406126946,"final_drift_up_prob":0.3400698495065511,"final_known_seconds":0,"final_sd":46.82146742168858,"final_drift_shift":111.37936422844678},"books":[{"bid":null,"ask":0.01,"asks":[[0.01,2243.52]],"received_ms":1789999740065,"observed_ms":1789999740053,"hash":"26bce83f5350891a74af61283c1a805b87da0a57"},{"bid":0.99,"ask":null,"asks":[],"received_ms":1789999740074,"observed_ms":1789999740055,"hash":"4a86a055627c144d87801f8f5e736c97b211d7c8"}],"book_errors":[null,null],"decision_ms":1789999740076,"feature_cutoff_ms":1789999740074,"request_ms":1789999740028,"http_ms":46,"schedule_lag_ms":76,"bars_received_ms":1789999695537}
{"kind":"execution","recorded_ms":1789999740375,"S":1789999500,"age":240,"rebound":0,"favorite":1,"execution_books":[{"bid":null,"ask":0.01,"asks":[[0.01,2412.06]],"received_ms":1789999740355,"observed_ms":1789999740345,"hash":"70b99eed0274c68ca7072bb07b3ffa41de82ef52"},{"bid":0.99,"ask":null,"asks":[],"received_ms":1789999740374,"observed_ms":1789999740352,"hash":"9a106c419f6bbce0decee4acb27219170d687a87"}],"book_errors":[null,null],"costs":[[0.05,0.00347],null],"cost_errors":[null,"insufficient ask depth"],"execution_ms":1789999740375,"request_ms":1789999740326,"delay_ms":299,"http_ms":49,"fee_schedule":{"exponent":1,"rate":0.07,"takerOnly":true,"rebateRate":0.2},"qty":5.0}
{"kind":"decision","recorded_ms":1789999770048,"S":1789999500,"age":270,"rebound":null,"favorite":1,"signal":{"rsi14":39.820218373495024,"volume_ratio":0.6500844248788099,"taker_buy_fraction":0.418612933173532,"volume5":180.35728,"return1":8.316610119196428,"return5":-17.946739888833207,"return15":-31.48808277310174,"bollinger_z":-1.3396727994271702,"bar_close_ms":1789999739999,"ref":85287.01946901706,"reference_received_ms":1789999501188,"spot":85193.51723629612,"twap":85148.84682787699,"sigma":9.400911212012584,"spot_z":-1.8172309249347782,"twap_z":-2.685407494054564,"momentum":-0.497924626564476,"decision_ms":1789999770044,"momentum30":0.6774396066690959,"momentum60":1.1084491515878168,"spot_twap_gap":0.613443186423963,"range60":1.7720203543591029,"final_mean":85192.24837200117,"final_z":-6.389871134470323,"final_up_prob":8.301281884115497e-11,"final_drift_up_prob":4.796718577892989e-13,"final_known_seconds":30,"final_sd":14.831456694744586,"final_drift_shift":-11.069294897698091},"books":[{"bid":null,"ask":0.01,"asks":[[0.01,37881.59]],"received_ms":1789999770037,"observed_ms":1789999770025,"hash":"2343b9ce1113e453d816b21d78358acf8e1b3e42"},{"bid":0.99,"ask":null,"asks":[],"received_ms":1789999770044,"observed_ms":1789999770025,"hash":"257b6a4140655b623e1645728ed599a1385e01a6"}],"book_errors":[null,null],"decision_ms":1789999770048,"feature_cutoff_ms":1789999770044,"request_ms":1789999770012,"http_ms":32,"schedule_lag_ms":48,"bars_received_ms":1789999745260}
{"kind":"execution","recorded_ms":1789999770332,"S":1789999500,"age":270,"rebound":null,"favorite":1,"execution_books":[{"bid":null,"ask":0.01,"asks":[[0.01,38031.59]],"received_ms":1789999770332,"observed_ms":1789999770317,"hash":"f866279b3d3b7f22709cdfe5438dc9f5a72eb7d2"},{"bid":0.99,"ask":null,"asks":[],"received_ms":1789999770326,"observed_ms":1789999770317,"hash":"8450703364f6e0f2ee775487a91d2e8a0ddfa990"}],"book_errors":[null,null],"costs":[[0.05,0.00347],null],"cost_errors":[null,"insufficient ask depth"],"execution_ms":1789999770332,"request_ms":1789999770298,"delay_ms":284,"http_ms":34,"fee_schedule":{"exponent":1,"rate":0.07,"takerOnly":true,"rebateRate":0.2},"qty":5.0}
{"kind":"decision","recorded_ms":1789999780047,"S":1789999500,"age":280,"rebound":null,"favorite":1,"signal":{"rsi14":39.820218373495024,"volume_ratio":0.6500844248788099,"taker_buy_fraction":0.418612933173532,"volume5":180.35728,"return1":8.316610119196428,"return5":-17.946739888833207,"return15":-31.48808277310174,"bollinger_z":-1.3396727994271702,"bar_close_ms":1789999739999,"ref":85287.01946901706,"reference_received_ms":1789999501188,"spot":85184.16806876248,"twap":85163.3889296756,"sigma":8.683062870945212,"spot_z":-2.651687120429616,"twap_z":-3.1874092919694292,"momentum":-0.27438789912167644,"decision_ms":1789999780046,"momentum30":-0.2046868436962683,"momentum60":1.1246831452793529,"spot_twap_gap":0.30894344091915904,"range60":1.5039200410224958,"final_mean":85187.10558549438,"final_z":-13.415900239508606,"final_up_prob":0.0,"final_drift_up_prob":0.0,"final_known_seconds":40,"final_sd":7.447422963718788,"final_drift_shift":-2.499865192833842},"books":[{"bid":null,"ask":0.01,"asks":[[0.01,51684.31]],"received_ms":1789999780032,"observed_ms":1789999780002,"hash":"e96dca01132b23757dc8be4ef3d3a19f7662ed14"},{"bid":0.99,"ask":null,"asks":[],"received_ms":1789999780046,"observed_ms":1789999780035,"hash":"f108b305f4bb3e23203992730ef42434f3b039ec"}],"book_errors":[null,null],"decision_ms":1789999780047,"feature_cutoff_ms":1789999780046,"request_ms":1789999780003,"http_ms":43,"schedule_lag_ms":47,"bars_received_ms":1789999745260}
{"kind":"execution","recorded_ms":1789999780361,"S":1789999500,"age":280,"rebound":null,"favorite":1,"execution_books":[{"bid":null,"ask":0.01,"asks":[[0.01,51712.67]],"received_ms":1789999780361,"observed_ms":1789999780339,"hash":"d9bb3a19b4e09849661bc1fddb39dbdd30f79335"},{"bid":0.99,"ask":null,"asks":[],"received_ms":1789999780336,"observed_ms":1789999780322,"hash":"5048c70f3c7807335c0a430bf16825c9df5bb098"}],"book_errors":[null,null],"costs":[[0.05,0.00347],null],"cost_errors":[null,"insufficient ask depth"],"execution_ms":1789999780361,"request_ms":1789999780297,"delay_ms":314,"http_ms":64,"fee_schedule":{"exponent":1,"rate":0.07,"takerOnly":true,"rebateRate":0.2},"qty":5.0}
{"kind":"decision","recorded_ms":1790000070050,"S":1789999800,"age":270,"rebound":null,"favorite":0,"signal":{"rsi14":39.81074052466647,"volume_ratio":1.3867905723784584,"taker_buy_fraction":0.5849717337618322,"volume5":176.36765,"return1":0.8069411009238956,"return5":8.12688210508339,"return15":-27.013760808818525,"bollinger_z":-0.6534442878752716,"bar_close_ms":1790000039999,"ref":85196.4363623876,"reference_received_ms":1789999802215,"spot":85298.55212367022,"twap":85266.03695590053,"sigma":10.742422035841996,"spot_z":1.7369113621284584,"twap_z":1.1838531110679493,"momentum":-0.6412664312996323,"decision_ms":1790000070048,"momentum30":1.0380203822470464,"momentum60":0.536378435744618,"spot_twap_gap":0.39075825684674337,"range60":1.0590735507523168,"final_mean":85291.29695662812,"final_z":5.598307761975831,"final_up_prob":0.9999999891772878,"final_drift_up_prob":0.9999982340083664,"final_known_seconds":30,"final_sd":16.944512212213045,"final_drift_shift":-16.285875932129684},"books":[{"bid":0.99,"ask":null,"asks":[],"received_ms":1790000070047,"observed_ms":1790000070034,"hash":"f3171c87f459675071d1e9da7ed3a4b22f705936"},{"bid":null,"ask":0.01,"asks":[[0.01,39990.94]],"received_ms":1790000070033,"observed_ms":1790000070022,"hash":"035a9aeaca4c66fd2902f4b0e81235b90d523df2"}],"book_errors":[null,null],"decision_ms":1790000070050,"feature_cutoff_ms":1790000070048,"request_ms":1790000070007,"http_ms":41,"schedule_lag_ms":50,"bars_received_ms":1790000045256}
{"kind":"execution","recorded_ms":1790000070336,"S":1789999800,"age":270,"rebound":null,"favorite":0,"execution_books":[{"bid":0.99,"ask":null,"asks":[],"received_ms":1790000070328,"observed_ms":1790000070309,"hash":"8faeca341197cc288609d10d7cee752e592459df"},{"bid":null,"ask":0.01,"asks":[[0.01,40090.94]],"received_ms":1790000070336,"observed_ms":1790000070308,"hash":"c7c202ec2f6cc45f895b22ac65451166ef206274"}],"book_errors":[null,null],"costs":[null,[0.05,0.00347]],"cost_errors":["insufficient ask depth",null],"execution_ms":1790000070336,"request_ms":1790000070300,"delay_ms":286,"http_ms":36,"fee_schedule":{"exponent":1,"rate":0.07,"takerOnly":true,"rebateRate":0.2},"qty":5.0}
{"kind":"gap","recorded_ms":1790000080038,"S":1789999800,"age":280,"phase":"decision","error":"ValueError","reason":"incomplete or stale context","books":[{"bid":0.99,"ask":null,"asks":[],"received_ms":1790000080036,"observed_ms":1790000080028,"hash":"03af1dabfdb88d2fe043d3ddd764e0523ec52eba"},{"bid":null,"ask":0.01,"asks":[[0.01,56398.48]],"received_ms":1790000080036,"observed_ms":1790000080024,"hash":"b21fdf56a8a8d44ca0e314ee2a4946299e55a464"}],"book_errors":[null,null]}
{"kind":"decision","recorded_ms":1790000370045,"S":1790000100,"age":270,"rebound":null,"favorite":0,"signal":{"rsi14":54.11545776159989,"volume_ratio":0.6556559671430722,"taker_buy_fraction":0.6218251222498264,"volume5":296.04132,"return1":-3.5699218622806512,"return5":14.027872094666185,"return15":4.236354125941673,"bollinger_z":0.46404680835139184,"bar_close_ms":1790000339999,"ref":85288.69659526845,"reference_received_ms":1790000101794,"spot":85344.65690891427,"twap":85366.20498129314,"sigma":5.705572368088686,"spot_z":1.7920041460322635,"twap_z":2.4820330705719695,"momentum":-1.1876052326697304,"decision_ms":1790000370044,"momentum30":-0.1806062938433219,"momentum60":-1.003092434819271,"spot_twap_gap":-0.4875661901627917,"range60":1.0104893718194197,"final_mean":85351.53754955601,"final_z":6.9811938303683885,"final_up_prob":0.9999999999985366,"final_drift_up_prob":0.9999999009399418,"final_known_seconds":30,"final_sd":9.001462473968251,"final_drift_shift":-16.023512410421418},"books":[{"bid":0.99,"ask":null,"asks":[],"received_ms":1790000370031,"observed_ms":1790000370022,"hash":"c9f2bdd5733da5e491a4b4c4c94c9c1bafe69a43"},{"bid":null,"ask":0.01,"asks":[[0.01,17959.35]],"received_ms":1790000370044,"observed_ms":1790000370022,"hash":"1cbf70e8049028522a93295faa7136ca68cf3211"}],"book_errors":[null,null],"decision_ms":1790000370045,"feature_cutoff_ms":1790000370044,"request_ms":1790000370005,"http_ms":39,"schedule_lag_ms":45,"bars_received_ms":1790000345252}
{"kind":"execution","recorded_ms":1790000370325,"S":1790000100,"age":270,"rebound":null,"favorite":0,"execution_books":[{"bid":0.99,"ask":null,"asks":[],"received_ms":1790000370317,"observed_ms":1790000370309,"hash":"67af98f6c5fae8e6a930dd88f2c2e6af2ead0a1f"},{"bid":null,"ask":0.01,"asks":[[0.01,18889.92]],"received_ms":1790000370325,"observed_ms":1790000370316,"hash":"d0af67e962b55a341dde8d3a067daf5db086a08c"}],"book_errors":[null,null],"costs":[null,[0.05,0.00347]],"cost_errors":["insufficient ask depth",null],"execution_ms":1790000370325,"request_ms":1790000370295,"delay_ms":280,"http_ms":30,"fee_schedule":{"exponent":1,"rate":0.07,"takerOnly":true,"rebateRate":0.2},"qty":5.0}
{"kind":"decision","recorded_ms":1790000380077,"S":1790000100,"age":280,"rebound":null,"favorite":0,"signal":{"rsi14":54.11545776159989,"volume_ratio":0.6556559671430722,"taker_buy_fraction":0.6218251222498264,"volume5":296.04132,"return1":-3.5699218622806512,"return5":14.027872094666185,"return15":4.236354125941673,"bollinger_z":0.46404680835139184,"bar_close_ms":1790000339999,"ref":85288.69659526845,"reference_received_ms":1790000101794,"spot":85371.84341446383,"twap":85360.10290362833,"sigma":5.842620122654936,"spot_z":3.1882305790729557,"twap_z":2.7380455206195697,"momentum":1.2574746809782809,"decision_ms":1790000380076,"momentum30":0.6484143721838308,"momentum60":0.06702392633469943,"spot_twap_gap":0.2594201573226285,"range60":0.6636403246439937,"final_mean":85363.50531471842,"final_z":14.962068816832414,"final_up_prob":1.0,"final_drift_up_prob":1.0,"final_known_seconds":40,"final_sd":4.999891416473594,"final_drift_shift":7.685616687474124},"books":[{"bid":0.99,"ask":null,"asks":[],"received_ms":1790000380072,"observed_ms":1790000380054,"hash":"af4d60d299c87da213200b36162e74e688f6e68b"},{"bid":null,"ask":0.01,"asks":[[0.01,40269.57]],"received_ms":1790000380075,"observed_ms":1790000380067,"hash":"8e297dd8ebc50e693104fc3b4b99ba0259da04fe"}],"book_errors":[null,null],"decision_ms":1790000380077,"feature_cutoff_ms":1790000380076,"request_ms":1790000380046,"http_ms":30,"schedule_lag_ms":77,"bars_received_ms":1790000345252}
{"kind":"execution","recorded_ms":1790000380362,"S":1790000100,"age":280,"rebound":null,"favorite":0,"execution_books":[{"bid":0.99,"ask":null,"asks":[],"received_ms":1790000380361,"observed_ms":1790000380351,"hash":"0eeb8968c9e6ce7a86e1768178ff0179398aadff"},{"bid":null,"ask":0.01,"asks":[[0.01,40292.57]],"received_ms":1790000380352,"observed_ms":1790000380314,"hash":"d5a15fbb748b16883605929a15f88651d974e9c0"}],"book_errors":[null,null],"costs":[null,[0.05,0.00347]],"cost_errors":["insufficient ask depth",null],"execution_ms":1790000380362,"request_ms":1790000380327,"delay_ms":285,"http_ms":35,"fee_schedule":{"exponent":1,"rate":0.07,"takerOnly":true,"rebateRate":0.2},"qty":5.0}
{"kind":"decision","recorded_ms":1790000640084,"S":1790000400,"age":240,"rebound":null,"favorite":0,"signal":{"rsi14":74.2579735300491,"volume_ratio":0.6392870468885787,"taker_buy_fraction":0.6437088015000301,"volume5":118.09896,"return1":24.213499165907784,"return5":26.586272618123484,"return15":60.49521370024357,"bollinger_z":2.6057781820059756,"bar_close_ms":1790000579999,"ref":85361.48203450121,"reference_received_ms":1790000400918,"spot":85712.94749679149,"twap":85653.9103965042,"sigma":10.26028621756669,"spot_z":4.425355333068651,"twap_z":3.6820101835828885,"momentum":1.0642894261194749,"decision_ms":1790000640083,"momentum30":1.1395775153747216,"momentum60":1.3576687374697736,"spot_twap_gap":0.7428308248346284,"range60":1.3693187673347762,"final_mean":85712.9474967915,"final_z":7.675558126753805,"final_up_prob":0.9999999999999918,"final_drift_up_prob":1.0,"final_known_seconds":0,"final_sd":45.790215706298476,"final_drift_shift":103.30898600362188},"books":[{"bid":0.99,"ask":null,"asks":[],"received_ms":1790000640083,"observed_ms":1790000640072,"hash":"148447fa8d1eb80977a98df9a854699cac64851d"},{"bid":null,"ask":0.01,"asks":[[0.01,11973.92]],"received_ms":1790000640082,"observed_ms":1790000640068,"hash":"357bdbebed31af4e7228ea1a5584bd1676daf53c"}],"book_errors":[null,null],"decision_ms":1790000640084,"feature_cutoff_ms":1790000640083,"request_ms":1790000640045,"http_ms":38,"schedule_lag_ms":84,"bars_received_ms":1790000595551}
{"kind":"execution","recorded_ms":1790000640366,"S":1790000400,"age":240,"rebound":null,"favorite":0,"execution_books":[{"bid":0.99,"ask":null,"asks":[],"received_ms":1790000640364,"observed_ms":1790000640354,"hash":"7a42851fee9649b494cc4403b3cadebeee55d109"},{"bid":null,"ask":0.01,"asks":[[0.01,15275.92]],"received_ms":1790000640366,"observed_ms":1790000640354,"hash":"8af4ba4f1efa6e1324dd07d816c8fd0ba2139967"}],"book_errors":[null,null],"costs":[null,[0.05,0.00347]],"cost_errors":["insufficient ask depth",null],"execution_ms":1790000640366,"request_ms":1790000640334,"delay_ms":282,"http_ms":32,"fee_schedule":{"exponent":1,"rate":0.07,"takerOnly":true,"rebateRate":0.2},"qty":5.0}
{"kind":"decision","recorded_ms":1790000670051,"S":1790000400,"age":270,"rebound":null,"favorite":0,"signal":{"rsi14":75.09629209827523,"volume_ratio":1.2276303241956235,"taker_buy_fraction":0.6746579778047034,"volume5":140.0567,"return1":10.533255692857605,"return5":40.646935534141264,"return15":62.7002834997179,"bollinger_z":2.5749116942341224,"bar_close_ms":1790000639999,"ref":85361.48203450121,"reference_received_ms":1790000400918,"spot":85734.48174337715,"twap":85691.84364313366,"sigma":9.464001485993531,"spot_z":7.201704199446018,"twap_z":6.37846767064192,"momentum":0.5993804148727568,"decision_ms":1790000670050,"momentum30":0.6079206271694487,"momentum60":1.1673527943210644,"spot_twap_gap":0.5816308334318955,"range60":1.2893737503352145,"final_mean":85725.86597082586,"final_z":24.411870637062222,"final_up_prob":1.0,"final_drift_up_prob":1.0,"final_known_seconds":30,"final_sd":14.926506114260745,"final_drift_shift":13.408795168835944},"books":[{"bid":0.99,"ask":null,"asks":[],"received_ms":1790000670035,"observed_ms":1790000670026,"hash":"283c652f9528b91012ef2111180e475d35b286c4"},{"bid":null,"ask":0.01,"asks":[[0.01,39563.09]],"received_ms":1790000670050,"observed_ms":1790000670033,"hash":"589ee3e3a8a35c2f88b25a4ae2deb12da2825558"}],"book_errors":[null,null],"decision_ms":1790000670051,"feature_cutoff_ms":1790000670050,"request_ms":1790000670007,"http_ms":43,"schedule_lag_ms":51,"bars_received_ms":1790000645255}
{"kind":"execution","recorded_ms":1790000670336,"S":1790000400,"age":270,"rebound":null,"favorite":0,"execution_books":[{"bid":0.99,"ask":null,"asks":[],"received_ms":1790000670335,"observed_ms":1790000670318,"hash":"162ab67fa854993312d49e6f0d1bae000be7aff9"},{"bid":null,"ask":0.01,"asks":[[0.01,39428.09]],"received_ms":1790000670329,"observed_ms":1790000670318,"hash":"a02d654823ec57acf59413a1050b699d8b254edd"}],"book_errors":[null,null],"costs":[null,[0.05,0.00347]],"cost_errors":["insufficient ask depth",null],"execution_ms":1790000670336,"request_ms":1790000670302,"delay_ms":285,"http_ms":34,"fee_schedule":{"exponent":1,"rate":0.07,"takerOnly":true,"rebateRate":0.2},"qty":5.0}
{"kind":"decision","recorded_ms":1790000680047,"S":1790000400,"age":280,"rebound":1,"favorite":0,"signal":{"rsi14":75.09629209827523,"volume_ratio":1.2276303241956235,"taker_buy_fraction":0.6746579778047034,"volume5":140.0567,"return1":10.533255692857605,"return5":40.646935534141264,"return15":62.7002834997179,"bollinger_z":2.5749116942341224,"bar_close_ms":1790000639999,"ref":85361.48203450121,"reference_received_ms":1790000400918,"spot":85697.47601598641,"twap":85704.60320376475,"sigma":9.873323775254342,"spot_z":7.6182134231556855,"twap_z":7.779812858247716,"momentum":-1.3529768358796226,"decision_ms":1790000680046,"momentum30":-0.6591325287660335,"momentum60":0.40708614427299145,"spot_twap_gap":-0.09319212117808315,"range60":0.9853787502908717,"final_mean":85710.56424086913,"final_z":41.222208846899626,"final_up_prob":1.0,"final_drift_up_prob":1.0,"final_known_seconds":40,"final_sd":8.468304249886828,"final_drift_shift":-14.016269189791533},"books":[{"bid":0.99,"ask":null,"asks":[],"received_ms":1790000680026,"observed_ms":1790000680017,"hash":"bc64ce4cd45bb4431a2cb58e2f8aa8145e94bd63"},{"bid":null,"ask":0.01,"asks":[[0.01,52339.09]],"received_ms":1790000680046,"observed_ms":1790000680028,"hash":"4d8f4bb0cdb1bfeb2b481584718007a70200e35f"}],"book_errors":[null,null],"decision_ms":1790000680047,"feature_cutoff_ms":1790000680046,"request_ms":1790000680005,"http_ms":41,"schedule_lag_ms":47,"bars_received_ms":1790000645255}
{"kind":"execution","recorded_ms":1790000680329,"S":1790000400,"age":280,"rebound":1,"favorite":0,"execution_books":[{"bid":0.99,"ask":null,"asks":[],"received_ms":1790000680321,"observed_ms":1790000680306,"hash":"14682552e525e811f5105fafb42f8c7836b92cfa"},{"bid":null,"ask":0.01,"asks":[[0.01,52354.09]],"received_ms":1790000680329,"observed_ms":1790000680306,"hash":"9be91ecf4b2eef1a6ca91fb549aaa06b00c741ce"}],"book_errors":[null,null],"costs":[null,[0.05,0.00347]],"cost_errors":["insufficient ask depth",null],"execution_ms":1790000680329,"request_ms":1790000680297,"delay_ms":282,"http_ms":32,"fee_schedule":{"exponent":1,"rate":0.07,"takerOnly":true,"rebateRate":0.2},"qty":5.0}
{"kind":"decision","recorded_ms":1790001240065,"S":1790001000,"age":240,"rebound":null,"favorite":0,"signal":{"rsi14":73.8148624500614,"volume_ratio":0.37593276019889293,"taker_buy_fraction":0.4285057891320554,"volume5":172.60964,"return1":10.249597632779123,"return5":4.871880612351442,"return15":45.22107556904617,"bollinger_z":1.373154903725814,"bar_close_ms":1790001179999,"ref":85705.48944666714,"reference_received_ms":1790001001829,"spot":85916.26898029403,"twap":85845.0087040774,"sigma":9.79968591449175,"spot_z":2.7782569182805603,"twap_z":1.8389847223950604,"momentum":0.8177141809270521,"decision_ms":1790001240064,"momentum30":0.61023740507023,"momentum60":1.9264626972464933,"spot_twap_gap":0.9387711179091148,"range60":1.941494531695904,"final_mean":85916.26898029403,"final_z":4.8172204987449465,"final_up_prob":0.9999992721410316,"final_drift_up_prob":0.9999999999714099,"final_known_seconds":0,"final_sd":43.755425702810456,"final_drift_shift":75.85914663479896},"books":[{"bid":0.99,"ask":null,"asks":[],"received_ms":1790001240063,"observed_ms":1790001240050,"hash":"59274c57d37032df9b972f1c0cd1da6745261f4b"},{"bid":null,"ask":0.01,"asks":[[0.01,13862.95]],"received_ms":1790001240056,"observed_ms":1790001240047,"hash":"5d23b33685bbef2879453b00693a81f61268b601"}],"book_errors":[null,null],"decision_ms":1790001240065,"feature_cutoff_ms":1790001240064,"request_ms":1790001240024,"http_ms":40,"schedule_lag_ms":65,"bars_received_ms":1790001195625}
{"kind":"execution","recorded_ms":1790001240354,"S":1790001000,"age":240,"rebound":null,"favorite":0,"execution_books":[{"bid":0.99,"ask":null,"asks":[],"received_ms":1790001240342,"observed_ms":1790001240327,"hash":"081f7607a00ce62cdbd5fcb98636dfd715e16f04"},{"bid":null,"ask":0.01,"asks":[[0.01,14581.53]],"received_ms":1790001240354,"observed_ms":1790001240344,"hash":"a96ab6be201720cf457269e76a8ed579d2b2a172"}],"book_errors":[null,null],"costs":[null,[0.05,0.00347]],"cost_errors":["insufficient ask depth",null],"execution_ms":1790001240354,"request_ms":1790001240315,"delay_ms":289,"http_ms":39,"fee_schedule":{"exponent":1,"rate":0.07,"takerOnly":true,"rebateRate":0.2},"qty":5.0}
{"kind":"decision","recorded_ms":1790001270080,"S":1790001000,"age":270,"rebound":null,"favorite":0,"signal":{"rsi14":76.83555519755043,"volume_ratio":2.2495153166697,"taker_buy_fraction":0.5096746335722812,"volume5":214.05927,"return1":17.186332845430265,"return5":26.37580253693617,"return15":65.87609458009698,"bollinger_z":1.9622053518970184,"bar_close_ms":1790001239999,"ref":85705.48944666714,"reference_received_ms":1790001001829,"spot":85951.03589427558,"twap":85902.91060720496,"sigma":8.569167007514896,"spot_z":5.2385005798636435,"twap_z":4.211793222942011,"momentum":1.0919720629145704,"decision_ms":1790001270079,"momentum30":0.7639980691335111,"momentum60":1.017249778144957,"spot_twap_gap":0.7250352151790916,"range60":1.0173107258785654,"final_mean":85931.88043986484,"final_z":16.77522134101715,"final_up_prob":1.0,"final_drift_up_prob":1.0,"final_known_seconds":30,"final_sd":13.495559229620808,"final_drift_shift":22.07603616553047},"books":[{"bid":0.99,"ask":null,"asks":[],"received_ms":1790001270070,"observed_ms":1790001270049,"hash":"042fd8097101d51a7c15774d4bd3fcb867d01826"},{"bid":null,"ask":0.01,"asks":[[0.01,45302.07]],"received_ms":1790001270079,"observed_ms":1790001270049,"hash":"bf9f753a8dbc410d87f436c987e4ee41dffb51dc"}],"book_errors":[null,null],"decision_ms":1790001270080,"feature_cutoff_ms":1790001270079,"request_ms":1790001270041,"http_ms":38,"schedule_lag_ms":80,"bars_received_ms":1790001245241}
{"kind":"execution","recorded_ms":1790001270360,"S":1790001000,"age":270,"rebound":null,"favorite":0,"execution_books":[{"bid":0.99,"ask":null,"asks":[],"received_ms":1790001270356,"observed_ms":1790001270345,"hash":"214bff5f5a4b728cee4bc7661cb50490d66a00d5"},{"bid":null,"ask":0.01,"asks":[[0.01,45276.07]],"received_ms":1790001270359,"observed_ms":1790001270352,"hash":"cec825a390aa214765675579e1c6da4343299473"}],"book_errors":[null,null],"costs":[null,[0.05,0.00347]],"cost_errors":["insufficient ask depth",null],"execution_ms":1790001270360,"request_ms":1790001270330,"delay_ms":280,"http_ms":30,"fee_schedule":{"exponent":1,"rate":0.07,"takerOnly":true,"rebateRate":0.2},"qty":5.0}
{"kind":"decision","recorded_ms":1790001280074,"S":1790001000,"age":280,"rebound":1,"favorite":0,"signal":{"rsi14":76.83555519755043,"volume_ratio":2.2495153166697,"taker_buy_fraction":0.5096746335722812,"volume5":214.05927,"return1":17.186332845430265,"return5":26.37580253693617,"return15":65.87609458009698,"bollinger_z":1.9622053518970184,"bar_close_ms":1790001239999,"ref":85705.48944666714,"reference_received_ms":1790001001829,"spot":85940.58358930892,"twap":85911.81951189581,"sigma":6.774143593447028,"spot_z":7.774392265728621,"twap_z":6.823185151597876,"momentum":-0.1691408925480328,"decision_ms":1790001280073,"momentum30":1.5382156145910122,"momentum60":0.6941062881273284,"spot_twap_gap":0.5481765148772337,"range60":1.170968559701177,"final_mean":85927.58375052117,"final_z":38.302931776226494,"final_up_prob":1.0,"final_drift_up_prob":1.0,"final_known_seconds":40,"final_sd":5.7983630378882784,"final_drift_shift":-1.1989625385630274},"books":[{"bid":0.99,"ask":null,"asks":[],"received_ms":1790001280073,"observed_ms":1790001280057,"hash":"6169dc2269c1daa276e708b385e03e0b08cb7edf"},{"bid":null,"ask":0.01,"asks":[[0.01,58264.53]],"received_ms":1790001280069,"observed_ms":1790001280036,"hash":"a94d581e9b16309446552df3a05b6ecf3e0af130"}],"book_errors":[null,null],"decision_ms":1790001280074,"feature_cutoff_ms":1790001280073,"request_ms":1790001280028,"http_ms":45,"schedule_lag_ms":74,"bars_received_ms":1790001245241}
{"kind":"execution","recorded_ms":1790001280365,"S":1790001000,"age":280,"rebound":1,"favorite":0,"execution_books":[{"bid":0.99,"ask":null,"asks":[],"received_ms":1790001280365,"observed_ms":1790001280333,"hash":"57933440da8d7e77ee6304e37e419c1d51bf48a0"},{"bid":null,"ask":0.01,"asks":[[0.01,58264.53]],"received_ms":1790001280348,"observed_ms":1790001280333,"hash":"b5bad4618940f3f4b20ea1c83ced9fadb015df7b"}],"book_errors":[null,null],"costs":[null,[0.05,0.00347]],"cost_errors":["insufficient ask depth",null],"execution_ms":1790001280365,"request_ms":1790001280324,"delay_ms":291,"http_ms":41,"fee_schedule":{"exponent":1,"rate":0.07,"takerOnly":true,"rebateRate":0.2},"qty":5.0}
{"kind":"decision","recorded_ms":1790001570089,"S":1790001300,"age":270,"rebound":null,"favorite":1,"signal":{"rsi14":62.23693892567951,"volume_ratio":0.74846631110769,"taker_buy_fraction":0.3444231898800067,"volume5":224.69422,"return1":-10.461041352079768,"return5":-5.416784488228981,"return15":19.92906375542564,"bollinger_z":0.8652869121115718,"bar_close_ms":1790001539999,"ref":85930.82645304846,"reference_received_ms":1790001301966,"spot":85771.727736955,"twap":85872.02309335925,"sigma":8.956020127982573,"spot_z":-3.2480962370355764,"twap_z":-1.2005060507173333,"momentum":-1.6382258240231318,"decision_ms":1790001570088,"momentum30":-2.1401390497096973,"momentum60":-2.218077900483129,"spot_twap_gap":-1.4457398096651946,"range60":2.218077900483129,"final_mean":85797.95698167219,"final_z":-9.42440296026951,"final_up_prob":0.0,"final_drift_up_prob":0.0,"final_known_seconds":30,"final_sd":14.098449730598885,"final_drift_shift":-34.59381711209176},"books":[{"bid":null,"ask":0.01,"asks":[[0.01,33589.83]],"received_ms":1790001570088,"observed_ms":1790001570060,"hash":"e56257c9087bf5e55ebc4d0a704e17ec6f572a74"},{"bid":0.99,"ask":null,"asks":[],"received_ms":1790001570045,"observed_ms":1790001570024,"hash":"f33ec98a4fd0e4fa3e798bec12de6c829960bf04"}],"book_errors":[null,null],"decision_ms":1790001570089,"feature_cutoff_ms":1790001570088,"request_ms":1790001570022,"http_ms":66,"schedule_lag_ms":89,"bars_received_ms":1790001545271}
{"kind":"execution","recorded_ms":1790001570367,"S":1790001300,"age":270,"rebound":null,"favorite":1,"execution_books":[{"bid":null,"ask":0.01,"asks":[[0.01,46577.83]],"received_ms":1790001570367,"observed_ms":1790001570354,"hash":"3a8074cb9b5ba14ed51cbc3cf32cdb0139d82240"},{"bid":0.99,"ask":null,"asks":[],"received_ms":1790001570366,"observed_ms":1790001570354,"hash":"9cb712131ef8fe283c4f7889a93e02e78ecb1b08"}],"book_errors":[null,null],"costs":[[0.05,0.00347],null],"cost_errors":[null,"insufficient ask depth"],"execution_ms":1790001570367,"request_ms":1790001570339,"delay_ms":278,"http_ms":28,"fee_schedule":{"exponent":1,"rate":0.07,"takerOnly":true,"rebateRate":0.2},"qty":5.0}
{"kind":"decision","recorded_ms":1790001580079,"S":1790001300,"age":280,"rebound":null,"favorite":1,"signal":{"rsi14":62.23693892567951,"volume_ratio":0.74846631110769,"taker_buy_fraction":0.3444231898800067,"volume5":224.69422,"return1":-10.461041352079768,"return5":-5.416784488228981,"return15":19.92906375542564,"bollinger_z":0.8652869121115718,"bar_close_ms":1790001539999,"ref":85930.82645304846,"reference_received_ms":1790001301966,"spot":85763.80512682656,"twap":85846.80449239828,"sigma":8.621098948734474,"spot_z":-4.340530687015178,"twap_z":-2.183552884143306,"momentum":-0.18558273353330734,"decision_ms":1790001580078,"momentum30":-1.4957996774523696,"momentum60":-2.194519997339392,"spot_twap_gap":-1.242900943822499,"range60":2.196926206388201,"final_mean":85794.03383007663,"final_z":-18.544388785196954,"final_up_prob":0.0,"final_drift_up_prob":0.0,"final_known_seconds":40,"final_sd":7.376496715870371,"final_drift_shift":-1.67334241545922},"books":[{"bid":null,"ask":0.01,"asks":[[0.01,47544.66]],"received_ms":1790001580078,"observed_ms":1790001580058,"hash":"cde9a60fd694a837f885f3a9e85bc124cdae3534"},{"bid":0.99,"ask":null,"asks":[],"received_ms":1790001580075,"observed_ms":1790001580066,"hash":"3b8aa01b53d50cec2b914c22dc597c9304b3d310"}],"book_errors":[null,null],"decision_ms":1790001580079,"feature_cutoff_ms":1790001580078,"request_ms":1790001580036,"http_ms":42,"schedule_lag_ms":79,"bars_received_ms":1790001545271}
{"kind":"execution","recorded_ms":1790001580362,"S":1790001300,"age":280,"rebound":null,"favorite":1,"execution_books":[{"bid":null,"ask":0.01,"asks":[[0.01,47644.66]],"received_ms":1790001580356,"observed_ms":1790001580346,"hash":"868925c10bcd43580667aa44f5cdd48cd99ff00b"},{"bid":0.99,"ask":null,"asks":[],"received_ms":1790001580362,"observed_ms":1790001580353,"hash":"e8fd35f9314cc0e6e3a3fcc9a5696e50e99fa456"}],"book_errors":[null,null],"costs":[[0.05,0.00347],null],"cost_errors":[null,"insufficient ask depth"],"execution_ms":1790001580362,"request_ms":1790001580329,"delay_ms":283,"http_ms":33,"fee_schedule":{"exponent":1,"rate":0.07,"takerOnly":true,"rebateRate":0.2},"qty":5.0}
{"kind":"decision","recorded_ms":1790001870072,"S":1790001600,"age":270,"rebound":null,"favorite":1,"signal":{"rsi14":51.51776428653937,"volume_ratio":0.5777934804232001,"taker_buy_fraction":0.3309433950952541,"volume5":180.14552,"return1":-6.507933416879332,"return5":-16.651727144426204,"return15":4.35650228372381,"bollinger_z":-0.4334888004404065,"bar_close_ms":1790001839999,"ref":85799.28883377438,"reference_received_ms":1790001601703,"spot":85768.20088858486,"twap":85742.7328117671,"sigma":7.125145583812021,"spot_z":-0.7975394467370879,"twap_z":-1.4509051089213802,"momentum":1.9756320954134732,"decision_ms":1790001870071,"momentum30":0.8768849167148552,"momentum60":-0.23713768578709643,"spot_twap_gap":0.4614522665531255,"range60":1.2069513535320504,"final_mean":85748.62539950898,"final_z":-4.513094772415275,"final_up_prob":3.1944227884550536e-06,"final_drift_up_prob":0.06019299976734804,"final_known_seconds":30,"final_sd":11.225874221623343,"final_drift_shift":33.22790644217798},"books":[{"bid":null,"ask":0.01,"asks":[[0.01,22078.67]],"received_ms":1790001870056,"observed_ms":1790001870045,"hash":"964dd288004d4d98b7ebed0e3d70ba99fd66731c"},{"bid":0.99,"ask":null,"asks":[],"received_ms":1790001870070,"observed_ms":1790001870046,"hash":"85c256dbb7ccc6db1413a726cd884d4326a3cb8a"}],"book_errors":[null,null],"decision_ms":1790001870072,"feature_cutoff_ms":1790001870071,"request_ms":1790001870028,"http_ms":43,"schedule_lag_ms":72,"bars_received_ms":1790001845224}
{"kind":"execution","recorded_ms":1790001870354,"S":1790001600,"age":270,"rebound":null,"favorite":1,"execution_books":[{"bid":null,"ask":0.01,"asks":[[0.01,22088.1]],"received_ms":1790001870350,"observed_ms":1790001870327,"hash":"6a1f279cb33dda18f543a6bb664fb3406df21e2c"},{"bid":0.99,"ask":null,"asks":[],"received_ms":1790001870354,"observed_ms":1790001870327,"hash":"ba313f768422d1bde449024664a0a5278bc94b37"}],"book_errors":[null,null],"costs":[[0.05,0.00347],null],"cost_errors":[null,"insufficient ask depth"],"execution_ms":1790001870354,"request_ms":1790001870322,"delay_ms":282,"http_ms":32,"fee_schedule":{"exponent":1,"rate":0.07,"takerOnly":true,"rebateRate":0.2},"qty":5.0}
{"kind":"decision","recorded_ms":1790001880061,"S":1790001600,"age":280,"rebound":null,"favorite":1,"signal":{"rsi14":51.51776428653937,"volume_ratio":0.5777934804232001,"taker_buy_fraction":0.3309433950952541,"volume5":180.14552,"return1":-6.507933416879332,"return5":-16.651727144426204,"return15":4.35650228372381,"bollinger_z":-0.4334888004404065,"bar_close_ms":1790001839999,"ref":85799.28883377438,"reference_received_ms":1790001601703,"spot":85771.08727226408,"twap":85738.79181139833,"sigma":6.99686948274194,"spot_z":-0.9026238512777034,"twap_z":-1.9362777237691247,"momentum":-0.06746189058031449,"decision_ms":1790001880060,"momentum30":1.099830099346463,"momentum60":0.23065836214647975,"spot_twap_gap":0.5958844994876648,"range60":1.0869621354154706,"final_mean":85750.36739563727,"final_z":-8.160552959285425,"final_up_prob":1.6653345369377348e-16,"final_drift_up_prob":1.1102230246251565e-16,"final_known_seconds":40,"final_sd":5.9948680415642785,"final_drift_shift":-0.4945740723423369},"books":[{"bid":null,"ask":0.01,"asks":[[0.01,35417.02]],"received_ms":1790001880050,"observed_ms":1790001880041,"hash":"7b150776ffd901a8c88cfbdc11dce7850ed0f669"},{"bid":0.99,"ask":null,"asks":[],"received_ms":1790001880060,"observed_ms":1790001880041,"hash":"051bfb02d2d5c016dd0607474e4f55342f7aef47"}],"book_errors":[null,null],"decision_ms":1790001880061,"feature_cutoff_ms":1790001880060,"request_ms":1790001880024,"http_ms":36,"schedule_lag_ms":61,"bars_received_ms":1790001845224}
{"kind":"execution","recorded_ms":1790001880350,"S":1790001600,"age":280,"rebound":null,"favorite":1,"execution_books":[{"bid":null,"ask":0.01,"asks":[[0.01,35417.02]],"received_ms":1790001880350,"observed_ms":1790001880297,"hash":"179857d15877f0a5483de6951764b9cc9ac56dad"},{"bid":0.99,"ask":null,"asks":[],"received_ms":1790001880349,"observed_ms":1790001880297,"hash":"2e3dbadc3fc8a225c1238f72d4026a23eced56b6"}],"book_errors":[null,null],"costs":[[0.05,0.00347],null],"cost_errors":[null,"insufficient ask depth"],"execution_ms":1790001880350,"request_ms":1790001880311,"delay_ms":289,"http_ms":39,"fee_schedule":{"exponent":1,"rate":0.07,"takerOnly":true,"rebateRate":0.2},"qty":5.0}
{"kind":"decision","recorded_ms":1790002140067,"S":1790001900,"age":240,"rebound":null,"favorite":0,"signal":{"rsi14":48.40031536222885,"volume_ratio":0.5805894491913767,"taker_buy_fraction":0.4086967208586037,"volume5":120.18024,"return1":16.715683119255253,"return5":11.715294937352414,"return15":13.366959469502172,"bollinger_z":0.807819192593616,"bar_close_ms":1790002079999,"ref":85745.48246540247,"reference_received_ms":1790001901161,"spot":85894.24542059563,"twap":85908.93105555147,"sigma":4.037216814900169,"spot_z":4.759661767582034,"twap_z":5.229527771125739,"momentum":-0.994723176173516,"decision_ms":1790002140066,"momentum30":-1.4243880482190128,"momentum60":0.29221918829233506,"spot_twap_gap":-0.46960750619518893,"range60":1.4841947850286057,"final_mean":85894.24542059563,"final_z":8.25305436599891,"final_up_prob":1.0,"final_drift_up_prob":0.9999999995978807,"final_known_seconds":0,"final_sd":18.02519995579296,"final_drift_shift":-38.01452702171506},"books":[{"bid":0.99,"ask":null,"asks":[],"received_ms":1790002140062,"observed_ms":1790002140052,"hash":"c72b2fa84ddf75c4fdd4941b0ab761f4c5818dba"},{"bid":null,"ask":0.01,"asks":[[0.01,4290.84]],"received_ms":1790002140066,"observed_ms":1790002140054,"hash":"ddecbe588c0c5ff5ac486736699f084d4fd43d0c"}],"book_errors":[null,null],"decision_ms":1790002140067,"feature_cutoff_ms":1790002140066,"request_ms":1790002140027,"http_ms":39,"schedule_lag_ms":67,"bars_received_ms":1790002095628}
{"kind":"execution","recorded_ms":1790002140350,"S":1790001900,"age":240,"rebound":null,"favorite":0,"execution_books":[{"bid":0.99,"ask":null,"asks":[],"received_ms":1790002140349,"observed_ms":1790002140236,"hash":"6b1e1ab7aea35c2467cfac0ecc019c370b060426"},{"bid":null,"ask":0.01,"asks":[[0.01,4439.05]],"received_ms":1790002140341,"observed_ms":1790002140236,"hash":"b9e80e6449f3cf4c52a3798adbd246f03e3c7f24"}],"book_errors":[null,null],"costs":[null,[0.05,0.00347]],"cost_errors":["insufficient ask depth",null],"execution_ms":1790002140350,"request_ms":1790002140318,"delay_ms":283,"http_ms":32,"fee_schedule":{"exponent":1,"rate":0.07,"takerOnly":true,"rebateRate":0.2},"qty":5.0}
{"kind":"decision","recorded_ms":1790002170066,"S":1790001900,"age":270,"rebound":null,"favorite":0,"signal":{"rsi14":45.56462280469669,"volume_ratio":0.6285926102665962,"taker_buy_fraction":0.47043333932698483,"volume5":119.07043,"return1":-0.5645542791591495,"return5":17.647850363549743,"return15":-4.390719053579014,"bollinger_z":0.6863133068287834,"bar_close_ms":1790002139999,"ref":85745.48246540247,"reference_received_ms":1790001901161,"spot":85901.85020716923,"twap":85900.29761641177,"sigma":6.25149123787668,"spot_z":4.571659817613928,"twap_z":4.526267355595265,"momentum":-0.42879705148614483,"decision_ms":1790002170065,"momentum30":0.40001934534178435,"momentum60":-0.49340045737593285,"spot_twap_gap":0.03206252672800524,"range60":1.31046761558741,"final_mean":85893.61775587776,"final_z":15.03550058524408,"final_up_prob":1.0,"final_drift_up_prob":1.0,"final_known_seconds":30,"final_sd":9.852368375461106,"final_drift_shift":-6.330130952580977},"books":[{"bid":0.99,"ask":null,"asks":[],"received_ms":1790002170062,"observed_ms":1790002170053,"hash":"eb80546600c2a2c6c94c1c1f0177dc148f5fe2f1"},{"bid":null,"ask":0.01,"asks":[[0.01,46257.77]],"received_ms":1790002170065,"observed_ms":1790002170053,"hash":"c8e9a25b49cfd49bd2aa6900adf9770b7cc426be"}],"book_errors":[null,null],"decision_ms":1790002170066,"feature_cutoff_ms":1790002170065,"request_ms":1790002170033,"http_ms":32,"schedule_lag_ms":66,"bars_received_ms":1790002145231}
{"kind":"execution","recorded_ms":1790002170346,"S":1790001900,"age":270,"rebound":null,"favorite":0,"execution_books":[{"bid":0.99,"ask":null,"asks":[],"received_ms":1790002170346,"observed_ms":1790002170331,"hash":"f106c87902153d635f559095e04d8b3ecc6e5499"},{"bid":null,"ask":0.01,"asks":[[0.01,46218.77]],"received_ms":1790002170344,"observed_ms":1790002170331,"hash":"4a3523d301291658709f3a6a000682fcbe9c4355"}],"book_errors":[null,null],"costs":[null,[0.05,0.00347]],"cost_errors":["insufficient ask depth",null],"execution_ms":1790002170346,"request_ms":1790002170316,"delay_ms":280,"http_ms":30,"fee_schedule":{"exponent":1,"rate":0.07,"takerOnly":true,"rebateRate":0.2},"qty":5.0}
{"kind":"decision","recorded_ms":1790002180059,"S":1790001900,"age":280,"rebound":null,"favorite":0,"signal":{"rsi14":45.56462280469669,"volume_ratio":0.6285926102665962,"taker_buy_fraction":0.47043333932698483,"volume5":119.07043,"return1":-0.5645542791591495,"return5":17.647850363549743,"return15":-4.390719053579014,"bollinger_z":0.6863133068287834,"bar_close_ms":1790002139999,"ref":85745.48246540247,"reference_received_ms":1790001901161,"spot":85937.31643045408,"twap":85896.65504615354,"sigma":7.046985826793028,"spot_z":6.095898825865772,"twap_z":4.803803941891018,"momentum":1.5776986332304508,"decision_ms":1790002180058,"momentum30":1.7636702774276651,"momentum60":0.36718232750625146,"spot_twap_gap":0.7449088546529478,"range60":1.3745675323091406,"final_mean":85907.84147078017,"final_z":26.88634684056726,"final_up_prob":1.0,"final_drift_up_prob":1.0,"final_known_seconds":40,"final_sd":6.038715722164475,"final_drift_shift":11.651547803003115},"books":[{"bid":0.99,"ask":null,"asks":[],"received_ms":1790002180058,"observed_ms":1790002180032,"hash":"97e01aa4cfe0783b510587f54421648a1bd6c8f0"},{"bid":null,"ask":0.01,"asks":[[0.01,59463.77]],"received_ms":1790002180046,"observed_ms":1790002180032,"hash":"6372106741f6ba4d8d8ec2f1055d74823cc87ff9"}],"book_errors":[null,null],"decision_ms":1790002180059,"feature_cutoff_ms":1790002180058,"request_ms":1790002180018,"http_ms":40,"schedule_lag_ms":59,"bars_received_ms":1790002145231}
{"kind":"execution","recorded_ms":1790002180333,"S":1790001900,"age":280,"rebound":null,"favorite":0,"execution_books":[{"bid":0.99,"ask":null,"asks":[],"received_ms":1790002180331,"observed_ms":1790002180314,"hash":"5460a70855d7bf58d45648c2c1cb8813880ba929"},{"bid":null,"ask":0.01,"asks":[[0.01,59478.77]],"received_ms":1790002180333,"observed_ms":1790002180314,"hash":"a49ff1bb9e5e7e73e273d84ccb1acfc75fbe2d91"}],"book_errors":[null,null],"costs":[null,[0.05,0.00347]],"cost_errors":["insufficient ask depth",null],"execution_ms":1790002180333,"request_ms":1790002180309,"delay_ms":274,"http_ms":24,"fee_schedule":{"exponent":1,"rate":0.07,"takerOnly":true,"rebateRate":0.2},"qty":5.0}
{"kind":"decision","recorded_ms":1790002470087,"S":1790002200,"age":270,"rebound":null,"favorite":0,"signal":{"rsi14":57.28147742389862,"volume_ratio":1.4488704297767012,"taker_buy_fraction":0.5892505793063141,"volume5":299.14225999999996,"return1":-15.309342920442836,"return5":9.856588727208011,"return15":10.881087862256031,"bollinger_z":0.7599054968557811,"bar_close_ms":1790002439999,"ref":85909.0374353972,"reference_received_ms":1790002201638,"spot":86047.14483545089,"twap":85996.89524299334,"sigma":8.715054965771,"spot_z":2.8974074606034534,"twap_z":1.8432022259658862,"momentum":1.3600440279430843,"decision_ms":1790002470086,"momentum30":1.6391265124831227,"momentum60":-0.013693223175576141,"spot_twap_gap":0.744366445980217,"range60":1.3943086463955454,"final_mean":86026.6277716646,"final_z":8.570410910307368,"final_up_prob":1.0,"final_drift_up_prob":1.0,"final_known_seconds":30,"final_sd":13.72050156031347,"final_drift_shift":27.950580487940137},"books":[{"bid":0.99,"ask":null,"asks":[],"received_ms":1790002470069,"observed_ms":1790002470045,"hash":"64077482a4cb88d09552c2fd9c537bc4a6cfe7c9"},{"bid":null,"ask":0.01,"asks":[[0.01,41372.0]],"received_ms":1790002470086,"observed_ms":1790002470061,"hash":"2f8f3fb61226e62355eea005fc6b23bc4a2b8153"}],"book_errors":[null,null],"decision_ms":1790002470087,"feature_cutoff_ms":1790002470086,"request_ms":1790002470024,"http_ms":62,"schedule_lag_ms":87,"bars_received_ms":1790002445270}
{"kind":"execution","recorded_ms":1790002470371,"S":1790002200,"age":270,"rebound":null,"favorite":0,"execution_books":[{"bid":0.99,"ask":null,"asks":[],"received_ms":1790002470365,"observed_ms":1790002470356,"hash":"baefb2af387f2c90b3b4fd73778a628dcef5f942"},{"bid":null,"ask":0.01,"asks":[[0.01,41584.5]],"received_ms":1790002470371,"observed_ms":1790002470356,"hash":"7ef7257b3e7e25f84826f660e43f74832a311964"}],"book_errors":[null,null],"costs":[null,[0.05,0.00347]],"cost_errors":["insufficient ask depth",null],"execution_ms":1790002470371,"request_ms":1790002470337,"delay_ms":284,"http_ms":34,"fee_schedule":{"exponent":1,"rate":0.07,"takerOnly":true,"rebateRate":0.2},"qty":5.0}
{"kind":"gap","recorded_ms":1790002480071,"S":1790002200,"age":280,"phase":"decision","error":"ValueError","reason":"incomplete or stale context","books":[{"bid":0.99,"ask":null,"asks":[],"received_ms":1790002480069,"observed_ms":1790002480051,"hash":"0d7484e83e8a0b6632d807905ce31901f86c1e0e"},{"bid":null,"ask":0.01,"asks":[[0.01,58424.52]],"received_ms":1790002480070,"observed_ms":1790002480051,"hash":"f1cca90a98f13dd213e8d1d655d44c2bba4dafe2"}],"book_errors":[null,null]}
{"kind":"decision","recorded_ms":1790002740059,"S":1790002500,"age":240,"rebound":null,"favorite":1,"signal":{"rsi14":55.16657874043166,"volume_ratio":1.21828840042398,"taker_buy_fraction":0.3752704516441281,"volume5":192.73316,"return1":-12.552893827537051,"return5":-30.77194357184295,"return15":5.590451880884243,"bollinger_z":-0.3402998198814537,"bar_close_ms":1790002679999,"ref":86023.57876290652,"reference_received_ms":1790002501487,"spot":85770.03319288447,"twap":85786.78674591176,"sigma":11.602716753563827,"spot_z":-2.8224790186460553,"twap_z":-2.6359778232073814,"momentum":0.6024638590528466,"decision_ms":1790002740058,"momentum30":0.04881684599427678,"momentum60":-0.8406258451725194,"spot_twap_gap":-0.1864110312628744,"range60":1.3099973080085137,"final_mean":85770.03319288447,"final_z":-4.893407364533461,"final_up_prob":4.955248658622402e-07,"final_drift_up_prob":0.00014959150020521506,"final_known_seconds":0,"final_sd":51.813705897387784,"final_drift_shift":66.18687874646787},"books":[{"bid":null,"ask":0.01,"asks":[[0.01,10875.39]],"received_ms":1790002740045,"observed_ms":1790002740027,"hash":"546e2ce7ec5b18b4681b4324d0578f27eb53af83"},{"bid":0.99,"ask":null,"asks":[],"received_ms":1790002740058,"observed_ms":1790002740043,"hash":"85bd1cba01f70269611f038e2942b2b0b84e90e3"}],"book_errors":[null,null],"decision_ms":1790002740059,"feature_cutoff_ms":1790002740058,"request_ms":1790002740008,"http_ms":50,"schedule_lag_ms":59,"bars_received_ms":1790002695605}
{"kind":"execution","recorded_ms":1790002740349,"S":1790002500,"age":240,"rebound":null,"favorite":1,"execution_books":[{"bid":null,"ask":0.01,"asks":[[0.01,11674.36]],"received_ms":1790002740342,"observed_ms":1790002740328,"hash":"bd0c54b5ee326c3cc34dab6144137ca4df4d5c79"},{"bid":0.99,"ask":null,"asks":[],"received_ms":1790002740349,"observed_ms":1790002740328,"hash":"fe7e95f6b1437cf07e4011b176a05884e28cf321"}],"book_errors":[null,null],"costs":[[0.05,0.00347],null],"cost_errors":[null,"insufficient ask depth"],"execution_ms":1790002740349,"request_ms":1790002740309,"delay_ms":290,"http_ms":40,"fee_schedule":{"exponent":1,"rate":0.07,"takerOnly":true,"rebateRate":0.2},"qty":5.0}
{"kind":"decision","recorded_ms":1790002770086,"S":1790002500,"age":270,"rebound":null,"favorite":1,"signal":{"rsi14":50.469122661778535,"volume_ratio":1.3239605064782676,"taker_buy_fraction":0.39176840486803566,"volume5":185.47851,"return1":-6.078650465010809,"return5":-21.526999882995433,"return15":6.0192158074756135,"bollinger_z":-0.7136110358743893,"bar_close_ms":1790002739999,"ref":86023.57876290652,"reference_received_ms":1790002501487,"spot":85797.81137729884,"twap":85774.6179704446,"sigma":9.062233333080304,"spot_z":-4.554927412382751,"twap_z":-5.022861628755963,"momentum":-0.8631336388471679,"decision_ms":1790002770085,"momentum30":0.341949933322927,"momentum60":0.43992016148285046,"spot_twap_gap":0.3304103789383013,"range60":1.3490512439931497,"final_mean":85798.36055484551,"final_z":-15.785074151899147,"final_up_prob":0.0,"final_drift_up_prob":0.0,"final_known_seconds":30,"final_sd":14.267795380227001,"final_drift_shift":-18.446333237505414},"books":[{"bid":null,"ask":0.01,"asks":[[0.01,39508.0]],"received_ms":1790002770085,"observed_ms":1790002770071,"hash":"b3b78ef5956f446274d035adda5072211dbd97a8"},{"bid":0.99,"ask":null,"asks":[],"received_ms":1790002770079,"observed_ms":1790002770071,"hash":"12025eba604664f05da34b2b83386b265fdfc410"}],"book_errors":[null,null],"decision_ms":1790002770086,"feature_cutoff_ms":1790002770085,"request_ms":1790002770046,"http_ms":39,"schedule_lag_ms":86,"bars_received_ms":1790002745239}
{"kind":"execution","recorded_ms":1790002770366,"S":1790002500,"age":270,"rebound":null,"favorite":1,"execution_books":[{"bid":null,"ask":0.01,"asks":[[0.01,52472.0]],"received_ms":1790002770366,"observed_ms":1790002770356,"hash":"7ce7feaf95caf5192744bbdecccd22a9d4cf43c6"},{"bid":0.99,"ask":null,"asks":[],"received_ms":1790002770362,"observed_ms":1790002770355,"hash":"d25026c3fa1d2c373f9eb6575247e2c972ead093"}],"book_errors":[null,null],"costs":[[0.05,0.00347],null],"cost_errors":[null,"insufficient ask depth"],"execution_ms":1790002770366,"request_ms":1790002770336,"delay_ms":280,"http_ms":30,"fee_schedule":{"exponent":1,"rate":0.07,"takerOnly":true,"rebateRate":0.2},"qty":5.0}
{"kind":"decision","recorded_ms":1790002780078,"S":1790002500,"age":280,"rebound":null,"favorite":1,"signal":{"rsi14":50.469122661778535,"volume_ratio":1.3239605064782676,"taker_buy_fraction":0.39176840486803566,"volume5":185.47851,"return1":-6.078650465010809,"return5":-21.526999882995433,"return15":6.0192158074756135,"bollinger_z":-0.7136110358743893,"bar_close_ms":1790002739999,"ref":86023.57876290652,"reference_received_ms":1790002501487,"spot":85797.53194922702,"twap":85779.37468288104,"sigma":6.2480408290022735,"spot_z":-8.105450581686085,"twap_z":-8.756522909007332,"momentum":0.07118268095783782,"decision_ms":1790002780077,"momentum30":0.28163024191809605,"momentum60":1.4398206670275453,"spot_twap_gap":0.3751724852384197,"range60":1.9566800995601692,"final_mean":85798.54120072964,"final_z":-42.09116320023011,"final_up_prob":0.0,"final_drift_up_prob":0.0,"final_known_seconds":40,"final_sd":5.346432482902871,"final_drift_shift":0.4652072001409271},"books":[{"bid":null,"ask":0.01,"asks":[[0.01,53127.0]],"received_ms":1790002780068,"observed_ms":1790002780041,"hash":"1af43830bd5e107a99a66250b9d5833377b04d80"},{"bid":0.99,"ask":null,"asks":[],"received_ms":1790002780077,"observed_ms":1790002780069,"hash":"fdea907a21d4d6f22f491aded40b416854254c1f"}],"book_errors":[null,null],"decision_ms":1790002780078,"feature_cutoff_ms":1790002780077,"request_ms":1790002780039,"http_ms":38,"schedule_lag_ms":78,"bars_received_ms":1790002745239}
{"kind":"execution","recorded_ms":1790002780360,"S":1790002500,"age":280,"rebound":null,"favorite":1,"execution_books":[{"bid":null,"ask":0.01,"asks":[[0.01,53142.0]],"received_ms":1790002780350,"observed_ms":1790002780335,"hash":"b9f68a6b4c00ec28339e73904d9d18953a005d23"},{"bid":0.99,"ask":null,"asks":[],"received_ms":1790002780360,"observed_ms":1790002780335,"hash":"886cb1b2677f46da50dab517519b03a7c44233b5"}],"book_errors":[null,null],"costs":[[0.05,0.00347],null],"cost_errors":[null,"insufficient ask depth"],"execution_ms":1790002780360,"request_ms":1790002780328,"delay_ms":282,"http_ms":32,"fee_schedule":{"exponent":1,"rate":0.07,"takerOnly":true,"rebateRate":0.2},"qty":5.0}
{"kind":"decision","recorded_ms":1790003040096,"S":1790002800,"age":240,"rebound":null,"favorite":0,"signal":{"rsi14":54.52310876807171,"volume_ratio":1.0263703627862315,"taker_buy_fraction":0.5187527126641344,"volume5":360.66942,"return1":5.201623073855248,"return5":15.316471608709376,"return15":9.193836803465711,"bollinger_z":0.6059049779351972,"bar_close_ms":1790002979999,"ref":85799.90972905437,"reference_received_ms":1790002801325,"spot":85945.00218555906,"twap":85962.80372325101,"sigma":2.087735889700792,"spot_z":8.979201971661764,"twap_z":10.080869185746089,"momentum":-2.0631674467483005,"decision_ms":1790003040095,"momentum30":-1.6224556912617882,"momentum60":-1.5025782526144391,"spot_twap_gap":-1.1007947151094193,"range60":1.797468328028781,"final_mean":85945.00218555906,"final_z":15.577097771907408,"final_up_prob":1.0,"final_drift_up_prob":1.0,"final_known_seconds":0,"final_sd":9.314472992931695,"final_drift_shift":-40.733800535689014},"books":[{"bid":0.99,"ask":null,"asks":[],"received_ms":1790003040095,"observed_ms":1790003040083,"hash":"b9bbe9dfb3426b60bfd1c7a61123380c6e8a1438"},{"bid":null,"ask":0.01,"asks":[[0.01,14492.89]],"received_ms":1790003040078,"observed_ms":1790003040055,"hash":"d4d11752ef58dfedb3148a187faf807210a22085"}],"book_errors":[null,null],"decision_ms":1790003040096,"feature_cutoff_ms":1790003040095,"request_ms":1790003040050,"http_ms":45,"schedule_lag_ms":96,"bars_received_ms":1790002995601}
{"kind":"execution","recorded_ms":1790003040397,"S":1790002800,"age":240,"rebound":null,"favorite":0,"execution_books":[{"bid":0.99,"ask":null,"asks":[],"received_ms":1790003040397,"observed_ms":1790003040372,"hash":"52d9537049bba8b898d5d8e8f4f3581810eedebb"},{"bid":null,"ask":0.01,"asks":[[0.01,17402.27]],"received_ms":1790003040381,"observed_ms":1790003040372,"hash":"1942dc2dc98b8aa6f2a7d465f8164a49f44d0356"}],"book_errors":[null,null],"costs":[null,[0.05,0.00347]],"cost_errors":["insufficient ask depth",null],"execution_ms":1790003040397,"request_ms":1790003040346,"delay_ms":301,"http_ms":51,"fee_schedule":{"exponent":1,"rate":0.07,"takerOnly":true,"rebateRate":0.2},"qty":5.0}
{"kind":"decision","recorded_ms":1790003070066,"S":1790002800,"age":270,"rebound":null,"favorite":0,"signal":{"rsi14":48.37201345726155,"volume_ratio":0.5419356461327293,"taker_buy_fraction":0.5267196340656699,"volume5":335.65803999999997,"return1":-3.5911417108486843,"return5":17.798661540652144,"return15":6.170202667427024,"bollinger_z":0.2541824930404804,"bar_close_ms":1790003039999,"ref":85799.90972905437,"reference_received_ms":1790002801325,"spot":85902.79951218302,"twap":85938.01821877704,"sigma":6.471325367533651,"spot_z":2.9059583472100865,"twap_z":3.9006547232038287,"momentum":0.9953014341034309,"decision_ms":1790003070065,"momentum30":-1.1756964648390449,"momentum60":-1.212038500801016,"spot_twap_gap":-0.7025941692353468,"range60":1.659141697282449,"final_mean":85906.1457895625,"final_z":10.416497330943649,"final_up_prob":1.0,"final_drift_up_prob":1.0,"final_known_seconds":30,"final_sd":10.198827603262089,"final_drift_shift":15.20985742533066},"books":[{"bid":0.99,"ask":null,"asks":[],"received_ms":1790003070065,"observed_ms":1790003070048,"hash":"8785bd6f2a7b28bdf2a640c835ce8fcecfc46743"},{"bid":null,"ask":0.01,"asks":[[0.01,33430.59]],"received_ms":1790003070059,"observed_ms":1790003070048,"hash":"3b00c296aeeeffe6b68030791b2ed207489ca4ed"}],"book_errors":[null,null],"decision_ms":1790003070066,"feature_cutoff_ms":1790003070065,"request_ms":1790003070030,"http_ms":35,"schedule_lag_ms":66,"bars_received_ms":1790003045228}
{"kind":"execution","recorded_ms":1790003070350,"S":1790002800,"age":270,"rebound":null,"favorite":0,"execution_books":[{"bid":0.99,"ask":null,"asks":[],"received_ms":1790003070348,"observed_ms":1790003070325,"hash":"b8fb42306c6fd0350f0a5830519412877fc2babc"},{"bid":null,"ask":0.01,"asks":[[0.01,33620.59]],"received_ms":1790003070350,"observed_ms":1790003070340,"hash":"cd6d45d4421102db09c254ba4f2824ccda3f6f6a"}],"book_errors":[null,null],"costs":[null,[0.05,0.00347]],"cost_errors":["insufficient ask depth",null],"execution_ms":1790003070350,"request_ms":1790003070317,"delay_ms":284,"http_ms":33,"fee_schedule":{"exponent":1,"rate":0.07,"takerOnly":true,"rebateRate":0.2},"qty":5.0}
{"kind":"decision","recorded_ms":1790003080063,"S":1790002800,"age":280,"rebound":null,"favorite":0,"signal":{"rsi14":48.37201345726155,"volume_ratio":0.5419356461327293,"taker_buy_fraction":0.5267196340656699,"volume5":335.65803999999997,"return1":-3.5911417108486843,"return5":17.798661540652144,"return15":6.170202667427024,"bollinger_z":0.2541824930404804,"bar_close_ms":1790003039999,"ref":85799.90972905437,"reference_received_ms":1790002801325,"spot":85923.37613522331,"twap":85929.07151416913,"sigma":6.948466482544882,"spot_z":3.979413277083583,"twap_z":4.162979538532935,"momentum":1.0494888095624493,"decision_ms":1790003080062,"momentum30":-0.000986531276316991,"momentum60":-0.6788209444714655,"spot_twap_gap":-0.10581763070990327,"range60":1.4474564893576942,"final_mean":85915.54507796107,"final_z":19.426346894161497,"final_up_prob":1.0,"final_drift_up_prob":1.0,"final_known_seconds":40,"final_sd":5.95250097904154,"final_drift_shift":7.6392146783849},"books":[{"bid":0.999,"ask":null,"asks":[],"received_ms":1790003080061,"observed_ms":1790003080003,"hash":"40544d4feb8c1383bca609d9caa496030ed43d6e"},{"bid":null,"ask":0.001,"asks":[[0.001,21121.36]],"received_ms":1790003080050,"observed_ms":1790003080003,"hash":"26fe66523b87f947cf9bf60aa5d92123f3bbcbc1"}],"book_errors":[null,null],"decision_ms":1790003080063,"feature_cutoff_ms":1790003080062,"request_ms":1790003080020,"http_ms":42,"schedule_lag_ms":63,"bars_received_ms":1790003045228}
{"kind":"execution","recorded_ms":1790003080344,"S":1790002800,"age":280,"rebound":null,"favorite":0,"execution_books":[{"bid":0.999,"ask":null,"asks":[],"received_ms":1790003080344,"observed_ms":1790003080310,"hash":"917a457771e6c5ba9593c9f835d2996a028182ec"},{"bid":null,"ask":0.001,"asks":[[0.001,21136.36]],"received_ms":1790003080338,"observed_ms":1790003080310,"hash":"692438715b85561828f71daf89b90e5cd5a9538c"}],"book_errors":[null,null],"costs":[null,[0.005,0.00035]],"cost_errors":["insufficient ask depth",null],"execution_ms":1790003080344,"request_ms":1790003080313,"delay_ms":281,"http_ms":31,"fee_schedule":{"exponent":1,"rate":0.07,"takerOnly":true,"rebateRate":0.2},"qty":5.0}
{"kind":"decision","recorded_ms":1790003340127,"S":1790003100,"age":240,"rebound":1,"favorite":0,"signal":{"rsi14":61.247190884348875,"volume_ratio":1.0078563941201972,"taker_buy_fraction":0.6675470276660921,"volume5":254.13817,"return1":24.56248187920817,"return5":23.208534670619407,"return15":7.835954967274226,"bollinger_z":2.304942989282478,"bar_close_ms":1790003279999,"ref":85929.17715486501,"reference_received_ms":1790003100999,"spot":86245.32591005086,"twap":86259.25240401806,"sigma":11.711864630803571,"spot_z":3.488560791211482,"twap_z":3.642233453260889,"momentum":-0.5775940157449594,"decision_ms":1790003340126,"momentum30":-0.9082670769680727,"momentum60":0.9100984284950169,"spot_twap_gap":-0.15351122104605025,"range60":1.7390168793943486,"final_mean":86245.32591005086,"final_z":6.055080196769726,"final_up_prob":0.9999999992982613,"final_drift_up_prob":0.9999993211147172,"final_known_seconds":0,"final_sd":52.21214994881555,"final_drift_shift":-63.90635242298842},"books":[{"bid":0.99,"ask":null,"asks":[],"received_ms":1790003340086,"observed_ms":1790003340077,"hash":"8f7f31e134265173024c262f5a794ed0722adb9c"},{"bid":null,"ask":0.01,"asks":[[0.01,14278.09]],"received_ms":1790003340125,"observed_ms":1790003340085,"hash":"f9cc49f51d561e05f0f443d8eed4be6bb0ba12af"}],"book_errors":[null,null],"decision_ms":1790003340127,"feature_cutoff_ms":1790003340126,"request_ms":1790003340050,"http_ms":76,"schedule_lag_ms":127,"bars_received_ms":1790003295602}
{"kind":"execution","recorded_ms":1790003340415,"S":1790003100,"age":240,"rebound":1,"favorite":0,"execution_books":[{"bid":0.99,"ask":null,"asks":[],"received_ms":1790003340415,"observed_ms":1790003340396,"hash":"61d0cda00ff94b82e0f96b04c3a20660c0984b9b"},{"bid":null,"ask":0.01,"asks":[[0.01,17114.09]],"received_ms":1790003340403,"observed_ms":1790003340390,"hash":"bef0e611cd3fc2562c6a2db2dbe3462354f1c298"}],"book_errors":[null,null],"costs":[null,[0.05,0.00347]],"cost_errors":["insufficient ask depth",null],"execution_ms":1790003340415,"request_ms":1790003340377,"delay_ms":288,"http_ms":38,"fee_schedule":{"exponent":1,"rate":0.07,"takerOnly":true,"rebateRate":0.2},"qty":5.0}
{"kind":"decision","recorded_ms":1790003370050,"S":1790003100,"age":270,"rebound":1,"favorite":0,"signal":{"rsi14":60.81664344926864,"volume_ratio":1.9779308870087393,"taker_buy_fraction":0.6958987401019693,"volume5":337.22491,"return1":8.119405808807485,"return5":34.88770956825107,"return15":31.210560050042147,"bollinger_z":2.436831262357481,"bar_close_ms":1790003339999,"ref":85929.17715486501,"reference_received_ms":1790003100999,"spot":86221.22709172037,"twap":86257.05538553235,"sigma":8.90704659025936,"spot_z":5.991253963341044,"twap_z":6.726252948829922,"momentum":-0.4556274186538581,"decision_ms":1790003370049,"momentum30":-0.5378928910825059,"momentum60":-1.1937731649918821,"spot_twap_gap":-0.519298152875116,"range60":1.601862827797396,"final_mean":86219.51023029206,"final_z":20.6660596259946,"final_up_prob":1.0,"final_drift_up_prob":1.0,"final_known_seconds":30,"final_sd":14.04878727156338,"final_drift_shift":-9.593674570678147},"books":[{"bid":0.999,"ask":null,"asks":[],"received_ms":1790003370040,"observed_ms":1790003370029,"hash":"062399b45074fab07154e4570f0baf534df08d14"},{"bid":null,"ask":0.001,"asks":[[0.001,17424.94]],"received_ms":1790003370049,"observed_ms":1790003370036,"hash":"baf9ed7a3b7c8d53fef8bfb32039a736a51824fe"}],"book_errors":[null,null],"decision_ms":1790003370050,"feature_cutoff_ms":1790003370049,"request_ms":1790003370010,"http_ms":39,"schedule_lag_ms":50,"bars_received_ms":1790003345253}
{"kind":"execution","recorded_ms":1790003370334,"S":1790003100,"age":270,"rebound":1,"favorite":0,"execution_books":[{"bid":0.999,"ask":null,"asks":[],"received_ms":1790003370334,"observed_ms":1790003370309,"hash":"37de6eb89eae37d05d1229b6fdc78a4801920810"},{"bid":null,"ask":0.001,"asks":[[0.001,17454.94]],"received_ms":1790003370327,"observed_ms":1790003370309,"hash":"0307b8f15a25657c7598d7e8d307a47a104b7af0"}],"book_errors":[null,null],"costs":[null,[0.005,0.00035]],"cost_errors":["insufficient ask depth",null],"execution_ms":1790003370334,"request_ms":1790003370300,"delay_ms":284,"http_ms":34,"fee_schedule":{"exponent":1,"rate":0.07,"takerOnly":true,"rebateRate":0.2},"qty":5.0}
{"kind":"decision","recorded_ms":1790003380038,"S":1790003100,"age":280,"rebound":null,"favorite":0,"signal":{"rsi14":60.81664344926864,"volume_ratio":1.9779308870087393,"taker_buy_fraction":0.6958987401019693,"volume5":337.22491,"return1":8.119405808807485,"return5":34.88770956825107,"return15":31.210560050042147,"bollinger_z":2.436831262357481,"bar_close_ms":1790003339999,"ref":85929.17715486501,"reference_received_ms":1790003100999,"spot":86225.38035519909,"twap":86244.09927557182,"sigma":8.232104636123493,"spot_z":8.052951511271843,"twap_z":8.561867545720343,"momentum":0.21506802688442525,"decision_ms":1790003380036,"momentum30":0.03481318843713323,"momentum60":-1.4921021159118686,"spot_twap_gap":-0.29355824975160333,"range60":1.7331979450050783,"final_mean":86220.64256811935,"final_z":41.24930930917069,"final_up_prob":1.0,"final_drift_up_prob":1.0,"final_known_seconds":40,"final_sd":7.065946512455588,"final_drift_shift":1.859518949850748},"books":[{"bid":0.999,"ask":null,"asks":[],"received_ms":1790003380032,"observed_ms":1790003380018,"hash":"75b1bb64af997c08734d14e59de54341b967acc1"},{"bid":null,"ask":0.001,"asks":[[0.001,17484.94]],"received_ms":1790003380036,"observed_ms":1790003380018,"hash":"3bc61527bcbad306efbb52a552102d464abfb396"}],"book_errors":[null,null],"decision_ms":1790003380038,"feature_cutoff_ms":1790003380036,"request_ms":1790003380005,"http_ms":31,"schedule_lag_ms":38,"bars_received_ms":1790003345253}
{"kind":"execution","recorded_ms":1790003380321,"S":1790003100,"age":280,"rebound":null,"favorite":0,"execution_books":[{"bid":0.999,"ask":null,"asks":[],"received_ms":1790003380318,"observed_ms":1790003380307,"hash":"91b02ac8bff3890e1b29ae20a278c2db276f41c0"},{"bid":null,"ask":0.001,"asks":[[0.001,17509.94]],"received_ms":1790003380321,"observed_ms":1790003380312,"hash":"38c16b9f9915f0b1a01c7a5058e8ed1ea31f64d5"}],"book_errors":[null,null],"costs":[null,[0.005,0.00035]],"cost_errors":["insufficient ask depth",null],"execution_ms":1790003380321,"request_ms":1790003380288,"delay_ms":283,"http_ms":33,"fee_schedule":{"exponent":1,"rate":0.07,"takerOnly":true,"rebateRate":0.2},"qty":5.0}
{"kind":"decision","recorded_ms":1790003970056,"S":1790003700,"age":270,"rebound":null,"favorite":1,"signal":{"rsi14":59.05109489051123,"volume_ratio":0.5017248754407013,"taker_buy_fraction":0.4514404124544779,"volume5":128.59407,"return1":-0.6845269414134483,"return5":-4.4842315738393035,"return15":26.61417543915007,"bollinger_z":0.5884323476997174,"bar_close_ms":1790003939999,"ref":86240.47200119696,"reference_received_ms":1790003701747,"spot":86190.5344745684,"twap":86156.78843956038,"sigma":9.034284523548038,"spot_z":-1.0101156644328315,"twap_z":-1.6927165234550248,"momentum":-0.2477283991755386,"decision_ms":1790003970055,"momentum30":0.1986138723245347,"momentum60":0.7251823657307855,"spot_twap_gap":0.48222904369067526,"range60":1.2029200383522791,"final_mean":86188.349311649,"final_z":-3.6589666949171504,"final_up_prob":0.00012661712211142762,"final_drift_up_prob":2.7862513037490988e-05,"final_known_seconds":30,"final_sd":14.245193764777708,"final_drift_shift":-5.28855404784786},"books":[{"bid":null,"ask":0.01,"asks":[[0.01,35502.51]],"received_ms":1790003970053,"observed_ms":1790003970041,"hash":"75a6bb5b53c5aaf5e7d1e34006804f98a07755d4"},{"bid":0.99,"ask":null,"asks":[],"received_ms":1790003970055,"observed_ms":1790003970042,"hash":"1106b8a71f958e6b697f39611f57488b7809adf8"}],"book_errors":[null,null],"decision_ms":1790003970056,"feature_cutoff_ms":1790003970055,"request_ms":1790003970025,"http_ms":30,"schedule_lag_ms":56,"bars_received_ms":1790003945269}
{"kind":"execution","recorded_ms":1790003970340,"S":1790003700,"age":270,"rebound":null,"favorite":1,"execution_books":[{"bid":null,"ask":0.01,"asks":[[0.01,35160.51]],"received_ms":1790003970340,"observed_ms":1790003970324,"hash":"4dc61d2dc7a27f1817cf99b1fec8dd6a736882ef"},{"bid":0.99,"ask":null,"asks":[],"received_ms":1790003970333,"observed_ms":1790003970324,"hash":"7d31c4e828ce59cf6af6075d7ffc22f1a007d234"}],"book_errors":[null,null],"costs":[[0.05,0.00347],null],"cost_errors":[null,"insufficient ask depth"],"execution_ms":1790003970340,"request_ms":1790003970306,"delay_ms":284,"http_ms":34,"fee_schedule":{"exponent":1,"rate":0.07,"takerOnly":true,"rebateRate":0.2},"qty":5.0}
{"kind":"gap","recorded_ms":1790003980045,"S":1790003700,"age":280,"phase":"decision","error":"ValueError","reason":"incomplete or stale context","books":[{"bid":null,"ask":0.01,"asks":[[0.01,57601.78]],"received_ms":1790003980039,"observed_ms":1790003979995,"hash":"ee175e3a6beb3714017fe9159155d64aaaaeaccb"},{"bid":0.99,"ask":null,"asks":[],"received_ms":1790003980044,"observed_ms":1790003979995,"hash":"37ed674ce09ab4275ec6b950dd434ae426097b71"}],"book_errors":[null,null]}
{"kind":"decision","recorded_ms":1790004240065,"S":1790004000,"age":240,"rebound":null,"favorite":1,"signal":{"rsi14":35.35105321329325,"volume_ratio":0.7258615673219367,"taker_buy_fraction":0.33119578398584487,"volume5":133.63902,"return1":-1.4106383295442622,"return5":-24.11575188767311,"return15":-23.60638701682331,"bollinger_z":-1.3177017637889654,"bar_close_ms":1790004179999,"ref":86169.19843132998,"reference_received_ms":1790004001552,"spot":85988.5472621577,"twap":85993.28694560124,"sigma":6.143016199387523,"spot_z":-3.798527176000014,"twap_z":-3.6988665070522475,"momentum":-0.46412252383348074,"decision_ms":1790004240064,"momentum30":-0.5505176112718576,"momentum60":0.18851639642892873,"spot_twap_gap":-0.09960750249980814,"range60":0.7521692906004508,"final_mean":85988.5472621577,"final_z":-6.586267402725198,"final_up_prob":2.2551072120791105e-11,"final_drift_up_prob":1.8596235662471372e-14,"final_known_seconds":0,"final_sd":27.428459569910853,"final_drift_shift":-26.99035350225177},"books":[{"bid":null,"ask":0.01,"asks":[[0.01,17799.98]],"received_ms":1790004240053,"observed_ms":1790004240037,"hash":"befb6d58c3e8dde03b9e341c642d7bcbe76f4ed6"},{"bid":0.99,"ask":null,"asks":[],"received_ms":1790004240064,"observed_ms":1790004240052,"hash":"ae56eea309e2561d52463ed190ce8ea443a6703f"}],"book_errors":[null,null],"decision_ms":1790004240065,"feature_cutoff_ms":1790004240064,"request_ms":1790004240022,"http_ms":42,"schedule_lag_ms":65,"bars_received_ms":1790004195626}
{"kind":"execution","recorded_ms":1790004240360,"S":1790004000,"age":240,"rebound":null,"favorite":1,"execution_books":[{"bid":null,"ask":0.01,"asks":[[0.01,20669.9]],"received_ms":1790004240355,"observed_ms":1790004240343,"hash":"19df301b8f70ba4751c9675bb6b35d814f26d5f4"},{"bid":0.99,"ask":null,"asks":[],"received_ms":1790004240360,"observed_ms":1790004240343,"hash":"344e6e0f61a69d98e1eb035cafba6ce637a3589e"}],"book_errors":[null,null],"costs":[[0.05,0.00347],null],"cost_errors":[null,"insufficient ask depth"],"execution_ms":1790004240360,"request_ms":1790004240315,"delay_ms":295,"http_ms":45,"fee_schedule":{"exponent":1,"rate":0.07,"takerOnly":true,"rebateRate":0.2},"qty":5.0}
{"kind":"gap","recorded_ms":1790004270030,"S":1790004000,"age":270,"phase":"decision","error":"ValueError","reason":"incomplete or stale context","books":[{"bid":null,"ask":0.01,"asks":[[0.01,31228.58]],"received_ms":1790004270027,"observed_ms":1790004270004,"hash":"92f31be9d9af1ea38954a433d282c8c8442c05de"},{"bid":0.99,"ask":null,"asks":[],"received_ms":1790004270027,"observed_ms":1790004270004,"hash":"542f0d4edf16ba16f9c859852c408887bcc88a64"}],"book_errors":[null,null]}
{"kind":"decision","recorded_ms":1790004280042,"S":1790004000,"age":280,"rebound":0,"favorite":1,"signal":{"rsi14":31.43871137871946,"volume_ratio":0.7994434623999289,"taker_buy_fraction":0.27958533692270005,"volume5":139.66809,"return1":-2.503259355350702,"return5":-25.938745522749098,"return15":-34.26278081405284,"bollinger_z":-1.5224704219900638,"bar_close_ms":1790004239999,"ref":86169.19843132998,"reference_received_ms":1790004001552,"spot":85912.4665905682,"twap":85937.20047363012,"sigma":12.151874707220307,"spot_z":-4.728857016866759,"twap_z":-4.273272714878221,"momentum":0.19290741750967333,"decision_ms":1790004280040,"momentum30":0.6993843430446053,"momentum60":-0.8101359345932984,"spot_twap_gap":-0.262768556275816,"range60":1.483375593255714,"final_mean":85904.79078463068,"final_z":-25.357229356576894,"final_up_prob":0.0,"final_drift_up_prob":0.0,"final_known_seconds":40,"final_sd":10.4273082433874,"final_drift_shift":2.4611157496603586},"books":[{"bid":null,"ask":0.01,"asks":[[0.01,43889.17]],"received_ms":1790004280034,"observed_ms":1790004279835,"hash":"86a75b7a854c2566f5ae75e89045e64f4a159085"},{"bid":0.99,"ask":null,"asks":[],"received_ms":1790004280040,"observed_ms":1790004279835,"hash":"2bad40078d9d1f72936b288c63d166e79c29c6a3"}],"book_errors":[null,null],"decision_ms":1790004280042,"feature_cutoff_ms":1790004280040,"request_ms":1790004280004,"http_ms":36,"schedule_lag_ms":42,"bars_received_ms":1790004245249}
{"kind":"execution","recorded_ms":1790004280334,"S":1790004000,"age":280,"rebound":0,"favorite":1,"execution_books":[{"bid":null,"ask":0.01,"asks":[[0.01,44054.17]],"received_ms":1790004280334,"observed_ms":1790004280320,"hash":"7feefe98c347f6b0e559ec43f5798cf12da5b80e"},{"bid":0.99,"ask":null,"asks":[],"received_ms":1790004280324,"observed_ms":1790004280310,"hash":"ec3054cd1f3643704dcbdbab853b43b94a8f62d1"}],"book_errors":[null,null],"costs":[[0.05,0.00347],null],"cost_errors":[null,"insufficient ask depth"],"execution_ms":1790004280334,"request_ms":1790004280292,"delay_ms":292,"http_ms":42,"fee_schedule":{"exponent":1,"rate":0.07,"takerOnly":true,"rebateRate":0.2},"qty":5.0}
{"kind":"gap","recorded_ms":1790004570061,"S":1790004300,"age":270,"phase":"decision","error":"ValueError","reason":"incomplete or stale context","books":[{"bid":null,"ask":0.01,"asks":[[0.01,36818.06]],"received_ms":1790004570047,"observed_ms":1790004570033,"hash":"a1e0bc5506a86b5b2926e3760d9de52ef66a525d"},{"bid":0.99,"ask":null,"asks":[],"received_ms":1790004570060,"observed_ms":1790004570043,"hash":"37fac5db213551bc4c79923ce35feaa13c5f506e"}],"book_errors":[null,null]}
{"kind":"gap","recorded_ms":1790004580081,"S":1790004300,"age":280,"phase":"decision","error":"ValueError","reason":"incomplete or stale context","books":[{"bid":null,"ask":0.01,"asks":[[0.01,54034.49]],"received_ms":1790004580072,"observed_ms":1790004580056,"hash":"797a296562e0fcf91ee274ce143909593010eced"},{"bid":0.99,"ask":null,"asks":[],"received_ms":1790004580080,"observed_ms":1790004580061,"hash":"0fcc277cee1a019863901f25e81f95d8e11b7b11"}],"book_errors":[null,null]}
{"kind":"decision","recorded_ms":1790004870075,"S":1790004600,"age":270,"rebound":null,"favorite":0,"signal":{"rsi14":29.135411163936922,"volume_ratio":0.9503498898268951,"taker_buy_fraction":0.45345854496614807,"volume5":135.47836,"return1":2.1573380520784475,"return5":8.816794964053011,"return15":-34.696701903964815,"bollinger_z":-0.6580180863481199,"bar_close_ms":1790004839999,"ref":85824.94072169792,"reference_received_ms":1790004601962,"spot":85850.00378250114,"twap":85884.25982967846,"sigma":5.174820958857757,"spot_z":0.8853488807833891,"twap_z":2.0954386326544654,"momentum":-1.8153999315649407,"decision_ms":1790004870074,"momentum30":-1.092085528436731,"momentum60":-0.802644477076381,"spot_twap_gap":-0.8546067022058027,"range60":1.2825205211357409,"final_mean":85866.87893988796,"final_z":5.144622516464059,"final_up_prob":0.9999998659703668,"final_drift_up_prob":0.9923433432078705,"final_known_seconds":30,"final_sd":8.151855273313265,"final_drift_shift":-22.170921474463473},"books":[{"bid":0.99,"ask":null,"asks":[],"received_ms":1790004870069,"observed_ms":1790004870061,"hash":"f2f6102f781667a43fbbc7165cc90d743b9f2f2b"},{"bid":null,"ask":0.01,"asks":[[0.01,13142.68]],"received_ms":1790004870074,"observed_ms":1790004870065,"hash":"a1980a86ce2fb2933c374dcc1a5e98d96679c08d"}],"book_errors":[null,null],"decision_ms":1790004870075,"feature_cutoff_ms":1790004870074,"request_ms":1790004870043,"http_ms":31,"schedule_lag_ms":75,"bars_received_ms":1790004845238}
{"kind":"execution","recorded_ms":1790004870361,"S":1790004600,"age":270,"rebound":null,"favorite":0,"execution_books":[{"bid":0.99,"ask":null,"asks":[],"received_ms":1790004870354,"observed_ms":1790004870331,"hash":"6177124ba878b3e3db1434cfe92464f7bdcd9c7d"},{"bid":null,"ask":0.01,"asks":[[0.01,13172.08]],"received_ms":1790004870360,"observed_ms":1790004870331,"hash":"d2f5db1dd6d8c52f1feaa804f577d0df586bab90"}],"book_errors":[null,null],"costs":[null,[0.05,0.00347]],"cost_errors":["insufficient ask depth",null],"execution_ms":1790004870361,"request_ms":1790004870325,"delay_ms":286,"http_ms":36,"fee_schedule":{"exponent":1,"rate":0.07,"takerOnly":true,"rebateRate":0.2},"qty":5.0}
{"kind":"decision","recorded_ms":1790004880069,"S":1790004600,"age":280,"rebound":null,"favorite":0,"signal":{"rsi14":29.135411163936922,"volume_ratio":0.9503498898268951,"taker_buy_fraction":0.45345854496614807,"volume5":135.47836,"return1":2.1573380520784475,"return5":8.816794964053011,"return15":-34.696701903964815,"bollinger_z":-0.6580180863481199,"bar_close_ms":1790004839999,"ref":85824.94072169792,"reference_received_ms":1790004601962,"spot":85879.68260765234,"twap":85880.11686989958,"sigma":6.324926891648569,"spot_z":1.9385540361573832,"twap_z":1.9539324035162227,"momentum":1.4995084771734386,"decision_ms":1790004880067,"momentum30":-0.5561539057160281,"momentum60":-0.03237400196878181,"spot_twap_gap":-0.008863820247671676,"range60":1.055701677031139,"final_mean":85879.93871115771,"final_z":10.154164112215735,"final_up_prob":1.0,"final_drift_up_prob":1.0,"final_known_seconds":40,"final_sd":5.416299052487113,"final_drift_shift":9.930440796395157},"books":[{"bid":0.99,"ask":null,"asks":[],"received_ms":1790004880057,"observed_ms":1790004880047,"hash":"2d67aa28a0533f859c6504cdaf9d041d84c23266"},{"bid":null,"ask":0.01,"asks":[[0.01,33382.07]],"received_ms":1790004880067,"observed_ms":1790004880056,"hash":"07c673d88c691628ee6d9bfa5dc0caa49bc18088"}],"book_errors":[null,null],"decision_ms":1790004880069,"feature_cutoff_ms":1790004880067,"request_ms":1790004880030,"http_ms":37,"schedule_lag_ms":69,"bars_received_ms":1790004845238}
{"kind":"execution","recorded_ms":1790004880355,"S":1790004600,"age":280,"rebound":null,"favorite":0,"execution_books":[{"bid":0.99,"ask":null,"asks":[],"received_ms":1790004880344,"observed_ms":1790004880335,"hash":"39bb3d29d7dc12aa6451195517045499833f0446"},{"bid":null,"ask":0.01,"asks":[[0.01,33392.07]],"received_ms":1790004880355,"observed_ms":1790004880335,"hash":"271afc819a5deea3b75ec43a15d70e9046994259"}],"book_errors":[null,null],"costs":[null,[0.05,0.00347]],"cost_errors":["insufficient ask depth",null],"execution_ms":1790004880355,"request_ms":1790004880319,"delay_ms":286,"http_ms":36,"fee_schedule":{"exponent":1,"rate":0.07,"takerOnly":true,"rebateRate":0.2},"qty":5.0}
{"kind":"decision","recorded_ms":1790005170043,"S":1790004900,"age":270,"rebound":null,"favorite":0,"signal":{"rsi14":55.65749745608648,"volume_ratio":0.24819678443184592,"taker_buy_fraction":0.51996128859806,"volume5":161.01716,"return1":12.50009890239376,"return5":5.867820791657521,"return15":-2.86235160568515,"bollinger_z":0.43534543056722935,"bar_close_ms":1790005139999,"ref":85876.71585863364,"reference_received_ms":1790004901255,"spot":85926.89301193401,"twap":85923.34912086763,"sigma":3.459862092770464,"spot_z":2.6496641057545745,"twap_z":2.4625247338360254,"momentum":0.19391996354843447,"decision_ms":1790005170042,"momentum30":-0.2542304940859728,"momentum60":0.7081702059621786,"spot_twap_gap":0.13223485708232738,"range60":1.2095963452742813,"final_mean":85926.69878659178,"final_z":9.155995254516531,"final_up_prob":1.0,"final_drift_up_prob":1.0,"final_known_seconds":30,"final_sd":5.459038211435928,"final_drift_shift":1.5868127983621914},"books":[{"bid":0.99,"ask":null,"asks":[],"received_ms":1790005170042,"observed_ms":1790005170032,"hash":"8f483ba01141f705d5bceee848619392d489e87e"},{"bid":null,"ask":0.01,"asks":[[0.01,23769.23]],"received_ms":1790005170039,"observed_ms":1790005170032,"hash":"26adda9fb0c7612a7fd85ff191dad9bb26204748"}],"book_errors":[null,null],"decision_ms":1790005170043,"feature_cutoff_ms":1790005170042,"request_ms":1790005170011,"http_ms":31,"schedule_lag_ms":43,"bars_received_ms":1790005145254}
{"kind":"execution","recorded_ms":1790005170327,"S":1790004900,"age":270,"rebound":null,"favorite":0,"execution_books":[{"bid":0.99,"ask":null,"asks":[],"received_ms":1790005170326,"observed_ms":1790005170308,"hash":"4b23e64cad142f80e431dfd7f164ab86d57966cd"},{"bid":null,"ask":0.01,"asks":[[0.01,24232.23]],"received_ms":1790005170318,"observed_ms":1790005170296,"hash":"954ceee0d43265bb247400e7161536054e5569fc"}],"book_errors":[null,null],"costs":[null,[0.05,0.00347]],"cost_errors":["insufficient ask depth",null],"execution_ms":1790005170327,"request_ms":1790005170293,"delay_ms":284,"http_ms":34,"fee_schedule":{"exponent":1,"rate":0.07,"takerOnly":true,"rebateRate":0.2},"qty":5.0}
{"kind":"decision","recorded_ms":1790005180075,"S":1790004900,"age":280,"rebound":null,"favorite":0,"signal":{"rsi14":55.65749745608648,"volume_ratio":0.24819678443184592,"taker_buy_fraction":0.51996128859806,"volume5":161.01716,"return1":12.50009890239376,"return5":5.867820791657521,"return15":-2.86235160568515,"bollinger_z":0.43534543056722935,"bar_close_ms":1790005139999,"ref":85876.71585863364,"reference_received_ms":1790004901255,"spot":85947.18263518618,"twap":85927.0064259048,"sigma":2.9897513491168137,"spot_z":5.28006502126677,"twap_z":3.768264679314304,"momentum":2.270321433442304,"decision_ms":1790005180074,"momentum30":1.3841180649254208,"momentum60":1.0727491989543096,"spot_twap_gap":0.8712220896395975,"range60":1.0727491989543096,"final_mean":85934.82411898536,"final_z":22.708292941397975,"final_up_prob":1.0,"final_drift_up_prob":1.0,"final_known_seconds":40,"final_sd":2.55890042028567,"final_drift_shift":7.102012474909394},"books":[{"bid":0.99,"ask":null,"asks":[],"received_ms":1790005180073,"observed_ms":1790005180065,"hash":"2540f02811e7e7d779c5a3d757339019155c7bdc"},{"bid":null,"ask":0.01,"asks":[[0.01,47933.26]],"received_ms":1790005180072,"observed_ms":1790005180065,"hash":"7517df2d9b18d5cefb78d824f0da6f71e7a9a444"}],"book_errors":[null,null],"decision_ms":1790005180075,"feature_cutoff_ms":1790005180074,"request_ms":1790005180048,"http_ms":26,"schedule_lag_ms":75,"bars_received_ms":1790005145254}
{"kind":"execution","recorded_ms":1790005180353,"S":1790004900,"age":280,"rebound":null,"favorite":0,"execution_books":[{"bid":0.99,"ask":null,"asks":[],"received_ms":1790005180353,"observed_ms":1790005180340,"hash":"b609de3dc1d23425369f7baf38670f7f7a7fe4be"},{"bid":null,"ask":0.01,"asks":[[0.01,47953.26]],"received_ms":1790005180349,"observed_ms":1790005180340,"hash":"767f5cf448197939e2c5f3c7b826525f81717743"}],"book_errors":[null,null],"costs":[null,[0.05,0.00347]],"cost_errors":["insufficient ask depth",null],"execution_ms":1790005180353,"request_ms":1790005180325,"delay_ms":278,"http_ms":28,"fee_schedule":{"exponent":1,"rate":0.07,"takerOnly":true,"rebateRate":0.2},"qty":5.0}
{"kind":"decision","recorded_ms":1790005470045,"S":1790005200,"age":270,"rebound":null,"favorite":0,"signal":{"rsi14":61.06718764308977,"volume_ratio":0.6633275077459168,"taker_buy_fraction":0.4027609858111644,"volume5":66.83917,"return1":7.2655378492305465,"return5":6.010813883269249,"return15":20.681432562190675,"bollinger_z":2.3525400728563213,"bar_close_ms":1790005439999,"ref":85936.67740243499,"reference_received_ms":1790005201488,"spot":86057.77265029661,"twap":85991.58028514229,"sigma":6.81343802726705,"spot_z":3.247273577612755,"twap_z":1.472268181439553,"momentum":0.524924193392549,"decision_ms":1790005470044,"momentum30":1.8021916314493693,"momentum60":1.8434034358610571,"spot_twap_gap":1.2541975962933212,"range60":2.147210717443495,"final_mean":86041.54927993045,"final_z":9.756159144167974,"final_up_prob":1.0,"final_drift_up_prob":1.0,"final_known_seconds":30,"final_sd":10.749299590725883,"final_drift_shift":8.457642036785083},"books":[{"bid":0.99,"ask":null,"asks":[],"received_ms":1790005470038,"observed_ms":1790005470023,"hash":"3f80b6cae90189511842c1fa689ba7c9d7f6fb15"},{"bid":null,"ask":0.01,"asks":[[0.01,42986.21]],"received_ms":1790005470043,"observed_ms":1790005470031,"hash":"81a096f30391b2977b7e4d85f91d7f2f15b78d02"}],"book_errors":[null,null],"decision_ms":1790005470045,"feature_cutoff_ms":1790005470044,"request_ms":1790005470014,"http_ms":30,"schedule_lag_ms":45,"bars_received_ms":1790005445259}
{"kind":"execution","recorded_ms":1790005470325,"S":1790005200,"age":270,"rebound":null,"favorite":0,"execution_books":[{"bid":0.99,"ask":null,"asks":[],"received_ms":1790005470325,"observed_ms":1790005470317,"hash":"290dc5ffbd206b163f3fb40c8b567815e0d297f8"},{"bid":null,"ask":0.01,"asks":[[0.01,43195.64]],"received_ms":1790005470323,"observed_ms":1790005470300,"hash":"0e65003f5808f92814c13fa8c4a19fbe0bc880a7"}],"book_errors":[null,null],"costs":[null,[0.05,0.00347]],"cost_errors":["insufficient ask depth",null],"execution_ms":1790005470325,"request_ms":1790005470295,"delay_ms":280,"http_ms":30,"fee_schedule":{"exponent":1,"rate":0.07,"takerOnly":true,"rebateRate":0.2},"qty":5.0}
{"kind":"decision","recorded_ms":1790005480079,"S":1790005200,"age":280,"rebound":null,"favorite":0,"signal":{"rsi14":61.06718764308977,"volume_ratio":0.6633275077459168,"taker_buy_fraction":0.4027609858111644,"volume5":66.83917,"return1":7.2655378492305465,"return5":6.010813883269249,"return15":20.681432562190675,"bollinger_z":2.3525400728563213,"bar_close_ms":1790005439999,"ref":85936.67740243499,"reference_received_ms":1790005201488,"spot":86046.51265787054,"twap":86007.11144757552,"sigma":6.872782094011292,"spot_z":3.580492123600055,"twap_z":2.296061887040767,"momentum":0.04493884776887981,"decision_ms":1790005480078,"momentum30":1.2444857060878949,"momentum60":1.8968418117683123,"spot_twap_gap":0.7401186749201443,"range60":2.1286703047857225,"final_mean":86035.79884444494,"final_z":16.855727954459173,"final_up_prob":1.0,"final_drift_up_prob":1.0,"final_known_seconds":40,"final_sd":5.880579128813852,"final_drift_shift":0.3230272275135059},"books":[{"bid":0.99,"ask":null,"asks":[],"received_ms":1790005480078,"observed_ms":1790005480062,"hash":"5ddb0ddadaeccad1cb77b9ecc2ea16aa99e275d1"},{"bid":null,"ask":0.01,"asks":[[0.01,56338.64]],"received_ms":1790005480073,"observed_ms":1790005480062,"hash":"ed7de51fa4faaa7753680848fcbe9c982f824f47"}],"book_errors":[null,null],"decision_ms":1790005480079,"feature_cutoff_ms":1790005480078,"request_ms":1790005480045,"http_ms":33,"schedule_lag_ms":79,"bars_received_ms":1790005445259}
{"kind":"execution","recorded_ms":1790005480364,"S":1790005200,"age":280,"rebound":null,"favorite":0,"execution_books":[{"bid":0.99,"ask":null,"asks":[],"received_ms":1790005480363,"observed_ms":1790005480297,"hash":"e03a0d9c98a0d2d20a954703271babcc557a5908"},{"bid":null,"ask":0.01,"asks":[[0.01,56348.64]],"received_ms":1790005480360,"observed_ms":1790005480297,"hash":"1036ad59079deafc4094d12f7a9b3309c7124356"}],"book_errors":[null,null],"costs":[null,[0.05,0.00347]],"cost_errors":["insufficient ask depth",null],"execution_ms":1790005480364,"request_ms":1790005480330,"delay_ms":285,"http_ms":34,"fee_schedule":{"exponent":1,"rate":0.07,"takerOnly":true,"rebateRate":0.2},"qty":5.0}
{"kind":"decision","recorded_ms":1790005740074,"S":1790005500,"age":240,"rebound":1,"favorite":0,"signal":{"rsi14":64.82961559082759,"volume_ratio":1.2757253433887878,"taker_buy_fraction":0.560679181646034,"volume5":119.66460000000001,"return1":5.4335988675809155,"return5":23.015006485487408,"return15":29.76869123179619,"bollinger_z":2.0903401927002823,"bar_close_ms":1790005679999,"ref":86041.04149463846,"reference_received_ms":1790005501844,"spot":86144.07693184417,"twap":86144.30170214336,"sigma":4.414395682603434,"spot_z":3.0151164571521285,"twap_z":3.021693889601975,"momentum":-0.7535309611071522,"decision_ms":1790005740073,"momentum30":-0.0826206038247277,"momentum60":0.5246507932945824,"spot_twap_gap":-0.006573429963155927,"range60":1.2406830774235382,"final_mean":86144.07693184417,"final_z":5.228696471242056,"final_up_prob":0.9999999146453202,"final_drift_up_prob":0.9998589405510161,"final_known_seconds":0,"final_sd":19.705759891096413,"final_drift_shift":-31.48010617434672},"books":[{"bid":0.99,"ask":null,"asks":[],"received_ms":1790005740061,"observed_ms":1790005740052,"hash":"73c0547d0299c925ec5a5b257ec294d618e7c6a5"},{"bid":null,"ask":0.01,"asks":[[0.01,5529.45]],"received_ms":1790005740073,"observed_ms":1790005740064,"hash":"9767a28c46a779244360dcd8177120e629ee1d72"}],"book_errors":[null,null],"decision_ms":1790005740074,"feature_cutoff_ms":1790005740073,"request_ms":1790005740024,"http_ms":49,"schedule_lag_ms":74,"bars_received_ms":1790005695571}
{"kind":"execution","recorded_ms":1790005740359,"S":1790005500,"age":240,"rebound":1,"favorite":0,"execution_books":[{"bid":0.99,"ask":null,"asks":[],"received_ms":1790005740359,"observed_ms":1790005740348,"hash":"659fc68a3c00b9f3da5f4be28a402ede6e6f4508"},{"bid":null,"ask":0.01,"asks":[[0.01,5781.45]],"received_ms":1790005740359,"observed_ms":1790005740350,"hash":"72f90ff81806ed0f34aa184ff9e3895f3e5b5116"}],"book_errors":[null,null],"costs":[null,[0.05,0.00347]],"cost_errors":["insufficient ask depth",null],"execution_ms":1790005740359,"request_ms":1790005740324,"delay_ms":285,"http_ms":35,"fee_schedule":{"exponent":1,"rate":0.07,"takerOnly":true,"rebateRate":0.2},"qty":5.0}
{"kind":"decision","recorded_ms":1790005770041,"S":1790005500,"age":270,"rebound":1,"favorite":0,"signal":{"rsi14":66.2252827089515,"volume_ratio":0.999556384662557,"taker_buy_fraction":0.5550440253020228,"volume5":126.83729,"return1":0.4876068903975391,"return5":16.247758169274316,"return15":28.103571418621076,"bollinger_z":1.848411229295202,"bar_close_ms":1790005739999,"ref":86041.04149463846,"reference_received_ms":1790005501844,"spot":86062.2447626275,"twap":86126.43595558275,"sigma":7.122344591722243,"spot_z":0.543887297368533,"twap_z":2.190462460656778,"momentum":-0.6364450835165489,"decision_ms":1790005770040,"momentum30":-1.8221237133223551,"momentum60":-1.519497335543244,"spot_twap_gap":-1.1635280025524488,"range60":1.917569396059803,"final_mean":86076.12355977595,"final_z":3.121485573978493,"final_up_prob":0.9991002946807883,"final_drift_up_prob":0.984899896272861,"final_known_seconds":30,"final_sd":11.238900294766449,"final_drift_shift":-10.722258933189444},"books":[{"bid":0.99,"ask":null,"asks":[],"received_ms":1790005770028,"observed_ms":1790005770019,"hash":"385b9cb2ab5d019710860def05ce2e4c5ce26fa6"},{"bid":null,"ask":0.01,"asks":[[0.01,11185.94]],"received_ms":1790005770039,"observed_ms":1790005770031,"hash":"3f939f75eeb363c139b99d0ebe0acd250e712a61"}],"book_errors":[null,null],"decision_ms":1790005770041,"feature_cutoff_ms":1790005770040,"request_ms":1790005770000,"http_ms":40,"schedule_lag_ms":41,"bars_received_ms":1790005745244}
{"kind":"execution","recorded_ms":1790005770351,"S":1790005500,"age":270,"rebound":1,"favorite":0,"execution_books":[{"bid":0.99,"ask":null,"asks":[],"received_ms":1790005770321,"observed_ms":1790005770298,"hash":"c389352867b04375eb56cc6c8c767f61dc1a8617"},{"bid":null,"ask":0.01,"asks":[[0.01,11122.75]],"received_ms":1790005770351,"observed_ms":1790005770314,"hash":"f4d7529cfabee64a058b0fc739d92c79b6af50e4"}],"book_errors":[null,null],"costs":[null,[0.05,0.00347]],"cost_errors":["insufficient ask depth",null],"execution_ms":1790005770351,"request_ms":1790005770291,"delay_ms":310,"http_ms":60,"fee_schedule":{"exponent":1,"rate":0.07,"takerOnly":true,"rebateRate":0.2},"qty":5.0}
{"kind":"decision","recorded_ms":1790005780064,"S":1790005500,"age":280,"rebound":1,"favorite":0,"signal":{"rsi14":66.2252827089515,"volume_ratio":0.999556384662557,"taker_buy_fraction":0.5550440253020228,"volume5":126.83729,"return1":0.4876068903975391,"return5":16.247758169274316,"return15":28.103571418621076,"bollinger_z":1.848411229295202,"bar_close_ms":1790005739999,"ref":86041.04149463846,"reference_received_ms":1790005501844,"spot":86067.92675485191,"twap":86112.90362416401,"sigma":7.193753660251394,"spot_z":0.8370063974918481,"twap_z":2.2372505109759744,"momentum":-0.10861515695713349,"decision_ms":1790005780063,"momentum30":-0.5469106517963258,"momentum60":-1.3737612916714326,"spot_twap_gap":-0.8071570329725242,"range60":1.8773901335679384,"final_mean":86079.09283586893,"final_z":6.1749944367683085,"final_up_prob":0.9999999996691711,"final_drift_up_prob":0.9999999992397632,"final_known_seconds":40,"final_sd":6.162166074822563,"final_drift_shift":-0.8184353313556945},"books":[{"bid":0.99,"ask":null,"asks":[],"received_ms":1790005780060,"observed_ms":1790005780041,"hash":"fddf9251adb226b19c17a8cb573e90f4bc76013c"},{"bid":null,"ask":0.01,"asks":[[0.01,16674.25]],"received_ms":1790005780063,"observed_ms":1790005780041,"hash":"16e9571b0b12d3284ef999b564cff214627771f2"}],"book_errors":[null,null],"decision_ms":1790005780064,"feature_cutoff_ms":1790005780063,"request_ms":1790005780022,"http_ms":41,"schedule_lag_ms":64,"bars_received_ms":1790005745244}
{"kind":"execution","recorded_ms":1790005780360,"S":1790005500,"age":280,"rebound":1,"favorite":0,"execution_books":[{"bid":0.99,"ask":null,"asks":[],"received_ms":1790005780359,"observed_ms":1790005780340,"hash":"4cec6937aad4a340aa25e172bc18a4a7f23d4ad9"},{"bid":null,"ask":0.01,"asks":[[0.01,15662.84]],"received_ms":1790005780352,"observed_ms":1790005780340,"hash":"3285941404e4fc2a58485c856063874fc5002b3e"}],"book_errors":[null,null],"costs":[null,[0.05,0.00347]],"cost_errors":["insufficient ask depth",null],"execution_ms":1790005780359,"request_ms":1790005780314,"delay_ms":295,"http_ms":45,"fee_schedule":{"exponent":1,"rate":0.07,"takerOnly":true,"rebateRate":0.2},"qty":5.0}
{"kind":"decision","recorded_ms":1790006070052,"S":1790005800,"age":270,"rebound":null,"favorite":1,"signal":{"rsi14":53.66030692658606,"volume_ratio":1.441434362965848,"taker_buy_fraction":0.46778906741682513,"volume5":177.65847,"return1":-5.072503439689622,"return5":-11.912944031480816,"return15":10.362366673884196,"bollinger_z":0.3447187019496242,"bar_close_ms":1790006039999,"ref":86080.1983010768,"reference_received_ms":1790005801488,"spot":86002.36114431082,"twap":86033.41425788886,"sigma":6.393476402153966,"spot_z":-2.224634843077028,"twap_z":-1.3371173472951718,"momentum":0.040828035484440355,"decision_ms":1790006070051,"momentum30":-0.9547190012520083,"momentum60":-1.2114693006572035,"spot_twap_gap":-0.6270359773549308,"range60":1.2823677755029097,"final_mean":86007.42379572183,"final_z":-7.217396875221266,"final_up_prob":2.649547248267936e-13,"final_drift_up_prob":4.1472381084872723e-13,"final_known_seconds":30,"final_sd":10.083206814471083,"final_drift_shift":0.6169911750964089},"books":[{"bid":null,"ask":0.01,"asks":[[0.01,38266.98]],"received_ms":1790006070045,"observed_ms":1790006070034,"hash":"edaec6294269de539e1b0cbb6823a7b0dd135c73"},{"bid":0.99,"ask":null,"asks":[],"received_ms":1790006070050,"observed_ms":1790006070040,"hash":"e13f2b8a8368ab0f43f31893c1b3731ebf7d937c"}],"book_errors":[null,null],"decision_ms":1790006070052,"feature_cutoff_ms":1790006070051,"request_ms":1790006070011,"http_ms":40,"schedule_lag_ms":52,"bars_received_ms":1790006045256}
{"kind":"execution","recorded_ms":1790006070336,"S":1790005800,"age":270,"rebound":null,"favorite":1,"execution_books":[{"bid":null,"ask":0.01,"asks":[[0.01,51070.98]],"received_ms":1790006070328,"observed_ms":1790006070305,"hash":"0f798ef941dd4d8784f7ff28dea1819e5ee2b1a0"},{"bid":0.99,"ask":null,"asks":[],"received_ms":1790006070336,"observed_ms":1790006070327,"hash":"b7a1193cc7e0397650b600cb7f3486c2ea8197d8"}],"book_errors":[null,null],"costs":[[0.05,0.00347],null],"cost_errors":[null,"insufficient ask depth"],"execution_ms":1790006070336,"request_ms":1790006070302,"delay_ms":284,"http_ms":34,"fee_schedule":{"exponent":1,"rate":0.07,"takerOnly":true,"rebateRate":0.2},"qty":5.0}
{"kind":"decision","recorded_ms":1790006080038,"S":1790005800,"age":280,"rebound":null,"favorite":1,"signal":{"rsi14":53.66030692658606,"volume_ratio":1.441434362965848,"taker_buy_fraction":0.46778906741682513,"volume5":177.65847,"return1":-5.072503439689622,"return5":-11.912944031480816,"return15":10.362366673884196,"bollinger_z":0.3447187019496242,"bar_close_ms":1790006039999,"ref":86080.1983010768,"reference_received_ms":1790005801488,"spot":85977.43376985822,"twap":86021.56873632835,"sigma":6.199556102655253,"spot_z":-3.709964440159452,"twap_z":-2.116621345706661,"momentum":-1.261184067848967,"decision_ms":1790006080037,"momentum30":-1.0906284390962588,"momentum60":-1.8054527629986337,"spot_twap_gap":-0.9190657486536938,"range60":1.8054527629986337,"final_mean":85997.08877912334,"final_z":-15.619364339051293,"final_up_prob":0.0,"final_drift_up_prob":0.0,"final_known_seconds":40,"final_sd":5.320928569780056,"final_drift_shift":-8.211253128641106},"books":[{"bid":null,"ask":0.01,"asks":[[0.01,57604.88]],"received_ms":1790006080028,"observed_ms":1790006080005,"hash":"8f9b670e5d43e4d63158efdbc8bf9c6240a3c3b1"},{"bid":0.99,"ask":null,"asks":[],"received_ms":1790006080037,"observed_ms":1790006080005,"hash":"e3a34724446ece629885427a4051319ec9184ead"}],"book_errors":[null,null],"decision_ms":1790006080038,"feature_cutoff_ms":1790006080037,"request_ms":1790006080006,"http_ms":31,"schedule_lag_ms":38,"bars_received_ms":1790006045256}
{"kind":"execution","recorded_ms":1790006080332,"S":1790005800,"age":280,"rebound":null,"favorite":1,"execution_books":[{"bid":null,"ask":0.01,"asks":[[0.01,57614.88]],"received_ms":1790006080332,"observed_ms":1790006080317,"hash":"4bb89fe34b943e7912fde97dbff7ddaa2c8e3086"},{"bid":0.99,"ask":null,"asks":[],"received_ms":1790006080319,"observed_ms":1790006080298,"hash":"5bd8e7f76306687ea949643ef8972b8b390d9304"}],"book_errors":[null,null],"costs":[[0.05,0.00347],null],"cost_errors":[null,"insufficient ask depth"],"execution_ms":1790006080332,"request_ms":1790006080289,"delay_ms":294,"http_ms":43,"fee_schedule":{"exponent":1,"rate":0.07,"takerOnly":true,"rebateRate":0.2},"qty":5.0}
{"kind":"decision","recorded_ms":1790006370044,"S":1790006100,"age":270,"rebound":null,"favorite":1,"signal":{"rsi14":35.71806722087877,"volume_ratio":1.1836109816353542,"taker_buy_fraction":0.3471026946210895,"volume5":106.85584,"return1":-3.4497062163146683,"return5":-13.048129686607526,"return15":-8.688278307957995,"bollinger_z":-1.2724456233193413,"bar_close_ms":1790006339999,"ref":85998.00298464045,"reference_received_ms":1790006101346,"spot":85930.21660158278,"twap":85931.40476490972,"sigma":4.93827018328654,"spot_z":-2.5079057214025693,"twap_z":-2.46394701655398,"momentum":-0.3368958625542602,"decision_ms":1790006370042,"momentum30":0.17514994682205773,"momentum60":-0.6517535944623408,"spot_twap_gap":-0.03106173219234402,"range60":1.073934318192513,"final_mean":85931.23748205153,"final_z":-8.568798483533838,"final_up_prob":0.0,"final_drift_up_prob":0.0,"final_known_seconds":30,"final_sd":7.791699468393928,"final_drift_shift":-3.9347297598807556},"books":[{"bid":null,"ask":0.01,"asks":[[0.01,39456.2]],"received_ms":1790006370034,"observed_ms":1790006370021,"hash":"1e2555452bdd89b3ae21687edf6c1a5d7db9f1f1"},{"bid":0.99,"ask":null,"asks":[],"received_ms":1790006370042,"observed_ms":1790006370021,"hash":"78bfdad47cff2cac717643efab997d026e5c79b1"}],"book_errors":[null,null],"decision_ms":1790006370044,"feature_cutoff_ms":1790006370042,"request_ms":1790006370009,"http_ms":33,"schedule_lag_ms":44,"bars_received_ms":1790006345256}
{"kind":"execution","recorded_ms":1790006370325,"S":1790006100,"age":270,"rebound":null,"favorite":1,"execution_books":[{"bid":null,"ask":0.01,"asks":[[0.01,39336.2]],"received_ms":1790006370325,"observed_ms":1790006370299,"hash":"672c0205beb6a96a47f19c25d92faaedb14d85a9"},{"bid":0.99,"ask":null,"asks":[],"received_ms":1790006370319,"observed_ms":1790006370299,"hash":"7986776273e7272f25e8800f87cc895ba60b2197"}],"book_errors":[null,null],"costs":[[0.05,0.00347],null],"cost_errors":[null,"insufficient ask depth"],"execution_ms":1790006370325,"request_ms":1790006370294,"delay_ms":281,"http_ms":31,"fee_schedule":{"exponent":1,"rate":0.07,"takerOnly":true,"rebateRate":0.2},"qty":5.0}
{"kind":"decision","recorded_ms":1790006380079,"S":1790006100,"age":280,"rebound":null,"favorite":1,"signal":{"rsi14":35.71806722087877,"volume_ratio":1.1836109816353542,"taker_buy_fraction":0.3471026946210895,"volume5":106.85584,"return1":-3.4497062163146683,"return5":-13.048129686607526,"return15":-8.688278307957995,"bollinger_z":-1.2724456233193413,"bar_close_ms":1790006339999,"ref":85998.00298464045,"reference_received_ms":1790006101346,"spot":85914.85324660152,"twap":85927.96402405649,"sigma":3.1327422547051813,"spot_z":-5.946614058826253,"twap_z":-5.008971495245495,"momentum":-1.2185115676625349,"decision_ms":1790006380078,"momentum30":-1.092681196345289,"momentum60":0.03238117669128955,"spot_twap_gap":-0.5402915253420884,"range60":0.8823062707725547,"final_mean":85924.56414505356,"final_z":-27.397669178557095,"final_up_prob":0.0,"final_drift_up_prob":0.0,"final_known_seconds":40,"final_sd":2.680477638746198,"final_drift_shift":-3.9924450167252648},"books":[{"bid":null,"ask":0.01,"asks":[[0.01,59162.59]],"received_ms":1790006380073,"observed_ms":1790006380059,"hash":"9fa062230153564fe50448265937d033371a10a5"},{"bid":0.99,"ask":null,"asks":[],"received_ms":1790006380078,"observed_ms":1790006380068,"hash":"397e97bca3274633e36b84f864f73e3e7a6a4a62"}],"book_errors":[null,null],"decision_ms":1790006380079,"feature_cutoff_ms":1790006380078,"request_ms":1790006380045,"http_ms":33,"schedule_lag_ms":79,"bars_received_ms":1790006345256}
{"kind":"execution","recorded_ms":1790006380364,"S":1790006100,"age":280,"rebound":null,"favorite":1,"execution_books":[{"bid":null,"ask":0.01,"asks":[[0.01,59162.59]],"received_ms":1790006380364,"observed_ms":1790006380298,"hash":"2f9dcc23adc969cbdd15207299c4757327f7c179"},{"bid":0.99,"ask":null,"asks":[],"received_ms":1790006380359,"observed_ms":1790006380298,"hash":"7b09997bf04de4eb8ac20990e87040766ce281be"}],"book_errors":[null,null],"costs":[[0.05,0.00347],null],"cost_errors":[null,"insufficient ask depth"],"execution_ms":1790006380364,"request_ms":1790006380329,"delay_ms":285,"http_ms":35,"fee_schedule":{"exponent":1,"rate":0.07,"takerOnly":true,"rebateRate":0.2},"qty":5.0}
