{"kind":"decision","recorded_ms":1789996840035,"S":1789996800,"age":40,"signal":{"rsi14":34.11196071117662,"volume_ratio":0.87891473725721,"taker_buy_fraction":0.4232676822662559,"volume5":107.84237,"return1":6.937833536141371,"return5":0.18081339728573226,"return15":-7.025892008847536,"bollinger_z":-0.6901348188630002,"bar_close_ms":1789996799999,"ref":85155.41144321438,"reference_received_ms":1789996801280,"spot":85150.66061206402,"twap":85141.5218904163,"sigma":6.81114219668695,"spot_z":-0.04326048381835678,"twap_z":-0.12647655853221385,"momentum":2.38731566731103,"decision_ms":1789996840034,"momentum30":0.033620153534152715,"momentum60":-0.4088981686104223,"spot_twap_gap":0.1732167465462968,"range60":1.3835157085877465,"final_mean":85150.66061206402,"final_z":-0.04702966329381214,"final_up_prob":0.48124479289461597,"final_drift_up_prob":1.0,"final_known_seconds":0,"final_sd":101.01775810475736,"final_drift_shift":1182.4789728815424},"entry_side":0,"context_gap":null,"book_errors":[null,null],"books":[{"bid":0.47,"ask":0.48,"asks":[[0.48,307.11]],"received_ms":1789996840033,"observed_ms":1789996840024,"hash":"7059a412a53a3793da41e46f619ff207d86b6134"},{"bid":0.52,"ask":0.53,"asks":[[0.53,418.99]],"received_ms":1789996840034,"observed_ms":1789996840024,"hash":"025cc93dac07f8ed4fada2219fb634a994d6c80c"}],"intents":{"pair_fast":{"kind":"first","side":0,"qty":5.0,"max_cost":2.5373599999999996},"pair_250":{"kind":"first","side":0,"qty":5.0,"max_cost":2.5373599999999996},"pair_add_fast":{"kind":"first","side":0,"qty":5.0,"max_cost":2.5373599999999996},"pair_add_250":{"kind":"first","side":0,"qty":5.0,"max_cost":2.5373599999999996}},"decision_ms":1789996840035,"feature_cutoff_ms":1789996840034,"request_ms":1789996840001,"inventory":{"pair_fast":{"qty":[0.0,0.0],"cash":0.0,"lots":[[],[]],"floor":0.0},"pair_250":{"qty":[0.0,0.0],"cash":0.0,"lots":[[],[]],"floor":0.0},"pair_add_fast":{"qty":[0.0,0.0],"cash":0.0,"lots":[[],[]],"floor":0.0},"pair_add_250":{"qty":[0.0,0.0],"cash":0.0,"lots":[[],[]],"floor":0.0}}}
{"kind":"decision","recorded_ms":1789996850040,"S":1789996800,"age":50,"signal":{"rsi14":34.11196071117662,"volume_ratio":0.87891473725721,"taker_buy_fraction":0.4232676822662559,"volume5":107.84237,"return1":6.937833536141371,"return5":0.18081339728573226,"return15":-7.025892008847536,"bollinger_z":-0.6901348188630002,"bar_close_ms":1789996799999,"ref":85155.41144321438,"reference_received_ms":1789996801280,"spot":85128.595402615,"twap":85137.24776251076,"sigma":7.200746321888438,"spot_z":-0.23554886533184852,"twap_z":-0.15954757989468132,"momentum":-0.9690150963307044,"decision_ms":1789996850039,"momentum30":-0.1320511121954489,"momentum60":-0.6164812985168227,"spot_twap_gap":-0.1551248730972886,"range60":1.1427673516392947,"final_mean":85128.595402615,"final_z":-0.2570087012434821,"final_up_prob":0.39858602801144,"final_drift_up_prob":4.58509981593469e-07,"final_known_seconds":0,"final_sd":104.33903782105537,"final_drift_shift":-485.3485534858669},"entry_side":null,"context_gap":null,"book_errors":[null,null],"books":[{"bid":0.44,"ask":0.45,"asks":[[0.45,1116.67]],"received_ms":1789996850039,"observed_ms":1789996850027,"hash":"68c3a18d7925172450e3aa5d5edb8108e7197dd5"},{"bid":0.55,"ask":0.56,"asks":[[0.56,86.0]],"received_ms":1789996850035,"observed_ms":1789996850027,"hash":"0082c8354a75d6530a2f8995302ad0cb0c764d4b"}],"intents":{"pair_fast":null,"pair_250":null,"pair_add_fast":null,"pair_add_250":null},"decision_ms":1789996850040,"feature_cutoff_ms":1789996850039,"request_ms":1789996850004,"inventory":{"pair_fast":{"qty":[5.0,0.0],"cash":2.48736,"lots":[[[5.0,0.49747199999999997]],[]],"floor":-2.48736},"pair_250":{"qty":[5.0,0.0],"cash":2.48736,"lots":[[[5.0,0.49747199999999997]],[]],"floor":-2.48736},"pair_add_fast":{"qty":[5.0,0.0],"cash":2.48736,"lots":[[[5.0,0.49747199999999997]],[]],"floor":-2.48736},"pair_add_250":{"qty":[5.0,0.0],"cash":2.48736,"lots":[[[5.0,0.49747199999999997]],[]],"floor":-2.48736}}}
{"kind":"decision","recorded_ms":1789996860047,"S":1789996800,"age":60,"signal":{"rsi14":34.11196071117662,"volume_ratio":0.87891473725721,"taker_buy_fraction":0.4232676822662559,"volume5":107.84237,"return1":6.937833536141371,"return5":0.18081339728573226,"return15":-7.025892008847536,"bollinger_z":-0.6901348188630002,"bar_close_ms":1789996799999,"ref":85155.41144321438,"reference_received_ms":1789996801280,"spot":85134.04623787818,"twap":85133.82560326597,"sigma":7.47058827860065,"spot_z":-0.1846240493138419,"twap_z":-0.186530628487045,"momentum":0.2307322253508935,"decision_ms":1789996860046,"momentum30":0.8506103320543517,"momentum60":-0.28980867616805644,"spot_twap_gap":0.003812792901189258,"range60":0.8912810101110294,"final_mean":85134.04623787818,"final_z":-0.20224939016153343,"final_up_prob":0.41986088154224316,"final_drift_up_prob":0.8108673524718302,"final_known_seconds":0,"final_sd":105.63792216697414,"final_drift_shift":114.44246668253085},"entry_side":0,"context_gap":null,"book_errors":[null,null],"books":[{"bid":0.43,"ask":0.44,"asks":[[0.44,268.15]],"received_ms":1789996860046,"observed_ms":1789996860036,"hash":"7b174f099fbba9eea75e23dff8ee61bb7fd75d5b"},{"bid":0.56,"ask":0.57,"asks":[[0.57,563.66]],"received_ms":1789996860040,"observed_ms":1789996860031,"hash":"e74cb439baa7ca30d92f519e5bed2649d262bdc7"}],"intents":{"pair_fast":null,"pair_250":null,"pair_add_fast":null,"pair_add_250":null},"decision_ms":1789996860047,"feature_cutoff_ms":1789996860046,"request_ms":1789996860013,"inventory":{"pair_fast":{"qty":[5.0,0.0],"cash":2.48736,"lots":[[[5.0,0.49747199999999997]],[]],"floor":-2.48736},"pair_250":{"qty":[5.0,0.0],"cash":2.48736,"lots":[[[5.0,0.49747199999999997]],[]],"floor":-2.48736},"pair_add_fast":{"qty":[5.0,0.0],"cash":2.48736,"lots":[[[5.0,0.49747199999999997]],[]],"floor":-2.48736},"pair_add_250":{"qty":[5.0,0.0],"cash":2.48736,"lots":[[[5.0,0.49747199999999997]],[]],"floor":-2.48736}}}
{"kind":"decision","recorded_ms":1789996870084,"S":1789996800,"age":70,"signal":{"rsi14":27.719227131468532,"volume_ratio":0.5827337090745752,"taker_buy_fraction":0.482378832591407,"volume5":99.965,"return1":-0.4708414688509908,"return5":3.1960859805838555,"return15":-24.477885539026147,"bollinger_z":-0.6939693871461076,"bar_close_ms":1789996859999,"ref":85155.41144321438,"reference_received_ms":1789996801280,"spot":85123.31600473424,"twap":85131.8314693454,"sigma":7.679634130811365,"spot_z":-0.27562413325852814,"twap_z":-0.20249637230903123,"momentum":-0.4418436605377986,"decision_ms":1789996870083,"momentum30":-0.6500855815753236,"momentum60":-0.43859538399697773,"spot_twap_gap":-0.1431502771376855,"range60":0.8643977745681278,"final_mean":85123.31600473424,"final_z":-0.30326400244166113,"final_up_prob":0.38084433853942135,"final_drift_up_prob":0.009898235556312251,"final_known_seconds":0,"final_sd":105.83332746958176,"final_drift_shift":-214.51560200310382},"entry_side":null,"context_gap":null,"book_errors":[null,null],"books":[{"bid":0.38,"ask":0.39,"asks":[[0.39,452.91]],"received_ms":1789996870082,"observed_ms":1789996870061,"hash":"f355e18f9f3ed13f979f4520580185d1ef82bbdc"},{"bid":0.61,"ask":0.62,"asks":[[0.62,170.78]],"received_ms":1789996870072,"observed_ms":1789996870063,"hash":"3397fd883883910bd181c989bf50af5d8ae6b98e"}],"intents":{"pair_fast":null,"pair_250":null,"pair_add_fast":null,"pair_add_250":null},"decision_ms":1789996870084,"feature_cutoff_ms":1789996870083,"request_ms":1789996870045,"inventory":{"pair_fast":{"qty":[5.0,0.0],"cash":2.48736,"lots":[[[5.0,0.49747199999999997]],[]],"floor":-2.48736},"pair_250":{"qty":[5.0,0.0],"cash":2.48736,"lots":[[[5.0,0.49747199999999997]],[]],"floor":-2.48736},"pair_add_fast":{"qty":[5.0,0.0],"cash":2.48736,"lots":[[[5.0,0.49747199999999997]],[]],"floor":-2.48736},"pair_add_250":{"qty":[5.0,0.0],"cash":2.48736,"lots":[[[5.0,0.49747199999999997]],[]],"floor":-2.48736}}}
{"kind":"decision","recorded_ms":1789996880038,"S":1789996800,"age":80,"signal":{},"entry_side":null,"context_gap":"incomplete or stale context","book_errors":[null,null],"books":[{"bid":0.46,"ask":0.47,"asks":[[0.47,767.05]],"received_ms":1789996880037,"observed_ms":1789996880029,"hash":"99dcef0b522e7468168460657967c17aa10f630f"},{"bid":0.53,"ask":0.54,"asks":[[0.54,27.0]],"received_ms":1789996880034,"observed_ms":1789996880025,"hash":"107f8f63f3e211d89c2a0e22532639d3de10a192"}],"intents":{"pair_fast":null,"pair_250":null,"pair_add_fast":null,"pair_add_250":null},"decision_ms":1789996880038,"feature_cutoff_ms":1789996880037,"request_ms":1789996880007,"inventory":{"pair_fast":{"qty":[5.0,0.0],"cash":2.48736,"lots":[[[5.0,0.49747199999999997]],[]],"floor":-2.48736},"pair_250":{"qty":[5.0,0.0],"cash":2.48736,"lots":[[[5.0,0.49747199999999997]],[]],"floor":-2.48736},"pair_add_fast":{"qty":[5.0,0.0],"cash":2.48736,"lots":[[[5.0,0.49747199999999997]],[]],"floor":-2.48736},"pair_add_250":{"qty":[5.0,0.0],"cash":2.48736,"lots":[[[5.0,0.49747199999999997]],[]],"floor":-2.48736}}}
{"kind":"decision","recorded_ms":1789996890067,"S":1789996800,"age":90,"signal":{},"entry_side":null,"context_gap":"incomplete or stale context","book_errors":[null,null],"books":[{"bid":0.51,"ask":0.52,"asks":[[0.52,15.0]],"received_ms":1789996890066,"observed_ms":1789996890049,"hash":"aba3faa42f487718aa2e9bb7e858f6eb83c9348e"},{"bid":0.48,"ask":0.49,"asks":[[0.49,229.75]],"received_ms":1789996890047,"observed_ms":1789996890034,"hash":"25a4149cc267fc8eb54fe1e6b7af349ba6c95734"}],"intents":{"pair_fast":null,"pair_250":null,"pair_add_fast":null,"pair_add_250":null},"decision_ms":1789996890067,"feature_cutoff_ms":1789996890066,"request_ms":1789996890010,"inventory":{"pair_fast":{"qty":[5.0,0.0],"cash":2.48736,"lots":[[[5.0,0.49747199999999997]],[]],"floor":-2.48736},"pair_250":{"qty":[5.0,0.0],"cash":2.48736,"lots":[[[5.0,0.49747199999999997]],[]],"floor":-2.48736},"pair_add_fast":{"qty":[5.0,0.0],"cash":2.48736,"lots":[[[5.0,0.49747199999999997]],[]],"floor":-2.48736},"pair_add_250":{"qty":[5.0,0.0],"cash":2.48736,"lots":[[[5.0,0.49747199999999997]],[]],"floor":-2.48736}}}
{"kind":"decision","recorded_ms":1789996900073,"S":1789996800,"age":100,"signal":{},"entry_side":null,"context_gap":"incomplete or stale context","book_errors":[null,null],"books":[{"bid":0.58,"ask":0.59,"asks":[[0.59,1092.87]],"received_ms":1789996900064,"observed_ms":1789996900031,"hash":"f94096e3d22351c29fbe5404b5f538da1fc59adf"},{"bid":0.41,"ask":0.42,"asks":[[0.42,157.67]],"received_ms":1789996900072,"observed_ms":1789996900064,"hash":"7ab163c34e325f14273b109a8af270ab86a907c8"}],"intents":{"pair_fast":{"kind":"complete","side":1,"qty":5.0,"max_cost":2.4126400000000006},"pair_250":{"kind":"complete","side":1,"qty":5.0,"max_cost":2.4126400000000006},"pair_add_fast":{"kind":"complete","side":1,"qty":5.0,"max_cost":2.4126400000000006},"pair_add_250":{"kind":"complete","side":1,"qty":5.0,"max_cost":2.4126400000000006}},"decision_ms":1789996900073,"feature_cutoff_ms":1789996900072,"request_ms":1789996900039,"inventory":{"pair_fast":{"qty":[5.0,0.0],"cash":2.48736,"lots":[[[5.0,0.49747199999999997]],[]],"floor":-2.48736},"pair_250":{"qty":[5.0,0.0],"cash":2.48736,"lots":[[[5.0,0.49747199999999997]],[]],"floor":-2.48736},"pair_add_fast":{"qty":[5.0,0.0],"cash":2.48736,"lots":[[[5.0,0.49747199999999997]],[]],"floor":-2.48736},"pair_add_250":{"qty":[5.0,0.0],"cash":2.48736,"lots":[[[5.0,0.49747199999999997]],[]],"floor":-2.48736}}}
{"kind":"decision","recorded_ms":1789997130043,"S":1789997100,"age":30,"signal":{"rsi14":32.395062667605664,"volume_ratio":0.9216650190917347,"taker_buy_fraction":0.5527563391349439,"volume5":91.44702,"return1":-3.3923643121864497,"return5":-11.433654769450234,"return15":-31.426975831814026,"bollinger_z":-1.2423189610052172,"bar_close_ms":1789997099999,"ref":85069.06077693662,"reference_received_ms":1789997101569,"spot":85019.08612515178,"twap":85037.85110474359,"sigma":6.495282903984559,"spot_z":-0.4682778374914006,"twap_z":-0.2924442148449415,"momentum":1.473470867678009,"decision_ms":1789997130042,"momentum30":-1.0121838347569923,"momentum60":-1.0053543208886533,"spot_twap_gap":-0.3729704285675995,"range60":1.6068962836665055,"final_mean":85019.08612515178,"final_z":-0.5073731066691408,"final_up_prob":0.30594652590258664,"final_drift_up_prob":0.9999999999966933,"final_known_seconds":0,"final_sd":98.49684803540129,"final_drift_shift":726.2311262212802},"entry_side":0,"context_gap":null,"book_errors":[null,null],"books":[{"bid":0.33,"ask":0.34,"asks":[[0.34,1242.46]],"received_ms":1789997130027,"observed_ms":1789997130021,"hash":"a0edeca2ef1f1a1721653d8f779be3861c7ea863"},{"bid":0.66,"ask":0.67,"asks":[[0.67,102.0]],"received_ms":1789997130042,"observed_ms":1789997130028,"hash":"dd91a4ff986f6745dfe19c4f82bbd2a0b73ed184"}],"intents":{"pair_fast":{"kind":"first","side":0,"qty":5.0,"max_cost":1.8285400000000003},"pair_250":{"kind":"first","side":0,"qty":5.0,"max_cost":1.8285400000000003},"pair_add_fast":{"kind":"first","side":0,"qty":5.0,"max_cost":1.8285400000000003},"pair_add_250":{"kind":"first","side":0,"qty":5.0,"max_cost":1.8285400000000003}},"decision_ms":1789997130043,"feature_cutoff_ms":1789997130042,"request_ms":1789997130003,"inventory":{"pair_fast":{"qty":[0.0,0.0],"cash":0.0,"lots":[[],[]],"floor":0.0},"pair_250":{"qty":[0.0,0.0],"cash":0.0,"lots":[[],[]],"floor":0.0},"pair_add_fast":{"qty":[0.0,0.0],"cash":0.0,"lots":[[],[]],"floor":0.0},"pair_add_250":{"qty":[0.0,0.0],"cash":0.0,"lots":[[],[]],"floor":0.0}}}
{"kind":"decision","recorded_ms":1789997140051,"S":1789997100,"age":40,"signal":{"rsi14":32.395062667605664,"volume_ratio":0.9216650190917347,"taker_buy_fraction":0.5527563391349439,"volume5":91.44702,"return1":-3.3923643121864497,"return5":-11.433654769450234,"return15":-31.426975831814026,"bollinger_z":-1.2423189610052172,"bar_close_ms":1789997099999,"ref":85069.06077693662,"reference_received_ms":1789997101569,"spot":85031.26658229265,"twap":85030.6896281844,"sigma":6.507954226905783,"spot_z":-0.3601933535583792,"twap_z":-0.3656919502888954,"momentum":0.5918601478168577,"decision_ms":1789997140050,"momentum30":0.677620140598256,"momentum60":-0.5901210505789544,"spot_twap_gap":0.011445141206643675,"range60":1.5938202732152913,"final_mean":85031.26658229265,"final_z":-0.39157830530675997,"final_up_prob":0.3476849101002536,"final_drift_up_prob":0.9939698618485531,"final_known_seconds":0,"final_sd":96.51759081586518,"final_drift_shift":280.0896120124331},"entry_side":0,"context_gap":null,"book_errors":[null,null],"books":[{"bid":0.32,"ask":0.33,"asks":[[0.33,792.28]],"received_ms":1789997140029,"observed_ms":1789997140020,"hash":"86290c40bcbb5076bceb39532a68ac2d480ccf0b"},{"bid":0.67,"ask":0.68,"asks":[[0.68,277.87]],"received_ms":1789997140050,"observed_ms":1789997140034,"hash":"44cc6e5a8e7c125f08e48c39a47b9aea8650bb4a"}],"intents":{"pair_fast":null,"pair_250":null,"pair_add_fast":null,"pair_add_250":null},"decision_ms":1789997140051,"feature_cutoff_ms":1789997140050,"request_ms":1789997140006,"inventory":{"pair_fast":{"qty":[5.0,0.0],"cash":1.7785400000000002,"lots":[[[5.0,0.355708]],[]],"floor":-1.7785400000000002},"pair_250":{"qty":[5.0,0.0],"cash":1.7273900000000002,"lots":[[[5.0,0.34547800000000006]],[]],"floor":-1.7273900000000002},"pair_add_fast":{"qty":[5.0,0.0],"cash":1.7785400000000002,"lots":[[[5.0,0.355708]],[]],"floor":-1.7785400000000002},"pair_add_250":{"qty":[5.0,0.0],"cash":1.7273900000000002,"lots":[[[5.0,0.34547800000000006]],[]],"floor":-1.7273900000000002}}}
{"kind":"decision","recorded_ms":1789997150052,"S":1789997100,"age":50,"signal":{},"entry_side":null,"context_gap":"incomplete or stale context","book_errors":[null,null],"books":[{"bid":0.33,"ask":0.34,"asks":[[0.34,778.33]],"received_ms":1789997150051,"observed_ms":1789997150042,"hash":"55190c6abd4d63d124a158308531ed89a329128e"},{"bid":0.66,"ask":0.67,"asks":[[0.67,324.37]],"received_ms":1789997150051,"observed_ms":1789997150042,"hash":"24ee641968e2c357f7586c751779ff0d67475f4d"}],"intents":{"pair_fast":null,"pair_250":null,"pair_add_fast":null,"pair_add_250":null},"decision_ms":1789997150052,"feature_cutoff_ms":1789997150051,"request_ms":1789997150023,"inventory":{"pair_fast":{"qty":[5.0,0.0],"cash":1.7785400000000002,"lots":[[[5.0,0.355708]],[]],"floor":-1.7785400000000002},"pair_250":{"qty":[5.0,0.0],"cash":1.7273900000000002,"lots":[[[5.0,0.34547800000000006]],[]],"floor":-1.7273900000000002},"pair_add_fast":{"qty":[5.0,0.0],"cash":1.7785400000000002,"lots":[[[5.0,0.355708]],[]],"floor":-1.7785400000000002},"pair_add_250":{"qty":[5.0,0.0],"cash":1.7273900000000002,"lots":[[[5.0,0.34547800000000006]],[]],"floor":-1.7273900000000002}}}
{"kind":"decision","recorded_ms":1789997160052,"S":1789997100,"age":60,"signal":{},"entry_side":null,"context_gap":"incomplete or stale context","book_errors":[null,null],"books":[{"bid":0.47,"ask":0.48,"asks":[[0.48,44.89]],"received_ms":1789997160050,"observed_ms":1789997160042,"hash":"108ee51f8ea3309a73392d0634c414e67ba343f5"},{"bid":0.52,"ask":0.53,"asks":[[0.53,40.58]],"received_ms":1789997160051,"observed_ms":1789997160043,"hash":"eaf73e5f61929732e66ba119e2f756607a2fdab3"}],"intents":{"pair_fast":{"kind":"complete","side":1,"qty":5.0,"max_cost":3.1214600000000003},"pair_250":{"kind":"complete","side":1,"qty":5.0,"max_cost":3.17261},"pair_add_fast":{"kind":"complete","side":1,"qty":5.0,"max_cost":3.1214600000000003},"pair_add_250":{"kind":"complete","side":1,"qty":5.0,"max_cost":3.17261}},"decision_ms":1789997160052,"feature_cutoff_ms":1789997160051,"request_ms":1789997160025,"inventory":{"pair_fast":{"qty":[5.0,0.0],"cash":1.7785400000000002,"lots":[[[5.0,0.355708]],[]],"floor":-1.7785400000000002},"pair_250":{"qty":[5.0,0.0],"cash":1.7273900000000002,"lots":[[[5.0,0.34547800000000006]],[]],"floor":-1.7273900000000002},"pair_add_fast":{"qty":[5.0,0.0],"cash":1.7785400000000002,"lots":[[[5.0,0.355708]],[]],"floor":-1.7785400000000002},"pair_add_250":{"qty":[5.0,0.0],"cash":1.7273900000000002,"lots":[[[5.0,0.34547800000000006]],[]],"floor":-1.7273900000000002}}}
{"kind":"decision","recorded_ms":1789997430073,"S":1789997400,"age":30,"signal":{},"entry_side":null,"context_gap":"incomplete or stale context","book_errors":[null,null],"books":[{"bid":0.49,"ask":0.51,"asks":[[0.51,53.1]],"received_ms":1789997430071,"observed_ms":1789997430062,"hash":"7ffe6b1ed02b2a26faabeaafa6a7215a13d7f81c"},{"bid":0.49,"ask":0.51,"asks":[[0.51,673.16]],"received_ms":1789997430065,"observed_ms":1789997430056,"hash":"86c1cd7bb082a97c63dec1af0b1fffdf796f8d1e"}],"intents":{"pair_fast":null,"pair_250":null,"pair_add_fast":null,"pair_add_250":null},"decision_ms":1789997430073,"feature_cutoff_ms":1789997430071,"request_ms":1789997430037,"inventory":{"pair_fast":{"qty":[0.0,0.0],"cash":0.0,"lots":[[],[]],"floor":0.0},"pair_250":{"qty":[0.0,0.0],"cash":0.0,"lots":[[],[]],"floor":0.0},"pair_add_fast":{"qty":[0.0,0.0],"cash":0.0,"lots":[[],[]],"floor":0.0},"pair_add_250":{"qty":[0.0,0.0],"cash":0.0,"lots":[[],[]],"floor":0.0}}}
{"kind":"decision","recorded_ms":1789997440088,"S":1789997400,"age":40,"signal":{},"entry_side":null,"context_gap":"incomplete or stale context","book_errors":[null,null],"books":[{"bid":0.59,"ask":0.6,"asks":[[0.6,1564.61]],"received_ms":1789997440071,"observed_ms":1789997440064,"hash":"50b9915ab662b248a72594135cde0d007c9c8bf7"},{"bid":0.4,"ask":0.41,"asks":[[0.41,40.31]],"received_ms":1789997440087,"observed_ms":1789997440076,"hash":"31b3ea0a8f98ce8258860570f5434a06ceb747f3"}],"intents":{"pair_fast":null,"pair_250":null,"pair_add_fast":null,"pair_add_250":null},"decision_ms":1789997440088,"feature_cutoff_ms":1789997440087,"request_ms":1789997440048,"inventory":{"pair_fast":{"qty":[0.0,0.0],"cash":0.0,"lots":[[],[]],"floor":0.0},"pair_250":{"qty":[0.0,0.0],"cash":0.0,"lots":[[],[]],"floor":0.0},"pair_add_fast":{"qty":[0.0,0.0],"cash":0.0,"lots":[[],[]],"floor":0.0},"pair_add_250":{"qty":[0.0,0.0],"cash":0.0,"lots":[[],[]],"floor":0.0}}}
{"kind":"decision","recorded_ms":1789997450075,"S":1789997400,"age":50,"signal":{},"entry_side":null,"context_gap":"incomplete or stale context","book_errors":[null,null],"books":[{"bid":0.68,"ask":0.69,"asks":[[0.69,348.3]],"received_ms":1789997450047,"observed_ms":1789997450039,"hash":"1ba5cd4384e3e92222c8b960d72ed0fadd1c2b41"},{"bid":0.31,"ask":0.32,"asks":[[0.32,332.24]],"received_ms":1789997450073,"observed_ms":1789997450061,"hash":"e5444b3dd56fbf1191ee2e2bad72c8e87354b4a7"}],"intents":{"pair_fast":null,"pair_250":null,"pair_add_fast":null,"pair_add_250":null},"decision_ms":1789997450075,"feature_cutoff_ms":1789997450074,"request_ms":1789997450014,"inventory":{"pair_fast":{"qty":[0.0,0.0],"cash":0.0,"lots":[[],[]],"floor":0.0},"pair_250":{"qty":[0.0,0.0],"cash":0.0,"lots":[[],[]],"floor":0.0},"pair_add_fast":{"qty":[0.0,0.0],"cash":0.0,"lots":[[],[]],"floor":0.0},"pair_add_250":{"qty":[0.0,0.0],"cash":0.0,"lots":[[],[]],"floor":0.0}}}
{"kind":"decision","recorded_ms":1789997460085,"S":1789997400,"age":60,"signal":{"rsi14":22.425249169433528,"volume_ratio":1.552734378598341,"taker_buy_fraction":0.24451715347824085,"volume5":338.6252,"return1":-4.5228259680840885,"return5":-14.89401201150555,"return15":-26.163406335417342,"bollinger_z":-2.2422121383333584,"bar_close_ms":1789997399999,"ref":84935.87191029677,"reference_received_ms":1789997401639,"spot":85003.24633837,"twap":84942.54060547077,"sigma":15.087371395855698,"spot_z":0.2883042199093645,"twap_z":0.028536241641461676,"momentum":-0.30411475258175974,"decision_ms":1789997460083,"momentum30":1.128471246515477,"momentum60":0.7224784248676677,"spot_twap_gap":0.5194461124014165,"range60":1.2883835742369723,"final_mean":85003.24633837,"final_z":0.3158323758333145,"final_up_prob":0.6239351287051044,"final_drift_up_prob":0.1330810829220634,"final_known_seconds":0,"final_sd":213.32337413305174,"final_drift_shift":-304.5781052546381},"entry_side":null,"context_gap":null,"book_errors":[null,null],"books":[{"bid":0.68,"ask":0.69,"asks":[[0.69,41.98]],"received_ms":1789997460083,"observed_ms":1789997460065,"hash":"456a4ced908f51aabc843e42255045428497621a"},{"bid":0.31,"ask":0.32,"asks":[[0.32,903.51]],"received_ms":1789997460078,"observed_ms":1789997460065,"hash":"f261cdf0cbeb42ea0c234c9543f6e5b9bc819048"}],"intents":{"pair_fast":null,"pair_250":null,"pair_add_fast":null,"pair_add_250":null},"decision_ms":1789997460085,"feature_cutoff_ms":1789997460083,"request_ms":1789997460048,"inventory":{"pair_fast":{"qty":[0.0,0.0],"cash":0.0,"lots":[[],[]],"floor":0.0},"pair_250":{"qty":[0.0,0.0],"cash":0.0,"lots":[[],[]],"floor":0.0},"pair_add_fast":{"qty":[0.0,0.0],"cash":0.0,"lots":[[],[]],"floor":0.0},"pair_add_250":{"qty":[0.0,0.0],"cash":0.0,"lots":[[],[]],"floor":0.0}}}
{"kind":"decision","recorded_ms":1789997470073,"S":1789997400,"age":70,"signal":{"rsi14":40.91028425499384,"volume_ratio":1.2619228408254741,"taker_buy_fraction":0.260232665648237,"volume5":338.25277,"return1":10.94896519285049,"return5":-5.36806208842829,"return15":-11.694496707431455,"bollinger_z":-0.9459217163664141,"bar_close_ms":1789997459999,"ref":84935.87191029677,"reference_received_ms":1789997401639,"spot":84929.31006191947,"twap":84954.80774282683,"sigma":12.448274185187838,"spot_z":-0.034763309479381804,"twap_z":0.10031810682632573,"momentum":-1.8782285143889286,"decision_ms":1789997470072,"momentum30":-0.6397193307670803,"momentum60":0.6442681664237309,"spot_twap_gap":-0.2644331576998984,"range60":1.5615274210430565,"final_mean":84929.31006191947,"final_z":-0.03824921690638395,"final_up_prob":0.484744490082895,"final_drift_up_prob":0.0,"final_known_seconds":0,"final_sd":171.55510381715587,"final_drift_shift":-1478.1931876225326},"entry_side":null,"context_gap":null,"book_errors":[null,null],"books":[{"bid":0.33,"ask":0.34,"asks":[[0.34,606.96]],"received_ms":1789997470072,"observed_ms":1789997470058,"hash":"c4c52497c1d7e663279028b9414987df755b4c95"},{"bid":0.66,"ask":0.67,"asks":[[0.67,243.6]],"received_ms":1789997470058,"observed_ms":1789997470050,"hash":"dcf205d78c507acb21e41092f8ac4d475f0d3850"}],"intents":{"pair_fast":null,"pair_250":null,"pair_add_fast":null,"pair_add_250":null},"decision_ms":1789997470073,"feature_cutoff_ms":1789997470072,"request_ms":1789997470032,"inventory":{"pair_fast":{"qty":[0.0,0.0],"cash":0.0,"lots":[[],[]],"floor":0.0},"pair_250":{"qty":[0.0,0.0],"cash":0.0,"lots":[[],[]],"floor":0.0},"pair_add_fast":{"qty":[0.0,0.0],"cash":0.0,"lots":[[],[]],"floor":0.0},"pair_add_250":{"qty":[0.0,0.0],"cash":0.0,"lots":[[],[]],"floor":0.0}}}
{"kind":"decision","recorded_ms":1789997480087,"S":1789997400,"age":80,"signal":{"rsi14":40.91028425499384,"volume_ratio":1.2619228408254741,"taker_buy_fraction":0.260232665648237,"volume5":338.25277,"return1":10.94896519285049,"return5":-5.36806208842829,"return15":-11.694496707431455,"bollinger_z":-0.9459217163664141,"bar_close_ms":1789997459999,"ref":84935.87191029677,"reference_received_ms":1789997401639,"spot":84830.08794622,"twap":84952.42356872755,"sigma":14.082918841873504,"spot_z":-0.5065248095375287,"twap_z":0.07925422068787845,"momentum":-2.228003181685316,"decision_ms":1789997480086,"momentum30":-2.4329689462719104,"momentum60":-0.9049133352494362,"spot_twap_gap":-1.12146218630684,"range60":1.720368840325157,"final_mean":84830.08794622,"final_z":-0.560008580383406,"final_up_prob":0.2877367925524321,"final_drift_up_prob":0.0,"final_known_seconds":0,"final_sd":188.89704154953068,"final_drift_shift":-1884.3668884357244},"entry_side":null,"context_gap":null,"book_errors":[null,null],"books":[{"bid":0.28,"ask":0.29,"asks":[[0.29,362.03]],"received_ms":1789997480078,"observed_ms":1789997480064,"hash":"2b96699bdf656c499a902fe8f92a766f8bbb79a2"},{"bid":0.71,"ask":0.72,"asks":[[0.72,263.37]],"received_ms":1789997480086,"observed_ms":1789997480072,"hash":"9e41aa2fe27cfc44cd93a8747f732094449da6c3"}],"intents":{"pair_fast":null,"pair_250":null,"pair_add_fast":null,"pair_add_250":null},"decision_ms":1789997480087,"feature_cutoff_ms":1789997480086,"request_ms":1789997480047,"inventory":{"pair_fast":{"qty":[0.0,0.0],"cash":0.0,"lots":[[],[]],"floor":0.0},"pair_250":{"qty":[0.0,0.0],"cash":0.0,"lots":[[],[]],"floor":0.0},"pair_add_fast":{"qty":[0.0,0.0],"cash":0.0,"lots":[[],[]],"floor":0.0},"pair_add_250":{"qty":[0.0,0.0],"cash":0.0,"lots":[[],[]],"floor":0.0}}}
{"kind":"decision","recorded_ms":1789997490059,"S":1789997400,"age":90,"signal":{},"entry_side":null,"context_gap":"incomplete or stale context","book_errors":[null,null],"books":[{"bid":0.23,"ask":0.25,"asks":[[0.25,47.15]],"received_ms":1789997490058,"observed_ms":1789997490043,"hash":"cd24ca2d14ef1d51ca395c5512a92b236bf3020a"},{"bid":0.75,"ask":0.77,"asks":[[0.77,105.0]],"received_ms":1789997490034,"observed_ms":1789997490027,"hash":"4e5a86974b110cb3a73f06f45b550664c09e68c2"}],"intents":{"pair_fast":null,"pair_250":null,"pair_add_fast":null,"pair_add_250":null},"decision_ms":1789997490059,"feature_cutoff_ms":1789997490058,"request_ms":1789997490011,"inventory":{"pair_fast":{"qty":[0.0,0.0],"cash":0.0,"lots":[[],[]],"floor":0.0},"pair_250":{"qty":[0.0,0.0],"cash":0.0,"lots":[[],[]],"floor":0.0},"pair_add_fast":{"qty":[0.0,0.0],"cash":0.0,"lots":[[],[]],"floor":0.0},"pair_add_250":{"qty":[0.0,0.0],"cash":0.0,"lots":[[],[]],"floor":0.0}}}
{"kind":"decision","recorded_ms":1789997500074,"S":1789997400,"age":100,"signal":{},"entry_side":null,"context_gap":"incomplete or stale context","book_errors":[null,null],"books":[{"bid":0.42,"ask":0.43,"asks":[[0.43,70.12]],"received_ms":1789997500073,"observed_ms":1789997500051,"hash":"5136cf617df5299d574769607cfc1cb37a163886"},{"bid":0.57,"ask":0.58,"asks":[[0.58,458.35]],"received_ms":1789997500057,"observed_ms":1789997500050,"hash":"0f1664c77fadd6e5a7107a797bbeba56acf19b75"}],"intents":{"pair_fast":null,"pair_250":null,"pair_add_fast":null,"pair_add_250":null},"decision_ms":1789997500074,"feature_cutoff_ms":1789997500073,"request_ms":1789997500033,"inventory":{"pair_fast":{"qty":[0.0,0.0],"cash":0.0,"lots":[[],[]],"floor":0.0},"pair_250":{"qty":[0.0,0.0],"cash":0.0,"lots":[[],[]],"floor":0.0},"pair_add_fast":{"qty":[0.0,0.0],"cash":0.0,"lots":[[],[]],"floor":0.0},"pair_add_250":{"qty":[0.0,0.0],"cash":0.0,"lots":[[],[]],"floor":0.0}}}
{"kind":"decision","recorded_ms":1789997510090,"S":1789997400,"age":110,"signal":{},"entry_side":null,"context_gap":"incomplete or stale context","book_errors":[null,null],"books":[{"bid":0.55,"ask":0.56,"asks":[[0.56,62.0]],"received_ms":1789997510089,"observed_ms":1789997510077,"hash":"e15f1b4ff007c0f82ac07a2cbf87cfe5492c62cc"},{"bid":0.44,"ask":0.45,"asks":[[0.45,1172.62]],"received_ms":1789997510084,"observed_ms":1789997510073,"hash":"58fc15a258f867bd428d2dccdaf77172720a378a"}],"intents":{"pair_fast":null,"pair_250":null,"pair_add_fast":null,"pair_add_250":null},"decision_ms":1789997510090,"feature_cutoff_ms":1789997510089,"request_ms":1789997510047,"inventory":{"pair_fast":{"qty":[0.0,0.0],"cash":0.0,"lots":[[],[]],"floor":0.0},"pair_250":{"qty":[0.0,0.0],"cash":0.0,"lots":[[],[]],"floor":0.0},"pair_add_fast":{"qty":[0.0,0.0],"cash":0.0,"lots":[[],[]],"floor":0.0},"pair_add_250":{"qty":[0.0,0.0],"cash":0.0,"lots":[[],[]],"floor":0.0}}}
{"kind":"decision","recorded_ms":1789997520047,"S":1789997400,"age":120,"signal":{},"entry_side":null,"context_gap":"incomplete or stale context","book_errors":[null,null],"books":[{"bid":0.65,"ask":0.66,"asks":[[0.66,348.08]],"received_ms":1789997520046,"observed_ms":1789997520036,"hash":"bd1593d0c4d82d459210f83aa73310997d3f23d8"},{"bid":0.34,"ask":0.35,"asks":[[0.35,395.17]],"received_ms":1789997520040,"observed_ms":1789997520029,"hash":"30288c947f2120642df320be6d46c4912ec9a812"}],"intents":{"pair_fast":null,"pair_250":null,"pair_add_fast":null,"pair_add_250":null},"decision_ms":1789997520047,"feature_cutoff_ms":1789997520046,"request_ms":1789997520013,"inventory":{"pair_fast":{"qty":[0.0,0.0],"cash":0.0,"lots":[[],[]],"floor":0.0},"pair_250":{"qty":[0.0,0.0],"cash":0.0,"lots":[[],[]],"floor":0.0},"pair_add_fast":{"qty":[0.0,0.0],"cash":0.0,"lots":[[],[]],"floor":0.0},"pair_add_250":{"qty":[0.0,0.0],"cash":0.0,"lots":[[],[]],"floor":0.0}}}
{"kind":"decision","recorded_ms":1789997530089,"S":1789997400,"age":130,"signal":{},"entry_side":null,"context_gap":"incomplete or stale context","book_errors":[null,null],"books":[{"bid":0.73,"ask":0.74,"asks":[[0.74,515.0]],"received_ms":1789997530088,"observed_ms":1789997530074,"hash":"ffbc19f7856c98b3454ecadc3db53f662853b4cb"},{"bid":0.26,"ask":0.27,"asks":[[0.27,674.08]],"received_ms":1789997530077,"observed_ms":1789997530064,"hash":"206e1717ed7cc4ec935cb1aa462319c49223ba01"}],"intents":{"pair_fast":null,"pair_250":null,"pair_add_fast":null,"pair_add_250":null},"decision_ms":1789997530089,"feature_cutoff_ms":1789997530088,"request_ms":1789997530042,"inventory":{"pair_fast":{"qty":[0.0,0.0],"cash":0.0,"lots":[[],[]],"floor":0.0},"pair_250":{"qty":[0.0,0.0],"cash":0.0,"lots":[[],[]],"floor":0.0},"pair_add_fast":{"qty":[0.0,0.0],"cash":0.0,"lots":[[],[]],"floor":0.0},"pair_add_250":{"qty":[0.0,0.0],"cash":0.0,"lots":[[],[]],"floor":0.0}}}
{"kind":"decision","recorded_ms":1789997540059,"S":1789997400,"age":140,"signal":{},"entry_side":null,"context_gap":"incomplete or stale context","book_errors":[null,null],"books":[{"bid":0.68,"ask":0.69,"asks":[[0.69,521.52]],"received_ms":1789997540045,"observed_ms":1789997539988,"hash":"414c30b33133ae9689ded83fc92c6b64d87d649f"},{"bid":0.31,"ask":0.32,"asks":[[0.32,794.43]],"received_ms":1789997540058,"observed_ms":1789997539988,"hash":"8c43fb03425d9b1537bf0cbf379c0356993009b5"}],"intents":{"pair_fast":null,"pair_250":null,"pair_add_fast":null,"pair_add_250":null},"decision_ms":1789997540059,"feature_cutoff_ms":1789997540058,"request_ms":1789997540012,"inventory":{"pair_fast":{"qty":[0.0,0.0],"cash":0.0,"lots":[[],[]],"floor":0.0},"pair_250":{"qty":[0.0,0.0],"cash":0.0,"lots":[[],[]],"floor":0.0},"pair_add_fast":{"qty":[0.0,0.0],"cash":0.0,"lots":[[],[]],"floor":0.0},"pair_add_250":{"qty":[0.0,0.0],"cash":0.0,"lots":[[],[]],"floor":0.0}}}
{"kind":"decision","recorded_ms":1789997550082,"S":1789997400,"age":150,"signal":{},"entry_side":null,"context_gap":"incomplete or stale context","book_errors":[null,null],"books":[{"bid":0.61,"ask":0.62,"asks":[[0.62,668.87]],"received_ms":1789997550079,"observed_ms":1789997550069,"hash":"355762fade81a14042256b9ad30b19345a9cd25e"},{"bid":0.38,"ask":0.39,"asks":[[0.39,181.04]],"received_ms":1789997550081,"observed_ms":1789997550071,"hash":"274e16e57fb4622adcf025cfe13db803c9c1ef84"}],"intents":{"pair_fast":null,"pair_250":null,"pair_add_fast":null,"pair_add_250":null},"decision_ms":1789997550082,"feature_cutoff_ms":1789997550081,"request_ms":1789997550048,"inventory":{"pair_fast":{"qty":[0.0,0.0],"cash":0.0,"lots":[[],[]],"floor":0.0},"pair_250":{"qty":[0.0,0.0],"cash":0.0,"lots":[[],[]],"floor":0.0},"pair_add_fast":{"qty":[0.0,0.0],"cash":0.0,"lots":[[],[]],"floor":0.0},"pair_add_250":{"qty":[0.0,0.0],"cash":0.0,"lots":[[],[]],"floor":0.0}}}
{"kind":"decision","recorded_ms":1789997560062,"S":1789997400,"age":160,"signal":{},"entry_side":null,"context_gap":"incomplete or stale context","book_errors":[null,null],"books":[{"bid":0.79,"ask":0.82,"asks":[[0.82,41.0]],"received_ms":1789997560061,"observed_ms":1789997560045,"hash":"d04297b0a462382a4f516da12f231cae65fb4f9c"},{"bid":0.18,"ask":0.21,"asks":[[0.21,43.32]],"received_ms":1789997560050,"observed_ms":1789997560041,"hash":"c5b447013ee8cb2d5afc2d17b333217677cb3cd9"}],"intents":{"pair_fast":null,"pair_250":null,"pair_add_fast":null,"pair_add_250":null},"decision_ms":1789997560062,"feature_cutoff_ms":1789997560061,"request_ms":1789997560005,"inventory":{"pair_fast":{"qty":[0.0,0.0],"cash":0.0,"lots":[[],[]],"floor":0.0},"pair_250":{"qty":[0.0,0.0],"cash":0.0,"lots":[[],[]],"floor":0.0},"pair_add_fast":{"qty":[0.0,0.0],"cash":0.0,"lots":[[],[]],"floor":0.0},"pair_add_250":{"qty":[0.0,0.0],"cash":0.0,"lots":[[],[]],"floor":0.0}}}
{"kind":"decision","recorded_ms":1789997570065,"S":1789997400,"age":170,"signal":{},"entry_side":null,"context_gap":"incomplete or stale context","book_errors":[null,null],"books":[{"bid":0.83,"ask":0.84,"asks":[[0.84,10.0]],"received_ms":1789997570064,"observed_ms":1789997570051,"hash":"47bb47ebc57dbd0dddb5133f71bec8f67934c7a2"},{"bid":0.16,"ask":0.17,"asks":[[0.17,859.71]],"received_ms":1789997570063,"observed_ms":1789997570052,"hash":"c1c01ca1689ef1360ba9d8c714008e649c1d49ad"}],"intents":{"pair_fast":null,"pair_250":null,"pair_add_fast":null,"pair_add_250":null},"decision_ms":1789997570065,"feature_cutoff_ms":1789997570064,"request_ms":1789997570036,"inventory":{"pair_fast":{"qty":[0.0,0.0],"cash":0.0,"lots":[[],[]],"floor":0.0},"pair_250":{"qty":[0.0,0.0],"cash":0.0,"lots":[[],[]],"floor":0.0},"pair_add_fast":{"qty":[0.0,0.0],"cash":0.0,"lots":[[],[]],"floor":0.0},"pair_add_250":{"qty":[0.0,0.0],"cash":0.0,"lots":[[],[]],"floor":0.0}}}
{"kind":"decision","recorded_ms":1789997580085,"S":1789997400,"age":180,"signal":{},"entry_side":null,"context_gap":"incomplete or stale context","book_errors":[null,null],"books":[{"bid":0.81,"ask":0.82,"asks":[[0.82,684.12]],"received_ms":1789997580068,"observed_ms":1789997580056,"hash":"3c96f126b646236909ea32ffbcae6c624481ada0"},{"bid":0.18,"ask":0.19,"asks":[[0.19,15.0]],"received_ms":1789997580084,"observed_ms":1789997580075,"hash":"ea3a2786a79b6ed5fc3fd34047faa1b4d5627798"}],"intents":{"pair_fast":null,"pair_250":null,"pair_add_fast":null,"pair_add_250":null},"decision_ms":1789997580085,"feature_cutoff_ms":1789997580084,"request_ms":1789997580038,"inventory":{"pair_fast":{"qty":[0.0,0.0],"cash":0.0,"lots":[[],[]],"floor":0.0},"pair_250":{"qty":[0.0,0.0],"cash":0.0,"lots":[[],[]],"floor":0.0},"pair_add_fast":{"qty":[0.0,0.0],"cash":0.0,"lots":[[],[]],"floor":0.0},"pair_add_250":{"qty":[0.0,0.0],"cash":0.0,"lots":[[],[]],"floor":0.0}}}
{"kind":"decision","recorded_ms":1789997590062,"S":1789997400,"age":190,"signal":{},"entry_side":null,"context_gap":"incomplete or stale context","book_errors":[null,null],"books":[{"bid":0.75,"ask":0.76,"asks":[[0.76,367.0]],"received_ms":1789997590058,"observed_ms":1789997590041,"hash":"d8261c5c6a658d9217f197e851f0654c88179ed0"},{"bid":0.24,"ask":0.25,"asks":[[0.25,107.09]],"received_ms":1789997590061,"observed_ms":1789997590050,"hash":"55245f79d312c8740e0e9a3aa8823b48613de4b5"}],"intents":{"pair_fast":null,"pair_250":null,"pair_add_fast":null,"pair_add_250":null},"decision_ms":1789997590062,"feature_cutoff_ms":1789997590061,"request_ms":1789997590028,"inventory":{"pair_fast":{"qty":[0.0,0.0],"cash":0.0,"lots":[[],[]],"floor":0.0},"pair_250":{"qty":[0.0,0.0],"cash":0.0,"lots":[[],[]],"floor":0.0},"pair_add_fast":{"qty":[0.0,0.0],"cash":0.0,"lots":[[],[]],"floor":0.0},"pair_add_250":{"qty":[0.0,0.0],"cash":0.0,"lots":[[],[]],"floor":0.0}}}
{"kind":"decision","recorded_ms":1789997600078,"S":1789997400,"age":200,"signal":{},"entry_side":null,"context_gap":"incomplete or stale context","book_errors":[null,null],"books":[{"bid":0.84,"ask":0.86,"asks":[[0.86,884.01]],"received_ms":1789997600062,"observed_ms":1789997600051,"hash":"6015b0bd2a4997ff89d212c54e7eae76c3428951"},{"bid":0.14,"ask":0.16,"asks":[[0.16,108.0]],"received_ms":1789997600077,"observed_ms":1789997600060,"hash":"80e1fa03d72d08233cb9c309ea111ee337e03291"}],"intents":{"pair_fast":null,"pair_250":null,"pair_add_fast":null,"pair_add_250":null},"decision_ms":1789997600078,"feature_cutoff_ms":1789997600077,"request_ms":1789997600035,"inventory":{"pair_fast":{"qty":[0.0,0.0],"cash":0.0,"lots":[[],[]],"floor":0.0},"pair_250":{"qty":[0.0,0.0],"cash":0.0,"lots":[[],[]],"floor":0.0},"pair_add_fast":{"qty":[0.0,0.0],"cash":0.0,"lots":[[],[]],"floor":0.0},"pair_add_250":{"qty":[0.0,0.0],"cash":0.0,"lots":[[],[]],"floor":0.0}}}
{"kind":"decision","recorded_ms":1789997610057,"S":1789997400,"age":210,"signal":{"rsi14":43.8780202324217,"volume_ratio":0.8656090744270605,"taker_buy_fraction":0.2843522103947162,"volume5":338.36287,"return1":4.618296283693997,"return5":2.420843189441092,"return15":-6.798113317801096,"bollinger_z":-0.6036106963608824,"bar_close_ms":1789997579999,"ref":84935.87191029677,"reference_received_ms":1789997401639,"spot":85030.63563281242,"twap":85014.3369015039,"sigma":11.7435949298307,"spot_z":0.8508538155931977,"twap_z":0.7045126065837022,"momentum":0.35782681275258177,"decision_ms":1789997610056,"momentum30":0.06574894057070085,"momentum60":0.6563594420976335,"spot_twap_gap":0.17917487589157016,"range60":0.998674380887839,"final_mean":85030.63563281242,"final_z":1.1418245821276116,"final_up_prob":0.8732365288891839,"final_drift_up_prob":0.9822065438344197,"final_known_seconds":0,"final_sd":82.99324081731807,"final_drift_shift":79.65621429792175},"entry_side":null,"context_gap":null,"book_errors":[null,null],"books":[{"bid":0.88,"ask":0.89,"asks":[[0.89,682.91]],"received_ms":1789997610055,"observed_ms":1789997610041,"hash":"c6996f32f57d9fa06c67c3395857444b1662c340"},{"bid":0.11,"ask":0.12,"asks":[[0.12,10.0]],"received_ms":1789997610054,"observed_ms":1789997610038,"hash":"5f0c9e70dc3c2cd23b6d5e1ebe301c2465b876e5"}],"intents":{"pair_fast":null,"pair_250":null,"pair_add_fast":null,"pair_add_250":null},"decision_ms":1789997610057,"feature_cutoff_ms":1789997610056,"request_ms":1789997610004,"inventory":{"pair_fast":{"qty":[0.0,0.0],"cash":0.0,"lots":[[],[]],"floor":0.0},"pair_250":{"qty":[0.0,0.0],"cash":0.0,"lots":[[],[]],"floor":0.0},"pair_add_fast":{"qty":[0.0,0.0],"cash":0.0,"lots":[[],[]],"floor":0.0},"pair_add_250":{"qty":[0.0,0.0],"cash":0.0,"lots":[[],[]],"floor":0.0}}}
{"kind":"decision","recorded_ms":1789997620072,"S":1789997400,"age":220,"signal":{"rsi14":43.8780202324217,"volume_ratio":0.8656090744270605,"taker_buy_fraction":0.2843522103947162,"volume5":338.36287,"return1":4.618296283693997,"return5":2.420843189441092,"return15":-6.798113317801096,"bollinger_z":-0.6036106963608824,"bar_close_ms":1789997579999,"ref":84935.87191029677,"reference_received_ms":1789997401639,"spot":85008.361699025,"twap":85023.3751506258,"sigma":11.306430150253561,"spot_z":0.7171320633326697,"twap_z":0.865658189744621,"momentum":-0.6229761497129745,"decision_ms":1789997620071,"momentum30":0.4932529524513803,"momentum60":0.06674854950154181,"spot_twap_gap":-0.17142707658754128,"range60":0.8780681361661692,"final_mean":85008.361699025,"final_z":1.0146286321271152,"final_up_prob":0.8448585572139613,"final_drift_up_prob":0.29391535604447894,"final_known_seconds":0,"final_sd":71.44465120825215,"final_drift_shift":-111.21152378630528},"entry_side":null,"context_gap":null,"book_errors":[null,null],"books":[{"bid":0.82,"ask":0.83,"asks":[[0.83,43.43]],"received_ms":1789997620071,"observed_ms":1789997620061,"hash":"5666d33b51100c4ff9c2854b24506ad55bc211fc"},{"bid":0.17,"ask":0.18,"asks":[[0.18,478.0]],"received_ms":1789997620064,"observed_ms":1789997620055,"hash":"abc3c6155bcac391890fb0d7f4622d1384f05dc9"}],"intents":{"pair_fast":null,"pair_250":null,"pair_add_fast":null,"pair_add_250":null},"decision_ms":1789997620072,"feature_cutoff_ms":1789997620071,"request_ms":1789997620030,"inventory":{"pair_fast":{"qty":[0.0,0.0],"cash":0.0,"lots":[[],[]],"floor":0.0},"pair_250":{"qty":[0.0,0.0],"cash":0.0,"lots":[[],[]],"floor":0.0},"pair_add_fast":{"qty":[0.0,0.0],"cash":0.0,"lots":[[],[]],"floor":0.0},"pair_add_250":{"qty":[0.0,0.0],"cash":0.0,"lots":[[],[]],"floor":0.0}}}
{"kind":"decision","recorded_ms":1789997630093,"S":1789997400,"age":230,"signal":{},"entry_side":null,"context_gap":"incomplete or stale context","book_errors":[null,null],"books":[{"bid":0.91,"ask":0.92,"asks":[[0.92,105.0]],"received_ms":1789997630092,"observed_ms":1789997630081,"hash":"df73db4d6195d4a8d040c03dddd2f047d0907079"},{"bid":0.08,"ask":0.09,"asks":[[0.09,263.0]],"received_ms":1789997630082,"observed_ms":1789997630073,"hash":"4e4cbc016190474370802a81293a4bbe848a9d3e"}],"intents":{"pair_fast":null,"pair_250":null,"pair_add_fast":null,"pair_add_250":null},"decision_ms":1789997630093,"feature_cutoff_ms":1789997630092,"request_ms":1789997630046,"inventory":{"pair_fast":{"qty":[0.0,0.0],"cash":0.0,"lots":[[],[]],"floor":0.0},"pair_250":{"qty":[0.0,0.0],"cash":0.0,"lots":[[],[]],"floor":0.0},"pair_add_fast":{"qty":[0.0,0.0],"cash":0.0,"lots":[[],[]],"floor":0.0},"pair_add_250":{"qty":[0.0,0.0],"cash":0.0,"lots":[[],[]],"floor":0.0}}}
{"kind":"decision","recorded_ms":1789997640065,"S":1789997400,"age":240,"signal":{"rsi14":43.8780202324217,"volume_ratio":0.8656090744270605,"taker_buy_fraction":0.2843522103947162,"volume5":338.36287,"return1":4.618296283693997,"return5":2.420843189441092,"return15":-6.798113317801096,"bollinger_z":-0.6036106963608824,"bar_close_ms":1789997579999,"ref":84935.87191029677,"reference_received_ms":1789997401639,"spot":84995.46319291089,"twap":85012.82068101002,"sigma":10.010007313952322,"spot_z":0.7689612587228046,"twap_z":0.9929409301020676,"momentum":-0.3144019119334023,"decision_ms":1789997640064,"momentum30":-0.6415159727111104,"momentum60":-0.39907711772213483,"spot_twap_gap":-0.22386018388567203,"range60":0.69323459176424,"final_mean":84995.46319291089,"final_z":1.3333021557101867,"final_up_prob":0.9087836667235476,"final_drift_up_prob":0.747521555226213,"final_known_seconds":0,"final_sd":44.69450706195884,"final_drift_shift":-29.792972800247373},"entry_side":null,"context_gap":null,"book_errors":[null,null],"books":[{"bid":0.9,"ask":0.91,"asks":[[0.91,234.77]],"received_ms":1789997640047,"observed_ms":1789997640038,"hash":"e17d368bb33270496fb4941ce4d4da121394c8ed"},{"bid":0.09,"ask":0.1,"asks":[[0.1,150.0]],"received_ms":1789997640063,"observed_ms":1789997640048,"hash":"268f7f6d2a365c4a9963c623ba0650084b8034eb"}],"intents":{"pair_fast":null,"pair_250":null,"pair_add_fast":null,"pair_add_250":null},"decision_ms":1789997640065,"feature_cutoff_ms":1789997640064,"request_ms":1789997640019,"inventory":{"pair_fast":{"qty":[0.0,0.0],"cash":0.0,"lots":[[],[]],"floor":0.0},"pair_250":{"qty":[0.0,0.0],"cash":0.0,"lots":[[],[]],"floor":0.0},"pair_add_fast":{"qty":[0.0,0.0],"cash":0.0,"lots":[[],[]],"floor":0.0},"pair_add_250":{"qty":[0.0,0.0],"cash":0.0,"lots":[[],[]],"floor":0.0}}}
{"kind":"decision","recorded_ms":1789997650041,"S":1789997400,"age":250,"signal":{"rsi14":34.32706749806611,"volume_ratio":1.0527951771025164,"taker_buy_fraction":0.4417022098729728,"volume5":217.59667,"return1":-2.360261799720489,"return5":5.6013587205152096,"return15":-9.24935677867826,"bollinger_z":-0.8153772338199392,"bar_close_ms":1789997639999,"ref":84935.87191029677,"reference_received_ms":1789997401639,"spot":85024.36483815333,"twap":85009.08837116703,"sigma":7.7703120481899015,"spot_z":1.6112350075470026,"twap_z":1.333088730820187,"momentum":1.1762079376666879,"decision_ms":1789997650040,"momentum30":0.37601579949931907,"momentum60":0.7733899744723265,"spot_twap_gap":0.253810065198056,"range60":0.8775757657745086,"final_mean":85022.15121272128,"final_z":3.2677317499760585,"final_up_prob":0.9994579346653967,"final_drift_up_prob":0.9999999852633799,"final_known_seconds":10,"final_sd":26.40342262645518,"final_drift_shift":60.11546073160513},"entry_side":null,"context_gap":null,"book_errors":[null,null],"books":[{"bid":0.98,"ask":0.99,"asks":[[0.99,2658.52]],"received_ms":1789997650039,"observed_ms":1789997650027,"hash":"3ada29de13166dfd76cad3ec97b2fde4cd665f2b"},{"bid":0.01,"ask":0.02,"asks":[[0.02,565.4]],"received_ms":1789997650037,"observed_ms":1789997650027,"hash":"0686134afa47bd0ef40be27b75a2e51a56863d0d"}],"intents":{"pair_fast":null,"pair_250":null,"pair_add_fast":null,"pair_add_250":null},"decision_ms":1789997650041,"feature_cutoff_ms":1789997650040,"request_ms":1789997650008,"inventory":{"pair_fast":{"qty":[0.0,0.0],"cash":0.0,"lots":[[],[]],"floor":0.0},"pair_250":{"qty":[0.0,0.0],"cash":0.0,"lots":[[],[]],"floor":0.0},"pair_add_fast":{"qty":[0.0,0.0],"cash":0.0,"lots":[[],[]],"floor":0.0},"pair_add_250":{"qty":[0.0,0.0],"cash":0.0,"lots":[[],[]],"floor":0.0}}}
{"kind":"decision","recorded_ms":1789997660070,"S":1789997400,"age":260,"signal":{},"entry_side":null,"context_gap":"two-sided entry context unavailable","book_errors":["empty/invalid public book",null],"books":[null,{"bid":null,"ask":0.01,"asks":[[0.01,31619.93]],"received_ms":1789997660056,"observed_ms":1789997660026,"hash":"decbdf1e362ed8e8c678e6e7bdd3c5f4b7962469"}],"intents":{"pair_fast":null,"pair_250":null,"pair_add_fast":null,"pair_add_250":null},"decision_ms":1789997660070,"feature_cutoff_ms":1789997660070,"request_ms":1789997660014,"inventory":{"pair_fast":{"qty":[0.0,0.0],"cash":0.0,"lots":[[],[]],"floor":0.0},"pair_250":{"qty":[0.0,0.0],"cash":0.0,"lots":[[],[]],"floor":0.0},"pair_add_fast":{"qty":[0.0,0.0],"cash":0.0,"lots":[[],[]],"floor":0.0},"pair_add_250":{"qty":[0.0,0.0],"cash":0.0,"lots":[[],[]],"floor":0.0}}}
{"kind":"decision","recorded_ms":1789997670087,"S":1789997400,"age":270,"signal":{},"entry_side":null,"context_gap":"two-sided entry context unavailable","book_errors":["empty/invalid public book",null],"books":[null,{"bid":null,"ask":0.01,"asks":[[0.01,36578.46]],"received_ms":1789997670070,"observed_ms":1789997670060,"hash":"e140eb45e1d05c11b4fa3f4dafc1a673ed01cc4c"}],"intents":{"pair_fast":null,"pair_250":null,"pair_add_fast":null,"pair_add_250":null},"decision_ms":1789997670087,"feature_cutoff_ms":1789997670087,"request_ms":1789997670044,"inventory":{"pair_fast":{"qty":[0.0,0.0],"cash":0.0,"lots":[[],[]],"floor":0.0},"pair_250":{"qty":[0.0,0.0],"cash":0.0,"lots":[[],[]],"floor":0.0},"pair_add_fast":{"qty":[0.0,0.0],"cash":0.0,"lots":[[],[]],"floor":0.0},"pair_add_250":{"qty":[0.0,0.0],"cash":0.0,"lots":[[],[]],"floor":0.0}}}
{"kind":"decision","recorded_ms":1789997680055,"S":1789997400,"age":280,"signal":{},"entry_side":null,"context_gap":"two-sided entry context unavailable","book_errors":["empty/invalid public book",null],"books":[null,{"bid":null,"ask":0.01,"asks":[[0.01,53208.76]],"received_ms":1789997680055,"observed_ms":1789997680042,"hash":"2aefe92ade39d75c1b5368fa5acd4756251c3f8d"}],"intents":{"pair_fast":null,"pair_250":null,"pair_add_fast":null,"pair_add_250":null},"decision_ms":1789997680055,"feature_cutoff_ms":1789997680055,"request_ms":1789997680013,"inventory":{"pair_fast":{"qty":[0.0,0.0],"cash":0.0,"lots":[[],[]],"floor":0.0},"pair_250":{"qty":[0.0,0.0],"cash":0.0,"lots":[[],[]],"floor":0.0},"pair_add_fast":{"qty":[0.0,0.0],"cash":0.0,"lots":[[],[]],"floor":0.0},"pair_add_250":{"qty":[0.0,0.0],"cash":0.0,"lots":[[],[]],"floor":0.0}}}
{"kind":"decision","recorded_ms":1789997690058,"S":1789997400,"age":290,"signal":{},"entry_side":null,"context_gap":"two-sided entry context unavailable","book_errors":["empty/invalid public book",null],"books":[null,{"bid":null,"ask":0.01,"asks":[[0.01,54619.57]],"received_ms":1789997690058,"observed_ms":1789997690045,"hash":"0558a7daeb5ab1aa6ce18e9a81a1e80330557c45"}],"intents":{"pair_fast":null,"pair_250":null,"pair_add_fast":null,"pair_add_250":null},"decision_ms":1789997690058,"feature_cutoff_ms":1789997690058,"request_ms":1789997690027,"inventory":{"pair_fast":{"qty":[0.0,0.0],"cash":0.0,"lots":[[],[]],"floor":0.0},"pair_250":{"qty":[0.0,0.0],"cash":0.0,"lots":[[],[]],"floor":0.0},"pair_add_fast":{"qty":[0.0,0.0],"cash":0.0,"lots":[[],[]],"floor":0.0},"pair_add_250":{"qty":[0.0,0.0],"cash":0.0,"lots":[[],[]],"floor":0.0}}}
{"kind":"decision","recorded_ms":1789997730044,"S":1789997700,"age":30,"signal":{},"entry_side":null,"context_gap":"incomplete or stale context","book_errors":[null,null],"books":[{"bid":0.57,"ask":0.58,"asks":[[0.58,68.59]],"received_ms":1789997730040,"observed_ms":1789997730001,"hash":"a61f1066dfa6c225066d2d17a3b742284c30259d"},{"bid":0.42,"ask":0.43,"asks":[[0.43,1136.74]],"received_ms":1789997730043,"observed_ms":1789997730001,"hash":"5418375897d9a105d29942cc9d9223004f4ee5bf"}],"intents":{"pair_fast":null,"pair_250":null,"pair_add_fast":null,"pair_add_250":null},"decision_ms":1789997730044,"feature_cutoff_ms":1789997730043,"request_ms":1789997730008,"inventory":{"pair_fast":{"qty":[0.0,0.0],"cash":0.0,"lots":[[],[]],"floor":0.0},"pair_250":{"qty":[0.0,0.0],"cash":0.0,"lots":[[],[]],"floor":0.0},"pair_add_fast":{"qty":[0.0,0.0],"cash":0.0,"lots":[[],[]],"floor":0.0},"pair_add_250":{"qty":[0.0,0.0],"cash":0.0,"lots":[[],[]],"floor":0.0}}}
{"kind":"decision","recorded_ms":1789997740047,"S":1789997700,"age":40,"signal":{"rsi14":49.7740830950618,"volume_ratio":0.8728896401236882,"taker_buy_fraction":0.463159070712759,"volume5":199.87878,"return1":15.402027919976884,"return5":25.50604943796174,"return15":-0.7714517300764879,"bollinger_z":1.2166744742466873,"bar_close_ms":1789997699999,"ref":85042.04733770393,"reference_received_ms":1789997701631,"spot":85097.26333404476,"twap":85110.63854746365,"sigma":14.393780006161503,"spot_z":0.23792594354652571,"twap_z":0.29555979032492014,"momentum":0.09603929194652228,"decision_ms":1789997740046,"momentum30":-1.1997160066149435,"momentum60":0.6198946667973654,"spot_twap_gap":-0.11996380566497256,"range60":1.4942605445203847,"final_mean":85097.26333404476,"final_z":0.25865693102978987,"final_up_prob":0.6020500235393624,"final_drift_up_prob":0.7671679122278817,"final_known_seconds":0,"final_sd":213.47193798752159,"final_drift_shift":100.52284665018158},"entry_side":null,"context_gap":null,"book_errors":[null,null],"books":[{"bid":0.73,"ask":0.74,"asks":[[0.74,1956.2]],"received_ms":1789997740043,"observed_ms":1789997740035,"hash":"d49fdebf33b2487908362669f36848be1b8718b0"},{"bid":0.26,"ask":0.27,"asks":[[0.27,110.64]],"received_ms":1789997740046,"observed_ms":1789997740039,"hash":"e5cc1073fd263336ff0c2d1a2b032693a68e9aff"}],"intents":{"pair_fast":null,"pair_250":null,"pair_add_fast":null,"pair_add_250":null},"decision_ms":1789997740047,"feature_cutoff_ms":1789997740046,"request_ms":1789997740018,"inventory":{"pair_fast":{"qty":[0.0,0.0],"cash":0.0,"lots":[[],[]],"floor":0.0},"pair_250":{"qty":[0.0,0.0],"cash":0.0,"lots":[[],[]],"floor":0.0},"pair_add_fast":{"qty":[0.0,0.0],"cash":0.0,"lots":[[],[]],"floor":0.0},"pair_add_250":{"qty":[0.0,0.0],"cash":0.0,"lots":[[],[]],"floor":0.0}}}
{"kind":"decision","recorded_ms":1789997750053,"S":1789997700,"age":50,"signal":{"rsi14":49.7740830950618,"volume_ratio":0.8728896401236882,"taker_buy_fraction":0.463159070712759,"volume5":199.87878,"return1":15.402027919976884,"return5":25.50604943796174,"return15":-0.7714517300764879,"bollinger_z":1.2166744742466873,"bar_close_ms":1789997699999,"ref":85042.04733770393,"reference_received_ms":1789997701631,"spot":85156.68219273,"twap":85127.12457697596,"sigma":15.465758225804587,"spot_z":0.46883565939793503,"twap_z":0.3479503992462259,"momentum":1.2149351274580662,"decision_ms":1789997750052,"momentum30":0.09863354178325655,"momentum60":0.7359809856200838,"spot_twap_gap":0.24673034001446859,"range60":1.1128120973002575,"final_mean":85156.68219273,"final_z":0.511551778120783,"final_up_prob":0.6955176291196735,"final_drift_up_prob":0.9999999998877336,"final_known_seconds":0,"final_sd":224.09237916676167,"final_drift_shift":1306.9059127381117},"entry_side":null,"context_gap":null,"book_errors":[null,null],"books":[{"bid":0.73,"ask":0.74,"asks":[[0.74,18.0]],"received_ms":1789997750045,"observed_ms":1789997750036,"hash":"90df08ee7d04f534b5762667dd775c995845f755"},{"bid":0.26,"ask":0.27,"asks":[[0.27,1265.3]],"received_ms":1789997750051,"observed_ms":1789997750038,"hash":"cf7f6c9eb3795aa66e7642ec266cff09d02ab0f1"}],"intents":{"pair_fast":null,"pair_250":null,"pair_add_fast":null,"pair_add_250":null},"decision_ms":1789997750053,"feature_cutoff_ms":1789997750052,"request_ms":1789997750020,"inventory":{"pair_fast":{"qty":[0.0,0.0],"cash":0.0,"lots":[[],[]],"floor":0.0},"pair_250":{"qty":[0.0,0.0],"cash":0.0,"lots":[[],[]],"floor":0.0},"pair_add_fast":{"qty":[0.0,0.0],"cash":0.0,"lots":[[],[]],"floor":0.0},"pair_add_250":{"qty":[0.0,0.0],"cash":0.0,"lots":[[],[]],"floor":0.0}}}
{"kind":"decision","recorded_ms":1789997760057,"S":1789997700,"age":60,"signal":{},"entry_side":null,"context_gap":"incomplete or stale context","book_errors":[null,null],"books":[{"bid":0.79,"ask":0.8,"asks":[[0.8,543.74]],"received_ms":1789997760050,"observed_ms":1789997759778,"hash":"f1579dca9f840a282596a9bd3dbf75aa11bf9c07"},{"bid":0.2,"ask":0.21,"asks":[[0.21,500.07]],"received_ms":1789997760056,"observed_ms":1789997759778,"hash":"96d17b703ff48bcf6eb073a30daacdc2a29b4a65"}],"intents":{"pair_fast":null,"pair_250":null,"pair_add_fast":null,"pair_add_250":null},"decision_ms":1789997760057,"feature_cutoff_ms":1789997760056,"request_ms":1789997760026,"inventory":{"pair_fast":{"qty":[0.0,0.0],"cash":0.0,"lots":[[],[]],"floor":0.0},"pair_250":{"qty":[0.0,0.0],"cash":0.0,"lots":[[],[]],"floor":0.0},"pair_add_fast":{"qty":[0.0,0.0],"cash":0.0,"lots":[[],[]],"floor":0.0},"pair_add_250":{"qty":[0.0,0.0],"cash":0.0,"lots":[[],[]],"floor":0.0}}}
{"kind":"decision","recorded_ms":1789997770051,"S":1789997700,"age":70,"signal":{},"entry_side":null,"context_gap":"incomplete or stale context","book_errors":[null,null],"books":[{"bid":0.78,"ask":0.79,"asks":[[0.79,1714.16]],"received_ms":1789997770050,"observed_ms":1789997770033,"hash":"b0dda857be62df139cf16d00c8ed598de5529f3e"},{"bid":0.21,"ask":0.22,"asks":[[0.22,211.12]],"received_ms":1789997770042,"observed_ms":1789997770033,"hash":"2ea4a3a62f00ed2289fedb297fbe6fdb315d6879"}],"intents":{"pair_fast":null,"pair_250":null,"pair_add_fast":null,"pair_add_250":null},"decision_ms":1789997770051,"feature_cutoff_ms":1789997770050,"request_ms":1789997770008,"inventory":{"pair_fast":{"qty":[0.0,0.0],"cash":0.0,"lots":[[],[]],"floor":0.0},"pair_250":{"qty":[0.0,0.0],"cash":0.0,"lots":[[],[]],"floor":0.0},"pair_add_fast":{"qty":[0.0,0.0],"cash":0.0,"lots":[[],[]],"floor":0.0},"pair_add_250":{"qty":[0.0,0.0],"cash":0.0,"lots":[[],[]],"floor":0.0}}}
{"kind":"decision","recorded_ms":1789997780055,"S":1789997700,"age":80,"signal":{},"entry_side":null,"context_gap":"incomplete or stale context","book_errors":[null,null],"books":[{"bid":0.66,"ask":0.67,"asks":[[0.67,174.0]],"received_ms":1789997780053,"observed_ms":1789997779632,"hash":"500bbb937bb5e1447e66f636f9ce653b439536c3"},{"bid":0.33,"ask":0.34,"asks":[[0.34,80.0]],"received_ms":1789997780054,"observed_ms":1789997779632,"hash":"e6a041c6d1c9e413b878f7cfb7ee84611b072c65"}],"intents":{"pair_fast":null,"pair_250":null,"pair_add_fast":null,"pair_add_250":null},"decision_ms":1789997780055,"feature_cutoff_ms":1789997780054,"request_ms":1789997780022,"inventory":{"pair_fast":{"qty":[0.0,0.0],"cash":0.0,"lots":[[],[]],"floor":0.0},"pair_250":{"qty":[0.0,0.0],"cash":0.0,"lots":[[],[]],"floor":0.0},"pair_add_fast":{"qty":[0.0,0.0],"cash":0.0,"lots":[[],[]],"floor":0.0},"pair_add_250":{"qty":[0.0,0.0],"cash":0.0,"lots":[[],[]],"floor":0.0}}}
{"kind":"decision","recorded_ms":1789997790065,"S":1789997700,"age":90,"signal":{},"entry_side":null,"context_gap":"incomplete or stale context","book_errors":[null,null],"books":[{"bid":0.52,"ask":0.54,"asks":[[0.54,1560.24]],"received_ms":1789997790062,"observed_ms":1789997790051,"hash":"e3080289eb6fbd9c0502e0a74e90d9f6da4e108a"},{"bid":0.46,"ask":0.48,"asks":[[0.48,167.0]],"received_ms":1789997790064,"observed_ms":1789997790055,"hash":"3cff7ea934cca9996a12866a9b1dc94d86049413"}],"intents":{"pair_fast":null,"pair_250":null,"pair_add_fast":null,"pair_add_250":null},"decision_ms":1789997790065,"feature_cutoff_ms":1789997790064,"request_ms":1789997790028,"inventory":{"pair_fast":{"qty":[0.0,0.0],"cash":0.0,"lots":[[],[]],"floor":0.0},"pair_250":{"qty":[0.0,0.0],"cash":0.0,"lots":[[],[]],"floor":0.0},"pair_add_fast":{"qty":[0.0,0.0],"cash":0.0,"lots":[[],[]],"floor":0.0},"pair_add_250":{"qty":[0.0,0.0],"cash":0.0,"lots":[[],[]],"floor":0.0}}}
{"kind":"decision","recorded_ms":1789997800072,"S":1789997700,"age":100,"signal":{},"entry_side":null,"context_gap":"incomplete or stale context","book_errors":[null,null],"books":[{"bid":0.31,"ask":0.32,"asks":[[0.32,279.01]],"received_ms":1789997800065,"observed_ms":1789997799833,"hash":"949972d95ce3a03d3132865c958aaf743f102eae"},{"bid":0.68,"ask":0.69,"asks":[[0.69,394.13]],"received_ms":1789997800071,"observed_ms":1789997799833,"hash":"33ffbabb513e69ed021dedea17c41a34bc9df429"}],"intents":{"pair_fast":null,"pair_250":null,"pair_add_fast":null,"pair_add_250":null},"decision_ms":1789997800072,"feature_cutoff_ms":1789997800071,"request_ms":1789997800039,"inventory":{"pair_fast":{"qty":[0.0,0.0],"cash":0.0,"lots":[[],[]],"floor":0.0},"pair_250":{"qty":[0.0,0.0],"cash":0.0,"lots":[[],[]],"floor":0.0},"pair_add_fast":{"qty":[0.0,0.0],"cash":0.0,"lots":[[],[]],"floor":0.0},"pair_add_250":{"qty":[0.0,0.0],"cash":0.0,"lots":[[],[]],"floor":0.0}}}
{"kind":"decision","recorded_ms":1789997810082,"S":1789997700,"age":110,"signal":{},"entry_side":null,"context_gap":"incomplete or stale context","book_errors":[null,null],"books":[{"bid":0.39,"ask":0.4,"asks":[[0.4,110.0]],"received_ms":1789997810071,"observed_ms":1789997810063,"hash":"eed8fbb5444ef39be8debdef12a9179ad9e8237f"},{"bid":0.6,"ask":0.61,"asks":[[0.61,50.1]],"received_ms":1789997810081,"observed_ms":1789997810071,"hash":"e9d827b141a96c0959ae3c8ac96a803dacb31ce9"}],"intents":{"pair_fast":null,"pair_250":null,"pair_add_fast":null,"pair_add_250":null},"decision_ms":1789997810082,"feature_cutoff_ms":1789997810081,"request_ms":1789997810045,"inventory":{"pair_fast":{"qty":[0.0,0.0],"cash":0.0,"lots":[[],[]],"floor":0.0},"pair_250":{"qty":[0.0,0.0],"cash":0.0,"lots":[[],[]],"floor":0.0},"pair_add_fast":{"qty":[0.0,0.0],"cash":0.0,"lots":[[],[]],"floor":0.0},"pair_add_250":{"qty":[0.0,0.0],"cash":0.0,"lots":[[],[]],"floor":0.0}}}
{"kind":"decision","recorded_ms":1789997820051,"S":1789997700,"age":120,"signal":{},"entry_side":null,"context_gap":"incomplete or stale context","book_errors":[null,null],"books":[{"bid":0.34,"ask":0.35,"asks":[[0.35,97.0]],"received_ms":1789997820034,"observed_ms":1789997820027,"hash":"f922e0a1bb7eb5243abe4e07cf7000cc9b93f758"},{"bid":0.65,"ask":0.66,"asks":[[0.66,452.19]],"received_ms":1789997820049,"observed_ms":1789997820035,"hash":"1613623db4a7250674fef6c632f9a7808fce59b9"}],"intents":{"pair_fast":null,"pair_250":null,"pair_add_fast":null,"pair_add_250":null},"decision_ms":1789997820051,"feature_cutoff_ms":1789997820050,"request_ms":1789997820005,"inventory":{"pair_fast":{"qty":[0.0,0.0],"cash":0.0,"lots":[[],[]],"floor":0.0},"pair_250":{"qty":[0.0,0.0],"cash":0.0,"lots":[[],[]],"floor":0.0},"pair_add_fast":{"qty":[0.0,0.0],"cash":0.0,"lots":[[],[]],"floor":0.0},"pair_add_250":{"qty":[0.0,0.0],"cash":0.0,"lots":[[],[]],"floor":0.0}}}
{"kind":"decision","recorded_ms":1789997830086,"S":1789997700,"age":130,"signal":{"rsi14":40.75636105728401,"volume_ratio":1.246176810659534,"taker_buy_fraction":0.472591353452005,"volume5":196.28897,"return1":-23.69286908281194,"return5":-0.5917041432228508,"return15":-19.313317342814038,"bollinger_z":-1.0567249572324027,"bar_close_ms":1789997819999,"ref":85042.04733770393,"reference_received_ms":1789997701631,"spot":84923.59993187651,"twap":85042.47632523061,"sigma":14.21645728899216,"spot_z":-0.6391728348776433,"twap_z":0.0023149276393381944,"momentum":-1.390665312491842,"decision_ms":1789997830085,"momentum30":-1.2217874422247894,"momentum60":-2.009182641435338,"spot_twap_gap":-1.0795148241658965,"range60":2.009182641435338,"final_mean":84923.59993187651,"final_z":-0.730978359785736,"final_up_prob":0.232396185533906,"final_drift_up_prob":4.4138470656207573e-10,"final_known_seconds":0,"final_sd":162.03955184410674,"final_drift_shift":-874.738584236852},"entry_side":null,"context_gap":null,"book_errors":[null,null],"books":[{"bid":0.16,"ask":0.17,"asks":[[0.17,915.86]],"received_ms":1789997830085,"observed_ms":1789997830069,"hash":"ac2b6208dec39e2c0b71b30c5cc9ea76e85f476a"},{"bid":0.83,"ask":0.84,"asks":[[0.84,226.44]],"received_ms":1789997830084,"observed_ms":1789997830069,"hash":"0f7731c33ea72e0aba345cb6fbd7c4a4bd4a1196"}],"intents":{"pair_fast":null,"pair_250":null,"pair_add_fast":null,"pair_add_250":null},"decision_ms":1789997830086,"feature_cutoff_ms":1789997830085,"request_ms":1789997830050,"inventory":{"pair_fast":{"qty":[0.0,0.0],"cash":0.0,"lots":[[],[]],"floor":0.0},"pair_250":{"qty":[0.0,0.0],"cash":0.0,"lots":[[],[]],"floor":0.0},"pair_add_fast":{"qty":[0.0,0.0],"cash":0.0,"lots":[[],[]],"floor":0.0},"pair_add_250":{"qty":[0.0,0.0],"cash":0.0,"lots":[[],[]],"floor":0.0}}}
{"kind":"decision","recorded_ms":1789997840050,"S":1789997700,"age":140,"signal":{"rsi14":40.75636105728401,"volume_ratio":1.246176810659534,"taker_buy_fraction":0.472591353452005,"volume5":196.28897,"return1":-23.69286908281194,"return5":-0.5917041432228508,"return15":-19.313317342814038,"bollinger_z":-1.0567249572324027,"bar_close_ms":1789997819999,"ref":85042.04733770393,"reference_received_ms":1789997701631,"spot":84942.14443530579,"twap":85004.59716517157,"sigma":14.191431094696096,"spot_z":-0.5566195206626557,"twap_z":-0.20865757233581728,"momentum":0.4132273096491416,"decision_ms":1789997840049,"momentum30":-0.15600213107051175,"momentum60":-1.5811389051786162,"spot_twap_gap":-0.5681324668887622,"range60":1.8074502183524113,"final_mean":84942.14443530579,"final_z":-0.6427616787137809,"final_up_prob":0.260189376176274,"final_drift_up_prob":0.8179869753395872,"final_known_seconds":0,"final_sd":155.42759580511392,"final_drift_shift":240.98767646783946},"entry_side":null,"context_gap":null,"book_errors":[null,null],"books":[{"bid":0.2,"ask":0.21,"asks":[[0.21,138.51]],"received_ms":1789997840049,"observed_ms":1789997840036,"hash":"619ef72905b91a6319cdfdecd3af11cd6530ef50"},{"bid":0.79,"ask":0.8,"asks":[[0.8,1206.05]],"received_ms":1789997840038,"observed_ms":1789997840030,"hash":"9928a8453d9fbccb92f1d4b717f52a8b7742e640"}],"intents":{"pair_fast":null,"pair_250":null,"pair_add_fast":null,"pair_add_250":null},"decision_ms":1789997840050,"feature_cutoff_ms":1789997840049,"request_ms":1789997840009,"inventory":{"pair_fast":{"qty":[0.0,0.0],"cash":0.0,"lots":[[],[]],"floor":0.0},"pair_250":{"qty":[0.0,0.0],"cash":0.0,"lots":[[],[]],"floor":0.0},"pair_add_fast":{"qty":[0.0,0.0],"cash":0.0,"lots":[[],[]],"floor":0.0},"pair_add_250":{"qty":[0.0,0.0],"cash":0.0,"lots":[[],[]],"floor":0.0}}}
{"kind":"decision","recorded_ms":1789997850069,"S":1789997700,"age":150,"signal":{"rsi14":40.75636105728401,"volume_ratio":1.246176810659534,"taker_buy_fraction":0.472591353452005,"volume5":196.28897,"return1":-23.69286908281194,"return5":-0.5917041432228508,"return15":-19.313317342814038,"bollinger_z":-1.0567249572324027,"bar_close_ms":1789997819999,"ref":85042.04733770393,"reference_received_ms":1789997701631,"spot":84923.434,"twap":84975.07060895552,"sigma":14.351719572437077,"spot_z":-0.6749668133105223,"twap_z":-0.38112972827826946,"momentum":-0.4122683089012822,"decision_ms":1789997850068,"momentum30":-0.7974446885575031,"momentum60":-1.1076888367925004,"spot_twap_gap":-0.4644919041001154,"range60":1.3487758555878602,"final_mean":84923.434,"final_z":-0.7882564309207498,"final_up_prob":0.21527336346942982,"final_drift_up_prob":0.011318233548979595,"final_known_seconds":0,"final_sd":150.4755724801211,"final_drift_shift":-224.39799256314038},"entry_side":null,"context_gap":null,"book_errors":[null,null],"books":[{"bid":0.17,"ask":0.18,"asks":[[0.18,4.44],[0.19,161.25]],"received_ms":1789997850059,"observed_ms":1789997850048,"hash":"04410d0f7d5ca651c8e3c1926db945e87e528bbd"},{"bid":0.82,"ask":0.83,"asks":[[0.83,955.38]],"received_ms":1789997850068,"observed_ms":1789997850053,"hash":"89b424a9c1ee0fa00a01b3be72e628783f859f5b"}],"intents":{"pair_fast":null,"pair_250":null,"pair_add_fast":null,"pair_add_250":null},"decision_ms":1789997850069,"feature_cutoff_ms":1789997850068,"request_ms":1789997850022,"inventory":{"pair_fast":{"qty":[0.0,0.0],"cash":0.0,"lots":[[],[]],"floor":0.0},"pair_250":{"qty":[0.0,0.0],"cash":0.0,"lots":[[],[]],"floor":0.0},"pair_add_fast":{"qty":[0.0,0.0],"cash":0.0,"lots":[[],[]],"floor":0.0},"pair_add_250":{"qty":[0.0,0.0],"cash":0.0,"lots":[[],[]],"floor":0.0}}}
{"kind":"decision","recorded_ms":1789997860076,"S":1789997700,"age":160,"signal":{"rsi14":40.75636105728401,"volume_ratio":1.246176810659534,"taker_buy_fraction":0.472591353452005,"volume5":196.28897,"return1":-23.69286908281194,"return5":-0.5917041432228508,"return15":-19.313317342814038,"bollinger_z":-1.0567249572324027,"bar_close_ms":1789997819999,"ref":85042.04733770393,"reference_received_ms":1789997701631,"spot":84966.56992282583,"twap":84956.19381587477,"sigma":14.538650717077873,"spot_z":-0.4388794604374657,"twap_z":-0.4992135382205991,"momentum":0.9382422602852678,"decision_ms":1789997860075,"momentum30":0.539610674028821,"momentum60":-0.46322603127841694,"spot_twap_gap":0.09213713661598338,"range60":1.0842490651852217,"final_mean":84966.56992282583,"final_z":-0.519344857559415,"final_up_prob":0.30176013866040996,"final_drift_up_prob":0.9969590645218426,"final_known_seconds":0,"final_sd":145.33197696958985,"final_drift_shift":474.17163145732553},"entry_side":null,"context_gap":null,"book_errors":[null,null],"books":[{"bid":0.21,"ask":0.22,"asks":[[0.22,740.39]],"received_ms":1789997860075,"observed_ms":1789997860066,"hash":"9a583d3402d8056b69d4a3f1ee88026473939365"},{"bid":0.78,"ask":0.79,"asks":[[0.79,60.7]],"received_ms":1789997860073,"observed_ms":1789997860060,"hash":"988220be86d60526c7eccbfbba3d2feb494911e9"}],"intents":{"pair_fast":null,"pair_250":null,"pair_add_fast":null,"pair_add_250":null},"decision_ms":1789997860076,"feature_cutoff_ms":1789997860075,"request_ms":1789997860044,"inventory":{"pair_fast":{"qty":[0.0,0.0],"cash":0.0,"lots":[[],[]],"floor":0.0},"pair_250":{"qty":[0.0,0.0],"cash":0.0,"lots":[[],[]],"floor":0.0},"pair_add_fast":{"qty":[0.0,0.0],"cash":0.0,"lots":[[],[]],"floor":0.0},"pair_add_250":{"qty":[0.0,0.0],"cash":0.0,"lots":[[],[]],"floor":0.0}}}
{"kind":"decision","recorded_ms":1789997870075,"S":1789997700,"age":170,"signal":{"rsi14":40.75636105728401,"volume_ratio":1.246176810659534,"taker_buy_fraction":0.472591353452005,"volume5":196.28897,"return1":-23.69286908281194,"return5":-0.5917041432228508,"return15":-19.313317342814038,"bollinger_z":-1.0567249572324027,"bar_close_ms":1789997819999,"ref":85042.04733770393,"reference_received_ms":1789997701631,"spot":84937.86327894374,"twap":84948.2239555074,"sigma":14.164873801036878,"spot_z":-0.6452685949266023,"twap_z":-0.5810992844938662,"momentum":-0.6408696605549786,"decision_ms":1789997870074,"momentum30":-0.05518076957215359,"momentum60":-0.14953567830810077,"spot_twap_gap":-0.09442778041453236,"range60":0.9796852885709937,"final_mean":84937.86327894374,"final_z":-0.77561450900866,"final_up_prob":0.21898831550397047,"final_drift_up_prob":0.001800539940522261,"final_known_seconds":0,"final_sd":134.32453564252202,"final_drift_shift":-286.85400999565627},"entry_side":null,"context_gap":null,"book_errors":[null,null],"books":[{"bid":0.24,"ask":0.25,"asks":[[0.25,386.51]],"received_ms":1789997870071,"observed_ms":1789997870064,"hash":"7182779f83d8cba6d8435748398049f44bc71d4a"},{"bid":0.75,"ask":0.76,"asks":[[0.76,26.84]],"received_ms":1789997870074,"observed_ms":1789997870064,"hash":"463686d893ffd32b2c663a0b40b613d6b85a2f58"}],"intents":{"pair_fast":null,"pair_250":null,"pair_add_fast":null,"pair_add_250":null},"decision_ms":1789997870075,"feature_cutoff_ms":1789997870074,"request_ms":1789997870048,"inventory":{"pair_fast":{"qty":[0.0,0.0],"cash":0.0,"lots":[[],[]],"floor":0.0},"pair_250":{"qty":[0.0,0.0],"cash":0.0,"lots":[[],[]],"floor":0.0},"pair_add_fast":{"qty":[0.0,0.0],"cash":0.0,"lots":[[],[]],"floor":0.0},"pair_add_250":{"qty":[0.0,0.0],"cash":0.0,"lots":[[],[]],"floor":0.0}}}
{"kind":"decision","recorded_ms":1789997880082,"S":1789997700,"age":180,"signal":{"rsi14":40.75636105728401,"volume_ratio":1.246176810659534,"taker_buy_fraction":0.472591353452005,"volume5":196.28897,"return1":-23.69286908281194,"return5":-0.5917041432228508,"return15":-19.313317342814038,"bollinger_z":-1.0567249572324027,"bar_close_ms":1789997819999,"ref":85042.04733770393,"reference_received_ms":1789997701631,"spot":84910.99115122062,"twap":84938.30391374565,"sigma":13.118165972089628,"spot_z":-0.9123057376915075,"twap_z":-0.7221766744826754,"momentum":-0.6477820860082342,"decision_ms":1789997880081,"momentum30":-0.17317535013636456,"momentum60":-0.739355765792588,"spot_twap_gap":-0.2687923363256709,"range60":0.8806596965544159,"final_mean":84910.99115122062,"final_z":-1.1175305001753244,"final_up_prob":0.13188378305554732,"final_drift_up_prob":0.0007416049086760301,"final_known_seconds":0,"final_sd":117.27302875648903,"final_drift_shift":-241.6314850326572},"entry_side":null,"context_gap":null,"book_errors":[null,null],"books":[{"bid":0.1,"ask":0.11,"asks":[[0.11,1101.08]],"received_ms":1789997880075,"observed_ms":1789997880068,"hash":"70149302ff1e49d33025cb3144205564555982a9"},{"bid":0.89,"ask":0.9,"asks":[[0.9,200.25]],"received_ms":1789997880081,"observed_ms":1789997880068,"hash":"c5db2379564ead581be8a6ac9a086c9d518fcff4"}],"intents":{"pair_fast":null,"pair_250":null,"pair_add_fast":null,"pair_add_250":null},"decision_ms":1789997880082,"feature_cutoff_ms":1789997880081,"request_ms":1789997880048,"inventory":{"pair_fast":{"qty":[0.0,0.0],"cash":0.0,"lots":[[],[]],"floor":0.0},"pair_250":{"qty":[0.0,0.0],"cash":0.0,"lots":[[],[]],"floor":0.0},"pair_add_fast":{"qty":[0.0,0.0],"cash":0.0,"lots":[[],[]],"floor":0.0},"pair_add_250":{"qty":[0.0,0.0],"cash":0.0,"lots":[[],[]],"floor":0.0}}}
{"kind":"decision","recorded_ms":1789997890104,"S":1789997700,"age":190,"signal":{"rsi14":39.03729043841078,"volume_ratio":0.6298641648014824,"taker_buy_fraction":0.44443899775787554,"volume5":191.34977,"return1":-10.264770312074955,"return5":-15.4825284000413,"return15":-27.45357979301591,"bollinger_z":-1.93492547390236,"bar_close_ms":1789997879999,"ref":85042.04733770393,"reference_received_ms":1789997701631,"spot":84818.9582991602,"twap":84921.07740157773,"sigma":14.54532550790969,"spot_z":-1.4630590955136913,"twap_z":-0.7933431713564545,"momentum":-2.000872595900282,"decision_ms":1789997890103,"momentum30":-1.8528338878280253,"momentum60":-0.9287641371102621,"spot_twap_gap":-0.9063750017779215,"range60":1.3101514064954316,"final_mean":84818.9582991602,"final_z":-1.834532959674214,"final_up_prob":0.03328745993476817,"final_drift_up_prob":1.609823385706477e-15,"final_known_seconds":0,"final_sd":121.60535866488611,"final_drift_shift":-735.3148787917664},"entry_side":null,"context_gap":null,"book_errors":[null,null],"books":[{"bid":0.01,"ask":0.02,"asks":[[0.02,441.21]],"received_ms":1789997890103,"observed_ms":1789997890073,"hash":"0f6790b605bef5588bdf225c3669c7e407e5ad6e"},{"bid":0.98,"ask":0.99,"asks":[[0.99,3922.97]],"received_ms":1789997890067,"observed_ms":1789997890053,"hash":"7dbf8ccd41893b9ccd3a824de69c1199e8ca553f"}],"intents":{"pair_fast":null,"pair_250":null,"pair_add_fast":null,"pair_add_250":null},"decision_ms":1789997890104,"feature_cutoff_ms":1789997890103,"request_ms":1789997890028,"inventory":{"pair_fast":{"qty":[0.0,0.0],"cash":0.0,"lots":[[],[]],"floor":0.0},"pair_250":{"qty":[0.0,0.0],"cash":0.0,"lots":[[],[]],"floor":0.0},"pair_add_fast":{"qty":[0.0,0.0],"cash":0.0,"lots":[[],[]],"floor":0.0},"pair_add_250":{"qty":[0.0,0.0],"cash":0.0,"lots":[[],[]],"floor":0.0}}}
{"kind":"decision","recorded_ms":1789997900067,"S":1789997700,"age":200,"signal":{"rsi14":39.03729043841078,"volume_ratio":0.6298641648014824,"taker_buy_fraction":0.44443899775787554,"volume5":191.34977,"return1":-10.264770312074955,"return5":-15.4825284000413,"return15":-27.45357979301591,"bollinger_z":-1.93492547390236,"bar_close_ms":1789997879999,"ref":85042.04733770393,"reference_received_ms":1789997701631,"spot":84764.63441155083,"twap":84902.77047349403,"sigma":15.612299115815306,"spot_z":-1.7774737447656015,"twap_z":-0.8923916157019472,"momentum":-1.1003325962835244,"decision_ms":1789997900066,"momentum30":-2.025782313852271,"momentum60":-1.467845661696772,"spot_twap_gap":-1.1422589832285261,"range60":1.6698221198860532,"final_mean":84764.63441155083,"final_z":-2.295214073360257,"final_up_prob":0.010860429528232018,"final_drift_up_prob":2.6874423075806675e-08,"final_known_seconds":0,"final_sd":120.86581786550525,"final_drift_shift":-379.90867569024147},"entry_side":null,"context_gap":null,"book_errors":[null,null],"books":[{"bid":0.01,"ask":0.02,"asks":[[0.02,755.72]],"received_ms":1789997900055,"observed_ms":1789997900047,"hash":"291b94a9e8b5711f4959bb1cfe769f38e43f9528"},{"bid":0.98,"ask":0.99,"asks":[[0.99,4321.89]],"received_ms":1789997900065,"observed_ms":1789997900048,"hash":"75a805e0f0c158b2f471fc0841cd59a8e55a153f"}],"intents":{"pair_fast":null,"pair_250":null,"pair_add_fast":null,"pair_add_250":null},"decision_ms":1789997900067,"feature_cutoff_ms":1789997900066,"request_ms":1789997900027,"inventory":{"pair_fast":{"qty":[0.0,0.0],"cash":0.0,"lots":[[],[]],"floor":0.0},"pair_250":{"qty":[0.0,0.0],"cash":0.0,"lots":[[],[]],"floor":0.0},"pair_add_fast":{"qty":[0.0,0.0],"cash":0.0,"lots":[[],[]],"floor":0.0},"pair_add_250":{"qty":[0.0,0.0],"cash":0.0,"lots":[[],[]],"floor":0.0}}}
{"kind":"decision","recorded_ms":1789997910080,"S":1789997700,"age":210,"signal":{"rsi14":39.03729043841078,"volume_ratio":0.6298641648014824,"taker_buy_fraction":0.44443899775787554,"volume5":191.34977,"return1":-10.264770312074955,"return5":-15.4825284000413,"return15":-27.45357979301591,"bollinger_z":-1.93492547390236,"bar_close_ms":1789997879999,"ref":85042.04733770393,"reference_received_ms":1789997701631,"spot":84849.6020817707,"twap":84880.92707198592,"sigma":16.05793531475037,"spot_z":-1.2638249983039371,"twap_z":-1.058107764519005,"momentum":1.6732622227345795,"decision_ms":1789997910079,"momentum30":-0.6979763683376011,"momentum60":-0.5935794029882231,"spot_twap_gap":-0.251840524213599,"range60":1.623481593048822,"final_mean":84849.6020817707,"final_z":-1.6961953457221222,"final_up_prob":0.04492444580239363,"final_drift_up_prob":0.9973749433882116,"final_known_seconds":0,"final_sd":113.45701214107375,"final_drift_shift":509.1347767569412},"entry_side":0,"context_gap":null,"book_errors":[null,null],"books":[{"bid":0.04,"ask":0.05,"asks":[[0.05,565.71]],"received_ms":1789997910079,"observed_ms":1789997910069,"hash":"1adb2b5d4acf8afab5a54c4507b1bcb43caa74fa"},{"bid":0.95,"ask":0.96,"asks":[[0.96,4958.95]],"received_ms":1789997910066,"observed_ms":1789997910057,"hash":"7a18fab1c59d29e6bfcc34cf8ed68d3534dc7ca7"}],"intents":{"pair_fast":null,"pair_250":null,"pair_add_fast":null,"pair_add_250":null},"decision_ms":1789997910080,"feature_cutoff_ms":1789997910079,"request_ms":1789997910039,"inventory":{"pair_fast":{"qty":[0.0,0.0],"cash":0.0,"lots":[[],[]],"floor":0.0},"pair_250":{"qty":[0.0,0.0],"cash":0.0,"lots":[[],[]],"floor":0.0},"pair_add_fast":{"qty":[0.0,0.0],"cash":0.0,"lots":[[],[]],"floor":0.0},"pair_add_250":{"qty":[0.0,0.0],"cash":0.0,"lots":[[],[]],"floor":0.0}}}
{"kind":"decision","recorded_ms":1789997920033,"S":1789997700,"age":220,"signal":{"rsi14":39.03729043841078,"volume_ratio":0.6298641648014824,"taker_buy_fraction":0.44443899775787554,"volume5":191.34977,"return1":-10.264770312074955,"return5":-15.4825284000413,"return15":-27.45357979301591,"bollinger_z":-1.93492547390236,"bar_close_ms":1789997879999,"ref":85042.04733770393,"reference_received_ms":1789997701631,"spot":84879.16295505517,"twap":84866.55939163963,"sigma":15.79888869248682,"spot_z":-1.1529083636357138,"twap_z":-1.2421173684346873,"momentum":0.5916852192711696,"decision_ms":1789997920032,"momentum30":0.6957334941370217,"momentum60":-0.7142395415850382,"spot_twap_gap":0.10298908183011271,"range60":1.6501010237677902,"final_mean":84879.16295505517,"final_z":-1.6307849648449484,"final_up_prob":0.05146785051637848,"final_drift_up_prob":0.43962227514131985,"final_known_seconds":0,"final_sd":99.88096907935622,"final_drift_shift":147.7097714361393},"entry_side":0,"context_gap":null,"book_errors":[null,null],"books":[{"bid":0.02,"ask":0.03,"asks":[[0.03,60.0]],"received_ms":1789997920030,"observed_ms":1789997920022,"hash":"fb3d775d8d8a4c35f79bf668d3477d56d37f487f"},{"bid":0.97,"ask":0.98,"asks":[[0.98,469.78]],"received_ms":1789997920032,"observed_ms":1789997920024,"hash":"8699c0d5e38fd1bca1ccde367a4292b49e4489b9"}],"intents":{"pair_fast":null,"pair_250":null,"pair_add_fast":null,"pair_add_250":null},"decision_ms":1789997920033,"feature_cutoff_ms":1789997920032,"request_ms":1789997920005,"inventory":{"pair_fast":{"qty":[0.0,0.0],"cash":0.0,"lots":[[],[]],"floor":0.0},"pair_250":{"qty":[0.0,0.0],"cash":0.0,"lots":[[],[]],"floor":0.0},"pair_add_fast":{"qty":[0.0,0.0],"cash":0.0,"lots":[[],[]],"floor":0.0},"pair_add_250":{"qty":[0.0,0.0],"cash":0.0,"lots":[[],[]],"floor":0.0}}}
{"kind":"decision","recorded_ms":1789997930042,"S":1789997700,"age":230,"signal":{"rsi14":39.03729043841078,"volume_ratio":0.6298641648014824,"taker_buy_fraction":0.44443899775787554,"volume5":191.34977,"return1":-10.264770312074955,"return5":-15.4825284000413,"return15":-27.45357979301591,"bollinger_z":-1.93492547390236,"bar_close_ms":1789997879999,"ref":85042.04733770393,"reference_received_ms":1789997701631,"spot":84933.29463626274,"twap":84860.12775668314,"sigma":15.712281873690547,"spot_z":-0.827520945844737,"twap_z":-1.384262291961644,"momentum":1.0894624190562583,"decision_ms":1789997930041,"momentum30":1.9598046583607198,"momentum60":-0.03753810163820385,"spot_twap_gap":0.601173248595734,"range60":1.4233292653660539,"final_mean":84933.29463626274,"final_z":-1.2645532870514258,"final_up_prob":0.10301575367075066,"final_drift_up_prob":0.8944584540010412,"final_known_seconds":0,"final_sd":86.00088470353815,"final_drift_shift":216.30478553615714},"entry_side":0,"context_gap":null,"book_errors":[null,null],"books":[{"bid":0.07,"ask":0.08,"asks":[[0.08,1117.28]],"received_ms":1789997930037,"observed_ms":1789997930027,"hash":"aeb6ef0038340d8ab2baa99d975d06d80d93a400"},{"bid":0.92,"ask":0.93,"asks":[[0.93,73.0]],"received_ms":1789997930041,"observed_ms":1789997930028,"hash":"3c65635363098a9f81d29d209dc89dccd38bcd33"}],"intents":{"pair_fast":null,"pair_250":null,"pair_add_fast":null,"pair_add_250":null},"decision_ms":1789997930042,"feature_cutoff_ms":1789997930041,"request_ms":1789997930005,"inventory":{"pair_fast":{"qty":[0.0,0.0],"cash":0.0,"lots":[[],[]],"floor":0.0},"pair_250":{"qty":[0.0,0.0],"cash":0.0,"lots":[[],[]],"floor":0.0},"pair_add_fast":{"qty":[0.0,0.0],"cash":0.0,"lots":[[],[]],"floor":0.0},"pair_add_250":{"qty":[0.0,0.0],"cash":0.0,"lots":[[],[]],"floor":0.0}}}
{"kind":"decision","recorded_ms":1789997940050,"S":1789997700,"age":240,"signal":{},"entry_side":null,"context_gap":"two-sided entry context unavailable","book_errors":[null,"empty/invalid public book"],"books":[{"bid":null,"ask":0.01,"asks":[[0.01,2382.48]],"received_ms":1789997940045,"observed_ms":1789997940035,"hash":"b8d374a8a188515befe9dcbfeace7af0945d42bc"},null],"intents":{"pair_fast":null,"pair_250":null,"pair_add_fast":null,"pair_add_250":null},"decision_ms":1789997940050,"feature_cutoff_ms":1789997940050,"request_ms":1789997940015,"inventory":{"pair_fast":{"qty":[0.0,0.0],"cash":0.0,"lots":[[],[]],"floor":0.0},"pair_250":{"qty":[0.0,0.0],"cash":0.0,"lots":[[],[]],"floor":0.0},"pair_add_fast":{"qty":[0.0,0.0],"cash":0.0,"lots":[[],[]],"floor":0.0},"pair_add_250":{"qty":[0.0,0.0],"cash":0.0,"lots":[[],[]],"floor":0.0}}}
{"kind":"decision","recorded_ms":1789997950034,"S":1789997700,"age":250,"signal":{},"entry_side":null,"context_gap":"two-sided entry context unavailable","book_errors":[null,"empty/invalid public book"],"books":[{"bid":null,"ask":0.01,"asks":[[0.01,6387.26]],"received_ms":1789997950033,"observed_ms":1789997950015,"hash":"457e9b0ce869745d06ddc4343f158342ef87f324"},null],"intents":{"pair_fast":null,"pair_250":null,"pair_add_fast":null,"pair_add_250":null},"decision_ms":1789997950034,"feature_cutoff_ms":1789997950034,"request_ms":1789997950002,"inventory":{"pair_fast":{"qty":[0.0,0.0],"cash":0.0,"lots":[[],[]],"floor":0.0},"pair_250":{"qty":[0.0,0.0],"cash":0.0,"lots":[[],[]],"floor":0.0},"pair_add_fast":{"qty":[0.0,0.0],"cash":0.0,"lots":[[],[]],"floor":0.0},"pair_add_250":{"qty":[0.0,0.0],"cash":0.0,"lots":[[],[]],"floor":0.0}}}
{"kind":"decision","recorded_ms":1789997960045,"S":1789997700,"age":260,"signal":{},"entry_side":null,"context_gap":"two-sided entry context unavailable","book_errors":[null,"empty/invalid public book"],"books":[{"bid":null,"ask":0.01,"asks":[[0.01,21511.34]],"received_ms":1789997960045,"observed_ms":1789997959980,"hash":"69e878971f41ab0f27276359a70431406daa0a03"},null],"intents":{"pair_fast":null,"pair_250":null,"pair_add_fast":null,"pair_add_250":null},"decision_ms":1789997960045,"feature_cutoff_ms":1789997960045,"request_ms":1789997960005,"inventory":{"pair_fast":{"qty":[0.0,0.0],"cash":0.0,"lots":[[],[]],"floor":0.0},"pair_250":{"qty":[0.0,0.0],"cash":0.0,"lots":[[],[]],"floor":0.0},"pair_add_fast":{"qty":[0.0,0.0],"cash":0.0,"lots":[[],[]],"floor":0.0},"pair_add_250":{"qty":[0.0,0.0],"cash":0.0,"lots":[[],[]],"floor":0.0}}}
{"kind":"decision","recorded_ms":1789997970053,"S":1789997700,"age":270,"signal":{},"entry_side":null,"context_gap":"two-sided entry context unavailable","book_errors":[null,"empty/invalid public book"],"books":[{"bid":null,"ask":0.01,"asks":[[0.01,35324.36]],"received_ms":1789997970053,"observed_ms":1789997970039,"hash":"2c6b47e9ef54309228817d790ef29840e885ae82"},null],"intents":{"pair_fast":null,"pair_250":null,"pair_add_fast":null,"pair_add_250":null},"decision_ms":1789997970053,"feature_cutoff_ms":1789997970053,"request_ms":1789997970016,"inventory":{"pair_fast":{"qty":[0.0,0.0],"cash":0.0,"lots":[[],[]],"floor":0.0},"pair_250":{"qty":[0.0,0.0],"cash":0.0,"lots":[[],[]],"floor":0.0},"pair_add_fast":{"qty":[0.0,0.0],"cash":0.0,"lots":[[],[]],"floor":0.0},"pair_add_250":{"qty":[0.0,0.0],"cash":0.0,"lots":[[],[]],"floor":0.0}}}
{"kind":"decision","recorded_ms":1789997980056,"S":1789997700,"age":280,"signal":{},"entry_side":null,"context_gap":"two-sided entry context unavailable","book_errors":[null,"empty/invalid public book"],"books":[{"bid":null,"ask":0.01,"asks":[[0.01,55472.79]],"received_ms":1789997980056,"observed_ms":1789997980046,"hash":"e919b225be5b119b32dd8fc950fd107b4ead01b0"},null],"intents":{"pair_fast":null,"pair_250":null,"pair_add_fast":null,"pair_add_250":null},"decision_ms":1789997980056,"feature_cutoff_ms":1789997980056,"request_ms":1789997980026,"inventory":{"pair_fast":{"qty":[0.0,0.0],"cash":0.0,"lots":[[],[]],"floor":0.0},"pair_250":{"qty":[0.0,0.0],"cash":0.0,"lots":[[],[]],"floor":0.0},"pair_add_fast":{"qty":[0.0,0.0],"cash":0.0,"lots":[[],[]],"floor":0.0},"pair_add_250":{"qty":[0.0,0.0],"cash":0.0,"lots":[[],[]],"floor":0.0}}}
{"kind":"decision","recorded_ms":1789997990057,"S":1789997700,"age":290,"signal":{},"entry_side":null,"context_gap":"two-sided entry context unavailable","book_errors":[null,"empty/invalid public book"],"books":[{"bid":null,"ask":0.01,"asks":[[0.01,55706.11]],"received_ms":1789997990053,"observed_ms":1789997990042,"hash":"51a0202805a3d4aa7e863648bfdc7e5504d4bbf0"},null],"intents":{"pair_fast":null,"pair_250":null,"pair_add_fast":null,"pair_add_250":null},"decision_ms":1789997990057,"feature_cutoff_ms":1789997990057,"request_ms":1789997990028,"inventory":{"pair_fast":{"qty":[0.0,0.0],"cash":0.0,"lots":[[],[]],"floor":0.0},"pair_250":{"qty":[0.0,0.0],"cash":0.0,"lots":[[],[]],"floor":0.0},"pair_add_fast":{"qty":[0.0,0.0],"cash":0.0,"lots":[[],[]],"floor":0.0},"pair_add_250":{"qty":[0.0,0.0],"cash":0.0,"lots":[[],[]],"floor":0.0}}}
{"kind":"decision","recorded_ms":1789998030081,"S":1789998000,"age":30,"signal":{"rsi14":49.32223517957834,"volume_ratio":0.47227413377714433,"taker_buy_fraction":0.43411870186344365,"volume5":213.38772,"return1":14.455823693962047,"return5":-10.711979291192652,"return15":-0.050544838091667536,"bollinger_z":0.14706568699157554,"bar_close_ms":1789997999999,"ref":84945.18946902028,"reference_received_ms":1789998001596,"spot":85083.01315401398,"twap":85007.38058212459,"sigma":9.970157444731196,"spot_z":0.8414034883571562,"twap_z":0.379672184161775,"momentum":0.46109218315724376,"decision_ms":1789998030080,"momentum30":1.0696655215828006,"momentum60":1.76975991032334,"spot_twap_gap":0.9793348900865907,"range60":1.9936574430449603,"final_mean":85083.01315401398,"final_z":0.9116611867141071,"final_up_prob":0.8190264490615558,"final_drift_up_prob":0.9993562647571228,"final_known_seconds":0,"final_sd":151.17862535144891,"final_drift_shift":348.78373911859836},"entry_side":null,"context_gap":null,"book_errors":[null,null],"books":[{"bid":0.76,"ask":0.77,"asks":[[0.77,10.0]],"received_ms":1789998030080,"observed_ms":1789998030067,"hash":"edc6d9fa6834fd56471f009f05ddf813cd01145e"},{"bid":0.23,"ask":0.24,"asks":[[0.24,1475.0]],"received_ms":1789998030072,"observed_ms":1789998030063,"hash":"97f445bfafa6dc4a7bb7f8f5f70cf2ce0d5b2d3b"}],"intents":{"pair_fast":null,"pair_250":null,"pair_add_fast":null,"pair_add_250":null},"decision_ms":1789998030081,"feature_cutoff_ms":1789998030080,"request_ms":1789998030041,"inventory":{"pair_fast":{"qty":[0.0,0.0],"cash":0.0,"lots":[[],[]],"floor":0.0},"pair_250":{"qty":[0.0,0.0],"cash":0.0,"lots":[[],[]],"floor":0.0},"pair_add_fast":{"qty":[0.0,0.0],"cash":0.0,"lots":[[],[]],"floor":0.0},"pair_add_250":{"qty":[0.0,0.0],"cash":0.0,"lots":[[],[]],"floor":0.0}}}
{"kind":"decision","recorded_ms":1789998040047,"S":1789998000,"age":40,"signal":{"rsi14":49.32223517957834,"volume_ratio":0.47227413377714433,"taker_buy_fraction":0.43411870186344365,"volume5":213.38772,"return1":14.455823693962047,"return5":-10.711979291192652,"return15":-0.050544838091667536,"bollinger_z":0.14706568699157554,"bar_close_ms":1789997999999,"ref":84945.18946902028,"reference_received_ms":1789998001596,"spot":85031.75229243436,"twap":85029.48399203,"sigma":10.519685028748926,"spot_z":0.5103644604285883,"twap_z":0.4969908218814067,"momentum":-1.5409309021250563,"decision_ms":1789998040046,"momentum30":-0.052582459756826516,"momentum60":1.0333273148748774,"spot_twap_gap":0.02783698582321797,"range60":1.66240972139037,"final_mean":85031.75229243436,"final_z":0.5548335884410153,"final_up_prob":0.7104957547658817,"final_drift_up_prob":1.2745360322696797e-12,"final_known_seconds":0,"final_sd":156.01583108426402,"final_drift_shift":-1178.764016348435},"entry_side":null,"context_gap":null,"book_errors":[null,null],"books":[{"bid":0.69,"ask":0.7,"asks":[[0.7,333.0]],"received_ms":1789998040044,"observed_ms":1789998040034,"hash":"7a0f0baa253d5e963ca1cb8c1cf678e6585ff5e3"},{"bid":0.3,"ask":0.31,"asks":[[0.31,1191.21]],"received_ms":1789998040046,"observed_ms":1789998040036,"hash":"0440c62b9c228a3646365c7f9d8c4fa9039471f1"}],"intents":{"pair_fast":null,"pair_250":null,"pair_add_fast":null,"pair_add_250":null},"decision_ms":1789998040047,"feature_cutoff_ms":1789998040046,"request_ms":1789998040004,"inventory":{"pair_fast":{"qty":[0.0,0.0],"cash":0.0,"lots":[[],[]],"floor":0.0},"pair_250":{"qty":[0.0,0.0],"cash":0.0,"lots":[[],[]],"floor":0.0},"pair_add_fast":{"qty":[0.0,0.0],"cash":0.0,"lots":[[],[]],"floor":0.0},"pair_add_250":{"qty":[0.0,0.0],"cash":0.0,"lots":[[],[]],"floor":0.0}}}
{"kind":"decision","recorded_ms":1789998050052,"S":1789998000,"age":50,"signal":{"rsi14":49.32223517957834,"volume_ratio":0.47227413377714433,"taker_buy_fraction":0.43411870186344365,"volume5":213.38772,"return1":14.455823693962047,"return5":-10.711979291192652,"return15":-0.050544838091667536,"bollinger_z":0.14706568699157554,"bar_close_ms":1789997999999,"ref":84945.18946902028,"reference_received_ms":1789998001596,"spot":85029.5371742201,"twap":85042.30575978982,"sigma":10.582717566841927,"spot_z":0.5041390794557302,"twap_z":0.5804558323516243,"momentum":-0.0661911158393285,"decision_ms":1789998050051,"momentum30":-0.6717708286440809,"momentum60":0.8971652516868396,"spot_twap_gap":-0.15576502901641576,"range60":1.5495231419789215,"final_mean":85029.5371742201,"final_z":0.5500715209348264,"final_up_prob":0.7088648403943265,"final_drift_up_prob":0.5918617517842677,"final_known_seconds":0,"final_sd":153.33952402493756,"final_drift_shift":-48.72130358484672},"entry_side":null,"context_gap":null,"book_errors":[null,null],"books":[{"bid":0.7,"ask":0.71,"asks":[[0.71,97.0]],"received_ms":1789998050051,"observed_ms":1789998050041,"hash":"8d3026852530f66f2e0ee6fa5b65da84011b2c3c"},{"bid":0.29,"ask":0.3,"asks":[[0.3,1329.1]],"received_ms":1789998050046,"observed_ms":1789998050038,"hash":"a083f82cd8029ebbefc40b01e692198c5d67842b"}],"intents":{"pair_fast":null,"pair_250":null,"pair_add_fast":null,"pair_add_250":null},"decision_ms":1789998050052,"feature_cutoff_ms":1789998050051,"request_ms":1789998050021,"inventory":{"pair_fast":{"qty":[0.0,0.0],"cash":0.0,"lots":[[],[]],"floor":0.0},"pair_250":{"qty":[0.0,0.0],"cash":0.0,"lots":[[],[]],"floor":0.0},"pair_add_fast":{"qty":[0.0,0.0],"cash":0.0,"lots":[[],[]],"floor":0.0},"pair_add_250":{"qty":[0.0,0.0],"cash":0.0,"lots":[[],[]],"floor":0.0}}}
{"kind":"decision","recorded_ms":1789998060074,"S":1789998000,"age":60,"signal":{"rsi14":49.32223517957834,"volume_ratio":0.47227413377714433,"taker_buy_fraction":0.43411870186344365,"volume5":213.38772,"return1":14.455823693962047,"return5":-10.711979291192652,"return15":-0.050544838091667536,"bollinger_z":0.14706568699157554,"bar_close_ms":1789997999999,"ref":84945.18946902028,"reference_received_ms":1789998001596,"spot":85046.74526363389,"twap":85049.4256379735,"sigma":7.791247589810521,"spot_z":0.8415077909254299,"twap_z":0.8637178075765233,"momentum":0.6984344432665346,"decision_ms":1789998060073,"momentum30":-0.8498742315365972,"momentum60":0.36694264238984065,"spot_twap_gap":-0.04441327724591108,"range60":1.00698107166171,"final_mean":85046.74526363389,"final_z":0.9218536474679659,"final_up_prob":0.8216975400542552,"final_drift_up_prob":0.9999867119283454,"final_known_seconds":0,"final_sd":110.1647695299047,"final_drift_shift":361.24425871565705},"entry_side":null,"context_gap":null,"book_errors":[null,null],"books":[{"bid":0.72,"ask":0.73,"asks":[[0.73,904.57]],"received_ms":1789998060073,"observed_ms":1789998060059,"hash":"db368b30d442a31ce8c4f66468d6091c42270392"},{"bid":0.27,"ask":0.28,"asks":[[0.28,352.58]],"received_ms":1789998060071,"observed_ms":1789998060053,"hash":"5cb7600a33e370f276c3a65a7c3774e7f7defcf6"}],"intents":{"pair_fast":null,"pair_250":null,"pair_add_fast":null,"pair_add_250":null},"decision_ms":1789998060074,"feature_cutoff_ms":1789998060073,"request_ms":1789998060026,"inventory":{"pair_fast":{"qty":[0.0,0.0],"cash":0.0,"lots":[[],[]],"floor":0.0},"pair_250":{"qty":[0.0,0.0],"cash":0.0,"lots":[[],[]],"floor":0.0},"pair_add_fast":{"qty":[0.0,0.0],"cash":0.0,"lots":[[],[]],"floor":0.0},"pair_add_250":{"qty":[0.0,0.0],"cash":0.0,"lots":[[],[]],"floor":0.0}}}
{"kind":"decision","recorded_ms":1789998070059,"S":1789998000,"age":70,"signal":{"rsi14":51.82041972505422,"volume_ratio":0.5347921049524241,"taker_buy_fraction":0.39943030923723777,"volume5":189.97324,"return1":-0.20570996798800253,"return5":-16.32514305952843,"return15":-1.6950501362209356,"bollinger_z":0.19417391761113562,"bar_close_ms":1789998059999,"ref":84945.18946902028,"reference_received_ms":1789998001596,"spot":85077.00685775126,"twap":85050.0644121877,"sigma":7.281107868493229,"spot_z":1.1938948721187592,"twap_z":0.9498720773240645,"momentum":1.3142994825353536,"decision_ms":1789998070058,"momentum30":1.1347607489519096,"momentum60":0.7486776183066339,"spot_twap_gap":0.47770955033413665,"range60":1.077533665105927,"final_mean":85077.00685775126,"final_z":1.3136048275162353,"final_up_prob":0.9055103883439124,"final_drift_up_prob":0.9999999999998958,"final_known_seconds":0,"final_sd":100.3478260507177,"final_drift_shift":605.0563648360442},"entry_side":null,"context_gap":null,"book_errors":[null,null],"books":[{"bid":0.8,"ask":0.81,"asks":[[0.81,1874.47]],"received_ms":1789998070055,"observed_ms":1789998070044,"hash":"b14835414d3ea6c400a561b3aec09168ce76d0e3"},{"bid":0.19,"ask":0.2,"asks":[[0.2,42.62]],"received_ms":1789998070058,"observed_ms":1789998070047,"hash":"23f6721ab73f175854f2f399f4f0627bb89bfaf2"}],"intents":{"pair_fast":null,"pair_250":null,"pair_add_fast":null,"pair_add_250":null},"decision_ms":1789998070059,"feature_cutoff_ms":1789998070058,"request_ms":1789998070023,"inventory":{"pair_fast":{"qty":[0.0,0.0],"cash":0.0,"lots":[[],[]],"floor":0.0},"pair_250":{"qty":[0.0,0.0],"cash":0.0,"lots":[[],[]],"floor":0.0},"pair_add_fast":{"qty":[0.0,0.0],"cash":0.0,"lots":[[],[]],"floor":0.0},"pair_add_250":{"qty":[0.0,0.0],"cash":0.0,"lots":[[],[]],"floor":0.0}}}
{"kind":"decision","recorded_ms":1789998080060,"S":1789998000,"age":80,"signal":{"rsi14":51.82041972505422,"volume_ratio":0.5347921049524241,"taker_buy_fraction":0.39943030923723777,"volume5":189.97324,"return1":-0.20570996798800253,"return5":-16.32514305952843,"return15":-1.6950501362209356,"bollinger_z":0.19417391761113562,"bar_close_ms":1789998059999,"ref":84945.18946902028,"reference_received_ms":1789998001596,"spot":85084.67537420239,"twap":85055.89292258403,"sigma":6.688690490499279,"spot_z":1.4061644929899833,"twap_z":1.1160071367029785,"momentum":0.3625519568364589,"decision_ms":1789998080059,"momentum30":1.5050497529339117,"momentum60":0.31267332466625014,"spot_twap_gap":0.5555345297123654,"range60":1.225139533634959,"final_mean":85084.67537420239,"final_z":1.5546196765777147,"final_up_prob":0.9399816626351875,"final_drift_up_prob":0.9992585609562571,"final_known_seconds":0,"final_sd":89.72349140027012,"final_drift_shift":145.65656831269015},"entry_side":null,"context_gap":null,"book_errors":[null,null],"books":[{"bid":0.83,"ask":0.84,"asks":[[0.84,194.9]],"received_ms":1789998080058,"observed_ms":1789998080050,"hash":"f563735fc271e71a6694692226e2b124676dfd80"},{"bid":0.16,"ask":0.17,"asks":[[0.17,1379.16]],"received_ms":1789998080059,"observed_ms":1789998080050,"hash":"eb324ae22d70dc799c716882c035b0c619bb59f6"}],"intents":{"pair_fast":null,"pair_250":null,"pair_add_fast":null,"pair_add_250":null},"decision_ms":1789998080060,"feature_cutoff_ms":1789998080059,"request_ms":1789998080031,"inventory":{"pair_fast":{"qty":[0.0,0.0],"cash":0.0,"lots":[[],[]],"floor":0.0},"pair_250":{"qty":[0.0,0.0],"cash":0.0,"lots":[[],[]],"floor":0.0},"pair_add_fast":{"qty":[0.0,0.0],"cash":0.0,"lots":[[],[]],"floor":0.0},"pair_add_250":{"qty":[0.0,0.0],"cash":0.0,"lots":[[],[]],"floor":0.0}}}
{"kind":"decision","recorded_ms":1789998090091,"S":1789998000,"age":90,"signal":{"rsi14":51.82041972505422,"volume_ratio":0.5347921049524241,"taker_buy_fraction":0.39943030923723777,"volume5":189.97324,"return1":-0.20570996798800253,"return5":-16.32514305952843,"return15":-1.6950501362209356,"bollinger_z":0.19417391761113562,"bar_close_ms":1789998059999,"ref":84945.18946902028,"reference_received_ms":1789998001596,"spot":85083.69173744174,"twap":85057.57130553038,"sigma":6.577936217456002,"spot_z":1.4532845748185945,"twap_z":1.1792066032660602,"momentum":-0.04728736264821092,"decision_ms":1789998090090,"momentum30":1.025469410458009,"momentum60":0.013317967965548102,"spot_twap_gap":0.512643046107088,"range60":1.245767498689445,"final_mean":85083.69173744174,"final_z":1.6153169799156177,"final_up_prob":0.9468789658084817,"final_drift_up_prob":0.9205714596986673,"final_known_seconds":0,"final_sd":85.74308952580866,"final_drift_shift":-17.69660896925434},"entry_side":null,"context_gap":null,"book_errors":[null,null],"books":[{"bid":0.78,"ask":0.79,"asks":[[0.79,1689.64]],"received_ms":1789998090071,"observed_ms":1789998090058,"hash":"fa228d64825fccb1afb842c4150706c56af1af54"},{"bid":0.21,"ask":0.22,"asks":[[0.22,80.0]],"received_ms":1789998090090,"observed_ms":1789998090070,"hash":"a0325e0b9432b8b53f3d0bdaa55ed884920e6105"}],"intents":{"pair_fast":null,"pair_250":null,"pair_add_fast":null,"pair_add_250":null},"decision_ms":1789998090091,"feature_cutoff_ms":1789998090090,"request_ms":1789998090033,"inventory":{"pair_fast":{"qty":[0.0,0.0],"cash":0.0,"lots":[[],[]],"floor":0.0},"pair_250":{"qty":[0.0,0.0],"cash":0.0,"lots":[[],[]],"floor":0.0},"pair_add_fast":{"qty":[0.0,0.0],"cash":0.0,"lots":[[],[]],"floor":0.0},"pair_add_250":{"qty":[0.0,0.0],"cash":0.0,"lots":[[],[]],"floor":0.0}}}
{"kind":"decision","recorded_ms":1789998100054,"S":1789998000,"age":100,"signal":{},"entry_side":null,"context_gap":"incomplete or stale context","book_errors":[null,null],"books":[{"bid":0.69,"ask":0.7,"asks":[[0.7,1359.08]],"received_ms":1789998100053,"observed_ms":1789998099939,"hash":"6b07284d75e1195a9946686b1c1fa299e5fab3b3"},{"bid":0.3,"ask":0.31,"asks":[[0.31,607.1]],"received_ms":1789998100048,"observed_ms":1789998099939,"hash":"72996732d32fda875be6199606af04ac2d224202"}],"intents":{"pair_fast":null,"pair_250":null,"pair_add_fast":null,"pair_add_250":null},"decision_ms":1789998100054,"feature_cutoff_ms":1789998100053,"request_ms":1789998100013,"inventory":{"pair_fast":{"qty":[0.0,0.0],"cash":0.0,"lots":[[],[]],"floor":0.0},"pair_250":{"qty":[0.0,0.0],"cash":0.0,"lots":[[],[]],"floor":0.0},"pair_add_fast":{"qty":[0.0,0.0],"cash":0.0,"lots":[[],[]],"floor":0.0},"pair_add_250":{"qty":[0.0,0.0],"cash":0.0,"lots":[[],[]],"floor":0.0}}}
{"kind":"decision","recorded_ms":1789998110064,"S":1789998000,"age":110,"signal":{},"entry_side":null,"context_gap":"incomplete or stale context","book_errors":[null,null],"books":[{"bid":0.55,"ask":0.57,"asks":[[0.57,1495.17]],"received_ms":1789998110055,"observed_ms":1789998110046,"hash":"ca14ee210f9e8484a9dee91f3e2227a9b640d53a"},{"bid":0.44,"ask":0.45,"asks":[[0.45,12.0]],"received_ms":1789998110063,"observed_ms":1789998110054,"hash":"f0cb6a7f0ce32ccbd9c487f3feaa733387aaf1d0"}],"intents":{"pair_fast":null,"pair_250":null,"pair_add_fast":null,"pair_add_250":null},"decision_ms":1789998110064,"feature_cutoff_ms":1789998110063,"request_ms":1789998110028,"inventory":{"pair_fast":{"qty":[0.0,0.0],"cash":0.0,"lots":[[],[]],"floor":0.0},"pair_250":{"qty":[0.0,0.0],"cash":0.0,"lots":[[],[]],"floor":0.0},"pair_add_fast":{"qty":[0.0,0.0],"cash":0.0,"lots":[[],[]],"floor":0.0},"pair_add_250":{"qty":[0.0,0.0],"cash":0.0,"lots":[[],[]],"floor":0.0}}}
{"kind":"decision","recorded_ms":1789998120099,"S":1789998000,"age":120,"signal":{},"entry_side":null,"context_gap":"incomplete or stale context","book_errors":[null,null],"books":[{"bid":0.6,"ask":0.61,"asks":[[0.61,69.3]],"received_ms":1789998120070,"observed_ms":1789998120059,"hash":"4c3a8f661fed7996e9d32561453f2150912a20a1"},{"bid":0.39,"ask":0.4,"asks":[[0.4,98.5]],"received_ms":1789998120098,"observed_ms":1789998120084,"hash":"7cc163e25e090892e0f2da3cedcb415700371583"}],"intents":{"pair_fast":null,"pair_250":null,"pair_add_fast":null,"pair_add_250":null},"decision_ms":1789998120099,"feature_cutoff_ms":1789998120098,"request_ms":1789998120037,"inventory":{"pair_fast":{"qty":[0.0,0.0],"cash":0.0,"lots":[[],[]],"floor":0.0},"pair_250":{"qty":[0.0,0.0],"cash":0.0,"lots":[[],[]],"floor":0.0},"pair_add_fast":{"qty":[0.0,0.0],"cash":0.0,"lots":[[],[]],"floor":0.0},"pair_add_250":{"qty":[0.0,0.0],"cash":0.0,"lots":[[],[]],"floor":0.0}}}
{"kind":"decision","recorded_ms":1789998130077,"S":1789998000,"age":130,"signal":{},"entry_side":null,"context_gap":"incomplete or stale context","book_errors":[null,null],"books":[{"bid":0.6,"ask":0.61,"asks":[[0.61,1182.79]],"received_ms":1789998130076,"observed_ms":1789998130066,"hash":"27361b0a6d1f4fe0235461493bd0c30cc8b90e82"},{"bid":0.39,"ask":0.4,"asks":[[0.4,686.11]],"received_ms":1789998130073,"observed_ms":1789998130054,"hash":"e7ea9bf286a3345023dff8d418f4a30a3926058e"}],"intents":{"pair_fast":null,"pair_250":null,"pair_add_fast":null,"pair_add_250":null},"decision_ms":1789998130077,"feature_cutoff_ms":1789998130076,"request_ms":1789998130048,"inventory":{"pair_fast":{"qty":[0.0,0.0],"cash":0.0,"lots":[[],[]],"floor":0.0},"pair_250":{"qty":[0.0,0.0],"cash":0.0,"lots":[[],[]],"floor":0.0},"pair_add_fast":{"qty":[0.0,0.0],"cash":0.0,"lots":[[],[]],"floor":0.0},"pair_add_250":{"qty":[0.0,0.0],"cash":0.0,"lots":[[],[]],"floor":0.0}}}
{"kind":"decision","recorded_ms":1789998140044,"S":1789998000,"age":140,"signal":{},"entry_side":null,"context_gap":"incomplete or stale context","book_errors":[null,null],"books":[{"bid":0.81,"ask":0.82,"asks":[[0.82,1323.86]],"received_ms":1789998140043,"observed_ms":1789998140030,"hash":"f3592c0484c02c5cd6775445831f35e4a6838656"},{"bid":0.18,"ask":0.19,"asks":[[0.19,632.68]],"received_ms":1789998140034,"observed_ms":1789998140025,"hash":"01f70dcd6ceecae1b447fb4a977d3ad800b5e808"}],"intents":{"pair_fast":null,"pair_250":null,"pair_add_fast":null,"pair_add_250":null},"decision_ms":1789998140044,"feature_cutoff_ms":1789998140043,"request_ms":1789998140003,"inventory":{"pair_fast":{"qty":[0.0,0.0],"cash":0.0,"lots":[[],[]],"floor":0.0},"pair_250":{"qty":[0.0,0.0],"cash":0.0,"lots":[[],[]],"floor":0.0},"pair_add_fast":{"qty":[0.0,0.0],"cash":0.0,"lots":[[],[]],"floor":0.0},"pair_add_250":{"qty":[0.0,0.0],"cash":0.0,"lots":[[],[]],"floor":0.0}}}
{"kind":"decision","recorded_ms":1789998150065,"S":1789998000,"age":150,"signal":{},"entry_side":null,"context_gap":"incomplete or stale context","book_errors":[null,null],"books":[{"bid":0.87,"ask":0.88,"asks":[[0.88,470.31]],"received_ms":1789998150055,"observed_ms":1789998150046,"hash":"a199f19c41e4c05ac01e9f27c61e652f250e67a0"},{"bid":0.12,"ask":0.13,"asks":[[0.13,610.48]],"received_ms":1789998150064,"observed_ms":1789998150050,"hash":"de3ce30ea0c82169af3d89f524f4377c15fd02b6"}],"intents":{"pair_fast":null,"pair_250":null,"pair_add_fast":null,"pair_add_250":null},"decision_ms":1789998150065,"feature_cutoff_ms":1789998150064,"request_ms":1789998150018,"inventory":{"pair_fast":{"qty":[0.0,0.0],"cash":0.0,"lots":[[],[]],"floor":0.0},"pair_250":{"qty":[0.0,0.0],"cash":0.0,"lots":[[],[]],"floor":0.0},"pair_add_fast":{"qty":[0.0,0.0],"cash":0.0,"lots":[[],[]],"floor":0.0},"pair_add_250":{"qty":[0.0,0.0],"cash":0.0,"lots":[[],[]],"floor":0.0}}}
{"kind":"decision","recorded_ms":1789998160069,"S":1789998000,"age":160,"signal":{},"entry_side":null,"context_gap":"incomplete or stale context","book_errors":[null,null],"books":[{"bid":0.9,"ask":0.91,"asks":[[0.91,966.25]],"received_ms":1789998160068,"observed_ms":1789998160043,"hash":"4b78cf1c04085c070a3991cdf72b4ba1c0e76ccc"},{"bid":0.09,"ask":0.1,"asks":[[0.1,755.03]],"received_ms":1789998160066,"observed_ms":1789998160043,"hash":"ac9af73621b95f0c9f13520b04cd2c38197cceae"}],"intents":{"pair_fast":null,"pair_250":null,"pair_add_fast":null,"pair_add_250":null},"decision_ms":1789998160069,"feature_cutoff_ms":1789998160068,"request_ms":1789998160038,"inventory":{"pair_fast":{"qty":[0.0,0.0],"cash":0.0,"lots":[[],[]],"floor":0.0},"pair_250":{"qty":[0.0,0.0],"cash":0.0,"lots":[[],[]],"floor":0.0},"pair_add_fast":{"qty":[0.0,0.0],"cash":0.0,"lots":[[],[]],"floor":0.0},"pair_add_250":{"qty":[0.0,0.0],"cash":0.0,"lots":[[],[]],"floor":0.0}}}
{"kind":"decision","recorded_ms":1789998170077,"S":1789998000,"age":170,"signal":{},"entry_side":null,"context_gap":"incomplete or stale context","book_errors":[null,null],"books":[{"bid":0.88,"ask":0.89,"asks":[[0.89,1577.69]],"received_ms":1789998170073,"observed_ms":1789998170062,"hash":"f1a94c80a1a1bcc726e3757a95ff5cdd441c9a2a"},{"bid":0.11,"ask":0.12,"asks":[[0.12,245.0]],"received_ms":1789998170076,"observed_ms":1789998170065,"hash":"393bb52850790615b7e68dd406f761745f1b0abc"}],"intents":{"pair_fast":null,"pair_250":null,"pair_add_fast":null,"pair_add_250":null},"decision_ms":1789998170077,"feature_cutoff_ms":1789998170076,"request_ms":1789998170045,"inventory":{"pair_fast":{"qty":[0.0,0.0],"cash":0.0,"lots":[[],[]],"floor":0.0},"pair_250":{"qty":[0.0,0.0],"cash":0.0,"lots":[[],[]],"floor":0.0},"pair_add_fast":{"qty":[0.0,0.0],"cash":0.0,"lots":[[],[]],"floor":0.0},"pair_add_250":{"qty":[0.0,0.0],"cash":0.0,"lots":[[],[]],"floor":0.0}}}
{"kind":"decision","recorded_ms":1789998180082,"S":1789998000,"age":180,"signal":{"rsi14":49.1424246623532,"volume_ratio":0.49309602690135346,"taker_buy_fraction":0.443906807310006,"volume5":163.04884,"return1":-6.4575829137759975,"return5":0.897474638108309,"return15":-2.6477266191089126,"bollinger_z":-0.4546603575268435,"bar_close_ms":1789998119999,"ref":84945.18946902028,"reference_received_ms":1789998001596,"spot":85027.94672578902,"twap":85043.0671358615,"sigma":12.035773730661257,"spot_z":0.6278965152237708,"twap_z":0.742618210504203,"momentum":-1.616121424028037,"decision_ms":1789998180081,"momentum30":-0.811996364072053,"momentum60":0.381252467425201,"spot_twap_gap":-0.16218621173028866,"range60":1.2548981791248743,"final_mean":85027.94672578902,"final_z":0.7691429284352902,"final_up_prob":0.7790957668592953,"final_drift_up_prob":6.175483345083332e-06,"final_known_seconds":0,"final_sd":107.59672059535588,"final_drift_shift":-553.0946657693869},"entry_side":null,"context_gap":null,"book_errors":[null,null],"books":[{"bid":0.77,"ask":0.78,"asks":[[0.78,805.65]],"received_ms":1789998180077,"observed_ms":1789998179963,"hash":"47afbb84bf0d27146047da74fcdd93837646035e"},{"bid":0.22,"ask":0.23,"asks":[[0.23,326.09]],"received_ms":1789998180081,"observed_ms":1789998179963,"hash":"9f339fd1e39376d6945bfda59916d1d83bd11431"}],"intents":{"pair_fast":null,"pair_250":null,"pair_add_fast":null,"pair_add_250":null},"decision_ms":1789998180082,"feature_cutoff_ms":1789998180081,"request_ms":1789998180048,"inventory":{"pair_fast":{"qty":[0.0,0.0],"cash":0.0,"lots":[[],[]],"floor":0.0},"pair_250":{"qty":[0.0,0.0],"cash":0.0,"lots":[[],[]],"floor":0.0},"pair_add_fast":{"qty":[0.0,0.0],"cash":0.0,"lots":[[],[]],"floor":0.0},"pair_add_250":{"qty":[0.0,0.0],"cash":0.0,"lots":[[],[]],"floor":0.0}}}
{"kind":"decision","recorded_ms":1789998190061,"S":1789998000,"age":190,"signal":{"rsi14":53.351197708731135,"volume_ratio":0.5305325801895103,"taker_buy_fraction":0.5064112818401176,"volume5":160.72059000000002,"return1":3.616819811235724,"return5":14.763585679415684,"return15":1.7249267435250584,"bollinger_z":0.056208763805942474,"bar_close_ms":1789998179999,"ref":84945.18946902028,"reference_received_ms":1789998001596,"spot":85011.87165226566,"twap":85049.55346637244,"sigma":11.905950909548935,"spot_z":0.5341556871461985,"twap_z":0.8360047617790984,"momentum":-0.4269616620686214,"decision_ms":1789998190060,"momentum30":-1.2000460111277667,"momentum60":0.03946027571236593,"spot_twap_gap":-0.4085940988646984,"range60":1.2685816239047487,"final_mean":85011.87165226566,"final_z":0.6697040247515657,"final_up_prob":0.7484767572478996,"final_drift_up_prob":0.2673354526753549,"final_known_seconds":0,"final_sd":99.5696319282576,"final_drift_shift":-128.50413783771901},"entry_side":null,"context_gap":null,"book_errors":[null,null],"books":[{"bid":0.79,"ask":0.81,"asks":[[0.81,228.0]],"received_ms":1789998190060,"observed_ms":1789998190048,"hash":"fdaa0afb2de23f524658170530c72bfe1553c92d"},{"bid":0.19,"ask":0.21,"asks":[[0.21,248.0]],"received_ms":1789998190054,"observed_ms":1789998190041,"hash":"398eafe2c8f7cfb789ab3c084a1712c688b3ff39"}],"intents":{"pair_fast":null,"pair_250":null,"pair_add_fast":null,"pair_add_250":null},"decision_ms":1789998190061,"feature_cutoff_ms":1789998190060,"request_ms":1789998190026,"inventory":{"pair_fast":{"qty":[0.0,0.0],"cash":0.0,"lots":[[],[]],"floor":0.0},"pair_250":{"qty":[0.0,0.0],"cash":0.0,"lots":[[],[]],"floor":0.0},"pair_add_fast":{"qty":[0.0,0.0],"cash":0.0,"lots":[[],[]],"floor":0.0},"pair_add_250":{"qty":[0.0,0.0],"cash":0.0,"lots":[[],[]],"floor":0.0}}}
{"kind":"decision","recorded_ms":1789998200066,"S":1789998000,"age":200,"signal":{"rsi14":53.351197708731135,"volume_ratio":0.5305325801895103,"taker_buy_fraction":0.5064112818401176,"volume5":160.72059000000002,"return1":3.616819811235724,"return5":14.763585679415684,"return15":1.7249267435250584,"bollinger_z":0.056208763805942474,"bar_close_ms":1789998179999,"ref":84945.18946902028,"reference_received_ms":1789998001596,"spot":85045.7139389504,"twap":85054.18313544926,"sigma":11.90447287949785,"spot_z":0.844700621060683,"twap_z":0.9158667316349981,"momentum":0.8989789655993555,"decision_ms":1789998200065,"momentum30":-0.6708707392686426,"momentum60":0.5462704472165364,"spot_twap_gap":-0.09184518941708707,"range60":1.1567128991130495,"final_mean":85045.7139389504,"final_z":1.090740319264043,"final_up_prob":0.8623064180674571,"final_drift_up_prob":0.9998732968271034,"final_known_seconds":0,"final_sd":92.16168885913439,"final_drift_shift":236.67603173607873},"entry_side":null,"context_gap":null,"book_errors":[null,null],"books":[{"bid":0.92,"ask":0.93,"asks":[[0.93,420.19]],"received_ms":1789998200062,"observed_ms":1789998200050,"hash":"ce84151e10a2796387a13938568487b89d923830"},{"bid":0.07,"ask":0.08,"asks":[[0.08,811.53]],"received_ms":1789998200065,"observed_ms":1789998200055,"hash":"65d2e68e3a7432704bdd2716dc1d8eb5a5bd41b1"}],"intents":{"pair_fast":null,"pair_250":null,"pair_add_fast":null,"pair_add_250":null},"decision_ms":1789998200066,"feature_cutoff_ms":1789998200065,"request_ms":1789998200035,"inventory":{"pair_fast":{"qty":[0.0,0.0],"cash":0.0,"lots":[[],[]],"floor":0.0},"pair_250":{"qty":[0.0,0.0],"cash":0.0,"lots":[[],[]],"floor":0.0},"pair_add_fast":{"qty":[0.0,0.0],"cash":0.0,"lots":[[],[]],"floor":0.0},"pair_add_250":{"qty":[0.0,0.0],"cash":0.0,"lots":[[],[]],"floor":0.0}}}
{"kind":"decision","recorded_ms":1789998210078,"S":1789998000,"age":210,"signal":{"rsi14":53.351197708731135,"volume_ratio":0.5305325801895103,"taker_buy_fraction":0.5064112818401176,"volume5":160.72059000000002,"return1":3.616819811235724,"return5":14.763585679415684,"return15":1.7249267435250584,"bollinger_z":0.056208763805942474,"bar_close_ms":1789998179999,"ref":84945.18946902028,"reference_received_ms":1789998001596,"spot":85045.58069887028,"twap":85056.08842522575,"sigma":7.62965561591589,"spot_z":1.387571737176779,"twap_z":1.5328057793796916,"momentum":-0.005522426568226178,"decision_ms":1789998210077,"momentum30":0.42197294877012875,"momentum60":-0.6073696976393534,"spot_twap_gap":-0.17779854133191728,"range60":1.525103703642307,"final_mean":85045.58069887028,"final_z":1.8622607980057728,"final_up_prob":0.9687168308357103,"final_drift_up_prob":0.9676590389192763,"final_known_seconds":0,"final_sd":53.90825493266707,"final_drift_shift":-0.7984145333896511},"entry_side":null,"context_gap":null,"book_errors":[null,null],"books":[{"bid":0.93,"ask":0.94,"asks":[[0.94,57.07]],"received_ms":1789998210066,"observed_ms":1789998210055,"hash":"947c2fe0ddfe9d7229e70c54dfbb5c73a8791e6b"},{"bid":0.06,"ask":0.07,"asks":[[0.07,1142.1]],"received_ms":1789998210077,"observed_ms":1789998210059,"hash":"423d06be3240b0e3cb81bda6bbb7fc15c318129c"}],"intents":{"pair_fast":null,"pair_250":null,"pair_add_fast":null,"pair_add_250":null},"decision_ms":1789998210078,"feature_cutoff_ms":1789998210077,"request_ms":1789998210038,"inventory":{"pair_fast":{"qty":[0.0,0.0],"cash":0.0,"lots":[[],[]],"floor":0.0},"pair_250":{"qty":[0.0,0.0],"cash":0.0,"lots":[[],[]],"floor":0.0},"pair_add_fast":{"qty":[0.0,0.0],"cash":0.0,"lots":[[],[]],"floor":0.0},"pair_add_250":{"qty":[0.0,0.0],"cash":0.0,"lots":[[],[]],"floor":0.0}}}
{"kind":"decision","recorded_ms":1789998220088,"S":1789998000,"age":220,"signal":{},"entry_side":null,"context_gap":"incomplete or stale context","book_errors":[null,null],"books":[{"bid":0.92,"ask":0.93,"asks":[[0.93,194.52]],"received_ms":1789998220087,"observed_ms":1789998220076,"hash":"340df7e83cc2279788ac3821fe047b51dec6ff88"},{"bid":0.07,"ask":0.08,"asks":[[0.08,120.0]],"received_ms":1789998220083,"observed_ms":1789998220072,"hash":"2a63f9c6232cf834c184b067df6b1e69e924b117"}],"intents":{"pair_fast":null,"pair_250":null,"pair_add_fast":null,"pair_add_250":null},"decision_ms":1789998220088,"feature_cutoff_ms":1789998220087,"request_ms":1789998220050,"inventory":{"pair_fast":{"qty":[0.0,0.0],"cash":0.0,"lots":[[],[]],"floor":0.0},"pair_250":{"qty":[0.0,0.0],"cash":0.0,"lots":[[],[]],"floor":0.0},"pair_add_fast":{"qty":[0.0,0.0],"cash":0.0,"lots":[[],[]],"floor":0.0},"pair_add_250":{"qty":[0.0,0.0],"cash":0.0,"lots":[[],[]],"floor":0.0}}}
{"kind":"decision","recorded_ms":1789998230061,"S":1789998000,"age":230,"signal":{},"entry_side":null,"context_gap":"incomplete or stale context","book_errors":[null,null],"books":[{"bid":0.94,"ask":0.95,"asks":[[0.95,86.84]],"received_ms":1789998230041,"observed_ms":1789998230032,"hash":"b05f1e3f5112a86da96d9c7ed564df069e5a5ead"},{"bid":0.05,"ask":0.06,"asks":[[0.06,1032.96]],"received_ms":1789998230060,"observed_ms":1789998230034,"hash":"1afadd20982d4b89ab046441e93628cf46f405c3"}],"intents":{"pair_fast":null,"pair_250":null,"pair_add_fast":null,"pair_add_250":null},"decision_ms":1789998230061,"feature_cutoff_ms":1789998230060,"request_ms":1789998230010,"inventory":{"pair_fast":{"qty":[0.0,0.0],"cash":0.0,"lots":[[],[]],"floor":0.0},"pair_250":{"qty":[0.0,0.0],"cash":0.0,"lots":[[],[]],"floor":0.0},"pair_add_fast":{"qty":[0.0,0.0],"cash":0.0,"lots":[[],[]],"floor":0.0},"pair_add_250":{"qty":[0.0,0.0],"cash":0.0,"lots":[[],[]],"floor":0.0}}}
{"kind":"decision","recorded_ms":1789998240076,"S":1789998000,"age":240,"signal":{},"entry_side":null,"context_gap":"two-sided entry context unavailable","book_errors":["empty/invalid public book",null],"books":[null,{"bid":null,"ask":0.01,"asks":[[0.01,7168.61]],"received_ms":1789998240060,"observed_ms":1789998240049,"hash":"26dc93dafcb382699ec98ffa58bafe011a4eadc1"}],"intents":{"pair_fast":null,"pair_250":null,"pair_add_fast":null,"pair_add_250":null},"decision_ms":1789998240076,"feature_cutoff_ms":1789998240076,"request_ms":1789998240033,"inventory":{"pair_fast":{"qty":[0.0,0.0],"cash":0.0,"lots":[[],[]],"floor":0.0},"pair_250":{"qty":[0.0,0.0],"cash":0.0,"lots":[[],[]],"floor":0.0},"pair_add_fast":{"qty":[0.0,0.0],"cash":0.0,"lots":[[],[]],"floor":0.0},"pair_add_250":{"qty":[0.0,0.0],"cash":0.0,"lots":[[],[]],"floor":0.0}}}
{"kind":"decision","recorded_ms":1789998250060,"S":1789998000,"age":250,"signal":{},"entry_side":null,"context_gap":"two-sided entry context unavailable","book_errors":["empty/invalid public book",null],"books":[null,{"bid":null,"ask":0.01,"asks":[[0.01,4117.36]],"received_ms":1789998250048,"observed_ms":1789998250039,"hash":"bd8c1229dc4f7248373f01f66a5c722665662bda"}],"intents":{"pair_fast":null,"pair_250":null,"pair_add_fast":null,"pair_add_250":null},"decision_ms":1789998250060,"feature_cutoff_ms":1789998250060,"request_ms":1789998250019,"inventory":{"pair_fast":{"qty":[0.0,0.0],"cash":0.0,"lots":[[],[]],"floor":0.0},"pair_250":{"qty":[0.0,0.0],"cash":0.0,"lots":[[],[]],"floor":0.0},"pair_add_fast":{"qty":[0.0,0.0],"cash":0.0,"lots":[[],[]],"floor":0.0},"pair_add_250":{"qty":[0.0,0.0],"cash":0.0,"lots":[[],[]],"floor":0.0}}}
{"kind":"decision","recorded_ms":1789998260069,"S":1789998000,"age":260,"signal":{},"entry_side":null,"context_gap":"two-sided entry context unavailable","book_errors":["empty/invalid public book",null],"books":[null,{"bid":null,"ask":0.01,"asks":[[0.01,4634.27]],"received_ms":1789998260068,"observed_ms":1789998260055,"hash":"69c40500a818c2cef49016512bd46644e1e0a673"}],"intents":{"pair_fast":null,"pair_250":null,"pair_add_fast":null,"pair_add_250":null},"decision_ms":1789998260069,"feature_cutoff_ms":1789998260069,"request_ms":1789998260032,"inventory":{"pair_fast":{"qty":[0.0,0.0],"cash":0.0,"lots":[[],[]],"floor":0.0},"pair_250":{"qty":[0.0,0.0],"cash":0.0,"lots":[[],[]],"floor":0.0},"pair_add_fast":{"qty":[0.0,0.0],"cash":0.0,"lots":[[],[]],"floor":0.0},"pair_add_250":{"qty":[0.0,0.0],"cash":0.0,"lots":[[],[]],"floor":0.0}}}
{"kind":"decision","recorded_ms":1789998270069,"S":1789998000,"age":270,"signal":{},"entry_side":null,"context_gap":"two-sided entry context unavailable","book_errors":["empty/invalid public book",null],"books":[null,{"bid":null,"ask":0.001,"asks":[[0.001,8018.19]],"received_ms":1789998270069,"observed_ms":1789998270060,"hash":"ff3b515d755ffdd5b47419d13c512e908a77349b"}],"intents":{"pair_fast":null,"pair_250":null,"pair_add_fast":null,"pair_add_250":null},"decision_ms":1789998270069,"feature_cutoff_ms":1789998270069,"request_ms":1789998270042,"inventory":{"pair_fast":{"qty":[0.0,0.0],"cash":0.0,"lots":[[],[]],"floor":0.0},"pair_250":{"qty":[0.0,0.0],"cash":0.0,"lots":[[],[]],"floor":0.0},"pair_add_fast":{"qty":[0.0,0.0],"cash":0.0,"lots":[[],[]],"floor":0.0},"pair_add_250":{"qty":[0.0,0.0],"cash":0.0,"lots":[[],[]],"floor":0.0}}}
{"kind":"decision","recorded_ms":1789998280069,"S":1789998000,"age":280,"signal":{},"entry_side":null,"context_gap":"two-sided entry context unavailable","book_errors":["empty/invalid public book",null],"books":[null,{"bid":null,"ask":0.001,"asks":[[0.001,5100.54]],"received_ms":1789998280068,"observed_ms":1789998280062,"hash":"a67a5d13453a77e9be13d2fecb3f9572ba460b6d"}],"intents":{"pair_fast":null,"pair_250":null,"pair_add_fast":null,"pair_add_250":null},"decision_ms":1789998280069,"feature_cutoff_ms":1789998280069,"request_ms":1789998280043,"inventory":{"pair_fast":{"qty":[0.0,0.0],"cash":0.0,"lots":[[],[]],"floor":0.0},"pair_250":{"qty":[0.0,0.0],"cash":0.0,"lots":[[],[]],"floor":0.0},"pair_add_fast":{"qty":[0.0,0.0],"cash":0.0,"lots":[[],[]],"floor":0.0},"pair_add_250":{"qty":[0.0,0.0],"cash":0.0,"lots":[[],[]],"floor":0.0}}}
{"kind":"decision","recorded_ms":1789998290068,"S":1789998000,"age":290,"signal":{},"entry_side":null,"context_gap":"two-sided entry context unavailable","book_errors":["empty/invalid public book",null],"books":[null,{"bid":null,"ask":0.001,"asks":[[0.001,1659.49]],"received_ms":1789998290067,"observed_ms":1789998290033,"hash":"ae97a75c353d23ace156158d75ef316b47f54bae"}],"intents":{"pair_fast":null,"pair_250":null,"pair_add_fast":null,"pair_add_250":null},"decision_ms":1789998290068,"feature_cutoff_ms":1789998290068,"request_ms":1789998290043,"inventory":{"pair_fast":{"qty":[0.0,0.0],"cash":0.0,"lots":[[],[]],"floor":0.0},"pair_250":{"qty":[0.0,0.0],"cash":0.0,"lots":[[],[]],"floor":0.0},"pair_add_fast":{"qty":[0.0,0.0],"cash":0.0,"lots":[[],[]],"floor":0.0},"pair_add_250":{"qty":[0.0,0.0],"cash":0.0,"lots":[[],[]],"floor":0.0}}}
{"kind":"decision","recorded_ms":1789998330057,"S":1789998300,"age":30,"signal":{"rsi14":52.28039021758688,"volume_ratio":0.5496079894029877,"taker_buy_fraction":0.5289764790027052,"volume5":122.07263,"return1":-3.881026669071141,"return5":0.8932708263161606,"return15":15.713339048699753,"bollinger_z":0.5369536048729463,"bar_close_ms":1789998299999,"ref":85040.08656975995,"reference_received_ms":1789998301904,"spot":85074.15359737736,"twap":85046.48490759231,"sigma":5.64309450875191,"spot_z":0.3674346249702916,"twap_z":0.0690101551643913,"momentum":0.7782648607342673,"decision_ms":1789998330056,"momentum30":0.7749170561413026,"momentum60":1.2599376869792291,"spot_twap_gap":0.6329882453835853,"range60":1.2599376869792291,"final_mean":85074.15359737736,"final_z":0.3981125587061308,"final_up_prob":0.6547263912994459,"final_drift_up_prob":0.9999911617748506,"final_known_seconds":0,"final_sd":85.57134627484275,"final_drift_shift":333.238092950806},"entry_side":null,"context_gap":null,"book_errors":[null,null],"books":[{"bid":0.6,"ask":0.61,"asks":[[0.61,85.22]],"received_ms":1789998330056,"observed_ms":1789998330046,"hash":"b934485160852563dcf1e8da1b2adf011b599814"},{"bid":0.39,"ask":0.4,"asks":[[0.4,1511.72]],"received_ms":1789998330040,"observed_ms":1789998330029,"hash":"f73d8764a06961c2249aad2bf9512179b079b66c"}],"intents":{"pair_fast":null,"pair_250":null,"pair_add_fast":null,"pair_add_250":null},"decision_ms":1789998330057,"feature_cutoff_ms":1789998330056,"request_ms":1789998330015,"inventory":{"pair_fast":{"qty":[0.0,0.0],"cash":0.0,"lots":[[],[]],"floor":0.0},"pair_250":{"qty":[0.0,0.0],"cash":0.0,"lots":[[],[]],"floor":0.0},"pair_add_fast":{"qty":[0.0,0.0],"cash":0.0,"lots":[[],[]],"floor":0.0},"pair_add_250":{"qty":[0.0,0.0],"cash":0.0,"lots":[[],[]],"floor":0.0}}}
{"kind":"decision","recorded_ms":1789998340107,"S":1789998300,"age":40,"signal":{},"entry_side":null,"context_gap":"incomplete or stale context","book_errors":[null,null],"books":[{"bid":0.74,"ask":0.75,"asks":[[0.75,24.59]],"received_ms":1789998340065,"observed_ms":1789998340053,"hash":"89ba136d0e5cabb14a99ba2d1ac0b2c270a2adbb"},{"bid":0.25,"ask":0.26,"asks":[[0.26,1095.25]],"received_ms":1789998340106,"observed_ms":1789998340063,"hash":"67928149258cc4a5b24420a66c0b86d38fe3806f"}],"intents":{"pair_fast":null,"pair_250":null,"pair_add_fast":null,"pair_add_250":null},"decision_ms":1789998340107,"feature_cutoff_ms":1789998340106,"request_ms":1789998340030,"inventory":{"pair_fast":{"qty":[0.0,0.0],"cash":0.0,"lots":[[],[]],"floor":0.0},"pair_250":{"qty":[0.0,0.0],"cash":0.0,"lots":[[],[]],"floor":0.0},"pair_add_fast":{"qty":[0.0,0.0],"cash":0.0,"lots":[[],[]],"floor":0.0},"pair_add_250":{"qty":[0.0,0.0],"cash":0.0,"lots":[[],[]],"floor":0.0}}}
{"kind":"decision","recorded_ms":1789998350062,"S":1789998300,"age":50,"signal":{},"entry_side":null,"context_gap":"incomplete or stale context","book_errors":[null,null],"books":[{"bid":0.76,"ask":0.77,"asks":[[0.77,1568.14]],"received_ms":1789998350061,"observed_ms":1789998350050,"hash":"950afd1f5c4b01d0e1c0c1b432784d7ae98d8735"},{"bid":0.23,"ask":0.24,"asks":[[0.24,254.0]],"received_ms":1789998350061,"observed_ms":1789998350052,"hash":"f9d022e02de78b633e9d04df1145d274f7169187"}],"intents":{"pair_fast":null,"pair_250":null,"pair_add_fast":null,"pair_add_250":null},"decision_ms":1789998350062,"feature_cutoff_ms":1789998350061,"request_ms":1789998350031,"inventory":{"pair_fast":{"qty":[0.0,0.0],"cash":0.0,"lots":[[],[]],"floor":0.0},"pair_250":{"qty":[0.0,0.0],"cash":0.0,"lots":[[],[]],"floor":0.0},"pair_add_fast":{"qty":[0.0,0.0],"cash":0.0,"lots":[[],[]],"floor":0.0},"pair_add_250":{"qty":[0.0,0.0],"cash":0.0,"lots":[[],[]],"floor":0.0}}}
{"kind":"decision","recorded_ms":1789998360071,"S":1789998300,"age":60,"signal":{},"entry_side":null,"context_gap":"incomplete or stale context","book_errors":[null,null],"books":[{"bid":0.86,"ask":0.87,"asks":[[0.87,215.0]],"received_ms":1789998360065,"observed_ms":1789998360050,"hash":"a88689c40b3229f0a6e019443ace1a20775715a1"},{"bid":0.13,"ask":0.14,"asks":[[0.14,1160.62]],"received_ms":1789998360069,"observed_ms":1789998360058,"hash":"6b705e8b07401dc3cdd7677bf7af1652e9ee0617"}],"intents":{"pair_fast":null,"pair_250":null,"pair_add_fast":null,"pair_add_250":null},"decision_ms":1789998360070,"feature_cutoff_ms":1789998360069,"request_ms":1789998360036,"inventory":{"pair_fast":{"qty":[0.0,0.0],"cash":0.0,"lots":[[],[]],"floor":0.0},"pair_250":{"qty":[0.0,0.0],"cash":0.0,"lots":[[],[]],"floor":0.0},"pair_add_fast":{"qty":[0.0,0.0],"cash":0.0,"lots":[[],[]],"floor":0.0},"pair_add_250":{"qty":[0.0,0.0],"cash":0.0,"lots":[[],[]],"floor":0.0}}}
{"kind":"decision","recorded_ms":1789998370065,"S":1789998300,"age":70,"signal":{},"entry_side":null,"context_gap":"incomplete or stale context","book_errors":[null,null],"books":[{"bid":0.87,"ask":0.88,"asks":[[0.88,243.79]],"received_ms":1789998370055,"observed_ms":1789998370044,"hash":"b68751fd341b8500c1ad8808662a3972705ae4b1"},{"bid":0.12,"ask":0.13,"asks":[[0.13,1137.57]],"received_ms":1789998370063,"observed_ms":1789998370054,"hash":"7564746df17c078cf26b41a5a1bec8d9d5dfe330"}],"intents":{"pair_fast":null,"pair_250":null,"pair_add_fast":null,"pair_add_250":null},"decision_ms":1789998370065,"feature_cutoff_ms":1789998370063,"request_ms":1789998370025,"inventory":{"pair_fast":{"qty":[0.0,0.0],"cash":0.0,"lots":[[],[]],"floor":0.0},"pair_250":{"qty":[0.0,0.0],"cash":0.0,"lots":[[],[]],"floor":0.0},"pair_add_fast":{"qty":[0.0,0.0],"cash":0.0,"lots":[[],[]],"floor":0.0},"pair_add_250":{"qty":[0.0,0.0],"cash":0.0,"lots":[[],[]],"floor":0.0}}}
{"kind":"decision","recorded_ms":1789998380068,"S":1789998300,"age":80,"signal":{},"entry_side":null,"context_gap":"incomplete or stale context","book_errors":[null,null],"books":[{"bid":0.9,"ask":0.91,"asks":[[0.91,665.45]],"received_ms":1789998380063,"observed_ms":1789998380048,"hash":"43a7bc55b9ace7144fdeb422c179d669394b3cf3"},{"bid":0.09,"ask":0.1,"asks":[[0.1,341.8]],"received_ms":1789998380067,"observed_ms":1789998380058,"hash":"6911a648ef0696e5ad1d5ed0f44eb2c0a19716a2"}],"intents":{"pair_fast":null,"pair_250":null,"pair_add_fast":null,"pair_add_250":null},"decision_ms":1789998380068,"feature_cutoff_ms":1789998380067,"request_ms":1789998380038,"inventory":{"pair_fast":{"qty":[0.0,0.0],"cash":0.0,"lots":[[],[]],"floor":0.0},"pair_250":{"qty":[0.0,0.0],"cash":0.0,"lots":[[],[]],"floor":0.0},"pair_add_fast":{"qty":[0.0,0.0],"cash":0.0,"lots":[[],[]],"floor":0.0},"pair_add_250":{"qty":[0.0,0.0],"cash":0.0,"lots":[[],[]],"floor":0.0}}}
{"kind":"decision","recorded_ms":1789998390071,"S":1789998300,"age":90,"signal":{},"entry_side":null,"context_gap":"incomplete or stale context","book_errors":[null,null],"books":[{"bid":0.91,"ask":0.92,"asks":[[0.92,39.57]],"received_ms":1789998390068,"observed_ms":1789998390052,"hash":"004bb58c4239642e162db6687c41cc2a799dfa33"},{"bid":0.08,"ask":0.09,"asks":[[0.09,713.31]],"received_ms":1789998390069,"observed_ms":1789998390052,"hash":"e4ebf92e76a81d791961d9ac2755e2b3b32bfc48"}],"intents":{"pair_fast":null,"pair_250":null,"pair_add_fast":null,"pair_add_250":null},"decision_ms":1789998390071,"feature_cutoff_ms":1789998390070,"request_ms":1789998390042,"inventory":{"pair_fast":{"qty":[0.0,0.0],"cash":0.0,"lots":[[],[]],"floor":0.0},"pair_250":{"qty":[0.0,0.0],"cash":0.0,"lots":[[],[]],"floor":0.0},"pair_add_fast":{"qty":[0.0,0.0],"cash":0.0,"lots":[[],[]],"floor":0.0},"pair_add_250":{"qty":[0.0,0.0],"cash":0.0,"lots":[[],[]],"floor":0.0}}}
{"kind":"decision","recorded_ms":1789998400090,"S":1789998300,"age":100,"signal":{"rsi14":61.361167158156505,"volume_ratio":0.6302931904140928,"taker_buy_fraction":0.562695519712694,"volume5":126.3044,"return1":19.63565818634736,"return5":20.732458497252807,"return15":24.39588884052033,"bollinger_z":2.426015095789452,"bar_close_ms":1789998359999,"ref":85040.08656975995,"reference_received_ms":1789998301904,"spot":85271.7961873511,"twap":85209.3245030513,"sigma":10.12026187945004,"spot_z":1.6193247877248822,"twap_z":1.182735456780181,"momentum":-0.10740391042468661,"decision_ms":1789998400089,"momentum30":0.6052199590885384,"momentum60":1.8724987850418147,"spot_twap_gap":0.7969220420863706,"range60":1.9196903720634577,"final_mean":85271.7961873511,"final_z":1.8105609115779193,"final_up_prob":0.9648955762449212,"final_drift_up_prob":0.9121647191104771,"final_known_seconds":0,"final_sd":127.97670385428015,"final_drift_shift":-58.402755819697724},"entry_side":1,"context_gap":null,"book_errors":[null,null],"books":[{"bid":0.92,"ask":0.93,"asks":[[0.93,331.06]],"received_ms":1789998400089,"observed_ms":1789998400072,"hash":"cc6d66253752205db4eb309343fb951b2b900720"},{"bid":0.07,"ask":0.08,"asks":[[0.08,779.09]],"received_ms":1789998400068,"observed_ms":1789998400060,"hash":"ea7644a93db0eafd5236e35d359fd361cfc4408c"}],"intents":{"pair_fast":{"kind":"first","side":1,"qty":5.0,"max_cost":0.47576},"pair_250":{"kind":"first","side":1,"qty":5.0,"max_cost":0.47576},"pair_add_fast":{"kind":"first","side":1,"qty":5.0,"max_cost":0.47576},"pair_add_250":{"kind":"first","side":1,"qty":5.0,"max_cost":0.47576}},"decision_ms":1789998400090,"feature_cutoff_ms":1789998400089,"request_ms":1789998400044,"inventory":{"pair_fast":{"qty":[0.0,0.0],"cash":0.0,"lots":[[],[]],"floor":0.0},"pair_250":{"qty":[0.0,0.0],"cash":0.0,"lots":[[],[]],"floor":0.0},"pair_add_fast":{"qty":[0.0,0.0],"cash":0.0,"lots":[[],[]],"floor":0.0},"pair_add_250":{"qty":[0.0,0.0],"cash":0.0,"lots":[[],[]],"floor":0.0}}}
{"kind":"decision","recorded_ms":1789998630055,"S":1789998600,"age":30,"signal":{},"entry_side":null,"context_gap":"incomplete or stale context","book_errors":[null,null],"books":[{"bid":0.83,"ask":0.84,"asks":[[0.84,1404.52]],"received_ms":1789998630047,"observed_ms":1789998630035,"hash":"239543ce5587f5e632853bcadea576fd09ac676c"},{"bid":0.16,"ask":0.17,"asks":[[0.17,144.0]],"received_ms":1789998630054,"observed_ms":1789998630041,"hash":"b985d8559d2c0bb6bb02820f8c90795e75544747"}],"intents":{"pair_fast":null,"pair_250":null,"pair_add_fast":null,"pair_add_250":null},"decision_ms":1789998630055,"feature_cutoff_ms":1789998630054,"request_ms":1789998630017,"inventory":{"pair_fast":{"qty":[0.0,0.0],"cash":0.0,"lots":[[],[]],"floor":0.0},"pair_250":{"qty":[0.0,0.0],"cash":0.0,"lots":[[],[]],"floor":0.0},"pair_add_fast":{"qty":[0.0,0.0],"cash":0.0,"lots":[[],[]],"floor":0.0},"pair_add_250":{"qty":[0.0,0.0],"cash":0.0,"lots":[[],[]],"floor":0.0}}}
{"kind":"decision","recorded_ms":1789998640057,"S":1789998600,"age":40,"signal":{},"entry_side":null,"context_gap":"incomplete or stale context","book_errors":[null,null],"books":[{"bid":0.82,"ask":0.83,"asks":[[0.83,1680.82]],"received_ms":1789998640054,"observed_ms":1789998640046,"hash":"0ff3d69f198ec99f7b5042201d3ac672c226585b"},{"bid":0.17,"ask":0.18,"asks":[[0.18,255.75]],"received_ms":1789998640056,"observed_ms":1789998640046,"hash":"c7bfc788fca488294e4dd5997f67b2552cc4fc1f"}],"intents":{"pair_fast":null,"pair_250":null,"pair_add_fast":null,"pair_add_250":null},"decision_ms":1789998640057,"feature_cutoff_ms":1789998640056,"request_ms":1789998640030,"inventory":{"pair_fast":{"qty":[0.0,0.0],"cash":0.0,"lots":[[],[]],"floor":0.0},"pair_250":{"qty":[0.0,0.0],"cash":0.0,"lots":[[],[]],"floor":0.0},"pair_add_fast":{"qty":[0.0,0.0],"cash":0.0,"lots":[[],[]],"floor":0.0},"pair_add_250":{"qty":[0.0,0.0],"cash":0.0,"lots":[[],[]],"floor":0.0}}}
{"kind":"decision","recorded_ms":1789998650074,"S":1789998600,"age":50,"signal":{},"entry_side":null,"context_gap":"incomplete or stale context","book_errors":[null,null],"books":[{"bid":0.87,"ask":0.88,"asks":[[0.88,1126.98]],"received_ms":1789998650053,"observed_ms":1789998650046,"hash":"e162566598705fd67c6542a99c7e29afe610ff62"},{"bid":0.12,"ask":0.13,"asks":[[0.13,21.53]],"received_ms":1789998650072,"observed_ms":1789998650061,"hash":"4ce99cf4a6c417d3ed31274ae5506b2c5cdcddf5"}],"intents":{"pair_fast":null,"pair_250":null,"pair_add_fast":null,"pair_add_250":null},"decision_ms":1789998650074,"feature_cutoff_ms":1789998650073,"request_ms":1789998650033,"inventory":{"pair_fast":{"qty":[0.0,0.0],"cash":0.0,"lots":[[],[]],"floor":0.0},"pair_250":{"qty":[0.0,0.0],"cash":0.0,"lots":[[],[]],"floor":0.0},"pair_add_fast":{"qty":[0.0,0.0],"cash":0.0,"lots":[[],[]],"floor":0.0},"pair_add_250":{"qty":[0.0,0.0],"cash":0.0,"lots":[[],[]],"floor":0.0}}}
{"kind":"decision","recorded_ms":1789998660093,"S":1789998600,"age":60,"signal":{},"entry_side":null,"context_gap":"incomplete or stale context","book_errors":[null,null],"books":[{"bid":0.9,"ask":0.91,"asks":[[0.91,938.53]],"received_ms":1789998660092,"observed_ms":1789998660080,"hash":"d4a030d14863437dcf4d4558d467e8250fe068e9"},{"bid":0.09,"ask":0.1,"asks":[[0.1,191.05]],"received_ms":1789998660091,"observed_ms":1789998660079,"hash":"0edb1fa249dc55c82ac8fa7851308c983251cf2c"}],"intents":{"pair_fast":null,"pair_250":null,"pair_add_fast":null,"pair_add_250":null},"decision_ms":1789998660093,"feature_cutoff_ms":1789998660093,"request_ms":1789998660049,"inventory":{"pair_fast":{"qty":[0.0,0.0],"cash":0.0,"lots":[[],[]],"floor":0.0},"pair_250":{"qty":[0.0,0.0],"cash":0.0,"lots":[[],[]],"floor":0.0},"pair_add_fast":{"qty":[0.0,0.0],"cash":0.0,"lots":[[],[]],"floor":0.0},"pair_add_250":{"qty":[0.0,0.0],"cash":0.0,"lots":[[],[]],"floor":0.0}}}
{"kind":"decision","recorded_ms":1789998670066,"S":1789998600,"age":70,"signal":{},"entry_side":null,"context_gap":"incomplete or stale context","book_errors":[null,null],"books":[{"bid":0.93,"ask":0.94,"asks":[[0.94,672.12]],"received_ms":1789998670065,"observed_ms":1789998670049,"hash":"092287808b136d1f129f61ffc0e85a3f53835730"},{"bid":0.06,"ask":0.07,"asks":[[0.07,361.79]],"received_ms":1789998670065,"observed_ms":1789998670050,"hash":"3c7693001bd74a52cc8c55aefd3882d98e3ec450"}],"intents":{"pair_fast":null,"pair_250":null,"pair_add_fast":null,"pair_add_250":null},"decision_ms":1789998670066,"feature_cutoff_ms":1789998670065,"request_ms":1789998670038,"inventory":{"pair_fast":{"qty":[0.0,0.0],"cash":0.0,"lots":[[],[]],"floor":0.0},"pair_250":{"qty":[0.0,0.0],"cash":0.0,"lots":[[],[]],"floor":0.0},"pair_add_fast":{"qty":[0.0,0.0],"cash":0.0,"lots":[[],[]],"floor":0.0},"pair_add_250":{"qty":[0.0,0.0],"cash":0.0,"lots":[[],[]],"floor":0.0}}}
{"kind":"decision","recorded_ms":1789998680081,"S":1789998600,"age":80,"signal":{},"entry_side":null,"context_gap":"incomplete or stale context","book_errors":[null,null],"books":[{"bid":0.94,"ask":0.95,"asks":[[0.95,292.12]],"received_ms":1789998680080,"observed_ms":1789998680068,"hash":"09eb1508a4ca00151a11f6c5609c6f085aec78b1"},{"bid":0.05,"ask":0.06,"asks":[[0.06,829.46]],"received_ms":1789998680072,"observed_ms":1789998680062,"hash":"11c237b7918db9e320ffbbbc5adf88e49eed05cb"}],"intents":{"pair_fast":null,"pair_250":null,"pair_add_fast":null,"pair_add_250":null},"decision_ms":1789998680081,"feature_cutoff_ms":1789998680080,"request_ms":1789998680040,"inventory":{"pair_fast":{"qty":[0.0,0.0],"cash":0.0,"lots":[[],[]],"floor":0.0},"pair_250":{"qty":[0.0,0.0],"cash":0.0,"lots":[[],[]],"floor":0.0},"pair_add_fast":{"qty":[0.0,0.0],"cash":0.0,"lots":[[],[]],"floor":0.0},"pair_add_250":{"qty":[0.0,0.0],"cash":0.0,"lots":[[],[]],"floor":0.0}}}
{"kind":"decision","recorded_ms":1789998690069,"S":1789998600,"age":90,"signal":{},"entry_side":null,"context_gap":"incomplete or stale context","book_errors":[null,null],"books":[{"bid":0.95,"ask":0.96,"asks":[[0.96,2168.5]],"received_ms":1789998690068,"observed_ms":1789998690049,"hash":"3d5f5338d78de6ad057ad5baf0282566cbda5a05"},{"bid":0.04,"ask":0.05,"asks":[[0.05,315.6]],"received_ms":1789998690047,"observed_ms":1789998690034,"hash":"2c7a21615d098c66690be50af97cae1acffe6996"}],"intents":{"pair_fast":null,"pair_250":null,"pair_add_fast":null,"pair_add_250":null},"decision_ms":1789998690069,"feature_cutoff_ms":1789998690068,"request_ms":1789998690005,"inventory":{"pair_fast":{"qty":[0.0,0.0],"cash":0.0,"lots":[[],[]],"floor":0.0},"pair_250":{"qty":[0.0,0.0],"cash":0.0,"lots":[[],[]],"floor":0.0},"pair_add_fast":{"qty":[0.0,0.0],"cash":0.0,"lots":[[],[]],"floor":0.0},"pair_add_250":{"qty":[0.0,0.0],"cash":0.0,"lots":[[],[]],"floor":0.0}}}
{"kind":"decision","recorded_ms":1789998700096,"S":1789998600,"age":100,"signal":{},"entry_side":null,"context_gap":"incomplete or stale context","book_errors":[null,null],"books":[{"bid":0.94,"ask":0.95,"asks":[[0.95,601.01]],"received_ms":1789998700078,"observed_ms":1789998700068,"hash":"2be1007d14e0ce6602deff5490a72a61d18a5db7"},{"bid":0.05,"ask":0.06,"asks":[[0.06,520.08]],"received_ms":1789998700095,"observed_ms":1789998700081,"hash":"3e0ad2d4daa26bfdd3979d0e730d81bcab02d4ac"}],"intents":{"pair_fast":null,"pair_250":null,"pair_add_fast":null,"pair_add_250":null},"decision_ms":1789998700096,"feature_cutoff_ms":1789998700095,"request_ms":1789998700044,"inventory":{"pair_fast":{"qty":[0.0,0.0],"cash":0.0,"lots":[[],[]],"floor":0.0},"pair_250":{"qty":[0.0,0.0],"cash":0.0,"lots":[[],[]],"floor":0.0},"pair_add_fast":{"qty":[0.0,0.0],"cash":0.0,"lots":[[],[]],"floor":0.0},"pair_add_250":{"qty":[0.0,0.0],"cash":0.0,"lots":[[],[]],"floor":0.0}}}
{"kind":"decision","recorded_ms":1789998710049,"S":1789998600,"age":110,"signal":{},"entry_side":null,"context_gap":"incomplete or stale context","book_errors":[null,null],"books":[{"bid":0.96,"ask":0.97,"asks":[[0.97,1937.37]],"received_ms":1789998710045,"observed_ms":1789998710035,"hash":"6191469b34ec7b8908bdd52b742ce9c8a9a4770c"},{"bid":0.03,"ask":0.04,"asks":[[0.04,130.12]],"received_ms":1789998710048,"observed_ms":1789998710039,"hash":"26b623f7a8611f9973b9f21678b6af7eb4564b33"}],"intents":{"pair_fast":null,"pair_250":null,"pair_add_fast":null,"pair_add_250":null},"decision_ms":1789998710049,"feature_cutoff_ms":1789998710048,"request_ms":1789998710019,"inventory":{"pair_fast":{"qty":[0.0,0.0],"cash":0.0,"lots":[[],[]],"floor":0.0},"pair_250":{"qty":[0.0,0.0],"cash":0.0,"lots":[[],[]],"floor":0.0},"pair_add_fast":{"qty":[0.0,0.0],"cash":0.0,"lots":[[],[]],"floor":0.0},"pair_add_250":{"qty":[0.0,0.0],"cash":0.0,"lots":[[],[]],"floor":0.0}}}
{"kind":"decision","recorded_ms":1789998720056,"S":1789998600,"age":120,"signal":{},"entry_side":null,"context_gap":"incomplete or stale context","book_errors":[null,null],"books":[{"bid":0.96,"ask":0.97,"asks":[[0.97,796.29]],"received_ms":1789998720055,"observed_ms":1789998720045,"hash":"920d4077d464bc3fb6feb9ec5b1c01fcce5364d8"},{"bid":0.03,"ask":0.04,"asks":[[0.04,94.2]],"received_ms":1789998720049,"observed_ms":1789998720039,"hash":"f2ea6d1cdf26285da4280917fd3575e3fa2fb8c5"}],"intents":{"pair_fast":null,"pair_250":null,"pair_add_fast":null,"pair_add_250":null},"decision_ms":1789998720056,"feature_cutoff_ms":1789998720056,"request_ms":1789998720023,"inventory":{"pair_fast":{"qty":[0.0,0.0],"cash":0.0,"lots":[[],[]],"floor":0.0},"pair_250":{"qty":[0.0,0.0],"cash":0.0,"lots":[[],[]],"floor":0.0},"pair_add_fast":{"qty":[0.0,0.0],"cash":0.0,"lots":[[],[]],"floor":0.0},"pair_add_250":{"qty":[0.0,0.0],"cash":0.0,"lots":[[],[]],"floor":0.0}}}
{"kind":"decision","recorded_ms":1789998730043,"S":1789998600,"age":130,"signal":{"rsi14":86.84286880043527,"volume_ratio":1.791763002272077,"taker_buy_fraction":0.5841906854652281,"volume5":410.90662,"return1":6.453666511886182,"return5":43.27560725176147,"return15":84.62316267916964,"bollinger_z":2.3399055600294854,"bar_close_ms":1789998719999,"ref":85346.42241923072,"reference_received_ms":1789998601650,"spot":85759.96540192945,"twap":85697.36110542237,"sigma":9.548533900254325,"spot_z":3.322103476123627,"twap_z":2.8191861017573503,"momentum":1.9339708741769166,"decision_ms":1789998730042,"momentum30":0.9735298597166718,"momentum60":1.3172308435209854,"spot_twap_gap":0.8464315056314486,"range60":1.3172308435209854,"final_mean":85759.96540192945,"final_z":3.799115105664648,"final_up_prob":0.9999273931790901,"final_drift_up_prob":1.0,"final_known_seconds":0,"final_sd":108.85244884581873,"final_drift_shift":817.3053677378387},"entry_side":null,"context_gap":null,"book_errors":[null,null],"books":[{"bid":0.98,"ask":0.99,"asks":[[0.99,4047.52]],"received_ms":1789998730035,"observed_ms":1789998730025,"hash":"687d9ad88e909e589b0e724ac56ae3a9c0cc74ac"},{"bid":0.01,"ask":0.02,"asks":[[0.02,757.41]],"received_ms":1789998730041,"observed_ms":1789998730028,"hash":"59945af06eac7fd21bdadba5b77e5bf6428611b9"}],"intents":{"pair_fast":null,"pair_250":null,"pair_add_fast":null,"pair_add_250":null},"decision_ms":1789998730043,"feature_cutoff_ms":1789998730042,"request_ms":1789998730006,"inventory":{"pair_fast":{"qty":[0.0,0.0],"cash":0.0,"lots":[[],[]],"floor":0.0},"pair_250":{"qty":[0.0,0.0],"cash":0.0,"lots":[[],[]],"floor":0.0},"pair_add_fast":{"qty":[0.0,0.0],"cash":0.0,"lots":[[],[]],"floor":0.0},"pair_add_250":{"qty":[0.0,0.0],"cash":0.0,"lots":[[],[]],"floor":0.0}}}
{"kind":"decision","recorded_ms":1789998740065,"S":1789998600,"age":140,"signal":{"rsi14":86.84286880043527,"volume_ratio":1.791763002272077,"taker_buy_fraction":0.5841906854652281,"volume5":410.90662,"return1":6.453666511886182,"return5":43.27560725176147,"return15":84.62316267916964,"bollinger_z":2.3399055600294854,"bar_close_ms":1789998719999,"ref":85346.42241923072,"reference_received_ms":1789998601650,"spot":85779.23730745123,"twap":85714.99158863872,"sigma":10.006808248230605,"spot_z":3.4200582141249005,"twap_z":2.912395228568953,"momentum":0.6090165294329517,"decision_ms":1789998740064,"momentum30":1.1489033164079128,"momentum60":1.0421824787311025,"spot_twap_gap":0.8288443656013869,"range60":1.557239655686729,"final_mean":85779.23730745123,"final_z":3.9494064685990433,"final_up_prob":0.999960827391928,"final_drift_up_prob":0.9999999997732345,"final_known_seconds":0,"final_sd":109.58985651685629,"final_drift_shift":250.41143179725628},"entry_side":null,"context_gap":null,"book_errors":[null,null],"books":[{"bid":0.98,"ask":0.99,"asks":[[0.99,773.12]],"received_ms":1789998740043,"observed_ms":1789998740029,"hash":"08a38dec7dda35b6842e610f9a34d22a32dc0695"},{"bid":0.01,"ask":0.02,"asks":[[0.02,1322.85]],"received_ms":1789998740064,"observed_ms":1789998740052,"hash":"db57d8fc3f2848d39b432a8cafdb842c1e48fd64"}],"intents":{"pair_fast":null,"pair_250":null,"pair_add_fast":null,"pair_add_250":null},"decision_ms":1789998740065,"feature_cutoff_ms":1789998740064,"request_ms":1789998740018,"inventory":{"pair_fast":{"qty":[0.0,0.0],"cash":0.0,"lots":[[],[]],"floor":0.0},"pair_250":{"qty":[0.0,0.0],"cash":0.0,"lots":[[],[]],"floor":0.0},"pair_add_fast":{"qty":[0.0,0.0],"cash":0.0,"lots":[[],[]],"floor":0.0},"pair_add_250":{"qty":[0.0,0.0],"cash":0.0,"lots":[[],[]],"floor":0.0}}}
{"kind":"decision","recorded_ms":1789998750075,"S":1789998600,"age":150,"signal":{"rsi14":86.84286880043527,"volume_ratio":1.791763002272077,"taker_buy_fraction":0.5841906854652281,"volume5":410.90662,"return1":6.453666511886182,"return5":43.27560725176147,"return15":84.62316267916964,"bollinger_z":2.3399055600294854,"bar_close_ms":1789998719999,"ref":85346.42241923072,"reference_received_ms":1789998601650,"spot":85761.094,"twap":85730.18640458751,"sigma":9.844615107755686,"spot_z":3.440068208538933,"twap_z":3.183662316956908,"momentum":-0.5827975518250174,"decision_ms":1789998750074,"momentum30":1.069792336461317,"momentum60":0.8526288765336489,"spot_twap_gap":0.40531329731577065,"range60":1.296197280863276,"final_mean":85761.094,"final_z":4.017494752858187,"final_up_prob":0.9999705899276627,"final_drift_up_prob":0.9718976453275651,"final_known_seconds":0,"final_sd":103.21645858386495,"final_drift_shift":-217.58542915419395},"entry_side":1,"context_gap":null,"book_errors":[null,null],"books":[{"bid":0.98,"ask":0.99,"asks":[[0.99,422.73]],"received_ms":1789998750066,"observed_ms":1789998750054,"hash":"0b4489f1ddfcfcbad9ecb5d8cccfb380a11f2135"},{"bid":0.01,"ask":0.02,"asks":[[0.02,1715.88]],"received_ms":1789998750074,"observed_ms":1789998750054,"hash":"911e8480f352feb8ad54b3df230368c7b901a681"}],"intents":{"pair_fast":{"kind":"first","side":1,"qty":5.0,"max_cost":0.15686},"pair_250":{"kind":"first","side":1,"qty":5.0,"max_cost":0.15686},"pair_add_fast":{"kind":"first","side":1,"qty":5.0,"max_cost":0.15686},"pair_add_250":{"kind":"first","side":1,"qty":5.0,"max_cost":0.15686}},"decision_ms":1789998750075,"feature_cutoff_ms":1789998750074,"request_ms":1789998750037,"inventory":{"pair_fast":{"qty":[0.0,0.0],"cash":0.0,"lots":[[],[]],"floor":0.0},"pair_250":{"qty":[0.0,0.0],"cash":0.0,"lots":[[],[]],"floor":0.0},"pair_add_fast":{"qty":[0.0,0.0],"cash":0.0,"lots":[[],[]],"floor":0.0},"pair_add_250":{"qty":[0.0,0.0],"cash":0.0,"lots":[[],[]],"floor":0.0}}}
{"kind":"decision","recorded_ms":1789998930040,"S":1789998900,"age":30,"signal":{},"entry_side":null,"context_gap":"incomplete or stale context","book_errors":[null,null],"books":[{"bid":0.46,"ask":0.47,"asks":[[0.47,366.49]],"received_ms":1789998930037,"observed_ms":1789998930028,"hash":"5da631dcc3334f94985c8b7d9b44e659d5ee4446"},{"bid":0.53,"ask":0.54,"asks":[[0.54,293.27]],"received_ms":1789998930039,"observed_ms":1789998930031,"hash":"5e719ca8c23a2897cc3744c57e7e9f35a3c8502b"}],"intents":{"pair_fast":null,"pair_250":null,"pair_add_fast":null,"pair_add_250":null},"decision_ms":1789998930040,"feature_cutoff_ms":1789998930039,"request_ms":1789998930006,"inventory":{"pair_fast":{"qty":[0.0,0.0],"cash":0.0,"lots":[[],[]],"floor":0.0},"pair_250":{"qty":[0.0,0.0],"cash":0.0,"lots":[[],[]],"floor":0.0},"pair_add_fast":{"qty":[0.0,0.0],"cash":0.0,"lots":[[],[]],"floor":0.0},"pair_add_250":{"qty":[0.0,0.0],"cash":0.0,"lots":[[],[]],"floor":0.0}}}
{"kind":"decision","recorded_ms":1789998940041,"S":1789998900,"age":40,"signal":{},"entry_side":null,"context_gap":"incomplete or stale context","book_errors":[null,null],"books":[{"bid":0.44,"ask":0.45,"asks":[[0.45,460.0]],"received_ms":1789998940036,"observed_ms":1789998940027,"hash":"33ff084e2e4e44328b28d0e74899f804c4c3a115"},{"bid":0.55,"ask":0.56,"asks":[[0.56,283.54]],"received_ms":1789998940040,"observed_ms":1789998940032,"hash":"a95b8a0e3809c476d3f39636149c27f69b57d4af"}],"intents":{"pair_fast":null,"pair_250":null,"pair_add_fast":null,"pair_add_250":null},"decision_ms":1789998940041,"feature_cutoff_ms":1789998940041,"request_ms":1789998940013,"inventory":{"pair_fast":{"qty":[0.0,0.0],"cash":0.0,"lots":[[],[]],"floor":0.0},"pair_250":{"qty":[0.0,0.0],"cash":0.0,"lots":[[],[]],"floor":0.0},"pair_add_fast":{"qty":[0.0,0.0],"cash":0.0,"lots":[[],[]],"floor":0.0},"pair_add_250":{"qty":[0.0,0.0],"cash":0.0,"lots":[[],[]],"floor":0.0}}}
{"kind":"decision","recorded_ms":1789998950069,"S":1789998900,"age":50,"signal":{},"entry_side":null,"context_gap":"incomplete or stale context","book_errors":[null,null],"books":[{"bid":0.48,"ask":0.49,"asks":[[0.49,12.0]],"received_ms":1789998950068,"observed_ms":1789998950058,"hash":"5dcbf7e7c1f0505d37b1ec80c301814e149b34ea"},{"bid":0.51,"ask":0.53,"asks":[[0.53,1873.17]],"received_ms":1789998950045,"observed_ms":1789998950025,"hash":"bf70eb7b0ee6c5d1223c356d5f5cb270f9cf9210"}],"intents":{"pair_fast":null,"pair_250":null,"pair_add_fast":null,"pair_add_250":null},"decision_ms":1789998950069,"feature_cutoff_ms":1789998950069,"request_ms":1789998950019,"inventory":{"pair_fast":{"qty":[0.0,0.0],"cash":0.0,"lots":[[],[]],"floor":0.0},"pair_250":{"qty":[0.0,0.0],"cash":0.0,"lots":[[],[]],"floor":0.0},"pair_add_fast":{"qty":[0.0,0.0],"cash":0.0,"lots":[[],[]],"floor":0.0},"pair_add_250":{"qty":[0.0,0.0],"cash":0.0,"lots":[[],[]],"floor":0.0}}}
{"kind":"decision","recorded_ms":1789998960078,"S":1789998900,"age":60,"signal":{},"entry_side":null,"context_gap":"incomplete or stale context","book_errors":[null,null],"books":[{"bid":0.44,"ask":0.45,"asks":[[0.45,894.88]],"received_ms":1789998960069,"observed_ms":1789998960061,"hash":"1721745c9800df2d28450dec0fa0a0af79379903"},{"bid":0.55,"ask":0.56,"asks":[[0.56,1467.64]],"received_ms":1789998960077,"observed_ms":1789998960067,"hash":"23caa818f3f66fa6a814da51b9be20b24429249d"}],"intents":{"pair_fast":null,"pair_250":null,"pair_add_fast":null,"pair_add_250":null},"decision_ms":1789998960078,"feature_cutoff_ms":1789998960078,"request_ms":1789998960044,"inventory":{"pair_fast":{"qty":[0.0,0.0],"cash":0.0,"lots":[[],[]],"floor":0.0},"pair_250":{"qty":[0.0,0.0],"cash":0.0,"lots":[[],[]],"floor":0.0},"pair_add_fast":{"qty":[0.0,0.0],"cash":0.0,"lots":[[],[]],"floor":0.0},"pair_add_250":{"qty":[0.0,0.0],"cash":0.0,"lots":[[],[]],"floor":0.0}}}
{"kind":"decision","recorded_ms":1789998970063,"S":1789998900,"age":70,"signal":{},"entry_side":null,"context_gap":"incomplete or stale context","book_errors":[null,null],"books":[{"bid":0.61,"ask":0.62,"asks":[[0.62,279.26]],"received_ms":1789998970062,"observed_ms":1789998970048,"hash":"465fd2141029ef2e0efb03da6a5dfc126e79f8ea"},{"bid":0.38,"ask":0.39,"asks":[[0.39,278.9]],"received_ms":1789998970053,"observed_ms":1789998970042,"hash":"34ab29e4a4c4ba44585505f1568e41923221e137"}],"intents":{"pair_fast":null,"pair_250":null,"pair_add_fast":null,"pair_add_250":null},"decision_ms":1789998970063,"feature_cutoff_ms":1789998970062,"request_ms":1789998970028,"inventory":{"pair_fast":{"qty":[0.0,0.0],"cash":0.0,"lots":[[],[]],"floor":0.0},"pair_250":{"qty":[0.0,0.0],"cash":0.0,"lots":[[],[]],"floor":0.0},"pair_add_fast":{"qty":[0.0,0.0],"cash":0.0,"lots":[[],[]],"floor":0.0},"pair_add_250":{"qty":[0.0,0.0],"cash":0.0,"lots":[[],[]],"floor":0.0}}}
{"kind":"decision","recorded_ms":1789998980089,"S":1789998900,"age":80,"signal":{},"entry_side":null,"context_gap":"incomplete or stale context","book_errors":[null,null],"books":[{"bid":0.59,"ask":0.6,"asks":[[0.6,273.94]],"received_ms":1789998980088,"observed_ms":1789998980073,"hash":"a949f5f8720e59af40f959e9adca27f3fd09de43"},{"bid":0.4,"ask":0.41,"asks":[[0.41,449.41]],"received_ms":1789998980075,"observed_ms":1789998980061,"hash":"e9b5e620f93748261cdaa350930bee334523b26d"}],"intents":{"pair_fast":null,"pair_250":null,"pair_add_fast":null,"pair_add_250":null},"decision_ms":1789998980089,"feature_cutoff_ms":1789998980088,"request_ms":1789998980037,"inventory":{"pair_fast":{"qty":[0.0,0.0],"cash":0.0,"lots":[[],[]],"floor":0.0},"pair_250":{"qty":[0.0,0.0],"cash":0.0,"lots":[[],[]],"floor":0.0},"pair_add_fast":{"qty":[0.0,0.0],"cash":0.0,"lots":[[],[]],"floor":0.0},"pair_add_250":{"qty":[0.0,0.0],"cash":0.0,"lots":[[],[]],"floor":0.0}}}
{"kind":"decision","recorded_ms":1789998990046,"S":1789998900,"age":90,"signal":{},"entry_side":null,"context_gap":"incomplete or stale context","book_errors":[null,null],"books":[{"bid":0.56,"ask":0.57,"asks":[[0.57,353.29]],"received_ms":1789998990044,"observed_ms":1789998990037,"hash":"4248d8da8222021f30b1ea60d48a1f867951fdfa"},{"bid":0.43,"ask":0.44,"asks":[[0.44,130.77]],"received_ms":1789998990045,"observed_ms":1789998990034,"hash":"e1ea4c66e8e970485ffb5a95e0f80085ae21ff0c"}],"intents":{"pair_fast":null,"pair_250":null,"pair_add_fast":null,"pair_add_250":null},"decision_ms":1789998990046,"feature_cutoff_ms":1789998990045,"request_ms":1789998990013,"inventory":{"pair_fast":{"qty":[0.0,0.0],"cash":0.0,"lots":[[],[]],"floor":0.0},"pair_250":{"qty":[0.0,0.0],"cash":0.0,"lots":[[],[]],"floor":0.0},"pair_add_fast":{"qty":[0.0,0.0],"cash":0.0,"lots":[[],[]],"floor":0.0},"pair_add_250":{"qty":[0.0,0.0],"cash":0.0,"lots":[[],[]],"floor":0.0}}}
{"kind":"decision","recorded_ms":1789999000060,"S":1789998900,"age":100,"signal":{},"entry_side":null,"context_gap":"incomplete or stale context","book_errors":[null,null],"books":[{"bid":0.73,"ask":0.74,"asks":[[0.74,102.07]],"received_ms":1789999000059,"observed_ms":1789999000049,"hash":"6c2b617d56f09c3cbb83962a55eed4bac3bf553c"},{"bid":0.26,"ask":0.27,"asks":[[0.27,190.06]],"received_ms":1789999000048,"observed_ms":1789999000037,"hash":"b9017b95a83c3bb5224a9303907f441309e6866e"}],"intents":{"pair_fast":null,"pair_250":null,"pair_add_fast":null,"pair_add_250":null},"decision_ms":1789999000060,"feature_cutoff_ms":1789999000059,"request_ms":1789999000020,"inventory":{"pair_fast":{"qty":[0.0,0.0],"cash":0.0,"lots":[[],[]],"floor":0.0},"pair_250":{"qty":[0.0,0.0],"cash":0.0,"lots":[[],[]],"floor":0.0},"pair_add_fast":{"qty":[0.0,0.0],"cash":0.0,"lots":[[],[]],"floor":0.0},"pair_add_250":{"qty":[0.0,0.0],"cash":0.0,"lots":[[],[]],"floor":0.0}}}
{"kind":"decision","recorded_ms":1789999010060,"S":1789998900,"age":110,"signal":{"rsi14":67.02624184407247,"volume_ratio":0.5522464483072471,"taker_buy_fraction":0.4505294021120663,"volume5":299.52185,"return1":4.455480480911828,"return5":-27.333266780057247,"return15":43.782381085075784,"bollinger_z":0.6513942277031034,"bar_close_ms":1789998959999,"ref":85426.38316465008,"reference_received_ms":1789998901464,"spot":85555.80485750611,"twap":85464.97585213347,"sigma":12.467880150504717,"spot_z":0.7531909571418333,"twap_z":0.22459653078892564,"momentum":0.9394435032333608,"decision_ms":1789999010059,"momentum30":1.0502563562163594,"momentum60":1.4819222528745017,"spot_twap_gap":0.9404946174071395,"range60":1.7529407004299735,"final_mean":85555.80485750611,"final_z":0.8477235649510898,"final_up_prob":0.8017040302532165,"final_drift_up_prob":0.9999988666683959,"final_known_seconds":0,"final_sd":152.66968880769713,"final_drift_shift":592.4109717448267},"entry_side":null,"context_gap":null,"book_errors":[null,null],"books":[{"bid":0.78,"ask":0.79,"asks":[[0.79,140.28]],"received_ms":1789999010057,"observed_ms":1789999010051,"hash":"6d85e35027459f7e130668d52d3d8cc1ccece355"},{"bid":0.21,"ask":0.22,"asks":[[0.22,442.41]],"received_ms":1789999010059,"observed_ms":1789999010052,"hash":"1b2b2060633f66c9709e7cf55062e46058a9389d"}],"intents":{"pair_fast":null,"pair_250":null,"pair_add_fast":null,"pair_add_250":null},"decision_ms":1789999010060,"feature_cutoff_ms":1789999010059,"request_ms":1789999010033,"inventory":{"pair_fast":{"qty":[0.0,0.0],"cash":0.0,"lots":[[],[]],"floor":0.0},"pair_250":{"qty":[0.0,0.0],"cash":0.0,"lots":[[],[]],"floor":0.0},"pair_add_fast":{"qty":[0.0,0.0],"cash":0.0,"lots":[[],[]],"floor":0.0},"pair_add_250":{"qty":[0.0,0.0],"cash":0.0,"lots":[[],[]],"floor":0.0}}}
{"kind":"decision","recorded_ms":1789999020065,"S":1789998900,"age":120,"signal":{"rsi14":67.02624184407247,"volume_ratio":0.5522464483072471,"taker_buy_fraction":0.4505294021120663,"volume5":299.52185,"return1":4.455480480911828,"return5":-27.333266780057247,"return15":43.782381085075784,"bollinger_z":0.6513942277031034,"bar_close_ms":1789998959999,"ref":85426.38316465008,"reference_received_ms":1789998901464,"spot":85555.36888042233,"twap":85487.22153924897,"sigma":11.774192753290613,"spot_z":0.8166791078360042,"twap_z":0.385201021618136,"momentum":-0.011709342808118138,"decision_ms":1789999020064,"momentum30":1.0772426981792582,"momentum60":1.8514364951531141,"spot_twap_gap":0.7472090953014644,"range60":1.885761485683347,"final_mean":85555.36888042233,"final_z":0.9260741223646157,"final_up_prob":0.8227962694137227,"final_drift_up_prob":0.8103377531137193,"final_known_seconds":0,"final_sd":139.28228060504384,"final_drift_shift":-6.53686600804941},"entry_side":1,"context_gap":null,"book_errors":[null,null],"books":[{"bid":0.84,"ask":0.85,"asks":[[0.85,223.45]],"received_ms":1789999020063,"observed_ms":1789999020054,"hash":"34da2b1f2e6eb1116f988eb79f0dd7b825080559"},{"bid":0.15,"ask":0.16,"asks":[[0.16,926.97]],"received_ms":1789999020064,"observed_ms":1789999020054,"hash":"c228800783ce95c479402cfe6d188d905d37ab42"}],"intents":{"pair_fast":{"kind":"first","side":1,"qty":5.0,"max_cost":0.8970400000000001},"pair_250":{"kind":"first","side":1,"qty":5.0,"max_cost":0.8970400000000001},"pair_add_fast":{"kind":"first","side":1,"qty":5.0,"max_cost":0.8970400000000001},"pair_add_250":{"kind":"first","side":1,"qty":5.0,"max_cost":0.8970400000000001}},"decision_ms":1789999020065,"feature_cutoff_ms":1789999020064,"request_ms":1789999020034,"inventory":{"pair_fast":{"qty":[0.0,0.0],"cash":0.0,"lots":[[],[]],"floor":0.0},"pair_250":{"qty":[0.0,0.0],"cash":0.0,"lots":[[],[]],"floor":0.0},"pair_add_fast":{"qty":[0.0,0.0],"cash":0.0,"lots":[[],[]],"floor":0.0},"pair_add_250":{"qty":[0.0,0.0],"cash":0.0,"lots":[[],[]],"floor":0.0}}}
{"kind":"decision","recorded_ms":1789999230054,"S":1789999200,"age":30,"signal":{"rsi14":58.5374817224307,"volume_ratio":0.707748511582004,"taker_buy_fraction":0.49491660345954985,"volume5":142.45495,"return1":-2.835034236871554,"return5":6.912662926714979,"return15":45.13589794531915,"bollinger_z":0.34135036641209054,"bar_close_ms":1789999199999,"ref":85408.50237928922,"reference_received_ms":1789999201674,"spot":85459.55170358,"twap":85415.73366541565,"sigma":6.039797028500788,"spot_z":0.5144325037832396,"twap_z":0.0728708690913519,"momentum":1.7503500002634478,"decision_ms":1789999230053,"momentum30":1.534642764373412,"momentum60":1.4427104788792746,"spot_twap_gap":0.9366017393916832,"range60":1.4486752383563295,"final_mean":85459.55170358,"final_z":0.5573830784586266,"final_up_prob":0.711367137818911,"final_drift_up_prob":1.0,"final_known_seconds":0,"final_sd":91.58750285701856,"final_drift_shift":802.1628917421256},"entry_side":null,"context_gap":null,"book_errors":[null,null],"books":[{"bid":0.62,"ask":0.63,"asks":[[0.63,163.0]],"received_ms":1789999230053,"observed_ms":1789999230045,"hash":"5ff4cff5a4dca6e451b1f8b783c3e5398e5517d4"},{"bid":0.37,"ask":0.38,"asks":[[0.38,1930.69]],"received_ms":1789999230047,"observed_ms":1789999230037,"hash":"f8f9f7e4d91581b37ef5bcf099b9eddc7e87deb3"}],"intents":{"pair_fast":null,"pair_250":null,"pair_add_fast":null,"pair_add_250":null},"decision_ms":1789999230054,"feature_cutoff_ms":1789999230053,"request_ms":1789999230022,"inventory":{"pair_fast":{"qty":[0.0,0.0],"cash":0.0,"lots":[[],[]],"floor":0.0},"pair_250":{"qty":[0.0,0.0],"cash":0.0,"lots":[[],[]],"floor":0.0},"pair_add_fast":{"qty":[0.0,0.0],"cash":0.0,"lots":[[],[]],"floor":0.0},"pair_add_250":{"qty":[0.0,0.0],"cash":0.0,"lots":[[],[]],"floor":0.0}}}
{"kind":"decision","recorded_ms":1789999240086,"S":1789999200,"age":40,"signal":{"rsi14":58.5374817224307,"volume_ratio":0.707748511582004,"taker_buy_fraction":0.49491660345954985,"volume5":142.45495,"return1":-2.835034236871554,"return5":6.912662926714979,"return15":45.13589794531915,"bollinger_z":0.34135036641209054,"bar_close_ms":1789999199999,"ref":85408.50237928922,"reference_received_ms":1789999201674,"spot":85427.96404374,"twap":85424.1560568441,"sigma":6.847701775053443,"spot_z":0.17628666847254876,"twap_z":0.14179335341405683,"momentum":-1.4587222739890782,"decision_ms":1789999240085,"momentum30":-0.052854297585752545,"momentum60":0.6627937322384924,"spot_twap_gap":0.07179182308085151,"range60":1.2583146068560924,"final_mean":85427.96404374,"final_z":0.19164951120228038,"final_up_prob":0.5759916215152633,"final_drift_up_prob":1.7001400287597335e-12,"final_known_seconds":0,"final_sd":101.54820812579933,"final_drift_shift":-726.2476810910093},"entry_side":null,"context_gap":null,"book_errors":[null,null],"books":[{"bid":0.5,"ask":0.51,"asks":[[0.51,687.67]],"received_ms":1789999240056,"observed_ms":1789999240047,"hash":"e1f0a33b43b43c12f615f6ec4455f3ae9205bc42"},{"bid":0.49,"ask":0.5,"asks":[[0.5,97.5]],"received_ms":1789999240085,"observed_ms":1789999240068,"hash":"c35fa2f150918876fcd02a427d2aa08614caeb12"}],"intents":{"pair_fast":null,"pair_250":null,"pair_add_fast":null,"pair_add_250":null},"decision_ms":1789999240086,"feature_cutoff_ms":1789999240085,"request_ms":1789999240027,"inventory":{"pair_fast":{"qty":[0.0,0.0],"cash":0.0,"lots":[[],[]],"floor":0.0},"pair_250":{"qty":[0.0,0.0],"cash":0.0,"lots":[[],[]],"floor":0.0},"pair_add_fast":{"qty":[0.0,0.0],"cash":0.0,"lots":[[],[]],"floor":0.0},"pair_add_250":{"qty":[0.0,0.0],"cash":0.0,"lots":[[],[]],"floor":0.0}}}
{"kind":"decision","recorded_ms":1789999250036,"S":1789999200,"age":50,"signal":{"rsi14":58.5374817224307,"volume_ratio":0.707748511582004,"taker_buy_fraction":0.49491660345954985,"volume5":142.45495,"return1":-2.835034236871554,"return5":6.912662926714979,"return15":45.13589794531915,"bollinger_z":0.34135036641209054,"bar_close_ms":1789999199999,"ref":85408.50237928922,"reference_received_ms":1789999201674,"spot":85413.89561358745,"twap":85427.19057916067,"sigma":7.090660268805611,"spot_z":0.04810863209448074,"twap_z":0.16670214613500622,"momentum":-0.6274208705324518,"decision_ms":1789999250035,"momentum30":-0.3147824920905895,"momentum60":0.16738507257563437,"spot_twap_gap":-0.24206105074126386,"range60":0.9986441725310374,"final_mean":85413.89561358745,"final_z":0.05249152098031411,"final_up_prob":0.520931474350114,"final_drift_up_prob":0.0015412017677623457,"final_known_seconds":0,"final_sd":102.74486617090832,"final_drift_shift":-309.4562237297515},"entry_side":null,"context_gap":null,"book_errors":[null,null],"books":[{"bid":0.47,"ask":0.48,"asks":[[0.48,215.04]],"received_ms":1789999250034,"observed_ms":1789999250024,"hash":"81c6e7ea6e56701901e2b24f4bdf4c0763dd9209"},{"bid":0.52,"ask":0.53,"asks":[[0.53,586.02]],"received_ms":1789999250035,"observed_ms":1789999250027,"hash":"e42b622f402ba72132480703020a3b991de0f442"}],"intents":{"pair_fast":null,"pair_250":null,"pair_add_fast":null,"pair_add_250":null},"decision_ms":1789999250036,"feature_cutoff_ms":1789999250035,"request_ms":1789999250009,"inventory":{"pair_fast":{"qty":[0.0,0.0],"cash":0.0,"lots":[[],[]],"floor":0.0},"pair_250":{"qty":[0.0,0.0],"cash":0.0,"lots":[[],[]],"floor":0.0},"pair_add_fast":{"qty":[0.0,0.0],"cash":0.0,"lots":[[],[]],"floor":0.0},"pair_add_250":{"qty":[0.0,0.0],"cash":0.0,"lots":[[],[]],"floor":0.0}}}
{"kind":"decision","recorded_ms":1789999260042,"S":1789999200,"age":60,"signal":{"rsi14":58.5374817224307,"volume_ratio":0.707748511582004,"taker_buy_fraction":0.49491660345954985,"volume5":142.45495,"return1":-2.835034236871554,"return5":6.912662926714979,"return15":45.13589794531915,"bollinger_z":0.34135036641209054,"bar_close_ms":1789999199999,"ref":85408.50237928922,"reference_received_ms":1789999201674,"spot":85398.65009820317,"twap":85425.95309240464,"sigma":7.238279572649679,"spot_z":-0.08786844051257768,"twap_z":0.15563572881173757,"momentum":-0.6660498842793006,"decision_ms":1789999260041,"momentum30":-1.5361469401840122,"momentum60":-0.18073902841008022,"spot_twap_gap":-0.48696673835519544,"range60":1.1654598472366466,"final_mean":85398.65009820317,"final_z":-0.09625669859892311,"final_up_prob":0.4616583504246787,"final_drift_up_prob":0.0006330265796379853,"final_known_seconds":0,"final_sd":102.35423850444828,"final_drift_shift":-320.09331662535},"entry_side":null,"context_gap":null,"book_errors":[null,null],"books":[{"bid":0.55,"ask":0.56,"asks":[[0.56,51.82]],"received_ms":1789999260039,"observed_ms":1789999259962,"hash":"e36470925ccadde7794b606661ace210250d86c8"},{"bid":0.44,"ask":0.45,"asks":[[0.45,324.0]],"received_ms":1789999260040,"observed_ms":1789999259962,"hash":"c9986c78a73780ff76310fa58adefa17cbc6ee51"}],"intents":{"pair_fast":null,"pair_250":null,"pair_add_fast":null,"pair_add_250":null},"decision_ms":1789999260042,"feature_cutoff_ms":1789999260041,"request_ms":1789999260009,"inventory":{"pair_fast":{"qty":[0.0,0.0],"cash":0.0,"lots":[[],[]],"floor":0.0},"pair_250":{"qty":[0.0,0.0],"cash":0.0,"lots":[[],[]],"floor":0.0},"pair_add_fast":{"qty":[0.0,0.0],"cash":0.0,"lots":[[],[]],"floor":0.0},"pair_add_250":{"qty":[0.0,0.0],"cash":0.0,"lots":[[],[]],"floor":0.0}}}
{"kind":"decision","recorded_ms":1789999270079,"S":1789999200,"age":70,"signal":{"rsi14":54.163068108939754,"volume_ratio":0.36053333555279954,"taker_buy_fraction":0.4903968605488818,"volume5":131.76316,"return1":-0.6763353762248734,"return5":1.7821086124401626,"return15":24.875802358420835,"bollinger_z":0.2405190723362708,"bar_close_ms":1789999259999,"ref":85408.50237928922,"reference_received_ms":1789999201674,"spot":85454.20838851236,"twap":85426.9017460832,"sigma":9.599273908509163,"spot_z":0.31401085006754414,"twap_z":0.12640790359699333,"momentum":1.830250308058689,"decision_ms":1789999270078,"momentum30":0.49915649092389813,"momentum60":0.32629622648770684,"spot_twap_gap":0.3672436491098676,"range60":0.9180242257642498,"final_mean":85454.20838851236,"final_z":0.3454993871518549,"final_up_prob":0.6351405145382734,"final_drift_up_prob":1.0,"final_known_seconds":0,"final_sd":132.28969695118906,"final_drift_shift":1110.7324511378079},"entry_side":null,"context_gap":null,"book_errors":[null,null],"books":[{"bid":0.61,"ask":0.62,"asks":[[0.62,1168.99]],"received_ms":1789999270066,"observed_ms":1789999270055,"hash":"7c6d53452dac14940519d0e5359fb8ee85ddb6ad"},{"bid":0.38,"ask":0.39,"asks":[[0.39,75.18]],"received_ms":1789999270078,"observed_ms":1789999270069,"hash":"baa4664f5669db537e4d2d5f46cbc21bb48f5e23"}],"intents":{"pair_fast":null,"pair_250":null,"pair_add_fast":null,"pair_add_250":null},"decision_ms":1789999270079,"feature_cutoff_ms":1789999270078,"request_ms":1789999270040,"inventory":{"pair_fast":{"qty":[0.0,0.0],"cash":0.0,"lots":[[],[]],"floor":0.0},"pair_250":{"qty":[0.0,0.0],"cash":0.0,"lots":[[],[]],"floor":0.0},"pair_add_fast":{"qty":[0.0,0.0],"cash":0.0,"lots":[[],[]],"floor":0.0},"pair_add_250":{"qty":[0.0,0.0],"cash":0.0,"lots":[[],[]],"floor":0.0}}}
{"kind":"decision","recorded_ms":1789999280038,"S":1789999200,"age":80,"signal":{"rsi14":54.163068108939754,"volume_ratio":0.36053333555279954,"taker_buy_fraction":0.4903968605488818,"volume5":131.76316,"return1":-0.6763353762248734,"return5":1.7821086124401626,"return15":24.875802358420835,"bollinger_z":0.2405190723362708,"bar_close_ms":1789999259999,"ref":85408.50237928922,"reference_received_ms":1789999201674,"spot":85468.2122022149,"twap":85429.47031691129,"sigma":9.717300424615987,"spot_z":0.41430992415645973,"twap_z":0.1454907119173931,"momentum":0.4557227346447225,"decision_ms":1789999280037,"momentum30":1.020531064458305,"momentum60":0.559205515682291,"spot_twap_gap":0.5147063142538628,"range60":0.9831938247877798,"final_mean":85468.2122022149,"final_z":0.4580454160565055,"final_up_prob":0.6765400935478507,"final_drift_up_prob":0.9937682216712764,"final_known_seconds":0,"final_sd":130.3578659071546,"final_drift_shift":266.0206463203688},"entry_side":null,"context_gap":null,"book_errors":[null,null],"books":[{"bid":0.75,"ask":0.76,"asks":[[0.76,201.96]],"received_ms":1789999280037,"observed_ms":1789999280019,"hash":"fcb941daa201cf4eb3d68364feab2af68a5c0b6c"},{"bid":0.24,"ask":0.25,"asks":[[0.25,1317.19]],"received_ms":1789999280031,"observed_ms":1789999280019,"hash":"b503ec01726d100d667765331642dbc94671dfb8"}],"intents":{"pair_fast":null,"pair_250":null,"pair_add_fast":null,"pair_add_250":null},"decision_ms":1789999280038,"feature_cutoff_ms":1789999280037,"request_ms":1789999280002,"inventory":{"pair_fast":{"qty":[0.0,0.0],"cash":0.0,"lots":[[],[]],"floor":0.0},"pair_250":{"qty":[0.0,0.0],"cash":0.0,"lots":[[],[]],"floor":0.0},"pair_add_fast":{"qty":[0.0,0.0],"cash":0.0,"lots":[[],[]],"floor":0.0},"pair_add_250":{"qty":[0.0,0.0],"cash":0.0,"lots":[[],[]],"floor":0.0}}}
{"kind":"decision","recorded_ms":1789999290049,"S":1789999200,"age":90,"signal":{"rsi14":54.163068108939754,"volume_ratio":0.36053333555279954,"taker_buy_fraction":0.4903968605488818,"volume5":131.76316,"return1":-0.6763353762248734,"return5":1.7821086124401626,"return15":24.875802358420835,"bollinger_z":0.2405190723362708,"bar_close_ms":1789999259999,"ref":85408.50237928922,"reference_received_ms":1789999201674,"spot":85467.95136712,"twap":85438.56278851311,"sigma":10.530835099956098,"spot_z":0.3896024188631486,"twap_z":0.19700265005321801,"momentum":-0.007832550654958179,"decision_ms":1789999290048,"momentum30":1.2014833229966926,"momentum60":0.10297302064324335,"spot_twap_gap":0.3602799918297426,"range60":1.2842135350632689,"final_mean":85467.95136712,"final_z":0.43303052620916155,"final_up_prob":0.667503703448134,"final_drift_up_prob":0.6549947112803971,"final_known_seconds":0,"final_sd":137.28590534068857,"final_drift_shift":-4.69377969723002},"entry_side":null,"context_gap":null,"book_errors":[null,null],"books":[{"bid":0.71,"ask":0.72,"asks":[[0.72,80.0]],"received_ms":1789999290047,"observed_ms":1789999290035,"hash":"a5cd32fa5fa1c1800ff66b1d39eabf99b36f879f"},{"bid":0.28,"ask":0.29,"asks":[[0.29,86.0]],"received_ms":1789999290047,"observed_ms":1789999290038,"hash":"d21fd0bb642d6304f476797dfe2b2beb00ad48c1"}],"intents":{"pair_fast":null,"pair_250":null,"pair_add_fast":null,"pair_add_250":null},"decision_ms":1789999290049,"feature_cutoff_ms":1789999290048,"request_ms":1789999290011,"inventory":{"pair_fast":{"qty":[0.0,0.0],"cash":0.0,"lots":[[],[]],"floor":0.0},"pair_250":{"qty":[0.0,0.0],"cash":0.0,"lots":[[],[]],"floor":0.0},"pair_add_fast":{"qty":[0.0,0.0],"cash":0.0,"lots":[[],[]],"floor":0.0},"pair_add_250":{"qty":[0.0,0.0],"cash":0.0,"lots":[[],[]],"floor":0.0}}}
{"kind":"decision","recorded_ms":1789999300062,"S":1789999200,"age":100,"signal":{"rsi14":54.163068108939754,"volume_ratio":0.36053333555279954,"taker_buy_fraction":0.4903968605488818,"volume5":131.76316,"return1":-0.6763353762248734,"return5":1.7821086124401626,"return15":24.875802358420835,"bollinger_z":0.2405190723362708,"bar_close_ms":1789999259999,"ref":85408.50237928922,"reference_received_ms":1789999201674,"spot":85470.87807950331,"twap":85442.93338391976,"sigma":10.165049570711611,"spot_z":0.43396746916554363,"twap_z":0.23954738606637752,"momentum":0.09104802807999557,"decision_ms":1789999300061,"momentum30":0.29940387792736234,"momentum60":0.5450222505841761,"spot_twap_gap":0.3549067480587072,"range60":1.3674584336209517,"final_mean":85470.87807950331,"final_z":0.4852088851572363,"final_up_prob":0.6862359100084724,"final_drift_up_prob":0.8084225179439162,"final_known_seconds":0,"final_sd":128.55432396683855,"final_drift_shift":49.73625753895381},"entry_side":null,"context_gap":null,"book_errors":[null,null],"books":[{"bid":0.66,"ask":0.67,"asks":[[0.67,1688.8]],"received_ms":1789999300048,"observed_ms":1789999300034,"hash":"6b0b6a92f3b63984de64fe79ac27bb5c9a4c889f"},{"bid":0.33,"ask":0.34,"asks":[[0.34,162.57]],"received_ms":1789999300061,"observed_ms":1789999300051,"hash":"638504dcaa0509d64f6bbc62249e72fca4cbcb5e"}],"intents":{"pair_fast":null,"pair_250":null,"pair_add_fast":null,"pair_add_250":null},"decision_ms":1789999300062,"feature_cutoff_ms":1789999300061,"request_ms":1789999300024,"inventory":{"pair_fast":{"qty":[0.0,0.0],"cash":0.0,"lots":[[],[]],"floor":0.0},"pair_250":{"qty":[0.0,0.0],"cash":0.0,"lots":[[],[]],"floor":0.0},"pair_add_fast":{"qty":[0.0,0.0],"cash":0.0,"lots":[[],[]],"floor":0.0},"pair_add_250":{"qty":[0.0,0.0],"cash":0.0,"lots":[[],[]],"floor":0.0}}}
