{"kind":"decision","recorded_ms":1789995030068,"S":1789995000,"age":30,"signal":{"rsi14":44.960130278526044,"volume_ratio":0.5896210690854897,"taker_buy_fraction":0.4594279801729622,"volume5":85.8222,"return1":3.364283017230937,"return5":-1.4270939114566508,"return15":3.105131205864562,"bollinger_z":0.5227098352755803,"bar_close_ms":1789994999999,"ref":85244.88383356572,"reference_received_ms":1789995001080,"spot":85245.26095390263,"twap":85257.95539260622,"sigma":4.223646331068595,"spot_z":0.0054345603661904145,"twap_z":0.18837004990974412,"momentum":-1.046357168104579,"decision_ms":1789995030067,"momentum30":-0.9540139711650357,"momentum60":0.061536871999357395,"spot_twap_gap":-0.38801662382575997,"range60":0.9000257871205549,"final_mean":85245.26095390263,"final_z":0.005888324764071462,"final_up_prob":0.5023490881343735,"final_drift_up_prob":8.487166286430536e-08,"final_known_seconds":0,"final_sd":64.04543771288776,"final_drift_shift":-335.3184758129956},"entry_side":null,"context_gap":null,"book_errors":[null,null],"books":[{"bid":0.49,"ask":0.5,"asks":[[0.5,57.66]],"received_ms":1789995030067,"observed_ms":1789995030058,"hash":"8805f265daf6435e23accc08b671826e2a73bf1a"},{"bid":0.5,"ask":0.51,"asks":[[0.51,1463.68]],"received_ms":1789995030064,"observed_ms":1789995030051,"hash":"215a153ee2600b0802487c42d49ece7908aed9fd"}],"intents":{"pair_fast":null,"pair_250":null,"pair_add_fast":null,"pair_add_250":null},"decision_ms":1789995030068,"feature_cutoff_ms":1789995030067,"request_ms":1789995030035,"inventory":{"pair_fast":{"qty":[0.0,0.0],"cash":0.0,"lots":[[],[]],"floor":0.0},"pair_250":{"qty":[0.0,0.0],"cash":0.0,"lots":[[],[]],"floor":0.0},"pair_add_fast":{"qty":[0.0,0.0],"cash":0.0,"lots":[[],[]],"floor":0.0},"pair_add_250":{"qty":[0.0,0.0],"cash":0.0,"lots":[[],[]],"floor":0.0}}}
{"kind":"decision","recorded_ms":1789995040070,"S":1789995000,"age":40,"signal":{"rsi14":44.960130278526044,"volume_ratio":0.5896210690854897,"taker_buy_fraction":0.4594279801729622,"volume5":85.8222,"return1":3.364283017230937,"return5":-1.4270939114566508,"return15":3.105131205864562,"bollinger_z":0.5227098352755803,"bar_close_ms":1789994999999,"ref":85244.88383356572,"reference_received_ms":1789995001080,"spot":85241.36503063937,"twap":85258.99819113096,"sigma":3.0231141467350007,"spot_z":-0.07219570473511475,"twap_z":0.2895859792757056,"momentum":-0.40752649430887805,"decision_ms":1789995040069,"momentum30":-1.6666268707545355,"momentum60":-0.901794934783845,"spot_twap_gap":-0.7530086924735028,"range60":1.1784831620182477,"final_mean":85241.36503063937,"final_z":-0.07848689970477302,"final_up_prob":0.4687203752984441,"final_drift_up_prob":0.018921353413601072,"final_known_seconds":0,"final_sd":44.832996838806125,"final_drift_shift":-89.57935318228886},"entry_side":null,"context_gap":null,"book_errors":[null,null],"books":[{"bid":0.44,"ask":0.45,"asks":[[0.45,985.66]],"received_ms":1789995040069,"observed_ms":1789995040059,"hash":"18be7bbf09d5dcd3dc5ec8ed7da8238603b14be5"},{"bid":0.55,"ask":0.56,"asks":[[0.56,120.0]],"received_ms":1789995040066,"observed_ms":1789995040056,"hash":"51df8ba0fdd975f2705dce6d730d65fce5a136c3"}],"intents":{"pair_fast":null,"pair_250":null,"pair_add_fast":null,"pair_add_250":null},"decision_ms":1789995040070,"feature_cutoff_ms":1789995040069,"request_ms":1789995040040,"inventory":{"pair_fast":{"qty":[0.0,0.0],"cash":0.0,"lots":[[],[]],"floor":0.0},"pair_250":{"qty":[0.0,0.0],"cash":0.0,"lots":[[],[]],"floor":0.0},"pair_add_fast":{"qty":[0.0,0.0],"cash":0.0,"lots":[[],[]],"floor":0.0},"pair_add_250":{"qty":[0.0,0.0],"cash":0.0,"lots":[[],[]],"floor":0.0}}}
{"kind":"decision","recorded_ms":1789995050099,"S":1789995000,"age":50,"signal":{"rsi14":44.960130278526044,"volume_ratio":0.5896210690854897,"taker_buy_fraction":0.4594279801729622,"volume5":85.8222,"return1":3.364283017230937,"return5":-1.4270939114566508,"return15":3.105131205864562,"bollinger_z":0.5227098352755803,"bar_close_ms":1789994999999,"ref":85244.88383356572,"reference_received_ms":1789995001080,"spot":85222.65808577,"twap":85256.61984925465,"sigma":3.739503139649333,"spot_z":-0.37597382769451293,"twap_z":0.1985280666822573,"momentum":-1.5819361995760608,"decision_ms":1789995050098,"momentum30":-1.7858700421813432,"momentum60":-1.1692496461236368,"spot_twap_gap":-1.1724672099639986,"range60":1.598539991401821,"final_mean":85222.65808577,"final_z":-0.41023639910937704,"final_up_prob":0.3408162711166303,"final_drift_up_prob":6.106226635438361e-16,"final_known_seconds":0,"final_sd":54.17790289688923,"final_drift_shift":-411.3694589735524},"entry_side":null,"context_gap":null,"book_errors":[null,null],"books":[{"bid":0.34,"ask":0.35,"asks":[[0.35,142.0]],"received_ms":1789995050073,"observed_ms":1789995050058,"hash":"f63015d9c26c48b0a9d945eb7df56ec7f658246e"},{"bid":0.65,"ask":0.66,"asks":[[0.66,670.46]],"received_ms":1789995050098,"observed_ms":1789995050043,"hash":"6151187784034b34662d6e1be55ac5bad9b8362d"}],"intents":{"pair_fast":null,"pair_250":null,"pair_add_fast":null,"pair_add_250":null},"decision_ms":1789995050099,"feature_cutoff_ms":1789995050098,"request_ms":1789995050042,"inventory":{"pair_fast":{"qty":[0.0,0.0],"cash":0.0,"lots":[[],[]],"floor":0.0},"pair_250":{"qty":[0.0,0.0],"cash":0.0,"lots":[[],[]],"floor":0.0},"pair_add_fast":{"qty":[0.0,0.0],"cash":0.0,"lots":[[],[]],"floor":0.0},"pair_add_250":{"qty":[0.0,0.0],"cash":0.0,"lots":[[],[]],"floor":0.0}}}
{"kind":"decision","recorded_ms":1789995060050,"S":1789995000,"age":60,"signal":{"rsi14":44.960130278526044,"volume_ratio":0.5896210690854897,"taker_buy_fraction":0.4594279801729622,"volume5":85.8222,"return1":3.364283017230937,"return5":-1.4270939114566508,"return15":3.105131205864562,"bollinger_z":0.5227098352755803,"bar_close_ms":1789994999999,"ref":85244.88383356572,"reference_received_ms":1789995001080,"spot":85216.60114558908,"twap":85250.24327074306,"sigma":3.644161530317427,"spot_z":-0.5010277506874657,"twap_z":0.09494241693468768,"momentum":-0.5256003737416015,"decision_ms":1789995060049,"momentum30":-1.4358697125532682,"momentum60":-1.797174412989951,"spot_twap_gap":-1.1918186517289286,"range60":1.8603104339259138,"final_mean":85216.60114558908,"final_z":-0.5488596102673592,"final_up_prob":0.29155089902884246,"final_drift_up_prob":0.0012778385207023457,"final_known_seconds":0,"final_sd":51.52991301884872,"final_drift_shift":-127.16606477739191},"entry_side":null,"context_gap":null,"book_errors":[null,null],"books":[{"bid":0.36,"ask":0.37,"asks":[[0.37,1048.38]],"received_ms":1789995060049,"observed_ms":1789995060039,"hash":"111fadfeed687e7af048c2e63245f7e1b5c8e33d"},{"bid":0.63,"ask":0.64,"asks":[[0.64,88.07]],"received_ms":1789995060049,"observed_ms":1789995060039,"hash":"e41855763b2743b1bdd9873ac105584c90c2f68c"}],"intents":{"pair_fast":null,"pair_250":null,"pair_add_fast":null,"pair_add_250":null},"decision_ms":1789995060050,"feature_cutoff_ms":1789995060049,"request_ms":1789995060021,"inventory":{"pair_fast":{"qty":[0.0,0.0],"cash":0.0,"lots":[[],[]],"floor":0.0},"pair_250":{"qty":[0.0,0.0],"cash":0.0,"lots":[[],[]],"floor":0.0},"pair_add_fast":{"qty":[0.0,0.0],"cash":0.0,"lots":[[],[]],"floor":0.0},"pair_add_250":{"qty":[0.0,0.0],"cash":0.0,"lots":[[],[]],"floor":0.0}}}
{"kind":"decision","recorded_ms":1789995070074,"S":1789995000,"age":70,"signal":{},"entry_side":null,"context_gap":"incomplete or stale context","book_errors":[null,null],"books":[{"bid":0.32,"ask":0.33,"asks":[[0.33,1004.81]],"received_ms":1789995070073,"observed_ms":1789995070062,"hash":"68498a06a84deba90f4d4dcc2288d66de565d770"},{"bid":0.67,"ask":0.68,"asks":[[0.68,50.0]],"received_ms":1789995070065,"observed_ms":1789995070057,"hash":"f28390fc40e7f9606f7d70c5871c1fb6f0364959"}],"intents":{"pair_fast":null,"pair_250":null,"pair_add_fast":null,"pair_add_250":null},"decision_ms":1789995070074,"feature_cutoff_ms":1789995070073,"request_ms":1789995070042,"inventory":{"pair_fast":{"qty":[0.0,0.0],"cash":0.0,"lots":[[],[]],"floor":0.0},"pair_250":{"qty":[0.0,0.0],"cash":0.0,"lots":[[],[]],"floor":0.0},"pair_add_fast":{"qty":[0.0,0.0],"cash":0.0,"lots":[[],[]],"floor":0.0},"pair_add_250":{"qty":[0.0,0.0],"cash":0.0,"lots":[[],[]],"floor":0.0}}}
{"kind":"decision","recorded_ms":1789995080080,"S":1789995000,"age":80,"signal":{},"entry_side":null,"context_gap":"incomplete or stale context","book_errors":[null,null],"books":[{"bid":0.38,"ask":0.39,"asks":[[0.39,516.48]],"received_ms":1789995080078,"observed_ms":1789995080061,"hash":"13af88359db6eb8f03f01d0caac6b53fc6f99f86"},{"bid":0.61,"ask":0.62,"asks":[[0.62,1027.0]],"received_ms":1789995080071,"observed_ms":1789995080061,"hash":"598450ef823ab0780cda7995e0216c7a19b93891"}],"intents":{"pair_fast":null,"pair_250":null,"pair_add_fast":null,"pair_add_250":null},"decision_ms":1789995080080,"feature_cutoff_ms":1789995080079,"request_ms":1789995080045,"inventory":{"pair_fast":{"qty":[0.0,0.0],"cash":0.0,"lots":[[],[]],"floor":0.0},"pair_250":{"qty":[0.0,0.0],"cash":0.0,"lots":[[],[]],"floor":0.0},"pair_add_fast":{"qty":[0.0,0.0],"cash":0.0,"lots":[[],[]],"floor":0.0},"pair_add_250":{"qty":[0.0,0.0],"cash":0.0,"lots":[[],[]],"floor":0.0}}}
{"kind":"decision","recorded_ms":1789995090035,"S":1789995000,"age":90,"signal":{},"entry_side":null,"context_gap":"incomplete or stale context","book_errors":[null,null],"books":[{"bid":0.36,"ask":0.37,"asks":[[0.37,242.64]],"received_ms":1789995090034,"observed_ms":1789995090024,"hash":"7e5df38dbb8f7d8f58a0629c1513149377d954ed"},{"bid":0.63,"ask":0.64,"asks":[[0.64,347.57]],"received_ms":1789995090024,"observed_ms":1789995090016,"hash":"a81f3c2a5b6b3d60e7cca8dd3a89cacfbc9cff33"}],"intents":{"pair_fast":null,"pair_250":null,"pair_add_fast":null,"pair_add_250":null},"decision_ms":1789995090035,"feature_cutoff_ms":1789995090034,"request_ms":1789995090001,"inventory":{"pair_fast":{"qty":[0.0,0.0],"cash":0.0,"lots":[[],[]],"floor":0.0},"pair_250":{"qty":[0.0,0.0],"cash":0.0,"lots":[[],[]],"floor":0.0},"pair_add_fast":{"qty":[0.0,0.0],"cash":0.0,"lots":[[],[]],"floor":0.0},"pair_add_250":{"qty":[0.0,0.0],"cash":0.0,"lots":[[],[]],"floor":0.0}}}
{"kind":"decision","recorded_ms":1789995100036,"S":1789995000,"age":100,"signal":{},"entry_side":null,"context_gap":"incomplete or stale context","book_errors":[null,null],"books":[{"bid":0.37,"ask":0.38,"asks":[[0.38,1211.16]],"received_ms":1789995100035,"observed_ms":1789995100023,"hash":"344bcf017f0e120cac3df0d45dd8ab8340867f4f"},{"bid":0.62,"ask":0.63,"asks":[[0.63,34.0]],"received_ms":1789995100035,"observed_ms":1789995100023,"hash":"0494269a03933b24d5f7f24fd1567e6833b3142c"}],"intents":{"pair_fast":null,"pair_250":null,"pair_add_fast":null,"pair_add_250":null},"decision_ms":1789995100036,"feature_cutoff_ms":1789995100035,"request_ms":1789995100007,"inventory":{"pair_fast":{"qty":[0.0,0.0],"cash":0.0,"lots":[[],[]],"floor":0.0},"pair_250":{"qty":[0.0,0.0],"cash":0.0,"lots":[[],[]],"floor":0.0},"pair_add_fast":{"qty":[0.0,0.0],"cash":0.0,"lots":[[],[]],"floor":0.0},"pair_add_250":{"qty":[0.0,0.0],"cash":0.0,"lots":[[],[]],"floor":0.0}}}
{"kind":"decision","recorded_ms":1789995111075,"S":1789995000,"age":110,"signal":{},"entry_side":null,"context_gap":"incomplete or stale context","book_errors":[null,null],"books":[{"bid":0.33,"ask":0.34,"asks":[[0.34,358.34]],"received_ms":1789995110039,"observed_ms":1789995110026,"hash":"7072c1636bef9e92d949560535edc3ed936ec4f5"},{"bid":0.66,"ask":0.67,"asks":[[0.67,22.41]],"received_ms":1789995111074,"observed_ms":1789995111059,"hash":"58f896cf74fdc1affb13a0c0faa6150027866b89"}],"intents":{"pair_fast":null,"pair_250":null,"pair_add_fast":null,"pair_add_250":null},"decision_ms":1789995111075,"feature_cutoff_ms":1789995111074,"request_ms":1789995110008,"inventory":{"pair_fast":{"qty":[0.0,0.0],"cash":0.0,"lots":[[],[]],"floor":0.0},"pair_250":{"qty":[0.0,0.0],"cash":0.0,"lots":[[],[]],"floor":0.0},"pair_add_fast":{"qty":[0.0,0.0],"cash":0.0,"lots":[[],[]],"floor":0.0},"pair_add_250":{"qty":[0.0,0.0],"cash":0.0,"lots":[[],[]],"floor":0.0}}}
{"kind":"decision","recorded_ms":1789995120080,"S":1789995000,"age":120,"signal":{},"entry_side":null,"context_gap":"incomplete or stale context","book_errors":[null,null],"books":[{"bid":0.28,"ask":0.29,"asks":[[0.29,334.0]],"received_ms":1789995120077,"observed_ms":1789995120058,"hash":"f60ceb4d469ff1e17a2d8bf752e870482fdbb0e5"},{"bid":0.71,"ask":0.72,"asks":[[0.72,890.79]],"received_ms":1789995120079,"observed_ms":1789995120070,"hash":"4475455ec2db63efabd612678bdc6aecc2278c09"}],"intents":{"pair_fast":null,"pair_250":null,"pair_add_fast":null,"pair_add_250":null},"decision_ms":1789995120080,"feature_cutoff_ms":1789995120079,"request_ms":1789995120045,"inventory":{"pair_fast":{"qty":[0.0,0.0],"cash":0.0,"lots":[[],[]],"floor":0.0},"pair_250":{"qty":[0.0,0.0],"cash":0.0,"lots":[[],[]],"floor":0.0},"pair_add_fast":{"qty":[0.0,0.0],"cash":0.0,"lots":[[],[]],"floor":0.0},"pair_add_250":{"qty":[0.0,0.0],"cash":0.0,"lots":[[],[]],"floor":0.0}}}
{"kind":"decision","recorded_ms":1789995130068,"S":1789995000,"age":130,"signal":{},"entry_side":null,"context_gap":"incomplete or stale context","book_errors":[null,null],"books":[{"bid":0.29,"ask":0.3,"asks":[[0.3,239.41]],"received_ms":1789995130056,"observed_ms":1789995130046,"hash":"5e48783d1ed787a104dca30d4fa7c7ff7486b0b6"},{"bid":0.7,"ask":0.71,"asks":[[0.71,154.24]],"received_ms":1789995130067,"observed_ms":1789995130055,"hash":"3262b792460aab2065410147c67370a4d12af36c"}],"intents":{"pair_fast":null,"pair_250":null,"pair_add_fast":null,"pair_add_250":null},"decision_ms":1789995130068,"feature_cutoff_ms":1789995130067,"request_ms":1789995130031,"inventory":{"pair_fast":{"qty":[0.0,0.0],"cash":0.0,"lots":[[],[]],"floor":0.0},"pair_250":{"qty":[0.0,0.0],"cash":0.0,"lots":[[],[]],"floor":0.0},"pair_add_fast":{"qty":[0.0,0.0],"cash":0.0,"lots":[[],[]],"floor":0.0},"pair_add_250":{"qty":[0.0,0.0],"cash":0.0,"lots":[[],[]],"floor":0.0}}}
{"kind":"decision","recorded_ms":1789995140088,"S":1789995000,"age":140,"signal":{"rsi14":40.59710250213001,"volume_ratio":0.8322826508317023,"taker_buy_fraction":0.379871617846106,"volume5":87.97796,"return1":-0.9034320326976272,"return5":7.941988869246608,"return15":-12.312487988460749,"bollinger_z":-0.3217280414439576,"bar_close_ms":1789995119999,"ref":85244.88383356572,"reference_received_ms":1789995001080,"spot":85205.24218807074,"twap":85218.50966988786,"sigma":2.070490521800495,"spot_z":-1.5140371832243193,"twap_z":-1.0073109727440075,"momentum":-0.3633986063259137,"decision_ms":1789995140087,"momentum30":-1.4590758448205243,"momentum60":-0.8402436054341004,"spot_twap_gap":-0.8272554350894928,"range60":1.197834283574408,"final_mean":85205.24218807074,"final_z":-1.7484180941828726,"final_up_prob":0.040195828488542085,"final_drift_up_prob":0.0009298983879486578,"final_known_seconds":0,"final_sd":22.672863903016328,"final_drift_shift":-30.910719653978642},"entry_side":null,"context_gap":null,"book_errors":[null,null],"books":[{"bid":0.25,"ask":0.26,"asks":[[0.26,85.0]],"received_ms":1789995140087,"observed_ms":1789995140076,"hash":"45b17ce2ff30757e661c05a8a14018e67b636651"},{"bid":0.74,"ask":0.75,"asks":[[0.75,85.0]],"received_ms":1789995140085,"observed_ms":1789995140073,"hash":"98aacebc55a90b2f8665ebf670870c735b9b3869"}],"intents":{"pair_fast":null,"pair_250":null,"pair_add_fast":null,"pair_add_250":null},"decision_ms":1789995140088,"feature_cutoff_ms":1789995140087,"request_ms":1789995140042,"inventory":{"pair_fast":{"qty":[0.0,0.0],"cash":0.0,"lots":[[],[]],"floor":0.0},"pair_250":{"qty":[0.0,0.0],"cash":0.0,"lots":[[],[]],"floor":0.0},"pair_add_fast":{"qty":[0.0,0.0],"cash":0.0,"lots":[[],[]],"floor":0.0},"pair_add_250":{"qty":[0.0,0.0],"cash":0.0,"lots":[[],[]],"floor":0.0}}}
{"kind":"decision","recorded_ms":1789995150043,"S":1789995000,"age":150,"signal":{"rsi14":40.59710250213001,"volume_ratio":0.8322826508317023,"taker_buy_fraction":0.379871617846106,"volume5":87.97796,"return1":-0.9034320326976272,"return5":7.941988869246608,"return15":-12.312487988460749,"bollinger_z":-0.3217280414439576,"bar_close_ms":1789995119999,"ref":85244.88383356572,"reference_received_ms":1789995001080,"spot":85210.68949601,"twap":85216.27680805823,"sigma":2.1018087178223923,"spot_z":-1.3285447447756502,"twap_z":-1.1114621928180248,"momentum":0.8195750668612612,"decision_ms":1789995150042,"momentum30":-0.8575975590551357,"momentum60":-0.8453957226208291,"spot_twap_gap":-0.3431895955351634,"range60":1.1799858425737453,"final_mean":85210.68949601,"final_z":-1.5514850305489811,"final_up_prob":0.06039274598772559,"final_drift_up_prob":0.9212275976396924,"final_known_seconds":0,"final_sd":22.03974700524002,"final_drift_shift":65.34481654767828},"entry_side":null,"context_gap":null,"book_errors":[null,null],"books":[{"bid":0.19,"ask":0.2,"asks":[[0.2,561.25]],"received_ms":1789995150037,"observed_ms":1789995150031,"hash":"74af8d65ed06d6e054203151a5392cb919038806"},{"bid":0.8,"ask":0.81,"asks":[[0.81,137.74]],"received_ms":1789995150042,"observed_ms":1789995150031,"hash":"2563fba5a3a7b6b89d2edec7bbd0260977c7837a"}],"intents":{"pair_fast":null,"pair_250":null,"pair_add_fast":null,"pair_add_250":null},"decision_ms":1789995150043,"feature_cutoff_ms":1789995150042,"request_ms":1789995150009,"inventory":{"pair_fast":{"qty":[0.0,0.0],"cash":0.0,"lots":[[],[]],"floor":0.0},"pair_250":{"qty":[0.0,0.0],"cash":0.0,"lots":[[],[]],"floor":0.0},"pair_add_fast":{"qty":[0.0,0.0],"cash":0.0,"lots":[[],[]],"floor":0.0},"pair_add_250":{"qty":[0.0,0.0],"cash":0.0,"lots":[[],[]],"floor":0.0}}}
{"kind":"decision","recorded_ms":1789995160047,"S":1789995000,"age":160,"signal":{},"entry_side":null,"context_gap":"incomplete or stale context","book_errors":[null,null],"books":[{"bid":0.18,"ask":0.19,"asks":[[0.19,139.08]],"received_ms":1789995160046,"observed_ms":1789995160027,"hash":"7ef4bfc924d9a722ba870f8642af193d367a3ef8"},{"bid":0.81,"ask":0.82,"asks":[[0.82,799.49]],"received_ms":1789995160045,"observed_ms":1789995160034,"hash":"9b6fc85c376b20b8ee27b78bdb21f7504ad336bb"}],"intents":{"pair_fast":null,"pair_250":null,"pair_add_fast":null,"pair_add_250":null},"decision_ms":1789995160047,"feature_cutoff_ms":1789995160046,"request_ms":1789995160016,"inventory":{"pair_fast":{"qty":[0.0,0.0],"cash":0.0,"lots":[[],[]],"floor":0.0},"pair_250":{"qty":[0.0,0.0],"cash":0.0,"lots":[[],[]],"floor":0.0},"pair_add_fast":{"qty":[0.0,0.0],"cash":0.0,"lots":[[],[]],"floor":0.0},"pair_add_250":{"qty":[0.0,0.0],"cash":0.0,"lots":[[],[]],"floor":0.0}}}
{"kind":"decision","recorded_ms":1789995170046,"S":1789995000,"age":170,"signal":{},"entry_side":null,"context_gap":"incomplete or stale context","book_errors":[null,null],"books":[{"bid":0.33,"ask":0.34,"asks":[[0.34,1316.73]],"received_ms":1789995170043,"observed_ms":1789995169798,"hash":"bc64f7c508a3811251c631b570dd9a188720c916"},{"bid":0.66,"ask":0.67,"asks":[[0.67,22.52]],"received_ms":1789995170045,"observed_ms":1789995169798,"hash":"05aa6e7366b67ebd38506f7cc2ce4afdae8dcf77"}],"intents":{"pair_fast":null,"pair_250":null,"pair_add_fast":null,"pair_add_250":null},"decision_ms":1789995170046,"feature_cutoff_ms":1789995170045,"request_ms":1789995170018,"inventory":{"pair_fast":{"qty":[0.0,0.0],"cash":0.0,"lots":[[],[]],"floor":0.0},"pair_250":{"qty":[0.0,0.0],"cash":0.0,"lots":[[],[]],"floor":0.0},"pair_add_fast":{"qty":[0.0,0.0],"cash":0.0,"lots":[[],[]],"floor":0.0},"pair_add_250":{"qty":[0.0,0.0],"cash":0.0,"lots":[[],[]],"floor":0.0}}}
{"kind":"decision","recorded_ms":1789995180055,"S":1789995000,"age":180,"signal":{},"entry_side":null,"context_gap":"incomplete or stale context","book_errors":[null,null],"books":[{"bid":0.18,"ask":0.19,"asks":[[0.19,577.35]],"received_ms":1789995180047,"observed_ms":1789995180039,"hash":"b6753919f7a9c03cbae623a6337cea455e0c4b5e"},{"bid":0.81,"ask":0.82,"asks":[[0.82,453.74]],"received_ms":1789995180054,"observed_ms":1789995180042,"hash":"811aa7ac0c06f291766b59911192145c29d244ae"}],"intents":{"pair_fast":null,"pair_250":null,"pair_add_fast":null,"pair_add_250":null},"decision_ms":1789995180055,"feature_cutoff_ms":1789995180054,"request_ms":1789995180017,"inventory":{"pair_fast":{"qty":[0.0,0.0],"cash":0.0,"lots":[[],[]],"floor":0.0},"pair_250":{"qty":[0.0,0.0],"cash":0.0,"lots":[[],[]],"floor":0.0},"pair_add_fast":{"qty":[0.0,0.0],"cash":0.0,"lots":[[],[]],"floor":0.0},"pair_add_250":{"qty":[0.0,0.0],"cash":0.0,"lots":[[],[]],"floor":0.0}}}
{"kind":"decision","recorded_ms":1789995190082,"S":1789995000,"age":190,"signal":{},"entry_side":null,"context_gap":"incomplete or stale context","book_errors":[null,null],"books":[{"bid":0.29,"ask":0.3,"asks":[[0.3,16.0]],"received_ms":1789995190081,"observed_ms":1789995190071,"hash":"c28d411ccada1081b982784225b4f19e2113415a"},{"bid":0.7,"ask":0.71,"asks":[[0.71,835.47]],"received_ms":1789995190081,"observed_ms":1789995190072,"hash":"1b92f1c1112601e99d19b767b0e2fd88e37c101e"}],"intents":{"pair_fast":null,"pair_250":null,"pair_add_fast":null,"pair_add_250":null},"decision_ms":1789995190082,"feature_cutoff_ms":1789995190081,"request_ms":1789995190050,"inventory":{"pair_fast":{"qty":[0.0,0.0],"cash":0.0,"lots":[[],[]],"floor":0.0},"pair_250":{"qty":[0.0,0.0],"cash":0.0,"lots":[[],[]],"floor":0.0},"pair_add_fast":{"qty":[0.0,0.0],"cash":0.0,"lots":[[],[]],"floor":0.0},"pair_add_250":{"qty":[0.0,0.0],"cash":0.0,"lots":[[],[]],"floor":0.0}}}
{"kind":"decision","recorded_ms":1789995200040,"S":1789995000,"age":200,"signal":{},"entry_side":null,"context_gap":"incomplete or stale context","book_errors":[null,null],"books":[{"bid":0.31,"ask":0.32,"asks":[[0.32,147.28]],"received_ms":1789995200038,"observed_ms":1789995200025,"hash":"c05513de483b55b1fd1a5f64077dfe38bea90e20"},{"bid":0.68,"ask":0.69,"asks":[[0.69,250.5]],"received_ms":1789995200028,"observed_ms":1789995200021,"hash":"232c9957c814051e3ddccbad06b331849144ca9b"}],"intents":{"pair_fast":null,"pair_250":null,"pair_add_fast":null,"pair_add_250":null},"decision_ms":1789995200040,"feature_cutoff_ms":1789995200039,"request_ms":1789995200005,"inventory":{"pair_fast":{"qty":[0.0,0.0],"cash":0.0,"lots":[[],[]],"floor":0.0},"pair_250":{"qty":[0.0,0.0],"cash":0.0,"lots":[[],[]],"floor":0.0},"pair_add_fast":{"qty":[0.0,0.0],"cash":0.0,"lots":[[],[]],"floor":0.0},"pair_add_250":{"qty":[0.0,0.0],"cash":0.0,"lots":[[],[]],"floor":0.0}}}
{"kind":"decision","recorded_ms":1789995210055,"S":1789995000,"age":210,"signal":{},"entry_side":null,"context_gap":"incomplete or stale context","book_errors":[null,null],"books":[{"bid":0.34,"ask":0.35,"asks":[[0.35,654.82]],"received_ms":1789995210040,"observed_ms":1789995210029,"hash":"8584ab7ba85ba63e69664960a2890f5d396d2070"},{"bid":0.65,"ask":0.66,"asks":[[0.66,111.3]],"received_ms":1789995210054,"observed_ms":1789995210039,"hash":"cec30f35594bd11c9ee446c6187be6c8e5ce8129"}],"intents":{"pair_fast":null,"pair_250":null,"pair_add_fast":null,"pair_add_250":null},"decision_ms":1789995210055,"feature_cutoff_ms":1789995210054,"request_ms":1789995210011,"inventory":{"pair_fast":{"qty":[0.0,0.0],"cash":0.0,"lots":[[],[]],"floor":0.0},"pair_250":{"qty":[0.0,0.0],"cash":0.0,"lots":[[],[]],"floor":0.0},"pair_add_fast":{"qty":[0.0,0.0],"cash":0.0,"lots":[[],[]],"floor":0.0},"pair_add_250":{"qty":[0.0,0.0],"cash":0.0,"lots":[[],[]],"floor":0.0}}}
{"kind":"decision","recorded_ms":1789995220056,"S":1789995000,"age":220,"signal":{},"entry_side":null,"context_gap":"incomplete or stale context","book_errors":[null,null],"books":[{"bid":0.59,"ask":0.6,"asks":[[0.6,88.79]],"received_ms":1789995220052,"observed_ms":1789995220043,"hash":"21f68432c1a24dcdd2feaee4b2b0cb427df84b18"},{"bid":0.4,"ask":0.41,"asks":[[0.41,559.12]],"received_ms":1789995220054,"observed_ms":1789995220046,"hash":"9bd8b0a04b2c823403aeee702c20a1462e966a07"}],"intents":{"pair_fast":null,"pair_250":null,"pair_add_fast":null,"pair_add_250":null},"decision_ms":1789995220056,"feature_cutoff_ms":1789995220055,"request_ms":1789995220027,"inventory":{"pair_fast":{"qty":[0.0,0.0],"cash":0.0,"lots":[[],[]],"floor":0.0},"pair_250":{"qty":[0.0,0.0],"cash":0.0,"lots":[[],[]],"floor":0.0},"pair_add_fast":{"qty":[0.0,0.0],"cash":0.0,"lots":[[],[]],"floor":0.0},"pair_add_250":{"qty":[0.0,0.0],"cash":0.0,"lots":[[],[]],"floor":0.0}}}
{"kind":"decision","recorded_ms":1789995230066,"S":1789995000,"age":230,"signal":{"rsi14":43.84199346159051,"volume_ratio":1.208532886324569,"taker_buy_fraction":0.27783220930278535,"volume5":103.68787,"return1":0.04927786804381948,"return5":1.338715415150022,"return15":-15.744278839518852,"bollinger_z":-0.3429130666205066,"bar_close_ms":1789995179999,"ref":85244.88383356572,"reference_received_ms":1789995001080,"spot":85247.16287326903,"twap":85222.91404915262,"sigma":3.7879697593144375,"spot_z":0.07194458279494476,"twap_z":-0.6935407800926428,"momentum":-0.1483938577138733,"decision_ms":1789995230065,"momentum30":1.1237274168771507,"momentum60":0.790440414473916,"spot_twap_gap":0.8264347212825189,"range60":1.7472583469259682,"final_mean":85247.16287326903,"final_z":0.10996532372469438,"final_up_prob":0.5437815621257677,"final_drift_up_prob":0.4080554357656266,"final_known_seconds":0,"final_sd":20.725076106857703,"final_drift_shift":-7.098655765164591},"entry_side":null,"context_gap":null,"book_errors":[null,null],"books":[{"bid":0.3,"ask":0.31,"asks":[[0.31,390.51]],"received_ms":1789995230055,"observed_ms":1789995230026,"hash":"f5f2fe5ec8ab3f2be47b664a1e8bc3d3931fbb6a"},{"bid":0.69,"ask":0.7,"asks":[[0.7,51.28]],"received_ms":1789995230065,"observed_ms":1789995230051,"hash":"7413b332507dd6592081ce2d69ab4795e03a29f5"}],"intents":{"pair_fast":null,"pair_250":null,"pair_add_fast":null,"pair_add_250":null},"decision_ms":1789995230066,"feature_cutoff_ms":1789995230065,"request_ms":1789995230029,"inventory":{"pair_fast":{"qty":[0.0,0.0],"cash":0.0,"lots":[[],[]],"floor":0.0},"pair_250":{"qty":[0.0,0.0],"cash":0.0,"lots":[[],[]],"floor":0.0},"pair_add_fast":{"qty":[0.0,0.0],"cash":0.0,"lots":[[],[]],"floor":0.0},"pair_add_250":{"qty":[0.0,0.0],"cash":0.0,"lots":[[],[]],"floor":0.0}}}
{"kind":"decision","recorded_ms":1789995240075,"S":1789995000,"age":240,"signal":{"rsi14":43.84199346159051,"volume_ratio":1.208532886324569,"taker_buy_fraction":0.27783220930278535,"volume5":103.68787,"return1":0.04927786804381948,"return5":1.338715415150022,"return15":-15.744278839518852,"bollinger_z":-0.3429130666205066,"bar_close_ms":1789995179999,"ref":85244.88383356572,"reference_received_ms":1789995001080,"spot":85212.74904368869,"twap":85226.20271610636,"sigma":4.631716872795848,"spot_z":-0.8962430792294741,"twap_z":-0.5210185689495053,"momentum":-2.349584127690157,"decision_ms":1789995240074,"momentum30":-0.5090899194923789,"momentum60":0.1944865957229388,"spot_twap_gap":-0.3749930508131598,"range60":1.4289651033592068,"final_mean":85212.74904368869,"final_z":-1.5542554611628716,"final_up_prob":0.060061746455780496,"final_drift_up_prob":3.1719571413901804e-11,"final_known_seconds":0,"final_sd":20.675359154273107,"final_drift_shift":-102.9869838503689},"entry_side":null,"context_gap":null,"book_errors":[null,null],"books":[{"bid":0.03,"ask":0.04,"asks":[[0.04,622.98]],"received_ms":1789995240065,"observed_ms":1789995240057,"hash":"531c1c1d74296ee35ddf9211457f1f34dcdbd961"},{"bid":0.96,"ask":0.97,"asks":[[0.97,806.21]],"received_ms":1789995240074,"observed_ms":1789995240066,"hash":"407dde20581311d4abb557140cda576364c98998"}],"intents":{"pair_fast":null,"pair_250":null,"pair_add_fast":null,"pair_add_250":null},"decision_ms":1789995240075,"feature_cutoff_ms":1789995240074,"request_ms":1789995240039,"inventory":{"pair_fast":{"qty":[0.0,0.0],"cash":0.0,"lots":[[],[]],"floor":0.0},"pair_250":{"qty":[0.0,0.0],"cash":0.0,"lots":[[],[]],"floor":0.0},"pair_add_fast":{"qty":[0.0,0.0],"cash":0.0,"lots":[[],[]],"floor":0.0},"pair_add_250":{"qty":[0.0,0.0],"cash":0.0,"lots":[[],[]],"floor":0.0}}}
{"kind":"decision","recorded_ms":1789995250048,"S":1789995000,"age":250,"signal":{"rsi14":44.69238566206984,"volume_ratio":0.6184879250705887,"taker_buy_fraction":0.28591270343796177,"volume5":105.41973,"return1":-2.111180962241457,"return5":-4.288079619803605,"return15":-11.704790949077967,"bollinger_z":-0.6168701723393666,"bar_close_ms":1789995239999,"ref":85244.88383356572,"reference_received_ms":1789995001080,"spot":85198.53203182101,"twap":85225.78956606626,"sigma":5.35557139287924,"spot_z":-1.2245598589221827,"twap_z":-0.5044479963074993,"momentum":-0.8394648437189682,"decision_ms":1789995250047,"momentum30":-1.7184480988245057,"momentum60":-0.10385432232304533,"spot_twap_gap":-0.6570601494292122,"range60":1.4813311969711722,"final_mean":85198.71287016993,"final_z":-2.537655342335773,"final_up_prob":0.0055798914198816885,"final_drift_up_prob":1.5738569043688422e-05,"final_known_seconds":10,"final_sd":18.194339721995714,"final_drift_shift":-29.563117680260586},"entry_side":null,"context_gap":null,"book_errors":[null,null],"books":[{"bid":0.02,"ask":0.03,"asks":[[0.03,1088.55]],"received_ms":1789995250047,"observed_ms":1789995249015,"hash":"37d57faf06f53073140b8a51607c6669828a6a3c"},{"bid":0.97,"ask":0.98,"asks":[[0.98,888.0]],"received_ms":1789995250042,"observed_ms":1789995249015,"hash":"ae36a31ffe1cb546701489d5ca8824f131bd46d4"}],"intents":{"pair_fast":null,"pair_250":null,"pair_add_fast":null,"pair_add_250":null},"decision_ms":1789995250048,"feature_cutoff_ms":1789995250047,"request_ms":1789995250017,"inventory":{"pair_fast":{"qty":[0.0,0.0],"cash":0.0,"lots":[[],[]],"floor":0.0},"pair_250":{"qty":[0.0,0.0],"cash":0.0,"lots":[[],[]],"floor":0.0},"pair_add_fast":{"qty":[0.0,0.0],"cash":0.0,"lots":[[],[]],"floor":0.0},"pair_add_250":{"qty":[0.0,0.0],"cash":0.0,"lots":[[],[]],"floor":0.0}}}
{"kind":"decision","recorded_ms":1789995260049,"S":1789995000,"age":260,"signal":{},"entry_side":null,"context_gap":"two-sided entry context unavailable","book_errors":[null,"empty/invalid public book"],"books":[{"bid":null,"ask":0.01,"asks":[[0.01,15718.69]],"received_ms":1789995260042,"observed_ms":1789995260034,"hash":"82c80a40cfca1e348e96415ca0f47a8e981490a8"},null],"intents":{"pair_fast":null,"pair_250":null,"pair_add_fast":null,"pair_add_250":null},"decision_ms":1789995260049,"feature_cutoff_ms":1789995260049,"request_ms":1789995260020,"inventory":{"pair_fast":{"qty":[0.0,0.0],"cash":0.0,"lots":[[],[]],"floor":0.0},"pair_250":{"qty":[0.0,0.0],"cash":0.0,"lots":[[],[]],"floor":0.0},"pair_add_fast":{"qty":[0.0,0.0],"cash":0.0,"lots":[[],[]],"floor":0.0},"pair_add_250":{"qty":[0.0,0.0],"cash":0.0,"lots":[[],[]],"floor":0.0}}}
{"kind":"decision","recorded_ms":1789995270070,"S":1789995000,"age":270,"signal":{},"entry_side":null,"context_gap":"two-sided entry context unavailable","book_errors":[null,"empty/invalid public book"],"books":[{"bid":null,"ask":0.01,"asks":[[0.01,42339.41]],"received_ms":1789995270069,"observed_ms":1789995270029,"hash":"97495d66c10e4a5dc23bdf6d6c5d2684f98408aa"},null],"intents":{"pair_fast":null,"pair_250":null,"pair_add_fast":null,"pair_add_250":null},"decision_ms":1789995270070,"feature_cutoff_ms":1789995270070,"request_ms":1789995270020,"inventory":{"pair_fast":{"qty":[0.0,0.0],"cash":0.0,"lots":[[],[]],"floor":0.0},"pair_250":{"qty":[0.0,0.0],"cash":0.0,"lots":[[],[]],"floor":0.0},"pair_add_fast":{"qty":[0.0,0.0],"cash":0.0,"lots":[[],[]],"floor":0.0},"pair_add_250":{"qty":[0.0,0.0],"cash":0.0,"lots":[[],[]],"floor":0.0}}}
{"kind":"decision","recorded_ms":1789995280089,"S":1789995000,"age":280,"signal":{},"entry_side":null,"context_gap":"two-sided entry context unavailable","book_errors":[null,"empty/invalid public book"],"books":[{"bid":null,"ask":0.01,"asks":[[0.01,35724.69]],"received_ms":1789995280089,"observed_ms":1789995280066,"hash":"63625cfa57765f72e77544abd8b600ee6246703c"},null],"intents":{"pair_fast":null,"pair_250":null,"pair_add_fast":null,"pair_add_250":null},"decision_ms":1789995280089,"feature_cutoff_ms":1789995280089,"request_ms":1789995280043,"inventory":{"pair_fast":{"qty":[0.0,0.0],"cash":0.0,"lots":[[],[]],"floor":0.0},"pair_250":{"qty":[0.0,0.0],"cash":0.0,"lots":[[],[]],"floor":0.0},"pair_add_fast":{"qty":[0.0,0.0],"cash":0.0,"lots":[[],[]],"floor":0.0},"pair_add_250":{"qty":[0.0,0.0],"cash":0.0,"lots":[[],[]],"floor":0.0}}}
{"kind":"decision","recorded_ms":1789995290046,"S":1789995000,"age":290,"signal":{},"entry_side":null,"context_gap":"two-sided entry context unavailable","book_errors":[null,"empty/invalid public book"],"books":[{"bid":null,"ask":0.01,"asks":[[0.01,39379.2]],"received_ms":1789995290046,"observed_ms":1789995290032,"hash":"f4590e33974044ae6e070bbad8ce3d3c9a13e793"},null],"intents":{"pair_fast":null,"pair_250":null,"pair_add_fast":null,"pair_add_250":null},"decision_ms":1789995290046,"feature_cutoff_ms":1789995290046,"request_ms":1789995290010,"inventory":{"pair_fast":{"qty":[0.0,0.0],"cash":0.0,"lots":[[],[]],"floor":0.0},"pair_250":{"qty":[0.0,0.0],"cash":0.0,"lots":[[],[]],"floor":0.0},"pair_add_fast":{"qty":[0.0,0.0],"cash":0.0,"lots":[[],[]],"floor":0.0},"pair_add_250":{"qty":[0.0,0.0],"cash":0.0,"lots":[[],[]],"floor":0.0}}}
{"kind":"decision","recorded_ms":1789995330059,"S":1789995300,"age":30,"signal":{},"entry_side":null,"context_gap":"incomplete or stale context","book_errors":[null,null],"books":[{"bid":0.76,"ask":0.77,"asks":[[0.77,438.0]],"received_ms":1789995330058,"observed_ms":1789995330049,"hash":"03822a0ef5346f3efa4cca53328ddba23a1a1522"},{"bid":0.23,"ask":0.24,"asks":[[0.24,873.23]],"received_ms":1789995330052,"observed_ms":1789995330044,"hash":"215def419ccfb94a13c50df4d1b3bd6aa6aa414e"}],"intents":{"pair_fast":null,"pair_250":null,"pair_add_fast":null,"pair_add_250":null},"decision_ms":1789995330059,"feature_cutoff_ms":1789995330058,"request_ms":1789995330029,"inventory":{"pair_fast":{"qty":[0.0,0.0],"cash":0.0,"lots":[[],[]],"floor":0.0},"pair_250":{"qty":[0.0,0.0],"cash":0.0,"lots":[[],[]],"floor":0.0},"pair_add_fast":{"qty":[0.0,0.0],"cash":0.0,"lots":[[],[]],"floor":0.0},"pair_add_250":{"qty":[0.0,0.0],"cash":0.0,"lots":[[],[]],"floor":0.0}}}
{"kind":"decision","recorded_ms":1789995340073,"S":1789995300,"age":40,"signal":{},"entry_side":null,"context_gap":"incomplete or stale context","book_errors":[null,null],"books":[{"bid":0.83,"ask":0.84,"asks":[[0.84,648.5]],"received_ms":1789995340069,"observed_ms":1789995340060,"hash":"af794cc21424ee41c97409d29be4b4c0c9921c5d"},{"bid":0.16,"ask":0.17,"asks":[[0.17,1028.56]],"received_ms":1789995340072,"observed_ms":1789995340061,"hash":"e1c2267659c5deaa667a581e1c6d5f57aec4c47d"}],"intents":{"pair_fast":null,"pair_250":null,"pair_add_fast":null,"pair_add_250":null},"decision_ms":1789995340073,"feature_cutoff_ms":1789995340072,"request_ms":1789995340031,"inventory":{"pair_fast":{"qty":[0.0,0.0],"cash":0.0,"lots":[[],[]],"floor":0.0},"pair_250":{"qty":[0.0,0.0],"cash":0.0,"lots":[[],[]],"floor":0.0},"pair_add_fast":{"qty":[0.0,0.0],"cash":0.0,"lots":[[],[]],"floor":0.0},"pair_add_250":{"qty":[0.0,0.0],"cash":0.0,"lots":[[],[]],"floor":0.0}}}
{"kind":"decision","recorded_ms":1789995350074,"S":1789995300,"age":50,"signal":{},"entry_side":null,"context_gap":"incomplete or stale context","book_errors":[null,null],"books":[{"bid":0.86,"ask":0.87,"asks":[[0.87,1224.31]],"received_ms":1789995350065,"observed_ms":1789995350036,"hash":"471b4dbcbbe6220ad61df296b334d49f422ef872"},{"bid":0.13,"ask":0.14,"asks":[[0.14,82.0]],"received_ms":1789995350073,"observed_ms":1789995350062,"hash":"37c29d7f383b41be1412de20997c0022184b8d09"}],"intents":{"pair_fast":null,"pair_250":null,"pair_add_fast":null,"pair_add_250":null},"decision_ms":1789995350074,"feature_cutoff_ms":1789995350073,"request_ms":1789995350044,"inventory":{"pair_fast":{"qty":[0.0,0.0],"cash":0.0,"lots":[[],[]],"floor":0.0},"pair_250":{"qty":[0.0,0.0],"cash":0.0,"lots":[[],[]],"floor":0.0},"pair_add_fast":{"qty":[0.0,0.0],"cash":0.0,"lots":[[],[]],"floor":0.0},"pair_add_250":{"qty":[0.0,0.0],"cash":0.0,"lots":[[],[]],"floor":0.0}}}
{"kind":"decision","recorded_ms":1789995360072,"S":1789995300,"age":60,"signal":{},"entry_side":null,"context_gap":"incomplete or stale context","book_errors":[null,null],"books":[{"bid":0.83,"ask":0.84,"asks":[[0.84,412.56]],"received_ms":1789995360070,"observed_ms":1789995360062,"hash":"0de9d61366d07ecaef1d15823fb15d9369e93429"},{"bid":0.16,"ask":0.17,"asks":[[0.17,308.88]],"received_ms":1789995360071,"observed_ms":1789995360062,"hash":"cad0c6b8591fabd942c5b903ec08b63e9b5091c7"}],"intents":{"pair_fast":null,"pair_250":null,"pair_add_fast":null,"pair_add_250":null},"decision_ms":1789995360072,"feature_cutoff_ms":1789995360071,"request_ms":1789995360045,"inventory":{"pair_fast":{"qty":[0.0,0.0],"cash":0.0,"lots":[[],[]],"floor":0.0},"pair_250":{"qty":[0.0,0.0],"cash":0.0,"lots":[[],[]],"floor":0.0},"pair_add_fast":{"qty":[0.0,0.0],"cash":0.0,"lots":[[],[]],"floor":0.0},"pair_add_250":{"qty":[0.0,0.0],"cash":0.0,"lots":[[],[]],"floor":0.0}}}
{"kind":"decision","recorded_ms":1789995371117,"S":1789995300,"age":70,"signal":{},"entry_side":null,"context_gap":"incomplete or stale context","book_errors":[null,null],"books":[{"bid":0.87,"ask":0.88,"asks":[[0.88,810.69]],"received_ms":1789995370046,"observed_ms":1789995369998,"hash":"cfbf297589745dd8ea80f14957a3c4f6b0b12c55"},{"bid":0.12,"ask":0.13,"asks":[[0.13,268.6]],"received_ms":1789995371116,"observed_ms":1789995371102,"hash":"9d90bd149e786b3069ad22229eb9d9643360039b"}],"intents":{"pair_fast":null,"pair_250":null,"pair_add_fast":null,"pair_add_250":null},"decision_ms":1789995371117,"feature_cutoff_ms":1789995371116,"request_ms":1789995370018,"inventory":{"pair_fast":{"qty":[0.0,0.0],"cash":0.0,"lots":[[],[]],"floor":0.0},"pair_250":{"qty":[0.0,0.0],"cash":0.0,"lots":[[],[]],"floor":0.0},"pair_add_fast":{"qty":[0.0,0.0],"cash":0.0,"lots":[[],[]],"floor":0.0},"pair_add_250":{"qty":[0.0,0.0],"cash":0.0,"lots":[[],[]],"floor":0.0}}}
{"kind":"decision","recorded_ms":1789995380065,"S":1789995300,"age":80,"signal":{},"entry_side":null,"context_gap":"incomplete or stale context","book_errors":[null,null],"books":[{"bid":0.86,"ask":0.87,"asks":[[0.87,110.0]],"received_ms":1789995380064,"observed_ms":1789995380057,"hash":"dfddae218d27011030237a61f1b437155695ee9e"},{"bid":0.13,"ask":0.14,"asks":[[0.14,661.0]],"received_ms":1789995380064,"observed_ms":1789995380057,"hash":"f0b0150845104121b13d14de2ce6ea3563733492"}],"intents":{"pair_fast":null,"pair_250":null,"pair_add_fast":null,"pair_add_250":null},"decision_ms":1789995380065,"feature_cutoff_ms":1789995380064,"request_ms":1789995380035,"inventory":{"pair_fast":{"qty":[0.0,0.0],"cash":0.0,"lots":[[],[]],"floor":0.0},"pair_250":{"qty":[0.0,0.0],"cash":0.0,"lots":[[],[]],"floor":0.0},"pair_add_fast":{"qty":[0.0,0.0],"cash":0.0,"lots":[[],[]],"floor":0.0},"pair_add_250":{"qty":[0.0,0.0],"cash":0.0,"lots":[[],[]],"floor":0.0}}}
{"kind":"decision","recorded_ms":1789995390072,"S":1789995300,"age":90,"signal":{},"entry_side":null,"context_gap":"incomplete or stale context","book_errors":[null,null],"books":[{"bid":0.87,"ask":0.88,"asks":[[0.88,5.0]],"received_ms":1789995390071,"observed_ms":1789995390057,"hash":"46a9788adef76ea2c6926481a4fac641e26a5ba5"},{"bid":0.12,"ask":0.13,"asks":[[0.13,1268.36]],"received_ms":1789995390065,"observed_ms":1789995390057,"hash":"9da112d2703656a9b49b45bdc780b40939dd2d93"}],"intents":{"pair_fast":null,"pair_250":null,"pair_add_fast":null,"pair_add_250":null},"decision_ms":1789995390072,"feature_cutoff_ms":1789995390071,"request_ms":1789995390036,"inventory":{"pair_fast":{"qty":[0.0,0.0],"cash":0.0,"lots":[[],[]],"floor":0.0},"pair_250":{"qty":[0.0,0.0],"cash":0.0,"lots":[[],[]],"floor":0.0},"pair_add_fast":{"qty":[0.0,0.0],"cash":0.0,"lots":[[],[]],"floor":0.0},"pair_add_250":{"qty":[0.0,0.0],"cash":0.0,"lots":[[],[]],"floor":0.0}}}
{"kind":"decision","recorded_ms":1789995400101,"S":1789995300,"age":100,"signal":{},"entry_side":null,"context_gap":"incomplete or stale context","book_errors":[null,null],"books":[{"bid":0.89,"ask":0.9,"asks":[[0.9,703.92]],"received_ms":1789995400100,"observed_ms":1789995400082,"hash":"0524efa8124fcb02b0f1b3b4f7f3ea5c8be18c1e"},{"bid":0.1,"ask":0.11,"asks":[[0.11,955.98]],"received_ms":1789995400075,"observed_ms":1789995400061,"hash":"2b1d75f210aa27a44bd6864e2ce80f50c7cf7431"}],"intents":{"pair_fast":null,"pair_250":null,"pair_add_fast":null,"pair_add_250":null},"decision_ms":1789995400101,"feature_cutoff_ms":1789995400100,"request_ms":1789995400043,"inventory":{"pair_fast":{"qty":[0.0,0.0],"cash":0.0,"lots":[[],[]],"floor":0.0},"pair_250":{"qty":[0.0,0.0],"cash":0.0,"lots":[[],[]],"floor":0.0},"pair_add_fast":{"qty":[0.0,0.0],"cash":0.0,"lots":[[],[]],"floor":0.0},"pair_add_250":{"qty":[0.0,0.0],"cash":0.0,"lots":[[],[]],"floor":0.0}}}
{"kind":"decision","recorded_ms":1789995410056,"S":1789995300,"age":110,"signal":{"rsi14":59.87223696546935,"volume_ratio":0.7768861482593694,"taker_buy_fraction":0.2793394173740077,"volume5":107.96772,"return1":3.6506324794010783,"return5":10.481944428816979,"return15":1.9501291960591707,"bollinger_z":1.23352878617006,"bar_close_ms":1789995359999,"ref":85213.82960265716,"reference_received_ms":1789995301250,"spot":85311.08425536132,"twap":85312.76500920854,"sigma":2.3826125226215695,"spot_z":2.9617134281657727,"twap_z":3.012897727326208,"momentum":-0.4769611860688809,"decision_ms":1789995410055,"momentum30":-0.5077542282974806,"momentum60":-0.3516605586708622,"spot_twap_gap":-0.09106994384740885,"range60":0.708337538027796,"final_mean":85311.08425536132,"final_z":3.3334271867821683,"final_up_prob":0.9995710843923663,"final_drift_up_prob":0.9136106902532849,"final_known_seconds":0,"final_sd":29.175574342764623,"final_drift_shift":-57.478725102966465},"entry_side":null,"context_gap":null,"book_errors":[null,null],"books":[{"bid":0.89,"ask":0.9,"asks":[[0.9,369.76]],"received_ms":1789995410055,"observed_ms":1789995410045,"hash":"e193e5b3843b15c01cd93917aa5698850fa02eb5"},{"bid":0.1,"ask":0.11,"asks":[[0.11,904.23]],"received_ms":1789995410047,"observed_ms":1789995410039,"hash":"1cbfa79fe9b7db252fe594dfe12b3c5fc0eae50e"}],"intents":{"pair_fast":null,"pair_250":null,"pair_add_fast":null,"pair_add_250":null},"decision_ms":1789995410056,"feature_cutoff_ms":1789995410055,"request_ms":1789995410023,"inventory":{"pair_fast":{"qty":[0.0,0.0],"cash":0.0,"lots":[[],[]],"floor":0.0},"pair_250":{"qty":[0.0,0.0],"cash":0.0,"lots":[[],[]],"floor":0.0},"pair_add_fast":{"qty":[0.0,0.0],"cash":0.0,"lots":[[],[]],"floor":0.0},"pair_add_250":{"qty":[0.0,0.0],"cash":0.0,"lots":[[],[]],"floor":0.0}}}
{"kind":"decision","recorded_ms":1789995420065,"S":1789995300,"age":120,"signal":{"rsi14":59.87223696546935,"volume_ratio":0.7768861482593694,"taker_buy_fraction":0.2793394173740077,"volume5":107.96772,"return1":3.6506324794010783,"return5":10.481944428816979,"return15":1.9501291960591707,"bollinger_z":1.23352878617006,"bar_close_ms":1789995359999,"ref":85213.82960265716,"reference_received_ms":1789995301250,"spot":85309.22583549,"twap":85311.74110965726,"sigma":2.3955204553243803,"spot_z":2.9687409988354134,"twap_z":3.0470166007321358,"momentum":-0.2453262141523763,"decision_ms":1789995420064,"momentum30":-0.01944171660925312,"momentum60":-0.3847966496377861,"spot_twap_gap":-0.13555321474169751,"range60":0.6874987624049024,"final_mean":85309.22583549,"final_z":3.366406938349689,"final_up_prob":0.9996192286345078,"final_drift_up_prob":0.9914164436763134,"final_known_seconds":0,"final_sd":28.337700872135315,"final_drift_shift":-27.864404202851023},"entry_side":null,"context_gap":null,"book_errors":[null,null],"books":[{"bid":0.75,"ask":0.76,"asks":[[0.76,2308.45]],"received_ms":1789995420061,"observed_ms":1789995420049,"hash":"ef2b259dad7e6644b3b02421176e881a4bf7068b"},{"bid":0.24,"ask":0.25,"asks":[[0.25,123.92]],"received_ms":1789995420064,"observed_ms":1789995420038,"hash":"2280a880dc788428c8f24f7e0462b3a4fb12cd4e"}],"intents":{"pair_fast":null,"pair_250":null,"pair_add_fast":null,"pair_add_250":null},"decision_ms":1789995420065,"feature_cutoff_ms":1789995420064,"request_ms":1789995420029,"inventory":{"pair_fast":{"qty":[0.0,0.0],"cash":0.0,"lots":[[],[]],"floor":0.0},"pair_250":{"qty":[0.0,0.0],"cash":0.0,"lots":[[],[]],"floor":0.0},"pair_add_fast":{"qty":[0.0,0.0],"cash":0.0,"lots":[[],[]],"floor":0.0},"pair_add_250":{"qty":[0.0,0.0],"cash":0.0,"lots":[[],[]],"floor":0.0}}}
{"kind":"decision","recorded_ms":1789995430064,"S":1789995300,"age":130,"signal":{"rsi14":59.45276379530724,"volume_ratio":0.7139751485478883,"taker_buy_fraction":0.34055810495988026,"volume5":102.91075000000001,"return1":-4.659509890846313,"return5":6.730142620399641,"return15":9.908786635016545,"bollinger_z":0.6478003566380661,"bar_close_ms":1789995419999,"ref":85213.82960265716,"reference_received_ms":1789995301250,"spot":85307.90872380635,"twap":85308.84436705628,"sigma":4.248251551272639,"spot_z":1.698787487303328,"twap_z":1.7156824053909057,"momentum":-0.09804204866097516,"decision_ms":1789995430063,"momentum30":-0.2909147035880711,"momentum60":-0.05123932845120023,"spot_twap_gap":-0.02843311482577849,"range60":0.9187127664534709,"final_mean":85307.90872380635,"final_z":1.9427486205359952,"final_up_prob":0.973976730728384,"final_drift_up_prob":0.9408725046999533,"final_known_seconds":0,"final_sd":48.425781984718505,"final_drift_shift":-18.431265772205084},"entry_side":null,"context_gap":null,"book_errors":[null,null],"books":[{"bid":0.8,"ask":0.81,"asks":[[0.81,186.91]],"received_ms":1789995430063,"observed_ms":1789995430040,"hash":"0dc4849f3dbddd04e3c4f0317550d3ccacfb7b01"},{"bid":0.19,"ask":0.2,"asks":[[0.2,822.87]],"received_ms":1789995430063,"observed_ms":1789995430051,"hash":"a267452bc867d7d0c4e849f386b6d66753a30183"}],"intents":{"pair_fast":null,"pair_250":null,"pair_add_fast":null,"pair_add_250":null},"decision_ms":1789995430064,"feature_cutoff_ms":1789995430063,"request_ms":1789995430011,"inventory":{"pair_fast":{"qty":[0.0,0.0],"cash":0.0,"lots":[[],[]],"floor":0.0},"pair_250":{"qty":[0.0,0.0],"cash":0.0,"lots":[[],[]],"floor":0.0},"pair_add_fast":{"qty":[0.0,0.0],"cash":0.0,"lots":[[],[]],"floor":0.0},"pair_add_250":{"qty":[0.0,0.0],"cash":0.0,"lots":[[],[]],"floor":0.0}}}
{"kind":"decision","recorded_ms":1789995440063,"S":1789995300,"age":140,"signal":{"rsi14":59.45276379530724,"volume_ratio":0.7139751485478883,"taker_buy_fraction":0.34055810495988026,"volume5":102.91075000000001,"return1":-4.659509890846313,"return5":6.730142620399641,"return15":9.908786635016545,"bollinger_z":0.6478003566380661,"bar_close_ms":1789995419999,"ref":85213.82960265716,"reference_received_ms":1789995301250,"spot":85310.83199712729,"twap":85306.31987318439,"sigma":5.916772627519919,"spot_z":1.2963484240735437,"twap_z":1.2360480078358476,"momentum":0.15623723437274503,"decision_ms":1789995440062,"momentum30":-0.00778394651913737,"momentum60":-0.15008370522285736,"spot_twap_gap":0.09845108691851588,"range60":0.6810340128231546,"final_mean":85310.83199712729,"final_z":1.496990944529424,"final_up_prob":0.9328021928371845,"final_drift_up_prob":0.9813828739889866,"final_known_seconds":0,"final_sd":64.79825066718541,"final_drift_shift":37.98442886697852},"entry_side":null,"context_gap":null,"book_errors":[null,null],"books":[{"bid":0.91,"ask":0.92,"asks":[[0.92,236.62]],"received_ms":1789995440062,"observed_ms":1789995440052,"hash":"62cc6557201fa87494150c389ed0d0631a0e60f6"},{"bid":0.08,"ask":0.09,"asks":[[0.09,1066.77]],"received_ms":1789995440061,"observed_ms":1789995440046,"hash":"72590a46ab1750dfe01f9d21dd51c95c1a37ae67"}],"intents":{"pair_fast":null,"pair_250":null,"pair_add_fast":null,"pair_add_250":null},"decision_ms":1789995440063,"feature_cutoff_ms":1789995440062,"request_ms":1789995440035,"inventory":{"pair_fast":{"qty":[0.0,0.0],"cash":0.0,"lots":[[],[]],"floor":0.0},"pair_250":{"qty":[0.0,0.0],"cash":0.0,"lots":[[],[]],"floor":0.0},"pair_add_fast":{"qty":[0.0,0.0],"cash":0.0,"lots":[[],[]],"floor":0.0},"pair_add_250":{"qty":[0.0,0.0],"cash":0.0,"lots":[[],[]],"floor":0.0}}}
{"kind":"decision","recorded_ms":1789995450064,"S":1789995300,"age":150,"signal":{"rsi14":59.45276379530724,"volume_ratio":0.7139751485478883,"taker_buy_fraction":0.34055810495988026,"volume5":102.91075000000001,"return1":-4.659509890846313,"return5":6.730142620399641,"return15":9.908786635016545,"bollinger_z":0.6478003566380661,"bar_close_ms":1789995419999,"ref":85213.82960265716,"reference_received_ms":1789995301250,"spot":85333.4299240586,"twap":85306.02163332044,"sigma":6.223463053309874,"spot_z":1.5694439944274736,"twap_z":1.2097812711799776,"momentum":1.148250080202437,"decision_ms":1789995450063,"momentum30":0.7100615407271559,"momentum60":0.4967977259901787,"spot_twap_gap":0.5685572628807275,"range60":0.9735563651311878,"final_mean":85333.4299240586,"final_z":1.8328557664826657,"final_up_prob":0.9665879883278392,"final_drift_up_prob":0.9999999989272478,"final_known_seconds":0,"final_sd":65.25353690593613,"final_drift_shift":271.0327563179493},"entry_side":null,"context_gap":null,"book_errors":[null,null],"books":[{"bid":0.93,"ask":0.94,"asks":[[0.94,1500.52]],"received_ms":1789995450063,"observed_ms":1789995450054,"hash":"64122756ad85960cffba323176fa31cf4762c9bf"},{"bid":0.06,"ask":0.07,"asks":[[0.07,20.0]],"received_ms":1789995450060,"observed_ms":1789995450042,"hash":"352ab008a45b9343b6d3f98938f5fcd56b8c3992"}],"intents":{"pair_fast":null,"pair_250":null,"pair_add_fast":null,"pair_add_250":null},"decision_ms":1789995450064,"feature_cutoff_ms":1789995450063,"request_ms":1789995450036,"inventory":{"pair_fast":{"qty":[0.0,0.0],"cash":0.0,"lots":[[],[]],"floor":0.0},"pair_250":{"qty":[0.0,0.0],"cash":0.0,"lots":[[],[]],"floor":0.0},"pair_add_fast":{"qty":[0.0,0.0],"cash":0.0,"lots":[[],[]],"floor":0.0},"pair_add_250":{"qty":[0.0,0.0],"cash":0.0,"lots":[[],[]],"floor":0.0}}}
{"kind":"decision","recorded_ms":1789995460073,"S":1789995300,"age":160,"signal":{"rsi14":59.45276379530724,"volume_ratio":0.7139751485478883,"taker_buy_fraction":0.34055810495988026,"volume5":102.91075000000001,"return1":-4.659509890846313,"return5":6.730142620399641,"return15":9.908786635016545,"bollinger_z":0.6478003566380661,"bar_close_ms":1789995419999,"ref":85213.82960265716,"reference_received_ms":1789995301250,"spot":85318.5592770928,"twap":85308.54056081692,"sigma":6.310792835000017,"spot_z":1.4029219698370408,"twap_z":1.268714762102094,"momentum":-0.7451538328333358,"decision_ms":1789995460072,"momentum30":0.3081254837241376,"momentum60":0.07940083297295704,"spot_twap_gap":0.20495217374096558,"range60":0.960084133186189,"final_mean":85318.5592770928,"final_z":1.66013051360304,"final_up_prob":0.9515559002006073,"final_drift_up_prob":0.1758937914730257,"final_known_seconds":0,"final_sd":63.08520539649871,"final_drift_shift":-163.4700479258474},"entry_side":null,"context_gap":null,"book_errors":[null,null],"books":[{"bid":0.93,"ask":0.94,"asks":[[0.94,388.2]],"received_ms":1789995460072,"observed_ms":1789995460059,"hash":"04a139063d343b379c9dafd6eec392c8233d195c"},{"bid":0.06,"ask":0.07,"asks":[[0.07,422.43]],"received_ms":1789995460059,"observed_ms":1789995460035,"hash":"964a9860ad9dcf439ec844210c0430f64905433f"}],"intents":{"pair_fast":null,"pair_250":null,"pair_add_fast":null,"pair_add_250":null},"decision_ms":1789995460073,"feature_cutoff_ms":1789995460072,"request_ms":1789995460036,"inventory":{"pair_fast":{"qty":[0.0,0.0],"cash":0.0,"lots":[[],[]],"floor":0.0},"pair_250":{"qty":[0.0,0.0],"cash":0.0,"lots":[[],[]],"floor":0.0},"pair_add_fast":{"qty":[0.0,0.0],"cash":0.0,"lots":[[],[]],"floor":0.0},"pair_add_250":{"qty":[0.0,0.0],"cash":0.0,"lots":[[],[]],"floor":0.0}}}
{"kind":"decision","recorded_ms":1789995470075,"S":1789995300,"age":170,"signal":{"rsi14":59.45276379530724,"volume_ratio":0.7139751485478883,"taker_buy_fraction":0.34055810495988026,"volume5":102.91075000000001,"return1":-4.659509890846313,"return5":6.730142620399641,"return15":9.908786635016545,"bollinger_z":0.6478003566380661,"bar_close_ms":1789995419999,"ref":85213.82960265716,"reference_received_ms":1789995301250,"spot":85342.56034194051,"twap":85310.30887623607,"sigma":6.6715982784454955,"spot_z":1.6927948969464182,"twap_z":1.2686917117441157,"momentum":1.1376289161977302,"decision_ms":1789995470074,"momentum30":0.8682742096272704,"momentum60":0.6090812327976477,"spot_twap_gap":0.6240852858683147,"range60":1.0848410900444125,"final_mean":85342.56034194051,"final_z":2.0347438154754864,"final_up_prob":0.9790616715013442,"final_drift_up_prob":0.9999999971544893,"final_known_seconds":0,"final_sd":63.26631308780465,"final_drift_shift":239.8330408809898},"entry_side":null,"context_gap":null,"book_errors":[null,null],"books":[{"bid":0.93,"ask":0.94,"asks":[[0.94,110.93]],"received_ms":1789995470073,"observed_ms":1789995470059,"hash":"12a7cc230263499de7ebcb8c2d001b32b30ab2d4"},{"bid":0.06,"ask":0.07,"asks":[[0.07,507.45]],"received_ms":1789995470070,"observed_ms":1789995470059,"hash":"0e0c90dbe2ab5c683599814aa955814b5654d830"}],"intents":{"pair_fast":null,"pair_250":null,"pair_add_fast":null,"pair_add_250":null},"decision_ms":1789995470075,"feature_cutoff_ms":1789995470074,"request_ms":1789995470044,"inventory":{"pair_fast":{"qty":[0.0,0.0],"cash":0.0,"lots":[[],[]],"floor":0.0},"pair_250":{"qty":[0.0,0.0],"cash":0.0,"lots":[[],[]],"floor":0.0},"pair_add_fast":{"qty":[0.0,0.0],"cash":0.0,"lots":[[],[]],"floor":0.0},"pair_add_250":{"qty":[0.0,0.0],"cash":0.0,"lots":[[],[]],"floor":0.0}}}
{"kind":"decision","recorded_ms":1789995480092,"S":1789995300,"age":180,"signal":{"rsi14":59.45276379530724,"volume_ratio":0.7139751485478883,"taker_buy_fraction":0.34055810495988026,"volume5":102.91075000000001,"return1":-4.659509890846313,"return5":6.730142620399641,"return15":9.908786635016545,"bollinger_z":0.6478003566380661,"bar_close_ms":1789995419999,"ref":85213.82960265716,"reference_received_ms":1789995301250,"spot":85346.55644537693,"twap":85313.74141061144,"sigma":7.700462333218162,"spot_z":1.5740411153664988,"twap_z":1.1848793387082976,"momentum":0.16410428462475296,"decision_ms":1789995480091,"momentum30":0.31122338358872653,"momentum60":0.6258534623831549,"spot_twap_gap":0.5501491453905092,"range60":1.006890021470525,"final_mean":85346.55644537693,"final_z":1.9281646437349476,"final_up_prob":0.9730826747936234,"final_drift_up_prob":0.9928593758813835,"final_known_seconds":0,"final_sd":68.83584508772665,"final_drift_shift":35.92856635453378},"entry_side":null,"context_gap":null,"book_errors":[null,null],"books":[{"bid":0.97,"ask":0.98,"asks":[[0.98,554.39]],"received_ms":1789995480091,"observed_ms":1789995480079,"hash":"b7eb6b5a353eed739c136d850876f44961870f87"},{"bid":0.02,"ask":0.03,"asks":[[0.03,795.89]],"received_ms":1789995480081,"observed_ms":1789995480063,"hash":"2b900fd7966317ed30f21cfb107b0da422d6be94"}],"intents":{"pair_fast":null,"pair_250":null,"pair_add_fast":null,"pair_add_250":null},"decision_ms":1789995480092,"feature_cutoff_ms":1789995480091,"request_ms":1789995480045,"inventory":{"pair_fast":{"qty":[0.0,0.0],"cash":0.0,"lots":[[],[]],"floor":0.0},"pair_250":{"qty":[0.0,0.0],"cash":0.0,"lots":[[],[]],"floor":0.0},"pair_add_fast":{"qty":[0.0,0.0],"cash":0.0,"lots":[[],[]],"floor":0.0},"pair_add_250":{"qty":[0.0,0.0],"cash":0.0,"lots":[[],[]],"floor":0.0}}}
{"kind":"decision","recorded_ms":1789995490093,"S":1789995300,"age":190,"signal":{"rsi14":66.88420633566567,"volume_ratio":2.010705993159225,"taker_buy_fraction":0.5686723321818001,"volume5":118.46525,"return1":10.967236727172233,"return5":17.640807302932945,"return15":24.99953737094079,"bollinger_z":2.1657830696700286,"bar_close_ms":1789995479999,"ref":85213.82960265716,"reference_received_ms":1789995301250,"spot":85357.06142742865,"twap":85323.14844736885,"sigma":6.739440016067351,"spot_z":2.0272208304014234,"twap_z":1.547236024595159,"momentum":0.4929143962022546,"decision_ms":1789995490092,"momentum30":1.0430389963716171,"momentum60":0.9415599421533407,"spot_twap_gap":0.6496306650539821,"range60":1.3517007367959692,"final_mean":85357.06142742865,"final_z":2.5418637864906843,"final_up_prob":0.9944868432406029,"final_drift_up_prob":0.9999722963235393,"final_known_seconds":0,"final_sd":56.34913465179559,"final_drift_shift":83.9432105708381},"entry_side":null,"context_gap":null,"book_errors":[null,null],"books":[{"bid":0.98,"ask":0.99,"asks":[[0.99,3401.16]],"received_ms":1789995490068,"observed_ms":1789995490057,"hash":"48aa429212c6871d80f33e4edcbb22c8de9c5c00"},{"bid":0.01,"ask":0.02,"asks":[[0.02,480.33]],"received_ms":1789995490092,"observed_ms":1789995490077,"hash":"54df96a65ca0830f34ff943687e3b82ab5c37be6"}],"intents":{"pair_fast":null,"pair_250":null,"pair_add_fast":null,"pair_add_250":null},"decision_ms":1789995490093,"feature_cutoff_ms":1789995490092,"request_ms":1789995490042,"inventory":{"pair_fast":{"qty":[0.0,0.0],"cash":0.0,"lots":[[],[]],"floor":0.0},"pair_250":{"qty":[0.0,0.0],"cash":0.0,"lots":[[],[]],"floor":0.0},"pair_add_fast":{"qty":[0.0,0.0],"cash":0.0,"lots":[[],[]],"floor":0.0},"pair_add_250":{"qty":[0.0,0.0],"cash":0.0,"lots":[[],[]],"floor":0.0}}}
{"kind":"decision","recorded_ms":1789995500051,"S":1789995300,"age":200,"signal":{"rsi14":66.88420633566567,"volume_ratio":2.010705993159225,"taker_buy_fraction":0.5686723321818001,"volume5":118.46525,"return1":10.967236727172233,"return5":17.640807302932945,"return15":24.99953737094079,"bollinger_z":2.1657830696700286,"bar_close_ms":1789995479999,"ref":85213.82960265716,"reference_received_ms":1789995301250,"spot":85360.7563658503,"twap":85334.0341821904,"sigma":5.336590056449634,"spot_z":2.7538841671264556,"twap_z":2.253023759582315,"momentum":0.2189491998243677,"decision_ms":1789995500050,"momentum30":0.6225181652751064,"momentum60":1.2077390655136129,"spot_twap_gap":0.6464463336722542,"range60":1.2524062704629433,"final_mean":85360.7563658503,"final_z":3.5558421579282697,"final_up_prob":0.9998116148787857,"final_drift_up_prob":0.99998551117252,"final_known_seconds":0,"final_sd":41.31982148463725,"final_drift_shift":25.846094277108456},"entry_side":null,"context_gap":null,"book_errors":[null,null],"books":[{"bid":0.98,"ask":0.99,"asks":[[0.99,2791.94]],"received_ms":1789995500050,"observed_ms":1789995500037,"hash":"35f8674b182fa5b244d9f5e43f2befac493d8b79"},{"bid":0.01,"ask":0.02,"asks":[[0.02,642.73]],"received_ms":1789995500039,"observed_ms":1789995500022,"hash":"a692b6e7ca33d853b44db316bb912284cbf459fe"}],"intents":{"pair_fast":null,"pair_250":null,"pair_add_fast":null,"pair_add_250":null},"decision_ms":1789995500051,"feature_cutoff_ms":1789995500050,"request_ms":1789995500016,"inventory":{"pair_fast":{"qty":[0.0,0.0],"cash":0.0,"lots":[[],[]],"floor":0.0},"pair_250":{"qty":[0.0,0.0],"cash":0.0,"lots":[[],[]],"floor":0.0},"pair_add_fast":{"qty":[0.0,0.0],"cash":0.0,"lots":[[],[]],"floor":0.0},"pair_add_250":{"qty":[0.0,0.0],"cash":0.0,"lots":[[],[]],"floor":0.0}}}
{"kind":"decision","recorded_ms":1789995510071,"S":1789995300,"age":210,"signal":{"rsi14":66.88420633566567,"volume_ratio":2.010705993159225,"taker_buy_fraction":0.5686723321818001,"volume5":118.46525,"return1":10.967236727172233,"return5":17.640807302932945,"return15":24.99953737094079,"bollinger_z":2.1657830696700286,"bar_close_ms":1789995479999,"ref":85213.82960265716,"reference_received_ms":1789995301250,"spot":85358.79442774944,"twap":85342.06099860658,"sigma":4.812968198760927,"spot_z":3.1761232495048928,"twap_z":2.8095002889988723,"momentum":-0.12890575567488774,"decision_ms":1789995510070,"momentum30":0.46423320821011244,"momentum60":0.6803584006278278,"spot_twap_gap":0.4488449380842078,"range60":1.181389749701728,"final_mean":85358.79442774944,"final_z":4.262543856879601,"final_up_prob":0.9999898943592334,"final_drift_up_prob":0.9999551366986994,"final_known_seconds":0,"final_sd":34.00899321148523,"final_drift_shift":-11.757895051593122},"entry_side":1,"context_gap":null,"book_errors":[null,null],"books":[{"bid":0.98,"ask":0.99,"asks":[[0.99,2362.86]],"received_ms":1789995510050,"observed_ms":1789995510039,"hash":"fa35d369be0c372dbcbcc790685b0f2825ea202f"},{"bid":0.01,"ask":0.02,"asks":[[0.02,732.39]],"received_ms":1789995510070,"observed_ms":1789995510039,"hash":"91f495a5f84b846a732aa8cc2fc27c3a8d333203"}],"intents":{"pair_fast":null,"pair_250":null,"pair_add_fast":null,"pair_add_250":null},"decision_ms":1789995510071,"feature_cutoff_ms":1789995510070,"request_ms":1789995510023,"inventory":{"pair_fast":{"qty":[0.0,0.0],"cash":0.0,"lots":[[],[]],"floor":0.0},"pair_250":{"qty":[0.0,0.0],"cash":0.0,"lots":[[],[]],"floor":0.0},"pair_add_fast":{"qty":[0.0,0.0],"cash":0.0,"lots":[[],[]],"floor":0.0},"pair_add_250":{"qty":[0.0,0.0],"cash":0.0,"lots":[[],[]],"floor":0.0}}}
{"kind":"decision","recorded_ms":1789995520079,"S":1789995300,"age":220,"signal":{},"entry_side":null,"context_gap":"two-sided entry context unavailable","book_errors":["empty/invalid public book",null],"books":[null,{"bid":null,"ask":0.01,"asks":[[0.01,8767.58]],"received_ms":1789995520079,"observed_ms":1789995520053,"hash":"c19a042b65d6ea80e6fe9f0afb4e3b9e9db10a97"}],"intents":{"pair_fast":null,"pair_250":null,"pair_add_fast":null,"pair_add_250":null},"decision_ms":1789995520079,"feature_cutoff_ms":1789995520079,"request_ms":1789995520042,"inventory":{"pair_fast":{"qty":[0.0,0.0],"cash":0.0,"lots":[[],[]],"floor":0.0},"pair_250":{"qty":[0.0,0.0],"cash":0.0,"lots":[[],[]],"floor":0.0},"pair_add_fast":{"qty":[0.0,0.0],"cash":0.0,"lots":[[],[]],"floor":0.0},"pair_add_250":{"qty":[0.0,0.0],"cash":0.0,"lots":[[],[]],"floor":0.0}}}
{"kind":"decision","recorded_ms":1789995530202,"S":1789995300,"age":230,"signal":{},"entry_side":null,"context_gap":"two-sided entry context unavailable","book_errors":["empty/invalid public book",null],"books":[null,{"bid":null,"ask":0.01,"asks":[[0.01,12937.44]],"received_ms":1789995530202,"observed_ms":1789995530168,"hash":"f438c1420723eaaed748f5084657abc902eef333"}],"intents":{"pair_fast":null,"pair_250":null,"pair_add_fast":null,"pair_add_250":null},"decision_ms":1789995530202,"feature_cutoff_ms":1789995530202,"request_ms":1789995530002,"inventory":{"pair_fast":{"qty":[0.0,0.0],"cash":0.0,"lots":[[],[]],"floor":0.0},"pair_250":{"qty":[0.0,0.0],"cash":0.0,"lots":[[],[]],"floor":0.0},"pair_add_fast":{"qty":[0.0,0.0],"cash":0.0,"lots":[[],[]],"floor":0.0},"pair_add_250":{"qty":[0.0,0.0],"cash":0.0,"lots":[[],[]],"floor":0.0}}}
{"kind":"decision","recorded_ms":1789995540096,"S":1789995300,"age":240,"signal":{},"entry_side":null,"context_gap":"two-sided entry context unavailable","book_errors":["empty/invalid public book",null],"books":[null,{"bid":null,"ask":0.01,"asks":[[0.01,14411.88]],"received_ms":1789995540096,"observed_ms":1789995540064,"hash":"6b7d43fa9a08aa9ebad4b26a5de51936ec708aa0"}],"intents":{"pair_fast":null,"pair_250":null,"pair_add_fast":null,"pair_add_250":null},"decision_ms":1789995540096,"feature_cutoff_ms":1789995540096,"request_ms":1789995540024,"inventory":{"pair_fast":{"qty":[0.0,0.0],"cash":0.0,"lots":[[],[]],"floor":0.0},"pair_250":{"qty":[0.0,0.0],"cash":0.0,"lots":[[],[]],"floor":0.0},"pair_add_fast":{"qty":[0.0,0.0],"cash":0.0,"lots":[[],[]],"floor":0.0},"pair_add_250":{"qty":[0.0,0.0],"cash":0.0,"lots":[[],[]],"floor":0.0}}}
{"kind":"decision","recorded_ms":1789995550066,"S":1789995300,"age":250,"signal":{},"entry_side":null,"context_gap":"two-sided entry context unavailable","book_errors":["empty/invalid public book",null],"books":[null,{"bid":null,"ask":0.01,"asks":[[0.01,23156.92]],"received_ms":1789995550066,"observed_ms":1789995550054,"hash":"b42eee183433c817144dfcd9484efd7b6b31281e"}],"intents":{"pair_fast":null,"pair_250":null,"pair_add_fast":null,"pair_add_250":null},"decision_ms":1789995550066,"feature_cutoff_ms":1789995550066,"request_ms":1789995550041,"inventory":{"pair_fast":{"qty":[0.0,0.0],"cash":0.0,"lots":[[],[]],"floor":0.0},"pair_250":{"qty":[0.0,0.0],"cash":0.0,"lots":[[],[]],"floor":0.0},"pair_add_fast":{"qty":[0.0,0.0],"cash":0.0,"lots":[[],[]],"floor":0.0},"pair_add_250":{"qty":[0.0,0.0],"cash":0.0,"lots":[[],[]],"floor":0.0}}}
{"kind":"decision","recorded_ms":1789995560067,"S":1789995300,"age":260,"signal":{},"entry_side":null,"context_gap":"two-sided entry context unavailable","book_errors":["empty/invalid public book",null],"books":[null,{"bid":null,"ask":0.01,"asks":[[0.01,34098.75]],"received_ms":1789995560066,"observed_ms":1789995560059,"hash":"8bcd3af43dec420510bb485eacf9ae9719f91bf5"}],"intents":{"pair_fast":null,"pair_250":null,"pair_add_fast":null,"pair_add_250":null},"decision_ms":1789995560067,"feature_cutoff_ms":1789995560067,"request_ms":1789995560040,"inventory":{"pair_fast":{"qty":[0.0,0.0],"cash":0.0,"lots":[[],[]],"floor":0.0},"pair_250":{"qty":[0.0,0.0],"cash":0.0,"lots":[[],[]],"floor":0.0},"pair_add_fast":{"qty":[0.0,0.0],"cash":0.0,"lots":[[],[]],"floor":0.0},"pair_add_250":{"qty":[0.0,0.0],"cash":0.0,"lots":[[],[]],"floor":0.0}}}
{"kind":"decision","recorded_ms":1789995570079,"S":1789995300,"age":270,"signal":{},"entry_side":null,"context_gap":"two-sided entry context unavailable","book_errors":["empty/invalid public book",null],"books":[null,{"bid":null,"ask":0.01,"asks":[[0.01,34216.09]],"received_ms":1789995570075,"observed_ms":1789995570053,"hash":"c3b5bd972732471da71b532fd5bfbf193fdea94a"}],"intents":{"pair_fast":null,"pair_250":null,"pair_add_fast":null,"pair_add_250":null},"decision_ms":1789995570079,"feature_cutoff_ms":1789995570079,"request_ms":1789995570038,"inventory":{"pair_fast":{"qty":[0.0,0.0],"cash":0.0,"lots":[[],[]],"floor":0.0},"pair_250":{"qty":[0.0,0.0],"cash":0.0,"lots":[[],[]],"floor":0.0},"pair_add_fast":{"qty":[0.0,0.0],"cash":0.0,"lots":[[],[]],"floor":0.0},"pair_add_250":{"qty":[0.0,0.0],"cash":0.0,"lots":[[],[]],"floor":0.0}}}
{"kind":"decision","recorded_ms":1789995580079,"S":1789995300,"age":280,"signal":{},"entry_side":null,"context_gap":"two-sided entry context unavailable","book_errors":["empty/invalid public book",null],"books":[null,{"bid":null,"ask":0.01,"asks":[[0.01,40601.61]],"received_ms":1789995580078,"observed_ms":1789995580067,"hash":"f91a9f43378de5ffc90136c92fcfddf74c5f2c66"}],"intents":{"pair_fast":null,"pair_250":null,"pair_add_fast":null,"pair_add_250":null},"decision_ms":1789995580079,"feature_cutoff_ms":1789995580079,"request_ms":1789995580050,"inventory":{"pair_fast":{"qty":[0.0,0.0],"cash":0.0,"lots":[[],[]],"floor":0.0},"pair_250":{"qty":[0.0,0.0],"cash":0.0,"lots":[[],[]],"floor":0.0},"pair_add_fast":{"qty":[0.0,0.0],"cash":0.0,"lots":[[],[]],"floor":0.0},"pair_add_250":{"qty":[0.0,0.0],"cash":0.0,"lots":[[],[]],"floor":0.0}}}
{"kind":"decision","recorded_ms":1789995590031,"S":1789995300,"age":290,"signal":{},"entry_side":null,"context_gap":"two-sided entry context unavailable","book_errors":["empty/invalid public book",null],"books":[null,{"bid":null,"ask":0.01,"asks":[[0.01,40822.62]],"received_ms":1789995590031,"observed_ms":1789995590018,"hash":"95c5d35d993e45de321185bae4a61d98d96272d5"}],"intents":{"pair_fast":null,"pair_250":null,"pair_add_fast":null,"pair_add_250":null},"decision_ms":1789995590031,"feature_cutoff_ms":1789995590031,"request_ms":1789995590001,"inventory":{"pair_fast":{"qty":[0.0,0.0],"cash":0.0,"lots":[[],[]],"floor":0.0},"pair_250":{"qty":[0.0,0.0],"cash":0.0,"lots":[[],[]],"floor":0.0},"pair_add_fast":{"qty":[0.0,0.0],"cash":0.0,"lots":[[],[]],"floor":0.0},"pair_add_250":{"qty":[0.0,0.0],"cash":0.0,"lots":[[],[]],"floor":0.0}}}
{"kind":"decision","recorded_ms":1789995630054,"S":1789995600,"age":30,"signal":{},"entry_side":null,"context_gap":"incomplete or stale context","book_errors":[null,null],"books":[{"bid":0.16,"ask":0.17,"asks":[[0.17,158.11]],"received_ms":1789995630042,"observed_ms":1789995630037,"hash":"dff2ae923130c926f045c9d49868f2f25b93c061"},{"bid":0.83,"ask":0.84,"asks":[[0.84,1040.13]],"received_ms":1789995630053,"observed_ms":1789995630045,"hash":"5b1072b6b0c2c8c397106d97e7818259e921cdf6"}],"intents":{"pair_fast":null,"pair_250":null,"pair_add_fast":null,"pair_add_250":null},"decision_ms":1789995630054,"feature_cutoff_ms":1789995630054,"request_ms":1789995630014,"inventory":{"pair_fast":{"qty":[0.0,0.0],"cash":0.0,"lots":[[],[]],"floor":0.0},"pair_250":{"qty":[0.0,0.0],"cash":0.0,"lots":[[],[]],"floor":0.0},"pair_add_fast":{"qty":[0.0,0.0],"cash":0.0,"lots":[[],[]],"floor":0.0},"pair_add_250":{"qty":[0.0,0.0],"cash":0.0,"lots":[[],[]],"floor":0.0}}}
{"kind":"decision","recorded_ms":1789995640055,"S":1789995600,"age":40,"signal":{},"entry_side":null,"context_gap":"incomplete or stale context","book_errors":[null,null],"books":[{"bid":0.18,"ask":0.19,"asks":[[0.19,766.56]],"received_ms":1789995640054,"observed_ms":1789995640040,"hash":"d3344b3140f52a7d5651f5a4e3bfa02991a69417"},{"bid":0.81,"ask":0.82,"asks":[[0.82,245.0]],"received_ms":1789995640051,"observed_ms":1789995640040,"hash":"94a3e66e8a132064a9ffb5df27a90c367e62591b"}],"intents":{"pair_fast":null,"pair_250":null,"pair_add_fast":null,"pair_add_250":null},"decision_ms":1789995640055,"feature_cutoff_ms":1789995640054,"request_ms":1789995640028,"inventory":{"pair_fast":{"qty":[0.0,0.0],"cash":0.0,"lots":[[],[]],"floor":0.0},"pair_250":{"qty":[0.0,0.0],"cash":0.0,"lots":[[],[]],"floor":0.0},"pair_add_fast":{"qty":[0.0,0.0],"cash":0.0,"lots":[[],[]],"floor":0.0},"pair_add_250":{"qty":[0.0,0.0],"cash":0.0,"lots":[[],[]],"floor":0.0}}}
{"kind":"decision","recorded_ms":1789995650054,"S":1789995600,"age":50,"signal":{},"entry_side":null,"context_gap":"incomplete or stale context","book_errors":[null,null],"books":[{"bid":0.16,"ask":0.17,"asks":[[0.17,798.34]],"received_ms":1789995650053,"observed_ms":1789995650042,"hash":"91e19d8be0ceafd378964d07f4e18dd6eea85c01"},{"bid":0.83,"ask":0.84,"asks":[[0.84,371.69]],"received_ms":1789995650047,"observed_ms":1789995650042,"hash":"536a2e950ded221c53645761e75b82b1bb01d30f"}],"intents":{"pair_fast":null,"pair_250":null,"pair_add_fast":null,"pair_add_250":null},"decision_ms":1789995650054,"feature_cutoff_ms":1789995650053,"request_ms":1789995650026,"inventory":{"pair_fast":{"qty":[0.0,0.0],"cash":0.0,"lots":[[],[]],"floor":0.0},"pair_250":{"qty":[0.0,0.0],"cash":0.0,"lots":[[],[]],"floor":0.0},"pair_add_fast":{"qty":[0.0,0.0],"cash":0.0,"lots":[[],[]],"floor":0.0},"pair_add_250":{"qty":[0.0,0.0],"cash":0.0,"lots":[[],[]],"floor":0.0}}}
{"kind":"decision","recorded_ms":1789995660079,"S":1789995600,"age":60,"signal":{},"entry_side":null,"context_gap":"incomplete or stale context","book_errors":[null,null],"books":[{"bid":0.11,"ask":0.12,"asks":[[0.12,476.67]],"received_ms":1789995660076,"observed_ms":1789995660063,"hash":"6cf45acd1418c03ffbfcce61308097ada93bd858"},{"bid":0.88,"ask":0.89,"asks":[[0.89,1007.0]],"received_ms":1789995660071,"observed_ms":1789995660061,"hash":"ad29caf5af350584d1661b51d481686caa792bf8"}],"intents":{"pair_fast":null,"pair_250":null,"pair_add_fast":null,"pair_add_250":null},"decision_ms":1789995660079,"feature_cutoff_ms":1789995660076,"request_ms":1789995660025,"inventory":{"pair_fast":{"qty":[0.0,0.0],"cash":0.0,"lots":[[],[]],"floor":0.0},"pair_250":{"qty":[0.0,0.0],"cash":0.0,"lots":[[],[]],"floor":0.0},"pair_add_fast":{"qty":[0.0,0.0],"cash":0.0,"lots":[[],[]],"floor":0.0},"pair_add_250":{"qty":[0.0,0.0],"cash":0.0,"lots":[[],[]],"floor":0.0}}}
{"kind":"decision","recorded_ms":1789995670067,"S":1789995600,"age":70,"signal":{},"entry_side":null,"context_gap":"incomplete or stale context","book_errors":[null,null],"books":[{"bid":0.11,"ask":0.12,"asks":[[0.12,1329.55]],"received_ms":1789995670066,"observed_ms":1789995670055,"hash":"8212ab686acd4e7e2b0b2e404bf6d2ad2bca024c"},{"bid":0.88,"ask":0.89,"asks":[[0.89,220.56]],"received_ms":1789995670054,"observed_ms":1789995670045,"hash":"b598e56bc5ed14812975c82588aaf882b76e3357"}],"intents":{"pair_fast":null,"pair_250":null,"pair_add_fast":null,"pair_add_250":null},"decision_ms":1789995670067,"feature_cutoff_ms":1789995670066,"request_ms":1789995670028,"inventory":{"pair_fast":{"qty":[0.0,0.0],"cash":0.0,"lots":[[],[]],"floor":0.0},"pair_250":{"qty":[0.0,0.0],"cash":0.0,"lots":[[],[]],"floor":0.0},"pair_add_fast":{"qty":[0.0,0.0],"cash":0.0,"lots":[[],[]],"floor":0.0},"pair_add_250":{"qty":[0.0,0.0],"cash":0.0,"lots":[[],[]],"floor":0.0}}}
{"kind":"decision","recorded_ms":1789995680076,"S":1789995600,"age":80,"signal":{},"entry_side":null,"context_gap":"incomplete or stale context","book_errors":[null,null],"books":[{"bid":0.18,"ask":0.19,"asks":[[0.19,505.91]],"received_ms":1789995680075,"observed_ms":1789995680019,"hash":"c73f15c23e30727af66b8139aed86fc9b2389215"},{"bid":0.81,"ask":0.82,"asks":[[0.82,10.0]],"received_ms":1789995680062,"observed_ms":1789995680019,"hash":"03cd0693d21dedaed333bc809705afcc2f1489f5"}],"intents":{"pair_fast":null,"pair_250":null,"pair_add_fast":null,"pair_add_250":null},"decision_ms":1789995680076,"feature_cutoff_ms":1789995680075,"request_ms":1789995680038,"inventory":{"pair_fast":{"qty":[0.0,0.0],"cash":0.0,"lots":[[],[]],"floor":0.0},"pair_250":{"qty":[0.0,0.0],"cash":0.0,"lots":[[],[]],"floor":0.0},"pair_add_fast":{"qty":[0.0,0.0],"cash":0.0,"lots":[[],[]],"floor":0.0},"pair_add_250":{"qty":[0.0,0.0],"cash":0.0,"lots":[[],[]],"floor":0.0}}}
{"kind":"decision","recorded_ms":1789995690091,"S":1789995600,"age":90,"signal":{},"entry_side":null,"context_gap":"incomplete or stale context","book_errors":[null,null],"books":[{"bid":0.24,"ask":0.26,"asks":[[0.26,87.2]],"received_ms":1789995690080,"observed_ms":1789995690070,"hash":"a0be50c68acf9c7ee0af15fd25390f87b872d054"},{"bid":0.74,"ask":0.76,"asks":[[0.76,1953.32]],"received_ms":1789995690090,"observed_ms":1789995690081,"hash":"2f497bbc55569a82579a556db9290a1fb7e2217b"}],"intents":{"pair_fast":null,"pair_250":null,"pair_add_fast":null,"pair_add_250":null},"decision_ms":1789995690091,"feature_cutoff_ms":1789995690090,"request_ms":1789995690048,"inventory":{"pair_fast":{"qty":[0.0,0.0],"cash":0.0,"lots":[[],[]],"floor":0.0},"pair_250":{"qty":[0.0,0.0],"cash":0.0,"lots":[[],[]],"floor":0.0},"pair_add_fast":{"qty":[0.0,0.0],"cash":0.0,"lots":[[],[]],"floor":0.0},"pair_add_250":{"qty":[0.0,0.0],"cash":0.0,"lots":[[],[]],"floor":0.0}}}
{"kind":"decision","recorded_ms":1789995700049,"S":1789995600,"age":100,"signal":{},"entry_side":null,"context_gap":"incomplete or stale context","book_errors":[null,null],"books":[{"bid":0.27,"ask":0.28,"asks":[[0.28,409.0]],"received_ms":1789995700047,"observed_ms":1789995700035,"hash":"7025946b608ce8ed0010b465472f19f86146c836"},{"bid":0.72,"ask":0.73,"asks":[[0.73,123.98]],"received_ms":1789995700048,"observed_ms":1789995700036,"hash":"267a19069f1c08772798c9b41d699e3a60c2cbad"}],"intents":{"pair_fast":null,"pair_250":null,"pair_add_fast":null,"pair_add_250":null},"decision_ms":1789995700049,"feature_cutoff_ms":1789995700049,"request_ms":1789995700012,"inventory":{"pair_fast":{"qty":[0.0,0.0],"cash":0.0,"lots":[[],[]],"floor":0.0},"pair_250":{"qty":[0.0,0.0],"cash":0.0,"lots":[[],[]],"floor":0.0},"pair_add_fast":{"qty":[0.0,0.0],"cash":0.0,"lots":[[],[]],"floor":0.0},"pair_add_250":{"qty":[0.0,0.0],"cash":0.0,"lots":[[],[]],"floor":0.0}}}
{"kind":"decision","recorded_ms":1789995710048,"S":1789995600,"age":110,"signal":{},"entry_side":null,"context_gap":"incomplete or stale context","book_errors":[null,null],"books":[{"bid":0.15,"ask":0.16,"asks":[[0.16,946.24]],"received_ms":1789995710044,"observed_ms":1789995710030,"hash":"9b868341bc63c979bc169360a7c0002dc6541806"},{"bid":0.84,"ask":0.85,"asks":[[0.85,33.83]],"received_ms":1789995710047,"observed_ms":1789995710028,"hash":"23aae664ce1ad46de1f7a3407589028e6f33c08e"}],"intents":{"pair_fast":null,"pair_250":null,"pair_add_fast":null,"pair_add_250":null},"decision_ms":1789995710048,"feature_cutoff_ms":1789995710047,"request_ms":1789995710020,"inventory":{"pair_fast":{"qty":[0.0,0.0],"cash":0.0,"lots":[[],[]],"floor":0.0},"pair_250":{"qty":[0.0,0.0],"cash":0.0,"lots":[[],[]],"floor":0.0},"pair_add_fast":{"qty":[0.0,0.0],"cash":0.0,"lots":[[],[]],"floor":0.0},"pair_add_250":{"qty":[0.0,0.0],"cash":0.0,"lots":[[],[]],"floor":0.0}}}
{"kind":"decision","recorded_ms":1789995720064,"S":1789995600,"age":120,"signal":{"rsi14":54.489164086687225,"volume_ratio":3.1403326167601735,"taker_buy_fraction":0.4533460535020488,"volume5":244.89193,"return1":-11.816156099987573,"return5":-12.365308141177849,"return15":4.260621926420393,"bollinger_z":-0.4461171750756416,"bar_close_ms":1789995659999,"ref":85348.91601144883,"reference_received_ms":1789995602029,"spot":85239.28453386374,"twap":85242.89937103997,"sigma":8.920529612580907,"spot_z":-0.9161875596468643,"twap_z":-0.8859784543428195,"momentum":-0.6023006071559813,"decision_ms":1789995720063,"momentum30":-0.5848714589582479,"momentum60":0.7646991930768517,"spot_twap_gap":-0.05231454779330855,"range60":1.6635517271779328,"final_mean":85239.28453386374,"final_z":-1.0389110094861036,"final_up_prob":0.14942306281977663,"final_drift_up_prob":0.00027717986168579456,"final_known_seconds":0,"final_sd":105.52537857821008,"final_drift_shift":-254.74915807300107},"entry_side":null,"context_gap":null,"book_errors":[null,null],"books":[{"bid":0.12,"ask":0.13,"asks":[[0.13,849.28]],"received_ms":1789995720048,"observed_ms":1789995720030,"hash":"9739bbb3470c705f3cd4637c79b87ab7cceac99d"},{"bid":0.87,"ask":0.88,"asks":[[0.88,194.19]],"received_ms":1789995720063,"observed_ms":1789995720052,"hash":"5447ffb5b381503fe87368423d329aecb3a8e32f"}],"intents":{"pair_fast":null,"pair_250":null,"pair_add_fast":null,"pair_add_250":null},"decision_ms":1789995720064,"feature_cutoff_ms":1789995720063,"request_ms":1789995720020,"inventory":{"pair_fast":{"qty":[0.0,0.0],"cash":0.0,"lots":[[],[]],"floor":0.0},"pair_250":{"qty":[0.0,0.0],"cash":0.0,"lots":[[],[]],"floor":0.0},"pair_add_fast":{"qty":[0.0,0.0],"cash":0.0,"lots":[[],[]],"floor":0.0},"pair_add_250":{"qty":[0.0,0.0],"cash":0.0,"lots":[[],[]],"floor":0.0}}}
{"kind":"decision","recorded_ms":1789995730044,"S":1789995600,"age":130,"signal":{"rsi14":53.17234627756303,"volume_ratio":1.2193144960161226,"taker_buy_fraction":0.4628183986134353,"volume5":261.04228,"return1":4.466318353261121,"return5":-3.2324509930635625,"return15":11.43907639163687,"bollinger_z":0.056725135261976305,"bar_close_ms":1789995719999,"ref":85348.91601144883,"reference_received_ms":1789995602029,"spot":85240.94792885173,"twap":85249.5535025814,"sigma":8.28878580251843,"spot_z":-0.9991597800279391,"twap_z":-0.919521956071785,"momentum":0.06302824972962935,"decision_ms":1789995730043,"momentum30":-0.8177480255523606,"momentum60":0.5306691588146736,"spot_twap_gap":-0.1340334782184297,"range60":1.4990042041692926,"final_mean":85240.94792885173,"final_z":-1.1426273978273431,"final_up_prob":0.12659666259513985,"final_drift_up_prob":0.18461153727926632,"final_known_seconds":0,"final_sd":94.49106751894584,"final_drift_shift":23.121754662095338},"entry_side":null,"context_gap":null,"book_errors":[null,null],"books":[{"bid":0.14,"ask":0.15,"asks":[[0.15,1079.36]],"received_ms":1789995730042,"observed_ms":1789995730033,"hash":"f77041a03b6facbc05cc6a48f21881ba6b401cf7"},{"bid":0.85,"ask":0.86,"asks":[[0.86,268.0]],"received_ms":1789995730038,"observed_ms":1789995730030,"hash":"0d7646a27579ee33dd5b35fc64998b7f14bf2a2a"}],"intents":{"pair_fast":null,"pair_250":null,"pair_add_fast":null,"pair_add_250":null},"decision_ms":1789995730044,"feature_cutoff_ms":1789995730043,"request_ms":1789995730013,"inventory":{"pair_fast":{"qty":[0.0,0.0],"cash":0.0,"lots":[[],[]],"floor":0.0},"pair_250":{"qty":[0.0,0.0],"cash":0.0,"lots":[[],[]],"floor":0.0},"pair_add_fast":{"qty":[0.0,0.0],"cash":0.0,"lots":[[],[]],"floor":0.0},"pair_add_250":{"qty":[0.0,0.0],"cash":0.0,"lots":[[],[]],"floor":0.0}}}
{"kind":"decision","recorded_ms":1789995740051,"S":1789995600,"age":140,"signal":{},"entry_side":null,"context_gap":"incomplete or stale context","book_errors":[null,null],"books":[{"bid":0.1,"ask":0.11,"asks":[[0.11,320.36]],"received_ms":1789995740050,"observed_ms":1789995740040,"hash":"fbfbe1ea49f408bd20a22334b2fe448696bf258c"},{"bid":0.89,"ask":0.9,"asks":[[0.9,680.45]],"received_ms":1789995740049,"observed_ms":1789995740040,"hash":"c996ac2f4caaeff266a82589d745c4462c7ec618"}],"intents":{"pair_fast":null,"pair_250":null,"pair_add_fast":null,"pair_add_250":null},"decision_ms":1789995740051,"feature_cutoff_ms":1789995740050,"request_ms":1789995740015,"inventory":{"pair_fast":{"qty":[0.0,0.0],"cash":0.0,"lots":[[],[]],"floor":0.0},"pair_250":{"qty":[0.0,0.0],"cash":0.0,"lots":[[],[]],"floor":0.0},"pair_add_fast":{"qty":[0.0,0.0],"cash":0.0,"lots":[[],[]],"floor":0.0},"pair_add_250":{"qty":[0.0,0.0],"cash":0.0,"lots":[[],[]],"floor":0.0}}}
{"kind":"decision","recorded_ms":1789995750055,"S":1789995600,"age":150,"signal":{},"entry_side":null,"context_gap":"incomplete or stale context","book_errors":[null,null],"books":[{"bid":0.14,"ask":0.15,"asks":[[0.15,169.0]],"received_ms":1789995750054,"observed_ms":1789995750044,"hash":"d3cd6c9523180d39d0886fe7cc31a88552763bcc"},{"bid":0.85,"ask":0.86,"asks":[[0.86,860.97]],"received_ms":1789995750049,"observed_ms":1789995750035,"hash":"6e9363411e53c68f5102e356ba06479a936a4a3d"}],"intents":{"pair_fast":null,"pair_250":null,"pair_add_fast":null,"pair_add_250":null},"decision_ms":1789995750055,"feature_cutoff_ms":1789995750055,"request_ms":1789995750022,"inventory":{"pair_fast":{"qty":[0.0,0.0],"cash":0.0,"lots":[[],[]],"floor":0.0},"pair_250":{"qty":[0.0,0.0],"cash":0.0,"lots":[[],[]],"floor":0.0},"pair_add_fast":{"qty":[0.0,0.0],"cash":0.0,"lots":[[],[]],"floor":0.0},"pair_add_250":{"qty":[0.0,0.0],"cash":0.0,"lots":[[],[]],"floor":0.0}}}
{"kind":"decision","recorded_ms":1789995760085,"S":1789995600,"age":160,"signal":{},"entry_side":null,"context_gap":"incomplete or stale context","book_errors":[null,null],"books":[{"bid":0.28,"ask":0.29,"asks":[[0.29,126.0]],"received_ms":1789995760062,"observed_ms":1789995760049,"hash":"fb0f3f4305be9834deab8cd59e54080fa9b51a32"},{"bid":0.71,"ask":0.72,"asks":[[0.72,695.65]],"received_ms":1789995760083,"observed_ms":1789995760061,"hash":"ed1e5c2169daddd1aa4989d6abdc86e0126948f7"}],"intents":{"pair_fast":null,"pair_250":null,"pair_add_fast":null,"pair_add_250":null},"decision_ms":1789995760085,"feature_cutoff_ms":1789995760083,"request_ms":1789995760029,"inventory":{"pair_fast":{"qty":[0.0,0.0],"cash":0.0,"lots":[[],[]],"floor":0.0},"pair_250":{"qty":[0.0,0.0],"cash":0.0,"lots":[[],[]],"floor":0.0},"pair_add_fast":{"qty":[0.0,0.0],"cash":0.0,"lots":[[],[]],"floor":0.0},"pair_add_250":{"qty":[0.0,0.0],"cash":0.0,"lots":[[],[]],"floor":0.0}}}
{"kind":"decision","recorded_ms":1789995770048,"S":1789995600,"age":170,"signal":{},"entry_side":null,"context_gap":"incomplete or stale context","book_errors":[null,null],"books":[{"bid":0.37,"ask":0.38,"asks":[[0.38,1189.78]],"received_ms":1789995770047,"observed_ms":1789995770037,"hash":"a3fb2a4070a3d94f832d3196a764656b7bb15baa"},{"bid":0.62,"ask":0.63,"asks":[[0.63,23.73]],"received_ms":1789995770045,"observed_ms":1789995770027,"hash":"dadeaeaeb383ddfe013846c01359ca7baa57b50f"}],"intents":{"pair_fast":null,"pair_250":null,"pair_add_fast":null,"pair_add_250":null},"decision_ms":1789995770048,"feature_cutoff_ms":1789995770047,"request_ms":1789995770005,"inventory":{"pair_fast":{"qty":[0.0,0.0],"cash":0.0,"lots":[[],[]],"floor":0.0},"pair_250":{"qty":[0.0,0.0],"cash":0.0,"lots":[[],[]],"floor":0.0},"pair_add_fast":{"qty":[0.0,0.0],"cash":0.0,"lots":[[],[]],"floor":0.0},"pair_add_250":{"qty":[0.0,0.0],"cash":0.0,"lots":[[],[]],"floor":0.0}}}
{"kind":"decision","recorded_ms":1789995780114,"S":1789995600,"age":180,"signal":{"rsi14":53.17234627756303,"volume_ratio":1.2193144960161226,"taker_buy_fraction":0.4628183986134353,"volume5":261.04228,"return1":4.466318353261121,"return5":-3.2324509930635625,"return15":11.43907639163687,"bollinger_z":0.056725135261976305,"bar_close_ms":1789995719999,"ref":85348.91601144883,"reference_received_ms":1789995602029,"spot":85310.3184222587,"twap":85270.50178217213,"sigma":7.353300934149749,"spot_z":-0.4793931156784735,"twap_z":-0.9739271927402307,"momentum":-0.9918933093666756,"decision_ms":1789995780113,"momentum30":1.4671252500882508,"momentum60":1.2471182182157539,"spot_twap_gap":0.6990474316147665,"range60":1.7011378526745748,"final_mean":85310.3184222587,"final_z":-0.5872726600966479,"final_up_prob":0.2785102999145001,"final_drift_up_prob":9.138119640195175e-05,"final_known_seconds":0,"final_sd":65.72345660324207,"final_drift_shift":-207.32142586690094},"entry_side":null,"context_gap":null,"book_errors":[null,null],"books":[{"bid":0.27,"ask":0.28,"asks":[[0.28,370.57]],"received_ms":1789995780113,"observed_ms":1789995780078,"hash":"cb3e0c3767beb919ea389a142c437ba7daaeabf3"},{"bid":0.72,"ask":0.73,"asks":[[0.73,72.0]],"received_ms":1789995780050,"observed_ms":1789995780039,"hash":"4d1605a595c1abbd31d3cc3e1df51aba4dcd40ac"}],"intents":{"pair_fast":null,"pair_250":null,"pair_add_fast":null,"pair_add_250":null},"decision_ms":1789995780114,"feature_cutoff_ms":1789995780113,"request_ms":1789995780019,"inventory":{"pair_fast":{"qty":[0.0,0.0],"cash":0.0,"lots":[[],[]],"floor":0.0},"pair_250":{"qty":[0.0,0.0],"cash":0.0,"lots":[[],[]],"floor":0.0},"pair_add_fast":{"qty":[0.0,0.0],"cash":0.0,"lots":[[],[]],"floor":0.0},"pair_add_250":{"qty":[0.0,0.0],"cash":0.0,"lots":[[],[]],"floor":0.0}}}
{"kind":"decision","recorded_ms":1789995790049,"S":1789995600,"age":190,"signal":{},"entry_side":null,"context_gap":"incomplete or stale context","book_errors":[null,null],"books":[{"bid":0.14,"ask":0.15,"asks":[[0.15,912.53]],"received_ms":1789995790048,"observed_ms":1789995790039,"hash":"59b74201cafa5d344da86f02d6d8513b10d2da1b"},{"bid":0.85,"ask":0.86,"asks":[[0.86,153.75]],"received_ms":1789995790038,"observed_ms":1789995790028,"hash":"2d32f1e21159cd648a16d36317b882bfe4b94aa3"}],"intents":{"pair_fast":null,"pair_250":null,"pair_add_fast":null,"pair_add_250":null},"decision_ms":1789995790049,"feature_cutoff_ms":1789995790049,"request_ms":1789995790012,"inventory":{"pair_fast":{"qty":[0.0,0.0],"cash":0.0,"lots":[[],[]],"floor":0.0},"pair_250":{"qty":[0.0,0.0],"cash":0.0,"lots":[[],[]],"floor":0.0},"pair_add_fast":{"qty":[0.0,0.0],"cash":0.0,"lots":[[],[]],"floor":0.0},"pair_add_250":{"qty":[0.0,0.0],"cash":0.0,"lots":[[],[]],"floor":0.0}}}
{"kind":"decision","recorded_ms":1789995800060,"S":1789995600,"age":200,"signal":{},"entry_side":null,"context_gap":"incomplete or stale context","book_errors":[null,null],"books":[{"bid":0.14,"ask":0.15,"asks":[[0.15,236.01]],"received_ms":1789995800059,"observed_ms":1789995799948,"hash":"3450e0c3fb7e620bb214d321651e582813fe293e"},{"bid":0.85,"ask":0.86,"asks":[[0.86,96.2]],"received_ms":1789995800046,"observed_ms":1789995799948,"hash":"227b132157f0ffab14974419a5719159780b2cc0"}],"intents":{"pair_fast":null,"pair_250":null,"pair_add_fast":null,"pair_add_250":null},"decision_ms":1789995800060,"feature_cutoff_ms":1789995800059,"request_ms":1789995800022,"inventory":{"pair_fast":{"qty":[0.0,0.0],"cash":0.0,"lots":[[],[]],"floor":0.0},"pair_250":{"qty":[0.0,0.0],"cash":0.0,"lots":[[],[]],"floor":0.0},"pair_add_fast":{"qty":[0.0,0.0],"cash":0.0,"lots":[[],[]],"floor":0.0},"pair_add_250":{"qty":[0.0,0.0],"cash":0.0,"lots":[[],[]],"floor":0.0}}}
{"kind":"decision","recorded_ms":1789995810080,"S":1789995600,"age":210,"signal":{},"entry_side":null,"context_gap":"incomplete or stale context","book_errors":[null,null],"books":[{"bid":0.05,"ask":0.06,"asks":[[0.06,405.54]],"received_ms":1789995810074,"observed_ms":1789995810065,"hash":"95f8a171cd2ded35a3dd3f123ccfa4e1ec07f869"},{"bid":0.94,"ask":0.95,"asks":[[0.95,181.15]],"received_ms":1789995810078,"observed_ms":1789995810054,"hash":"d1275e6965b643d1a04733d4ca9ff094ff5a3e82"}],"intents":{"pair_fast":null,"pair_250":null,"pair_add_fast":null,"pair_add_250":null},"decision_ms":1789995810080,"feature_cutoff_ms":1789995810078,"request_ms":1789995810032,"inventory":{"pair_fast":{"qty":[0.0,0.0],"cash":0.0,"lots":[[],[]],"floor":0.0},"pair_250":{"qty":[0.0,0.0],"cash":0.0,"lots":[[],[]],"floor":0.0},"pair_add_fast":{"qty":[0.0,0.0],"cash":0.0,"lots":[[],[]],"floor":0.0},"pair_add_250":{"qty":[0.0,0.0],"cash":0.0,"lots":[[],[]],"floor":0.0}}}
{"kind":"decision","recorded_ms":1789995820034,"S":1789995600,"age":220,"signal":{},"entry_side":null,"context_gap":"incomplete or stale context","book_errors":[null,null],"books":[{"bid":0.03,"ask":0.04,"asks":[[0.04,1641.76]],"received_ms":1789995820029,"observed_ms":1789995819985,"hash":"2c3b8a5cddea07fb3daf3cd4b4b19ff7a8363982"},{"bid":0.96,"ask":0.97,"asks":[[0.97,797.36]],"received_ms":1789995820033,"observed_ms":1789995819985,"hash":"23c3f0351e561b34414cd66981cab5b2a34da910"}],"intents":{"pair_fast":null,"pair_250":null,"pair_add_fast":null,"pair_add_250":null},"decision_ms":1789995820034,"feature_cutoff_ms":1789995820033,"request_ms":1789995820003,"inventory":{"pair_fast":{"qty":[0.0,0.0],"cash":0.0,"lots":[[],[]],"floor":0.0},"pair_250":{"qty":[0.0,0.0],"cash":0.0,"lots":[[],[]],"floor":0.0},"pair_add_fast":{"qty":[0.0,0.0],"cash":0.0,"lots":[[],[]],"floor":0.0},"pair_add_250":{"qty":[0.0,0.0],"cash":0.0,"lots":[[],[]],"floor":0.0}}}
{"kind":"decision","recorded_ms":1789995830035,"S":1789995600,"age":230,"signal":{},"entry_side":null,"context_gap":"incomplete or stale context","book_errors":[null,null],"books":[{"bid":0.01,"ask":0.02,"asks":[[0.02,1315.38]],"received_ms":1789995830034,"observed_ms":1789995830025,"hash":"c1ad405fe4d3748532deb877adeb2b7fbf145e0b"},{"bid":0.98,"ask":0.99,"asks":[[0.99,3801.81]],"received_ms":1789995830034,"observed_ms":1789995830026,"hash":"cbc2d70961d617b84b767c33fa34e1869b76be01"}],"intents":{"pair_fast":null,"pair_250":null,"pair_add_fast":null,"pair_add_250":null},"decision_ms":1789995830035,"feature_cutoff_ms":1789995830034,"request_ms":1789995830006,"inventory":{"pair_fast":{"qty":[0.0,0.0],"cash":0.0,"lots":[[],[]],"floor":0.0},"pair_250":{"qty":[0.0,0.0],"cash":0.0,"lots":[[],[]],"floor":0.0},"pair_add_fast":{"qty":[0.0,0.0],"cash":0.0,"lots":[[],[]],"floor":0.0},"pair_add_250":{"qty":[0.0,0.0],"cash":0.0,"lots":[[],[]],"floor":0.0}}}
{"kind":"decision","recorded_ms":1789995840050,"S":1789995600,"age":240,"signal":{},"entry_side":null,"context_gap":"two-sided entry context unavailable","book_errors":[null,"empty/invalid public book"],"books":[{"bid":null,"ask":0.01,"asks":[[0.01,6410.97]],"received_ms":1789995840050,"observed_ms":1789995839996,"hash":"a7e235890cafed00b8124e392aa826dc7853e7f1"},null],"intents":{"pair_fast":null,"pair_250":null,"pair_add_fast":null,"pair_add_250":null},"decision_ms":1789995840050,"feature_cutoff_ms":1789995840050,"request_ms":1789995840007,"inventory":{"pair_fast":{"qty":[0.0,0.0],"cash":0.0,"lots":[[],[]],"floor":0.0},"pair_250":{"qty":[0.0,0.0],"cash":0.0,"lots":[[],[]],"floor":0.0},"pair_add_fast":{"qty":[0.0,0.0],"cash":0.0,"lots":[[],[]],"floor":0.0},"pair_add_250":{"qty":[0.0,0.0],"cash":0.0,"lots":[[],[]],"floor":0.0}}}
{"kind":"decision","recorded_ms":1789995850049,"S":1789995600,"age":250,"signal":{},"entry_side":null,"context_gap":"two-sided entry context unavailable","book_errors":[null,"empty/invalid public book"],"books":[{"bid":null,"ask":0.01,"asks":[[0.01,14845.68]],"received_ms":1789995850049,"observed_ms":1789995850038,"hash":"28b3186c4f56a134c1b38ac732f9e393afa41bc4"},null],"intents":{"pair_fast":null,"pair_250":null,"pair_add_fast":null,"pair_add_250":null},"decision_ms":1789995850049,"feature_cutoff_ms":1789995850049,"request_ms":1789995850012,"inventory":{"pair_fast":{"qty":[0.0,0.0],"cash":0.0,"lots":[[],[]],"floor":0.0},"pair_250":{"qty":[0.0,0.0],"cash":0.0,"lots":[[],[]],"floor":0.0},"pair_add_fast":{"qty":[0.0,0.0],"cash":0.0,"lots":[[],[]],"floor":0.0},"pair_add_250":{"qty":[0.0,0.0],"cash":0.0,"lots":[[],[]],"floor":0.0}}}
{"kind":"decision","recorded_ms":1789995860054,"S":1789995600,"age":260,"signal":{},"entry_side":null,"context_gap":"two-sided entry context unavailable","book_errors":[null,"empty/invalid public book"],"books":[{"bid":null,"ask":0.01,"asks":[[0.01,30424.01]],"received_ms":1789995860045,"observed_ms":1789995860030,"hash":"3c1aafa56d785c2efa9e792648282d78324bb8b2"},null],"intents":{"pair_fast":null,"pair_250":null,"pair_add_fast":null,"pair_add_250":null},"decision_ms":1789995860054,"feature_cutoff_ms":1789995860054,"request_ms":1789995860022,"inventory":{"pair_fast":{"qty":[0.0,0.0],"cash":0.0,"lots":[[],[]],"floor":0.0},"pair_250":{"qty":[0.0,0.0],"cash":0.0,"lots":[[],[]],"floor":0.0},"pair_add_fast":{"qty":[0.0,0.0],"cash":0.0,"lots":[[],[]],"floor":0.0},"pair_add_250":{"qty":[0.0,0.0],"cash":0.0,"lots":[[],[]],"floor":0.0}}}
{"kind":"decision","recorded_ms":1789995870063,"S":1789995600,"age":270,"signal":{},"entry_side":null,"context_gap":"two-sided entry context unavailable","book_errors":[null,"empty/invalid public book"],"books":[{"bid":null,"ask":0.01,"asks":[[0.01,39484.68]],"received_ms":1789995870056,"observed_ms":1789995870039,"hash":"0468c1d5eca781f7c8813942361a7a6784aa4d19"},null],"intents":{"pair_fast":null,"pair_250":null,"pair_add_fast":null,"pair_add_250":null},"decision_ms":1789995870063,"feature_cutoff_ms":1789995870063,"request_ms":1789995870026,"inventory":{"pair_fast":{"qty":[0.0,0.0],"cash":0.0,"lots":[[],[]],"floor":0.0},"pair_250":{"qty":[0.0,0.0],"cash":0.0,"lots":[[],[]],"floor":0.0},"pair_add_fast":{"qty":[0.0,0.0],"cash":0.0,"lots":[[],[]],"floor":0.0},"pair_add_250":{"qty":[0.0,0.0],"cash":0.0,"lots":[[],[]],"floor":0.0}}}
{"kind":"decision","recorded_ms":1789995880062,"S":1789995600,"age":280,"signal":{},"entry_side":null,"context_gap":"two-sided entry context unavailable","book_errors":[null,"empty/invalid public book"],"books":[{"bid":null,"ask":0.01,"asks":[[0.01,51991.52]],"received_ms":1789995880062,"observed_ms":1789995880044,"hash":"f9de78bffc8166875d5b06e708bb7454ae4ff80a"},null],"intents":{"pair_fast":null,"pair_250":null,"pair_add_fast":null,"pair_add_250":null},"decision_ms":1789995880062,"feature_cutoff_ms":1789995880062,"request_ms":1789995880036,"inventory":{"pair_fast":{"qty":[0.0,0.0],"cash":0.0,"lots":[[],[]],"floor":0.0},"pair_250":{"qty":[0.0,0.0],"cash":0.0,"lots":[[],[]],"floor":0.0},"pair_add_fast":{"qty":[0.0,0.0],"cash":0.0,"lots":[[],[]],"floor":0.0},"pair_add_250":{"qty":[0.0,0.0],"cash":0.0,"lots":[[],[]],"floor":0.0}}}
{"kind":"decision","recorded_ms":1789995890067,"S":1789995600,"age":290,"signal":{},"entry_side":null,"context_gap":"two-sided entry context unavailable","book_errors":[null,"empty/invalid public book"],"books":[{"bid":null,"ask":0.01,"asks":[[0.01,52447.62]],"received_ms":1789995890063,"observed_ms":1789995890050,"hash":"b134847d157ed5410da3ded406809513d17ba677"},null],"intents":{"pair_fast":null,"pair_250":null,"pair_add_fast":null,"pair_add_250":null},"decision_ms":1789995890067,"feature_cutoff_ms":1789995890067,"request_ms":1789995890034,"inventory":{"pair_fast":{"qty":[0.0,0.0],"cash":0.0,"lots":[[],[]],"floor":0.0},"pair_250":{"qty":[0.0,0.0],"cash":0.0,"lots":[[],[]],"floor":0.0},"pair_add_fast":{"qty":[0.0,0.0],"cash":0.0,"lots":[[],[]],"floor":0.0},"pair_add_250":{"qty":[0.0,0.0],"cash":0.0,"lots":[[],[]],"floor":0.0}}}
{"kind":"decision","recorded_ms":1789995930094,"S":1789995900,"age":30,"signal":{"rsi14":49.47710647520988,"volume_ratio":0.5874214567808764,"taker_buy_fraction":0.36067571044976504,"volume5":178.76,"return1":-4.343514506304728,"return5":-10.85057324535811,"return15":-5.594240185322466,"bollinger_z":-0.5994276724831356,"bar_close_ms":1789995899999,"ref":85215.27975749645,"reference_received_ms":1789995901219,"spot":85243.19279745923,"twap":85217.5350148258,"sigma":4.258013653991399,"spot_z":0.39901848332312784,"twap_z":0.03223903094255979,"momentum":-0.7730318646990411,"decision_ms":1789995930093,"momentum30":1.5216125487072008,"momentum60":1.4983005127789488,"spot_twap_gap":0.7779227038309694,"range60":1.8138894500164244,"final_mean":85243.19279745923,"final_z":0.43233857852490576,"final_up_prob":0.667252323924969,"final_drift_up_prob":0.00029577080021686575,"final_known_seconds":0,"final_sd":64.56291746624149,"final_drift_shift":-249.71657282482815},"entry_side":null,"context_gap":null,"book_errors":[null,null],"books":[{"bid":0.58,"ask":0.59,"asks":[[0.59,499.0]],"received_ms":1789995930088,"observed_ms":1789995930079,"hash":"c1eb6484cdf2f4e6e916ea663fbd88fd66104d49"},{"bid":0.41,"ask":0.42,"asks":[[0.42,152.0]],"received_ms":1789995930093,"observed_ms":1789995930084,"hash":"7b3bf4394c7e5cd22d6fad8fb64b226721ee6c23"}],"intents":{"pair_fast":null,"pair_250":null,"pair_add_fast":null,"pair_add_250":null},"decision_ms":1789995930094,"feature_cutoff_ms":1789995930093,"request_ms":1789995930048,"inventory":{"pair_fast":{"qty":[0.0,0.0],"cash":0.0,"lots":[[],[]],"floor":0.0},"pair_250":{"qty":[0.0,0.0],"cash":0.0,"lots":[[],[]],"floor":0.0},"pair_add_fast":{"qty":[0.0,0.0],"cash":0.0,"lots":[[],[]],"floor":0.0},"pair_add_250":{"qty":[0.0,0.0],"cash":0.0,"lots":[[],[]],"floor":0.0}}}
{"kind":"decision","recorded_ms":1789995940097,"S":1789995900,"age":40,"signal":{"rsi14":49.47710647520988,"volume_ratio":0.5874214567808764,"taker_buy_fraction":0.36067571044976504,"volume5":178.76,"return1":-4.343514506304728,"return5":-10.85057324535811,"return15":-5.594240185322466,"bollinger_z":-0.5994276724831356,"bar_close_ms":1789995899999,"ref":85215.27975749645,"reference_received_ms":1789995901219,"spot":85311.60997735793,"twap":85225.97524522545,"sigma":9.731750185041477,"spot_z":0.6139954003643537,"twap_z":0.06817154865524613,"momentum":2.2231779017299518,"decision_ms":1789995940096,"momentum30":1.4227734459377404,"momentum60":1.4235081526074342,"spot_twap_gap":1.1360131702923142,"range60":1.4303990028863771,"final_mean":85311.60997735793,"final_z":0.6675057864872189,"final_up_prob":0.7477754426118844,"final_drift_up_prob":1.0,"final_known_seconds":0,"final_sd":144.3136850819319,"final_drift_shift":1572.9383330433989},"entry_side":null,"context_gap":null,"book_errors":[null,null],"books":[{"bid":0.78,"ask":0.79,"asks":[[0.79,510.0]],"received_ms":1789995940096,"observed_ms":1789995940082,"hash":"355032beab5f9c1066d93fb7a9d84633cb868a89"},{"bid":0.21,"ask":0.22,"asks":[[0.22,459.57]],"received_ms":1789995940053,"observed_ms":1789995940044,"hash":"d4751d4d745a1236ec15081347e73daf0892c6ad"}],"intents":{"pair_fast":null,"pair_250":null,"pair_add_fast":null,"pair_add_250":null},"decision_ms":1789995940097,"feature_cutoff_ms":1789995940096,"request_ms":1789995940017,"inventory":{"pair_fast":{"qty":[0.0,0.0],"cash":0.0,"lots":[[],[]],"floor":0.0},"pair_250":{"qty":[0.0,0.0],"cash":0.0,"lots":[[],[]],"floor":0.0},"pair_add_fast":{"qty":[0.0,0.0],"cash":0.0,"lots":[[],[]],"floor":0.0},"pair_add_250":{"qty":[0.0,0.0],"cash":0.0,"lots":[[],[]],"floor":0.0}}}
{"kind":"decision","recorded_ms":1789995950070,"S":1789995900,"age":50,"signal":{"rsi14":49.47710647520988,"volume_ratio":0.5874214567808764,"taker_buy_fraction":0.36067571044976504,"volume5":178.76,"return1":-4.343514506304728,"return5":-10.85057324535811,"return15":-5.594240185322466,"bollinger_z":-0.5994276724831356,"bar_close_ms":1789995899999,"ref":85215.27975749645,"reference_received_ms":1789995901219,"spot":85362.00041694184,"twap":85246.69660795828,"sigma":10.922059975513422,"spot_z":0.8497215836826003,"twap_z":0.18194830932231815,"momentum":1.4589606881805992,"decision_ms":1789995950069,"momentum30":1.812003386518104,"momentum60":1.8551903103417224,"spot_twap_gap":1.3628983694431087,"range60":1.8551903103417224,"final_mean":85362.00041694184,"final_z":0.9271466341582244,"final_up_prob":0.823074796889441,"final_drift_up_prob":0.9999999999999989,"final_known_seconds":0,"final_sd":158.24968137709942,"final_drift_shift":1108.241976783956},"entry_side":null,"context_gap":null,"book_errors":[null,null],"books":[{"bid":0.83,"ask":0.84,"asks":[[0.84,1107.73]],"received_ms":1789995950068,"observed_ms":1789995950047,"hash":"42b13e91d2f9ddc973933077dc183f8afc45ec90"},{"bid":0.16,"ask":0.17,"asks":[[0.17,149.0]],"received_ms":1789995950052,"observed_ms":1789995950043,"hash":"0d7a3763dcd3bd81c3d71f7bba0e2c26f6d6b845"}],"intents":{"pair_fast":null,"pair_250":null,"pair_add_fast":null,"pair_add_250":null},"decision_ms":1789995950070,"feature_cutoff_ms":1789995950069,"request_ms":1789995950019,"inventory":{"pair_fast":{"qty":[0.0,0.0],"cash":0.0,"lots":[[],[]],"floor":0.0},"pair_250":{"qty":[0.0,0.0],"cash":0.0,"lots":[[],[]],"floor":0.0},"pair_add_fast":{"qty":[0.0,0.0],"cash":0.0,"lots":[[],[]],"floor":0.0},"pair_add_250":{"qty":[0.0,0.0],"cash":0.0,"lots":[[],[]],"floor":0.0}}}
{"kind":"decision","recorded_ms":1789995960074,"S":1789995900,"age":60,"signal":{"rsi14":49.47710647520988,"volume_ratio":0.5874214567808764,"taker_buy_fraction":0.36067571044976504,"volume5":178.76,"return1":-4.343514506304728,"return5":-10.85057324535811,"return15":-5.594240185322466,"bollinger_z":-0.5994276724831356,"bar_close_ms":1789995899999,"ref":85215.27975749645,"reference_received_ms":1789995901219,"spot":85347.91552245007,"twap":85271.4716436164,"sigma":11.028968407648634,"spot_z":0.7764011890945651,"twap_z":0.328926720603994,"momentum":-0.40384871504622927,"decision_ms":1789995960073,"momentum30":1.7335860931809937,"momentum60":1.6412254590135873,"spot_twap_gap":0.8948128198976414,"range60":1.806096006537238,"final_mean":85347.91552245007,"final_z":0.8505307684414712,"final_up_prob":0.8024849691973173,"final_drift_up_prob":0.14789002147420993,"final_known_seconds":0,"final_sd":155.94469932776968,"final_drift_shift":-295.6799646617936},"entry_side":null,"context_gap":null,"book_errors":[null,null],"books":[{"bid":0.82,"ask":0.83,"asks":[[0.83,1132.9]],"received_ms":1789995960073,"observed_ms":1789995960062,"hash":"b868d86156c7e16fcba9bbd121ebd8210304cab9"},{"bid":0.17,"ask":0.18,"asks":[[0.18,97.22]],"received_ms":1789995960068,"observed_ms":1789995960058,"hash":"7603af5866ade14923107689642643ce672d376e"}],"intents":{"pair_fast":null,"pair_250":null,"pair_add_fast":null,"pair_add_250":null},"decision_ms":1789995960074,"feature_cutoff_ms":1789995960073,"request_ms":1789995960043,"inventory":{"pair_fast":{"qty":[0.0,0.0],"cash":0.0,"lots":[[],[]],"floor":0.0},"pair_250":{"qty":[0.0,0.0],"cash":0.0,"lots":[[],[]],"floor":0.0},"pair_add_fast":{"qty":[0.0,0.0],"cash":0.0,"lots":[[],[]],"floor":0.0},"pair_add_250":{"qty":[0.0,0.0],"cash":0.0,"lots":[[],[]],"floor":0.0}}}
{"kind":"decision","recorded_ms":1789995970061,"S":1789995900,"age":70,"signal":{"rsi14":58.26172410640891,"volume_ratio":1.1944750773848005,"taker_buy_fraction":0.5302513474187043,"volume5":131.77975,"return1":16.939357288315467,"return5":17.902166836856317,"return15":16.035112797471744,"bollinger_z":1.5164967268824294,"bar_close_ms":1789995959999,"ref":85215.27975749645,"reference_received_ms":1789995901219,"spot":85343.43709126987,"twap":85295.6555777945,"sigma":10.537512142118334,"spot_z":0.8020438480924608,"twap_z":0.5030139930923826,"momentum":-0.13439645603978956,"decision_ms":1789995970060,"momentum30":0.5514403524836486,"momentum60":1.3190510818074055,"spot_twap_gap":0.585391198766265,"range60":1.5464781069854328,"final_mean":85343.43709126987,"final_z":0.8824643276226839,"final_up_prob":0.8112371188689926,"final_drift_up_prob":0.6048413989791208,"final_known_seconds":0,"final_sd":145.2266451593176,"final_drift_shift":-89.54175304268107},"entry_side":null,"context_gap":null,"book_errors":[null,null],"books":[{"bid":0.79,"ask":0.8,"asks":[[0.8,1112.61]],"received_ms":1789995970060,"observed_ms":1789995970051,"hash":"7bb02064349360afeaf4dcca993a2db17ea7b45d"},{"bid":0.2,"ask":0.21,"asks":[[0.21,105.92]],"received_ms":1789995970051,"observed_ms":1789995970041,"hash":"54a9f1312a859cf1fab8d099b8cad94a3b08ae1f"}],"intents":{"pair_fast":null,"pair_250":null,"pair_add_fast":null,"pair_add_250":null},"decision_ms":1789995970061,"feature_cutoff_ms":1789995970060,"request_ms":1789995970027,"inventory":{"pair_fast":{"qty":[0.0,0.0],"cash":0.0,"lots":[[],[]],"floor":0.0},"pair_250":{"qty":[0.0,0.0],"cash":0.0,"lots":[[],[]],"floor":0.0},"pair_add_fast":{"qty":[0.0,0.0],"cash":0.0,"lots":[[],[]],"floor":0.0},"pair_add_250":{"qty":[0.0,0.0],"cash":0.0,"lots":[[],[]],"floor":0.0}}}
{"kind":"decision","recorded_ms":1789995980063,"S":1789995900,"age":80,"signal":{"rsi14":58.26172410640891,"volume_ratio":1.1944750773848005,"taker_buy_fraction":0.5302513474187043,"volume5":131.77975,"return1":16.939357288315467,"return5":17.902166836856317,"return15":16.035112797471744,"bollinger_z":1.5164967268824294,"bar_close_ms":1789995959999,"ref":85215.27975749645,"reference_received_ms":1789995901219,"spot":85340.3876468969,"twap":85310.87719731573,"sigma":10.509578123184593,"spot_z":0.8026926363601807,"twap_z":0.6133534932573653,"momentum":-0.09175620280412732,"decision_ms":1789995980062,"momentum30":-0.3754607319480213,"momentum60":1.0660769606395617,"spot_twap_gap":0.3625057651452321,"range60":1.459430392179178,"final_mean":85340.3876468969,"final_z":0.887437895673746,"final_up_prob":0.8125784057452379,"final_drift_up_prob":0.6831713362143939,"final_known_seconds":0,"final_sd":140.97650101527782,"final_drift_shift":-57.920536520256},"entry_side":null,"context_gap":null,"book_errors":[null,null],"books":[{"bid":0.8,"ask":0.81,"asks":[[0.81,895.69]],"received_ms":1789995980062,"observed_ms":1789995980052,"hash":"13b341ff30b7d2c3939d83f020c4c4a8ac910f04"},{"bid":0.19,"ask":0.2,"asks":[[0.2,62.0]],"received_ms":1789995980057,"observed_ms":1789995980050,"hash":"4d302889193e00f29f9a1405047b4fdca6c49ee6"}],"intents":{"pair_fast":null,"pair_250":null,"pair_add_fast":null,"pair_add_250":null},"decision_ms":1789995980063,"feature_cutoff_ms":1789995980062,"request_ms":1789995980033,"inventory":{"pair_fast":{"qty":[0.0,0.0],"cash":0.0,"lots":[[],[]],"floor":0.0},"pair_250":{"qty":[0.0,0.0],"cash":0.0,"lots":[[],[]],"floor":0.0},"pair_add_fast":{"qty":[0.0,0.0],"cash":0.0,"lots":[[],[]],"floor":0.0},"pair_add_250":{"qty":[0.0,0.0],"cash":0.0,"lots":[[],[]],"floor":0.0}}}
{"kind":"decision","recorded_ms":1789995990073,"S":1789995900,"age":90,"signal":{"rsi14":58.26172410640891,"volume_ratio":1.1944750773848005,"taker_buy_fraction":0.5302513474187043,"volume5":131.77975,"return1":16.939357288315467,"return5":17.902166836856317,"return15":16.035112797471744,"bollinger_z":1.5164967268824294,"bar_close_ms":1789995959999,"ref":85215.27975749645,"reference_received_ms":1789995901219,"spot":85342.48502523979,"twap":85324.18747244852,"sigma":10.714490180017238,"spot_z":0.8194046065961975,"twap_z":0.7015392122412218,"momentum":0.061902083694285986,"decision_ms":1789995990072,"momentum30":-0.09253530407785406,"momentum60":1.1963771744024456,"spot_twap_gap":0.2204681574399856,"range60":1.431519135699308,"final_mean":85342.48502523979,"final_z":0.9107540524527457,"final_up_prob":0.8187875115009496,"final_drift_up_prob":0.8811878065209966,"final_known_seconds":0,"final_sd":139.67027366033983,"final_drift_shift":37.737709042397825},"entry_side":null,"context_gap":null,"book_errors":[null,null],"books":[{"bid":0.87,"ask":0.88,"asks":[[0.88,15.03]],"received_ms":1789995990071,"observed_ms":1789995990057,"hash":"1036109f56b60d28a7ec1fb447a67f63bd2bd521"},{"bid":0.12,"ask":0.13,"asks":[[0.13,991.81]],"received_ms":1789995990064,"observed_ms":1789995990056,"hash":"62881d49cb5c21599711b02cad1846248726905e"}],"intents":{"pair_fast":null,"pair_250":null,"pair_add_fast":null,"pair_add_250":null},"decision_ms":1789995990073,"feature_cutoff_ms":1789995990072,"request_ms":1789995990036,"inventory":{"pair_fast":{"qty":[0.0,0.0],"cash":0.0,"lots":[[],[]],"floor":0.0},"pair_250":{"qty":[0.0,0.0],"cash":0.0,"lots":[[],[]],"floor":0.0},"pair_add_fast":{"qty":[0.0,0.0],"cash":0.0,"lots":[[],[]],"floor":0.0},"pair_add_250":{"qty":[0.0,0.0],"cash":0.0,"lots":[[],[]],"floor":0.0}}}
{"kind":"decision","recorded_ms":1789996000098,"S":1789995900,"age":100,"signal":{"rsi14":58.26172410640891,"volume_ratio":1.1944750773848005,"taker_buy_fraction":0.5302513474187043,"volume5":131.77975,"return1":16.939357288315467,"return5":17.902166836856317,"return15":16.035112797471744,"bollinger_z":1.5164967268824294,"bar_close_ms":1789995959999,"ref":85215.27975749645,"reference_received_ms":1789995901219,"spot":85411.72418699968,"twap":85344.243457818,"sigma":9.359985576828377,"spot_z":1.484413456604054,"twap_z":0.9745018102822246,"momentum":2.339249912779049,"decision_ms":1789996000097,"momentum30":1.331995739050698,"momentum60":1.3808449577853101,"spot_twap_gap":0.9307412501346717,"range60":1.3808449577853101,"final_mean":85411.72418699968,"final_z":1.6597253704488248,"final_up_prob":0.95151514344677,"final_drift_up_prob":1.0,"final_known_seconds":0,"final_sd":118.3595991245872,"final_drift_shift":1176.3941308546691},"entry_side":null,"context_gap":null,"book_errors":[null,null],"books":[{"bid":0.91,"ask":0.92,"asks":[[0.92,1548.92]],"received_ms":1789996000072,"observed_ms":1789996000063,"hash":"84d69cdc857f49efc1de5c5bb1efdaefcbdd31de"},{"bid":0.08,"ask":0.09,"asks":[[0.09,30.0]],"received_ms":1789996000097,"observed_ms":1789996000085,"hash":"5cac89e45fade9ec8b492a07a6fe078b1e6e2b5e"}],"intents":{"pair_fast":null,"pair_250":null,"pair_add_fast":null,"pair_add_250":null},"decision_ms":1789996000098,"feature_cutoff_ms":1789996000097,"request_ms":1789996000046,"inventory":{"pair_fast":{"qty":[0.0,0.0],"cash":0.0,"lots":[[],[]],"floor":0.0},"pair_250":{"qty":[0.0,0.0],"cash":0.0,"lots":[[],[]],"floor":0.0},"pair_add_fast":{"qty":[0.0,0.0],"cash":0.0,"lots":[[],[]],"floor":0.0},"pair_add_250":{"qty":[0.0,0.0],"cash":0.0,"lots":[[],[]],"floor":0.0}}}
{"kind":"decision","recorded_ms":1789996010053,"S":1789995900,"age":110,"signal":{"rsi14":58.26172410640891,"volume_ratio":1.1944750773848005,"taker_buy_fraction":0.5302513474187043,"volume5":131.77975,"return1":16.939357288315467,"return5":17.902166836856317,"return15":16.035112797471744,"bollinger_z":1.5164967268824294,"bar_close_ms":1789995959999,"ref":85215.27975749645,"reference_received_ms":1789995901219,"spot":85399.70080654683,"twap":85356.76325296216,"sigma":9.064937569735955,"spot_z":1.4761425810197046,"twap_z":1.132461903041221,"momentum":-0.4194322036227095,"decision_ms":1789996010052,"momentum30":1.1946085396709476,"momentum60":0.536914825069581,"spot_twap_gap":0.6115005524711045,"range60":1.1878606128461553,"final_mean":85399.70080654683,"final_z":1.661404306871727,"final_up_prob":0.9516838633009379,"final_drift_up_prob":0.4716655538726782,"final_known_seconds":0,"final_sd":111.00311241977194,"final_drift_shift":-192.3115656122757},"entry_side":null,"context_gap":null,"book_errors":[null,null],"books":[{"bid":0.91,"ask":0.92,"asks":[[0.92,182.0]],"received_ms":1789996010050,"observed_ms":1789996010038,"hash":"e40c65a4baedf3cfb352ef60556f9b6c538c263d"},{"bid":0.08,"ask":0.09,"asks":[[0.09,465.37]],"received_ms":1789996010052,"observed_ms":1789996010044,"hash":"c7c2dae1aa8765fa60d28b2b09a8310efb13c8d6"}],"intents":{"pair_fast":null,"pair_250":null,"pair_add_fast":null,"pair_add_250":null},"decision_ms":1789996010053,"feature_cutoff_ms":1789996010052,"request_ms":1789996010022,"inventory":{"pair_fast":{"qty":[0.0,0.0],"cash":0.0,"lots":[[],[]],"floor":0.0},"pair_250":{"qty":[0.0,0.0],"cash":0.0,"lots":[[],[]],"floor":0.0},"pair_add_fast":{"qty":[0.0,0.0],"cash":0.0,"lots":[[],[]],"floor":0.0},"pair_add_250":{"qty":[0.0,0.0],"cash":0.0,"lots":[[],[]],"floor":0.0}}}
{"kind":"decision","recorded_ms":1789996020058,"S":1789995900,"age":120,"signal":{},"entry_side":null,"context_gap":"incomplete or stale context","book_errors":[null,null],"books":[{"bid":0.93,"ask":0.94,"asks":[[0.94,1166.58]],"received_ms":1789996020051,"observed_ms":1789996020033,"hash":"f98521cc32d872a0760d05694364c609b69fd8ff"},{"bid":0.06,"ask":0.07,"asks":[[0.07,30.67]],"received_ms":1789996020057,"observed_ms":1789996020042,"hash":"96379990cf8dd91b23d05a936a0b4f7a072f8acb"}],"intents":{"pair_fast":null,"pair_250":null,"pair_add_fast":null,"pair_add_250":null},"decision_ms":1789996020058,"feature_cutoff_ms":1789996020057,"request_ms":1789996020026,"inventory":{"pair_fast":{"qty":[0.0,0.0],"cash":0.0,"lots":[[],[]],"floor":0.0},"pair_250":{"qty":[0.0,0.0],"cash":0.0,"lots":[[],[]],"floor":0.0},"pair_add_fast":{"qty":[0.0,0.0],"cash":0.0,"lots":[[],[]],"floor":0.0},"pair_add_250":{"qty":[0.0,0.0],"cash":0.0,"lots":[[],[]],"floor":0.0}}}
{"kind":"decision","recorded_ms":1789996030041,"S":1789995900,"age":130,"signal":{},"entry_side":null,"context_gap":"incomplete or stale context","book_errors":[null,null],"books":[{"bid":0.9,"ask":0.91,"asks":[[0.91,1105.63]],"received_ms":1789996030033,"observed_ms":1789996029999,"hash":"871576c8b28a5f3b535b3dcd9ab2ec5ef810cd70"},{"bid":0.09,"ask":0.1,"asks":[[0.1,105.0]],"received_ms":1789996030040,"observed_ms":1789996030026,"hash":"1729dccd56f26e9605287a2e518c8d5beea661e4"}],"intents":{"pair_fast":null,"pair_250":null,"pair_add_fast":null,"pair_add_250":null},"decision_ms":1789996030041,"feature_cutoff_ms":1789996030040,"request_ms":1789996030006,"inventory":{"pair_fast":{"qty":[0.0,0.0],"cash":0.0,"lots":[[],[]],"floor":0.0},"pair_250":{"qty":[0.0,0.0],"cash":0.0,"lots":[[],[]],"floor":0.0},"pair_add_fast":{"qty":[0.0,0.0],"cash":0.0,"lots":[[],[]],"floor":0.0},"pair_add_250":{"qty":[0.0,0.0],"cash":0.0,"lots":[[],[]],"floor":0.0}}}
{"kind":"decision","recorded_ms":1789996040043,"S":1789995900,"age":140,"signal":{},"entry_side":null,"context_gap":"incomplete or stale context","book_errors":[null,null],"books":[{"bid":0.88,"ask":0.89,"asks":[[0.89,415.52]],"received_ms":1789996040038,"observed_ms":1789996040027,"hash":"03051864db01127b7f86a140ba303006d5cf5ac4"},{"bid":0.11,"ask":0.12,"asks":[[0.12,230.36]],"received_ms":1789996040042,"observed_ms":1789996040027,"hash":"2ad55b9ca140a3767b06b5062781ddc090fdba91"}],"intents":{"pair_fast":null,"pair_250":null,"pair_add_fast":null,"pair_add_250":null},"decision_ms":1789996040043,"feature_cutoff_ms":1789996040042,"request_ms":1789996040014,"inventory":{"pair_fast":{"qty":[0.0,0.0],"cash":0.0,"lots":[[],[]],"floor":0.0},"pair_250":{"qty":[0.0,0.0],"cash":0.0,"lots":[[],[]],"floor":0.0},"pair_add_fast":{"qty":[0.0,0.0],"cash":0.0,"lots":[[],[]],"floor":0.0},"pair_add_250":{"qty":[0.0,0.0],"cash":0.0,"lots":[[],[]],"floor":0.0}}}
{"kind":"decision","recorded_ms":1789996050051,"S":1789995900,"age":150,"signal":{},"entry_side":null,"context_gap":"incomplete or stale context","book_errors":[null,null],"books":[{"bid":0.93,"ask":0.94,"asks":[[0.94,145.03]],"received_ms":1789996050050,"observed_ms":1789996050039,"hash":"7de7d1c0dfa7e82dde66c8bd2b85f22cd53dd030"},{"bid":0.06,"ask":0.07,"asks":[[0.07,431.78]],"received_ms":1789996050047,"observed_ms":1789996050037,"hash":"6e9ba8ffe2b3f73e18e797a04c490f216ee76924"}],"intents":{"pair_fast":null,"pair_250":null,"pair_add_fast":null,"pair_add_250":null},"decision_ms":1789996050051,"feature_cutoff_ms":1789996050050,"request_ms":1789996050016,"inventory":{"pair_fast":{"qty":[0.0,0.0],"cash":0.0,"lots":[[],[]],"floor":0.0},"pair_250":{"qty":[0.0,0.0],"cash":0.0,"lots":[[],[]],"floor":0.0},"pair_add_fast":{"qty":[0.0,0.0],"cash":0.0,"lots":[[],[]],"floor":0.0},"pair_add_250":{"qty":[0.0,0.0],"cash":0.0,"lots":[[],[]],"floor":0.0}}}
{"kind":"decision","recorded_ms":1789996060055,"S":1789995900,"age":160,"signal":{},"entry_side":null,"context_gap":"incomplete or stale context","book_errors":[null,null],"books":[{"bid":0.95,"ask":0.96,"asks":[[0.96,192.17]],"received_ms":1789996060051,"observed_ms":1789996060042,"hash":"3bd3a91a876aa384f1f585b521554534946a6b11"},{"bid":0.04,"ask":0.05,"asks":[[0.05,366.01]],"received_ms":1789996060054,"observed_ms":1789996060043,"hash":"51584cbd9446252eb1a754e8e1fc1f580e76b5e7"}],"intents":{"pair_fast":null,"pair_250":null,"pair_add_fast":null,"pair_add_250":null},"decision_ms":1789996060055,"feature_cutoff_ms":1789996060054,"request_ms":1789996060024,"inventory":{"pair_fast":{"qty":[0.0,0.0],"cash":0.0,"lots":[[],[]],"floor":0.0},"pair_250":{"qty":[0.0,0.0],"cash":0.0,"lots":[[],[]],"floor":0.0},"pair_add_fast":{"qty":[0.0,0.0],"cash":0.0,"lots":[[],[]],"floor":0.0},"pair_add_250":{"qty":[0.0,0.0],"cash":0.0,"lots":[[],[]],"floor":0.0}}}
{"kind":"decision","recorded_ms":1789996070069,"S":1789995900,"age":170,"signal":{},"entry_side":null,"context_gap":"incomplete or stale context","book_errors":[null,null],"books":[{"bid":0.94,"ask":0.95,"asks":[[0.95,780.56]],"received_ms":1789996070068,"observed_ms":1789996070045,"hash":"8ac18d2e4ec43cba0e31b626ce52e32cf7ef7d7e"},{"bid":0.05,"ask":0.06,"asks":[[0.06,96.13]],"received_ms":1789996070065,"observed_ms":1789996070045,"hash":"709bb9a4a8b21f2c30116550cf268d3ca368ede5"}],"intents":{"pair_fast":null,"pair_250":null,"pair_add_fast":null,"pair_add_250":null},"decision_ms":1789996070069,"feature_cutoff_ms":1789996070068,"request_ms":1789996070026,"inventory":{"pair_fast":{"qty":[0.0,0.0],"cash":0.0,"lots":[[],[]],"floor":0.0},"pair_250":{"qty":[0.0,0.0],"cash":0.0,"lots":[[],[]],"floor":0.0},"pair_add_fast":{"qty":[0.0,0.0],"cash":0.0,"lots":[[],[]],"floor":0.0},"pair_add_250":{"qty":[0.0,0.0],"cash":0.0,"lots":[[],[]],"floor":0.0}}}
{"kind":"decision","recorded_ms":1789996080079,"S":1789995900,"age":180,"signal":{},"entry_side":null,"context_gap":"incomplete or stale context","book_errors":[null,null],"books":[{"bid":0.94,"ask":0.95,"asks":[[0.95,450.55]],"received_ms":1789996080078,"observed_ms":1789996080043,"hash":"ed54dd3142be6138f0c54f574242dd8a6bec8809"},{"bid":0.05,"ask":0.06,"asks":[[0.06,235.4]],"received_ms":1789996080066,"observed_ms":1789996080043,"hash":"8638d165e42b0ab4e429283d8dfd0d382111fe9e"}],"intents":{"pair_fast":null,"pair_250":null,"pair_add_fast":null,"pair_add_250":null},"decision_ms":1789996080079,"feature_cutoff_ms":1789996080078,"request_ms":1789996080040,"inventory":{"pair_fast":{"qty":[0.0,0.0],"cash":0.0,"lots":[[],[]],"floor":0.0},"pair_250":{"qty":[0.0,0.0],"cash":0.0,"lots":[[],[]],"floor":0.0},"pair_add_fast":{"qty":[0.0,0.0],"cash":0.0,"lots":[[],[]],"floor":0.0},"pair_add_250":{"qty":[0.0,0.0],"cash":0.0,"lots":[[],[]],"floor":0.0}}}
{"kind":"decision","recorded_ms":1789996090055,"S":1789995900,"age":190,"signal":{},"entry_side":null,"context_gap":"incomplete or stale context","book_errors":[null,null],"books":[{"bid":0.95,"ask":0.96,"asks":[[0.96,143.63]],"received_ms":1789996090054,"observed_ms":1789996090037,"hash":"9aaad6c0b3b81d4adfb4d51c7a2e208a3df70735"},{"bid":0.04,"ask":0.05,"asks":[[0.05,543.96]],"received_ms":1789996090048,"observed_ms":1789996090038,"hash":"a6768416bb5f81b5baa3f3ee11dc04b688167e9f"}],"intents":{"pair_fast":null,"pair_250":null,"pair_add_fast":null,"pair_add_250":null},"decision_ms":1789996090055,"feature_cutoff_ms":1789996090054,"request_ms":1789996090023,"inventory":{"pair_fast":{"qty":[0.0,0.0],"cash":0.0,"lots":[[],[]],"floor":0.0},"pair_250":{"qty":[0.0,0.0],"cash":0.0,"lots":[[],[]],"floor":0.0},"pair_add_fast":{"qty":[0.0,0.0],"cash":0.0,"lots":[[],[]],"floor":0.0},"pair_add_250":{"qty":[0.0,0.0],"cash":0.0,"lots":[[],[]],"floor":0.0}}}
{"kind":"decision","recorded_ms":1789996100075,"S":1789995900,"age":200,"signal":{},"entry_side":null,"context_gap":"incomplete or stale context","book_errors":[null,null],"books":[{"bid":0.95,"ask":0.96,"asks":[[0.96,26.86]],"received_ms":1789996100070,"observed_ms":1789996100054,"hash":"10575f082d02cb39cd374622a81729301fa0411f"},{"bid":0.04,"ask":0.05,"asks":[[0.05,539.79]],"received_ms":1789996100074,"observed_ms":1789996100061,"hash":"8657d13cde53bca27f152d50f8bcb78eef25ae33"}],"intents":{"pair_fast":null,"pair_250":null,"pair_add_fast":null,"pair_add_250":null},"decision_ms":1789996100075,"feature_cutoff_ms":1789996100074,"request_ms":1789996100028,"inventory":{"pair_fast":{"qty":[0.0,0.0],"cash":0.0,"lots":[[],[]],"floor":0.0},"pair_250":{"qty":[0.0,0.0],"cash":0.0,"lots":[[],[]],"floor":0.0},"pair_add_fast":{"qty":[0.0,0.0],"cash":0.0,"lots":[[],[]],"floor":0.0},"pair_add_250":{"qty":[0.0,0.0],"cash":0.0,"lots":[[],[]],"floor":0.0}}}
{"kind":"decision","recorded_ms":1789996110083,"S":1789995900,"age":210,"signal":{},"entry_side":null,"context_gap":"incomplete or stale context","book_errors":[null,null],"books":[{"bid":0.97,"ask":0.98,"asks":[[0.98,1493.04]],"received_ms":1789996110082,"observed_ms":1789996110073,"hash":"481396c0eab98522fefe5f241d00b4257b47db39"},{"bid":0.02,"ask":0.03,"asks":[[0.03,112.84]],"received_ms":1789996110077,"observed_ms":1789996110067,"hash":"04b410d5ec2671702cbe2052be033698431d6c1c"}],"intents":{"pair_fast":null,"pair_250":null,"pair_add_fast":null,"pair_add_250":null},"decision_ms":1789996110083,"feature_cutoff_ms":1789996110082,"request_ms":1789996110048,"inventory":{"pair_fast":{"qty":[0.0,0.0],"cash":0.0,"lots":[[],[]],"floor":0.0},"pair_250":{"qty":[0.0,0.0],"cash":0.0,"lots":[[],[]],"floor":0.0},"pair_add_fast":{"qty":[0.0,0.0],"cash":0.0,"lots":[[],[]],"floor":0.0},"pair_add_250":{"qty":[0.0,0.0],"cash":0.0,"lots":[[],[]],"floor":0.0}}}
{"kind":"decision","recorded_ms":1789996120046,"S":1789995900,"age":220,"signal":{},"entry_side":null,"context_gap":"incomplete or stale context","book_errors":[null,null],"books":[{"bid":0.98,"ask":0.99,"asks":[[0.99,3991.36]],"received_ms":1789996120039,"observed_ms":1789996120024,"hash":"a155e21051e1e3aad5e5e5fc13175701aeb88f44"},{"bid":0.01,"ask":0.02,"asks":[[0.02,464.45]],"received_ms":1789996120045,"observed_ms":1789996120028,"hash":"beb4c72e475e5f67b4dc63246f3c5339ef8fd763"}],"intents":{"pair_fast":null,"pair_250":null,"pair_add_fast":null,"pair_add_250":null},"decision_ms":1789996120046,"feature_cutoff_ms":1789996120045,"request_ms":1789996120006,"inventory":{"pair_fast":{"qty":[0.0,0.0],"cash":0.0,"lots":[[],[]],"floor":0.0},"pair_250":{"qty":[0.0,0.0],"cash":0.0,"lots":[[],[]],"floor":0.0},"pair_add_fast":{"qty":[0.0,0.0],"cash":0.0,"lots":[[],[]],"floor":0.0},"pair_add_250":{"qty":[0.0,0.0],"cash":0.0,"lots":[[],[]],"floor":0.0}}}
{"kind":"decision","recorded_ms":1789996130053,"S":1789995900,"age":230,"signal":{},"entry_side":null,"context_gap":"incomplete or stale context","book_errors":[null,null],"books":[{"bid":0.97,"ask":0.98,"asks":[[0.98,15.0]],"received_ms":1789996130052,"observed_ms":1789996130027,"hash":"9dc350078816310878bc38373853daab4ca39b9c"},{"bid":0.02,"ask":0.03,"asks":[[0.03,674.14]],"received_ms":1789996130044,"observed_ms":1789996130036,"hash":"8874847488cf5ab3a9dce6968af5660598f4bfc3"}],"intents":{"pair_fast":null,"pair_250":null,"pair_add_fast":null,"pair_add_250":null},"decision_ms":1789996130053,"feature_cutoff_ms":1789996130052,"request_ms":1789996130018,"inventory":{"pair_fast":{"qty":[0.0,0.0],"cash":0.0,"lots":[[],[]],"floor":0.0},"pair_250":{"qty":[0.0,0.0],"cash":0.0,"lots":[[],[]],"floor":0.0},"pair_add_fast":{"qty":[0.0,0.0],"cash":0.0,"lots":[[],[]],"floor":0.0},"pair_add_250":{"qty":[0.0,0.0],"cash":0.0,"lots":[[],[]],"floor":0.0}}}
{"kind":"decision","recorded_ms":1789996140061,"S":1789995900,"age":240,"signal":{},"entry_side":null,"context_gap":"two-sided entry context unavailable","book_errors":["empty/invalid public book",null],"books":[null,{"bid":null,"ask":0.01,"asks":[[0.01,6366.38]],"received_ms":1789996140061,"observed_ms":1789996140051,"hash":"b07f546bfd2b07627a49daa071701d968d70aac8"}],"intents":{"pair_fast":null,"pair_250":null,"pair_add_fast":null,"pair_add_250":null},"decision_ms":1789996140061,"feature_cutoff_ms":1789996140061,"request_ms":1789996140026,"inventory":{"pair_fast":{"qty":[0.0,0.0],"cash":0.0,"lots":[[],[]],"floor":0.0},"pair_250":{"qty":[0.0,0.0],"cash":0.0,"lots":[[],[]],"floor":0.0},"pair_add_fast":{"qty":[0.0,0.0],"cash":0.0,"lots":[[],[]],"floor":0.0},"pair_add_250":{"qty":[0.0,0.0],"cash":0.0,"lots":[[],[]],"floor":0.0}}}
{"kind":"decision","recorded_ms":1789996150050,"S":1789995900,"age":250,"signal":{},"entry_side":null,"context_gap":"two-sided entry context unavailable","book_errors":["empty/invalid public book",null],"books":[null,{"bid":null,"ask":0.01,"asks":[[0.01,9690.04]],"received_ms":1789996150050,"observed_ms":1789996150030,"hash":"d87e18aa5aef77c04d660f4fe64778773e57d951"}],"intents":{"pair_fast":null,"pair_250":null,"pair_add_fast":null,"pair_add_250":null},"decision_ms":1789996150050,"feature_cutoff_ms":1789996150050,"request_ms":1789996150007,"inventory":{"pair_fast":{"qty":[0.0,0.0],"cash":0.0,"lots":[[],[]],"floor":0.0},"pair_250":{"qty":[0.0,0.0],"cash":0.0,"lots":[[],[]],"floor":0.0},"pair_add_fast":{"qty":[0.0,0.0],"cash":0.0,"lots":[[],[]],"floor":0.0},"pair_add_250":{"qty":[0.0,0.0],"cash":0.0,"lots":[[],[]],"floor":0.0}}}
{"kind":"decision","recorded_ms":1789996160058,"S":1789995900,"age":260,"signal":{},"entry_side":null,"context_gap":"two-sided entry context unavailable","book_errors":["empty/invalid public book",null],"books":[null,{"bid":null,"ask":0.01,"asks":[[0.01,22809.41]],"received_ms":1789996160049,"observed_ms":1789996160024,"hash":"7eeda6030f8a77670868b28703ab14355745a084"}],"intents":{"pair_fast":null,"pair_250":null,"pair_add_fast":null,"pair_add_250":null},"decision_ms":1789996160058,"feature_cutoff_ms":1789996160058,"request_ms":1789996160020,"inventory":{"pair_fast":{"qty":[0.0,0.0],"cash":0.0,"lots":[[],[]],"floor":0.0},"pair_250":{"qty":[0.0,0.0],"cash":0.0,"lots":[[],[]],"floor":0.0},"pair_add_fast":{"qty":[0.0,0.0],"cash":0.0,"lots":[[],[]],"floor":0.0},"pair_add_250":{"qty":[0.0,0.0],"cash":0.0,"lots":[[],[]],"floor":0.0}}}
{"kind":"decision","recorded_ms":1789996170084,"S":1789995900,"age":270,"signal":{},"entry_side":null,"context_gap":"two-sided entry context unavailable","book_errors":["empty/invalid public book",null],"books":[null,{"bid":null,"ask":0.01,"asks":[[0.01,30371.98]],"received_ms":1789996170063,"observed_ms":1789996170047,"hash":"7aa32fbda7d13aa9c0aa122713c5f2da3b14dbfb"}],"intents":{"pair_fast":null,"pair_250":null,"pair_add_fast":null,"pair_add_250":null},"decision_ms":1789996170084,"feature_cutoff_ms":1789996170084,"request_ms":1789996170029,"inventory":{"pair_fast":{"qty":[0.0,0.0],"cash":0.0,"lots":[[],[]],"floor":0.0},"pair_250":{"qty":[0.0,0.0],"cash":0.0,"lots":[[],[]],"floor":0.0},"pair_add_fast":{"qty":[0.0,0.0],"cash":0.0,"lots":[[],[]],"floor":0.0},"pair_add_250":{"qty":[0.0,0.0],"cash":0.0,"lots":[[],[]],"floor":0.0}}}
{"kind":"decision","recorded_ms":1789996180044,"S":1789995900,"age":280,"signal":{},"entry_side":null,"context_gap":"two-sided entry context unavailable","book_errors":["empty/invalid public book",null],"books":[null,{"bid":null,"ask":0.01,"asks":[[0.01,42993.79]],"received_ms":1789996180034,"observed_ms":1789996180018,"hash":"196b9a25f4dce1d8038a68a29cb90016c1577379"}],"intents":{"pair_fast":null,"pair_250":null,"pair_add_fast":null,"pair_add_250":null},"decision_ms":1789996180044,"feature_cutoff_ms":1789996180044,"request_ms":1789996180007,"inventory":{"pair_fast":{"qty":[0.0,0.0],"cash":0.0,"lots":[[],[]],"floor":0.0},"pair_250":{"qty":[0.0,0.0],"cash":0.0,"lots":[[],[]],"floor":0.0},"pair_add_fast":{"qty":[0.0,0.0],"cash":0.0,"lots":[[],[]],"floor":0.0},"pair_add_250":{"qty":[0.0,0.0],"cash":0.0,"lots":[[],[]],"floor":0.0}}}
{"kind":"decision","recorded_ms":1789996190048,"S":1789995900,"age":290,"signal":{},"entry_side":null,"context_gap":"two-sided entry context unavailable","book_errors":["empty/invalid public book",null],"books":[null,{"bid":null,"ask":0.01,"asks":[[0.01,43830.82]],"received_ms":1789996190048,"observed_ms":1789996190024,"hash":"4e75755309c5f966075df9991f9aa3dab9327dd3"}],"intents":{"pair_fast":null,"pair_250":null,"pair_add_fast":null,"pair_add_250":null},"decision_ms":1789996190048,"feature_cutoff_ms":1789996190048,"request_ms":1789996190016,"inventory":{"pair_fast":{"qty":[0.0,0.0],"cash":0.0,"lots":[[],[]],"floor":0.0},"pair_250":{"qty":[0.0,0.0],"cash":0.0,"lots":[[],[]],"floor":0.0},"pair_add_fast":{"qty":[0.0,0.0],"cash":0.0,"lots":[[],[]],"floor":0.0},"pair_add_250":{"qty":[0.0,0.0],"cash":0.0,"lots":[[],[]],"floor":0.0}}}
{"kind":"decision","recorded_ms":1789996230070,"S":1789996200,"age":30,"signal":{"rsi14":50.73778900023739,"volume_ratio":0.7755832050948358,"taker_buy_fraction":0.505315230984208,"volume5":129.42335,"return1":-0.6550210409393432,"return5":12.918796022112291,"return15":5.18392322919107,"bollinger_z":0.4928720777395429,"bar_close_ms":1789996199999,"ref":85319.31067827281,"reference_received_ms":1789996201103,"spot":85315.19783181652,"twap":85310.1086972005,"sigma":8.016161785212018,"spot_z":-0.031228393339528586,"twap_z":-0.06986963590371771,"momentum":1.8005573472748304,"decision_ms":1789996230069,"momentum30":-0.05073456093313158,"momentum60":-0.15817788861880153,"spot_twap_gap":0.08195997927926116,"range60":0.8932523475258992,"final_mean":85315.19783181652,"final_z":-0.03383586306278676,"final_up_prob":0.48650401886032696,"final_drift_up_prob":1.0,"final_known_seconds":0,"final_sd":121.55287567695764,"final_drift_shift":1095.1151721432952},"entry_side":null,"context_gap":null,"book_errors":[null,null],"books":[{"bid":0.44,"ask":0.45,"asks":[[0.45,51.0]],"received_ms":1789996230069,"observed_ms":1789996230041,"hash":"b55a057d16949a1a8824bb5aca640e6b567733eb"},{"bid":0.55,"ask":0.56,"asks":[[0.56,699.28]],"received_ms":1789996230051,"observed_ms":1789996230040,"hash":"431c88b31b46429b22795577e603b891949afa57"}],"intents":{"pair_fast":null,"pair_250":null,"pair_add_fast":null,"pair_add_250":null},"decision_ms":1789996230070,"feature_cutoff_ms":1789996230069,"request_ms":1789996230016,"inventory":{"pair_fast":{"qty":[0.0,0.0],"cash":0.0,"lots":[[],[]],"floor":0.0},"pair_250":{"qty":[0.0,0.0],"cash":0.0,"lots":[[],[]],"floor":0.0},"pair_add_fast":{"qty":[0.0,0.0],"cash":0.0,"lots":[[],[]],"floor":0.0},"pair_add_250":{"qty":[0.0,0.0],"cash":0.0,"lots":[[],[]],"floor":0.0}}}
{"kind":"decision","recorded_ms":1789996240104,"S":1789996200,"age":40,"signal":{"rsi14":50.73778900023739,"volume_ratio":0.7755832050948358,"taker_buy_fraction":0.505315230984208,"volume5":129.42335,"return1":-0.6550210409393432,"return5":12.918796022112291,"return15":5.18392322919107,"bollinger_z":0.4928720777395429,"bar_close_ms":1789996199999,"ref":85319.31067827281,"reference_received_ms":1789996201103,"spot":85309.79553158248,"twap":85308.058217104,"sigma":8.365956099198755,"spot_z":-0.07055036637378549,"twap_z":-0.08343174140163882,"momentum":-0.204203478252334,"decision_ms":1789996240103,"momentum30":-0.18003259542518335,"momentum60":-0.22158846871774973,"spot_twap_gap":0.026809408522241836,"range60":0.8425625407690065,"final_mean":85309.79553158248,"final_z":-0.07669909762081545,"final_up_prob":0.46943146121106566,"final_drift_up_prob":0.14055691339980464,"final_known_seconds":0,"final_sd":124.05813087103607,"final_drift_shift":-124.19726173069556},"entry_side":null,"context_gap":null,"book_errors":[null,null],"books":[{"bid":0.43,"ask":0.44,"asks":[[0.44,514.0]],"received_ms":1789996240103,"observed_ms":1789996240076,"hash":"18a944a6532088a95da37b7f2f420a51ed693c03"},{"bid":0.55,"ask":0.57,"asks":[[0.57,460.0]],"received_ms":1789996240074,"observed_ms":1789996240037,"hash":"acd2613c960840a00a989a7790a805cb29ed6caa"}],"intents":{"pair_fast":null,"pair_250":null,"pair_add_fast":null,"pair_add_250":null},"decision_ms":1789996240104,"feature_cutoff_ms":1789996240103,"request_ms":1789996240042,"inventory":{"pair_fast":{"qty":[0.0,0.0],"cash":0.0,"lots":[[],[]],"floor":0.0},"pair_250":{"qty":[0.0,0.0],"cash":0.0,"lots":[[],[]],"floor":0.0},"pair_add_fast":{"qty":[0.0,0.0],"cash":0.0,"lots":[[],[]],"floor":0.0},"pair_add_250":{"qty":[0.0,0.0],"cash":0.0,"lots":[[],[]],"floor":0.0}}}
{"kind":"decision","recorded_ms":1789996250072,"S":1789996200,"age":50,"signal":{"rsi14":50.73778900023739,"volume_ratio":0.7755832050948358,"taker_buy_fraction":0.505315230984208,"volume5":129.42335,"return1":-0.6550210409393432,"return5":12.918796022112291,"return15":5.18392322919107,"bollinger_z":0.4928720777395429,"bar_close_ms":1789996199999,"ref":85319.31067827281,"reference_received_ms":1789996201103,"spot":85286.03494915215,"twap":85305.73965207505,"sigma":8.545058773755533,"spot_z":-0.24632256620428167,"twap_z":-0.1004591060029737,"momentum":-0.8793100316968905,"decision_ms":1789996250071,"momentum30":0.3521133902325464,"momentum60":-0.2995680455806427,"spot_twap_gap":-0.2977002588394314,"range60":0.7325926228887216,"final_mean":85286.03494915215,"final_z":-0.26876722526025026,"final_up_prob":0.394054408021693,"final_drift_up_prob":3.5694537545150062e-06,"final_known_seconds":0,"final_sd":123.80873109972427,"final_drift_shift":-522.5641130963828},"entry_side":null,"context_gap":null,"book_errors":[null,null],"books":[{"bid":0.28,"ask":0.29,"asks":[[0.29,451.88]],"received_ms":1789996250071,"observed_ms":1789996250060,"hash":"e3ae6331effb130903d20b16362772f02ea3a33c"},{"bid":0.71,"ask":0.72,"asks":[[0.72,20.0]],"received_ms":1789996250051,"observed_ms":1789996250040,"hash":"71096eb084ebffdb382b686093639ab2b4077800"}],"intents":{"pair_fast":null,"pair_250":null,"pair_add_fast":null,"pair_add_250":null},"decision_ms":1789996250072,"feature_cutoff_ms":1789996250071,"request_ms":1789996250025,"inventory":{"pair_fast":{"qty":[0.0,0.0],"cash":0.0,"lots":[[],[]],"floor":0.0},"pair_250":{"qty":[0.0,0.0],"cash":0.0,"lots":[[],[]],"floor":0.0},"pair_add_fast":{"qty":[0.0,0.0],"cash":0.0,"lots":[[],[]],"floor":0.0},"pair_add_250":{"qty":[0.0,0.0],"cash":0.0,"lots":[[],[]],"floor":0.0}}}
{"kind":"decision","recorded_ms":1789996260079,"S":1789996200,"age":60,"signal":{"rsi14":50.73778900023739,"volume_ratio":0.7755832050948358,"taker_buy_fraction":0.505315230984208,"volume5":129.42335,"return1":-0.6550210409393432,"return5":12.918796022112291,"return15":5.18392322919107,"bollinger_z":0.4928720777395429,"bar_close_ms":1789996199999,"ref":85319.31067827281,"reference_received_ms":1789996201103,"spot":85236.4940544079,"twap":85298.03772042267,"sigma":10.02367532671748,"spot_z":-0.5334030495616222,"twap_z":-0.13701428603238341,"momentum":-1.5629203820769884,"decision_ms":1789996260078,"momentum30":-1.4335338699789935,"momentum60":-1.0423513780126166,"spot_twap_gap":-0.7926486901280624,"range60":1.0503318256799354,"final_mean":85236.4940544079,"final_z":-0.5843327622882296,"final_up_prob":0.27949822702746085,"final_drift_up_prob":1.1657341758564144e-15,"final_known_seconds":0,"final_sd":141.72853074437634,"final_drift_shift":-1039.97237031004},"entry_side":null,"context_gap":null,"book_errors":[null,null],"books":[{"bid":0.23,"ask":0.24,"asks":[[0.24,85.73]],"received_ms":1789996260068,"observed_ms":1789996260061,"hash":"ce61e40fb6e8a6cd99629ec52b0ee638f9150fea"},{"bid":0.76,"ask":0.77,"asks":[[0.77,959.14]],"received_ms":1789996260077,"observed_ms":1789996260063,"hash":"500f2988e1b6d9055703e166343c541dee7540e6"}],"intents":{"pair_fast":null,"pair_250":null,"pair_add_fast":null,"pair_add_250":null},"decision_ms":1789996260079,"feature_cutoff_ms":1789996260078,"request_ms":1789996260044,"inventory":{"pair_fast":{"qty":[0.0,0.0],"cash":0.0,"lots":[[],[]],"floor":0.0},"pair_250":{"qty":[0.0,0.0],"cash":0.0,"lots":[[],[]],"floor":0.0},"pair_add_fast":{"qty":[0.0,0.0],"cash":0.0,"lots":[[],[]],"floor":0.0},"pair_add_250":{"qty":[0.0,0.0],"cash":0.0,"lots":[[],[]],"floor":0.0}}}
{"kind":"decision","recorded_ms":1789996270055,"S":1789996200,"age":70,"signal":{"rsi14":48.418674698794646,"volume_ratio":0.784794844454507,"taker_buy_fraction":0.4341575803992974,"volume5":120.07039,"return1":-9.644781625396176,"return5":-13.676049343562045,"return15":-8.109451557579971,"bollinger_z":-0.750013019842809,"bar_close_ms":1789996259999,"ref":85319.31067827281,"reference_received_ms":1789996201103,"spot":85239.41650082255,"twap":85284.7260929493,"sigma":9.772710182653748,"spot_z":-0.5391221564260561,"twap_z":-0.23337515716108997,"momentum":0.09456524175353144,"decision_ms":1789996270054,"momentum30":-1.314824035574203,"momentum60":-1.0386984578901197,"spot_twap_gap":-0.5985487220724757,"range60":1.0773045561733008,"final_mean":85239.41650082255,"final_z":-0.5931779980124448,"final_up_prob":0.2765310177737421,"final_drift_up_prob":0.43670113119528325,"final_known_seconds":0,"final_sd":134.68836962591433,"final_drift_shift":58.43314711141987},"entry_side":null,"context_gap":null,"book_errors":[null,null],"books":[{"bid":0.28,"ask":0.29,"asks":[[0.29,577.96]],"received_ms":1789996270054,"observed_ms":1789996270046,"hash":"347336ec4a0ba01ca89731e41e19bc3c5c4aa448"},{"bid":0.71,"ask":0.72,"asks":[[0.72,200.0]],"received_ms":1789996270053,"observed_ms":1789996270044,"hash":"f732835221cd269063c38f5fe2b64600ae0798ac"}],"intents":{"pair_fast":null,"pair_250":null,"pair_add_fast":null,"pair_add_250":null},"decision_ms":1789996270055,"feature_cutoff_ms":1789996270054,"request_ms":1789996270027,"inventory":{"pair_fast":{"qty":[0.0,0.0],"cash":0.0,"lots":[[],[]],"floor":0.0},"pair_250":{"qty":[0.0,0.0],"cash":0.0,"lots":[[],[]],"floor":0.0},"pair_add_fast":{"qty":[0.0,0.0],"cash":0.0,"lots":[[],[]],"floor":0.0},"pair_add_250":{"qty":[0.0,0.0],"cash":0.0,"lots":[[],[]],"floor":0.0}}}
{"kind":"decision","recorded_ms":1789996280068,"S":1789996200,"age":80,"signal":{"rsi14":48.418674698794646,"volume_ratio":0.784794844454507,"taker_buy_fraction":0.4341575803992974,"volume5":120.07039,"return1":-9.644781625396176,"return5":-13.676049343562045,"return15":-8.109451557579971,"bollinger_z":-0.750013019842809,"bar_close_ms":1789996259999,"ref":85319.31067827281,"reference_received_ms":1789996201103,"spot":85239.3902777644,"twap":85274.64547762886,"sigma":8.662685402586616,"spot_z":-0.6220995822698342,"twap_z":-0.34767346617182987,"momentum":-0.0009572619475243472,"decision_ms":1789996280067,"momentum30":-0.9830800157673628,"momentum60":-0.44954158873343075,"spot_twap_gap":-0.5254059820815253,"range60":1.1729173461468236,"final_mean":85239.3902777644,"final_z":-0.6877802463674122,"final_up_prob":0.24579558869521756,"final_drift_up_prob":0.24444779051002574,"final_known_seconds":0,"final_sd":116.20048835442134,"final_drift_shift":-0.4980624107326177},"entry_side":null,"context_gap":null,"book_errors":[null,null],"books":[{"bid":0.2,"ask":0.21,"asks":[[0.21,399.99]],"received_ms":1789996280061,"observed_ms":1789996280050,"hash":"f94575be5db346de3d89667a8d1acaa9461fa9cc"},{"bid":0.79,"ask":0.8,"asks":[[0.8,134.12]],"received_ms":1789996280067,"observed_ms":1789996280054,"hash":"570ffa98e117dad3b792a3ce42b595096de6a3d5"}],"intents":{"pair_fast":null,"pair_250":null,"pair_add_fast":null,"pair_add_250":null},"decision_ms":1789996280068,"feature_cutoff_ms":1789996280067,"request_ms":1789996280029,"inventory":{"pair_fast":{"qty":[0.0,0.0],"cash":0.0,"lots":[[],[]],"floor":0.0},"pair_250":{"qty":[0.0,0.0],"cash":0.0,"lots":[[],[]],"floor":0.0},"pair_add_fast":{"qty":[0.0,0.0],"cash":0.0,"lots":[[],[]],"floor":0.0},"pair_add_250":{"qty":[0.0,0.0],"cash":0.0,"lots":[[],[]],"floor":0.0}}}
{"kind":"decision","recorded_ms":1789996290073,"S":1789996200,"age":90,"signal":{"rsi14":48.418674698794646,"volume_ratio":0.784794844454507,"taker_buy_fraction":0.4341575803992974,"volume5":120.07039,"return1":-9.644781625396176,"return5":-13.676049343562045,"return15":-8.109451557579971,"bollinger_z":-0.750013019842809,"bar_close_ms":1789996259999,"ref":85319.31067827281,"reference_received_ms":1789996201103,"spot":85227.52716419392,"twap":85265.9030518108,"sigma":7.150511611931039,"spot_z":-0.885915664865496,"twap_z":-0.51550273903555,"momentum":-0.5246402084204492,"decision_ms":1789996290072,"momentum30":-0.22895182458811061,"momentum60":-1.5828566032798286,"spot_twap_gap":-0.692860323393427,"range60":1.7530882096001905,"final_mean":85227.52716419392,"final_z":-0.9846799437206912,"final_up_prob":0.1623906536984056,"final_drift_up_prob":0.0005289840583587169,"final_known_seconds":0,"final_sd":93.21151980823778,"final_drift_shift":-213.45062981922158},"entry_side":null,"context_gap":null,"book_errors":[null,null],"books":[{"bid":0.25,"ask":0.26,"asks":[[0.26,114.62]],"received_ms":1789996290070,"observed_ms":1789996290060,"hash":"aec44830c6e13a08a96e15d55691650cf53b16dd"},{"bid":0.74,"ask":0.75,"asks":[[0.75,1353.7]],"received_ms":1789996290072,"observed_ms":1789996290060,"hash":"d4c6fc9fbc5dedb24a83e011235611ca24cb8268"}],"intents":{"pair_fast":null,"pair_250":null,"pair_add_fast":null,"pair_add_250":null},"decision_ms":1789996290073,"feature_cutoff_ms":1789996290072,"request_ms":1789996290040,"inventory":{"pair_fast":{"qty":[0.0,0.0],"cash":0.0,"lots":[[],[]],"floor":0.0},"pair_250":{"qty":[0.0,0.0],"cash":0.0,"lots":[[],[]],"floor":0.0},"pair_add_fast":{"qty":[0.0,0.0],"cash":0.0,"lots":[[],[]],"floor":0.0},"pair_add_250":{"qty":[0.0,0.0],"cash":0.0,"lots":[[],[]],"floor":0.0}}}
{"kind":"decision","recorded_ms":1789996300089,"S":1789996200,"age":100,"signal":{"rsi14":48.418674698794646,"volume_ratio":0.784794844454507,"taker_buy_fraction":0.4341575803992974,"volume5":120.07039,"return1":-9.644781625396176,"return5":-13.676049343562045,"return15":-8.109451557579971,"bollinger_z":-0.750013019842809,"bar_close_ms":1789996259999,"ref":85319.31067827281,"reference_received_ms":1789996201103,"spot":85248.88942060927,"twap":85252.88256634824,"sigma":7.378007593532707,"spot_z":-0.6750644642574667,"twap_z":-0.6367858126340805,"momentum":0.9156047262984613,"decision_ms":1789996300088,"momentum30":0.23441431790554004,"momentum60":-1.0657274360821973,"spot_twap_gap":-0.06987155972202438,"range60":1.6045041277278402,"final_mean":85248.88942060927,"final_z":-0.7547865483417221,"final_up_prob":0.22518853316130572,"final_drift_up_prob":0.9991424537135101,"final_known_seconds":0,"final_sd":93.29956637179598,"final_drift_shift":362.9703710781571},"entry_side":null,"context_gap":null,"book_errors":[null,null],"books":[{"bid":0.24,"ask":0.25,"asks":[[0.25,184.4]],"received_ms":1789996300084,"observed_ms":1789996300074,"hash":"95b6d8b4d416ffe5f2b4d16f38ce492b71828215"},{"bid":0.75,"ask":0.76,"asks":[[0.76,518.36]],"received_ms":1789996300088,"observed_ms":1789996300077,"hash":"693cc1bfb69c32e34408dc07efc5cd9db7b8d8f7"}],"intents":{"pair_fast":null,"pair_250":null,"pair_add_fast":null,"pair_add_250":null},"decision_ms":1789996300089,"feature_cutoff_ms":1789996300088,"request_ms":1789996300047,"inventory":{"pair_fast":{"qty":[0.0,0.0],"cash":0.0,"lots":[[],[]],"floor":0.0},"pair_250":{"qty":[0.0,0.0],"cash":0.0,"lots":[[],[]],"floor":0.0},"pair_add_fast":{"qty":[0.0,0.0],"cash":0.0,"lots":[[],[]],"floor":0.0},"pair_add_250":{"qty":[0.0,0.0],"cash":0.0,"lots":[[],[]],"floor":0.0}}}
{"kind":"decision","recorded_ms":1789996310041,"S":1789996200,"age":110,"signal":{},"entry_side":null,"context_gap":"incomplete or stale context","book_errors":[null,null],"books":[{"bid":0.14,"ask":0.15,"asks":[[0.15,342.17]],"received_ms":1789996310039,"observed_ms":1789996310031,"hash":"cfa017d07f7e64d84293695f943ebce2bd87001b"},{"bid":0.85,"ask":0.86,"asks":[[0.86,304.26]],"received_ms":1789996310035,"observed_ms":1789996310028,"hash":"91b33392ce86c389ac4cede576f5d124a414f542"}],"intents":{"pair_fast":null,"pair_250":null,"pair_add_fast":null,"pair_add_250":null},"decision_ms":1789996310041,"feature_cutoff_ms":1789996310040,"request_ms":1789996310014,"inventory":{"pair_fast":{"qty":[0.0,0.0],"cash":0.0,"lots":[[],[]],"floor":0.0},"pair_250":{"qty":[0.0,0.0],"cash":0.0,"lots":[[],[]],"floor":0.0},"pair_add_fast":{"qty":[0.0,0.0],"cash":0.0,"lots":[[],[]],"floor":0.0},"pair_add_250":{"qty":[0.0,0.0],"cash":0.0,"lots":[[],[]],"floor":0.0}}}
{"kind":"decision","recorded_ms":1789996320050,"S":1789996200,"age":120,"signal":{"rsi14":48.418674698794646,"volume_ratio":0.784794844454507,"taker_buy_fraction":0.4341575803992974,"volume5":120.07039,"return1":-9.644781625396176,"return5":-13.676049343562045,"return15":-8.109451557579971,"bollinger_z":-0.750013019842809,"bar_close_ms":1789996259999,"ref":85319.31067827281,"reference_received_ms":1789996201103,"spot":85211.88198691107,"twap":85232.40071392334,"sigma":5.673148475393836,"spot_z":-1.4116239020458836,"twap_z":-1.1420057476876333,"momentum":0.21239602313645045,"decision_ms":1789996320049,"momentum30":-0.5034956368671576,"momentum60":-0.5600777530876734,"spot_twap_gap":-0.4669287747863258,"range60":0.980830909260658,"final_mean":85211.88198691107,"final_z":-1.600693320049524,"final_up_prob":0.054722430706420244,"final_drift_up_prob":0.22682491797201682,"final_known_seconds":0,"final_sd":67.11384998996311,"final_drift_shift":57.137324061346014},"entry_side":null,"context_gap":null,"book_errors":[null,null],"books":[{"bid":0.13,"ask":0.14,"asks":[[0.14,85.0]],"received_ms":1789996320049,"observed_ms":1789996320036,"hash":"14e8d6c8fe7eb06bf3d2646018193f5a6d05da7b"},{"bid":0.86,"ask":0.87,"asks":[[0.87,1157.93]],"received_ms":1789996320041,"observed_ms":1789996320031,"hash":"40a98ed25f92aec05b57d6b1015f1d6789b3c4ec"}],"intents":{"pair_fast":null,"pair_250":null,"pair_add_fast":null,"pair_add_250":null},"decision_ms":1789996320050,"feature_cutoff_ms":1789996320049,"request_ms":1789996320013,"inventory":{"pair_fast":{"qty":[0.0,0.0],"cash":0.0,"lots":[[],[]],"floor":0.0},"pair_250":{"qty":[0.0,0.0],"cash":0.0,"lots":[[],[]],"floor":0.0},"pair_add_fast":{"qty":[0.0,0.0],"cash":0.0,"lots":[[],[]],"floor":0.0},"pair_add_250":{"qty":[0.0,0.0],"cash":0.0,"lots":[[],[]],"floor":0.0}}}
{"kind":"decision","recorded_ms":1789996330081,"S":1789996200,"age":130,"signal":{"rsi14":41.391562837468435,"volume_ratio":0.7289381439220373,"taker_buy_fraction":0.3826465311602498,"volume5":101.56321,"return1":-2.9601103136785287,"return5":-23.13649440576661,"return15":-6.409465970523104,"bollinger_z":-1.1335244946573009,"bar_close_ms":1789996319999,"ref":85319.31067827281,"reference_received_ms":1789996201103,"spot":85222.5041061058,"twap":85228.57057353384,"sigma":5.801011315450692,"spot_z":-1.2802031162699725,"twap_z":-1.1999780826562385,"momentum":0.5790385228807028,"decision_ms":1789996330080,"momentum30":-0.8304202580404698,"momentum60":-0.37637933296224546,"spot_twap_gap":-0.13500707630372374,"range60":0.9592119502802491,"final_mean":85222.5041061058,"final_z":-1.464074322051778,"final_up_prob":0.07158682119843784,"final_drift_up_prob":0.7833866679156611,"final_known_seconds":0,"final_sd":66.12135101949423,"final_drift_shift":148.62469185364807},"entry_side":null,"context_gap":null,"book_errors":[null,null],"books":[{"bid":0.13,"ask":0.14,"asks":[[0.14,1078.07]],"received_ms":1789996330075,"observed_ms":1789996330059,"hash":"a67de2a638a2a0881e52690fad86f09ad975bdb8"},{"bid":0.86,"ask":0.87,"asks":[[0.87,159.21]],"received_ms":1789996330080,"observed_ms":1789996330059,"hash":"a14013c391b35b8e4736267e15dc7d29ce62d1a8"}],"intents":{"pair_fast":null,"pair_250":null,"pair_add_fast":null,"pair_add_250":null},"decision_ms":1789996330081,"feature_cutoff_ms":1789996330080,"request_ms":1789996330046,"inventory":{"pair_fast":{"qty":[0.0,0.0],"cash":0.0,"lots":[[],[]],"floor":0.0},"pair_250":{"qty":[0.0,0.0],"cash":0.0,"lots":[[],[]],"floor":0.0},"pair_add_fast":{"qty":[0.0,0.0],"cash":0.0,"lots":[[],[]],"floor":0.0},"pair_add_250":{"qty":[0.0,0.0],"cash":0.0,"lots":[[],[]],"floor":0.0}}}
{"kind":"decision","recorded_ms":1789996340036,"S":1789996200,"age":140,"signal":{"rsi14":41.391562837468435,"volume_ratio":0.7289381439220373,"taker_buy_fraction":0.3826465311602498,"volume5":101.56321,"return1":-2.9601103136785287,"return5":-23.13649440576661,"return15":-6.409465970523104,"bollinger_z":-1.1335244946573009,"bar_close_ms":1789996319999,"ref":85319.31067827281,"reference_received_ms":1789996201103,"spot":85210.330213675,"twap":85224.18711952055,"sigma":5.932844884592114,"spot_z":-1.4523563109134507,"twap_z":-1.2676886759498445,"momentum":-0.6488831044815329,"decision_ms":1789996340035,"momentum30":0.06950575820662465,"momentum60":-0.6358178821750115,"spot_twap_gap":-0.30152799999397967,"range60":0.9681574841784342,"final_mean":85210.330213675,"final_z":-1.6770977729632741,"final_up_prob":0.046761682114978886,"final_drift_up_prob":1.9619904591150483e-05,"final_known_seconds":0,"final_sd":64.98158089212443,"final_drift_shift":-158.21799287241663},"entry_side":null,"context_gap":null,"book_errors":[null,null],"books":[{"bid":0.08,"ask":0.09,"asks":[[0.09,1100.71]],"received_ms":1789996340035,"observed_ms":1789996340025,"hash":"c6835f5849305aab6d5c23830b4437393c1f56da"},{"bid":0.91,"ask":0.92,"asks":[[0.92,413.45]],"received_ms":1789996340030,"observed_ms":1789996340023,"hash":"15e55dc8c5b8a9adc34401f5554bccd823913807"}],"intents":{"pair_fast":null,"pair_250":null,"pair_add_fast":null,"pair_add_250":null},"decision_ms":1789996340036,"feature_cutoff_ms":1789996340035,"request_ms":1789996340004,"inventory":{"pair_fast":{"qty":[0.0,0.0],"cash":0.0,"lots":[[],[]],"floor":0.0},"pair_250":{"qty":[0.0,0.0],"cash":0.0,"lots":[[],[]],"floor":0.0},"pair_add_fast":{"qty":[0.0,0.0],"cash":0.0,"lots":[[],[]],"floor":0.0},"pair_add_250":{"qty":[0.0,0.0],"cash":0.0,"lots":[[],[]],"floor":0.0}}}
{"kind":"decision","recorded_ms":1789996350046,"S":1789996200,"age":150,"signal":{"rsi14":41.391562837468435,"volume_ratio":0.7289381439220373,"taker_buy_fraction":0.3826465311602498,"volume5":101.56321,"return1":-2.9601103136785287,"return5":-23.13649440576661,"return15":-6.409465970523104,"bollinger_z":-1.1335244946573009,"bar_close_ms":1789996319999,"ref":85319.31067827281,"reference_received_ms":1789996201103,"spot":85203.8379566286,"twap":85220.27993646941,"sigma":5.179378268965374,"spot_z":-1.8206283299897763,"twap_z":-1.5613919157695917,"momentum":-0.39638578909959776,"decision_ms":1789996350045,"momentum30":-0.28355377873340587,"momentum60":-0.5904692392332681,"spot_twap_gap":-0.4098272726650226,"range60":1.1312335868540306,"final_mean":85203.8379566286,"final_z":-2.1261518589946866,"final_up_prob":0.016745308533155645,"final_drift_up_prob":0.00018536729951390551,"final_known_seconds":0,"final_sd":54.3106651369723,"final_drift_shift":-77.87786935052135},"entry_side":null,"context_gap":null,"book_errors":[null,null],"books":[{"bid":0.06,"ask":0.07,"asks":[[0.07,199.0]],"received_ms":1789996350045,"observed_ms":1789996350020,"hash":"bec0c0e21b247bc7a0d67e46adcc503feac709dd"},{"bid":0.93,"ask":0.94,"asks":[[0.94,405.0]],"received_ms":1789996350042,"observed_ms":1789996350031,"hash":"35a510607d09f553f32f820303d9ffdb45251947"}],"intents":{"pair_fast":null,"pair_250":null,"pair_add_fast":null,"pair_add_250":null},"decision_ms":1789996350046,"feature_cutoff_ms":1789996350045,"request_ms":1789996350013,"inventory":{"pair_fast":{"qty":[0.0,0.0],"cash":0.0,"lots":[[],[]],"floor":0.0},"pair_250":{"qty":[0.0,0.0],"cash":0.0,"lots":[[],[]],"floor":0.0},"pair_add_fast":{"qty":[0.0,0.0],"cash":0.0,"lots":[[],[]],"floor":0.0},"pair_add_250":{"qty":[0.0,0.0],"cash":0.0,"lots":[[],[]],"floor":0.0}}}
{"kind":"decision","recorded_ms":1789996360057,"S":1789996200,"age":160,"signal":{"rsi14":41.391562837468435,"volume_ratio":0.7289381439220373,"taker_buy_fraction":0.3826465311602498,"volume5":101.56321,"return1":-2.9601103136785287,"return5":-23.13649440576661,"return15":-6.409465970523104,"bollinger_z":-1.1335244946573009,"bar_close_ms":1789996319999,"ref":85319.31067827281,"reference_received_ms":1789996201103,"spot":85178.30496673517,"twap":85214.77165978064,"sigma":5.6074194763168315,"spot_z":-2.1256732979606188,"twap_z":-1.5759347460510489,"momentum":-1.4399208740903657,"decision_ms":1789996360056,"momentum30":-1.4390972388073846,"momentum60":-1.6250636946882462,"spot_twap_gap":-0.8395715441709146,"range60":1.6250636946882462,"final_mean":85178.30496673517,"final_z":-2.515331879816686,"final_up_prob":0.005946018977020573,"final_drift_up_prob":2.6756374893466273e-14,"final_known_seconds":0,"final_sd":56.05849179151525,"final_drift_shift":-280.71990409892317},"entry_side":null,"context_gap":null,"book_errors":[null,null],"books":[{"bid":0.02,"ask":0.03,"asks":[[0.03,109.24]],"received_ms":1789996360048,"observed_ms":1789996360039,"hash":"e51303767ce85602657f5e9ea637788b18800a35"},{"bid":0.97,"ask":0.98,"asks":[[0.98,1031.71]],"received_ms":1789996360056,"observed_ms":1789996360039,"hash":"5249adcb360885a4b25c63fada8cc94e51d46ec2"}],"intents":{"pair_fast":null,"pair_250":null,"pair_add_fast":null,"pair_add_250":null},"decision_ms":1789996360057,"feature_cutoff_ms":1789996360056,"request_ms":1789996360019,"inventory":{"pair_fast":{"qty":[0.0,0.0],"cash":0.0,"lots":[[],[]],"floor":0.0},"pair_250":{"qty":[0.0,0.0],"cash":0.0,"lots":[[],[]],"floor":0.0},"pair_add_fast":{"qty":[0.0,0.0],"cash":0.0,"lots":[[],[]],"floor":0.0},"pair_add_250":{"qty":[0.0,0.0],"cash":0.0,"lots":[[],[]],"floor":0.0}}}
{"kind":"decision","recorded_ms":1789996370086,"S":1789996200,"age":170,"signal":{"rsi14":41.391562837468435,"volume_ratio":0.7289381439220373,"taker_buy_fraction":0.3826465311602498,"volume5":101.56321,"return1":-2.9601103136785287,"return5":-23.13649440576661,"return15":-6.409465970523104,"bollinger_z":-1.1335244946573009,"bar_close_ms":1789996319999,"ref":85319.31067827281,"reference_received_ms":1789996201103,"spot":85149.70064666908,"twap":85203.86982750967,"sigma":4.947955595947164,"spot_z":-3.0074339136857255,"twap_z":-2.0469351153765882,"momentum":-1.828124779523163,"decision_ms":1789996370085,"momentum30":-2.237165152149799,"momentum60":-1.5229837614033663,"spot_twap_gap":-1.4133536649974519,"range60":1.8995494231709265,"final_mean":85149.70064666908,"final_z":-3.6150113679637723,"final_up_prob":0.00015016722130289928,"final_drift_up_prob":0.0,"final_known_seconds":0,"final_sd":46.918256774188215,"final_drift_shift":-285.8000638312549},"entry_side":null,"context_gap":null,"book_errors":[null,null],"books":[{"bid":0.01,"ask":0.02,"asks":[[0.02,722.05]],"received_ms":1789996370085,"observed_ms":1789996370074,"hash":"18485a2524af5984f48809f98a41c5283f3b0c97"},{"bid":0.98,"ask":0.99,"asks":[[0.99,3945.81]],"received_ms":1789996370069,"observed_ms":1789996370058,"hash":"f60197c4cee0be01dad2f3d1ef76bce3009670dd"}],"intents":{"pair_fast":null,"pair_250":null,"pair_add_fast":null,"pair_add_250":null},"decision_ms":1789996370086,"feature_cutoff_ms":1789996370085,"request_ms":1789996370032,"inventory":{"pair_fast":{"qty":[0.0,0.0],"cash":0.0,"lots":[[],[]],"floor":0.0},"pair_250":{"qty":[0.0,0.0],"cash":0.0,"lots":[[],[]],"floor":0.0},"pair_add_fast":{"qty":[0.0,0.0],"cash":0.0,"lots":[[],[]],"floor":0.0},"pair_add_250":{"qty":[0.0,0.0],"cash":0.0,"lots":[[],[]],"floor":0.0}}}
{"kind":"decision","recorded_ms":1789996380036,"S":1789996200,"age":180,"signal":{},"entry_side":null,"context_gap":"two-sided entry context unavailable","book_errors":[null,"empty/invalid public book"],"books":[{"bid":null,"ask":0.01,"asks":[[0.01,7061.71]],"received_ms":1789996380036,"observed_ms":1789996380012,"hash":"77e08b3c37140258edac3206cd2601f385c23aae"},null],"intents":{"pair_fast":null,"pair_250":null,"pair_add_fast":null,"pair_add_250":null},"decision_ms":1789996380036,"feature_cutoff_ms":1789996380036,"request_ms":1789996380009,"inventory":{"pair_fast":{"qty":[0.0,0.0],"cash":0.0,"lots":[[],[]],"floor":0.0},"pair_250":{"qty":[0.0,0.0],"cash":0.0,"lots":[[],[]],"floor":0.0},"pair_add_fast":{"qty":[0.0,0.0],"cash":0.0,"lots":[[],[]],"floor":0.0},"pair_add_250":{"qty":[0.0,0.0],"cash":0.0,"lots":[[],[]],"floor":0.0}}}
{"kind":"decision","recorded_ms":1789996390077,"S":1789996200,"age":190,"signal":{},"entry_side":null,"context_gap":"two-sided entry context unavailable","book_errors":[null,"empty/invalid public book"],"books":[{"bid":null,"ask":0.01,"asks":[[0.01,2251.48]],"received_ms":1789996390077,"observed_ms":1789996390060,"hash":"1a936844d857700189ced2b2653b8ea5408e665e"},null],"intents":{"pair_fast":null,"pair_250":null,"pair_add_fast":null,"pair_add_250":null},"decision_ms":1789996390077,"feature_cutoff_ms":1789996390077,"request_ms":1789996390031,"inventory":{"pair_fast":{"qty":[0.0,0.0],"cash":0.0,"lots":[[],[]],"floor":0.0},"pair_250":{"qty":[0.0,0.0],"cash":0.0,"lots":[[],[]],"floor":0.0},"pair_add_fast":{"qty":[0.0,0.0],"cash":0.0,"lots":[[],[]],"floor":0.0},"pair_add_250":{"qty":[0.0,0.0],"cash":0.0,"lots":[[],[]],"floor":0.0}}}
{"kind":"decision","recorded_ms":1789996400031,"S":1789996200,"age":200,"signal":{},"entry_side":null,"context_gap":"two-sided entry context unavailable","book_errors":[null,"empty/invalid public book"],"books":[{"bid":null,"ask":0.01,"asks":[[0.01,2417.47]],"received_ms":1789996400031,"observed_ms":1789996399977,"hash":"b434a1f1b19b6cdb8afefc83c69793b7e479fb04"},null],"intents":{"pair_fast":null,"pair_250":null,"pair_add_fast":null,"pair_add_250":null},"decision_ms":1789996400031,"feature_cutoff_ms":1789996400031,"request_ms":1789996400001,"inventory":{"pair_fast":{"qty":[0.0,0.0],"cash":0.0,"lots":[[],[]],"floor":0.0},"pair_250":{"qty":[0.0,0.0],"cash":0.0,"lots":[[],[]],"floor":0.0},"pair_add_fast":{"qty":[0.0,0.0],"cash":0.0,"lots":[[],[]],"floor":0.0},"pair_add_250":{"qty":[0.0,0.0],"cash":0.0,"lots":[[],[]],"floor":0.0}}}
{"kind":"decision","recorded_ms":1789996410042,"S":1789996200,"age":210,"signal":{},"entry_side":null,"context_gap":"two-sided entry context unavailable","book_errors":[null,"empty/invalid public book"],"books":[{"bid":null,"ask":0.01,"asks":[[0.01,1667.31]],"received_ms":1789996410032,"observed_ms":1789996410020,"hash":"bb3193d4d391cf901bd4cce23d734fee03413915"},null],"intents":{"pair_fast":null,"pair_250":null,"pair_add_fast":null,"pair_add_250":null},"decision_ms":1789996410042,"feature_cutoff_ms":1789996410042,"request_ms":1789996410003,"inventory":{"pair_fast":{"qty":[0.0,0.0],"cash":0.0,"lots":[[],[]],"floor":0.0},"pair_250":{"qty":[0.0,0.0],"cash":0.0,"lots":[[],[]],"floor":0.0},"pair_add_fast":{"qty":[0.0,0.0],"cash":0.0,"lots":[[],[]],"floor":0.0},"pair_add_250":{"qty":[0.0,0.0],"cash":0.0,"lots":[[],[]],"floor":0.0}}}
{"kind":"decision","recorded_ms":1789996420059,"S":1789996200,"age":220,"signal":{},"entry_side":null,"context_gap":"two-sided entry context unavailable","book_errors":[null,"empty/invalid public book"],"books":[{"bid":null,"ask":0.01,"asks":[[0.01,5392.87]],"received_ms":1789996420046,"observed_ms":1789996419992,"hash":"9ec08ca4ca629598966f27a4efa9450563c6bfcd"},null],"intents":{"pair_fast":null,"pair_250":null,"pair_add_fast":null,"pair_add_250":null},"decision_ms":1789996420059,"feature_cutoff_ms":1789996420059,"request_ms":1789996420018,"inventory":{"pair_fast":{"qty":[0.0,0.0],"cash":0.0,"lots":[[],[]],"floor":0.0},"pair_250":{"qty":[0.0,0.0],"cash":0.0,"lots":[[],[]],"floor":0.0},"pair_add_fast":{"qty":[0.0,0.0],"cash":0.0,"lots":[[],[]],"floor":0.0},"pair_add_250":{"qty":[0.0,0.0],"cash":0.0,"lots":[[],[]],"floor":0.0}}}
{"kind":"decision","recorded_ms":1789996430059,"S":1789996200,"age":230,"signal":{},"entry_side":null,"context_gap":"two-sided entry context unavailable","book_errors":[null,"empty/invalid public book"],"books":[{"bid":null,"ask":0.01,"asks":[[0.01,9464.85]],"received_ms":1789996430056,"observed_ms":1789996430013,"hash":"5da5930bf41540edec64321f1f1fbd5c2addb353"},null],"intents":{"pair_fast":null,"pair_250":null,"pair_add_fast":null,"pair_add_250":null},"decision_ms":1789996430059,"feature_cutoff_ms":1789996430059,"request_ms":1789996430030,"inventory":{"pair_fast":{"qty":[0.0,0.0],"cash":0.0,"lots":[[],[]],"floor":0.0},"pair_250":{"qty":[0.0,0.0],"cash":0.0,"lots":[[],[]],"floor":0.0},"pair_add_fast":{"qty":[0.0,0.0],"cash":0.0,"lots":[[],[]],"floor":0.0},"pair_add_250":{"qty":[0.0,0.0],"cash":0.0,"lots":[[],[]],"floor":0.0}}}
{"kind":"decision","recorded_ms":1789996440096,"S":1789996200,"age":240,"signal":{},"entry_side":null,"context_gap":"two-sided entry context unavailable","book_errors":[null,"empty/invalid public book"],"books":[{"bid":null,"ask":0.01,"asks":[[0.01,12557.12]],"received_ms":1789996440096,"observed_ms":1789996440058,"hash":"5fa5eaca12b8b65ffc9099d0cd0e6dbb3994eabf"},null],"intents":{"pair_fast":null,"pair_250":null,"pair_add_fast":null,"pair_add_250":null},"decision_ms":1789996440096,"feature_cutoff_ms":1789996440096,"request_ms":1789996440032,"inventory":{"pair_fast":{"qty":[0.0,0.0],"cash":0.0,"lots":[[],[]],"floor":0.0},"pair_250":{"qty":[0.0,0.0],"cash":0.0,"lots":[[],[]],"floor":0.0},"pair_add_fast":{"qty":[0.0,0.0],"cash":0.0,"lots":[[],[]],"floor":0.0},"pair_add_250":{"qty":[0.0,0.0],"cash":0.0,"lots":[[],[]],"floor":0.0}}}
{"kind":"decision","recorded_ms":1789996450070,"S":1789996200,"age":250,"signal":{},"entry_side":null,"context_gap":"two-sided entry context unavailable","book_errors":[null,"empty/invalid public book"],"books":[{"bid":null,"ask":0.01,"asks":[[0.01,19124.43]],"received_ms":1789996450070,"observed_ms":1789996450060,"hash":"d673e4f14d85a1d57c5cc9096f95805d38286c7e"},null],"intents":{"pair_fast":null,"pair_250":null,"pair_add_fast":null,"pair_add_250":null},"decision_ms":1789996450070,"feature_cutoff_ms":1789996450070,"request_ms":1789996450036,"inventory":{"pair_fast":{"qty":[0.0,0.0],"cash":0.0,"lots":[[],[]],"floor":0.0},"pair_250":{"qty":[0.0,0.0],"cash":0.0,"lots":[[],[]],"floor":0.0},"pair_add_fast":{"qty":[0.0,0.0],"cash":0.0,"lots":[[],[]],"floor":0.0},"pair_add_250":{"qty":[0.0,0.0],"cash":0.0,"lots":[[],[]],"floor":0.0}}}
{"kind":"decision","recorded_ms":1789996460086,"S":1789996200,"age":260,"signal":{},"entry_side":null,"context_gap":"two-sided entry context unavailable","book_errors":[null,"empty/invalid public book"],"books":[{"bid":null,"ask":0.01,"asks":[[0.01,36127.59]],"received_ms":1789996460067,"observed_ms":1789996460041,"hash":"0b4eb3bc105537d525abf523f2d1d2a910a46f24"},null],"intents":{"pair_fast":null,"pair_250":null,"pair_add_fast":null,"pair_add_250":null},"decision_ms":1789996460086,"feature_cutoff_ms":1789996460086,"request_ms":1789996460041,"inventory":{"pair_fast":{"qty":[0.0,0.0],"cash":0.0,"lots":[[],[]],"floor":0.0},"pair_250":{"qty":[0.0,0.0],"cash":0.0,"lots":[[],[]],"floor":0.0},"pair_add_fast":{"qty":[0.0,0.0],"cash":0.0,"lots":[[],[]],"floor":0.0},"pair_add_250":{"qty":[0.0,0.0],"cash":0.0,"lots":[[],[]],"floor":0.0}}}
{"kind":"decision","recorded_ms":1789996470039,"S":1789996200,"age":270,"signal":{},"entry_side":null,"context_gap":"two-sided entry context unavailable","book_errors":[null,"empty/invalid public book"],"books":[{"bid":null,"ask":0.01,"asks":[[0.01,55015.52]],"received_ms":1789996470039,"observed_ms":1789996470022,"hash":"7b30969c4077f43acf108697faa78bf16d767848"},null],"intents":{"pair_fast":null,"pair_250":null,"pair_add_fast":null,"pair_add_250":null},"decision_ms":1789996470039,"feature_cutoff_ms":1789996470039,"request_ms":1789996470006,"inventory":{"pair_fast":{"qty":[0.0,0.0],"cash":0.0,"lots":[[],[]],"floor":0.0},"pair_250":{"qty":[0.0,0.0],"cash":0.0,"lots":[[],[]],"floor":0.0},"pair_add_fast":{"qty":[0.0,0.0],"cash":0.0,"lots":[[],[]],"floor":0.0},"pair_add_250":{"qty":[0.0,0.0],"cash":0.0,"lots":[[],[]],"floor":0.0}}}
{"kind":"decision","recorded_ms":1789996480045,"S":1789996200,"age":280,"signal":{},"entry_side":null,"context_gap":"two-sided entry context unavailable","book_errors":[null,"empty/invalid public book"],"books":[{"bid":null,"ask":0.01,"asks":[[0.01,47755.62]],"received_ms":1789996480045,"observed_ms":1789996480031,"hash":"09669c57c56c3d68371a90c5547733ae2ee6a183"},null],"intents":{"pair_fast":null,"pair_250":null,"pair_add_fast":null,"pair_add_250":null},"decision_ms":1789996480045,"feature_cutoff_ms":1789996480045,"request_ms":1789996480011,"inventory":{"pair_fast":{"qty":[0.0,0.0],"cash":0.0,"lots":[[],[]],"floor":0.0},"pair_250":{"qty":[0.0,0.0],"cash":0.0,"lots":[[],[]],"floor":0.0},"pair_add_fast":{"qty":[0.0,0.0],"cash":0.0,"lots":[[],[]],"floor":0.0},"pair_add_250":{"qty":[0.0,0.0],"cash":0.0,"lots":[[],[]],"floor":0.0}}}
{"kind":"decision","recorded_ms":1789996490047,"S":1789996200,"age":290,"signal":{},"entry_side":null,"context_gap":"two-sided entry context unavailable","book_errors":[null,"empty/invalid public book"],"books":[{"bid":null,"ask":0.01,"asks":[[0.01,48077.62]],"received_ms":1789996490040,"observed_ms":1789996490032,"hash":"7a2537cbe95c45b3acd081966acaebf2de5bcf00"},null],"intents":{"pair_fast":null,"pair_250":null,"pair_add_fast":null,"pair_add_250":null},"decision_ms":1789996490047,"feature_cutoff_ms":1789996490047,"request_ms":1789996490015,"inventory":{"pair_fast":{"qty":[0.0,0.0],"cash":0.0,"lots":[[],[]],"floor":0.0},"pair_250":{"qty":[0.0,0.0],"cash":0.0,"lots":[[],[]],"floor":0.0},"pair_add_fast":{"qty":[0.0,0.0],"cash":0.0,"lots":[[],[]],"floor":0.0},"pair_add_250":{"qty":[0.0,0.0],"cash":0.0,"lots":[[],[]],"floor":0.0}}}
{"kind":"decision","recorded_ms":1789996530088,"S":1789996500,"age":30,"signal":{"rsi14":47.05079555289236,"volume_ratio":0.4150564124443265,"taker_buy_fraction":0.28404819749990284,"volume5":125.55672,"return1":-3.225346645510471,"return5":-20.15166526279409,"return15":-18.06522879061601,"bollinger_z":-1.4584776267684485,"bar_close_ms":1789996499999,"ref":85156.7056167453,"reference_received_ms":1789996501961,"spot":85160.00648586416,"twap":85158.12887928764,"sigma":5.660647333821348,"spot_z":0.0354936207765241,"twap_z":0.015304072692510318,"momentum":0.07650234634374788,"decision_ms":1789996530087,"momentum30":0.257346880120048,"momentum60":0.30639833408362566,"spot_twap_gap":0.04282159838335844,"range60":0.8966918054562907,"final_mean":85160.00648586416,"final_z":0.03845744625930151,"final_up_prob":0.5153385203341466,"final_drift_up_prob":0.6632083552123959,"final_known_seconds":0,"final_sd":85.83172935099564,"final_drift_shift":32.854482845668066},"entry_side":null,"context_gap":null,"book_errors":[null,null],"books":[{"bid":0.5,"ask":0.51,"asks":[[0.51,444.25]],"received_ms":1789996530087,"observed_ms":1789996530077,"hash":"5c968e457eb260af3d3bfa5c264448338512c08e"},{"bid":0.49,"ask":0.5,"asks":[[0.5,204.26]],"received_ms":1789996530075,"observed_ms":1789996530067,"hash":"a8d517c77481f94478ac5385f04f4fcb1eaeec30"}],"intents":{"pair_fast":null,"pair_250":null,"pair_add_fast":null,"pair_add_250":null},"decision_ms":1789996530088,"feature_cutoff_ms":1789996530087,"request_ms":1789996530050,"inventory":{"pair_fast":{"qty":[0.0,0.0],"cash":0.0,"lots":[[],[]],"floor":0.0},"pair_250":{"qty":[0.0,0.0],"cash":0.0,"lots":[[],[]],"floor":0.0},"pair_add_fast":{"qty":[0.0,0.0],"cash":0.0,"lots":[[],[]],"floor":0.0},"pair_add_250":{"qty":[0.0,0.0],"cash":0.0,"lots":[[],[]],"floor":0.0}}}
{"kind":"decision","recorded_ms":1789996540064,"S":1789996500,"age":40,"signal":{"rsi14":47.05079555289236,"volume_ratio":0.4150564124443265,"taker_buy_fraction":0.28404819749990284,"volume5":125.55672,"return1":-3.225346645510471,"return5":-20.15166526279409,"return15":-18.06522879061601,"bollinger_z":-1.4584776267684485,"bar_close_ms":1789996499999,"ref":85156.7056167453,"reference_received_ms":1789996501961,"spot":85159.64371032029,"twap":85159.7578002206,"sigma":4.52426387372359,"spot_z":0.04027946053935119,"twap_z":0.04184356308410669,"momentum":-0.025356544844379315,"decision_ms":1789996540063,"momentum30":0.14361194321234275,"momentum60":-0.6006099642801155,"spot_twap_gap":-0.0032555445938810203,"range60":1.1219186633422507,"final_mean":85159.64371032029,"final_z":0.043789354991002324,"final_up_prob":0.5174638437835815,"final_drift_up_prob":0.46790661197066163,"final_known_seconds":0,"final_sd":67.09606879566589,"final_drift_shift":-8.341552024276437},"entry_side":null,"context_gap":null,"book_errors":[null,null],"books":[{"bid":0.5,"ask":0.51,"asks":[[0.51,1652.22]],"received_ms":1789996540063,"observed_ms":1789996540047,"hash":"460ec9c3480ec21591635c08ed53ad833c65eeb0"},{"bid":0.49,"ask":0.5,"asks":[[0.5,20.61]],"received_ms":1789996540041,"observed_ms":1789996540032,"hash":"0226a90c81befd8c7decb6d94564b94145ea000a"}],"intents":{"pair_fast":null,"pair_250":null,"pair_add_fast":null,"pair_add_250":null},"decision_ms":1789996540064,"feature_cutoff_ms":1789996540063,"request_ms":1789996540010,"inventory":{"pair_fast":{"qty":[0.0,0.0],"cash":0.0,"lots":[[],[]],"floor":0.0},"pair_250":{"qty":[0.0,0.0],"cash":0.0,"lots":[[],[]],"floor":0.0},"pair_add_fast":{"qty":[0.0,0.0],"cash":0.0,"lots":[[],[]],"floor":0.0},"pair_add_250":{"qty":[0.0,0.0],"cash":0.0,"lots":[[],[]],"floor":0.0}}}
{"kind":"decision","recorded_ms":1789996550108,"S":1789996500,"age":50,"signal":{"rsi14":47.05079555289236,"volume_ratio":0.4150564124443265,"taker_buy_fraction":0.28404819749990284,"volume5":125.55672,"return1":-3.225346645510471,"return5":-20.15166526279409,"return15":-18.06522879061601,"bollinger_z":-1.4584776267684485,"bar_close_ms":1789996499999,"ref":85156.7056167453,"reference_received_ms":1789996501961,"spot":85118.94599465365,"twap":85155.0467375043,"sigma":4.769269474289305,"spot_z":-0.5008396830776356,"twap_z":-0.022003200967211922,"momentum":-2.698473587334416,"decision_ms":1789996550107,"momentum30":-1.5194282142171416,"momentum60":-0.9706676989555594,"spot_twap_gap":-0.9772116854932469,"range60":1.3158910553669358,"final_mean":85118.94599465365,"final_z":-0.5464831806496231,"final_up_prob":0.29236692305883194,"final_drift_up_prob":0.0,"final_known_seconds":0,"final_sd":69.09567106303177,"final_drift_shift":-894.9142786504578},"entry_side":null,"context_gap":null,"book_errors":[null,null],"books":[{"bid":0.33,"ask":0.34,"asks":[[0.34,1018.0]],"received_ms":1789996550107,"observed_ms":1789996550077,"hash":"f03d27a469d5673d73a0d3a6b1c1db949ee98070"},{"bid":0.66,"ask":0.67,"asks":[[0.67,700.43]],"received_ms":1789996550062,"observed_ms":1789996550055,"hash":"4e4ecf3da5db5245afa7c9ff1ddedcbc4821d48d"}],"intents":{"pair_fast":null,"pair_250":null,"pair_add_fast":null,"pair_add_250":null},"decision_ms":1789996550108,"feature_cutoff_ms":1789996550107,"request_ms":1789996550036,"inventory":{"pair_fast":{"qty":[0.0,0.0],"cash":0.0,"lots":[[],[]],"floor":0.0},"pair_250":{"qty":[0.0,0.0],"cash":0.0,"lots":[[],[]],"floor":0.0},"pair_add_fast":{"qty":[0.0,0.0],"cash":0.0,"lots":[[],[]],"floor":0.0},"pair_add_250":{"qty":[0.0,0.0],"cash":0.0,"lots":[[],[]],"floor":0.0}}}
{"kind":"decision","recorded_ms":1789996560058,"S":1789996500,"age":60,"signal":{"rsi14":47.05079555289236,"volume_ratio":0.4150564124443265,"taker_buy_fraction":0.28404819749990284,"volume5":125.55672,"return1":-3.225346645510471,"return5":-20.15166526279409,"return15":-18.06522879061601,"bollinger_z":-1.4584776267684485,"bar_close_ms":1789996499999,"ref":85156.7056167453,"reference_received_ms":1789996501961,"spot":85112.70058252524,"twap":85149.3578813358,"sigma":4.818647476782622,"spot_z":-0.5895534232240125,"twap_z":-0.09844061345229295,"momentum":-0.40986038815610143,"decision_ms":1789996560057,"momentum30":-1.7923778049563608,"momentum60":-1.0536334376367493,"spot_twap_gap":-0.9821089734848804,"range60":1.4697315615553184,"final_mean":85112.70058252524,"final_z":-0.6458387599838958,"final_up_prob":0.25919189164931355,"final_drift_up_prob":0.0050821440759318826,"final_known_seconds":0,"final_sd":68.13625466076542,"final_drift_shift":-131.118055896317},"entry_side":null,"context_gap":null,"book_errors":[null,null],"books":[{"bid":0.32,"ask":0.33,"asks":[[0.33,129.88]],"received_ms":1789996560055,"observed_ms":1789996560049,"hash":"ab7ad5a9530fee9392c15ee073f3bcbf85ab37d0"},{"bid":0.67,"ask":0.68,"asks":[[0.68,975.78]],"received_ms":1789996560057,"observed_ms":1789996560049,"hash":"d8a86ce88d770be9cc9d40ce7f64947f96f80f62"}],"intents":{"pair_fast":null,"pair_250":null,"pair_add_fast":null,"pair_add_250":null},"decision_ms":1789996560058,"feature_cutoff_ms":1789996560057,"request_ms":1789996560030,"inventory":{"pair_fast":{"qty":[0.0,0.0],"cash":0.0,"lots":[[],[]],"floor":0.0},"pair_250":{"qty":[0.0,0.0],"cash":0.0,"lots":[[],[]],"floor":0.0},"pair_add_fast":{"qty":[0.0,0.0],"cash":0.0,"lots":[[],[]],"floor":0.0},"pair_add_250":{"qty":[0.0,0.0],"cash":0.0,"lots":[[],[]],"floor":0.0}}}
{"kind":"decision","recorded_ms":1789996570039,"S":1789996500,"age":70,"signal":{},"entry_side":null,"context_gap":"incomplete or stale context","book_errors":[null,null],"books":[{"bid":0.34,"ask":0.35,"asks":[[0.35,683.5]],"received_ms":1789996570025,"observed_ms":1789996570017,"hash":"eebfa81e763077bfb3f28e729aa5fce3eea9ed4d"},{"bid":0.65,"ask":0.66,"asks":[[0.66,94.02]],"received_ms":1789996570038,"observed_ms":1789996570022,"hash":"e172093bd153721d2d8d8842a82cc84ef8191524"}],"intents":{"pair_fast":null,"pair_250":null,"pair_add_fast":null,"pair_add_250":null},"decision_ms":1789996570039,"feature_cutoff_ms":1789996570038,"request_ms":1789996570004,"inventory":{"pair_fast":{"qty":[0.0,0.0],"cash":0.0,"lots":[[],[]],"floor":0.0},"pair_250":{"qty":[0.0,0.0],"cash":0.0,"lots":[[],[]],"floor":0.0},"pair_add_fast":{"qty":[0.0,0.0],"cash":0.0,"lots":[[],[]],"floor":0.0},"pair_add_250":{"qty":[0.0,0.0],"cash":0.0,"lots":[[],[]],"floor":0.0}}}
{"kind":"decision","recorded_ms":1789996580059,"S":1789996500,"age":80,"signal":{"rsi14":43.22801751654719,"volume_ratio":0.699406328166258,"taker_buy_fraction":0.2499902503625975,"volume5":123.59434,"return1":-3.4872200842267986,"return5":-13.987640277215382,"return15":-9.731094105024853,"bollinger_z":-1.584639319677781,"bar_close_ms":1789996559999,"ref":85156.7056167453,"reference_received_ms":1789996501961,"spot":85109.1765346068,"twap":85138.13684253869,"sigma":4.48264491930082,"spot_z":-0.7149423176404087,"twap_z":-0.2793153553508263,"momentum":-1.1907478031133178,"decision_ms":1789996580058,"momentum30":-0.3979015171205002,"momentum60":-1.4244548784879119,"spot_twap_gap":-0.8340521599819846,"range60":1.4638943321211244,"final_mean":85109.1765346068,"final_z":-0.7904216316985488,"final_up_prob":0.21464078662009867,"final_drift_up_prob":4.613737725200906e-10,"final_known_seconds":0,"final_sd":60.131302373851824,"final_drift_shift":-320.6085752009673},"entry_side":null,"context_gap":null,"book_errors":[null,null],"books":[{"bid":0.27,"ask":0.28,"asks":[[0.28,205.42]],"received_ms":1789996580058,"observed_ms":1789996580038,"hash":"7aba974ead397b087e8057b5a8984508ea945cb3"},{"bid":0.72,"ask":0.73,"asks":[[0.73,860.03]],"received_ms":1789996580041,"observed_ms":1789996580032,"hash":"4ac7a0f168c8ca26bccb61559cf8c0e9a377ec70"}],"intents":{"pair_fast":null,"pair_250":null,"pair_add_fast":null,"pair_add_250":null},"decision_ms":1789996580059,"feature_cutoff_ms":1789996580058,"request_ms":1789996580011,"inventory":{"pair_fast":{"qty":[0.0,0.0],"cash":0.0,"lots":[[],[]],"floor":0.0},"pair_250":{"qty":[0.0,0.0],"cash":0.0,"lots":[[],[]],"floor":0.0},"pair_add_fast":{"qty":[0.0,0.0],"cash":0.0,"lots":[[],[]],"floor":0.0},"pair_add_250":{"qty":[0.0,0.0],"cash":0.0,"lots":[[],[]],"floor":0.0}}}
{"kind":"decision","recorded_ms":1789996590078,"S":1789996500,"age":90,"signal":{"rsi14":43.22801751654719,"volume_ratio":0.699406328166258,"taker_buy_fraction":0.2499902503625975,"volume5":123.59434,"return1":-3.4872200842267986,"return5":-13.987640277215382,"return15":-9.731094105024853,"bollinger_z":-1.584639319677781,"bar_close_ms":1789996559999,"ref":85156.7056167453,"reference_received_ms":1789996501961,"spot":85085.52097854899,"twap":85129.52153417793,"sigma":4.9741940007033705,"spot_z":-0.9877169714746579,"twap_z":-0.37719064655093903,"momentum":-1.503870505450811,"decision_ms":1789996590076,"momentum30":-0.9976076660022587,"momentum60":-1.933185083685067,"spot_twap_gap":-1.141983466069475,"range60":1.933185083685067,"final_mean":85085.52097854899,"final_z":-1.0978327978722242,"final_up_prob":0.13613875348547722,"final_drift_up_prob":9.159339953157541e-15,"final_known_seconds":0,"final_sd":64.84105624670592,"final_drift_shift":-425.6202268732435},"entry_side":null,"context_gap":null,"book_errors":[null,null],"books":[{"bid":0.22,"ask":0.23,"asks":[[0.23,1022.12]],"received_ms":1789996590076,"observed_ms":1789996590066,"hash":"46f23d05fd59a780a83b4592b07a02d06cc0715e"},{"bid":0.77,"ask":0.78,"asks":[[0.78,11.41]],"received_ms":1789996590065,"observed_ms":1789996590056,"hash":"42562cda17746b69c7362b8e2c4910aec940a597"}],"intents":{"pair_fast":null,"pair_250":null,"pair_add_fast":null,"pair_add_250":null},"decision_ms":1789996590078,"feature_cutoff_ms":1789996590076,"request_ms":1789996590032,"inventory":{"pair_fast":{"qty":[0.0,0.0],"cash":0.0,"lots":[[],[]],"floor":0.0},"pair_250":{"qty":[0.0,0.0],"cash":0.0,"lots":[[],[]],"floor":0.0},"pair_add_fast":{"qty":[0.0,0.0],"cash":0.0,"lots":[[],[]],"floor":0.0},"pair_add_250":{"qty":[0.0,0.0],"cash":0.0,"lots":[[],[]],"floor":0.0}}}
{"kind":"decision","recorded_ms":1789996600034,"S":1789996500,"age":100,"signal":{"rsi14":43.22801751654719,"volume_ratio":0.699406328166258,"taker_buy_fraction":0.2499902503625975,"volume5":123.59434,"return1":-3.4872200842267986,"return5":-13.987640277215382,"return15":-9.731094105024853,"bollinger_z":-1.584639319677781,"bar_close_ms":1789996559999,"ref":85156.7056167453,"reference_received_ms":1789996501961,"spot":85102.53300001896,"twap":85118.27254892637,"sigma":5.230713421705409,"spot_z":-0.7323854735337314,"twap_z":-0.5195949960496171,"momentum":1.0284779744491173,"decision_ms":1789996600033,"momentum30":-0.8210467420452249,"momentum60":-1.4095517000880382,"spot_twap_gap":-0.38846842919658575,"range60":1.829426074936627,"final_mean":85102.53300001896,"final_z":-0.818848743990168,"final_up_prob":0.20643635827438317,"final_drift_up_prob":0.9998086862413578,"final_known_seconds":0,"final_sd":66.1570493011478,"final_drift_shift":289.1482253316341},"entry_side":null,"context_gap":null,"book_errors":[null,null],"books":[{"bid":0.25,"ask":0.26,"asks":[[0.26,210.0]],"received_ms":1789996600033,"observed_ms":1789996599037,"hash":"3f1e7a9d1f324c6744f23b6a9f53a49696e5c72b"},{"bid":0.74,"ask":0.75,"asks":[[0.75,1086.23]],"received_ms":1789996600027,"observed_ms":1789996599037,"hash":"12a2d696aebf72643bdb022bae4e9376e5b8c3f0"}],"intents":{"pair_fast":null,"pair_250":null,"pair_add_fast":null,"pair_add_250":null},"decision_ms":1789996600034,"feature_cutoff_ms":1789996600033,"request_ms":1789996600001,"inventory":{"pair_fast":{"qty":[0.0,0.0],"cash":0.0,"lots":[[],[]],"floor":0.0},"pair_250":{"qty":[0.0,0.0],"cash":0.0,"lots":[[],[]],"floor":0.0},"pair_add_fast":{"qty":[0.0,0.0],"cash":0.0,"lots":[[],[]],"floor":0.0},"pair_add_250":{"qty":[0.0,0.0],"cash":0.0,"lots":[[],[]],"floor":0.0}}}
{"kind":"decision","recorded_ms":1789996610044,"S":1789996500,"age":110,"signal":{"rsi14":43.22801751654719,"volume_ratio":0.699406328166258,"taker_buy_fraction":0.2499902503625975,"volume5":123.59434,"return1":-3.4872200842267986,"return5":-13.987640277215382,"return15":-9.731094105024853,"bollinger_z":-1.584639319677781,"bar_close_ms":1789996559999,"ref":85156.7056167453,"reference_received_ms":1789996501961,"spot":85103.29980109635,"twap":85110.02521318654,"sigma":3.6309478657257355,"spot_z":-1.0671878889400122,"twap_z":-0.9327965638835326,"momentum":0.06678250436256415,"decision_ms":1789996610043,"momentum30":-0.2954985518155972,"momentum60":-0.5563051239868493,"spot_twap_gap":-0.23912405231309602,"range60":1.4412285941034315,"final_mean":85103.29980109635,"final_z":-1.2011165948634333,"final_up_prob":0.11485298831516566,"final_drift_up_prob":0.17741520936330607,"final_known_seconds":0,"final_sd":44.463473302540145,"final_drift_shift":12.265519994960338},"entry_side":null,"context_gap":null,"book_errors":[null,null],"books":[{"bid":0.24,"ask":0.25,"asks":[[0.25,359.09]],"received_ms":1789996610041,"observed_ms":1789996610029,"hash":"5353748dbd5a13afb874aa17200322466a40f51a"},{"bid":0.75,"ask":0.76,"asks":[[0.76,225.68]],"received_ms":1789996610043,"observed_ms":1789996610031,"hash":"f24b016c8543f1daa33e3c031cd5ba9de52448a5"}],"intents":{"pair_fast":null,"pair_250":null,"pair_add_fast":null,"pair_add_250":null},"decision_ms":1789996610044,"feature_cutoff_ms":1789996610043,"request_ms":1789996610007,"inventory":{"pair_fast":{"qty":[0.0,0.0],"cash":0.0,"lots":[[],[]],"floor":0.0},"pair_250":{"qty":[0.0,0.0],"cash":0.0,"lots":[[],[]],"floor":0.0},"pair_add_fast":{"qty":[0.0,0.0],"cash":0.0,"lots":[[],[]],"floor":0.0},"pair_add_250":{"qty":[0.0,0.0],"cash":0.0,"lots":[[],[]],"floor":0.0}}}
{"kind":"decision","recorded_ms":1789996620045,"S":1789996500,"age":120,"signal":{"rsi14":43.22801751654719,"volume_ratio":0.699406328166258,"taker_buy_fraction":0.2499902503625975,"volume5":123.59434,"return1":-3.4872200842267986,"return5":-13.987640277215382,"return15":-9.731094105024853,"bollinger_z":-1.584639319677781,"bar_close_ms":1789996559999,"ref":85156.7056167453,"reference_received_ms":1789996501961,"spot":85090.56008564049,"twap":85108.27053979514,"sigma":4.928589463796261,"spot_z":-1.0004484089619685,"twap_z":-0.7325785259167686,"momentum":-0.8174046119866203,"decision_ms":1789996620044,"momentum30":0.18666819002182203,"momentum60":-0.5799480516773904,"spot_twap_gap":-0.4639075371602011,"range60":1.0617694831802857,"final_mean":85090.56008564049,"final_z":-1.134441492713339,"final_up_prob":0.1283047012712064,"final_drift_up_prob":5.147003389827098e-06,"final_known_seconds":0,"final_sd":58.306692350082336,"final_drift_shift":-191.0396772040495},"entry_side":null,"context_gap":null,"book_errors":[null,null],"books":[{"bid":0.19,"ask":0.2,"asks":[[0.2,1069.26]],"received_ms":1789996620043,"observed_ms":1789996620028,"hash":"39d515aac5691ec94e53d3b6db5d2fd9eea1503d"},{"bid":0.8,"ask":0.81,"asks":[[0.81,78.82]],"received_ms":1789996620043,"observed_ms":1789996620029,"hash":"189f4fbebb895b1b55f560e67a8f43ca469f3c15"}],"intents":{"pair_fast":null,"pair_250":null,"pair_add_fast":null,"pair_add_250":null},"decision_ms":1789996620045,"feature_cutoff_ms":1789996620044,"request_ms":1789996620018,"inventory":{"pair_fast":{"qty":[0.0,0.0],"cash":0.0,"lots":[[],[]],"floor":0.0},"pair_250":{"qty":[0.0,0.0],"cash":0.0,"lots":[[],[]],"floor":0.0},"pair_add_fast":{"qty":[0.0,0.0],"cash":0.0,"lots":[[],[]],"floor":0.0},"pair_add_250":{"qty":[0.0,0.0],"cash":0.0,"lots":[[],[]],"floor":0.0}}}
{"kind":"decision","recorded_ms":1789996630075,"S":1789996500,"age":130,"signal":{"rsi14":36.46277743157078,"volume_ratio":0.6027336511551044,"taker_buy_fraction":0.25283960622177765,"volume5":120.38553,"return1":-2.735085472008296,"return5":-13.762367362159202,"return15":-16.942726628795256,"bollinger_z":-1.6196131261419147,"bar_close_ms":1789996619999,"ref":85156.7056167453,"reference_received_ms":1789996501961,"spot":85089.56285817268,"twap":85102.8758202561,"sigma":4.872882854851285,"spot_z":-1.0570202124919077,"twap_z":-0.8474358833777564,"momentum":-0.06471549260490679,"decision_ms":1789996630074,"momentum30":-0.4859573189599828,"momentum60":-0.9668242829658774,"spot_twap_gap":-0.3527062040659952,"range60":1.110113871562072,"final_mean":85089.56285817268,"final_z":-1.2088298485494418,"final_up_prob":0.11336411084281506,"final_drift_up_prob":0.07213783465208101,"final_known_seconds":0,"final_sd":55.54359751555512,"final_drift_shift":-13.95380507793828},"entry_side":null,"context_gap":null,"book_errors":[null,null],"books":[{"bid":0.17,"ask":0.18,"asks":[[0.18,385.18]],"received_ms":1789996630063,"observed_ms":1789996630050,"hash":"d0da5e30c65643738b7cf7d8525257c20cda566c"},{"bid":0.82,"ask":0.83,"asks":[[0.83,289.52]],"received_ms":1789996630074,"observed_ms":1789996630066,"hash":"a1b4932a732eefdfabb102775db1eea5d8f295f5"}],"intents":{"pair_fast":null,"pair_250":null,"pair_add_fast":null,"pair_add_250":null},"decision_ms":1789996630075,"feature_cutoff_ms":1789996630074,"request_ms":1789996630040,"inventory":{"pair_fast":{"qty":[0.0,0.0],"cash":0.0,"lots":[[],[]],"floor":0.0},"pair_250":{"qty":[0.0,0.0],"cash":0.0,"lots":[[],[]],"floor":0.0},"pair_add_fast":{"qty":[0.0,0.0],"cash":0.0,"lots":[[],[]],"floor":0.0},"pair_add_250":{"qty":[0.0,0.0],"cash":0.0,"lots":[[],[]],"floor":0.0}}}
{"kind":"decision","recorded_ms":1789996640082,"S":1789996500,"age":140,"signal":{},"entry_side":null,"context_gap":"incomplete or stale context","book_errors":[null,null],"books":[{"bid":0.15,"ask":0.16,"asks":[[0.16,786.9]],"received_ms":1789996640081,"observed_ms":1789996640071,"hash":"df9dea6cbe0ac6daca3ee9e23ce856e2b642d142"},{"bid":0.84,"ask":0.85,"asks":[[0.85,237.21]],"received_ms":1789996640080,"observed_ms":1789996640063,"hash":"76458eab0357bf129aca52bbf4c231406dc983f9"}],"intents":{"pair_fast":null,"pair_250":null,"pair_add_fast":null,"pair_add_250":null},"decision_ms":1789996640082,"feature_cutoff_ms":1789996640081,"request_ms":1789996640048,"inventory":{"pair_fast":{"qty":[0.0,0.0],"cash":0.0,"lots":[[],[]],"floor":0.0},"pair_250":{"qty":[0.0,0.0],"cash":0.0,"lots":[[],[]],"floor":0.0},"pair_add_fast":{"qty":[0.0,0.0],"cash":0.0,"lots":[[],[]],"floor":0.0},"pair_add_250":{"qty":[0.0,0.0],"cash":0.0,"lots":[[],[]],"floor":0.0}}}
{"kind":"decision","recorded_ms":1789996650040,"S":1789996500,"age":150,"signal":{"rsi14":36.46277743157078,"volume_ratio":0.6027336511551044,"taker_buy_fraction":0.25283960622177765,"volume5":120.38553,"return1":-2.735085472008296,"return5":-13.762367362159202,"return15":-16.942726628795256,"bollinger_z":-1.6196131261419147,"bar_close_ms":1789996619999,"ref":85156.7056167453,"reference_received_ms":1789996501961,"spot":85084.731193345,"twap":85093.52805252816,"sigma":4.036037898259787,"spot_z":-1.4562428126827967,"twap_z":-1.2782578792237096,"momentum":0.23093452208097412,"decision_ms":1789996650039,"momentum30":-0.26367573645165615,"momentum60":-0.02526260505343288,"spot_twap_gap":-0.2813823025959744,"range60":1.0460018094471861,"final_mean":85084.731193345,"final_z":-1.7006056533212888,"final_up_prob":0.044508530939779856,"final_drift_up_prob":0.193470945184336,"final_known_seconds":0,"final_sd":42.322817908863655,"final_drift_shift":35.35771352204513},"entry_side":0,"context_gap":null,"book_errors":[null,null],"books":[{"bid":0.12,"ask":0.13,"asks":[[0.13,189.64]],"received_ms":1789996650035,"observed_ms":1789996650027,"hash":"a5015ddc26fcef8058094fc938b903297fde548a"},{"bid":0.87,"ask":0.88,"asks":[[0.88,287.63]],"received_ms":1789996650038,"observed_ms":1789996650027,"hash":"08187789e017a23374a8bcfe5a10803e69591c36"}],"intents":{"pair_fast":{"kind":"first","side":0,"qty":5.0,"max_cost":0.7395900000000001},"pair_250":{"kind":"first","side":0,"qty":5.0,"max_cost":0.7395900000000001},"pair_add_fast":{"kind":"first","side":0,"qty":5.0,"max_cost":0.7395900000000001},"pair_add_250":{"kind":"first","side":0,"qty":5.0,"max_cost":0.7395900000000001}},"decision_ms":1789996650040,"feature_cutoff_ms":1789996650039,"request_ms":1789996650003,"inventory":{"pair_fast":{"qty":[0.0,0.0],"cash":0.0,"lots":[[],[]],"floor":0.0},"pair_250":{"qty":[0.0,0.0],"cash":0.0,"lots":[[],[]],"floor":0.0},"pair_add_fast":{"qty":[0.0,0.0],"cash":0.0,"lots":[[],[]],"floor":0.0},"pair_add_250":{"qty":[0.0,0.0],"cash":0.0,"lots":[[],[]],"floor":0.0}}}
{"kind":"decision","recorded_ms":1789996660053,"S":1789996500,"age":160,"signal":{"rsi14":36.46277743157078,"volume_ratio":0.6027336511551044,"taker_buy_fraction":0.25283960622177765,"volume5":120.38553,"return1":-2.735085472008296,"return5":-13.762367362159202,"return15":-16.942726628795256,"bollinger_z":-1.6196131261419147,"bar_close_ms":1789996619999,"ref":85156.7056167453,"reference_received_ms":1789996501961,"spot":85082.46776798951,"twap":85092.3136287841,"sigma":3.705768344820163,"spot_z":-1.6934164071279938,"twap_z":-1.4688255482695722,"momentum":-0.1931469744221083,"decision_ms":1789996660052,"momentum30":-0.34955782258455254,"momentum60":-0.6990211139025904,"spot_twap_gap":-0.34300448506484477,"range60":1.1392247306764747,"final_mean":85082.46776798951,"final_z":-2.0038262307530603,"final_up_prob":0.022544338970506617,"final_drift_up_prob":0.0037303806854827593,"final_known_seconds":0,"final_sd":37.04804718914559,"final_drift_shift":-24.8859090881375},"entry_side":null,"context_gap":null,"book_errors":[null,null],"books":[{"bid":0.12,"ask":0.13,"asks":[[0.13,590.92]],"received_ms":1789996660052,"observed_ms":1789996660037,"hash":"e7fa7b26544b61564ffb5b7387ae2f627dc015be"},{"bid":0.87,"ask":0.88,"asks":[[0.88,197.0]],"received_ms":1789996660048,"observed_ms":1789996660033,"hash":"0069272c5c36b8976acae7304268a6cee669ffb8"}],"intents":{"pair_fast":null,"pair_250":null,"pair_add_fast":null,"pair_add_250":null},"decision_ms":1789996660053,"feature_cutoff_ms":1789996660052,"request_ms":1789996660005,"inventory":{"pair_fast":{"qty":[5.0,0.0],"cash":0.68959,"lots":[[[5.0,0.137918]],[]],"floor":-0.68959},"pair_250":{"qty":[5.0,0.0],"cash":0.68959,"lots":[[[5.0,0.137918]],[]],"floor":-0.68959},"pair_add_fast":{"qty":[5.0,0.0],"cash":0.68959,"lots":[[[5.0,0.137918]],[]],"floor":-0.68959},"pair_add_250":{"qty":[5.0,0.0],"cash":0.68959,"lots":[[[5.0,0.137918]],[]],"floor":-0.68959}}}
{"kind":"decision","recorded_ms":1789996670061,"S":1789996500,"age":170,"signal":{},"entry_side":null,"context_gap":"incomplete or stale context","book_errors":[null,null],"books":[{"bid":0.1,"ask":0.11,"asks":[[0.11,926.29]],"received_ms":1789996670060,"observed_ms":1789996670047,"hash":"66a199facf07e362731d858a478db92c4f10234a"},{"bid":0.89,"ask":0.9,"asks":[[0.9,285.62]],"received_ms":1789996670049,"observed_ms":1789996670040,"hash":"f1e9d3cab82b4b97bbe2a69a5e0372a4d551c36d"}],"intents":{"pair_fast":null,"pair_250":null,"pair_add_fast":null,"pair_add_250":null},"decision_ms":1789996670061,"feature_cutoff_ms":1789996670061,"request_ms":1789996670026,"inventory":{"pair_fast":{"qty":[5.0,0.0],"cash":0.68959,"lots":[[[5.0,0.137918]],[]],"floor":-0.68959},"pair_250":{"qty":[5.0,0.0],"cash":0.68959,"lots":[[[5.0,0.137918]],[]],"floor":-0.68959},"pair_add_fast":{"qty":[5.0,0.0],"cash":0.68959,"lots":[[[5.0,0.137918]],[]],"floor":-0.68959},"pair_add_250":{"qty":[5.0,0.0],"cash":0.68959,"lots":[[[5.0,0.137918]],[]],"floor":-0.68959}}}
{"kind":"decision","recorded_ms":1789996680068,"S":1789996500,"age":180,"signal":{},"entry_side":null,"context_gap":"incomplete or stale context","book_errors":[null,null],"books":[{"bid":0.09,"ask":0.1,"asks":[[0.1,1361.41]],"received_ms":1789996680067,"observed_ms":1789996680056,"hash":"717fac99ca8e41ca15d77376ae6fc243cd729db7"},{"bid":0.9,"ask":0.91,"asks":[[0.91,43.19]],"received_ms":1789996680062,"observed_ms":1789996680054,"hash":"fd362317458c095619eef25c1c93aa9cb9f6c217"}],"intents":{"pair_fast":null,"pair_250":null,"pair_add_fast":null,"pair_add_250":null},"decision_ms":1789996680068,"feature_cutoff_ms":1789996680067,"request_ms":1789996680034,"inventory":{"pair_fast":{"qty":[5.0,0.0],"cash":0.68959,"lots":[[[5.0,0.137918]],[]],"floor":-0.68959},"pair_250":{"qty":[5.0,0.0],"cash":0.68959,"lots":[[[5.0,0.137918]],[]],"floor":-0.68959},"pair_add_fast":{"qty":[5.0,0.0],"cash":0.68959,"lots":[[[5.0,0.137918]],[]],"floor":-0.68959},"pair_add_250":{"qty":[5.0,0.0],"cash":0.68959,"lots":[[[5.0,0.137918]],[]],"floor":-0.68959}}}
{"kind":"decision","recorded_ms":1789996690059,"S":1789996500,"age":190,"signal":{},"entry_side":null,"context_gap":"incomplete or stale context","book_errors":[null,null],"books":[{"bid":0.07,"ask":0.08,"asks":[[0.08,550.96]],"received_ms":1789996690046,"observed_ms":1789996690035,"hash":"9533cb33df431f42e4d0a77bd32d62b78b6a27c0"},{"bid":0.92,"ask":0.93,"asks":[[0.93,801.96]],"received_ms":1789996690058,"observed_ms":1789996690035,"hash":"9ab0153a95290a71bfdb994229aeae17422c2457"}],"intents":{"pair_fast":null,"pair_250":null,"pair_add_fast":null,"pair_add_250":null},"decision_ms":1789996690059,"feature_cutoff_ms":1789996690058,"request_ms":1789996690020,"inventory":{"pair_fast":{"qty":[5.0,0.0],"cash":0.68959,"lots":[[[5.0,0.137918]],[]],"floor":-0.68959},"pair_250":{"qty":[5.0,0.0],"cash":0.68959,"lots":[[[5.0,0.137918]],[]],"floor":-0.68959},"pair_add_fast":{"qty":[5.0,0.0],"cash":0.68959,"lots":[[[5.0,0.137918]],[]],"floor":-0.68959},"pair_add_250":{"qty":[5.0,0.0],"cash":0.68959,"lots":[[[5.0,0.137918]],[]],"floor":-0.68959}}}
{"kind":"decision","recorded_ms":1789996700062,"S":1789996500,"age":200,"signal":{},"entry_side":null,"context_gap":"incomplete or stale context","book_errors":[null,null],"books":[{"bid":0.13,"ask":0.14,"asks":[[0.14,470.43]],"received_ms":1789996700060,"observed_ms":1789996700048,"hash":"67b02a7fa55833a7bb7c3fdb3039eddddfe42116"},{"bid":0.86,"ask":0.87,"asks":[[0.87,402.35]],"received_ms":1789996700060,"observed_ms":1789996700048,"hash":"777505c188b83ee8b46df8f567a8f96f4d2c37d8"}],"intents":{"pair_fast":null,"pair_250":null,"pair_add_fast":null,"pair_add_250":null},"decision_ms":1789996700062,"feature_cutoff_ms":1789996700061,"request_ms":1789996700031,"inventory":{"pair_fast":{"qty":[5.0,0.0],"cash":0.68959,"lots":[[[5.0,0.137918]],[]],"floor":-0.68959},"pair_250":{"qty":[5.0,0.0],"cash":0.68959,"lots":[[[5.0,0.137918]],[]],"floor":-0.68959},"pair_add_fast":{"qty":[5.0,0.0],"cash":0.68959,"lots":[[[5.0,0.137918]],[]],"floor":-0.68959},"pair_add_250":{"qty":[5.0,0.0],"cash":0.68959,"lots":[[[5.0,0.137918]],[]],"floor":-0.68959}}}
{"kind":"decision","recorded_ms":1789996710060,"S":1789996500,"age":210,"signal":{},"entry_side":null,"context_gap":"incomplete or stale context","book_errors":[null,null],"books":[{"bid":0.1,"ask":0.11,"asks":[[0.11,679.99]],"received_ms":1789996710058,"observed_ms":1789996710033,"hash":"255f5f76a0f54cd3a35f673d117b3fdcea1318cd"},{"bid":0.89,"ask":0.9,"asks":[[0.9,85.0]],"received_ms":1789996710059,"observed_ms":1789996710047,"hash":"b113b80548913dc26580acf9aa4bb4e4bea3de4d"}],"intents":{"pair_fast":null,"pair_250":null,"pair_add_fast":null,"pair_add_250":null},"decision_ms":1789996710060,"feature_cutoff_ms":1789996710059,"request_ms":1789996710034,"inventory":{"pair_fast":{"qty":[5.0,0.0],"cash":0.68959,"lots":[[[5.0,0.137918]],[]],"floor":-0.68959},"pair_250":{"qty":[5.0,0.0],"cash":0.68959,"lots":[[[5.0,0.137918]],[]],"floor":-0.68959},"pair_add_fast":{"qty":[5.0,0.0],"cash":0.68959,"lots":[[[5.0,0.137918]],[]],"floor":-0.68959},"pair_add_250":{"qty":[5.0,0.0],"cash":0.68959,"lots":[[[5.0,0.137918]],[]],"floor":-0.68959}}}
{"kind":"decision","recorded_ms":1789996720064,"S":1789996500,"age":220,"signal":{},"entry_side":null,"context_gap":"incomplete or stale context","book_errors":[null,null],"books":[{"bid":0.09,"ask":0.1,"asks":[[0.1,615.87]],"received_ms":1789996720063,"observed_ms":1789996720040,"hash":"c20b7efc1ed7d25b090dd44b394a8e4987560cb6"},{"bid":0.9,"ask":0.91,"asks":[[0.91,351.3]],"received_ms":1789996720063,"observed_ms":1789996720044,"hash":"8129bf96a17b197cfd49d654e898fa4eddc90399"}],"intents":{"pair_fast":null,"pair_250":null,"pair_add_fast":null,"pair_add_250":null},"decision_ms":1789996720064,"feature_cutoff_ms":1789996720063,"request_ms":1789996720036,"inventory":{"pair_fast":{"qty":[5.0,0.0],"cash":0.68959,"lots":[[[5.0,0.137918]],[]],"floor":-0.68959},"pair_250":{"qty":[5.0,0.0],"cash":0.68959,"lots":[[[5.0,0.137918]],[]],"floor":-0.68959},"pair_add_fast":{"qty":[5.0,0.0],"cash":0.68959,"lots":[[[5.0,0.137918]],[]],"floor":-0.68959},"pair_add_250":{"qty":[5.0,0.0],"cash":0.68959,"lots":[[[5.0,0.137918]],[]],"floor":-0.68959}}}
{"kind":"decision","recorded_ms":1789996730078,"S":1789996500,"age":230,"signal":{},"entry_side":null,"context_gap":"incomplete or stale context","book_errors":[null,null],"books":[{"bid":0.02,"ask":0.03,"asks":[[0.03,633.82]],"received_ms":1789996730067,"observed_ms":1789996730053,"hash":"a2ff5b558da70827cec528ab6229a4f19697f895"},{"bid":0.97,"ask":0.98,"asks":[[0.98,520.65]],"received_ms":1789996730076,"observed_ms":1789996730064,"hash":"2a0a048de90365afcac8c92e946bdc7ef82fe2f4"}],"intents":{"pair_fast":null,"pair_250":null,"pair_add_fast":null,"pair_add_250":null},"decision_ms":1789996730078,"feature_cutoff_ms":1789996730077,"request_ms":1789996730036,"inventory":{"pair_fast":{"qty":[5.0,0.0],"cash":0.68959,"lots":[[[5.0,0.137918]],[]],"floor":-0.68959},"pair_250":{"qty":[5.0,0.0],"cash":0.68959,"lots":[[[5.0,0.137918]],[]],"floor":-0.68959},"pair_add_fast":{"qty":[5.0,0.0],"cash":0.68959,"lots":[[[5.0,0.137918]],[]],"floor":-0.68959},"pair_add_250":{"qty":[5.0,0.0],"cash":0.68959,"lots":[[[5.0,0.137918]],[]],"floor":-0.68959}}}
{"kind":"decision","recorded_ms":1789996740303,"S":1789996500,"age":240,"signal":{},"entry_side":null,"context_gap":"incomplete or stale context","book_errors":[null,null],"books":[{"bid":0.01,"ask":0.02,"asks":[[0.02,316.45]],"received_ms":1789996740302,"observed_ms":1789996740289,"hash":"81fe7759cc370b9cac87db3de77d3bf28fbb3abd"},{"bid":0.98,"ask":0.99,"asks":[[0.99,3502.64]],"received_ms":1789996740080,"observed_ms":1789996740033,"hash":"e55cbb9f35b832303fb34653ca696287a02644d6"}],"intents":{"pair_fast":null,"pair_250":null,"pair_add_fast":null,"pair_add_250":null},"decision_ms":1789996740303,"feature_cutoff_ms":1789996740302,"request_ms":1789996740050,"inventory":{"pair_fast":{"qty":[5.0,0.0],"cash":0.68959,"lots":[[[5.0,0.137918]],[]],"floor":-0.68959},"pair_250":{"qty":[5.0,0.0],"cash":0.68959,"lots":[[[5.0,0.137918]],[]],"floor":-0.68959},"pair_add_fast":{"qty":[5.0,0.0],"cash":0.68959,"lots":[[[5.0,0.137918]],[]],"floor":-0.68959},"pair_add_250":{"qty":[5.0,0.0],"cash":0.68959,"lots":[[[5.0,0.137918]],[]],"floor":-0.68959}}}
{"kind":"decision","recorded_ms":1789996750038,"S":1789996500,"age":250,"signal":{},"entry_side":null,"context_gap":"incomplete or stale context","book_errors":[null,null],"books":[{"bid":0.64,"ask":0.65,"asks":[[0.65,65.0]],"received_ms":1789996750037,"observed_ms":1789996750026,"hash":"4d7ad0a3385346549de2cae1b50f6ea067505810"},{"bid":0.34,"ask":0.36,"asks":[[0.36,169.0]],"received_ms":1789996750027,"observed_ms":1789996750020,"hash":"1ead6e9ddd6b67f3276733a29fe7e0c00baf0831"}],"intents":{"pair_fast":{"kind":"complete","side":1,"qty":5.0,"max_cost":4.21041},"pair_250":{"kind":"complete","side":1,"qty":5.0,"max_cost":4.21041},"pair_add_fast":{"kind":"complete","side":1,"qty":5.0,"max_cost":4.21041},"pair_add_250":{"kind":"complete","side":1,"qty":5.0,"max_cost":4.21041}},"decision_ms":1789996750038,"feature_cutoff_ms":1789996750037,"request_ms":1789996750000,"inventory":{"pair_fast":{"qty":[5.0,0.0],"cash":0.68959,"lots":[[[5.0,0.137918]],[]],"floor":-0.68959},"pair_250":{"qty":[5.0,0.0],"cash":0.68959,"lots":[[[5.0,0.137918]],[]],"floor":-0.68959},"pair_add_fast":{"qty":[5.0,0.0],"cash":0.68959,"lots":[[[5.0,0.137918]],[]],"floor":-0.68959},"pair_add_250":{"qty":[5.0,0.0],"cash":0.68959,"lots":[[[5.0,0.137918]],[]],"floor":-0.68959}}}
{"kind":"decision","recorded_ms":1789996830077,"S":1789996800,"age":30,"signal":{"rsi14":34.11196071117662,"volume_ratio":0.87891473725721,"taker_buy_fraction":0.4232676822662559,"volume5":107.84237,"return1":6.937833536141371,"return5":0.18081339728573226,"return15":-7.025892008847536,"bollinger_z":-0.6901348188630002,"bar_close_ms":1789996799999,"ref":85155.41144321438,"reference_received_ms":1789996801280,"spot":85099.24088164867,"twap":85151.16033751251,"sigma":5.367734052444681,"spot_z":-0.6369378020347525,"twap_z":-0.04820478639508484,"momentum":-2.0361783342458004,"decision_ms":1789996830076,"momentum30":-1.7542579890792096,"momentum60":-1.6382720633922572,"spot_twap_gap":-1.2487155407983614,"range60":1.755549386477053,"final_mean":85099.24088164867,"final_z":-0.6901216027674949,"final_up_prob":0.24505885951877937,"final_drift_up_prob":0.0,"final_known_seconds":0,"final_sd":81.39226672583396,"final_drift_shift":-829.2404827169682},"entry_side":null,"context_gap":null,"book_errors":[null,null],"books":[{"bid":0.27,"ask":0.32,"asks":[[0.32,11.78]],"received_ms":1789996830076,"observed_ms":1789996830059,"hash":"93ffdc50a79d525087bfcefc3cfdd4e15b4042ef"},{"bid":0.68,"ask":0.69,"asks":[[0.69,70.0]],"received_ms":1789996830072,"observed_ms":1789996830060,"hash":"e75ae1b3400fb925931fcf863c394d65dab7d3d3"}],"intents":{"pair_fast":null,"pair_250":null,"pair_add_fast":null,"pair_add_250":null},"decision_ms":1789996830077,"feature_cutoff_ms":1789996830076,"request_ms":1789996830034,"inventory":{"pair_fast":{"qty":[0.0,0.0],"cash":0.0,"lots":[[],[]],"floor":0.0},"pair_250":{"qty":[0.0,0.0],"cash":0.0,"lots":[[],[]],"floor":0.0},"pair_add_fast":{"qty":[0.0,0.0],"cash":0.0,"lots":[[],[]],"floor":0.0},"pair_add_250":{"qty":[0.0,0.0],"cash":0.0,"lots":[[],[]],"floor":0.0}}}
