{"kind":"decision","recorded_ms":1790001930040,"S":1790001900,"age":30,"signal":{"rsi14":57.7824248338675,"volume_ratio":0.5049609059600261,"taker_buy_fraction":0.3666027124670487,"volume5":162.17856,"return1":4.910313640019657,"return5":-3.1177519551509927,"return15":8.890546509865946,"bollinger_z":-0.10576275781640997,"bar_close_ms":1790001899999,"ref":85745.48246540247,"reference_received_ms":1790001901161,"spot":85720.28358565268,"twap":85757.18810214988,"sigma":5.204228887798491,"spot_z":-0.2946960609668957,"twap_z":0.13689517450080227,"momentum":-0.3151025607525388,"decision_ms":1790001930039,"momentum30":-1.8025661095962282,"momentum60":-1.2972968862286836,"spot_twap_gap":-0.9154771428841744,"range60":1.3222642545274348,"final_mean":85720.28358565268,"final_z":-0.3192991414333644,"final_up_prob":0.37474984183735893,"final_drift_up_prob":0.028976134523946373,"final_known_seconds":0,"final_sd":78.91934703197279,"final_drift_shift":-124.43684308975538},"entry_side":null,"context_gap":null,"book_errors":[null,null],"books":[{"bid":0.54,"ask":0.55,"asks":[[0.55,268.08]],"received_ms":1790001930032,"observed_ms":1790001930023,"hash":"8c3ef438557f80851f4b039768af0359c260c235"},{"bid":0.45,"ask":0.46,"asks":[[0.46,793.81]],"received_ms":1790001930039,"observed_ms":1790001930029,"hash":"497a7aa1b3f6b999016c8cb8942275978c5dc548"}],"intents":{"pair_fast":{"kind":"first","side":1,"qty":5.0,"participation":true,"max_cost":2.43694},"pair_250":{"kind":"first","side":1,"qty":5.0,"participation":true,"max_cost":2.43694},"pair_add_fast":{"kind":"first","side":1,"qty":5.0,"participation":true,"max_cost":2.43694},"pair_add_250":{"kind":"first","side":1,"qty":5.0,"participation":true,"max_cost":2.43694}},"decision_ms":1790001930040,"feature_cutoff_ms":1790001930039,"request_ms":1790001930004,"inventory":{"pair_fast":{"qty":[0.0,0.0],"cash":0.0,"lots":[[],[]],"floor":0.0},"pair_250":{"qty":[0.0,0.0],"cash":0.0,"lots":[[],[]],"floor":0.0},"pair_add_fast":{"qty":[0.0,0.0],"cash":0.0,"lots":[[],[]],"floor":0.0},"pair_add_250":{"qty":[0.0,0.0],"cash":0.0,"lots":[[],[]],"floor":0.0}}}
{"kind":"decision","recorded_ms":1790002120062,"S":1790001900,"age":220,"signal":{"rsi14":48.40031536222885,"volume_ratio":0.5805894491913767,"taker_buy_fraction":0.4086967208586037,"volume5":120.18024,"return1":16.715683119255253,"return5":11.715294937352414,"return15":13.366959469502172,"bollinger_z":0.807819192593616,"bar_close_ms":1790002079999,"ref":85745.48246540247,"reference_received_ms":1790001901161,"spot":85909.64908633941,"twap":85899.55485608746,"sigma":4.242311190248218,"spot_z":4.328156753636494,"twap_z":4.0620282886147345,"momentum":-1.1996293789133747,"decision_ms":1790002120061,"momentum30":0.8462540766182006,"momentum60":0.6978309935665441,"spot_twap_gap":0.3071815016656413,"range60":1.5418705665998176,"final_mean":85909.64908633941,"final_z":6.12327471099842,"final_up_prob":0.9999999995416429,"final_drift_up_prob":0.9991127064633112,"final_known_seconds":0,"final_sd":26.81026553358331,"final_drift_shift":-80.36916501490086},"entry_side":null,"context_gap":null,"book_errors":[null,null],"books":[{"bid":0.99,"ask":null,"asks":[],"received_ms":1790002120058,"observed_ms":1790002120041,"hash":"77d4345ee1ff2ca3053c3c39c69512659be6c2df"},{"bid":null,"ask":0.01,"asks":[[0.01,2813.33]],"received_ms":1790002120060,"observed_ms":1790002120041,"hash":"acbaf6a8a9fcd6997b5381917353bdd2c215073b"}],"intents":{"pair_fast":null,"pair_250":null,"pair_add_fast":null,"pair_add_250":null},"decision_ms":1790002120062,"feature_cutoff_ms":1790002120061,"request_ms":1790002120033,"inventory":{"pair_fast":{"qty":[5.0,5.0],"cash":4.470940000000001,"lots":[[],[]],"floor":0.5290599999999994},"pair_250":{"qty":[5.0,5.0],"cash":4.470940000000001,"lots":[[],[]],"floor":0.5290599999999994},"pair_add_fast":{"qty":[5.0,5.0],"cash":4.470940000000001,"lots":[[],[]],"floor":0.5290599999999994},"pair_add_250":{"qty":[5.0,5.0],"cash":4.470940000000001,"lots":[[],[]],"floor":0.5290599999999994}}}
{"kind":"decision","recorded_ms":1790002130070,"S":1790001900,"age":230,"signal":{"rsi14":48.40031536222885,"volume_ratio":0.5805894491913767,"taker_buy_fraction":0.4086967208586037,"volume5":120.18024,"return1":16.715683119255253,"return5":11.715294937352414,"return15":13.366959469502172,"bollinger_z":0.807819192593616,"bar_close_ms":1790002079999,"ref":85745.48246540247,"reference_received_ms":1790001901161,"spot":85912.07312488,"twap":85904.28577220459,"sigma":3.889801382904332,"spot_z":5.121395926979246,"twap_z":4.881994051754751,"momentum":-0.42277459959720165,"decision_ms":1790002130069,"momentum30":-0.5660597131228505,"momentum60":1.101744017332715,"spot_twap_gap":0.2584561031442266,"range60":1.68160122194127,"final_mean":85912.07312488,"final_z":7.828212524587591,"final_up_prob":0.9999999999999976,"final_drift_up_prob":0.9999999999963693,"final_known_seconds":0,"final_sd":21.280804392354703,"final_drift_shift":-20.765696373911904},"entry_side":null,"context_gap":null,"book_errors":[null,null],"books":[{"bid":0.99,"ask":null,"asks":[],"received_ms":1790002130069,"observed_ms":1790002130048,"hash":"9ac28c13b42877fc426cb1aad5f8506b50c19c85"},{"bid":null,"ask":0.01,"asks":[[0.01,4056.98]],"received_ms":1790002130061,"observed_ms":1790002130047,"hash":"c9944933c16ab876f4a4b1495a6f6a08ed048fb5"}],"intents":{"pair_fast":null,"pair_250":null,"pair_add_fast":null,"pair_add_250":null},"decision_ms":1790002130070,"feature_cutoff_ms":1790002130069,"request_ms":1790002130035,"inventory":{"pair_fast":{"qty":[5.0,5.0],"cash":4.470940000000001,"lots":[[],[]],"floor":0.5290599999999994},"pair_250":{"qty":[5.0,5.0],"cash":4.470940000000001,"lots":[[],[]],"floor":0.5290599999999994},"pair_add_fast":{"qty":[5.0,5.0],"cash":4.470940000000001,"lots":[[],[]],"floor":0.5290599999999994},"pair_add_250":{"qty":[5.0,5.0],"cash":4.470940000000001,"lots":[[],[]],"floor":0.5290599999999994}}}
{"kind":"decision","recorded_ms":1790002140095,"S":1790001900,"age":240,"signal":{"rsi14":48.40031536222885,"volume_ratio":0.5805894491913767,"taker_buy_fraction":0.4086967208586037,"volume5":120.18024,"return1":16.715683119255253,"return5":11.715294937352414,"return15":13.366959469502172,"bollinger_z":0.807819192593616,"bar_close_ms":1790002079999,"ref":85745.48246540247,"reference_received_ms":1790001901161,"spot":85894.24542059563,"twap":85908.93105555147,"sigma":4.037216814900169,"spot_z":4.760773972656475,"twap_z":5.230749771261041,"momentum":-0.994723176173516,"decision_ms":1790002140094,"momentum30":-1.4243880482190128,"momentum60":0.29221918829233506,"spot_twap_gap":-0.46960750619518893,"range60":1.4841947850286057,"final_mean":85894.24542059563,"final_z":8.258841269229029,"final_up_prob":1.0,"final_drift_up_prob":0.999999999613484,"final_known_seconds":0,"final_sd":18.01256984408027,"final_drift_shift":-37.979015874716026},"entry_side":null,"context_gap":null,"book_errors":[null,null],"books":[{"bid":0.99,"ask":null,"asks":[],"received_ms":1790002140086,"observed_ms":1790002140074,"hash":"6f6fb27b723f3b1d28b0ac5a622198def63b9f82"},{"bid":null,"ask":0.01,"asks":[[0.01,4290.84]],"received_ms":1790002140094,"observed_ms":1790002140076,"hash":"e11337f809b71de95a34846beb65de78356ff52d"}],"intents":{"pair_fast":null,"pair_250":null,"pair_add_fast":null,"pair_add_250":null},"decision_ms":1790002140095,"feature_cutoff_ms":1790002140094,"request_ms":1790002140045,"inventory":{"pair_fast":{"qty":[5.0,5.0],"cash":4.470940000000001,"lots":[[],[]],"floor":0.5290599999999994},"pair_250":{"qty":[5.0,5.0],"cash":4.470940000000001,"lots":[[],[]],"floor":0.5290599999999994},"pair_add_fast":{"qty":[5.0,5.0],"cash":4.470940000000001,"lots":[[],[]],"floor":0.5290599999999994},"pair_add_250":{"qty":[5.0,5.0],"cash":4.470940000000001,"lots":[[],[]],"floor":0.5290599999999994}}}
{"kind":"decision","recorded_ms":1790002150076,"S":1790001900,"age":250,"signal":{"rsi14":45.56462280469669,"volume_ratio":0.6285926102665962,"taker_buy_fraction":0.47043333932698483,"volume5":119.07043,"return1":-0.5645542791591495,"return5":17.647850363549743,"return15":-4.390719053579014,"bollinger_z":0.6863133068287834,"bar_close_ms":1790002139999,"ref":85745.48246540247,"reference_received_ms":1790001901161,"spot":85871.03876777839,"twap":85908.6503997803,"sigma":5.444415927436273,"spot_z":3.263834921698955,"twap_z":4.241548948529507,"momentum":-0.9940575940925094,"decision_ms":1790002150075,"momentum30":-1.5504458685197275,"momentum60":-0.44926869358569044,"spot_twap_gap":-0.8918570654689111,"range60":1.5948800851859637,"final_mean":85871.4161346729,"final_z":6.8143640192511645,"final_up_prob":0.9999999999952659,"final_drift_up_prob":0.9999994979265101,"final_known_seconds":10,"final_sd":18.480619602159535,"final_drift_shift":-35.54821052369834},"entry_side":null,"context_gap":null,"book_errors":[null,null],"books":[{"bid":0.99,"ask":null,"asks":[],"received_ms":1790002150075,"observed_ms":1790002150056,"hash":"10e44c5fc2faf4f09680c182f53f9f0a5c377097"},{"bid":null,"ask":0.01,"asks":[[0.01,22805.51]],"received_ms":1790002150073,"observed_ms":1790002150056,"hash":"e618c558f179f1ce5daf8ba788e759acd260493b"}],"intents":{"pair_fast":null,"pair_250":null,"pair_add_fast":null,"pair_add_250":null},"decision_ms":1790002150076,"feature_cutoff_ms":1790002150075,"request_ms":1790002150047,"inventory":{"pair_fast":{"qty":[5.0,5.0],"cash":4.470940000000001,"lots":[[],[]],"floor":0.5290599999999994},"pair_250":{"qty":[5.0,5.0],"cash":4.470940000000001,"lots":[[],[]],"floor":0.5290599999999994},"pair_add_fast":{"qty":[5.0,5.0],"cash":4.470940000000001,"lots":[[],[]],"floor":0.5290599999999994},"pair_add_250":{"qty":[5.0,5.0],"cash":4.470940000000001,"lots":[[],[]],"floor":0.5290599999999994}}}
{"kind":"decision","recorded_ms":1790002160088,"S":1790001900,"age":260,"signal":{"rsi14":45.56462280469669,"volume_ratio":0.6285926102665962,"taker_buy_fraction":0.47043333932698483,"volume5":119.07043,"return1":-0.5645542791591495,"return5":17.647850363549743,"return15":-4.390719053579014,"bollinger_z":0.6863133068287834,"bar_close_ms":1790002139999,"ref":85745.48246540247,"reference_received_ms":1790001901161,"spot":85902.3791255,"twap":85903.86638686921,"sigma":5.37994463961615,"spot_z":4.616137168214854,"twap_z":4.659894648335896,"momentum":1.947743189711715,"decision_ms":1790002160087,"momentum30":-0.1549428541541446,"momentum60":-0.5220202365119961,"spot_twap_gap":-0.03568895778842966,"range60":1.6139925444951997,"final_mean":85893.96358076452,"final_z":11.374537120243312,"final_up_prob":1.0,"final_drift_up_prob":1.0,"final_known_seconds":20,"final_sd":13.053816062352242,"final_drift_shift":43.990307898706625},"entry_side":null,"context_gap":null,"book_errors":[null,null],"books":[{"bid":0.99,"ask":null,"asks":[],"received_ms":1790002160087,"observed_ms":1790002160075,"hash":"d4efd5c8041322d3bcd1bf11f5cf3e7b7eaba69e"},{"bid":null,"ask":0.01,"asks":[[0.01,40218.84]],"received_ms":1790002160083,"observed_ms":1790002160062,"hash":"e896baa7ae389a686aec51d7de3d3c9d861bf120"}],"intents":{"pair_fast":null,"pair_250":null,"pair_add_fast":null,"pair_add_250":null},"decision_ms":1790002160088,"feature_cutoff_ms":1790002160087,"request_ms":1790002160050,"inventory":{"pair_fast":{"qty":[5.0,5.0],"cash":4.470940000000001,"lots":[[],[]],"floor":0.5290599999999994},"pair_250":{"qty":[5.0,5.0],"cash":4.470940000000001,"lots":[[],[]],"floor":0.5290599999999994},"pair_add_fast":{"qty":[5.0,5.0],"cash":4.470940000000001,"lots":[[],[]],"floor":0.5290599999999994},"pair_add_250":{"qty":[5.0,5.0],"cash":4.470940000000001,"lots":[[],[]],"floor":0.5290599999999994}}}
{"kind":"decision","recorded_ms":1790002170044,"S":1790001900,"age":270,"signal":{"rsi14":45.56462280469669,"volume_ratio":0.6285926102665962,"taker_buy_fraction":0.47043333932698483,"volume5":119.07043,"return1":-0.5645542791591495,"return5":17.647850363549743,"return15":-4.390719053579014,"bollinger_z":0.6863133068287834,"bar_close_ms":1790002139999,"ref":85745.48246540247,"reference_received_ms":1790001901161,"spot":85901.85020716923,"twap":85900.29761641177,"sigma":6.25149123787668,"spot_z":4.5699808222471745,"twap_z":4.524605031139397,"momentum":-0.42879705148614483,"decision_ms":1790002170043,"momentum30":0.40001934534178435,"momentum60":-0.49340045737593285,"spot_twap_gap":0.03206252672800524,"range60":1.31046761558741,"final_mean":85893.61775587776,"final_z":15.018940779870684,"final_up_prob":1.0,"final_drift_up_prob":1.0,"final_known_seconds":30,"final_sd":9.863231545184986,"final_drift_shift":-6.339438754577259},"entry_side":null,"context_gap":null,"book_errors":[null,null],"books":[{"bid":0.99,"ask":null,"asks":[],"received_ms":1790002170043,"observed_ms":1790002170029,"hash":"a968333eca8bbd624091529c54999887ac13d02e"},{"bid":null,"ask":0.01,"asks":[[0.01,46312.72]],"received_ms":1790002170040,"observed_ms":1790002170013,"hash":"963e659af84a708b77cfbd50b851f2dd2691b218"}],"intents":{"pair_fast":null,"pair_250":null,"pair_add_fast":null,"pair_add_250":null},"decision_ms":1790002170044,"feature_cutoff_ms":1790002170043,"request_ms":1790002170011,"inventory":{"pair_fast":{"qty":[5.0,5.0],"cash":4.470940000000001,"lots":[[],[]],"floor":0.5290599999999994},"pair_250":{"qty":[5.0,5.0],"cash":4.470940000000001,"lots":[[],[]],"floor":0.5290599999999994},"pair_add_fast":{"qty":[5.0,5.0],"cash":4.470940000000001,"lots":[[],[]],"floor":0.5290599999999994},"pair_add_250":{"qty":[5.0,5.0],"cash":4.470940000000001,"lots":[[],[]],"floor":0.5290599999999994}}}
{"kind":"decision","recorded_ms":1790002180051,"S":1790001900,"age":280,"signal":{},"entry_side":null,"context_gap":"incomplete or stale context","book_errors":[null,null],"books":[{"bid":0.99,"ask":null,"asks":[],"received_ms":1790002180050,"observed_ms":1790002180032,"hash":"97e01aa4cfe0783b510587f54421648a1bd6c8f0"},{"bid":null,"ask":0.01,"asks":[[0.01,59313.77]],"received_ms":1790002180044,"observed_ms":1790002180026,"hash":"ed87e64a9377b6d4ee0a0d57e3230ee29418ecac"}],"intents":{"pair_fast":null,"pair_250":null,"pair_add_fast":null,"pair_add_250":null},"decision_ms":1790002180051,"feature_cutoff_ms":1790002180050,"request_ms":1790002180018,"inventory":{"pair_fast":{"qty":[5.0,5.0],"cash":4.470940000000001,"lots":[[],[]],"floor":0.5290599999999994},"pair_250":{"qty":[5.0,5.0],"cash":4.470940000000001,"lots":[[],[]],"floor":0.5290599999999994},"pair_add_fast":{"qty":[5.0,5.0],"cash":4.470940000000001,"lots":[[],[]],"floor":0.5290599999999994},"pair_add_250":{"qty":[5.0,5.0],"cash":4.470940000000001,"lots":[[],[]],"floor":0.5290599999999994}}}
{"kind":"decision","recorded_ms":1790002190055,"S":1790001900,"age":290,"signal":{"rsi14":45.56462280469669,"volume_ratio":0.6285926102665962,"taker_buy_fraction":0.47043333932698483,"volume5":119.07043,"return1":-0.5645542791591495,"return5":17.647850363549743,"return15":-4.390719053579014,"bollinger_z":0.6863133068287834,"bar_close_ms":1790002139999,"ref":85745.48246540247,"reference_received_ms":1790001901161,"spot":85948.16781786269,"twap":85900.96975083636,"sigma":7.2200694557816565,"spot_z":8.901368071127518,"twap_z":6.828562307180855,"momentum":0.3505032536438784,"decision_ms":1790002190054,"momentum30":0.9568803794290367,"momentum60":0.7370928929169964,"spot_twap_gap":0.843931528570799,"range60":1.5356453392332619,"final_mean":85910.87547529669,"final_z":75.89531437137175,"final_up_prob":1.0,"final_drift_up_prob":1.0,"final_known_seconds":50,"final_sd":2.1792255722786664,"final_drift_shift":0.6597039760831468},"entry_side":null,"context_gap":null,"book_errors":[null,null],"books":[{"bid":0.99,"ask":null,"asks":[],"received_ms":1790002190053,"observed_ms":1790002190044,"hash":"7555513f419895d33c6aa4a9dd6384d69c2db317"},{"bid":null,"ask":0.01,"asks":[[0.01,60330.93]],"received_ms":1790002190050,"observed_ms":1790002190031,"hash":"4480a4d2404def926d8732158f00c0ee835588e8"}],"intents":{"pair_fast":null,"pair_250":null,"pair_add_fast":null,"pair_add_250":null},"decision_ms":1790002190055,"feature_cutoff_ms":1790002190054,"request_ms":1790002190025,"inventory":{"pair_fast":{"qty":[5.0,5.0],"cash":4.470940000000001,"lots":[[],[]],"floor":0.5290599999999994},"pair_250":{"qty":[5.0,5.0],"cash":4.470940000000001,"lots":[[],[]],"floor":0.5290599999999994},"pair_add_fast":{"qty":[5.0,5.0],"cash":4.470940000000001,"lots":[[],[]],"floor":0.5290599999999994},"pair_add_250":{"qty":[5.0,5.0],"cash":4.470940000000001,"lots":[[],[]],"floor":0.5290599999999994}}}
{"kind":"decision","recorded_ms":1790002230082,"S":1790002200,"age":30,"signal":{"rsi14":51.54019899916334,"volume_ratio":0.3674793331370843,"taker_buy_fraction":0.5077153114021722,"volume5":111.37334,"return1":9.488304870552035,"return5":22.2200074962152,"return15":-0.6500750609921014,"bollinger_z":1.2878642575642623,"bar_close_ms":1790002199999,"ref":85909.0374353972,"reference_received_ms":1790002201638,"spot":86005.9845893112,"twap":85961.25334746408,"sigma":10.71191229370252,"spot_z":0.5508717777351079,"twap_z":0.2967005336934041,"momentum":-1.4391591903531449,"decision_ms":1790002230080,"momentum30":0.685193843400704,"momentum60":1.2513110116981092,"spot_twap_gap":0.5390987465762647,"range60":1.8388452908651378,"final_mean":86005.9845893112,"final_z":0.5968699031636561,"final_up_prob":0.7247028786357305,"final_drift_up_prob":2.0006107881442858e-11,"final_known_seconds":0,"final_sd":162.42593804805196,"final_drift_shift":-1169.6132954101943},"entry_side":null,"context_gap":null,"book_errors":[null,null],"books":[{"bid":0.73,"ask":0.74,"asks":[[0.74,728.52]],"received_ms":1790002230080,"observed_ms":1790002230045,"hash":"2af0ad1ee4c49445253d2f08908e2909b95ccf4f"},{"bid":0.26,"ask":0.27,"asks":[[0.27,73.0]],"received_ms":1790002230074,"observed_ms":1790002230045,"hash":"666f613f560775e099e5ffe248f3cf5b46a1cac7"}],"intents":{"pair_fast":{"kind":"first","side":1,"qty":5.0,"participation":true,"max_cost":1.46899},"pair_250":{"kind":"first","side":1,"qty":5.0,"participation":true,"max_cost":1.46899},"pair_add_fast":{"kind":"first","side":1,"qty":5.0,"participation":true,"max_cost":1.46899},"pair_add_250":{"kind":"first","side":1,"qty":5.0,"participation":true,"max_cost":1.46899}},"decision_ms":1790002230082,"feature_cutoff_ms":1790002230080,"request_ms":1790002230048,"inventory":{"pair_fast":{"qty":[0.0,0.0],"cash":0.0,"lots":[[],[]],"floor":0.0},"pair_250":{"qty":[0.0,0.0],"cash":0.0,"lots":[[],[]],"floor":0.0},"pair_add_fast":{"qty":[0.0,0.0],"cash":0.0,"lots":[[],[]],"floor":0.0},"pair_add_250":{"qty":[0.0,0.0],"cash":0.0,"lots":[[],[]],"floor":0.0}}}
{"kind":"decision","recorded_ms":1790002460036,"S":1790002200,"age":260,"signal":{"rsi14":57.28147742389862,"volume_ratio":1.4488704297767012,"taker_buy_fraction":0.5892505793063141,"volume5":299.14225999999996,"return1":-15.309342920442836,"return5":9.856588727208011,"return15":10.881087862256031,"bollinger_z":0.7599054968557811,"bar_close_ms":1790002439999,"ref":85909.0374353972,"reference_received_ms":1790002201638,"spot":86007.79196699485,"twap":86005.0895440374,"sigma":7.787144033840571,"spot_z":2.0060369010929735,"twap_z":1.9511415956594609,"momentum":0.002657455820042482,"decision_ms":1790002460035,"momentum30":1.2624906667959974,"momentum60":-0.8426388766474671,"spot_twap_gap":0.044802215305596714,"range60":1.7353545883236428,"final_mean":86004.28839769257,"final_z":5.031335957837091,"final_up_prob":0.9999997564631173,"final_drift_up_prob":0.9999997622412674,"final_known_seconds":20,"final_sd":18.931544840888137,"final_drift_shift":0.0871009009946104},"entry_side":null,"context_gap":null,"book_errors":[null,null],"books":[{"bid":0.99,"ask":null,"asks":[],"received_ms":1790002460028,"observed_ms":1790002460006,"hash":"37de00b05a745bc8f32350510aefa1b267f73ba2"},{"bid":null,"ask":0.01,"asks":[[0.01,31908.75]],"received_ms":1790002460034,"observed_ms":1790002460020,"hash":"f84dab274f34c3706cffc71839816fc4d1954c36"}],"intents":{"pair_fast":null,"pair_250":null,"pair_add_fast":null,"pair_add_250":null},"decision_ms":1790002460036,"feature_cutoff_ms":1790002460035,"request_ms":1790002460002,"inventory":{"pair_fast":{"qty":[10.0,10.0],"cash":8.87089,"lots":[[],[]],"floor":1.1291100000000007},"pair_250":{"qty":[10.0,10.0],"cash":8.967880000000001,"lots":[[],[]],"floor":1.032119999999999},"pair_add_fast":{"qty":[10.0,15.0],"cash":9.243680000000001,"lots":[[],[[5.0,0.074558]]],"floor":0.7563199999999988},"pair_add_250":{"qty":[10.0,15.0],"cash":9.340670000000001,"lots":[[],[[5.0,0.074558]]],"floor":0.6593299999999989}}}
{"kind":"decision","recorded_ms":1790002470291,"S":1790002200,"age":270,"signal":{"rsi14":57.28147742389862,"volume_ratio":1.4488704297767012,"taker_buy_fraction":0.5892505793063141,"volume5":299.14225999999996,"return1":-15.309342920442836,"return5":9.856588727208011,"return15":10.881087862256031,"bollinger_z":0.7599054968557811,"bar_close_ms":1790002439999,"ref":85909.0374353972,"reference_received_ms":1790002201638,"spot":86047.14483545089,"twap":85996.89524299334,"sigma":8.715054965771,"spot_z":2.9073377862469787,"twap_z":1.849519459071547,"momentum":1.3600440279430843,"decision_ms":1790002470290,"momentum30":1.6391265124831227,"momentum60":-0.013693223175576141,"spot_twap_gap":0.744366445980217,"range60":1.3943086463955454,"final_mean":86026.6277716646,"final_z":8.65883374413066,"final_up_prob":1.0,"final_drift_up_prob":1.0,"final_known_seconds":30,"final_sd":13.580389662419346,"final_drift_shift":27.570659644853443},"entry_side":null,"context_gap":null,"book_errors":[null,null],"books":[{"bid":0.99,"ask":null,"asks":[],"received_ms":1790002470290,"observed_ms":1790002470052,"hash":"f056cae7e47fb5b4d4d07240056e937a5410aca3"},{"bid":null,"ask":0.01,"asks":[[0.01,41467.0]],"received_ms":1790002470042,"observed_ms":1790002470034,"hash":"26a690575d3ce98ae2a8f3056b94105d343ce9f5"}],"intents":{"pair_fast":null,"pair_250":null,"pair_add_fast":null,"pair_add_250":null},"decision_ms":1790002470291,"feature_cutoff_ms":1790002470290,"request_ms":1790002470010,"inventory":{"pair_fast":{"qty":[10.0,10.0],"cash":8.87089,"lots":[[],[]],"floor":1.1291100000000007},"pair_250":{"qty":[10.0,10.0],"cash":8.967880000000001,"lots":[[],[]],"floor":1.032119999999999},"pair_add_fast":{"qty":[10.0,15.0],"cash":9.243680000000001,"lots":[[],[[5.0,0.074558]]],"floor":0.7563199999999988},"pair_add_250":{"qty":[10.0,15.0],"cash":9.340670000000001,"lots":[[],[[5.0,0.074558]]],"floor":0.6593299999999989}}}
{"kind":"decision","recorded_ms":1790002480084,"S":1790002200,"age":280,"signal":{},"entry_side":null,"context_gap":"incomplete or stale context","book_errors":[null,null],"books":[{"bid":0.99,"ask":null,"asks":[],"received_ms":1790002480083,"observed_ms":1790002480073,"hash":"8cd8d6002861c28d3795a10a3254b423cbf90d9c"},{"bid":null,"ask":0.01,"asks":[[0.01,58424.52]],"received_ms":1790002480043,"observed_ms":1790002480018,"hash":"acf0fda32b6ef13e0f62da341badb27ec6ce0ca0"}],"intents":{"pair_fast":null,"pair_250":null,"pair_add_fast":null,"pair_add_250":null},"decision_ms":1790002480084,"feature_cutoff_ms":1790002480083,"request_ms":1790002480015,"inventory":{"pair_fast":{"qty":[10.0,10.0],"cash":8.87089,"lots":[[],[]],"floor":1.1291100000000007},"pair_250":{"qty":[10.0,10.0],"cash":8.967880000000001,"lots":[[],[]],"floor":1.032119999999999},"pair_add_fast":{"qty":[10.0,15.0],"cash":9.243680000000001,"lots":[[],[[5.0,0.074558]]],"floor":0.7563199999999988},"pair_add_250":{"qty":[10.0,15.0],"cash":9.340670000000001,"lots":[[],[[5.0,0.074558]]],"floor":0.6593299999999989}}}
{"kind":"decision","recorded_ms":1790002490043,"S":1790002200,"age":290,"signal":{"rsi14":57.28147742389862,"volume_ratio":1.4488704297767012,"taker_buy_fraction":0.5892505793063141,"volume5":299.14225999999996,"return1":-15.309342920442836,"return5":9.856588727208011,"return15":10.881087862256031,"bollinger_z":0.7599054968557811,"bar_close_ms":1790002439999,"ref":85909.0374353972,"reference_received_ms":1790002201638,"spot":86055.82681109,"twap":86005.52300884921,"sigma":11.338935367159094,"spot_z":4.102383755898017,"twap_z":2.696522465198124,"momentum":1.412364221347449,"decision_ms":1790002490042,"momentum30":0.7433110237454245,"momentum60":1.159983464890588,"spot_twap_gap":0.5727339237795533,"range60":1.236116986788043,"final_mean":86026.8901045949,"final_z":34.373269395760296,"final_up_prob":1.0,"final_drift_up_prob":1.0,"final_known_seconds":50,"final_sd":3.42861389880587,"final_drift_shift":4.184870082768943},"entry_side":null,"context_gap":null,"book_errors":[null,null],"books":[{"bid":0.99,"ask":null,"asks":[],"received_ms":1790002490042,"observed_ms":1790002490027,"hash":"494bfdb5208a3241c4480ce4d9602afad3fb2a8f"},{"bid":null,"ask":0.01,"asks":[[0.01,60099.15]],"received_ms":1790002490040,"observed_ms":1790002490027,"hash":"06fc2ae3aeef8238a5e2b008ec6a594f7723a660"}],"intents":{"pair_fast":null,"pair_250":null,"pair_add_fast":null,"pair_add_250":null},"decision_ms":1790002490043,"feature_cutoff_ms":1790002490042,"request_ms":1790002490009,"inventory":{"pair_fast":{"qty":[10.0,10.0],"cash":8.87089,"lots":[[],[]],"floor":1.1291100000000007},"pair_250":{"qty":[10.0,10.0],"cash":8.967880000000001,"lots":[[],[]],"floor":1.032119999999999},"pair_add_fast":{"qty":[10.0,15.0],"cash":9.243680000000001,"lots":[[],[[5.0,0.074558]]],"floor":0.7563199999999988},"pair_add_250":{"qty":[10.0,15.0],"cash":9.340670000000001,"lots":[[],[[5.0,0.074558]]],"floor":0.6593299999999989}}}
{"kind":"decision","recorded_ms":1790002530093,"S":1790002500,"age":30,"signal":{"rsi14":68.76111385239841,"volume_ratio":0.5271016272211978,"taker_buy_fraction":0.5731735208866561,"volume5":306.97901,"return1":9.267713537610632,"return5":9.636005526004933,"return15":28.726775094770684,"bollinger_z":1.350461258026546,"bar_close_ms":1790002499999,"ref":86023.57876290652,"reference_received_ms":1790002501487,"spot":86000.77515341374,"twap":86032.60560809055,"sigma":10.861760603660702,"spot_z":-0.12778959391342365,"twap_z":0.0505857145445673,"momentum":-0.0682135516834623,"decision_ms":1790002530092,"momentum30":-0.8741890252106964,"momentum60":-0.7338047504710036,"spot_twap_gap":-0.37832669847889316,"range60":0.7447422904579355,"final_mean":86000.77515341374,"final_z":-0.13846063750571147,"final_up_prob":0.4449381883207755,"final_drift_up_prob":0.31569822613512477,"final_known_seconds":0,"final_sd":164.69380687229946,"final_drift_shift":-56.21026327172262},"entry_side":null,"context_gap":null,"book_errors":[null,null],"books":[{"bid":0.44,"ask":0.45,"asks":[[0.45,700.94]],"received_ms":1790002530077,"observed_ms":1790002530067,"hash":"2a61138fe654ca6620c3ba1af71d67a9a41eabc0"},{"bid":0.55,"ask":0.56,"asks":[[0.56,339.92]],"received_ms":1790002530092,"observed_ms":1790002530081,"hash":"b62aabd3696206b88dd896aa8e84a967f1e15c74"}],"intents":{"pair_fast":{"kind":"first","side":0,"qty":5.0,"participation":true,"max_cost":2.38663},"pair_250":{"kind":"first","side":0,"qty":5.0,"participation":true,"max_cost":2.38663},"pair_add_fast":{"kind":"first","side":0,"qty":5.0,"participation":true,"max_cost":2.38663},"pair_add_250":{"kind":"first","side":0,"qty":5.0,"participation":true,"max_cost":2.38663}},"decision_ms":1790002530093,"feature_cutoff_ms":1790002530092,"request_ms":1790002530048,"inventory":{"pair_fast":{"qty":[0.0,0.0],"cash":0.0,"lots":[[],[]],"floor":0.0},"pair_250":{"qty":[0.0,0.0],"cash":0.0,"lots":[[],[]],"floor":0.0},"pair_add_fast":{"qty":[0.0,0.0],"cash":0.0,"lots":[[],[]],"floor":0.0},"pair_add_250":{"qty":[0.0,0.0],"cash":0.0,"lots":[[],[]],"floor":0.0}}}
{"kind":"decision","recorded_ms":1790002540075,"S":1790002500,"age":40,"signal":{"rsi14":68.76111385239841,"volume_ratio":0.5271016272211978,"taker_buy_fraction":0.5731735208866561,"volume5":306.97901,"return1":9.267713537610632,"return5":9.636005526004933,"return15":28.726775094770684,"bollinger_z":1.350461258026546,"bar_close_ms":1790002499999,"ref":86023.57876290652,"reference_received_ms":1790002501487,"spot":86022.36002705092,"twap":86025.33385218118,"sigma":8.549243269246807,"spot_z":-0.008842133169284581,"twap_z":0.012733467239282368,"momentum":0.7255412317809069,"decision_ms":1790002540074,"momentum30":0.40657023024452227,"momentum60":0.259371886986534,"spot_twap_gap":-0.044906801850990524,"range60":0.8573014765463155,"final_mean":86022.36002705092,"final_z":-0.009612660971334107,"final_up_prob":0.4961651621700415,"final_drift_up_prob":0.9998056334104677,"final_known_seconds":0,"final_sd":126.7844418138739,"final_drift_shift":451.0013660827161},"entry_side":null,"context_gap":null,"book_errors":[null,null],"books":[{"bid":0.48,"ask":0.49,"asks":[[0.49,1286.52]],"received_ms":1790002540073,"observed_ms":1790002540063,"hash":"bf5b1166737be459560e6678aa98f165ccd19f85"},{"bid":0.51,"ask":0.52,"asks":[[0.52,42.25]],"received_ms":1790002540074,"observed_ms":1790002540067,"hash":"478f8d2d5b103ad49ae5696a994d49daff9fa250"}],"intents":{"pair_fast":null,"pair_250":null,"pair_add_fast":null,"pair_add_250":null},"decision_ms":1790002540075,"feature_cutoff_ms":1790002540074,"request_ms":1790002540047,"inventory":{"pair_fast":{"qty":[5.0,0.0],"cash":2.33663,"lots":[[[5.0,0.467326]],[]],"floor":-2.33663},"pair_250":{"qty":[5.0,0.0],"cash":2.33663,"lots":[[[5.0,0.467326]],[]],"floor":-2.33663},"pair_add_fast":{"qty":[5.0,0.0],"cash":2.33663,"lots":[[[5.0,0.467326]],[]],"floor":-2.33663},"pair_add_250":{"qty":[5.0,0.0],"cash":2.33663,"lots":[[[5.0,0.467326]],[]],"floor":-2.33663}}}
{"kind":"decision","recorded_ms":1790002550039,"S":1790002500,"age":50,"signal":{"rsi14":68.76111385239841,"volume_ratio":0.5271016272211978,"taker_buy_fraction":0.5731735208866561,"volume5":306.97901,"return1":9.267713537610632,"return5":9.636005526004933,"return15":28.726775094770684,"bollinger_z":1.350461258026546,"bar_close_ms":1790002499999,"ref":86023.57876290652,"reference_received_ms":1790002501487,"spot":86013.25388058578,"twap":86023.17397462843,"sigma":7.872631234821773,"spot_z":-0.08295209087752764,"twap_z":-0.0032521468997836907,"momentum":-0.3546929367771356,"decision_ms":1790002550037,"momentum30":0.23505781732807243,"momentum60":-0.7112591736472021,"spot_twap_gap":-0.16267479014329342,"range60":0.9762934917044146,"final_mean":86013.25388058578,"final_z":-0.0905094272575127,"final_up_prob":0.46394120141718986,"final_drift_up_prob":0.03647202348839429,"final_known_seconds":0,"final_sd":114.07521441234785,"final_drift_shift":-194.23258202762685},"entry_side":null,"context_gap":null,"book_errors":[null,null],"books":[{"bid":0.49,"ask":0.5,"asks":[[0.5,1020.91]],"received_ms":1790002550027,"observed_ms":1790002550018,"hash":"2b03e2ff45c84431266ee3fefd4e4285dbbd6836"},{"bid":0.5,"ask":0.51,"asks":[[0.51,108.0]],"received_ms":1790002550037,"observed_ms":1790002550025,"hash":"3aefd9f09ae31e0fe3df9d2d332ab20927e1c819"}],"intents":{"pair_fast":null,"pair_250":null,"pair_add_fast":null,"pair_add_250":null},"decision_ms":1790002550039,"feature_cutoff_ms":1790002550037,"request_ms":1790002550001,"inventory":{"pair_fast":{"qty":[5.0,0.0],"cash":2.33663,"lots":[[[5.0,0.467326]],[]],"floor":-2.33663},"pair_250":{"qty":[5.0,0.0],"cash":2.33663,"lots":[[[5.0,0.467326]],[]],"floor":-2.33663},"pair_add_fast":{"qty":[5.0,0.0],"cash":2.33663,"lots":[[[5.0,0.467326]],[]],"floor":-2.33663},"pair_add_250":{"qty":[5.0,0.0],"cash":2.33663,"lots":[[[5.0,0.467326]],[]],"floor":-2.33663}}}
{"kind":"decision","recorded_ms":1790002560048,"S":1790002500,"age":60,"signal":{},"entry_side":null,"context_gap":"incomplete or stale context","book_errors":[null,null],"books":[{"bid":0.46,"ask":0.47,"asks":[[0.47,85.0]],"received_ms":1790002560046,"observed_ms":1790002560038,"hash":"522b947dcb3bbc5cc18f53356935ef2e177db2bd"},{"bid":0.53,"ask":0.54,"asks":[[0.54,1227.99]],"received_ms":1790002560037,"observed_ms":1790002560029,"hash":"28d79a22a3fdfc0aec7fdc4069597c24e4d455eb"}],"intents":{"pair_fast":null,"pair_250":null,"pair_add_fast":null,"pair_add_250":null},"decision_ms":1790002560048,"feature_cutoff_ms":1790002560046,"request_ms":1790002560011,"inventory":{"pair_fast":{"qty":[5.0,0.0],"cash":2.33663,"lots":[[[5.0,0.467326]],[]],"floor":-2.33663},"pair_250":{"qty":[5.0,0.0],"cash":2.33663,"lots":[[[5.0,0.467326]],[]],"floor":-2.33663},"pair_add_fast":{"qty":[5.0,0.0],"cash":2.33663,"lots":[[[5.0,0.467326]],[]],"floor":-2.33663},"pair_add_250":{"qty":[5.0,0.0],"cash":2.33663,"lots":[[[5.0,0.467326]],[]],"floor":-2.33663}}}
{"kind":"decision","recorded_ms":1790002570082,"S":1790002500,"age":70,"signal":{},"entry_side":null,"context_gap":"incomplete or stale context","book_errors":[null,null],"books":[{"bid":0.37,"ask":0.38,"asks":[[0.38,100.0]],"received_ms":1790002570081,"observed_ms":1790002570065,"hash":"7d70251d6de45fce5d5bb2ddfa2ab4594b729ba8"},{"bid":0.62,"ask":0.63,"asks":[[0.63,1071.28]],"received_ms":1790002570074,"observed_ms":1790002570065,"hash":"7504125d847ee13dbe6d82033e54672b5fe52492"}],"intents":{"pair_fast":null,"pair_250":null,"pair_add_fast":null,"pair_add_250":null},"decision_ms":1790002570082,"feature_cutoff_ms":1790002570081,"request_ms":1790002570045,"inventory":{"pair_fast":{"qty":[5.0,0.0],"cash":2.33663,"lots":[[[5.0,0.467326]],[]],"floor":-2.33663},"pair_250":{"qty":[5.0,0.0],"cash":2.33663,"lots":[[[5.0,0.467326]],[]],"floor":-2.33663},"pair_add_fast":{"qty":[5.0,0.0],"cash":2.33663,"lots":[[[5.0,0.467326]],[]],"floor":-2.33663},"pair_add_250":{"qty":[5.0,0.0],"cash":2.33663,"lots":[[[5.0,0.467326]],[]],"floor":-2.33663}}}
{"kind":"decision","recorded_ms":1790002580078,"S":1790002500,"age":80,"signal":{},"entry_side":null,"context_gap":"incomplete or stale context","book_errors":[null,null],"books":[{"bid":0.23,"ask":0.24,"asks":[[0.24,882.64]],"received_ms":1790002580041,"observed_ms":1790002580034,"hash":"68ebb0659829a3d9d5979136a928608e17bd384b"},{"bid":0.76,"ask":0.77,"asks":[[0.77,1091.71]],"received_ms":1790002580077,"observed_ms":1790002580063,"hash":"7279dc318b30bc7ba0c72a6f5ff90e76a34352f1"}],"intents":{"pair_fast":null,"pair_250":null,"pair_add_fast":null,"pair_add_250":null},"decision_ms":1790002580078,"feature_cutoff_ms":1790002580077,"request_ms":1790002580005,"inventory":{"pair_fast":{"qty":[5.0,0.0],"cash":2.33663,"lots":[[[5.0,0.467326]],[]],"floor":-2.33663},"pair_250":{"qty":[5.0,0.0],"cash":2.33663,"lots":[[[5.0,0.467326]],[]],"floor":-2.33663},"pair_add_fast":{"qty":[5.0,0.0],"cash":2.33663,"lots":[[[5.0,0.467326]],[]],"floor":-2.33663},"pair_add_250":{"qty":[5.0,0.0],"cash":2.33663,"lots":[[[5.0,0.467326]],[]],"floor":-2.33663}}}
{"kind":"decision","recorded_ms":1790002590031,"S":1790002500,"age":90,"signal":{},"entry_side":null,"context_gap":"incomplete or stale context","book_errors":[null,null],"books":[{"bid":0.27,"ask":0.28,"asks":[[0.28,260.01]],"received_ms":1790002590030,"observed_ms":1790002590020,"hash":"97eff397e52ca845637c98b4d9094ebe39cad4af"},{"bid":0.72,"ask":0.73,"asks":[[0.73,2160.81]],"received_ms":1790002590030,"observed_ms":1790002590020,"hash":"fab43d364b40ff8b1ba2b51a645a12fbda373912"}],"intents":{"pair_fast":null,"pair_250":null,"pair_add_fast":null,"pair_add_250":null},"decision_ms":1790002590031,"feature_cutoff_ms":1790002590030,"request_ms":1790002590003,"inventory":{"pair_fast":{"qty":[5.0,0.0],"cash":2.33663,"lots":[[[5.0,0.467326]],[]],"floor":-2.33663},"pair_250":{"qty":[5.0,0.0],"cash":2.33663,"lots":[[[5.0,0.467326]],[]],"floor":-2.33663},"pair_add_fast":{"qty":[5.0,0.0],"cash":2.33663,"lots":[[[5.0,0.467326]],[]],"floor":-2.33663},"pair_add_250":{"qty":[5.0,0.0],"cash":2.33663,"lots":[[[5.0,0.467326]],[]],"floor":-2.33663}}}
{"kind":"decision","recorded_ms":1790002600061,"S":1790002500,"age":100,"signal":{},"entry_side":null,"context_gap":"incomplete or stale context","book_errors":[null,null],"books":[{"bid":0.27,"ask":0.28,"asks":[[0.28,756.38]],"received_ms":1790002600058,"observed_ms":1790002600046,"hash":"4c8814a88d4a412dda4ee150666dc554ffe8a830"},{"bid":0.72,"ask":0.73,"asks":[[0.73,1058.21]],"received_ms":1790002600060,"observed_ms":1790002600046,"hash":"d9f8037716a3a8c2724e101e2970963ed9d55278"}],"intents":{"pair_fast":null,"pair_250":null,"pair_add_fast":null,"pair_add_250":null},"decision_ms":1790002600061,"feature_cutoff_ms":1790002600060,"request_ms":1790002600007,"inventory":{"pair_fast":{"qty":[5.0,0.0],"cash":2.33663,"lots":[[[5.0,0.467326]],[]],"floor":-2.33663},"pair_250":{"qty":[5.0,0.0],"cash":2.33663,"lots":[[[5.0,0.467326]],[]],"floor":-2.33663},"pair_add_fast":{"qty":[5.0,0.0],"cash":2.33663,"lots":[[[5.0,0.467326]],[]],"floor":-2.33663},"pair_add_250":{"qty":[5.0,0.0],"cash":2.33663,"lots":[[[5.0,0.467326]],[]],"floor":-2.33663}}}
{"kind":"decision","recorded_ms":1790002610071,"S":1790002500,"age":110,"signal":{},"entry_side":null,"context_gap":"incomplete or stale context","book_errors":[null,null],"books":[{"bid":0.19,"ask":0.2,"asks":[[0.2,485.06]],"received_ms":1790002610069,"observed_ms":1790002610061,"hash":"b65f1e65a0419fef8fb19ff968d07432bfa6bdcd"},{"bid":0.8,"ask":0.81,"asks":[[0.81,270.0]],"received_ms":1790002610069,"observed_ms":1790002610059,"hash":"0b31bf180408150b54865f0c76c0e07a7481974e"}],"intents":{"pair_fast":null,"pair_250":null,"pair_add_fast":null,"pair_add_250":null},"decision_ms":1790002610071,"feature_cutoff_ms":1790002610069,"request_ms":1790002610034,"inventory":{"pair_fast":{"qty":[5.0,0.0],"cash":2.33663,"lots":[[[5.0,0.467326]],[]],"floor":-2.33663},"pair_250":{"qty":[5.0,0.0],"cash":2.33663,"lots":[[[5.0,0.467326]],[]],"floor":-2.33663},"pair_add_fast":{"qty":[5.0,0.0],"cash":2.33663,"lots":[[[5.0,0.467326]],[]],"floor":-2.33663},"pair_add_250":{"qty":[5.0,0.0],"cash":2.33663,"lots":[[[5.0,0.467326]],[]],"floor":-2.33663}}}
{"kind":"decision","recorded_ms":1790002620100,"S":1790002500,"age":120,"signal":{},"entry_side":null,"context_gap":"incomplete or stale context","book_errors":[null,null],"books":[{"bid":0.22,"ask":0.23,"asks":[[0.23,51.0]],"received_ms":1790002620099,"observed_ms":1790002619781,"hash":"b8fc597f6c5405aa640bb8d367def783ab535ea4"},{"bid":0.77,"ask":0.78,"asks":[[0.78,365.4]],"received_ms":1790002620071,"observed_ms":1790002619575,"hash":"0d24af1ba02be65e7a9f229a8dc85e4ba55ec9e4"}],"intents":{"pair_fast":null,"pair_250":null,"pair_add_fast":null,"pair_add_250":null},"decision_ms":1790002620100,"feature_cutoff_ms":1790002620099,"request_ms":1790002620045,"inventory":{"pair_fast":{"qty":[5.0,0.0],"cash":2.33663,"lots":[[[5.0,0.467326]],[]],"floor":-2.33663},"pair_250":{"qty":[5.0,0.0],"cash":2.33663,"lots":[[[5.0,0.467326]],[]],"floor":-2.33663},"pair_add_fast":{"qty":[5.0,0.0],"cash":2.33663,"lots":[[[5.0,0.467326]],[]],"floor":-2.33663},"pair_add_250":{"qty":[5.0,0.0],"cash":2.33663,"lots":[[[5.0,0.467326]],[]],"floor":-2.33663}}}
{"kind":"decision","recorded_ms":1790002630046,"S":1790002500,"age":130,"signal":{"rsi14":58.17605441605689,"volume_ratio":0.88016714468153,"taker_buy_fraction":0.40076580568885417,"volume5":192.98368,"return1":-7.17239787708061,"return5":-7.175887528983044,"return15":13.275799054677105,"bollinger_z":0.4714579704854317,"bar_close_ms":1790002619999,"ref":86023.57876290652,"reference_received_ms":1790002501487,"spot":85947.19378796135,"twap":85952.99204408814,"sigma":8.08177462215479,"spot_z":-0.7249936999414647,"twap_z":-0.6699606366252256,"momentum":0.4493617752692289,"decision_ms":1790002630045,"momentum30":-0.2511161754836174,"momentum60":-0.7161912821037898,"spot_twap_gap":-0.09262218784854626,"range60":1.2637039371896992,"final_mean":85947.19378796135,"final_z":-0.8290957879748475,"final_up_prob":0.20352510348663172,"final_drift_up_prob":0.8200282620984364,"final_known_seconds":0,"final_sd":92.13045832947745,"final_drift_shift":160.72790353408257},"entry_side":null,"context_gap":null,"book_errors":[null,null],"books":[{"bid":0.23,"ask":0.24,"asks":[[0.24,906.87]],"received_ms":1790002630039,"observed_ms":1790002630029,"hash":"f62f324ca13edf75750098a4fc37e4efb3738772"},{"bid":0.76,"ask":0.77,"asks":[[0.77,520.0]],"received_ms":1790002630045,"observed_ms":1790002630035,"hash":"8ad7dbf6cfd093ae6e0d7dc0c8805f2680d614d8"}],"intents":{"pair_fast":null,"pair_250":null,"pair_add_fast":null,"pair_add_250":null},"decision_ms":1790002630046,"feature_cutoff_ms":1790002630045,"request_ms":1790002630004,"inventory":{"pair_fast":{"qty":[5.0,0.0],"cash":2.33663,"lots":[[[5.0,0.467326]],[]],"floor":-2.33663},"pair_250":{"qty":[5.0,0.0],"cash":2.33663,"lots":[[[5.0,0.467326]],[]],"floor":-2.33663},"pair_add_fast":{"qty":[5.0,0.0],"cash":2.33663,"lots":[[[5.0,0.467326]],[]],"floor":-2.33663},"pair_add_250":{"qty":[5.0,0.0],"cash":2.33663,"lots":[[[5.0,0.467326]],[]],"floor":-2.33663}}}
{"kind":"decision","recorded_ms":1790002640073,"S":1790002500,"age":140,"signal":{"rsi14":58.17605441605689,"volume_ratio":0.88016714468153,"taker_buy_fraction":0.40076580568885417,"volume5":192.98368,"return1":-7.17239787708061,"return5":-7.175887528983044,"return15":13.275799054677105,"bollinger_z":0.4714579704854317,"bar_close_ms":1790002619999,"ref":86023.57876290652,"reference_received_ms":1790002501487,"spot":85918.43547002038,"twap":85945.38851838476,"sigma":7.707320648918106,"spot_z":-1.0787377916711771,"twap_z":-0.8022078193515834,"momentum":-1.1539597611608812,"decision_ms":1790002640072,"momentum30":0.13067967668387695,"momentum60":-0.5953625388429734,"spot_twap_gap":-0.45146993877569064,"range60":1.0897317851330932,"final_mean":85918.43547002038,"final_z":-1.245712582859864,"final_up_prob":0.10643496623454757,"final_drift_up_prob":1.2364660406660732e-08,"final_known_seconds":0,"final_sd":84.40413489662913,"final_drift_shift":-365.4238137174151},"entry_side":null,"context_gap":null,"book_errors":[null,null],"books":[{"bid":0.14,"ask":0.15,"asks":[[0.15,989.7]],"received_ms":1790002640072,"observed_ms":1790002640044,"hash":"9d4a261406f952fb92b0f80b9e3f889b8ef6356c"},{"bid":0.85,"ask":0.86,"asks":[[0.86,29.94]],"received_ms":1790002640044,"observed_ms":1790002640029,"hash":"b7b9175f284d3d4d61f708647b856e9e7ff7c8cc"}],"intents":{"pair_fast":null,"pair_250":null,"pair_add_fast":null,"pair_add_250":null},"decision_ms":1790002640073,"feature_cutoff_ms":1790002640072,"request_ms":1790002640019,"inventory":{"pair_fast":{"qty":[5.0,0.0],"cash":2.33663,"lots":[[[5.0,0.467326]],[]],"floor":-2.33663},"pair_250":{"qty":[5.0,0.0],"cash":2.33663,"lots":[[[5.0,0.467326]],[]],"floor":-2.33663},"pair_add_fast":{"qty":[5.0,0.0],"cash":2.33663,"lots":[[[5.0,0.467326]],[]],"floor":-2.33663},"pair_add_250":{"qty":[5.0,0.0],"cash":2.33663,"lots":[[[5.0,0.467326]],[]],"floor":-2.33663}}}
{"kind":"decision","recorded_ms":1790002650077,"S":1790002500,"age":150,"signal":{"rsi14":58.17605441605689,"volume_ratio":0.88016714468153,"taker_buy_fraction":0.40076580568885417,"volume5":192.98368,"return1":-7.17239787708061,"return5":-7.175887528983044,"return15":13.275799054677105,"bollinger_z":0.4714579704854317,"bar_close_ms":1790002619999,"ref":86023.57876290652,"reference_received_ms":1790002501487,"spot":85898.36905654843,"twap":85939.4047087488,"sigma":7.707409777652906,"spot_z":-1.3267648798969862,"twap_z":-0.8919370718402085,"momentum":-1.0387223394755216,"decision_ms":1790002650076,"momentum30":-0.8845263337331235,"momentum60":-0.8238348910844283,"spot_twap_gap":-0.6873489371816593,"range60":1.3334290541376739,"final_mean":85898.36905654843,"final_z":-1.5494704052105674,"final_up_prob":0.06063434023340558,"final_drift_up_prob":5.5836130330444433e-08,"final_known_seconds":0,"final_sd":80.8080657346096,"final_drift_shift":-303.60857077611064},"entry_side":null,"context_gap":null,"book_errors":[null,null],"books":[{"bid":0.08,"ask":0.09,"asks":[[0.09,496.56]],"received_ms":1790002650076,"observed_ms":1790002650055,"hash":"ab1212a5f7f3130c8f563595de8954fbbff42d85"},{"bid":0.91,"ask":0.92,"asks":[[0.92,170.0]],"received_ms":1790002650075,"observed_ms":1790002650056,"hash":"314de86a9f1ccf99bd7d3bfe1776c4cfe99a77ca"}],"intents":{"pair_fast":null,"pair_250":null,"pair_add_fast":null,"pair_add_250":null},"decision_ms":1790002650077,"feature_cutoff_ms":1790002650076,"request_ms":1790002650047,"inventory":{"pair_fast":{"qty":[5.0,0.0],"cash":2.33663,"lots":[[[5.0,0.467326]],[]],"floor":-2.33663},"pair_250":{"qty":[5.0,0.0],"cash":2.33663,"lots":[[[5.0,0.467326]],[]],"floor":-2.33663},"pair_add_fast":{"qty":[5.0,0.0],"cash":2.33663,"lots":[[[5.0,0.467326]],[]],"floor":-2.33663},"pair_add_250":{"qty":[5.0,0.0],"cash":2.33663,"lots":[[[5.0,0.467326]],[]],"floor":-2.33663}}}
{"kind":"decision","recorded_ms":1790002660044,"S":1790002500,"age":160,"signal":{"rsi14":58.17605441605689,"volume_ratio":0.88016714468153,"taker_buy_fraction":0.40076580568885417,"volume5":192.98368,"return1":-7.17239787708061,"return5":-7.175887528983044,"return15":13.275799054677105,"bollinger_z":0.4714579704854317,"bar_close_ms":1790002619999,"ref":86023.57876290652,"reference_received_ms":1790002501487,"spot":85863.24968121678,"twap":85926.55839549756,"sigma":6.831174947962454,"spot_z":-1.9838991202112655,"twap_z":-1.2005221979483642,"momentum":-1.1695320981157074,"decision_ms":1790002660043,"momentum30":-2.2266181168407417,"momentum60":-1.7964970400455054,"spot_twap_gap":-1.1964442327372076,"range60":1.7964970400455054,"final_mean":85863.24968121678,"final_z":-2.3475253491665162,"final_up_prob":0.009449293571750228,"final_drift_up_prob":7.039602234470976e-11,"final_known_seconds":0,"final_sd":68.29706088015607,"final_drift_shift":-277.7988450779936},"entry_side":null,"context_gap":null,"book_errors":[null,null],"books":[{"bid":0.05,"ask":0.06,"asks":[[0.06,20.16]],"received_ms":1790002660040,"observed_ms":1790002660030,"hash":"fdce6d389e1887af6b92aee7a1843ae174fc7919"},{"bid":0.94,"ask":0.95,"asks":[[0.95,2287.86]],"received_ms":1790002660043,"observed_ms":1790002660034,"hash":"74198b01290342d0a255df528120ecacd94ca85b"}],"intents":{"pair_fast":null,"pair_250":null,"pair_add_fast":null,"pair_add_250":null},"decision_ms":1790002660044,"feature_cutoff_ms":1790002660043,"request_ms":1790002660001,"inventory":{"pair_fast":{"qty":[5.0,0.0],"cash":2.33663,"lots":[[[5.0,0.467326]],[]],"floor":-2.33663},"pair_250":{"qty":[5.0,0.0],"cash":2.33663,"lots":[[[5.0,0.467326]],[]],"floor":-2.33663},"pair_add_fast":{"qty":[5.0,0.0],"cash":2.33663,"lots":[[[5.0,0.467326]],[]],"floor":-2.33663},"pair_add_250":{"qty":[5.0,0.0],"cash":2.33663,"lots":[[[5.0,0.467326]],[]],"floor":-2.33663}}}
{"kind":"decision","recorded_ms":1790002670057,"S":1790002500,"age":170,"signal":{"rsi14":58.17605441605689,"volume_ratio":0.88016714468153,"taker_buy_fraction":0.40076580568885417,"volume5":192.98368,"return1":-7.17239787708061,"return5":-7.175887528983044,"return15":13.275799054677105,"bollinger_z":0.4714579704854317,"bar_close_ms":1790002619999,"ref":86023.57876290652,"reference_received_ms":1790002501487,"spot":85863.10567453633,"twap":85913.5132802335,"sigma":6.524879270976565,"spot_z":-2.1574957250826223,"twap_z":-1.479785867885804,"momentum":0.5520493528106836,"decision_ms":1790002670055,"momentum30":-1.6951069109214374,"momentum60":-0.985589865403405,"spot_twap_gap":-0.9973508539625059,"range60":1.9429714038491426,"final_mean":85863.10567453633,"final_z":-2.593231077471205,"final_up_prob":0.004753943199268251,"final_drift_up_prob":0.2255698185355069,"final_known_seconds":0,"final_sd":61.88152292493375,"final_drift_shift":113.84434362591189},"entry_side":null,"context_gap":null,"book_errors":[null,null],"books":[{"bid":0.05,"ask":0.06,"asks":[[0.06,240.51]],"received_ms":1790002670055,"observed_ms":1790002670042,"hash":"e1916d27e93f4f5381f0c8213499cfc01af6b90e"},{"bid":0.94,"ask":0.95,"asks":[[0.95,879.16]],"received_ms":1790002670052,"observed_ms":1790002670042,"hash":"8825b5111be6993b506b08fbcb2e05b3dd03746d"}],"intents":{"pair_fast":null,"pair_250":null,"pair_add_fast":null,"pair_add_250":null},"decision_ms":1790002670057,"feature_cutoff_ms":1790002670055,"request_ms":1790002670019,"inventory":{"pair_fast":{"qty":[5.0,0.0],"cash":2.33663,"lots":[[[5.0,0.467326]],[]],"floor":-2.33663},"pair_250":{"qty":[5.0,0.0],"cash":2.33663,"lots":[[[5.0,0.467326]],[]],"floor":-2.33663},"pair_add_fast":{"qty":[5.0,0.0],"cash":2.33663,"lots":[[[5.0,0.467326]],[]],"floor":-2.33663},"pair_add_250":{"qty":[5.0,0.0],"cash":2.33663,"lots":[[[5.0,0.467326]],[]],"floor":-2.33663}}}
{"kind":"decision","recorded_ms":1790002680064,"S":1790002500,"age":180,"signal":{"rsi14":58.17605441605689,"volume_ratio":0.88016714468153,"taker_buy_fraction":0.40076580568885417,"volume5":192.98368,"return1":-7.17239787708061,"return5":-7.175887528983044,"return15":13.275799054677105,"bollinger_z":0.4714579704854317,"bar_close_ms":1790002619999,"ref":86023.57876290652,"reference_received_ms":1790002501487,"spot":85842.93672333432,"twap":85903.42066928295,"sigma":8.713753370868794,"spot_z":-1.8929405449215477,"twap_z":-1.2591317489505647,"momentum":-1.0468369116423157,"decision_ms":1790002680063,"momentum30":-0.9549540146917976,"momentum60":-1.3744844035252382,"spot_twap_gap":-0.8961056749478068,"range60":1.82617187867318,"final_mean":85842.93672333432,"final_z":-2.3186737298436793,"final_up_prob":0.010206366991831584,"final_drift_up_prob":8.084783675865737e-09,"final_known_seconds":0,"final_sd":77.90748532109039,"final_drift_shift":-259.4314890149188},"entry_side":null,"context_gap":null,"book_errors":[null,null],"books":[{"bid":0.03,"ask":0.04,"asks":[[0.04,463.21]],"received_ms":1790002680063,"observed_ms":1790002680053,"hash":"d578e3c5247c1ddc06fa73ec37f0005bb8f72caf"},{"bid":0.96,"ask":0.97,"asks":[[0.97,864.15]],"received_ms":1790002680060,"observed_ms":1790002680051,"hash":"d0ecb7a13f8399c91223d6c611b8f15bf7ef0e81"}],"intents":{"pair_fast":null,"pair_250":null,"pair_add_fast":null,"pair_add_250":null},"decision_ms":1790002680064,"feature_cutoff_ms":1790002680063,"request_ms":1790002680033,"inventory":{"pair_fast":{"qty":[5.0,0.0],"cash":2.33663,"lots":[[[5.0,0.467326]],[]],"floor":-2.33663},"pair_250":{"qty":[5.0,0.0],"cash":2.33663,"lots":[[[5.0,0.467326]],[]],"floor":-2.33663},"pair_add_fast":{"qty":[5.0,0.0],"cash":2.33663,"lots":[[[5.0,0.467326]],[]],"floor":-2.33663},"pair_add_250":{"qty":[5.0,0.0],"cash":2.33663,"lots":[[[5.0,0.467326]],[]],"floor":-2.33663}}}
{"kind":"decision","recorded_ms":1790002690078,"S":1790002500,"age":190,"signal":{"rsi14":55.16657874043166,"volume_ratio":1.21828840042398,"taker_buy_fraction":0.3752704516441281,"volume5":192.73316,"return1":-12.552893827537051,"return5":-30.77194357184295,"return15":5.590451880884243,"bollinger_z":-0.3402998198814537,"bar_close_ms":1790002679999,"ref":86023.57876290652,"reference_received_ms":1790002501487,"spot":85827.21989828775,"twap":85885.83235708588,"sigma":8.860210158723264,"spot_z":-2.1137917696726896,"twap_z":-1.482832055944911,"momentum":-0.6554224729120038,"decision_ms":1790002690077,"momentum30":-0.5047474787837928,"momentum60":-1.7388768821194243,"spot_twap_gap":-0.8540244258274834,"range60":1.7470997891564235,"final_mean":85827.21989828775,"final_z":-2.6503086999264154,"final_up_prob":0.00402091273780153,"final_drift_up_prob":1.8168640673610348e-06,"final_known_seconds":0,"final_sd":74.08905408800972,"final_drift_shift":-146.7699442415674},"entry_side":null,"context_gap":null,"book_errors":[null,null],"books":[{"bid":0.01,"ask":0.02,"asks":[[0.02,598.58]],"received_ms":1790002690051,"observed_ms":1790002690041,"hash":"41157f692c0a2a74e43df398aa4548986aadd49a"},{"bid":0.98,"ask":0.99,"asks":[[0.99,3116.75]],"received_ms":1790002690077,"observed_ms":1790002690058,"hash":"fe986592daa72ef615984e6541375d2e007b52bf"}],"intents":{"pair_fast":null,"pair_250":null,"pair_add_fast":null,"pair_add_250":null},"decision_ms":1790002690078,"feature_cutoff_ms":1790002690077,"request_ms":1790002690013,"inventory":{"pair_fast":{"qty":[5.0,0.0],"cash":2.33663,"lots":[[[5.0,0.467326]],[]],"floor":-2.33663},"pair_250":{"qty":[5.0,0.0],"cash":2.33663,"lots":[[[5.0,0.467326]],[]],"floor":-2.33663},"pair_add_fast":{"qty":[5.0,0.0],"cash":2.33663,"lots":[[[5.0,0.467326]],[]],"floor":-2.33663},"pair_add_250":{"qty":[5.0,0.0],"cash":2.33663,"lots":[[[5.0,0.467326]],[]],"floor":-2.33663}}}
{"kind":"decision","recorded_ms":1790002700031,"S":1790002500,"age":200,"signal":{"rsi14":55.16657874043166,"volume_ratio":1.21828840042398,"taker_buy_fraction":0.3752704516441281,"volume5":192.73316,"return1":-12.552893827537051,"return5":-30.77194357184295,"return15":5.590451880884243,"bollinger_z":-0.3402998198814537,"bar_close_ms":1790002679999,"ref":86023.57876290652,"reference_received_ms":1790002501487,"spot":85827.04285187322,"twap":85864.54372477421,"sigma":8.609178100701518,"spot_z":-2.283207476106808,"twap_z":-1.8475503337662527,"momentum":-0.00022997482801246266,"decision_ms":1790002700030,"momentum30":-0.948793212368333,"momentum60":-1.449215176743332,"spot_twap_gap":-0.5623465814230857,"range60":1.4755587861495543,"final_mean":85827.04285187322,"final_z":-2.9479030702051383,"final_up_prob":0.0015996868191349711,"final_drift_up_prob":0.0015962899694145216,"final_known_seconds":0,"final_sd":66.66973314682878,"final_drift_shift":-0.043808044652948706},"entry_side":null,"context_gap":null,"book_errors":[null,null],"books":[{"bid":null,"ask":0.01,"asks":[[0.01,3929.73]],"received_ms":1790002700030,"observed_ms":1790002700017,"hash":"e6b63e6a56d9c2dde4c0030a21be97670d5c013e"},{"bid":0.99,"ask":null,"asks":[],"received_ms":1790002700029,"observed_ms":1790002700017,"hash":"1ce880ae4c9d36ecc75d718c8527a8167890da8f"}],"intents":{"pair_fast":null,"pair_250":null,"pair_add_fast":null,"pair_add_250":null},"decision_ms":1790002700031,"feature_cutoff_ms":1790002700030,"request_ms":1790002700003,"inventory":{"pair_fast":{"qty":[5.0,0.0],"cash":2.33663,"lots":[[[5.0,0.467326]],[]],"floor":-2.33663},"pair_250":{"qty":[5.0,0.0],"cash":2.33663,"lots":[[[5.0,0.467326]],[]],"floor":-2.33663},"pair_add_fast":{"qty":[5.0,0.0],"cash":2.33663,"lots":[[[5.0,0.467326]],[]],"floor":-2.33663},"pair_add_250":{"qty":[5.0,0.0],"cash":2.33663,"lots":[[[5.0,0.467326]],[]],"floor":-2.33663}}}
{"kind":"decision","recorded_ms":1790002710059,"S":1790002500,"age":210,"signal":{"rsi14":55.16657874043166,"volume_ratio":1.21828840042398,"taker_buy_fraction":0.3752704516441281,"volume5":192.73316,"return1":-12.552893827537051,"return5":-30.77194357184295,"return15":5.590451880884243,"bollinger_z":-0.3402998198814537,"bar_close_ms":1790002679999,"ref":86023.57876290652,"reference_received_ms":1790002501487,"spot":85778.15608584147,"twap":85845.7231369234,"sigma":11.751854434659812,"spot_z":-2.202049187367503,"twap_z":-1.5958054135358077,"momentum":-1.3048966294072935,"decision_ms":1790002710058,"momentum30":-1.047542165226496,"momentum60":-1.2123316571734064,"spot_twap_gap":-0.7422546658420112,"range60":1.3918437613370371,"final_mean":85778.15608584147,"final_z":-2.9551213589888308,"final_up_prob":0.0015627304048907442,"final_drift_up_prob":5.404787728480187e-11,"final_known_seconds":0,"final_sd":83.04994863189633,"final_drift_shift":-290.67905620469116},"entry_side":null,"context_gap":null,"book_errors":[null,null],"books":[{"bid":null,"ask":0.01,"asks":[[0.01,10221.49]],"received_ms":1790002710058,"observed_ms":1790002710037,"hash":"a3cd2ca3eab07537653244070f3dda0738f814d2"},{"bid":0.99,"ask":null,"asks":[],"received_ms":1790002710029,"observed_ms":1790002710000,"hash":"22e204c1df56899fd0e2ed6533fd32c2bba9e5f7"}],"intents":{"pair_fast":null,"pair_250":null,"pair_add_fast":null,"pair_add_250":null},"decision_ms":1790002710059,"feature_cutoff_ms":1790002710058,"request_ms":1790002710004,"inventory":{"pair_fast":{"qty":[5.0,0.0],"cash":2.33663,"lots":[[[5.0,0.467326]],[]],"floor":-2.33663},"pair_250":{"qty":[5.0,0.0],"cash":2.33663,"lots":[[[5.0,0.467326]],[]],"floor":-2.33663},"pair_add_fast":{"qty":[5.0,0.0],"cash":2.33663,"lots":[[[5.0,0.467326]],[]],"floor":-2.33663},"pair_add_250":{"qty":[5.0,0.0],"cash":2.33663,"lots":[[[5.0,0.467326]],[]],"floor":-2.33663}}}
{"kind":"decision","recorded_ms":1790002720064,"S":1790002500,"age":220,"signal":{"rsi14":55.16657874043166,"volume_ratio":1.21828840042398,"taker_buy_fraction":0.3752704516441281,"volume5":192.73316,"return1":-12.552893827537051,"return5":-30.77194357184295,"return15":5.590451880884243,"bollinger_z":-0.3402998198814537,"bar_close_ms":1790002679999,"ref":86023.57876290652,"reference_received_ms":1790002501487,"spot":85727.95374500853,"twap":85824.60094506314,"sigma":12.75842684996141,"spot_z":-2.5916129037556157,"twap_z":-1.7443499334078165,"momentum":-0.9660785333722384,"decision_ms":1790002720063,"momentum30":-1.4180632390017611,"momentum60":-1.2523100467645485,"spot_twap_gap":-0.9779497129517337,"range60":1.4553698713789214,"final_mean":85727.95374500853,"final_z":-3.6665392385038365,"final_up_prob":0.0001229276042714611,"final_drift_up_prob":5.9868976443056e-10,"final_known_seconds":0,"final_sd":80.62780695035327,"final_drift_shift":-194.63996084279006},"entry_side":null,"context_gap":null,"book_errors":[null,null],"books":[{"bid":null,"ask":0.01,"asks":[[0.01,10477.75]],"received_ms":1790002720057,"observed_ms":1790002720046,"hash":"d04cba954e9cefda075b7c4a68ceec301eb6192b"},{"bid":0.99,"ask":null,"asks":[],"received_ms":1790002720063,"observed_ms":1790002720046,"hash":"158ac437b7f48381156a65cd4ef7bd186de080d0"}],"intents":{"pair_fast":null,"pair_250":null,"pair_add_fast":null,"pair_add_250":null},"decision_ms":1790002720064,"feature_cutoff_ms":1790002720063,"request_ms":1790002720033,"inventory":{"pair_fast":{"qty":[5.0,0.0],"cash":2.33663,"lots":[[[5.0,0.467326]],[]],"floor":-2.33663},"pair_250":{"qty":[5.0,0.0],"cash":2.33663,"lots":[[[5.0,0.467326]],[]],"floor":-2.33663},"pair_add_fast":{"qty":[5.0,0.0],"cash":2.33663,"lots":[[[5.0,0.467326]],[]],"floor":-2.33663},"pair_add_250":{"qty":[5.0,0.0],"cash":2.33663,"lots":[[[5.0,0.467326]],[]],"floor":-2.33663}}}
{"kind":"decision","recorded_ms":1790002730082,"S":1790002500,"age":230,"signal":{"rsi14":55.16657874043166,"volume_ratio":1.21828840042398,"taker_buy_fraction":0.3752704516441281,"volume5":192.73316,"return1":-12.552893827537051,"return5":-30.77194357184295,"return15":5.590451880884243,"bollinger_z":-0.3402998198814537,"bar_close_ms":1790002679999,"ref":86023.57876290652,"reference_received_ms":1790002501487,"spot":85747.30870729931,"twap":85803.95792280907,"sigma":12.736966969056933,"spot_z":-2.5940012957967404,"twap_z":-2.062100948814775,"momentum":0.4831424140237027,"decision_ms":1790002730081,"momentum30":-1.1372861054061887,"momentum60":-1.2616437802953273,"spot_twap_gap":-0.5741855413931475,"range60":1.458885844871088,"final_mean":85747.30870729931,"final_z":-3.9654662350807945,"final_up_prob":3.662631087286705e-05,"final_drift_up_prob":0.0021828722811197965,"final_known_seconds":0,"final_sd":69.66899709375025,"final_drift_shift":77.68207896697022},"entry_side":null,"context_gap":null,"book_errors":[null,null],"books":[{"bid":null,"ask":0.01,"asks":[[0.01,13680.17]],"received_ms":1790002730081,"observed_ms":1790002730071,"hash":"4069db9ab29db7103d38dad0c668102028edd528"},{"bid":0.99,"ask":null,"asks":[],"received_ms":1790002730065,"observed_ms":1790002730045,"hash":"ec912c4da1b4f34b6ad2cd21530d13429a682db8"}],"intents":{"pair_fast":null,"pair_250":null,"pair_add_fast":null,"pair_add_250":null},"decision_ms":1790002730082,"feature_cutoff_ms":1790002730081,"request_ms":1790002730039,"inventory":{"pair_fast":{"qty":[5.0,0.0],"cash":2.33663,"lots":[[[5.0,0.467326]],[]],"floor":-2.33663},"pair_250":{"qty":[5.0,0.0],"cash":2.33663,"lots":[[[5.0,0.467326]],[]],"floor":-2.33663},"pair_add_fast":{"qty":[5.0,0.0],"cash":2.33663,"lots":[[[5.0,0.467326]],[]],"floor":-2.33663},"pair_add_250":{"qty":[5.0,0.0],"cash":2.33663,"lots":[[[5.0,0.467326]],[]],"floor":-2.33663}}}
{"kind":"decision","recorded_ms":1790002740061,"S":1790002500,"age":240,"signal":{"rsi14":55.16657874043166,"volume_ratio":1.21828840042398,"taker_buy_fraction":0.3752704516441281,"volume5":192.73316,"return1":-12.552893827537051,"return5":-30.77194357184295,"return15":5.590451880884243,"bollinger_z":-0.3402998198814537,"bar_close_ms":1790002679999,"ref":86023.57876290652,"reference_received_ms":1790002501487,"spot":85770.03319288447,"twap":85786.78674591176,"sigma":11.602716753563827,"spot_z":-2.8225025606513445,"twap_z":-2.6359998096255075,"momentum":0.6024638590528466,"decision_ms":1790002740059,"momentum30":0.04881684599427678,"momentum60":-0.8406258451725194,"spot_twap_gap":-0.1864110312628744,"range60":1.3099973080085137,"final_mean":85770.03319288447,"final_z":-4.893529811767446,"final_up_prob":4.952165160720945e-07,"final_drift_up_prob":0.00014951464375667634,"final_known_seconds":0,"final_sd":51.812409400745544,"final_drift_shift":66.1846705608999},"entry_side":null,"context_gap":null,"book_errors":[null,null],"books":[{"bid":null,"ask":0.01,"asks":[[0.01,10875.39]],"received_ms":1790002740045,"observed_ms":1790002740026,"hash":"1d2cb8d1552999e9cc0a4aa4ee3832ed0d59d487"},{"bid":0.99,"ask":null,"asks":[],"received_ms":1790002740059,"observed_ms":1790002740047,"hash":"8fea53a853774cce30c23635ff2cb2f4609149d8"}],"intents":{"pair_fast":null,"pair_250":null,"pair_add_fast":null,"pair_add_250":null},"decision_ms":1790002740061,"feature_cutoff_ms":1790002740059,"request_ms":1790002740009,"inventory":{"pair_fast":{"qty":[5.0,0.0],"cash":2.33663,"lots":[[[5.0,0.467326]],[]],"floor":-2.33663},"pair_250":{"qty":[5.0,0.0],"cash":2.33663,"lots":[[[5.0,0.467326]],[]],"floor":-2.33663},"pair_add_fast":{"qty":[5.0,0.0],"cash":2.33663,"lots":[[[5.0,0.467326]],[]],"floor":-2.33663},"pair_add_250":{"qty":[5.0,0.0],"cash":2.33663,"lots":[[[5.0,0.467326]],[]],"floor":-2.33663}}}
{"kind":"decision","recorded_ms":1790002750041,"S":1790002500,"age":250,"signal":{"rsi14":50.469122661778535,"volume_ratio":1.3239605064782676,"taker_buy_fraction":0.39176840486803566,"volume5":185.47851,"return1":-6.078650465010809,"return5":-21.526999882995433,"return15":6.0192158074756135,"bollinger_z":-0.7136110358743893,"bar_close_ms":1790002739999,"ref":86023.57876290652,"reference_received_ms":1790002501487,"spot":85786.83738638861,"twap":85776.9125720112,"sigma":11.44261490569685,"spot_z":-2.927100751283259,"twap_z":-3.049812429519374,"momentum":0.16578819922882176,"decision_ms":1790002750040,"momentum30":0.9412006487391852,"momentum60":-0.4536822750896865,"spot_twap_gap":0.11197510684013609,"range60":1.1192116362703421,"final_mean":85786.31163070981,"final_z":-6.102257523169569,"final_up_prob":5.229034427678414e-10,"final_drift_up_prob":3.7054301849082094e-09,"final_known_seconds":10,"final_sd":38.881861556289685,"final_drift_shift":12.477929013228351},"entry_side":null,"context_gap":null,"book_errors":[null,null],"books":[{"bid":null,"ask":0.01,"asks":[[0.01,17166.62]],"received_ms":1790002750039,"observed_ms":1790002750016,"hash":"0c3eda1445bc82b9be64885d96e3e64789e76cf3"},{"bid":0.99,"ask":null,"asks":[],"received_ms":1790002750033,"observed_ms":1790002750016,"hash":"d66c3b0420999925681e4da7bc3079eea9e3718b"}],"intents":{"pair_fast":null,"pair_250":null,"pair_add_fast":null,"pair_add_250":null},"decision_ms":1790002750041,"feature_cutoff_ms":1790002750040,"request_ms":1790002750008,"inventory":{"pair_fast":{"qty":[5.0,0.0],"cash":2.33663,"lots":[[[5.0,0.467326]],[]],"floor":-2.33663},"pair_250":{"qty":[5.0,0.0],"cash":2.33663,"lots":[[[5.0,0.467326]],[]],"floor":-2.33663},"pair_add_fast":{"qty":[5.0,0.0],"cash":2.33663,"lots":[[[5.0,0.467326]],[]],"floor":-2.33663},"pair_add_250":{"qty":[5.0,0.0],"cash":2.33663,"lots":[[[5.0,0.467326]],[]],"floor":-2.33663}}}
{"kind":"decision","recorded_ms":1790002760046,"S":1790002500,"age":260,"signal":{},"entry_side":null,"context_gap":"incomplete or stale context","book_errors":[null,null],"books":[{"bid":null,"ask":0.01,"asks":[[0.01,33836.27]],"received_ms":1790002760038,"observed_ms":1790002760025,"hash":"ba1727ef01ea4e9f4d0fd3c62b45b1bc54b29fb8"},{"bid":0.99,"ask":null,"asks":[],"received_ms":1790002760045,"observed_ms":1790002760036,"hash":"6b9e7c6b0529ea10936dec84f78fd104ad931cbd"}],"intents":{"pair_fast":null,"pair_250":null,"pair_add_fast":null,"pair_add_250":null},"decision_ms":1790002760046,"feature_cutoff_ms":1790002760045,"request_ms":1790002760015,"inventory":{"pair_fast":{"qty":[5.0,0.0],"cash":2.33663,"lots":[[[5.0,0.467326]],[]],"floor":-2.33663},"pair_250":{"qty":[5.0,0.0],"cash":2.33663,"lots":[[[5.0,0.467326]],[]],"floor":-2.33663},"pair_add_fast":{"qty":[5.0,0.0],"cash":2.33663,"lots":[[[5.0,0.467326]],[]],"floor":-2.33663},"pair_add_250":{"qty":[5.0,0.0],"cash":2.33663,"lots":[[[5.0,0.467326]],[]],"floor":-2.33663}}}
{"kind":"decision","recorded_ms":1790002770073,"S":1790002500,"age":270,"signal":{"rsi14":50.469122661778535,"volume_ratio":1.3239605064782676,"taker_buy_fraction":0.39176840486803566,"volume5":185.47851,"return1":-6.078650465010809,"return5":-21.526999882995433,"return15":6.0192158074756135,"bollinger_z":-0.7136110358743893,"bar_close_ms":1790002739999,"ref":86023.57876290652,"reference_received_ms":1790002501487,"spot":85797.81137729884,"twap":85774.6179704446,"sigma":9.062233333080304,"spot_z":-4.553938028858328,"twap_z":-5.0217706044451385,"momentum":-0.8631336388471679,"decision_ms":1790002770072,"momentum30":0.341949933322927,"momentum60":0.43992016148285046,"spot_twap_gap":0.3304103789383013,"range60":1.3490512439931497,"final_mean":85798.36055484551,"final_z":-15.774790277649814,"final_up_prob":0.0,"final_drift_up_prob":0.0,"final_known_seconds":30,"final_sd":14.277096816944887,"final_drift_shift":-18.462368982007433},"entry_side":null,"context_gap":null,"book_errors":[null,null],"books":[{"bid":null,"ask":0.01,"asks":[[0.01,39568.0]],"received_ms":1790002770047,"observed_ms":1790002770025,"hash":"0311e863ccd6f0b86d63013b80aea104490001a8"},{"bid":0.99,"ask":null,"asks":[],"received_ms":1790002770072,"observed_ms":1790002770046,"hash":"1ec08498c2ffe0be8df777b1643b29877c64411e"}],"intents":{"pair_fast":null,"pair_250":null,"pair_add_fast":null,"pair_add_250":null},"decision_ms":1790002770073,"feature_cutoff_ms":1790002770072,"request_ms":1790002770019,"inventory":{"pair_fast":{"qty":[5.0,0.0],"cash":2.33663,"lots":[[[5.0,0.467326]],[]],"floor":-2.33663},"pair_250":{"qty":[5.0,0.0],"cash":2.33663,"lots":[[[5.0,0.467326]],[]],"floor":-2.33663},"pair_add_fast":{"qty":[5.0,0.0],"cash":2.33663,"lots":[[[5.0,0.467326]],[]],"floor":-2.33663},"pair_add_250":{"qty":[5.0,0.0],"cash":2.33663,"lots":[[[5.0,0.467326]],[]],"floor":-2.33663}}}
{"kind":"decision","recorded_ms":1790002780086,"S":1790002500,"age":280,"signal":{"rsi14":50.469122661778535,"volume_ratio":1.3239605064782676,"taker_buy_fraction":0.39176840486803566,"volume5":185.47851,"return1":-6.078650465010809,"return5":-21.526999882995433,"return15":6.0192158074756135,"bollinger_z":-0.7136110358743893,"bar_close_ms":1790002739999,"ref":86023.57876290652,"reference_received_ms":1790002501487,"spot":85797.53194922702,"twap":85779.37468288104,"sigma":6.2480408290022735,"spot_z":-8.107078454934458,"twap_z":-8.75828154157793,"momentum":0.07118268095783782,"decision_ms":1790002780085,"momentum30":0.28163024191809605,"momentum60":1.4398206670275453,"spot_twap_gap":0.3751724852384197,"range60":1.9566800995601692,"final_mean":85798.54120072964,"final_z":-42.11652866509367,"final_up_prob":0.0,"final_drift_up_prob":0.0,"final_known_seconds":40,"final_sd":5.3432124942288555,"final_drift_shift":0.4648336646946019},"entry_side":null,"context_gap":null,"book_errors":[null,null],"books":[{"bid":null,"ask":0.01,"asks":[[0.01,53127.0]],"received_ms":1790002780085,"observed_ms":1790002780074,"hash":"88e5970ee3ed9f97a0e5a77339253ce291453978"},{"bid":0.99,"ask":null,"asks":[],"received_ms":1790002780070,"observed_ms":1790002780041,"hash":"84084e29850bbfd024fe18115f739ab0de1b69fa"}],"intents":{"pair_fast":null,"pair_250":null,"pair_add_fast":null,"pair_add_250":null},"decision_ms":1790002780086,"feature_cutoff_ms":1790002780085,"request_ms":1790002780046,"inventory":{"pair_fast":{"qty":[5.0,0.0],"cash":2.33663,"lots":[[[5.0,0.467326]],[]],"floor":-2.33663},"pair_250":{"qty":[5.0,0.0],"cash":2.33663,"lots":[[[5.0,0.467326]],[]],"floor":-2.33663},"pair_add_fast":{"qty":[5.0,0.0],"cash":2.33663,"lots":[[[5.0,0.467326]],[]],"floor":-2.33663},"pair_add_250":{"qty":[5.0,0.0],"cash":2.33663,"lots":[[[5.0,0.467326]],[]],"floor":-2.33663}}}
{"kind":"decision","recorded_ms":1790002790048,"S":1790002500,"age":290,"signal":{"rsi14":50.469122661778535,"volume_ratio":1.3239605064782676,"taker_buy_fraction":0.39176840486803566,"volume5":185.47851,"return1":-6.078650465010809,"return5":-21.526999882995433,"return15":6.0192158074756135,"bollinger_z":-0.7136110358743893,"bar_close_ms":1790002739999,"ref":86023.57876290652,"reference_received_ms":1790002501487,"spot":85801.63409060662,"twap":85790.25264598828,"sigma":6.588535936483923,"spot_z":-10.677726725320046,"twap_z":-11.225286412672094,"momentum":0.14776710226888076,"decision_ms":1790002790047,"momentum30":-0.5795002075958897,"momentum60":1.0523434597688808,"spot_twap_gap":0.22301436863241356,"range60":1.4621119862589464,"final_mean":85800.61542797092,"final_z":-112.00190247232644,"final_up_prob":0.0,"final_drift_up_prob":0.0,"final_known_seconds":50,"final_sd":1.9907102470039821,"final_drift_shift":0.2541519487158149},"entry_side":null,"context_gap":null,"book_errors":[null,null],"books":[{"bid":null,"ask":0.01,"asks":[[0.01,53763.0]],"received_ms":1790002790041,"observed_ms":1790002790031,"hash":"fcae515e1910c3c2a3a6093a7dfca8b93d21a6a5"},{"bid":0.99,"ask":null,"asks":[],"received_ms":1790002790047,"observed_ms":1790002790033,"hash":"c3f90cf29b5a6fcf8eb17dfb8fc1e2d1428994de"}],"intents":{"pair_fast":null,"pair_250":null,"pair_add_fast":null,"pair_add_250":null},"decision_ms":1790002790048,"feature_cutoff_ms":1790002790047,"request_ms":1790002790010,"inventory":{"pair_fast":{"qty":[5.0,0.0],"cash":2.33663,"lots":[[[5.0,0.467326]],[]],"floor":-2.33663},"pair_250":{"qty":[5.0,0.0],"cash":2.33663,"lots":[[[5.0,0.467326]],[]],"floor":-2.33663},"pair_add_fast":{"qty":[5.0,0.0],"cash":2.33663,"lots":[[[5.0,0.467326]],[]],"floor":-2.33663},"pair_add_250":{"qty":[5.0,0.0],"cash":2.33663,"lots":[[[5.0,0.467326]],[]],"floor":-2.33663}}}
{"kind":"decision","recorded_ms":1790002830060,"S":1790002800,"age":30,"signal":{"rsi14":56.21055224294177,"volume_ratio":1.6037612845392621,"taker_buy_fraction":0.3492860350468645,"volume5":226.87108,"return1":4.1493804935311065,"return5":-26.661109308101327,"return15":5.2583670824822075,"bollinger_z":-0.439770384333723,"bar_close_ms":1790002799999,"ref":85799.90972905437,"reference_received_ms":1790002801325,"spot":85862.14063925586,"twap":85806.14367920722,"sigma":8.060445999409977,"spot_z":0.4699069298844781,"twap_z":0.047072690531009806,"momentum":2.402637730523211,"decision_ms":1790002830058,"momentum30":0.8969178499598892,"momentum60":1.0573255353689328,"spot_twap_gap":0.896870527687453,"range60":1.0573255353689328,"final_mean":85862.14063925586,"final_z":0.5091408322934006,"final_up_prob":0.6946732437233816,"final_drift_up_prob":1.0,"final_known_seconds":0,"final_sd":122.2273018668883,"final_drift_shift":1469.4460304735999},"entry_side":null,"context_gap":null,"book_errors":[null,null],"books":[{"bid":0.68,"ask":0.69,"asks":[[0.69,94.72]],"received_ms":1790002830058,"observed_ms":1790002830049,"hash":"d20e3c4d674b24908f3de7bad2b119a865e66fc9"},{"bid":0.31,"ask":0.32,"asks":[[0.32,776.64]],"received_ms":1790002830050,"observed_ms":1790002830041,"hash":"83ecee2a3dfa1f36490714fe43fa9e76f765d3bb"}],"intents":{"pair_fast":{"kind":"first","side":1,"qty":5.0,"participation":true,"max_cost":1.7261600000000001},"pair_250":{"kind":"first","side":1,"qty":5.0,"participation":true,"max_cost":1.7261600000000001},"pair_add_fast":{"kind":"first","side":1,"qty":5.0,"participation":true,"max_cost":1.7261600000000001},"pair_add_250":{"kind":"first","side":1,"qty":5.0,"participation":true,"max_cost":1.7261600000000001}},"decision_ms":1790002830060,"feature_cutoff_ms":1790002830058,"request_ms":1790002830020,"inventory":{"pair_fast":{"qty":[0.0,0.0],"cash":0.0,"lots":[[],[]],"floor":0.0},"pair_250":{"qty":[0.0,0.0],"cash":0.0,"lots":[[],[]],"floor":0.0},"pair_add_fast":{"qty":[0.0,0.0],"cash":0.0,"lots":[[],[]],"floor":0.0},"pair_add_250":{"qty":[0.0,0.0],"cash":0.0,"lots":[[],[]],"floor":0.0}}}
{"kind":"decision","recorded_ms":1790003020078,"S":1790002800,"age":220,"signal":{"rsi14":54.52310876807171,"volume_ratio":1.0263703627862315,"taker_buy_fraction":0.5187527126641344,"volume5":360.66942,"return1":5.201623073855248,"return5":15.316471608709376,"return15":9.193836803465711,"bollinger_z":0.6059049779351972,"bar_close_ms":1790002979999,"ref":85799.90972905437,"reference_received_ms":1790002801325,"spot":85965.08692083976,"twap":85961.63288188755,"sigma":4.541007618905951,"spot_z":4.068758927718547,"twap_z":3.9836766492779914,"momentum":0.10668256134309277,"decision_ms":1790003020077,"momentum30":-0.22597034080871153,"momentum60":0.16994072294324916,"spot_twap_gap":0.09819726120833003,"range60":0.7998236407557979,"final_mean":85965.08692083976,"final_z":5.756867884192194,"final_up_prob":0.999999995715554,"final_drift_up_prob":0.9999999991461536,"final_known_seconds":0,"final_sd":28.69219775547601,"final_drift_shift":7.647972908257669},"entry_side":null,"context_gap":null,"book_errors":[null,null],"books":[{"bid":0.99,"ask":null,"asks":[],"received_ms":1790003020065,"observed_ms":1790003020055,"hash":"39f2845b90f03e1999dd2ab5f97b0a0795ae01c7"},{"bid":null,"ask":0.01,"asks":[[0.01,7667.12]],"received_ms":1790003020076,"observed_ms":1790003020067,"hash":"2df0036b11d2245669ccf0a29c55ea729125fce4"}],"intents":{"pair_fast":null,"pair_250":null,"pair_add_fast":null,"pair_add_250":null},"decision_ms":1790003020078,"feature_cutoff_ms":1790003020077,"request_ms":1790003020040,"inventory":{"pair_fast":{"qty":[0.0,5.0],"cash":1.67616,"lots":[[],[[5.0,0.33523200000000003]]],"floor":-1.67616},"pair_250":{"qty":[0.0,5.0],"cash":1.67616,"lots":[[],[[5.0,0.33523200000000003]]],"floor":-1.67616},"pair_add_fast":{"qty":[0.0,5.0],"cash":1.67616,"lots":[[],[[5.0,0.33523200000000003]]],"floor":-1.67616},"pair_add_250":{"qty":[0.0,5.0],"cash":1.67616,"lots":[[],[[5.0,0.33523200000000003]]],"floor":-1.67616}}}
{"kind":"decision","recorded_ms":1790003030033,"S":1790002800,"age":230,"signal":{"rsi14":54.52310876807171,"volume_ratio":1.0263703627862315,"taker_buy_fraction":0.5187527126641344,"volume5":360.66942,"return1":5.201623073855248,"return5":15.316471608709376,"return15":9.193836803465711,"bollinger_z":0.6059049779351972,"bar_close_ms":1790002979999,"ref":85799.90972905437,"reference_received_ms":1790002801325,"spot":85958.57470286863,"twap":85962.65405927273,"sigma":3.5699628538407624,"spot_z":5.313340368467183,"twap_z":5.4499490259306285,"momentum":-0.11846118921498287,"decision_ms":1790003030032,"momentum30":-0.10172407380538823,"momentum60":0.15439727477600293,"spot_twap_gap":-0.14752048376174232,"range60":1.0173790022900835,"final_mean":85958.57470286863,"final_z":8.118737273155558,"final_up_prob":0.9999999999999998,"final_drift_up_prob":0.9999999999999978,"final_known_seconds":0,"final_sd":19.5430605124865,"final_drift_shift":-5.3450552824013196},"entry_side":null,"context_gap":null,"book_errors":[null,null],"books":[{"bid":0.99,"ask":null,"asks":[],"received_ms":1790003030029,"observed_ms":1790003030013,"hash":"3245965dcf93795fbc759c52347d0c5129d91b1a"},{"bid":null,"ask":0.01,"asks":[[0.01,8301.49]],"received_ms":1790003030031,"observed_ms":1790003030013,"hash":"9cbf68868607f887f2f3f751cc9d08f2bde36306"}],"intents":{"pair_fast":null,"pair_250":null,"pair_add_fast":null,"pair_add_250":null},"decision_ms":1790003030033,"feature_cutoff_ms":1790003030032,"request_ms":1790003030001,"inventory":{"pair_fast":{"qty":[0.0,5.0],"cash":1.67616,"lots":[[],[[5.0,0.33523200000000003]]],"floor":-1.67616},"pair_250":{"qty":[0.0,5.0],"cash":1.67616,"lots":[[],[[5.0,0.33523200000000003]]],"floor":-1.67616},"pair_add_fast":{"qty":[0.0,5.0],"cash":1.67616,"lots":[[],[[5.0,0.33523200000000003]]],"floor":-1.67616},"pair_add_250":{"qty":[0.0,5.0],"cash":1.67616,"lots":[[],[[5.0,0.33523200000000003]]],"floor":-1.67616}}}
{"kind":"decision","recorded_ms":1790003040050,"S":1790002800,"age":240,"signal":{"rsi14":54.52310876807171,"volume_ratio":1.0263703627862315,"taker_buy_fraction":0.5187527126641344,"volume5":360.66942,"return1":5.201623073855248,"return5":15.316471608709376,"return15":9.193836803465711,"bollinger_z":0.6059049779351972,"bar_close_ms":1790002979999,"ref":85799.90972905437,"reference_received_ms":1790002801325,"spot":85945.00218555906,"twap":85962.80372325101,"sigma":2.087735889700792,"spot_z":8.97568161686762,"twap_z":10.076916915123467,"momentum":-2.0631674467483005,"decision_ms":1790003040048,"momentum30":-1.6224556912617882,"momentum60":-1.5025782526144391,"spot_twap_gap":-1.1007947151094193,"range60":1.797468328028781,"final_mean":85945.00218555906,"final_z":15.5587836451174,"final_up_prob":1.0,"final_drift_up_prob":1.0,"final_known_seconds":0,"final_sd":9.325436988785457,"final_drift_shift":-40.797743006515816},"entry_side":null,"context_gap":null,"book_errors":[null,null],"books":[{"bid":0.99,"ask":null,"asks":[],"received_ms":1790003040048,"observed_ms":1790003040037,"hash":"61c3546b74ad3c8b851097d660977086da05c77a"},{"bid":null,"ask":0.01,"asks":[[0.01,14475.89]],"received_ms":1790003040045,"observed_ms":1790003040036,"hash":"8598ce6e5057efc8f4b32339b19bf7bd4310bded"}],"intents":{"pair_fast":null,"pair_250":null,"pair_add_fast":null,"pair_add_250":null},"decision_ms":1790003040050,"feature_cutoff_ms":1790003040048,"request_ms":1790003040008,"inventory":{"pair_fast":{"qty":[0.0,5.0],"cash":1.67616,"lots":[[],[[5.0,0.33523200000000003]]],"floor":-1.67616},"pair_250":{"qty":[0.0,5.0],"cash":1.67616,"lots":[[],[[5.0,0.33523200000000003]]],"floor":-1.67616},"pair_add_fast":{"qty":[0.0,5.0],"cash":1.67616,"lots":[[],[[5.0,0.33523200000000003]]],"floor":-1.67616},"pair_add_250":{"qty":[0.0,5.0],"cash":1.67616,"lots":[[],[[5.0,0.33523200000000003]]],"floor":-1.67616}}}
{"kind":"decision","recorded_ms":1790003050097,"S":1790002800,"age":250,"signal":{"rsi14":48.37201345726155,"volume_ratio":0.5419356461327293,"taker_buy_fraction":0.5267196340656699,"volume5":335.65803999999997,"return1":-3.5911417108486843,"return5":17.798661540652144,"return15":6.170202667427024,"bollinger_z":0.2541824930404804,"bar_close_ms":1790003039999,"ref":85799.90972905437,"reference_received_ms":1790002801325,"spot":85935.78218322954,"twap":85958.85113780833,"sigma":2.262735864953277,"spot_z":8.500214406828341,"twap_z":9.943413922517449,"momentum":-1.2144372161502706,"decision_ms":1790003050096,"momentum30":-1.946974189104961,"momentum60":-1.9926369038208327,"spot_twap_gap":-1.3161895190966664,"range60":1.9928918419689505,"final_mean":85936.12276601393,"final_z":17.745721292963637,"final_up_prob":1.0,"final_drift_up_prob":1.0,"final_known_seconds":10,"final_sd":7.675824200708267,"final_drift_shift":-18.034262953748108},"entry_side":null,"context_gap":null,"book_errors":[null,null],"books":[{"bid":0.99,"ask":null,"asks":[],"received_ms":1790003050096,"observed_ms":1790003050076,"hash":"701cf2e1c2fe6252eeeeaeeecd60aeb02091bab4"},{"bid":null,"ask":0.01,"asks":[[0.01,19211.15]],"received_ms":1790003050082,"observed_ms":1790003050071,"hash":"f7e6ac320ad9caf147250df9854f382c958f0985"}],"intents":{"pair_fast":null,"pair_250":null,"pair_add_fast":null,"pair_add_250":null},"decision_ms":1790003050097,"feature_cutoff_ms":1790003050096,"request_ms":1790003050045,"inventory":{"pair_fast":{"qty":[0.0,5.0],"cash":1.67616,"lots":[[],[[5.0,0.33523200000000003]]],"floor":-1.67616},"pair_250":{"qty":[0.0,5.0],"cash":1.67616,"lots":[[],[[5.0,0.33523200000000003]]],"floor":-1.67616},"pair_add_fast":{"qty":[0.0,5.0],"cash":1.67616,"lots":[[],[[5.0,0.33523200000000003]]],"floor":-1.67616},"pair_add_250":{"qty":[0.0,5.0],"cash":1.67616,"lots":[[],[[5.0,0.33523200000000003]]],"floor":-1.67616}}}
{"kind":"decision","recorded_ms":1790003060058,"S":1790002800,"age":260,"signal":{"rsi14":48.37201345726155,"volume_ratio":0.5419356461327293,"taker_buy_fraction":0.5267196340656699,"volume5":335.65803999999997,"return1":-3.5911417108486843,"return5":17.798661540652144,"return15":6.170202667427024,"bollinger_z":0.2541824930404804,"bar_close_ms":1790003039999,"ref":85799.90972905437,"reference_received_ms":1790002801325,"spot":85880.02274335154,"twap":85950.77243746058,"sigma":5.917051515754483,"spot_z":2.142258850091192,"twap_z":4.0341382117155415,"momentum":-2.3189622777351158,"decision_ms":1790003060056,"momentum30":-2.4252649592014066,"momentum60":-1.7572605191873796,"spot_twap_gap":-1.5436313525635255,"range60":1.8578351443764916,"final_mean":85892.26705905951,"final_z":6.425405887869294,"final_up_prob":0.9999999999342409,"final_drift_up_prob":0.9920599147423028,"final_known_seconds":20,"final_sd":14.373773675449788,"final_drift_shift":-57.6927040353321},"entry_side":null,"context_gap":null,"book_errors":[null,null],"books":[{"bid":0.99,"ask":null,"asks":[],"received_ms":1790003060056,"observed_ms":1790003060023,"hash":"a7805c3b5e4a256ad72c9e8d3518b1ce5e7f8256"},{"bid":null,"ask":0.01,"asks":[[0.01,24340.27]],"received_ms":1790003060047,"observed_ms":1790003060023,"hash":"337c5076b29f29014f2449ded264047f2990d986"}],"intents":{"pair_fast":null,"pair_250":null,"pair_add_fast":null,"pair_add_250":null},"decision_ms":1790003060058,"feature_cutoff_ms":1790003060056,"request_ms":1790003060019,"inventory":{"pair_fast":{"qty":[0.0,5.0],"cash":1.67616,"lots":[[],[[5.0,0.33523200000000003]]],"floor":-1.67616},"pair_250":{"qty":[0.0,5.0],"cash":1.67616,"lots":[[],[[5.0,0.33523200000000003]]],"floor":-1.67616},"pair_add_fast":{"qty":[0.0,5.0],"cash":1.67616,"lots":[[],[[5.0,0.33523200000000003]]],"floor":-1.67616},"pair_add_250":{"qty":[0.0,5.0],"cash":1.67616,"lots":[[],[[5.0,0.33523200000000003]]],"floor":-1.67616}}}
{"kind":"decision","recorded_ms":1790003070066,"S":1790002800,"age":270,"signal":{"rsi14":48.37201345726155,"volume_ratio":0.5419356461327293,"taker_buy_fraction":0.5267196340656699,"volume5":335.65803999999997,"return1":-3.5911417108486843,"return5":17.798661540652144,"return15":6.170202667427024,"bollinger_z":0.2541824930404804,"bar_close_ms":1790003039999,"ref":85799.90972905437,"reference_received_ms":1790002801325,"spot":85902.79951218302,"twap":85938.01821877704,"sigma":6.471325367533651,"spot_z":2.9059583472100865,"twap_z":3.9006547232038287,"momentum":0.9953014341034309,"decision_ms":1790003070065,"momentum30":-1.1756964648390449,"momentum60":-1.212038500801016,"spot_twap_gap":-0.7025941692353468,"range60":1.659141697282449,"final_mean":85906.1457895625,"final_z":10.416497330943649,"final_up_prob":1.0,"final_drift_up_prob":1.0,"final_known_seconds":30,"final_sd":10.198827603262089,"final_drift_shift":15.20985742533066},"entry_side":null,"context_gap":null,"book_errors":[null,null],"books":[{"bid":0.99,"ask":null,"asks":[],"received_ms":1790003070063,"observed_ms":1790003070054,"hash":"cd9a6b57d37f42ddd96bde5233858fdc88fbd07a"},{"bid":null,"ask":0.01,"asks":[[0.01,33430.59]],"received_ms":1790003070065,"observed_ms":1790003070054,"hash":"84c3906236fee1e845c0b8541da3f51802deb234"}],"intents":{"pair_fast":null,"pair_250":null,"pair_add_fast":null,"pair_add_250":null},"decision_ms":1790003070066,"feature_cutoff_ms":1790003070065,"request_ms":1790003070031,"inventory":{"pair_fast":{"qty":[0.0,5.0],"cash":1.67616,"lots":[[],[[5.0,0.33523200000000003]]],"floor":-1.67616},"pair_250":{"qty":[0.0,5.0],"cash":1.67616,"lots":[[],[[5.0,0.33523200000000003]]],"floor":-1.67616},"pair_add_fast":{"qty":[0.0,5.0],"cash":1.67616,"lots":[[],[[5.0,0.33523200000000003]]],"floor":-1.67616},"pair_add_250":{"qty":[0.0,5.0],"cash":1.67616,"lots":[[],[[5.0,0.33523200000000003]]],"floor":-1.67616}}}
{"kind":"decision","recorded_ms":1790003080078,"S":1790002800,"age":280,"signal":{"rsi14":48.37201345726155,"volume_ratio":0.5419356461327293,"taker_buy_fraction":0.5267196340656699,"volume5":335.65803999999997,"return1":-3.5911417108486843,"return5":17.798661540652144,"return15":6.170202667427024,"bollinger_z":0.2541824930404804,"bar_close_ms":1790003039999,"ref":85799.90972905437,"reference_received_ms":1790002801325,"spot":85923.37613522331,"twap":85929.07151416913,"sigma":6.948466482544882,"spot_z":3.980911029345476,"twap_z":4.164546380573684,"momentum":1.0494888095624493,"decision_ms":1790003080077,"momentum30":-0.000986531276316991,"momentum60":-0.6788209444714655,"spot_twap_gap":-0.10581763070990327,"range60":1.4474564893576942,"final_mean":85915.54507796107,"final_z":19.448289933477852,"final_up_prob":1.0,"final_drift_up_prob":1.0,"final_known_seconds":40,"final_sd":5.945784914880602,"final_drift_shift":7.627724649595611},"entry_side":null,"context_gap":null,"book_errors":[null,null],"books":[{"bid":0.999,"ask":null,"asks":[],"received_ms":1790003080077,"observed_ms":1790003080060,"hash":"00141d096a880948b3741cc89e6961f354c5635c"},{"bid":null,"ask":0.001,"asks":[[0.001,21126.36]],"received_ms":1790003080070,"observed_ms":1790003080060,"hash":"cd73cae38ff31094e9208b83c63f41c86f160604"}],"intents":{"pair_fast":null,"pair_250":null,"pair_add_fast":null,"pair_add_250":null},"decision_ms":1790003080078,"feature_cutoff_ms":1790003080077,"request_ms":1790003080040,"inventory":{"pair_fast":{"qty":[0.0,5.0],"cash":1.67616,"lots":[[],[[5.0,0.33523200000000003]]],"floor":-1.67616},"pair_250":{"qty":[0.0,5.0],"cash":1.67616,"lots":[[],[[5.0,0.33523200000000003]]],"floor":-1.67616},"pair_add_fast":{"qty":[0.0,5.0],"cash":1.67616,"lots":[[],[[5.0,0.33523200000000003]]],"floor":-1.67616},"pair_add_250":{"qty":[0.0,5.0],"cash":1.67616,"lots":[[],[[5.0,0.33523200000000003]]],"floor":-1.67616}}}
{"kind":"decision","recorded_ms":1790003090033,"S":1790002800,"age":290,"signal":{"rsi14":48.37201345726155,"volume_ratio":0.5419356461327293,"taker_buy_fraction":0.5267196340656699,"volume5":335.65803999999997,"return1":-3.5911417108486843,"return5":17.798661540652144,"return15":6.170202667427024,"bollinger_z":0.2541824930404804,"bar_close_ms":1790003039999,"ref":85799.90972905437,"reference_received_ms":1790002801325,"spot":85973.28205304065,"twap":85924.629749741,"sigma":8.284309012575024,"spot_z":6.628231684822751,"twap_z":4.768195833334328,"momentum":1.3109878832697117,"decision_ms":1790003090031,"momentum30":2.002213950227475,"momentum60":0.22843757236358098,"spot_twap_gap":0.7581785443145058,"range60":1.4224076611787542,"final_mean":85928.83117718644,"final_z":51.381095798428454,"final_up_prob":1.0,"final_drift_up_prob":1.0,"final_known_seconds":50,"final_sd":2.509122200075968,"final_drift_shift":2.844309963688721},"entry_side":null,"context_gap":null,"book_errors":[null,null],"books":[{"bid":0.999,"ask":null,"asks":[],"received_ms":1790003090031,"observed_ms":1790003090000,"hash":"a318f901c967bd4b4e4abaeeadf33895f38c2580"},{"bid":null,"ask":0.001,"asks":[[0.001,11669.64]],"received_ms":1790003090025,"observed_ms":1790003090000,"hash":"5ab7207c815c40ea9a35b7bb87abe936bede6d3c"}],"intents":{"pair_fast":null,"pair_250":null,"pair_add_fast":null,"pair_add_250":null},"decision_ms":1790003090033,"feature_cutoff_ms":1790003090031,"request_ms":1790003090002,"inventory":{"pair_fast":{"qty":[0.0,5.0],"cash":1.67616,"lots":[[],[[5.0,0.33523200000000003]]],"floor":-1.67616},"pair_250":{"qty":[0.0,5.0],"cash":1.67616,"lots":[[],[[5.0,0.33523200000000003]]],"floor":-1.67616},"pair_add_fast":{"qty":[0.0,5.0],"cash":1.67616,"lots":[[],[[5.0,0.33523200000000003]]],"floor":-1.67616},"pair_add_250":{"qty":[0.0,5.0],"cash":1.67616,"lots":[[],[[5.0,0.33523200000000003]]],"floor":-1.67616}}}
{"kind":"decision","recorded_ms":1790003130095,"S":1790003100,"age":30,"signal":{"rsi14":46.2396237842457,"volume_ratio":0.5463373938516419,"taker_buy_fraction":0.5819864764754052,"volume5":299.20898,"return1":3.603802238124075,"return5":17.253828269461533,"return15":0.28374564249697753,"bollinger_z":0.47476402690080793,"bar_close_ms":1790003099999,"ref":85929.17715486501,"reference_received_ms":1790003100999,"spot":86017.8039803154,"twap":85971.64341824641,"sigma":8.580562687061272,"spot_z":0.6286995587644667,"twap_z":0.3012465008713375,"momentum":-0.5248797930940807,"decision_ms":1790003130094,"momentum30":0.599237734926448,"momentum60":1.7676774102663153,"spot_twap_gap":0.6945119050460364,"range60":1.9819586884959999,"final_mean":86017.8039803154,"final_z":0.6811994244277625,"final_up_prob":0.7521273439094641,"final_drift_up_prob":0.025888177425695102,"final_known_seconds":0,"final_sd":130.10408152477754,"final_drift_shift":-341.67777599577806},"entry_side":null,"context_gap":null,"book_errors":[null,null],"books":[{"bid":0.72,"ask":0.73,"asks":[[0.73,605.17]],"received_ms":1790003130064,"observed_ms":1790003130056,"hash":"fae2e2c8d1e1d617ffc3b74689625fcf3f86b0f3"},{"bid":0.27,"ask":0.28,"asks":[[0.28,159.51]],"received_ms":1790003130094,"observed_ms":1790003130071,"hash":"f10c8f370b64aab9f67eb11f37435446990c1898"}],"intents":{"pair_fast":{"kind":"first","side":1,"qty":5.0,"participation":true,"max_cost":1.5205600000000001},"pair_250":{"kind":"first","side":1,"qty":5.0,"participation":true,"max_cost":1.5205600000000001},"pair_add_fast":{"kind":"first","side":1,"qty":5.0,"participation":true,"max_cost":1.5205600000000001},"pair_add_250":{"kind":"first","side":1,"qty":5.0,"participation":true,"max_cost":1.5205600000000001}},"decision_ms":1790003130095,"feature_cutoff_ms":1790003130094,"request_ms":1790003130035,"inventory":{"pair_fast":{"qty":[0.0,0.0],"cash":0.0,"lots":[[],[]],"floor":0.0},"pair_250":{"qty":[0.0,0.0],"cash":0.0,"lots":[[],[]],"floor":0.0},"pair_add_fast":{"qty":[0.0,0.0],"cash":0.0,"lots":[[],[]],"floor":0.0},"pair_add_250":{"qty":[0.0,0.0],"cash":0.0,"lots":[[],[]],"floor":0.0}}}
{"kind":"decision","recorded_ms":1790003290057,"S":1790003100,"age":190,"signal":{"rsi14":61.247190884348875,"volume_ratio":1.0078563941201972,"taker_buy_fraction":0.6675470276660921,"volume5":254.13817,"return1":24.56248187920817,"return5":23.208534670619407,"return15":7.835954967274226,"bollinger_z":2.304942989282478,"bar_close_ms":1790003279999,"ref":85929.17715486501,"reference_received_ms":1790003100999,"spot":86237.92383933548,"twap":86070.62443098487,"sigma":11.40064056606121,"spot_z":2.582779211326954,"twap_z":1.1832583235274838,"momentum":2.0848168380044267,"decision_ms":1790003290056,"momentum30":2.6206271965313737,"momentum60":2.5057452619156866,"spot_twap_gap":1.8944778252230778,"range60":2.5057452619156866,"final_mean":86237.92383933548,"final_z":3.238156364413637,"final_up_prob":0.9993984757340562,"final_drift_up_prob":1.0,"final_known_seconds":0,"final_sd":95.34644091418635,"final_drift_shift":600.8734765790243},"entry_side":null,"context_gap":null,"book_errors":[null,null],"books":[{"bid":0.99,"ask":null,"asks":[],"received_ms":1790003290056,"observed_ms":1790003290044,"hash":"7daffc9d2f7cdcd82e286d44ca38177dc6589778"},{"bid":null,"ask":0.01,"asks":[[0.01,5388.2]],"received_ms":1790003290055,"observed_ms":1790003290044,"hash":"a05e8e9ffc97e8cedb1744dd1bc47e237125d51a"}],"intents":{"pair_fast":null,"pair_250":null,"pair_add_fast":null,"pair_add_250":null},"decision_ms":1790003290057,"feature_cutoff_ms":1790003290056,"request_ms":1790003290017,"inventory":{"pair_fast":{"qty":[5.0,5.0],"cash":4.653020000000001,"lots":[[],[]],"floor":0.3469799999999994},"pair_250":{"qty":[5.0,5.0],"cash":4.653020000000001,"lots":[[],[]],"floor":0.3469799999999994},"pair_add_fast":{"qty":[5.0,5.0],"cash":4.653020000000001,"lots":[[],[]],"floor":0.3469799999999994},"pair_add_250":{"qty":[5.0,5.0],"cash":4.653020000000001,"lots":[[],[]],"floor":0.3469799999999994}}}
{"kind":"decision","recorded_ms":1790003300078,"S":1790003100,"age":200,"signal":{"rsi14":61.247190884348875,"volume_ratio":1.0078563941201972,"taker_buy_fraction":0.6675470276660921,"volume5":254.13817,"return1":24.56248187920817,"return5":23.208534670619407,"return15":7.835954967274226,"bollinger_z":2.304942989282478,"bar_close_ms":1790003279999,"ref":85929.17715486501,"reference_received_ms":1790003100999,"spot":86257.77353283191,"twap":86108.41903832517,"sigma":11.991330307576735,"spot_z":2.741338551160689,"twap_z":1.4953381049181182,"momentum":0.34090488463782354,"decision_ms":1790003300077,"momentum30":2.506841066258674,"momentum60":2.4790723087883153,"spot_twap_gap":1.6079602375735875,"range60":2.5195560929362015,"final_mean":86257.77353283191,"final_z":3.5399622577827063,"final_up_prob":0.9997999078709445,"final_drift_up_prob":0.999996815172709,"final_known_seconds":0,"final_sd":92.82482524904553,"final_drift_shift":90.39005357509839},"entry_side":null,"context_gap":null,"book_errors":[null,null],"books":[{"bid":0.99,"ask":null,"asks":[],"received_ms":1790003300056,"observed_ms":1790003300037,"hash":"eac69d982ac2c5cda12b3a2ab1be12cad9dd1e5f"},{"bid":null,"ask":0.01,"asks":[[0.01,11837.76]],"received_ms":1790003300076,"observed_ms":1790003300055,"hash":"17496fc8efa57469a18bc1577b5f82ebb2b1c47a"}],"intents":{"pair_fast":null,"pair_250":null,"pair_add_fast":null,"pair_add_250":null},"decision_ms":1790003300078,"feature_cutoff_ms":1790003300077,"request_ms":1790003300031,"inventory":{"pair_fast":{"qty":[5.0,5.0],"cash":4.653020000000001,"lots":[[],[]],"floor":0.3469799999999994},"pair_250":{"qty":[5.0,5.0],"cash":4.653020000000001,"lots":[[],[]],"floor":0.3469799999999994},"pair_add_fast":{"qty":[5.0,5.0],"cash":4.653020000000001,"lots":[[],[]],"floor":0.3469799999999994},"pair_add_250":{"qty":[5.0,5.0],"cash":4.653020000000001,"lots":[[],[]],"floor":0.3469799999999994}}}
{"kind":"decision","recorded_ms":1790003310086,"S":1790003100,"age":210,"signal":{"rsi14":61.247190884348875,"volume_ratio":1.0078563941201972,"taker_buy_fraction":0.6675470276660921,"volume5":254.13817,"return1":24.56248187920817,"return5":23.208534670619407,"return15":7.835954967274226,"bollinger_z":2.304942989282478,"bar_close_ms":1790003279999,"ref":85929.17715486501,"reference_received_ms":1790003100999,"spot":86292.29581161618,"twap":86154.08820723023,"sigma":12.637432889395237,"spot_z":3.0301994277219886,"twap_z":1.8768667747977386,"momentum":0.3599043527299328,"decision_ms":1790003310084,"momentum30":1.8713866037719287,"momentum60":2.6420708588296655,"spot_twap_gap":1.4118789124099034,"range60":2.7207007060510238,"final_mean":86292.29581161618,"final_z":4.0669591793824855,"final_up_prob":0.999976184708775,"final_drift_up_prob":0.9999997574863468,"final_known_seconds":0,"final_sd":89.28505075536464,"final_drift_shift":86.17648435688679},"entry_side":null,"context_gap":null,"book_errors":[null,null],"books":[{"bid":0.99,"ask":null,"asks":[],"received_ms":1790003310084,"observed_ms":1790003310074,"hash":"328c171a760728df22e72b03b32c277a82fb471e"},{"bid":null,"ask":0.01,"asks":[[0.01,5196.15]],"received_ms":1790003310083,"observed_ms":1790003310070,"hash":"7525ef3f75068fefec5ebc6b6fd6c8320020ba78"}],"intents":{"pair_fast":null,"pair_250":null,"pair_add_fast":null,"pair_add_250":null},"decision_ms":1790003310086,"feature_cutoff_ms":1790003310084,"request_ms":1790003310049,"inventory":{"pair_fast":{"qty":[5.0,5.0],"cash":4.653020000000001,"lots":[[],[]],"floor":0.3469799999999994},"pair_250":{"qty":[5.0,5.0],"cash":4.653020000000001,"lots":[[],[]],"floor":0.3469799999999994},"pair_add_fast":{"qty":[5.0,5.0],"cash":4.653020000000001,"lots":[[],[]],"floor":0.3469799999999994},"pair_add_250":{"qty":[5.0,5.0],"cash":4.653020000000001,"lots":[[],[]],"floor":0.3469799999999994}}}
{"kind":"decision","recorded_ms":1790003320048,"S":1790003100,"age":220,"signal":{"rsi14":61.247190884348875,"volume_ratio":1.0078563941201972,"taker_buy_fraction":0.6675470276660921,"volume5":254.13817,"return1":24.56248187920817,"return5":23.208534670619407,"return15":7.835954967274226,"bollinger_z":2.304942989282478,"bar_close_ms":1790003279999,"ref":85929.17715486501,"reference_received_ms":1790003100999,"spot":86319.18526216024,"twap":86193.13080694077,"sigma":12.065448089002393,"spot_z":3.6150374220413872,"twap_z":2.4466217806493553,"momentum":0.4087445065789261,"decision_ms":1790003320047,"momentum30":1.1248938558758064,"momentum60":2.620450772743498,"spot_twap_gap":1.3487737937813828,"range60":2.620450772743498,"final_mean":86319.18526216024,"final_z":5.113938271942275,"final_up_prob":0.9999998422447507,"final_drift_up_prob":0.999999999575379,"final_known_seconds":0,"final_sd":76.26374949322678,"final_drift_shift":77.90349832555464},"entry_side":null,"context_gap":null,"book_errors":[null,null],"books":[{"bid":0.99,"ask":null,"asks":[],"received_ms":1790003320047,"observed_ms":1790003320039,"hash":"a96b633f3fae59db2f04723e42752779af922c5c"},{"bid":null,"ask":0.01,"asks":[[0.01,6726.97]],"received_ms":1790003320042,"observed_ms":1790003320024,"hash":"c9b671d63f6bd2b3565b0a740c3b5e726ed3df95"}],"intents":{"pair_fast":null,"pair_250":null,"pair_add_fast":null,"pair_add_250":null},"decision_ms":1790003320048,"feature_cutoff_ms":1790003320047,"request_ms":1790003320010,"inventory":{"pair_fast":{"qty":[5.0,5.0],"cash":4.653020000000001,"lots":[[],[]],"floor":0.3469799999999994},"pair_250":{"qty":[5.0,5.0],"cash":4.653020000000001,"lots":[[],[]],"floor":0.3469799999999994},"pair_add_fast":{"qty":[5.0,5.0],"cash":4.653020000000001,"lots":[[],[]],"floor":0.3469799999999994},"pair_add_250":{"qty":[5.0,5.0],"cash":4.653020000000001,"lots":[[],[]],"floor":0.3469799999999994}}}
{"kind":"decision","recorded_ms":1790003330058,"S":1790003100,"age":230,"signal":{"rsi14":61.247190884348875,"volume_ratio":1.0078563941201972,"taker_buy_fraction":0.6675470276660921,"volume5":254.13817,"return1":24.56248187920817,"return5":23.208534670619407,"return15":7.835954967274226,"bollinger_z":2.304942989282478,"bar_close_ms":1790003279999,"ref":85929.17715486501,"reference_received_ms":1790003100999,"spot":86293.50876034,"twap":86233.36441860825,"sigma":12.265619757338394,"spot_z":3.551691387160394,"twap_z":2.9653734907577682,"momentum":-0.6965268837146743,"decision_ms":1790003330057,"momentum30":0.23214451605512249,"momentum60":2.1090888531523517,"spot_twap_gap":0.6330378149225045,"range60":2.3934447626909896,"final_mean":86293.50876034,"final_z":5.428248171207951,"final_up_prob":0.999999971545064,"final_drift_up_prob":0.9999333964168442,"final_known_seconds":0,"final_sd":67.11771348396431,"final_drift_shift":-107.91158258809774},"entry_side":1,"context_gap":null,"book_errors":[null,null],"books":[{"bid":0.99,"ask":null,"asks":[],"received_ms":1790003330053,"observed_ms":1790003330045,"hash":"724b97396ccb24c421ed4322f9637bff5b904f33"},{"bid":null,"ask":0.01,"asks":[[0.01,13975.87]],"received_ms":1790003330057,"observed_ms":1790003330045,"hash":"aee1e791f3c337ed8af49ba831f49cac2234479b"}],"intents":{"pair_fast":null,"pair_250":null,"pair_add_fast":null,"pair_add_250":null},"decision_ms":1790003330058,"feature_cutoff_ms":1790003330057,"request_ms":1790003330021,"inventory":{"pair_fast":{"qty":[5.0,5.0],"cash":4.653020000000001,"lots":[[],[]],"floor":0.3469799999999994},"pair_250":{"qty":[5.0,5.0],"cash":4.653020000000001,"lots":[[],[]],"floor":0.3469799999999994},"pair_add_fast":{"qty":[5.0,5.0],"cash":4.653020000000001,"lots":[[],[]],"floor":0.3469799999999994},"pair_add_250":{"qty":[5.0,5.0],"cash":4.653020000000001,"lots":[[],[]],"floor":0.3469799999999994}}}
{"kind":"decision","recorded_ms":1790003340070,"S":1790003100,"age":240,"signal":{"rsi14":61.247190884348875,"volume_ratio":1.0078563941201972,"taker_buy_fraction":0.6675470276660921,"volume5":254.13817,"return1":24.56248187920817,"return5":23.208534670619407,"return15":7.835954967274226,"bollinger_z":2.304942989282478,"bar_close_ms":1790003279999,"ref":85929.17715486501,"reference_received_ms":1790003100999,"spot":86245.32591005086,"twap":86259.25240401806,"sigma":11.711864630803571,"spot_z":3.4869014246445933,"twap_z":3.640500990855082,"momentum":-0.5775940157449594,"decision_ms":1790003340069,"momentum30":-0.9082670769680727,"momentum60":0.9100984284950169,"spot_twap_gap":-0.15351122104605025,"range60":1.7390168793943486,"final_mean":86245.32591005086,"final_z":6.046443839460751,"final_up_prob":0.9999999992596109,"final_drift_up_prob":0.9999992889661786,"final_known_seconds":0,"final_sd":52.286726475911514,"final_drift_shift":-64.02808776677949},"entry_side":1,"context_gap":null,"book_errors":[null,null],"books":[{"bid":0.99,"ask":null,"asks":[],"received_ms":1790003340067,"observed_ms":1790003340056,"hash":"4108112682dde732f5bd6854683fd639490b44f0"},{"bid":null,"ask":0.01,"asks":[[0.01,14124.3]],"received_ms":1790003340069,"observed_ms":1790003340058,"hash":"1cda96d61259ed47c8d5ec1ee3f9311d9cb1adbd"}],"intents":{"pair_fast":null,"pair_250":null,"pair_add_fast":null,"pair_add_250":null},"decision_ms":1790003340070,"feature_cutoff_ms":1790003340069,"request_ms":1790003340031,"inventory":{"pair_fast":{"qty":[5.0,5.0],"cash":4.653020000000001,"lots":[[],[]],"floor":0.3469799999999994},"pair_250":{"qty":[5.0,5.0],"cash":4.653020000000001,"lots":[[],[]],"floor":0.3469799999999994},"pair_add_fast":{"qty":[5.0,5.0],"cash":4.653020000000001,"lots":[[],[]],"floor":0.3469799999999994},"pair_add_250":{"qty":[5.0,5.0],"cash":4.653020000000001,"lots":[[],[]],"floor":0.3469799999999994}}}
{"kind":"decision","recorded_ms":1790003350077,"S":1790003100,"age":250,"signal":{"rsi14":60.81664344926864,"volume_ratio":1.9779308870087393,"taker_buy_fraction":0.6958987401019693,"volume5":337.22491,"return1":8.119405808807485,"return5":34.88770956825107,"return15":31.210560050042147,"bollinger_z":2.436831262357481,"bar_close_ms":1790003339999,"ref":85929.17715486501,"reference_received_ms":1790003100999,"spot":86210.58212770168,"twap":86271.54725988176,"sigma":9.03018967466402,"spot_z":4.41042263013795,"twap_z":5.3659210206103545,"momentum":-1.291728434055834,"decision_ms":1790003350076,"momentum30":-2.2228501606056,"momentum60":-0.48985734768257927,"spot_twap_gap":-0.8715835441613025,"range60":1.571792422125826,"final_mean":86212.05824279085,"final_z":9.229004477196577,"final_up_prob":1.0,"final_drift_up_prob":0.9999999999914868,"final_known_seconds":10,"final_sd":30.651311159810668,"final_drift_shift":-76.61355159631893},"entry_side":1,"context_gap":null,"book_errors":[null,null],"books":[{"bid":0.999,"ask":null,"asks":[],"received_ms":1790003350075,"observed_ms":1790003350055,"hash":"79dc2d8ac682aa880cf6e84c2bf3351415295b1b"},{"bid":null,"ask":0.001,"asks":[[0.001,11115.88]],"received_ms":1790003350045,"observed_ms":1790003350029,"hash":"98219af8786e51d173978a4b9023ac6cfc328d0d"}],"intents":{"pair_fast":null,"pair_250":null,"pair_add_fast":null,"pair_add_250":null},"decision_ms":1790003350077,"feature_cutoff_ms":1790003350076,"request_ms":1790003350019,"inventory":{"pair_fast":{"qty":[5.0,5.0],"cash":4.653020000000001,"lots":[[],[]],"floor":0.3469799999999994},"pair_250":{"qty":[5.0,5.0],"cash":4.653020000000001,"lots":[[],[]],"floor":0.3469799999999994},"pair_add_fast":{"qty":[5.0,5.0],"cash":4.653020000000001,"lots":[[],[]],"floor":0.3469799999999994},"pair_add_250":{"qty":[5.0,5.0],"cash":4.653020000000001,"lots":[[],[]],"floor":0.3469799999999994}}}
{"kind":"decision","recorded_ms":1790003360030,"S":1790003100,"age":260,"signal":{"rsi14":60.81664344926864,"volume_ratio":1.9779308870087393,"taker_buy_fraction":0.6958987401019693,"volume5":337.22491,"return1":8.119405808807485,"return5":34.88770956825107,"return15":31.210560050042147,"bollinger_z":2.436831262357481,"bar_close_ms":1790003339999,"ref":85929.17715486501,"reference_received_ms":1790003100999,"spot":86220.61917647484,"twap":86266.95764037769,"sigma":8.653945762758028,"spot_z":5.326789011550405,"twap_z":6.173733522044827,"momentum":-0.11662145288566224,"decision_ms":1790003360029,"momentum30":-0.9725522960458026,"momentum60":-0.8547074063152592,"spot_twap_gap":-0.691276572577693,"range60":1.648712301826216,"final_mean":86219.91585868485,"final_z":13.816022725878277,"final_up_prob":1.0,"final_drift_up_prob":1.0,"final_known_seconds":20,"final_sd":21.043588997234636,"final_drift_shift":-4.249143487944739},"entry_side":1,"context_gap":null,"book_errors":[null,null],"books":[{"bid":0.999,"ask":null,"asks":[],"received_ms":1790003360028,"observed_ms":1790003360009,"hash":"b65e6620cd90255762953c7523541508df988fe6"},{"bid":null,"ask":0.001,"asks":[[0.001,16284.69]],"received_ms":1790003360029,"observed_ms":1790003360009,"hash":"98e1a8419e16e827fb7eac586bbbbd8089e24270"}],"intents":{"pair_fast":null,"pair_250":null,"pair_add_fast":null,"pair_add_250":null},"decision_ms":1790003360030,"feature_cutoff_ms":1790003360029,"request_ms":1790003360002,"inventory":{"pair_fast":{"qty":[5.0,5.0],"cash":4.653020000000001,"lots":[[],[]],"floor":0.3469799999999994},"pair_250":{"qty":[5.0,5.0],"cash":4.653020000000001,"lots":[[],[]],"floor":0.3469799999999994},"pair_add_fast":{"qty":[5.0,5.0],"cash":4.653020000000001,"lots":[[],[]],"floor":0.3469799999999994},"pair_add_250":{"qty":[5.0,5.0],"cash":4.653020000000001,"lots":[[],[]],"floor":0.3469799999999994}}}
{"kind":"decision","recorded_ms":1790003370055,"S":1790003100,"age":270,"signal":{"rsi14":60.81664344926864,"volume_ratio":1.9779308870087393,"taker_buy_fraction":0.6958987401019693,"volume5":337.22491,"return1":8.119405808807485,"return5":34.88770956825107,"return15":31.210560050042147,"bollinger_z":2.436831262357481,"bar_close_ms":1790003339999,"ref":85929.17715486501,"reference_received_ms":1790003100999,"spot":86221.22709172037,"twap":86257.05538553235,"sigma":8.90704659025936,"spot_z":5.991754101534351,"twap_z":6.726814443304724,"momentum":-0.4556274186538581,"decision_ms":1790003370054,"momentum30":-0.5378928910825059,"momentum60":-1.1937731649918821,"spot_twap_gap":-0.519298152875116,"range60":1.601862827797396,"final_mean":86219.51023029206,"final_z":20.671235545074786,"final_up_prob":1.0,"final_drift_up_prob":1.0,"final_known_seconds":30,"final_sd":14.045269562816177,"final_drift_shift":-9.590471794157416},"entry_side":1,"context_gap":null,"book_errors":[null,null],"books":[{"bid":0.999,"ask":null,"asks":[],"received_ms":1790003370054,"observed_ms":1790003370033,"hash":"c40605b87656478c53b67bfae3b2856b7041c618"},{"bid":null,"ask":0.001,"asks":[[0.001,17424.94]],"received_ms":1790003370046,"observed_ms":1790003370027,"hash":"62970d7022a70f9626a19f07e49e8df72ec8c1bd"}],"intents":{"pair_fast":null,"pair_250":null,"pair_add_fast":null,"pair_add_250":null},"decision_ms":1790003370055,"feature_cutoff_ms":1790003370054,"request_ms":1790003370005,"inventory":{"pair_fast":{"qty":[5.0,5.0],"cash":4.653020000000001,"lots":[[],[]],"floor":0.3469799999999994},"pair_250":{"qty":[5.0,5.0],"cash":4.653020000000001,"lots":[[],[]],"floor":0.3469799999999994},"pair_add_fast":{"qty":[5.0,5.0],"cash":4.653020000000001,"lots":[[],[]],"floor":0.3469799999999994},"pair_add_250":{"qty":[5.0,5.0],"cash":4.653020000000001,"lots":[[],[]],"floor":0.3469799999999994}}}
{"kind":"decision","recorded_ms":1790003380061,"S":1790003100,"age":280,"signal":{"rsi14":60.81664344926864,"volume_ratio":1.9779308870087393,"taker_buy_fraction":0.6958987401019693,"volume5":337.22491,"return1":8.119405808807485,"return5":34.88770956825107,"return15":31.210560050042147,"bollinger_z":2.436831262357481,"bar_close_ms":1790003339999,"ref":85929.17715486501,"reference_received_ms":1790003100999,"spot":86225.38035519909,"twap":86244.09927557182,"sigma":8.232104636123493,"spot_z":8.05779634946141,"twap_z":8.56701855933336,"momentum":0.21506802688442525,"decision_ms":1790003380060,"momentum30":0.03481318843713323,"momentum60":-1.4921021159118686,"spot_twap_gap":-0.29355824975160333,"range60":1.7331979450050783,"final_mean":86220.64256811935,"final_z":41.32380366750172,"final_up_prob":1.0,"final_drift_up_prob":1.0,"final_known_seconds":40,"final_sd":7.053208741371347,"final_drift_shift":1.8550507572645247},"entry_side":null,"context_gap":null,"book_errors":[null,null],"books":[{"bid":0.999,"ask":null,"asks":[],"received_ms":1790003380060,"observed_ms":1790003380030,"hash":"0fc74b6a41fe613c0bffc0b6b4a5cef7c5536200"},{"bid":null,"ask":0.001,"asks":[[0.001,17484.94]],"received_ms":1790003380054,"observed_ms":1790003380029,"hash":"3f49daf4684f4fd41e9fd5d8f6ef6f07f6bacb09"}],"intents":{"pair_fast":null,"pair_250":null,"pair_add_fast":null,"pair_add_250":null},"decision_ms":1790003380061,"feature_cutoff_ms":1790003380060,"request_ms":1790003380029,"inventory":{"pair_fast":{"qty":[5.0,5.0],"cash":4.653020000000001,"lots":[[],[]],"floor":0.3469799999999994},"pair_250":{"qty":[5.0,5.0],"cash":4.653020000000001,"lots":[[],[]],"floor":0.3469799999999994},"pair_add_fast":{"qty":[5.0,5.0],"cash":4.653020000000001,"lots":[[],[]],"floor":0.3469799999999994},"pair_add_250":{"qty":[5.0,5.0],"cash":4.653020000000001,"lots":[[],[]],"floor":0.3469799999999994}}}
{"kind":"decision","recorded_ms":1790003390066,"S":1790003100,"age":290,"signal":{"rsi14":60.81664344926864,"volume_ratio":1.9779308870087393,"taker_buy_fraction":0.6958987401019693,"volume5":337.22491,"return1":8.119405808807485,"return5":34.88770956825107,"return15":31.210560050042147,"bollinger_z":2.436831262357481,"bar_close_ms":1790003339999,"ref":85929.17715486501,"reference_received_ms":1790003100999,"spot":86233.75786344832,"twap":86229.00958758674,"sigma":6.675852209693814,"spot_z":14.474772429689242,"twap_z":14.249117256551555,"momentum":0.35379664381189735,"decision_ms":1790003390065,"momentum30":-0.0082779034530785,"momentum60":-0.6373878068609741,"spot_twap_gap":0.09182344943864418,"range60":1.096693624382817,"final_mean":86222.49249837013,"final_z":145.8102794923678,"final_up_prob":1.0,"final_drift_up_prob":1.0,"final_known_seconds":50,"final_sd":2.0116232170069597,"final_drift_shift":0.6143486585443375},"entry_side":null,"context_gap":null,"book_errors":[null,null],"books":[{"bid":0.999,"ask":null,"asks":[],"received_ms":1790003390065,"observed_ms":1790003390056,"hash":"ade6141e0e9700eb8fa173f8fb47bfd88f23bc0b"},{"bid":null,"ask":0.001,"asks":[[0.001,18063.5]],"received_ms":1790003390063,"observed_ms":1790003390016,"hash":"57c5137cd33d64ba596611e811e6d6058fcc6988"}],"intents":{"pair_fast":null,"pair_250":null,"pair_add_fast":null,"pair_add_250":null},"decision_ms":1790003390066,"feature_cutoff_ms":1790003390065,"request_ms":1790003390035,"inventory":{"pair_fast":{"qty":[5.0,5.0],"cash":4.653020000000001,"lots":[[],[]],"floor":0.3469799999999994},"pair_250":{"qty":[5.0,5.0],"cash":4.653020000000001,"lots":[[],[]],"floor":0.3469799999999994},"pair_add_fast":{"qty":[5.0,5.0],"cash":4.653020000000001,"lots":[[],[]],"floor":0.3469799999999994},"pair_add_250":{"qty":[5.0,5.0],"cash":4.653020000000001,"lots":[[],[]],"floor":0.3469799999999994}}}
{"kind":"decision","recorded_ms":1790003430061,"S":1790003400,"age":30,"signal":{"rsi14":65.730426843187,"volume_ratio":0.5453347870442993,"taker_buy_fraction":0.6898711634987282,"volume5":343.65882,"return1":5.018203879276413,"return5":36.29768481323083,"return15":26.970383675346433,"bollinger_z":2.2922988117751095,"bar_close_ms":1790003399999,"ref":86226.37589448872,"reference_received_ms":1790003401345,"spot":86264.88695819957,"twap":86254.05359438437,"sigma":11.458609526707182,"spot_z":0.2045596501616901,"twap_z":0.147015949765619,"momentum":0.3830808788855185,"decision_ms":1790003430060,"momentum30":-0.4285521209714362,"momentum60":0.5081828464505351,"spot_twap_gap":0.12205505837297437,"range60":1.1475423484119365,"final_mean":86264.88695819957,"final_z":0.22163907579474193,"final_up_prob":0.5877025695741925,"final_drift_up_prob":0.9837610601788003,"final_known_seconds":0,"final_sd":173.7557493991239,"final_drift_shift":333.0619727218596},"entry_side":null,"context_gap":null,"book_errors":[null,null],"books":[{"bid":0.56,"ask":0.57,"asks":[[0.57,719.38]],"received_ms":1790003430060,"observed_ms":1790003430049,"hash":"e8f6859f9fcc6094eb832a5048a9ab7638e6ecee"},{"bid":0.43,"ask":0.44,"asks":[[0.44,25.0]],"received_ms":1790003430050,"observed_ms":1790003430038,"hash":"4ae43ed0f0bc9b8519caf7bedaef2dff3fcb91ad"}],"intents":{"pair_fast":{"kind":"first","side":1,"qty":5.0,"participation":true,"max_cost":2.33624},"pair_250":{"kind":"first","side":1,"qty":5.0,"participation":true,"max_cost":2.33624},"pair_add_fast":{"kind":"first","side":1,"qty":5.0,"participation":true,"max_cost":2.33624},"pair_add_250":{"kind":"first","side":1,"qty":5.0,"participation":true,"max_cost":2.33624}},"decision_ms":1790003430061,"feature_cutoff_ms":1790003430060,"request_ms":1790003430013,"inventory":{"pair_fast":{"qty":[0.0,0.0],"cash":0.0,"lots":[[],[]],"floor":0.0},"pair_250":{"qty":[0.0,0.0],"cash":0.0,"lots":[[],[]],"floor":0.0},"pair_add_fast":{"qty":[0.0,0.0],"cash":0.0,"lots":[[],[]],"floor":0.0},"pair_add_250":{"qty":[0.0,0.0],"cash":0.0,"lots":[[],[]],"floor":0.0}}}
{"kind":"decision","recorded_ms":1790003690079,"S":1790003400,"age":290,"signal":{"rsi14":68.84031050192587,"volume_ratio":0.5472232342280093,"taker_buy_fraction":0.3790664665909893,"volume5":150.24315,"return1":-6.6937602372088145,"return5":-3.816556642525312,"return15":48.8278033658056,"bollinger_z":1.2475334786156544,"bar_close_ms":1790003639999,"ref":86226.37589448872,"reference_received_ms":1790003401345,"spot":86280.79275711403,"twap":86230.20152849394,"sigma":8.588338655164756,"spot_z":2.0115217281443534,"twap_z":0.1414147298128883,"momentum":0.2067157683373194,"decision_ms":1790003690078,"momentum30":1.4889882495973836,"momentum60":0.6590884830143992,"spot_twap_gap":0.7604846283510757,"range60":1.583867738610708,"final_mean":86238.63655148045,"final_z":4.746982488746344,"final_up_prob":0.9999989676309,"final_drift_up_prob":0.9999995788535917,"final_known_seconds":50,"final_sd":2.582831729586624,"final_drift_shift":0.4605745755363845},"entry_side":null,"context_gap":null,"book_errors":[null,null],"books":[{"bid":0.99,"ask":null,"asks":[],"received_ms":1790003690077,"observed_ms":1790003690070,"hash":"079c4c4e5c5cb0a2a391fc574a2e9002532ae536"},{"bid":null,"ask":0.01,"asks":[[0.01,19596.85]],"received_ms":1790003690075,"observed_ms":1790003690065,"hash":"e54226510eb21eb925e9021801829b7d87728257"}],"intents":{"pair_fast":null,"pair_250":null,"pair_add_fast":null,"pair_add_250":null},"decision_ms":1790003690079,"feature_cutoff_ms":1790003690078,"request_ms":1790003690047,"inventory":{"pair_fast":{"qty":[10.0,10.0],"cash":8.8414,"lots":[[],[]],"floor":1.1585999999999999},"pair_250":{"qty":[10.0,10.0],"cash":9.04392,"lots":[[],[]],"floor":0.95608},"pair_add_fast":{"qty":[15.0,15.0],"cash":12.032070000000001,"lots":[[],[]],"floor":2.967929999999999},"pair_add_250":{"qty":[15.0,15.0],"cash":11.87846,"lots":[[],[]],"floor":3.1215399999999995}}}
{"kind":"decision","recorded_ms":1790003730061,"S":1790003700,"age":30,"signal":{"rsi14":68.95322332404677,"volume_ratio":0.5276668276688132,"taker_buy_fraction":0.40526719539090195,"volume5":144.8266,"return1":6.90469275739702,"return5":-1.92840025987041,"return15":51.570800218891975,"bollinger_z":1.4866662882017523,"bar_close_ms":1790003699999,"ref":86240.47200119696,"reference_received_ms":1790003701747,"spot":86196.46775271888,"twap":86253.182696344,"sigma":10.949968422941014,"spot_z":-0.24459530681945346,"twap_z":0.07065173220548483,"momentum":-0.04892094078467796,"decision_ms":1790003730060,"momentum30":-1.402251746313369,"momentum60":-0.5872095086177713,"spot_twap_gap":-0.668665648633248,"range60":1.5018430383637287,"final_mean":86196.46775271888,"final_z":-0.26501745434324075,"final_up_prob":0.39549800790284373,"final_drift_up_prob":0.3050938687552954,"final_known_seconds":0,"final_sd":166.04283135666006,"final_drift_shift":-40.645298899360164},"entry_side":null,"context_gap":null,"book_errors":[null,null],"books":[{"bid":0.36,"ask":0.37,"asks":[[0.37,760.54]],"received_ms":1790003730060,"observed_ms":1790003730051,"hash":"f41d8f4dd5fbaa84cc9bb076b25b47f5dfe0cda8"},{"bid":0.63,"ask":0.64,"asks":[[0.64,116.97]],"received_ms":1790003730056,"observed_ms":1790003730048,"hash":"298355b763b3a4440c95fec4453c872ec91ee895"}],"intents":{"pair_fast":{"kind":"first","side":0,"qty":5.0,"participation":true,"max_cost":1.9815900000000002},"pair_250":{"kind":"first","side":0,"qty":5.0,"participation":true,"max_cost":1.9815900000000002},"pair_add_fast":{"kind":"first","side":0,"qty":5.0,"participation":true,"max_cost":1.9815900000000002},"pair_add_250":{"kind":"first","side":0,"qty":5.0,"participation":true,"max_cost":1.9815900000000002}},"decision_ms":1790003730061,"feature_cutoff_ms":1790003730060,"request_ms":1790003730026,"inventory":{"pair_fast":{"qty":[0.0,0.0],"cash":0.0,"lots":[[],[]],"floor":0.0},"pair_250":{"qty":[0.0,0.0],"cash":0.0,"lots":[[],[]],"floor":0.0},"pair_add_fast":{"qty":[0.0,0.0],"cash":0.0,"lots":[[],[]],"floor":0.0},"pair_add_250":{"qty":[0.0,0.0],"cash":0.0,"lots":[[],[]],"floor":0.0}}}
{"kind":"decision","recorded_ms":1790003740050,"S":1790003700,"age":40,"signal":{"rsi14":68.95322332404677,"volume_ratio":0.5276668276688132,"taker_buy_fraction":0.40526719539090195,"volume5":144.8266,"return1":6.90469275739702,"return5":-1.92840025987041,"return15":51.570800218891975,"bollinger_z":1.4866662882017523,"bar_close_ms":1790003699999,"ref":86240.47200119696,"reference_received_ms":1790003701747,"spot":86195.49094031667,"twap":86245.34374398467,"sigma":10.557443907902169,"spot_z":-0.264256187611008,"twap_z":0.028620671698438557,"momentum":0.06382151548836369,"decision_ms":1790003740049,"momentum30":-0.7962442107698947,"momentum60":-0.9744437871537953,"spot_twap_gap":-0.6096143474761028,"range60":1.5576813847893198,"final_mean":86195.49094031667,"final_z":-0.28728168606143595,"final_up_prob":0.38694832215748926,"final_drift_up_prob":0.5102288465235879,"final_known_seconds":0,"final_sd":156.57475941809676,"final_drift_shift":48.99606451298516},"entry_side":null,"context_gap":null,"book_errors":[null,null],"books":[{"bid":0.39,"ask":0.4,"asks":[[0.4,1387.83]],"received_ms":1790003740049,"observed_ms":1790003740037,"hash":"6b0d76879636d95e0414f7266dffd33eb3567b01"},{"bid":0.6,"ask":0.61,"asks":[[0.61,40.0]],"received_ms":1790003740039,"observed_ms":1790003740029,"hash":"9ae76f8f224fd83e5ce02ab82e2199c9fc888a7d"}],"intents":{"pair_fast":null,"pair_250":null,"pair_add_fast":null,"pair_add_250":null},"decision_ms":1790003740050,"feature_cutoff_ms":1790003740049,"request_ms":1790003740016,"inventory":{"pair_fast":{"qty":[5.0,0.0],"cash":1.9315900000000001,"lots":[[[5.0,0.38631800000000005]],[]],"floor":-1.9315900000000001},"pair_250":{"qty":[5.0,0.0],"cash":1.9315900000000001,"lots":[[[5.0,0.38631800000000005]],[]],"floor":-1.9315900000000001},"pair_add_fast":{"qty":[5.0,0.0],"cash":1.9315900000000001,"lots":[[[5.0,0.38631800000000005]],[]],"floor":-1.9315900000000001},"pair_add_250":{"qty":[5.0,0.0],"cash":1.9315900000000001,"lots":[[[5.0,0.38631800000000005]],[]],"floor":-1.9315900000000001}}}
{"kind":"decision","recorded_ms":1790003750053,"S":1790003700,"age":50,"signal":{"rsi14":68.95322332404677,"volume_ratio":0.5276668276688132,"taker_buy_fraction":0.40526719539090195,"volume5":144.8266,"return1":6.90469275739702,"return5":-1.92840025987041,"return15":51.570800218891975,"bollinger_z":1.4866662882017523,"bar_close_ms":1790003699999,"ref":86240.47200119696,"reference_received_ms":1790003701747,"spot":86199.31261887727,"twap":86233.93416343203,"sigma":10.22896694525589,"spot_z":-0.25451382144301654,"twap_z":-0.04042747922218901,"momentum":-0.055734709271567005,"decision_ms":1790003750051,"momentum30":0.020541911999274878,"momentum60":-1.3043022966164717,"spot_twap_gap":-0.4369573395442457,"range60":1.6077023158163333,"final_mean":86199.31261887727,"final_z":-0.27770274228937014,"final_up_prob":0.39062027766375496,"final_drift_up_prob":0.29279284352916274,"final_known_seconds":0,"final_sd":148.2138130159348,"final_drift_shift":-39.65331562243999},"entry_side":null,"context_gap":null,"book_errors":[null,null],"books":[{"bid":0.34,"ask":0.35,"asks":[[0.35,1253.48]],"received_ms":1790003750051,"observed_ms":1790003750040,"hash":"acdd99ef314032ccb151f12a3bb7bc0621c1d67f"},{"bid":0.65,"ask":0.66,"asks":[[0.66,5.37]],"received_ms":1790003750046,"observed_ms":1790003750028,"hash":"a34214986c04ad48476a8ff1781d537cf04ebb37"}],"intents":{"pair_fast":null,"pair_250":null,"pair_add_fast":null,"pair_add_250":null},"decision_ms":1790003750053,"feature_cutoff_ms":1790003750051,"request_ms":1790003750021,"inventory":{"pair_fast":{"qty":[5.0,0.0],"cash":1.9315900000000001,"lots":[[[5.0,0.38631800000000005]],[]],"floor":-1.9315900000000001},"pair_250":{"qty":[5.0,0.0],"cash":1.9315900000000001,"lots":[[[5.0,0.38631800000000005]],[]],"floor":-1.9315900000000001},"pair_add_fast":{"qty":[5.0,0.0],"cash":1.9315900000000001,"lots":[[[5.0,0.38631800000000005]],[]],"floor":-1.9315900000000001},"pair_add_250":{"qty":[5.0,0.0],"cash":1.9315900000000001,"lots":[[[5.0,0.38631800000000005]],[]],"floor":-1.9315900000000001}}}
{"kind":"decision","recorded_ms":1790003760060,"S":1790003700,"age":60,"signal":{"rsi14":68.95322332404677,"volume_ratio":0.5276668276688132,"taker_buy_fraction":0.40526719539090195,"volume5":144.8266,"return1":6.90469275739702,"return5":-1.92840025987041,"return15":51.570800218891975,"bollinger_z":1.4866662882017523,"bar_close_ms":1790003699999,"ref":86240.47200119696,"reference_received_ms":1790003701747,"spot":86181.79581941252,"twap":86216.87692404214,"sigma":10.039282881647862,"spot_z":-0.3773166904626853,"twap_z":-0.15172794398886383,"momentum":-0.37622245754608874,"decision_ms":1790003760058,"momentum30":-0.2103099933482246,"momentum60":-1.2701593436231462,"spot_twap_gap":-0.4511229722906151,"range60":1.312632603901863,"final_mean":86181.79581941252,"final_z":-0.41333971697285726,"final_up_prob":0.3396788673711715,"final_drift_up_prob":0.01463793179067363,"final_known_seconds":0,"final_sd":141.95631190285826,"final_drift_shift":-250.75334647787065},"entry_side":null,"context_gap":null,"book_errors":[null,null],"books":[{"bid":0.29,"ask":0.3,"asks":[[0.3,604.3]],"received_ms":1790003760058,"observed_ms":1790003760048,"hash":"d2a0f102a71b35e353cfdd8f9955b7425119601f"},{"bid":0.7,"ask":0.71,"asks":[[0.71,643.0]],"received_ms":1790003760047,"observed_ms":1790003760040,"hash":"0630423072d0838f33f1ca8d3b1032a1e32a56e6"}],"intents":{"pair_fast":null,"pair_250":null,"pair_add_fast":null,"pair_add_250":null},"decision_ms":1790003760060,"feature_cutoff_ms":1790003760058,"request_ms":1790003760025,"inventory":{"pair_fast":{"qty":[5.0,0.0],"cash":1.9315900000000001,"lots":[[[5.0,0.38631800000000005]],[]],"floor":-1.9315900000000001},"pair_250":{"qty":[5.0,0.0],"cash":1.9315900000000001,"lots":[[[5.0,0.38631800000000005]],[]],"floor":-1.9315900000000001},"pair_add_fast":{"qty":[5.0,0.0],"cash":1.9315900000000001,"lots":[[[5.0,0.38631800000000005]],[]],"floor":-1.9315900000000001},"pair_add_250":{"qty":[5.0,0.0],"cash":1.9315900000000001,"lots":[[[5.0,0.38631800000000005]],[]],"floor":-1.9315900000000001}}}
{"kind":"decision","recorded_ms":1790003770055,"S":1790003700,"age":70,"signal":{"rsi14":61.138121035329206,"volume_ratio":0.4854190893535024,"taker_buy_fraction":0.4508386914827491,"volume5":128.92822,"return1":-11.710418397132624,"return5":5.215330495900964,"return15":33.439608503298345,"bollinger_z":0.7763964592005138,"bar_close_ms":1790003759999,"ref":86240.47200119696,"reference_received_ms":1790003701747,"spot":86186.53315860419,"twap":86199.4727008582,"sigma":9.755296745891236,"spot_z":-0.36462648325686986,"twap_z":-0.2771551998506951,"momentum":0.18807949132255583,"decision_ms":1790003770054,"momentum30":-0.2729134663346276,"momentum60":-0.7278711356601805,"spot_twap_gap":-0.17123904740413398,"range60":0.9625266233316185,"final_mean":86186.53315860419,"final_z":-0.4011862706486513,"final_up_prob":0.3441414940662446,"final_drift_up_prob":0.6778414522540723,"final_known_seconds":0,"final_sd":134.44837607619363,"final_drift_shift":116.00979164129515},"entry_side":null,"context_gap":null,"book_errors":[null,null],"books":[{"bid":0.25,"ask":0.26,"asks":[[0.26,135.0]],"received_ms":1790003770054,"observed_ms":1790003770040,"hash":"34e87f11205a4a5a08b098eec038564cd72c2d0b"},{"bid":0.74,"ask":0.75,"asks":[[0.75,1957.28]],"received_ms":1790003770036,"observed_ms":1790003770027,"hash":"33646b973927442912e15b1fdf949d3f4e8d0f0e"}],"intents":{"pair_fast":null,"pair_250":null,"pair_add_fast":null,"pair_add_250":null},"decision_ms":1790003770055,"feature_cutoff_ms":1790003770054,"request_ms":1790003770007,"inventory":{"pair_fast":{"qty":[5.0,0.0],"cash":1.9315900000000001,"lots":[[[5.0,0.38631800000000005]],[]],"floor":-1.9315900000000001},"pair_250":{"qty":[5.0,0.0],"cash":1.9315900000000001,"lots":[[[5.0,0.38631800000000005]],[]],"floor":-1.9315900000000001},"pair_add_fast":{"qty":[5.0,0.0],"cash":1.9315900000000001,"lots":[[[5.0,0.38631800000000005]],[]],"floor":-1.9315900000000001},"pair_add_250":{"qty":[5.0,0.0],"cash":1.9315900000000001,"lots":[[[5.0,0.38631800000000005]],[]],"floor":-1.9315900000000001}}}
{"kind":"decision","recorded_ms":1790003780061,"S":1790003700,"age":80,"signal":{"rsi14":61.138121035329206,"volume_ratio":0.4854190893535024,"taker_buy_fraction":0.4508386914827491,"volume5":128.92822,"return1":-11.710418397132624,"return5":5.215330495900964,"return15":33.439608503298345,"bollinger_z":0.7763964592005138,"bar_close_ms":1790003759999,"ref":86240.47200119696,"reference_received_ms":1790003701747,"spot":86136.94009135047,"twap":86188.36824251784,"sigma":5.175480326183718,"spot_z":-1.3488742157813889,"twap_z":-0.6788382126029116,"momentum":-1.617887678544554,"decision_ms":1790003780060,"momentum30":-2.0037081521833673,"momentum60":-1.5271393395117245,"spot_twap_gap":-1.2828462960226448,"range60":1.8922596591592062,"final_mean":86136.94009135047,"final_z":-1.491281757703525,"final_up_prob":0.06794376815009295,"final_drift_up_prob":0.0,"final_known_seconds":0,"final_sd":69.42478127401577,"final_drift_shift":-502.9391730253941},"entry_side":null,"context_gap":null,"book_errors":[null,null],"books":[{"bid":0.23,"ask":0.24,"asks":[[0.24,7.58]],"received_ms":1790003780059,"observed_ms":1790003780049,"hash":"f9c29a553fedcec281e5ed7a97e2a434f680c567"},{"bid":0.76,"ask":0.77,"asks":[[0.77,1400.42]],"received_ms":1790003780059,"observed_ms":1790003780051,"hash":"e42b33481b8da868ce16cd6d51c9bd56e7095dce"}],"intents":{"pair_fast":null,"pair_250":null,"pair_add_fast":null,"pair_add_250":null},"decision_ms":1790003780061,"feature_cutoff_ms":1790003780060,"request_ms":1790003780027,"inventory":{"pair_fast":{"qty":[5.0,0.0],"cash":1.9315900000000001,"lots":[[[5.0,0.38631800000000005]],[]],"floor":-1.9315900000000001},"pair_250":{"qty":[5.0,0.0],"cash":1.9315900000000001,"lots":[[[5.0,0.38631800000000005]],[]],"floor":-1.9315900000000001},"pair_add_fast":{"qty":[5.0,0.0],"cash":1.9315900000000001,"lots":[[[5.0,0.38631800000000005]],[]],"floor":-1.9315900000000001},"pair_add_250":{"qty":[5.0,0.0],"cash":1.9315900000000001,"lots":[[[5.0,0.38631800000000005]],[]],"floor":-1.9315900000000001}}}
{"kind":"decision","recorded_ms":1790003790091,"S":1790003700,"age":90,"signal":{"rsi14":61.138121035329206,"volume_ratio":0.4854190893535024,"taker_buy_fraction":0.4508386914827491,"volume5":128.92822,"return1":-11.710418397132624,"return5":5.215330495900964,"return15":33.439608503298345,"bollinger_z":0.7763964592005138,"bar_close_ms":1790003759999,"ref":86240.47200119696,"reference_received_ms":1790003701747,"spot":86149.91791154027,"twap":86179.72926283693,"sigma":4.9441044751972045,"spot_z":-1.2641652998464206,"twap_z":-0.8479888908774569,"momentum":0.5087064393202397,"decision_ms":1790003790090,"momentum30":-1.1378588933890321,"momentum60":-1.1343567442228315,"spot_twap_gap":-0.7784279079534292,"range60":1.8496186057668684,"final_mean":86149.91791154027,"final_z":-1.405112054201041,"final_up_prob":0.07999398009723763,"final_drift_up_prob":0.7925196942087298,"final_known_seconds":0,"final_sd":64.44616953214181,"final_drift_shift":143.090294723886},"entry_side":null,"context_gap":null,"book_errors":[null,null],"books":[{"bid":0.22,"ask":0.23,"asks":[[0.23,1293.49]],"received_ms":1790003790064,"observed_ms":1790003790056,"hash":"46c56624f82ced791d7c72b284629349c6c08b82"},{"bid":0.77,"ask":0.78,"asks":[[0.78,85.58]],"received_ms":1790003790090,"observed_ms":1790003790065,"hash":"4b88116e4ab7398cd77f9ff37adb17cba4ba17c5"}],"intents":{"pair_fast":null,"pair_250":null,"pair_add_fast":null,"pair_add_250":null},"decision_ms":1790003790091,"feature_cutoff_ms":1790003790090,"request_ms":1790003790034,"inventory":{"pair_fast":{"qty":[5.0,0.0],"cash":1.9315900000000001,"lots":[[[5.0,0.38631800000000005]],[]],"floor":-1.9315900000000001},"pair_250":{"qty":[5.0,0.0],"cash":1.9315900000000001,"lots":[[[5.0,0.38631800000000005]],[]],"floor":-1.9315900000000001},"pair_add_fast":{"qty":[5.0,0.0],"cash":1.9315900000000001,"lots":[[[5.0,0.38631800000000005]],[]],"floor":-1.9315900000000001},"pair_add_250":{"qty":[5.0,0.0],"cash":1.9315900000000001,"lots":[[[5.0,0.38631800000000005]],[]],"floor":-1.9315900000000001}}}
{"kind":"decision","recorded_ms":1790003800059,"S":1790003700,"age":100,"signal":{"rsi14":61.138121035329206,"volume_ratio":0.4854190893535024,"taker_buy_fraction":0.4508386914827491,"volume5":128.92822,"return1":-11.710418397132624,"return5":5.215330495900964,"return15":33.439608503298345,"bollinger_z":0.7763964592005138,"bar_close_ms":1790003759999,"ref":86240.47200119696,"reference_received_ms":1790003701747,"spot":86151.99698674744,"twap":86170.84073334347,"sigma":5.835191624395894,"spot_z":-1.0722930810782327,"twap_z":-0.84391200397715,"momentum":0.2074450694333314,"decision_ms":1790003800058,"momentum30":-0.35737524945248955,"momentum60":-1.086711126216255,"spot_twap_gap":-0.4169044277338228,"range60":1.779750822662137,"final_mean":86151.99698674744,"final_z":-1.198903584262857,"final_up_prob":0.11528271894890729,"final_drift_up_prob":0.3754688972579996,"final_known_seconds":0,"final_sd":73.79660517398308,"final_drift_shift":65.05174701450345},"entry_side":null,"context_gap":null,"book_errors":[null,null],"books":[{"bid":0.27,"ask":0.28,"asks":[[0.28,1585.38]],"received_ms":1790003800058,"observed_ms":1790003800049,"hash":"5e30284f473e096dc5d8f4e4acef063f394d30e7"},{"bid":0.72,"ask":0.73,"asks":[[0.73,5.0]],"received_ms":1790003800043,"observed_ms":1790003800034,"hash":"337cb8e077013245059f2d4cdc6bbf8e61193267"}],"intents":{"pair_fast":null,"pair_250":null,"pair_add_fast":null,"pair_add_250":null},"decision_ms":1790003800059,"feature_cutoff_ms":1790003800058,"request_ms":1790003800013,"inventory":{"pair_fast":{"qty":[5.0,0.0],"cash":1.9315900000000001,"lots":[[[5.0,0.38631800000000005]],[]],"floor":-1.9315900000000001},"pair_250":{"qty":[5.0,0.0],"cash":1.9315900000000001,"lots":[[[5.0,0.38631800000000005]],[]],"floor":-1.9315900000000001},"pair_add_fast":{"qty":[5.0,0.0],"cash":1.9315900000000001,"lots":[[[5.0,0.38631800000000005]],[]],"floor":-1.9315900000000001},"pair_add_250":{"qty":[5.0,0.0],"cash":1.9315900000000001,"lots":[[[5.0,0.38631800000000005]],[]],"floor":-1.9315900000000001}}}
{"kind":"decision","recorded_ms":1790003810068,"S":1790003700,"age":110,"signal":{"rsi14":61.138121035329206,"volume_ratio":0.4854190893535024,"taker_buy_fraction":0.4508386914827491,"volume5":128.92822,"return1":-11.710418397132624,"return5":5.215330495900964,"return15":33.439608503298345,"bollinger_z":0.7763964592005138,"bar_close_ms":1790003759999,"ref":86240.47200119696,"reference_received_ms":1790003701747,"spot":86123.5308951583,"twap":86161.73466879649,"sigma":7.384122723166281,"spot_z":-1.1491271270743335,"twap_z":-0.7737159980763159,"momentum":-1.8007347047572753,"decision_ms":1790003810067,"momentum30":-0.45577460946358117,"momentum60":-1.2274883572690225,"spot_twap_gap":-0.66793120234754,"range60":1.2274883572690225,"final_mean":86123.5308951583,"final_z":-1.2933607452853744,"final_up_prob":0.09794316008192433,"final_drift_up_prob":0.0,"final_known_seconds":0,"final_sd":90.41646459809657,"final_drift_shift":-672.4913841546434},"entry_side":null,"context_gap":null,"book_errors":[null,null],"books":[{"bid":0.14,"ask":0.15,"asks":[[0.15,1117.76]],"received_ms":1790003810067,"observed_ms":1790003810051,"hash":"2837c8806c9fb25bdfd43be03f89c8a8ed032aff"},{"bid":0.85,"ask":0.86,"asks":[[0.86,190.66]],"received_ms":1790003810059,"observed_ms":1790003810051,"hash":"0ece81b5c4e9e468d21b5bd9c8a4b44e6bd96930"}],"intents":{"pair_fast":null,"pair_250":null,"pair_add_fast":null,"pair_add_250":null},"decision_ms":1790003810068,"feature_cutoff_ms":1790003810067,"request_ms":1790003810031,"inventory":{"pair_fast":{"qty":[5.0,0.0],"cash":1.9315900000000001,"lots":[[[5.0,0.38631800000000005]],[]],"floor":-1.9315900000000001},"pair_250":{"qty":[5.0,0.0],"cash":1.9315900000000001,"lots":[[[5.0,0.38631800000000005]],[]],"floor":-1.9315900000000001},"pair_add_fast":{"qty":[5.0,0.0],"cash":1.9315900000000001,"lots":[[[5.0,0.38631800000000005]],[]],"floor":-1.9315900000000001},"pair_add_250":{"qty":[5.0,0.0],"cash":1.9315900000000001,"lots":[[[5.0,0.38631800000000005]],[]],"floor":-1.9315900000000001}}}
{"kind":"decision","recorded_ms":1790003820079,"S":1790003700,"age":120,"signal":{"rsi14":61.138121035329206,"volume_ratio":0.4854190893535024,"taker_buy_fraction":0.4508386914827491,"volume5":128.92822,"return1":-11.710418397132624,"return5":5.215330495900964,"return15":33.439608503298345,"bollinger_z":0.7763964592005138,"bar_close_ms":1790003759999,"ref":86240.47200119696,"reference_received_ms":1790003701747,"spot":86123.17423400914,"twap":86149.46487726587,"sigma":7.768064663229166,"spot_z":-1.1257313952540497,"twap_z":-0.8734145504829974,"momentum":0.5043323100776602,"decision_ms":1790003820078,"momentum30":-0.5874588921339721,"momentum60":-0.95655225452887,"spot_twap_gap":-0.43693089552651077,"range60":1.1624450579437657,"final_mean":86123.17423400914,"final_z":-1.2765384812585368,"final_up_prob":0.10088261639935453,"final_drift_up_prob":0.7718038418147608,"final_known_seconds":0,"final_sd":91.88737269570936,"final_drift_shift":185.73553078126878},"entry_side":null,"context_gap":null,"book_errors":[null,null],"books":[{"bid":0.16,"ask":0.17,"asks":[[0.17,1389.27]],"received_ms":1790003820064,"observed_ms":1790003820047,"hash":"91c55698e061071aa3e19fec71f1c4cb9376d32c"},{"bid":0.83,"ask":0.84,"asks":[[0.84,90.65]],"received_ms":1790003820078,"observed_ms":1790003820047,"hash":"c38940830524318379b6234c572cf1b83542ec7a"}],"intents":{"pair_fast":null,"pair_250":null,"pair_add_fast":null,"pair_add_250":null},"decision_ms":1790003820079,"feature_cutoff_ms":1790003820078,"request_ms":1790003820041,"inventory":{"pair_fast":{"qty":[5.0,0.0],"cash":1.9315900000000001,"lots":[[[5.0,0.38631800000000005]],[]],"floor":-1.9315900000000001},"pair_250":{"qty":[5.0,0.0],"cash":1.9315900000000001,"lots":[[[5.0,0.38631800000000005]],[]],"floor":-1.9315900000000001},"pair_add_fast":{"qty":[5.0,0.0],"cash":1.9315900000000001,"lots":[[[5.0,0.38631800000000005]],[]],"floor":-1.9315900000000001},"pair_add_250":{"qty":[5.0,0.0],"cash":1.9315900000000001,"lots":[[[5.0,0.38631800000000005]],[]],"floor":-1.9315900000000001}}}
{"kind":"decision","recorded_ms":1790003830078,"S":1790003700,"age":130,"signal":{"rsi14":56.50453527229979,"volume_ratio":0.532822941981857,"taker_buy_fraction":0.42274265385185583,"volume5":125.52871,"return1":-6.283226536672053,"return5":1.2352832658938429,"return15":21.644159704942957,"bollinger_z":0.3844275251333322,"bar_close_ms":1790003819999,"ref":86240.47200119696,"reference_received_ms":1790003701747,"spot":86148.06107936025,"twap":86140.65239774183,"sigma":7.9530201775550475,"spot_z":-0.8913846162068733,"twap_z":-0.9628478663269271,"momentum":0.9989309863193836,"decision_ms":1790003830077,"momentum30":-0.40215656026448066,"momentum60":-0.2493003545906436,"spot_twap_gap":0.12026332925490012,"range60":0.889454305190056,"final_mean":86148.06107936025,"final_z":-1.0194083767996587,"final_up_prob":0.15400456546765162,"final_drift_up_prob":0.9978707976684673,"final_known_seconds":0,"final_sd":90.65152292236822,"final_drift_shift":351.5253728323435},"entry_side":null,"context_gap":null,"book_errors":[null,null],"books":[{"bid":0.18,"ask":0.19,"asks":[[0.19,1167.56]],"received_ms":1790003830077,"observed_ms":1790003830061,"hash":"d622b5e7f5a3d270510444b7392e26b4faec1776"},{"bid":0.81,"ask":0.82,"asks":[[0.82,430.99]],"received_ms":1790003830062,"observed_ms":1790003830052,"hash":"843e47255c2aced5ace493e0898e65aa7cf7dabc"}],"intents":{"pair_fast":null,"pair_250":null,"pair_add_fast":null,"pair_add_250":null},"decision_ms":1790003830078,"feature_cutoff_ms":1790003830077,"request_ms":1790003830027,"inventory":{"pair_fast":{"qty":[5.0,0.0],"cash":1.9315900000000001,"lots":[[[5.0,0.38631800000000005]],[]],"floor":-1.9315900000000001},"pair_250":{"qty":[5.0,0.0],"cash":1.9315900000000001,"lots":[[[5.0,0.38631800000000005]],[]],"floor":-1.9315900000000001},"pair_add_fast":{"qty":[5.0,0.0],"cash":1.9315900000000001,"lots":[[[5.0,0.38631800000000005]],[]],"floor":-1.9315900000000001},"pair_add_250":{"qty":[5.0,0.0],"cash":1.9315900000000001,"lots":[[[5.0,0.38631800000000005]],[]],"floor":-1.9315900000000001}}}
{"kind":"decision","recorded_ms":1790003840038,"S":1790003700,"age":140,"signal":{"rsi14":56.50453527229979,"volume_ratio":0.532822941981857,"taker_buy_fraction":0.42274265385185583,"volume5":125.52871,"return1":-6.283226536672053,"return5":1.2352832658938429,"return15":21.644159704942957,"bollinger_z":0.3844275251333322,"bar_close_ms":1790003819999,"ref":86240.47200119696,"reference_received_ms":1790003701747,"spot":86106.15078896165,"twap":86134.63495466049,"sigma":8.354322738351806,"spot_z":-1.2712283911910882,"twap_z":-1.0016516092876826,"momentum":-1.3952699267230295,"decision_ms":1790003840037,"momentum30":-0.10128463808628263,"momentum60":-0.5534292848234963,"spot_twap_gap":-0.44016613848619107,"range60":0.9183481380024564,"final_mean":86106.15078896165,"final_z":-1.4679446988334475,"final_up_prob":0.07105962256946458,"final_drift_up_prob":1.018135575847623e-11,"final_known_seconds":0,"final_sd":91.50291039032822,"final_drift_shift":-479.05922800854705},"entry_side":null,"context_gap":null,"book_errors":[null,null],"books":[{"bid":0.1,"ask":0.11,"asks":[[0.11,908.98]],"received_ms":1790003840034,"observed_ms":1790003840027,"hash":"e40d16c692ecbc28285f2f517f2922986cc1228f"},{"bid":0.89,"ask":0.9,"asks":[[0.9,76.46]],"received_ms":1790003840037,"observed_ms":1790003840028,"hash":"54ef4426d3086491edd83c99cfbaae56dccb437b"}],"intents":{"pair_fast":null,"pair_250":null,"pair_add_fast":null,"pair_add_250":null},"decision_ms":1790003840038,"feature_cutoff_ms":1790003840037,"request_ms":1790003840002,"inventory":{"pair_fast":{"qty":[5.0,0.0],"cash":1.9315900000000001,"lots":[[[5.0,0.38631800000000005]],[]],"floor":-1.9315900000000001},"pair_250":{"qty":[5.0,0.0],"cash":1.9315900000000001,"lots":[[[5.0,0.38631800000000005]],[]],"floor":-1.9315900000000001},"pair_add_fast":{"qty":[5.0,0.0],"cash":1.9315900000000001,"lots":[[[5.0,0.38631800000000005]],[]],"floor":-1.9315900000000001},"pair_add_250":{"qty":[5.0,0.0],"cash":1.9315900000000001,"lots":[[[5.0,0.38631800000000005]],[]],"floor":-1.9315900000000001}}}
{"kind":"decision","recorded_ms":1790003850070,"S":1790003700,"age":150,"signal":{"rsi14":56.50453527229979,"volume_ratio":0.532822941981857,"taker_buy_fraction":0.42274265385185583,"volume5":125.52871,"return1":-6.283226536672053,"return5":1.2352832658938429,"return15":21.644159704942957,"bollinger_z":0.3844275251333322,"bar_close_ms":1790003819999,"ref":86240.47200119696,"reference_received_ms":1790003701747,"spot":86106.25293859211,"twap":86128.95426632134,"sigma":8.829754276769005,"spot_z":-1.2414232213148035,"twap_z":-1.031453379097159,"momentum":0.3727930491573922,"decision_ms":1790003850069,"momentum30":-0.34500591897753485,"momentum60":-0.6128544414611126,"spot_twap_gap":-0.33191510384918443,"range60":1.0195989667437702,"final_mean":86106.25293859211,"final_z":-1.4497913167394494,"final_up_prob":0.07355836083732215,"final_drift_up_prob":0.45964508837560664,"final_known_seconds":0,"final_sd":92.57819456851901,"final_drift_shift":124.83830944731892},"entry_side":null,"context_gap":null,"book_errors":[null,null],"books":[{"bid":0.11,"ask":0.12,"asks":[[0.12,192.41]],"received_ms":1790003850046,"observed_ms":1790003850035,"hash":"0c6b3cd2d7c144d8896818c9592c8d5dbce73add"},{"bid":0.88,"ask":0.89,"asks":[[0.89,1078.33]],"received_ms":1790003850069,"observed_ms":1790003850050,"hash":"30e411a5afef527e9a73650e306cb8626393bc49"}],"intents":{"pair_fast":null,"pair_250":null,"pair_add_fast":null,"pair_add_250":null},"decision_ms":1790003850070,"feature_cutoff_ms":1790003850069,"request_ms":1790003850013,"inventory":{"pair_fast":{"qty":[5.0,0.0],"cash":1.9315900000000001,"lots":[[[5.0,0.38631800000000005]],[]],"floor":-1.9315900000000001},"pair_250":{"qty":[5.0,0.0],"cash":1.9315900000000001,"lots":[[[5.0,0.38631800000000005]],[]],"floor":-1.9315900000000001},"pair_add_fast":{"qty":[5.0,0.0],"cash":1.9315900000000001,"lots":[[[5.0,0.38631800000000005]],[]],"floor":-1.9315900000000001},"pair_add_250":{"qty":[5.0,0.0],"cash":1.9315900000000001,"lots":[[[5.0,0.38631800000000005]],[]],"floor":-1.9315900000000001}}}
{"kind":"decision","recorded_ms":1790003860089,"S":1790003700,"age":160,"signal":{"rsi14":56.50453527229979,"volume_ratio":0.532822941981857,"taker_buy_fraction":0.42274265385185583,"volume5":125.52871,"return1":-6.283226536672053,"return5":1.2352832658938429,"return15":21.644159704942957,"bollinger_z":0.3844275251333322,"bar_close_ms":1790003819999,"ref":86240.47200119696,"reference_received_ms":1790003701747,"spot":86116.3577667483,"twap":86123.77033506139,"sigma":7.5115821051786344,"spot_z":-1.3968915553480064,"twap_z":-1.3134639442767648,"momentum":0.15760132371341923,"decision_ms":1790003860088,"momentum30":-0.6478492881315447,"momentum60":-0.8459551497895187,"spot_twap_gap":-0.12739772273099653,"range60":1.1985235881251097,"final_mean":86116.3577667483,"final_z":-1.6530323316599014,"final_up_prob":0.04916214181835726,"final_drift_up_prob":0.13457705086928773,"final_known_seconds":0,"final_sd":75.08276279389403,"final_drift_shift":41.14683071301657},"entry_side":null,"context_gap":null,"book_errors":[null,null],"books":[{"bid":0.1,"ask":0.11,"asks":[[0.11,995.14]],"received_ms":1790003860070,"observed_ms":1790003860061,"hash":"c25b24851a733c3363b08a1f6a8ef9e3c710b86a"},{"bid":0.89,"ask":0.9,"asks":[[0.9,134.09]],"received_ms":1790003860088,"observed_ms":1790003860061,"hash":"52922a0fa6770bfe9dfd095cec5e5186cc0a7f7a"}],"intents":{"pair_fast":null,"pair_250":null,"pair_add_fast":null,"pair_add_250":null},"decision_ms":1790003860089,"feature_cutoff_ms":1790003860088,"request_ms":1790003860043,"inventory":{"pair_fast":{"qty":[5.0,0.0],"cash":1.9315900000000001,"lots":[[[5.0,0.38631800000000005]],[]],"floor":-1.9315900000000001},"pair_250":{"qty":[5.0,0.0],"cash":1.9315900000000001,"lots":[[[5.0,0.38631800000000005]],[]],"floor":-1.9315900000000001},"pair_add_fast":{"qty":[5.0,0.0],"cash":1.9315900000000001,"lots":[[[5.0,0.38631800000000005]],[]],"floor":-1.9315900000000001},"pair_add_250":{"qty":[5.0,0.0],"cash":1.9315900000000001,"lots":[[[5.0,0.38631800000000005]],[]],"floor":-1.9315900000000001}}}
{"kind":"decision","recorded_ms":1790003870062,"S":1790003700,"age":170,"signal":{"rsi14":56.50453527229979,"volume_ratio":0.532822941981857,"taker_buy_fraction":0.42274265385185583,"volume5":125.52871,"return1":-6.283226536672053,"return5":1.2352832658938429,"return15":21.644159704942957,"bollinger_z":0.3844275251333322,"bar_close_ms":1790003819999,"ref":86240.47200119696,"reference_received_ms":1790003701747,"spot":86168.20169639775,"twap":86119.97180032745,"sigma":8.609394373845532,"spot_z":-0.7364063492257326,"twap_z":-1.2278502664382884,"momentum":1.8930746118395678,"decision_ms":1790003870061,"momentum30":1.534450693716249,"momentum60":0.8609675300243872,"spot_twap_gap":0.7232161216707822,"range60":1.0850204909231618,"final_mean":86168.20169639775,"final_z":-0.8851426291379035,"final_up_prob":0.18803985510642257,"final_drift_up_prob":0.9999999707612268,"final_known_seconds":0,"final_sd":81.6482026965524,"final_drift_shift":515.0807654267863},"entry_side":null,"context_gap":null,"book_errors":[null,null],"books":[{"bid":0.21,"ask":0.22,"asks":[[0.22,1052.43]],"received_ms":1790003870045,"observed_ms":1790003870033,"hash":"84e154090283066386d2f48e8723498db6379f70"},{"bid":0.78,"ask":0.79,"asks":[[0.79,56.0]],"received_ms":1790003870061,"observed_ms":1790003870047,"hash":"3aa0df49c227bd13baa2612f0c0fd70f0b6ef634"}],"intents":{"pair_fast":null,"pair_250":null,"pair_add_fast":null,"pair_add_250":null},"decision_ms":1790003870062,"feature_cutoff_ms":1790003870061,"request_ms":1790003870012,"inventory":{"pair_fast":{"qty":[5.0,0.0],"cash":1.9315900000000001,"lots":[[[5.0,0.38631800000000005]],[]],"floor":-1.9315900000000001},"pair_250":{"qty":[5.0,0.0],"cash":1.9315900000000001,"lots":[[[5.0,0.38631800000000005]],[]],"floor":-1.9315900000000001},"pair_add_fast":{"qty":[5.0,0.0],"cash":1.9315900000000001,"lots":[[[5.0,0.38631800000000005]],[]],"floor":-1.9315900000000001},"pair_add_250":{"qty":[5.0,0.0],"cash":1.9315900000000001,"lots":[[[5.0,0.38631800000000005]],[]],"floor":-1.9315900000000001}}}
{"kind":"decision","recorded_ms":1790003880077,"S":1790003700,"age":180,"signal":{"rsi14":56.50453527229979,"volume_ratio":0.532822941981857,"taker_buy_fraction":0.42274265385185583,"volume5":125.52871,"return1":-6.283226536672053,"return5":1.2352832658938429,"return15":21.644159704942957,"bollinger_z":0.3844275251333322,"bar_close_ms":1790003819999,"ref":86240.47200119696,"reference_received_ms":1790003701747,"spot":86179.14711852015,"twap":86129.82911939459,"sigma":8.585333147419089,"spot_z":-0.6522686729516621,"twap_z":-1.1768287607677732,"momentum":0.3159766475307081,"decision_ms":1790003880076,"momentum30":1.4148783966292238,"momentum60":0.8452236255466435,"spot_twap_gap":0.7416050373420355,"range60":1.252649960730164,"final_mean":86179.14711852015,"final_z":-0.798989308767212,"final_up_prob":0.2121483056456107,"final_drift_up_prob":0.5816321622778404,"final_known_seconds":0,"final_sd":76.75307041521074,"final_drift_shift":77.14144262005365},"entry_side":null,"context_gap":null,"book_errors":[null,null],"books":[{"bid":0.23,"ask":0.24,"asks":[[0.24,180.45]],"received_ms":1790003880076,"observed_ms":1790003880060,"hash":"3013fcdba351b0ca9ab3a5d1a2069136984730b8"},{"bid":0.76,"ask":0.77,"asks":[[0.77,1473.33]],"received_ms":1790003880073,"observed_ms":1790003880061,"hash":"982ff018866472ffaffc36cc748d12c9bd8cc834"}],"intents":{"pair_fast":null,"pair_250":null,"pair_add_fast":null,"pair_add_250":null},"decision_ms":1790003880077,"feature_cutoff_ms":1790003880076,"request_ms":1790003880035,"inventory":{"pair_fast":{"qty":[5.0,0.0],"cash":1.9315900000000001,"lots":[[[5.0,0.38631800000000005]],[]],"floor":-1.9315900000000001},"pair_250":{"qty":[5.0,0.0],"cash":1.9315900000000001,"lots":[[[5.0,0.38631800000000005]],[]],"floor":-1.9315900000000001},"pair_add_fast":{"qty":[5.0,0.0],"cash":1.9315900000000001,"lots":[[[5.0,0.38631800000000005]],[]],"floor":-1.9315900000000001},"pair_add_250":{"qty":[5.0,0.0],"cash":1.9315900000000001,"lots":[[[5.0,0.38631800000000005]],[]],"floor":-1.9315900000000001}}}
{"kind":"decision","recorded_ms":1790003890062,"S":1790003700,"age":190,"signal":{"rsi14":60.49380513607254,"volume_ratio":0.48494711385247097,"taker_buy_fraction":0.4124156304150696,"volume5":132.34479,"return1":7.276371364555274,"return5":-10.495748044504335,"return15":23.715494807754283,"bollinger_z":0.702181407800456,"bar_close_ms":1790003879999,"ref":86240.47200119696,"reference_received_ms":1790003701747,"spot":86209.16693382084,"twap":86139.11564566704,"sigma":9.174804732896725,"spot_z":-0.3254182625064703,"twap_z":-1.0536060732358394,"momentum":0.9527011402849603,"decision_ms":1790003890061,"momentum30":1.840799938484374,"momentum60":0.9308717476004329,"spot_twap_gap":0.9856975354373259,"range60":1.6272502325199465,"final_mean":86209.16693382084,"final_z":-0.40799806560323404,"final_up_prob":0.34163754753319386,"final_drift_up_prob":0.993277473319165,"final_known_seconds":0,"final_sd":76.72847009662165,"final_drift_shift":220.95926953597066},"entry_side":null,"context_gap":null,"book_errors":[null,null],"books":[{"bid":0.34,"ask":0.35,"asks":[[0.35,108.0]],"received_ms":1790003890050,"observed_ms":1790003890042,"hash":"f01407814c230e8671050d9a5b23126e8ef61d79"},{"bid":0.65,"ask":0.66,"asks":[[0.66,430.58]],"received_ms":1790003890061,"observed_ms":1790003890051,"hash":"154b06a5646e890834cacac0f884060c2c8a99af"}],"intents":{"pair_fast":null,"pair_250":null,"pair_add_fast":null,"pair_add_250":null},"decision_ms":1790003890062,"feature_cutoff_ms":1790003890061,"request_ms":1790003890021,"inventory":{"pair_fast":{"qty":[5.0,0.0],"cash":1.9315900000000001,"lots":[[[5.0,0.38631800000000005]],[]],"floor":-1.9315900000000001},"pair_250":{"qty":[5.0,0.0],"cash":1.9315900000000001,"lots":[[[5.0,0.38631800000000005]],[]],"floor":-1.9315900000000001},"pair_add_fast":{"qty":[5.0,0.0],"cash":1.9315900000000001,"lots":[[[5.0,0.38631800000000005]],[]],"floor":-1.9315900000000001},"pair_add_250":{"qty":[5.0,0.0],"cash":1.9315900000000001,"lots":[[[5.0,0.38631800000000005]],[]],"floor":-1.9315900000000001}}}
{"kind":"decision","recorded_ms":1790003900078,"S":1790003700,"age":200,"signal":{"rsi14":60.49380513607254,"volume_ratio":0.48494711385247097,"taker_buy_fraction":0.4124156304150696,"volume5":132.34479,"return1":7.276371364555274,"return5":-10.495748044504335,"return15":23.715494807754283,"bollinger_z":0.702181407800456,"bar_close_ms":1790003879999,"ref":86240.47200119696,"reference_received_ms":1790003701747,"spot":86205.92229108093,"twap":86152.22942493335,"sigma":8.16878130882944,"spot_z":-0.4231110874136198,"twap_z":-1.0806577616335578,"momentum":-0.24849453661448478,"decision_ms":1790003900077,"momentum30":0.7901632527808065,"momentum60":1.7396814294196716,"spot_twap_gap":0.8485622213722526,"range60":1.8411288991821448,"final_mean":86205.92229108093,"final_z":-0.5463744270693757,"final_up_prob":0.292404292520534,"final_drift_up_prob":0.10452514502571658,"final_known_seconds":0,"final_sd":63.23449342485805,"final_drift_shift":-44.8842701887789},"entry_side":null,"context_gap":null,"book_errors":[null,null],"books":[{"bid":0.26,"ask":0.27,"asks":[[0.27,690.06]],"received_ms":1790003900077,"observed_ms":1790003900058,"hash":"67696538d67cc83d9c1d0f96ff95a47f5aac9380"},{"bid":0.73,"ask":0.74,"asks":[[0.74,38.0]],"received_ms":1790003900071,"observed_ms":1790003900060,"hash":"8a46e06f80df5b2b5e79b1d1b575531ee7598213"}],"intents":{"pair_fast":null,"pair_250":null,"pair_add_fast":null,"pair_add_250":null},"decision_ms":1790003900078,"feature_cutoff_ms":1790003900077,"request_ms":1790003900035,"inventory":{"pair_fast":{"qty":[5.0,0.0],"cash":1.9315900000000001,"lots":[[[5.0,0.38631800000000005]],[]],"floor":-1.9315900000000001},"pair_250":{"qty":[5.0,0.0],"cash":1.9315900000000001,"lots":[[[5.0,0.38631800000000005]],[]],"floor":-1.9315900000000001},"pair_add_fast":{"qty":[5.0,0.0],"cash":1.9315900000000001,"lots":[[[5.0,0.38631800000000005]],[]],"floor":-1.9315900000000001},"pair_add_250":{"qty":[5.0,0.0],"cash":1.9315900000000001,"lots":[[[5.0,0.38631800000000005]],[]],"floor":-1.9315900000000001}}}
{"kind":"decision","recorded_ms":1790003910041,"S":1790003700,"age":210,"signal":{"rsi14":60.49380513607254,"volume_ratio":0.48494711385247097,"taker_buy_fraction":0.4124156304150696,"volume5":132.34479,"return1":7.276371364555274,"return5":-10.495748044504335,"return15":23.715494807754283,"bollinger_z":0.702181407800456,"bar_close_ms":1790003879999,"ref":86240.47200119696,"reference_received_ms":1790003701747,"spot":86161.5808177981,"twap":86164.175883603,"sigma":10.076817929918027,"spot_z":-0.8254301641919882,"twap_z":-0.7982782632931636,"momentum":-1.3382681356216344,"decision_ms":1790003910040,"momentum30":-0.36137063175282796,"momentum60":0.6273378719791377,"spot_twap_gap":-0.03324676074872796,"range60":1.3420470221619518,"final_mean":86161.5808177981,"final_z":-1.1076277911837134,"final_up_prob":0.13401129802175277,"final_drift_up_prob":1.3160505563658553e-06,"final_known_seconds":0,"final_sd":71.22535568970991,"final_drift_shift":-255.69849604598494},"entry_side":null,"context_gap":null,"book_errors":[null,null],"books":[{"bid":0.05,"ask":0.06,"asks":[[0.06,1234.49]],"received_ms":1790003910037,"observed_ms":1790003910026,"hash":"a9b3ebefc152cc58fd8185382914dc7fe16269a6"},{"bid":0.94,"ask":0.95,"asks":[[0.95,397.03]],"received_ms":1790003910040,"observed_ms":1790003910021,"hash":"7ff3b206f7ce2abf1df2cf529963c3a056b9fea3"}],"intents":{"pair_fast":null,"pair_250":null,"pair_add_fast":null,"pair_add_250":null},"decision_ms":1790003910041,"feature_cutoff_ms":1790003910040,"request_ms":1790003910001,"inventory":{"pair_fast":{"qty":[5.0,0.0],"cash":1.9315900000000001,"lots":[[[5.0,0.38631800000000005]],[]],"floor":-1.9315900000000001},"pair_250":{"qty":[5.0,0.0],"cash":1.9315900000000001,"lots":[[[5.0,0.38631800000000005]],[]],"floor":-1.9315900000000001},"pair_add_fast":{"qty":[5.0,0.0],"cash":1.9315900000000001,"lots":[[[5.0,0.38631800000000005]],[]],"floor":-1.9315900000000001},"pair_add_250":{"qty":[5.0,0.0],"cash":1.9315900000000001,"lots":[[[5.0,0.38631800000000005]],[]],"floor":-1.9315900000000001}}}
{"kind":"decision","recorded_ms":1790003920056,"S":1790003700,"age":220,"signal":{"rsi14":60.49380513607254,"volume_ratio":0.48494711385247097,"taker_buy_fraction":0.4124156304150696,"volume5":132.34479,"return1":7.276371364555274,"return5":-10.495748044504335,"return15":23.715494807754283,"bollinger_z":0.702181407800456,"bar_close_ms":1790003879999,"ref":86240.47200119696,"reference_received_ms":1790003701747,"spot":86115.71854341112,"twap":86168.94924218752,"sigma":10.603493410766896,"spot_z":-1.3158465649122593,"twap_z":-0.7543917293032458,"momentum":-0.7177854563676148,"decision_ms":1790003920054,"momentum30":-1.6636816745001215,"momentum60":-0.011488954132612632,"spot_twap_gap":-0.6480933590516842,"range60":1.1764005937748263,"final_mean":86115.71854341112,"final_z":-1.8615168494433654,"final_up_prob":0.031335611721574064,"final_drift_up_prob":0.00012846391048915162,"final_known_seconds":0,"final_sd":67.01709835350134,"final_drift_shift":-120.21103573184604},"entry_side":null,"context_gap":null,"book_errors":[null,null],"books":[{"bid":0.02,"ask":0.03,"asks":[[0.03,1011.67]],"received_ms":1790003920054,"observed_ms":1790003920041,"hash":"b16276cd73ea811c10a2b926dd114720d9616dc7"},{"bid":0.97,"ask":0.98,"asks":[[0.98,417.03]],"received_ms":1790003920045,"observed_ms":1790003920032,"hash":"29f23094ff89aaa887c10e5ed7c30609857af7b6"}],"intents":{"pair_fast":null,"pair_250":null,"pair_add_fast":null,"pair_add_250":null},"decision_ms":1790003920056,"feature_cutoff_ms":1790003920054,"request_ms":1790003920014,"inventory":{"pair_fast":{"qty":[5.0,0.0],"cash":1.9315900000000001,"lots":[[[5.0,0.38631800000000005]],[]],"floor":-1.9315900000000001},"pair_250":{"qty":[5.0,0.0],"cash":1.9315900000000001,"lots":[[[5.0,0.38631800000000005]],[]],"floor":-1.9315900000000001},"pair_add_fast":{"qty":[5.0,0.0],"cash":1.9315900000000001,"lots":[[[5.0,0.38631800000000005]],[]],"floor":-1.9315900000000001},"pair_add_250":{"qty":[5.0,0.0],"cash":1.9315900000000001,"lots":[[[5.0,0.38631800000000005]],[]],"floor":-1.9315900000000001}}}
{"kind":"decision","recorded_ms":1790003930286,"S":1790003700,"age":230,"signal":{"rsi14":60.49380513607254,"volume_ratio":0.48494711385247097,"taker_buy_fraction":0.4124156304150696,"volume5":132.34479,"return1":7.276371364555274,"return5":-10.495748044504335,"return15":23.715494807754283,"bollinger_z":0.702181407800456,"bar_close_ms":1790003879999,"ref":86240.47200119696,"reference_received_ms":1790003701747,"spot":86120.99451801398,"twap":86167.50999132244,"sigma":8.423186963720417,"spot_z":-1.6988044663437387,"twap_z":-1.0374188085165885,"momentum":-0.07071727299561151,"decision_ms":1790003930284,"momentum30":-1.8040509750993685,"momentum60":-0.759805865002352,"spot_twap_gap":-0.7129275187668551,"range60":1.46689217746519,"final_mean":86120.99451801398,"final_z":-2.6020428823324266,"final_up_prob":0.004633513197525363,"final_drift_up_prob":0.002846393507805467,"final_known_seconds":0,"final_sd":45.9168002165621,"final_drift_shift":-7.481134253121877},"entry_side":null,"context_gap":null,"book_errors":[null,null],"books":[{"bid":0.01,"ask":0.02,"asks":[[0.02,786.42]],"received_ms":1790003930062,"observed_ms":1790003930054,"hash":"bbd70620bdaacfb2666a2a069526b11f001c910a"},{"bid":0.98,"ask":0.99,"asks":[[0.99,6108.73]],"received_ms":1790003930284,"observed_ms":1790003930274,"hash":"94fbde458f44bd179096ca5593b1905558aaf336"}],"intents":{"pair_fast":null,"pair_250":null,"pair_add_fast":null,"pair_add_250":null},"decision_ms":1790003930286,"feature_cutoff_ms":1790003930284,"request_ms":1790003930030,"inventory":{"pair_fast":{"qty":[5.0,0.0],"cash":1.9315900000000001,"lots":[[[5.0,0.38631800000000005]],[]],"floor":-1.9315900000000001},"pair_250":{"qty":[5.0,0.0],"cash":1.9315900000000001,"lots":[[[5.0,0.38631800000000005]],[]],"floor":-1.9315900000000001},"pair_add_fast":{"qty":[5.0,0.0],"cash":1.9315900000000001,"lots":[[[5.0,0.38631800000000005]],[]],"floor":-1.9315900000000001},"pair_add_250":{"qty":[5.0,0.0],"cash":1.9315900000000001,"lots":[[[5.0,0.38631800000000005]],[]],"floor":-1.9315900000000001}}}
{"kind":"decision","recorded_ms":1790003940054,"S":1790003700,"age":240,"signal":{"rsi14":60.49380513607254,"volume_ratio":0.48494711385247097,"taker_buy_fraction":0.4124156304150696,"volume5":132.34479,"return1":7.276371364555274,"return5":-10.495748044504335,"return15":23.715494807754283,"bollinger_z":0.702181407800456,"bar_close_ms":1790003879999,"ref":86240.47200119696,"reference_received_ms":1790003701747,"spot":86175.08336715953,"twap":86161.01943420431,"sigma":10.736444465172204,"spot_z":-0.7866074511032638,"twap_z":-0.9557927325707014,"momentum":1.6074314672319039,"decision_ms":1790003940053,"momentum30":0.6002221896246411,"momentum60":-0.07746826439886952,"spot_twap_gap":0.16911054149705557,"range60":1.150837887392739,"final_mean":86175.08336715953,"final_z":-1.3636486266030476,"final_up_prob":0.08633909000495277,"final_drift_up_prob":0.9795588674716297,"final_known_seconds":0,"final_sd":47.9512337429021,"final_drift_shift":163.43558066036357},"entry_side":null,"context_gap":null,"book_errors":[null,null],"books":[{"bid":0.06,"ask":0.07,"asks":[[0.07,1172.09]],"received_ms":1790003940044,"observed_ms":1790003940034,"hash":"dcb99cf36e96a5d1ec8ba9532266674391513dba"},{"bid":0.93,"ask":0.94,"asks":[[0.94,40.0]],"received_ms":1790003940052,"observed_ms":1790003940032,"hash":"cac5b25684eca774a4922c9b6a80e99fc78adfd9"}],"intents":{"pair_fast":null,"pair_250":null,"pair_add_fast":null,"pair_add_250":null},"decision_ms":1790003940054,"feature_cutoff_ms":1790003940053,"request_ms":1790003940009,"inventory":{"pair_fast":{"qty":[5.0,0.0],"cash":1.9315900000000001,"lots":[[[5.0,0.38631800000000005]],[]],"floor":-1.9315900000000001},"pair_250":{"qty":[5.0,0.0],"cash":1.9315900000000001,"lots":[[[5.0,0.38631800000000005]],[]],"floor":-1.9315900000000001},"pair_add_fast":{"qty":[5.0,0.0],"cash":1.9315900000000001,"lots":[[[5.0,0.38631800000000005]],[]],"floor":-1.9315900000000001},"pair_add_250":{"qty":[5.0,0.0],"cash":1.9315900000000001,"lots":[[[5.0,0.38631800000000005]],[]],"floor":-1.9315900000000001}}}
{"kind":"decision","recorded_ms":1790003950035,"S":1790003700,"age":250,"signal":{"rsi14":59.05109489051123,"volume_ratio":0.5017248754407013,"taker_buy_fraction":0.4514404124544779,"volume5":128.59407,"return1":-0.6845269414134483,"return5":-4.4842315738393035,"return15":26.61417543915007,"bollinger_z":0.5884323476997174,"bar_close_ms":1790003939999,"ref":86240.47200119696,"reference_received_ms":1790003701747,"spot":86171.43420752091,"twap":86159.92748012219,"sigma":10.447253704134411,"spot_z":-0.9348619204874037,"twap_z":-1.0906780423781395,"momentum":-0.280662919140339,"decision_ms":1790003950034,"momentum30":0.8485558269188905,"momentum60":-0.5055007551971281,"spot_twap_gap":0.1421916382578904,"range60":1.1826942674435579,"final_mean":86173.02635381384,"final_z":-1.8995546274399437,"final_up_prob":0.028745795666500595,"final_drift_up_prob":0.007285467995455153,"final_known_seconds":10,"final_sd":35.50603199762711,"final_drift_shift":-19.29101603043159},"entry_side":null,"context_gap":null,"book_errors":[null,null],"books":[{"bid":0.02,"ask":0.03,"asks":[[0.03,687.72]],"received_ms":1790003950033,"observed_ms":1790003950025,"hash":"508588db2af0e29b4338e2be0febd6cd343b6f4a"},{"bid":0.97,"ask":0.98,"asks":[[0.98,657.38]],"received_ms":1790003950034,"observed_ms":1790003950026,"hash":"0fd8d86d6a952b3d8e5ec330bb577eb2e7a4d8d3"}],"intents":{"pair_fast":null,"pair_250":null,"pair_add_fast":null,"pair_add_250":null},"decision_ms":1790003950035,"feature_cutoff_ms":1790003950034,"request_ms":1790003950004,"inventory":{"pair_fast":{"qty":[5.0,0.0],"cash":1.9315900000000001,"lots":[[[5.0,0.38631800000000005]],[]],"floor":-1.9315900000000001},"pair_250":{"qty":[5.0,0.0],"cash":1.9315900000000001,"lots":[[[5.0,0.38631800000000005]],[]],"floor":-1.9315900000000001},"pair_add_fast":{"qty":[5.0,0.0],"cash":1.9315900000000001,"lots":[[[5.0,0.38631800000000005]],[]],"floor":-1.9315900000000001},"pair_add_250":{"qty":[5.0,0.0],"cash":1.9315900000000001,"lots":[[[5.0,0.38631800000000005]],[]],"floor":-1.9315900000000001}}}
{"kind":"decision","recorded_ms":1790003960038,"S":1790003700,"age":260,"signal":{"rsi14":59.05109489051123,"volume_ratio":0.5017248754407013,"taker_buy_fraction":0.4514404124544779,"volume5":128.59407,"return1":-0.6845269414134483,"return5":-4.4842315738393035,"return15":26.61417543915007,"bollinger_z":0.5884323476997174,"bar_close_ms":1790003939999,"ref":86240.47200119696,"reference_received_ms":1790003701747,"spot":86198.06186561807,"twap":86154.57011575656,"sigma":11.11238677074074,"spot_z":-0.6037168122742403,"twap_z":-1.222830621466835,"momentum":0.4535160917322766,"decision_ms":1790003960037,"momentum30":1.2741860824513274,"momentum60":-0.07160864033936222,"spot_twap_gap":0.5052704589517588,"range60":1.0176185772449793,"final_mean":86192.2782695142,"final_z":-1.7840538494586957,"final_up_prob":0.03720745770541578,"final_drift_up_prob":0.15892052172701465,"final_known_seconds":20,"final_sd":27.013608192034425,"final_drift_shift":21.2097217684765},"entry_side":null,"context_gap":null,"book_errors":[null,null],"books":[{"bid":null,"ask":0.01,"asks":[[0.01,5406.46]],"received_ms":1790003960037,"observed_ms":1790003960021,"hash":"c2bec38d53fb38d2b63870cae61b864a8f153c75"},{"bid":0.99,"ask":null,"asks":[],"received_ms":1790003960035,"observed_ms":1790003960021,"hash":"2f3923c3cc8248f5cd8f882b03498f0cee39f709"}],"intents":{"pair_fast":null,"pair_250":null,"pair_add_fast":null,"pair_add_250":null},"decision_ms":1790003960038,"feature_cutoff_ms":1790003960037,"request_ms":1790003960007,"inventory":{"pair_fast":{"qty":[5.0,0.0],"cash":1.9315900000000001,"lots":[[[5.0,0.38631800000000005]],[]],"floor":-1.9315900000000001},"pair_250":{"qty":[5.0,0.0],"cash":1.9315900000000001,"lots":[[[5.0,0.38631800000000005]],[]],"floor":-1.9315900000000001},"pair_add_fast":{"qty":[5.0,0.0],"cash":1.9315900000000001,"lots":[[[5.0,0.38631800000000005]],[]],"floor":-1.9315900000000001},"pair_add_250":{"qty":[5.0,0.0],"cash":1.9315900000000001,"lots":[[[5.0,0.38631800000000005]],[]],"floor":-1.9315900000000001}}}
{"kind":"decision","recorded_ms":1790003970066,"S":1790003700,"age":270,"signal":{"rsi14":59.05109489051123,"volume_ratio":0.5017248754407013,"taker_buy_fraction":0.4514404124544779,"volume5":128.59407,"return1":-0.6845269414134483,"return5":-4.4842315738393035,"return15":26.61417543915007,"bollinger_z":0.5884323476997174,"bar_close_ms":1790003939999,"ref":86240.47200119696,"reference_received_ms":1790003701747,"spot":86190.5344745684,"twap":86156.78843956038,"sigma":9.034284523548038,"spot_z":-1.010284368351022,"twap_z":-1.6929992315843487,"momentum":-0.2477283991755386,"decision_ms":1790003970065,"momentum30":0.1986138723245347,"momentum60":0.7251823657307855,"spot_twap_gap":0.48222904369067526,"range60":1.2029200383522791,"final_mean":86188.349311649,"final_z":-3.660800302118167,"final_up_prob":0.0001257143363037061,"final_drift_up_prob":2.765325596265633e-05,"final_known_seconds":30,"final_sd":14.238058688370547,"final_drift_shift":-5.2850224626261735},"entry_side":null,"context_gap":null,"book_errors":[null,null],"books":[{"bid":null,"ask":0.01,"asks":[[0.01,35502.51]],"received_ms":1790003970065,"observed_ms":1790003970041,"hash":"75a6bb5b53c5aaf5e7d1e34006804f98a07755d4"},{"bid":0.99,"ask":null,"asks":[],"received_ms":1790003970045,"observed_ms":1790003970029,"hash":"8d7ec6df5e4d3e0f9a874a51d8fc9791990ebc9c"}],"intents":{"pair_fast":null,"pair_250":null,"pair_add_fast":null,"pair_add_250":null},"decision_ms":1790003970066,"feature_cutoff_ms":1790003970065,"request_ms":1790003970013,"inventory":{"pair_fast":{"qty":[5.0,0.0],"cash":1.9315900000000001,"lots":[[[5.0,0.38631800000000005]],[]],"floor":-1.9315900000000001},"pair_250":{"qty":[5.0,0.0],"cash":1.9315900000000001,"lots":[[[5.0,0.38631800000000005]],[]],"floor":-1.9315900000000001},"pair_add_fast":{"qty":[5.0,0.0],"cash":1.9315900000000001,"lots":[[[5.0,0.38631800000000005]],[]],"floor":-1.9315900000000001},"pair_add_250":{"qty":[5.0,0.0],"cash":1.9315900000000001,"lots":[[[5.0,0.38631800000000005]],[]],"floor":-1.9315900000000001}}}
{"kind":"decision","recorded_ms":1790003980080,"S":1790003700,"age":280,"signal":{},"entry_side":null,"context_gap":"incomplete or stale context","book_errors":[null,null],"books":[{"bid":null,"ask":0.01,"asks":[[0.01,57611.78]],"received_ms":1790003980079,"observed_ms":1790003980065,"hash":"d7e982589f51597e3b551e0eb61ef33a478b4451"},{"bid":0.99,"ask":null,"asks":[],"received_ms":1790003980070,"observed_ms":1790003980058,"hash":"55e1f0c9cb7a504c516edd370f071ef67141054d"}],"intents":{"pair_fast":null,"pair_250":null,"pair_add_fast":null,"pair_add_250":null},"decision_ms":1790003980080,"feature_cutoff_ms":1790003980079,"request_ms":1790003980039,"inventory":{"pair_fast":{"qty":[5.0,0.0],"cash":1.9315900000000001,"lots":[[[5.0,0.38631800000000005]],[]],"floor":-1.9315900000000001},"pair_250":{"qty":[5.0,0.0],"cash":1.9315900000000001,"lots":[[[5.0,0.38631800000000005]],[]],"floor":-1.9315900000000001},"pair_add_fast":{"qty":[5.0,0.0],"cash":1.9315900000000001,"lots":[[[5.0,0.38631800000000005]],[]],"floor":-1.9315900000000001},"pair_add_250":{"qty":[5.0,0.0],"cash":1.9315900000000001,"lots":[[[5.0,0.38631800000000005]],[]],"floor":-1.9315900000000001}}}
{"kind":"decision","recorded_ms":1790003990028,"S":1790003700,"age":290,"signal":{"rsi14":59.05109489051123,"volume_ratio":0.5017248754407013,"taker_buy_fraction":0.4514404124544779,"volume5":128.59407,"return1":-0.6845269414134483,"return5":-4.4842315738393035,"return15":26.61417543915007,"bollinger_z":0.5884323476997174,"bar_close_ms":1790003939999,"ref":86240.47200119696,"reference_received_ms":1790003701747,"spot":86140.54232484449,"twap":86169.49793420632,"sigma":10.138772140933485,"spot_z":-3.1210175258626385,"twap_z":-2.2166719141392077,"momentum":-0.5516302338163622,"decision_ms":1790003990027,"momentum30":-1.0276800771290513,"momentum60":0.25509596807048723,"spot_twap_gap":-0.3686987973125873,"range60":1.0225295638539784,"final_mean":86168.50285950706,"final_z":-23.42254631656754,"final_up_prob":0.0,"final_drift_up_prob":0.0,"final_known_seconds":50,"final_sd":3.072643798722869,"final_drift_shift":-1.465898229112445},"entry_side":null,"context_gap":null,"book_errors":[null,null],"books":[{"bid":null,"ask":0.01,"asks":[[0.01,65309.97]],"received_ms":1790003990026,"observed_ms":1790003989995,"hash":"fff5d0b8759d1158703ebcb12ec515125b4b0178"},{"bid":0.99,"ask":null,"asks":[],"received_ms":1790003990027,"observed_ms":1790003989995,"hash":"b56e2be66b1c73dc4dbedb7f2d1b4c3192f177d3"}],"intents":{"pair_fast":null,"pair_250":null,"pair_add_fast":null,"pair_add_250":null},"decision_ms":1790003990028,"feature_cutoff_ms":1790003990027,"request_ms":1790003990002,"inventory":{"pair_fast":{"qty":[5.0,0.0],"cash":1.9315900000000001,"lots":[[[5.0,0.38631800000000005]],[]],"floor":-1.9315900000000001},"pair_250":{"qty":[5.0,0.0],"cash":1.9315900000000001,"lots":[[[5.0,0.38631800000000005]],[]],"floor":-1.9315900000000001},"pair_add_fast":{"qty":[5.0,0.0],"cash":1.9315900000000001,"lots":[[[5.0,0.38631800000000005]],[]],"floor":-1.9315900000000001},"pair_add_250":{"qty":[5.0,0.0],"cash":1.9315900000000001,"lots":[[[5.0,0.38631800000000005]],[]],"floor":-1.9315900000000001}}}
{"kind":"decision","recorded_ms":1790004030068,"S":1790004000,"age":30,"signal":{"rsi14":54.520396421147964,"volume_ratio":0.4928618011615805,"taker_buy_fraction":0.36852292543774395,"volume5":124.23644999999999,"return1":-7.086972266416766,"return5":-18.49184260930663,"return15":15.94800967422807,"bollinger_z":0.04865519810540365,"bar_close_ms":1790003999999,"ref":86169.19843132998,"reference_received_ms":1790004001552,"spot":86076.97783188263,"twap":86119.91136767456,"sigma":8.534294398381125,"spot_z":-0.6577067968014139,"twap_z":-0.35150971642791906,"momentum":0.9026516646256032,"decision_ms":1790004030067,"momentum30":-1.1554838460376557,"momentum60":-1.2476479045628368,"spot_twap_gap":-0.6494614995060423,"range60":1.7641148564682312,"final_mean":86076.97783188263,"final_z":-0.7126227253261112,"final_up_prob":0.2380396227364156,"final_drift_up_prob":0.9999287980610716,"final_known_seconds":0,"final_sd":129.4101298904632,"final_drift_shift":584.4909511311968},"entry_side":null,"context_gap":null,"book_errors":[null,null],"books":[{"bid":0.24,"ask":0.25,"asks":[[0.25,371.38]],"received_ms":1790004030066,"observed_ms":1790004030054,"hash":"72dc62218b050fd8dfaf6213af2bb82905d1ae10"},{"bid":0.75,"ask":0.76,"asks":[[0.76,905.43]],"received_ms":1790004030065,"observed_ms":1790004030054,"hash":"457ef2e470ccbeb374efed1aa2d209659e5f2e43"}],"intents":{"pair_fast":{"kind":"first","side":0,"qty":5.0,"participation":true,"max_cost":1.3656300000000001},"pair_250":{"kind":"first","side":0,"qty":5.0,"participation":true,"max_cost":1.3656300000000001},"pair_add_fast":{"kind":"first","side":0,"qty":5.0,"participation":true,"max_cost":1.3656300000000001},"pair_add_250":{"kind":"first","side":0,"qty":5.0,"participation":true,"max_cost":1.3656300000000001}},"decision_ms":1790004030068,"feature_cutoff_ms":1790004030067,"request_ms":1790004030025,"inventory":{"pair_fast":{"qty":[0.0,0.0],"cash":0.0,"lots":[[],[]],"floor":0.0},"pair_250":{"qty":[0.0,0.0],"cash":0.0,"lots":[[],[]],"floor":0.0},"pair_add_fast":{"qty":[0.0,0.0],"cash":0.0,"lots":[[],[]],"floor":0.0},"pair_add_250":{"qty":[0.0,0.0],"cash":0.0,"lots":[[],[]],"floor":0.0}}}
{"kind":"decision","recorded_ms":1790004040076,"S":1790004000,"age":40,"signal":{"rsi14":54.520396421147964,"volume_ratio":0.4928618011615805,"taker_buy_fraction":0.36852292543774395,"volume5":124.23644999999999,"return1":-7.086972266416766,"return5":-18.49184260930663,"return15":15.94800967422807,"bollinger_z":0.04865519810540365,"bar_close_ms":1790003999999,"ref":86169.19843132998,"reference_received_ms":1790004001552,"spot":86028.17395644607,"twap":86101.58207924633,"sigma":9.369815447066172,"spot_z":-0.9335539656137236,"twap_z":-0.44760679789790525,"momentum":-1.1873402167624827,"decision_ms":1790004040075,"momentum30":-0.6648728856951377,"momentum60":-1.7919207537463826,"spot_twap_gap":-1.0114337850371176,"range60":1.7919207537463826,"final_mean":86028.17395644607,"final_z":-1.0149067807853314,"final_up_prob":0.15507513280493512,"final_drift_up_prob":4.064304448547773e-12,"final_known_seconds":0,"final_sd":138.95313102034743,"final_drift_shift":-808.8954827381084},"entry_side":null,"context_gap":null,"book_errors":[null,null],"books":[{"bid":0.19,"ask":0.2,"asks":[[0.2,841.48]],"received_ms":1790004040067,"observed_ms":1790004040055,"hash":"f027d51e64791b009699329a6620bde754808db7"},{"bid":0.8,"ask":0.81,"asks":[[0.81,632.36]],"received_ms":1790004040075,"observed_ms":1790004040061,"hash":"b6ce62586f67e10250bf47909bdc2269f8b537ab"}],"intents":{"pair_fast":null,"pair_250":null,"pair_add_fast":null,"pair_add_250":null},"decision_ms":1790004040076,"feature_cutoff_ms":1790004040075,"request_ms":1790004040037,"inventory":{"pair_fast":{"qty":[5.0,0.0],"cash":1.31563,"lots":[[[5.0,0.263126]],[]],"floor":-1.31563},"pair_250":{"qty":[5.0,0.0],"cash":1.31563,"lots":[[[5.0,0.263126]],[]],"floor":-1.31563},"pair_add_fast":{"qty":[5.0,0.0],"cash":1.31563,"lots":[[[5.0,0.263126]],[]],"floor":-1.31563},"pair_add_250":{"qty":[5.0,0.0],"cash":1.31563,"lots":[[[5.0,0.263126]],[]],"floor":-1.31563}}}
{"kind":"decision","recorded_ms":1790004050090,"S":1790004000,"age":50,"signal":{"rsi14":54.520396421147964,"volume_ratio":0.4928618011615805,"taker_buy_fraction":0.36852292543774395,"volume5":124.23644999999999,"return1":-7.086972266416766,"return5":-18.49184260930663,"return15":15.94800967422807,"bollinger_z":0.04865519810540365,"bar_close_ms":1790003999999,"ref":86169.19843132998,"reference_received_ms":1790004001552,"spot":86038.64354879252,"twap":86080.93651471953,"sigma":9.250028801831323,"spot_z":-0.8928065076914016,"twap_z":-0.6035838108812925,"momentum":0.348644727927294,"decision_ms":1790004050089,"momentum30":-0.2758083938344679,"momentum60":-1.441329773922232,"spot_twap_gap":-0.5902682618841165,"range60":1.5836633880777884,"final_mean":86038.64354879252,"final_z":-0.9741648036304588,"final_up_prob":0.16498735865800662,"final_drift_up_prob":0.757812749975191,"final_known_seconds":0,"final_sd":134.01724436246627,"final_drift_shift":224.27101098542738},"entry_side":null,"context_gap":null,"book_errors":[null,null],"books":[{"bid":0.19,"ask":0.2,"asks":[[0.2,117.0]],"received_ms":1790004050077,"observed_ms":1790004050069,"hash":"61c23bd8d1e31715678896c739c340366e6ec038"},{"bid":0.8,"ask":0.81,"asks":[[0.81,2098.12]],"received_ms":1790004050089,"observed_ms":1790004050073,"hash":"6a9b1520a911450234d61a92e2d0116b392d4c66"}],"intents":{"pair_fast":null,"pair_250":null,"pair_add_fast":null,"pair_add_250":null},"decision_ms":1790004050090,"feature_cutoff_ms":1790004050089,"request_ms":1790004050048,"inventory":{"pair_fast":{"qty":[5.0,0.0],"cash":1.31563,"lots":[[[5.0,0.263126]],[]],"floor":-1.31563},"pair_250":{"qty":[5.0,0.0],"cash":1.31563,"lots":[[[5.0,0.263126]],[]],"floor":-1.31563},"pair_add_fast":{"qty":[5.0,0.0],"cash":1.31563,"lots":[[[5.0,0.263126]],[]],"floor":-1.31563},"pair_add_250":{"qty":[5.0,0.0],"cash":1.31563,"lots":[[[5.0,0.263126]],[]],"floor":-1.31563}}}
{"kind":"decision","recorded_ms":1790004060059,"S":1790004000,"age":60,"signal":{"rsi14":54.520396421147964,"volume_ratio":0.4928618011615805,"taker_buy_fraction":0.36852292543774395,"volume5":124.23644999999999,"return1":-7.086972266416766,"return5":-18.49184260930663,"return15":15.94800967422807,"bollinger_z":0.04865519810540365,"bar_close_ms":1790003999999,"ref":86169.19843132998,"reference_received_ms":1790004001552,"spot":86077.48166951344,"twap":86065.77968542358,"sigma":10.965471901696201,"spot_z":-0.5399649057802663,"twap_z":-0.6088581005614031,"momentum":1.1360709539974951,"decision_ms":1790004060055,"momentum30":0.23521123571197464,"momentum60":-0.6299686957190201,"spot_twap_gap":0.1377706006146785,"range60":1.2072872016769678,"final_mean":86077.48166951344,"final_z":-0.5915154771560807,"final_up_prob":0.2770875440468342,"final_drift_up_prob":0.9999989446084554,"final_known_seconds":0,"final_sd":155.05386648123067,"final_drift_shift":827.0624786549389},"entry_side":null,"context_gap":null,"book_errors":[null,null],"books":[{"bid":0.23,"ask":0.24,"asks":[[0.24,140.0]],"received_ms":1790004060054,"observed_ms":1790004059999,"hash":"fdf42e8b98b4f2d8eb5a3796d790142215ba3299"},{"bid":0.76,"ask":0.77,"asks":[[0.77,712.82]],"received_ms":1790004060052,"observed_ms":1790004059999,"hash":"81791441e8f29498213dc4b54c1753414e59ca82"}],"intents":{"pair_fast":null,"pair_250":null,"pair_add_fast":null,"pair_add_250":null},"decision_ms":1790004060058,"feature_cutoff_ms":1790004060055,"request_ms":1790004060012,"inventory":{"pair_fast":{"qty":[5.0,0.0],"cash":1.31563,"lots":[[[5.0,0.263126]],[]],"floor":-1.31563},"pair_250":{"qty":[5.0,0.0],"cash":1.31563,"lots":[[[5.0,0.263126]],[]],"floor":-1.31563},"pair_add_fast":{"qty":[5.0,0.0],"cash":1.31563,"lots":[[[5.0,0.263126]],[]],"floor":-1.31563},"pair_add_250":{"qty":[5.0,0.0],"cash":1.31563,"lots":[[[5.0,0.263126]],[]],"floor":-1.31563}}}
{"kind":"decision","recorded_ms":1790004070053,"S":1790004000,"age":70,"signal":{"rsi14":53.895874852295385,"volume_ratio":0.5921291365925434,"taker_buy_fraction":0.3746699216388006,"volume5":121.96724999999999,"return1":-7.0629313105233145,"return5":-13.841207550958446,"return15":4.7124937317789,"bollinger_z":-0.5545619284731357,"bar_close_ms":1790004059999,"ref":86169.19843132998,"reference_received_ms":1790004001552,"spot":86070.01738114747,"twap":86057.60423461813,"sigma":8.914578122864656,"spot_z":-0.733690826451873,"twap_z":-0.8255169537132276,"momentum":0.1057402319273677,"decision_ms":1790004070052,"momentum30":0.8514134119651198,"momentum60":0.11182516438184083,"spot_twap_gap":0.17976513346839446,"range60":0.8085907694702135,"final_mean":86070.01738114747,"final_z":-0.8072546302773023,"final_up_prob":0.20975989859418265,"final_drift_up_prob":0.3736714515558183,"final_known_seconds":0,"final_sd":122.86216326617959,"final_drift_shift":59.60162741024289},"entry_side":null,"context_gap":null,"book_errors":[null,null],"books":[{"bid":0.26,"ask":0.27,"asks":[[0.27,646.57]],"received_ms":1790004070035,"observed_ms":1790004070027,"hash":"a5a140ec0df095b5f285492a3183b29df364553c"},{"bid":0.73,"ask":0.74,"asks":[[0.74,208.09]],"received_ms":1790004070051,"observed_ms":1790004070037,"hash":"58b61c898cc4c6e43ad4272b019fccde30f8880f"}],"intents":{"pair_fast":null,"pair_250":null,"pair_add_fast":null,"pair_add_250":null},"decision_ms":1790004070053,"feature_cutoff_ms":1790004070052,"request_ms":1790004070007,"inventory":{"pair_fast":{"qty":[5.0,0.0],"cash":1.31563,"lots":[[[5.0,0.263126]],[]],"floor":-1.31563},"pair_250":{"qty":[5.0,0.0],"cash":1.31563,"lots":[[[5.0,0.263126]],[]],"floor":-1.31563},"pair_add_fast":{"qty":[5.0,0.0],"cash":1.31563,"lots":[[[5.0,0.263126]],[]],"floor":-1.31563},"pair_add_250":{"qty":[5.0,0.0],"cash":1.31563,"lots":[[[5.0,0.263126]],[]],"floor":-1.31563}}}
{"kind":"decision","recorded_ms":1790004080077,"S":1790004000,"age":80,"signal":{"rsi14":53.895874852295385,"volume_ratio":0.5921291365925434,"taker_buy_fraction":0.3746699216388006,"volume5":121.96724999999999,"return1":-7.0629313105233145,"return5":-13.841207550958446,"return15":4.7124937317789,"bollinger_z":-0.5545619284731357,"bar_close_ms":1790004059999,"ref":86169.19843132998,"reference_received_ms":1790004001552,"spot":86053.03334492019,"twap":86060.58851242861,"sigma":8.986229958441196,"spot_z":-0.871689427965331,"twap_z":-0.8149963212226427,"momentum":-0.8354394657871589,"decision_ms":1790004080076,"momentum30":0.3036578500815588,"momentum60":0.005977891549056791,"spot_twap_gap":-0.108540281717224,"range60":0.8021434591820581,"final_mean":86053.03334492019,"final_z":-0.9637259270754188,"final_up_prob":0.16759167603018132,"final_drift_up_prob":1.273045694638597e-06,"final_known_seconds":0,"final_sd":120.53747143890972,"final_drift_shift":-450.89182758458634},"entry_side":null,"context_gap":null,"book_errors":[null,null],"books":[{"bid":0.14,"ask":0.15,"asks":[[0.15,353.29]],"received_ms":1790004080053,"observed_ms":1790004080045,"hash":"055b1e21c23cedfbd532cb2c9ea351d054eff67a"},{"bid":0.85,"ask":0.86,"asks":[[0.86,416.0]],"received_ms":1790004080076,"observed_ms":1790004080062,"hash":"38aa43eebe1e52e1fbaf0113ed8f47ca3fae8e36"}],"intents":{"pair_fast":null,"pair_250":null,"pair_add_fast":null,"pair_add_250":null},"decision_ms":1790004080077,"feature_cutoff_ms":1790004080076,"request_ms":1790004080025,"inventory":{"pair_fast":{"qty":[5.0,0.0],"cash":1.31563,"lots":[[[5.0,0.263126]],[]],"floor":-1.31563},"pair_250":{"qty":[5.0,0.0],"cash":1.31563,"lots":[[[5.0,0.263126]],[]],"floor":-1.31563},"pair_add_fast":{"qty":[5.0,0.0],"cash":1.31563,"lots":[[[5.0,0.263126]],[]],"floor":-1.31563},"pair_add_250":{"qty":[5.0,0.0],"cash":1.31563,"lots":[[[5.0,0.263126]],[]],"floor":-1.31563}}}
{"kind":"decision","recorded_ms":1790004090037,"S":1790004000,"age":90,"signal":{"rsi14":53.895874852295385,"volume_ratio":0.5921291365925434,"taker_buy_fraction":0.3746699216388006,"volume5":121.96724999999999,"return1":-7.0629313105233145,"return5":-13.841207550958446,"return15":4.7124937317789,"bollinger_z":-0.5545619284731357,"bar_close_ms":1790004059999,"ref":86169.19843132998,"reference_received_ms":1790004001552,"spot":86009.57243538776,"twap":86055.2838012761,"sigma":10.662256398059649,"spot_z":-1.033194484495481,"twap_z":-0.7373233086521009,"momentum":-0.5023483298033499,"decision_ms":1790004090036,"momentum30":-0.9839811517412317,"momentum60":-0.6512010971449137,"spot_twap_gap":-0.5534768383240697,"range60":1.0783546069535668,"final_mean":86009.57243538776,"final_z":-1.1483546315855182,"final_up_prob":0.12541109729132366,"final_drift_up_prob":0.0004170542956308809,"final_known_seconds":0,"final_sd":139.00409468617138,"final_drift_shift":-304.8173773286748},"entry_side":null,"context_gap":null,"book_errors":[null,null],"books":[{"bid":0.16,"ask":0.17,"asks":[[0.17,164.32]],"received_ms":1790004090036,"observed_ms":1790004090027,"hash":"d07828b5b975996f2395d51073fb70bcc790cc30"},{"bid":0.83,"ask":0.84,"asks":[[0.84,1133.15]],"received_ms":1790004090033,"observed_ms":1790004090025,"hash":"7ca1680e13d6831e5e018c8364245934433f18c9"}],"intents":{"pair_fast":null,"pair_250":null,"pair_add_fast":null,"pair_add_250":null},"decision_ms":1790004090037,"feature_cutoff_ms":1790004090036,"request_ms":1790004090001,"inventory":{"pair_fast":{"qty":[5.0,0.0],"cash":1.31563,"lots":[[[5.0,0.263126]],[]],"floor":-1.31563},"pair_250":{"qty":[5.0,0.0],"cash":1.31563,"lots":[[[5.0,0.263126]],[]],"floor":-1.31563},"pair_add_fast":{"qty":[5.0,0.0],"cash":1.31563,"lots":[[[5.0,0.263126]],[]],"floor":-1.31563},"pair_add_250":{"qty":[5.0,0.0],"cash":1.31563,"lots":[[[5.0,0.263126]],[]],"floor":-1.31563}}}
{"kind":"decision","recorded_ms":1790004100040,"S":1790004000,"age":100,"signal":{"rsi14":53.895874852295385,"volume_ratio":0.5921291365925434,"taker_buy_fraction":0.3746699216388006,"volume5":121.96724999999999,"return1":-7.0629313105233145,"return5":-13.841207550958446,"return15":4.7124937317789,"bollinger_z":-0.5545619284731357,"bar_close_ms":1790004059999,"ref":86169.19843132998,"reference_received_ms":1790004001552,"spot":85999.6697165917,"twap":86046.4286355276,"sigma":10.82639212503893,"spot_z":-1.107354988953677,"twap_z":-0.8019275441595287,"momentum":-0.6452043502175019,"decision_ms":1790004100039,"momentum30":-1.3002715751001976,"momentum60":-0.34313463140897504,"spot_twap_gap":-0.5575772988632229,"range60":1.062005991892375,"final_mean":85999.6697165917,"final_z":-1.2380907000032655,"final_up_prob":0.10784121592833545,"final_drift_up_prob":3.447005910350853e-05,"final_known_seconds":0,"final_sd":136.92754071880984,"final_drift_shift":-375.4311618165967},"entry_side":null,"context_gap":null,"book_errors":[null,null],"books":[{"bid":0.09,"ask":0.1,"asks":[[0.1,182.0]],"received_ms":1790004100038,"observed_ms":1790004100009,"hash":"18f7cdee9c022dc5f40d845b9da33b0492de93cb"},{"bid":0.9,"ask":0.91,"asks":[[0.91,776.25]],"received_ms":1790004100039,"observed_ms":1790004100032,"hash":"9aaf29dac0eb9ca7806fcd3aabbabff40998d33c"}],"intents":{"pair_fast":null,"pair_250":null,"pair_add_fast":null,"pair_add_250":null},"decision_ms":1790004100040,"feature_cutoff_ms":1790004100039,"request_ms":1790004100013,"inventory":{"pair_fast":{"qty":[5.0,0.0],"cash":1.31563,"lots":[[[5.0,0.263126]],[]],"floor":-1.31563},"pair_250":{"qty":[5.0,0.0],"cash":1.31563,"lots":[[[5.0,0.263126]],[]],"floor":-1.31563},"pair_add_fast":{"qty":[5.0,0.0],"cash":1.31563,"lots":[[[5.0,0.263126]],[]],"floor":-1.31563},"pair_add_250":{"qty":[5.0,0.0],"cash":1.31563,"lots":[[[5.0,0.263126]],[]],"floor":-1.31563}}}
{"kind":"decision","recorded_ms":1790004110052,"S":1790004000,"age":110,"signal":{"rsi14":53.895874852295385,"volume_ratio":0.5921291365925434,"taker_buy_fraction":0.3746699216388006,"volume5":121.96724999999999,"return1":-7.0629313105233145,"return5":-13.841207550958446,"return15":4.7124937317789,"bollinger_z":-0.5545619284731357,"bar_close_ms":1790004059999,"ref":86169.19843132998,"reference_received_ms":1790004001552,"spot":85990.21250091061,"twap":86040.3202254266,"sigma":10.795171594412245,"spot_z":-1.2030144336226498,"twap_z":-0.8662264208023405,"momentum":-0.21129067084435085,"decision_ms":1790004110051,"momentum30":-0.6138863564459573,"momentum60":-0.5725361558642222,"spot_twap_gap":-0.5992382207469495,"range60":1.1249545079902332,"final_mean":85990.21250091061,"final_z":-1.3539965472150348,"final_up_prob":0.08786873964188874,"final_drift_up_prob":0.012982094925674703,"final_known_seconds":0,"final_sd":132.19083223477475,"final_drift_shift":-115.36960373350342},"entry_side":null,"context_gap":null,"book_errors":[null,null],"books":[{"bid":0.09,"ask":0.11,"asks":[[0.11,140.0]],"received_ms":1790004110045,"observed_ms":1790004110036,"hash":"22f995364eb430b0ed54d7ab8d30c2db9c94511d"},{"bid":0.89,"ask":0.91,"asks":[[0.91,1148.61]],"received_ms":1790004110051,"observed_ms":1790004110038,"hash":"a44516fe526f17c8983f0874c5fc7582069d981d"}],"intents":{"pair_fast":null,"pair_250":null,"pair_add_fast":null,"pair_add_250":null},"decision_ms":1790004110052,"feature_cutoff_ms":1790004110051,"request_ms":1790004110015,"inventory":{"pair_fast":{"qty":[5.0,0.0],"cash":1.31563,"lots":[[[5.0,0.263126]],[]],"floor":-1.31563},"pair_250":{"qty":[5.0,0.0],"cash":1.31563,"lots":[[[5.0,0.263126]],[]],"floor":-1.31563},"pair_add_fast":{"qty":[5.0,0.0],"cash":1.31563,"lots":[[[5.0,0.263126]],[]],"floor":-1.31563},"pair_add_250":{"qty":[5.0,0.0],"cash":1.31563,"lots":[[[5.0,0.263126]],[]],"floor":-1.31563}}}
{"kind":"decision","recorded_ms":1790004120067,"S":1790004000,"age":120,"signal":{"rsi14":53.895874852295385,"volume_ratio":0.5921291365925434,"taker_buy_fraction":0.3746699216388006,"volume5":121.96724999999999,"return1":-7.0629313105233145,"return5":-13.841207550958446,"return15":4.7124937317789,"bollinger_z":-0.5545619284731357,"bar_close_ms":1790004059999,"ref":86169.19843132998,"reference_received_ms":1790004001552,"spot":86024.09159604476,"twap":86032.49526508861,"sigma":10.081159175596346,"spot_z":-1.0730520314573566,"twap_z":-1.0109076526520742,"momentum":1.032285612913971,"decision_ms":1790004120066,"momentum30":0.04224487200845301,"momentum60":-0.549953270241869,"spot_twap_gap":-0.10761748620027632,"range60":1.0980480083081965,"final_mean":86024.09159604476,"final_z":-1.2167903984182304,"final_up_prob":0.1118419870544341,"final_drift_up_prob":0.9982538438618476,"final_known_seconds":0,"final_sd":119.25376422582575,"final_drift_shift":493.4128709295882},"entry_side":null,"context_gap":null,"book_errors":[null,null],"books":[{"bid":0.09,"ask":0.1,"asks":[[0.1,653.73]],"received_ms":1790004120066,"observed_ms":1790004120052,"hash":"f641563df3f20f9a7b5929ad49081bf76ed48200"},{"bid":0.9,"ask":0.91,"asks":[[0.91,208.4]],"received_ms":1790004120054,"observed_ms":1790004120043,"hash":"d873f8f32835705e5c22e732331da4dd62169ab0"}],"intents":{"pair_fast":null,"pair_250":null,"pair_add_fast":null,"pair_add_250":null},"decision_ms":1790004120067,"feature_cutoff_ms":1790004120066,"request_ms":1790004120025,"inventory":{"pair_fast":{"qty":[5.0,0.0],"cash":1.31563,"lots":[[[5.0,0.263126]],[]],"floor":-1.31563},"pair_250":{"qty":[5.0,0.0],"cash":1.31563,"lots":[[[5.0,0.263126]],[]],"floor":-1.31563},"pair_add_fast":{"qty":[5.0,0.0],"cash":1.31563,"lots":[[[5.0,0.263126]],[]],"floor":-1.31563},"pair_add_250":{"qty":[5.0,0.0],"cash":1.31563,"lots":[[[5.0,0.263126]],[]],"floor":-1.31563}}}
{"kind":"decision","recorded_ms":1790004130061,"S":1790004000,"age":130,"signal":{"rsi14":40.35885312481135,"volume_ratio":0.9202955622271856,"taker_buy_fraction":0.3654065324985786,"volume5":130.34247,"return1":-7.8498566944760135,"return5":-15.409021021359203,"return15":2.4243743457248303,"bollinger_z":-1.211217332509348,"bar_close_ms":1790004119999,"ref":86169.19843132998,"reference_received_ms":1790004001552,"spot":85972.84994197181,"twap":86020.51375371522,"sigma":11.24168624140848,"spot_z":-1.339821737955133,"twap_z":-1.0145785374784277,"momentum":-0.867932787160162,"decision_ms":1790004130059,"momentum30":-0.3991255575285195,"momentum60":-1.1934630286545085,"spot_twap_gap":-0.5473708751954518,"range60":1.1934630286545085,"final_mean":85972.84994197181,"final_z":-1.5322266160813145,"final_up_prob":0.06273326134015383,"final_drift_up_prob":4.7513055201342524e-07,"final_known_seconds":0,"final_sd":128.14585473023953,"final_drift_shift":-431.7800054237409},"entry_side":null,"context_gap":null,"book_errors":[null,null],"books":[{"bid":0.05,"ask":0.06,"asks":[[0.06,188.1]],"received_ms":1790004130043,"observed_ms":1790004130029,"hash":"771228150c6c510689d9af975b1c8da6ec995a9b"},{"bid":0.94,"ask":0.95,"asks":[[0.95,1771.66]],"received_ms":1790004130059,"observed_ms":1790004130044,"hash":"6dd7cf4547eb171b53320847828ae5f9f2ccc870"}],"intents":{"pair_fast":null,"pair_250":null,"pair_add_fast":null,"pair_add_250":null},"decision_ms":1790004130061,"feature_cutoff_ms":1790004130059,"request_ms":1790004130017,"inventory":{"pair_fast":{"qty":[5.0,0.0],"cash":1.31563,"lots":[[[5.0,0.263126]],[]],"floor":-1.31563},"pair_250":{"qty":[5.0,0.0],"cash":1.31563,"lots":[[[5.0,0.263126]],[]],"floor":-1.31563},"pair_add_fast":{"qty":[5.0,0.0],"cash":1.31563,"lots":[[[5.0,0.263126]],[]],"floor":-1.31563},"pair_add_250":{"qty":[5.0,0.0],"cash":1.31563,"lots":[[[5.0,0.263126]],[]],"floor":-1.31563}}}
{"kind":"decision","recorded_ms":1790004140080,"S":1790004000,"age":140,"signal":{"rsi14":40.35885312481135,"volume_ratio":0.9202955622271856,"taker_buy_fraction":0.3654065324985786,"volume5":130.34247,"return1":-7.8498566944760135,"return5":-15.409021021359203,"return15":2.4243743457248303,"bollinger_z":-1.211217332509348,"bar_close_ms":1790004119999,"ref":86169.19843132998,"reference_received_ms":1790004001552,"spot":86039.89633072008,"twap":86005.47562837446,"sigma":11.64061586937953,"spot_z":-0.8783687449612638,"twap_z":-1.1121937870710947,"momentum":1.9193192792982245,"decision_ms":1790004140079,"momentum30":0.764032635220293,"momentum60":0.14845882530076945,"spot_twap_gap":0.38174041776141854,"range60":0.7835588146278337,"final_mean":86039.89633072008,"final_z":-1.0143363788019735,"final_up_prob":0.15521113545051396,"final_drift_up_prob":0.9999999996922977,"final_known_seconds":0,"final_sd":127.4745767894262,"final_drift_shift":917.9151514617158},"entry_side":null,"context_gap":null,"book_errors":[null,null],"books":[{"bid":0.18,"ask":0.19,"asks":[[0.19,41.0]],"received_ms":1790004140079,"observed_ms":1790004140068,"hash":"2d0727a1e1bfb8c04b94145fa631f78930066058"},{"bid":0.81,"ask":0.82,"asks":[[0.82,1935.0]],"received_ms":1790004140064,"observed_ms":1790004140057,"hash":"516bd1c220d830d2dca485f088a5fdef254c1117"}],"intents":{"pair_fast":null,"pair_250":null,"pair_add_fast":null,"pair_add_250":null},"decision_ms":1790004140080,"feature_cutoff_ms":1790004140079,"request_ms":1790004140036,"inventory":{"pair_fast":{"qty":[5.0,0.0],"cash":1.31563,"lots":[[[5.0,0.263126]],[]],"floor":-1.31563},"pair_250":{"qty":[5.0,0.0],"cash":1.31563,"lots":[[[5.0,0.263126]],[]],"floor":-1.31563},"pair_add_fast":{"qty":[5.0,0.0],"cash":1.31563,"lots":[[[5.0,0.263126]],[]],"floor":-1.31563},"pair_add_250":{"qty":[5.0,0.0],"cash":1.31563,"lots":[[[5.0,0.263126]],[]],"floor":-1.31563}}}
{"kind":"decision","recorded_ms":1790004150056,"S":1790004000,"age":150,"signal":{"rsi14":40.35885312481135,"volume_ratio":0.9202955622271856,"taker_buy_fraction":0.3654065324985786,"volume5":130.34247,"return1":-7.8498566944760135,"return5":-15.409021021359203,"return15":2.4243743457248303,"bollinger_z":-1.211217332509348,"bar_close_ms":1790004119999,"ref":86169.19843132998,"reference_received_ms":1790004001552,"spot":86071.07084877338,"twap":86011.32121653286,"sigma":11.7048888971103,"spot_z":-0.6846329703335923,"twap_z":-1.101504222344448,"momentum":0.1887710441686535,"decision_ms":1790004150055,"momentum30":1.050789923389976,"momentum60":0.5438869361156978,"spot_twap_gap":0.6590104717316987,"range60":1.1844164699951307,"final_mean":86071.07084877338,"final_z":-0.7995323903678642,"final_up_prob":0.21199088647947728,"final_drift_up_prob":0.453558658315625,"final_known_seconds":0,"final_sd":122.73121606924364,"final_drift_shift":83.8078737182149},"entry_side":null,"context_gap":null,"book_errors":[null,null],"books":[{"bid":0.13,"ask":0.14,"asks":[[0.14,978.38]],"received_ms":1790004150025,"observed_ms":1790004150018,"hash":"507db91aab8e1b04b2825006bd4f9878fee979e3"},{"bid":0.86,"ask":0.87,"asks":[[0.87,219.66]],"received_ms":1790004150055,"observed_ms":1790004150036,"hash":"acccc48e944f999d2302e8e22db184760f0adaad"}],"intents":{"pair_fast":null,"pair_250":null,"pair_add_fast":null,"pair_add_250":null},"decision_ms":1790004150056,"feature_cutoff_ms":1790004150055,"request_ms":1790004150003,"inventory":{"pair_fast":{"qty":[5.0,0.0],"cash":1.31563,"lots":[[[5.0,0.263126]],[]],"floor":-1.31563},"pair_250":{"qty":[5.0,0.0],"cash":1.31563,"lots":[[[5.0,0.263126]],[]],"floor":-1.31563},"pair_add_fast":{"qty":[5.0,0.0],"cash":1.31563,"lots":[[[5.0,0.263126]],[]],"floor":-1.31563},"pair_add_250":{"qty":[5.0,0.0],"cash":1.31563,"lots":[[[5.0,0.263126]],[]],"floor":-1.31563}}}
{"kind":"decision","recorded_ms":1790004160070,"S":1790004000,"age":160,"signal":{"rsi14":40.35885312481135,"volume_ratio":0.9202955622271856,"taker_buy_fraction":0.3654065324985786,"volume5":130.34247,"return1":-7.8498566944760135,"return5":-15.409021021359203,"return15":2.4243743457248303,"bollinger_z":-1.211217332509348,"bar_close_ms":1790004119999,"ref":86169.19843132998,"reference_received_ms":1790004001552,"spot":86005.5880246452,"twap":86018.9405636274,"sigma":12.864927562206265,"spot_z":-1.0750905845168481,"twap_z":-0.9873505120481215,"momentum":-1.2687033857129928,"decision_ms":1790004160068,"momentum30":0.5157730104290856,"momentum60":0.0819118702085549,"spot_twap_gap":-0.13399262156121833,"range60":1.0776168868550604,"final_mean":86005.5880246452,"final_z":-1.2721879845948392,"final_up_prob":0.10165316784931672,"final_drift_up_prob":6.573175004298548e-09,"final_known_seconds":0,"final_sd":128.6055273795739,"final_drift_shift":-567.4029284465527},"entry_side":null,"context_gap":null,"book_errors":[null,null],"books":[{"bid":0.07,"ask":0.08,"asks":[[0.08,250.45]],"received_ms":1790004160068,"observed_ms":1790004160058,"hash":"2c8639b0bfec4d715346b73200511237e9426aab"},{"bid":0.92,"ask":0.93,"asks":[[0.93,480.95]],"received_ms":1790004160057,"observed_ms":1790004160049,"hash":"eb5cdff05cfda0e4a63a523c0ab66f7a3707cfb3"}],"intents":{"pair_fast":null,"pair_250":null,"pair_add_fast":null,"pair_add_250":null},"decision_ms":1790004160070,"feature_cutoff_ms":1790004160068,"request_ms":1790004160030,"inventory":{"pair_fast":{"qty":[5.0,0.0],"cash":1.31563,"lots":[[[5.0,0.263126]],[]],"floor":-1.31563},"pair_250":{"qty":[5.0,0.0],"cash":1.31563,"lots":[[[5.0,0.263126]],[]],"floor":-1.31563},"pair_add_fast":{"qty":[5.0,0.0],"cash":1.31563,"lots":[[[5.0,0.263126]],[]],"floor":-1.31563},"pair_add_250":{"qty":[5.0,0.0],"cash":1.31563,"lots":[[[5.0,0.263126]],[]],"floor":-1.31563}}}
{"kind":"decision","recorded_ms":1790004170087,"S":1790004000,"age":170,"signal":{"rsi14":40.35885312481135,"volume_ratio":0.9202955622271856,"taker_buy_fraction":0.3654065324985786,"volume5":130.34247,"return1":-7.8498566944760135,"return5":-15.409021021359203,"return15":2.4243743457248303,"bollinger_z":-1.211217332509348,"bar_close_ms":1790004119999,"ref":86169.19843132998,"reference_received_ms":1790004001552,"spot":85983.74951875213,"twap":86020.50082872692,"sigma":13.321157541773264,"spot_z":-1.2213899697485535,"twap_z":-0.9793411987185088,"momentum":-0.3654480650766173,"decision_ms":1790004170086,"momentum30":-1.1010259287404358,"momentum60":-0.07203943021681207,"spot_twap_gap":-0.35616827601083184,"range60":1.0407100993833847,"final_mean":85983.74951875213,"final_z":-1.4681440428201198,"final_up_prob":0.07103255012936172,"final_drift_up_prob":0.00361740172145375,"final_known_seconds":0,"final_sd":126.31520284727996,"final_drift_shift":-153.81333102674884},"entry_side":null,"context_gap":null,"book_errors":[null,null],"books":[{"bid":0.04,"ask":0.05,"asks":[[0.05,921.59]],"received_ms":1790004170086,"observed_ms":1790004170076,"hash":"52fca121d246bfae9eebb663e08b4a6cda20c63c"},{"bid":0.95,"ask":0.96,"asks":[[0.96,277.0]],"received_ms":1790004170078,"observed_ms":1790004170066,"hash":"35aae2ed57d7feecf83aca27353bfcde0d1b76fe"}],"intents":{"pair_fast":null,"pair_250":null,"pair_add_fast":null,"pair_add_250":null},"decision_ms":1790004170087,"feature_cutoff_ms":1790004170086,"request_ms":1790004170044,"inventory":{"pair_fast":{"qty":[5.0,0.0],"cash":1.31563,"lots":[[[5.0,0.263126]],[]],"floor":-1.31563},"pair_250":{"qty":[5.0,0.0],"cash":1.31563,"lots":[[[5.0,0.263126]],[]],"floor":-1.31563},"pair_add_fast":{"qty":[5.0,0.0],"cash":1.31563,"lots":[[[5.0,0.263126]],[]],"floor":-1.31563},"pair_add_250":{"qty":[5.0,0.0],"cash":1.31563,"lots":[[[5.0,0.263126]],[]],"floor":-1.31563}}}
{"kind":"decision","recorded_ms":1790004180048,"S":1790004000,"age":180,"signal":{"rsi14":40.35885312481135,"volume_ratio":0.9202955622271856,"taker_buy_fraction":0.3654065324985786,"volume5":130.34247,"return1":-7.8498566944760135,"return5":-15.409021021359203,"return15":2.4243743457248303,"bollinger_z":-1.211217332509348,"bar_close_ms":1790004119999,"ref":86169.19843132998,"reference_received_ms":1790004001552,"spot":85971.24065130761,"twap":86015.65126947484,"sigma":12.19500178262509,"spot_z":-1.4821260806520373,"twap_z":-1.1496201521854346,"momentum":-0.12505246704729428,"decision_ms":1790004180047,"momentum30":-1.2869474262157812,"momentum60":-0.3436693685207188,"spot_twap_gap":-0.4701422971540672,"range60":1.191065025595631,"final_mean":85971.24065130761,"final_z":-1.815404152457351,"final_up_prob":0.03473091171119219,"final_drift_up_prob":0.013440974124156402,"final_known_seconds":0,"final_sd":109.04336632391497,"final_drift_shift":-43.380023644212635},"entry_side":null,"context_gap":null,"book_errors":[null,null],"books":[{"bid":0.04,"ask":0.05,"asks":[[0.05,221.0]],"received_ms":1790004180047,"observed_ms":1790004180037,"hash":"f88d5387e950721cd32c9107aa238e779015f6a0"},{"bid":0.95,"ask":0.96,"asks":[[0.96,1335.05]],"received_ms":1790004180047,"observed_ms":1790004180034,"hash":"b4eaaab37a960c4175e125bd5fdcdbfd1f85c172"}],"intents":{"pair_fast":null,"pair_250":null,"pair_add_fast":null,"pair_add_250":null},"decision_ms":1790004180048,"feature_cutoff_ms":1790004180047,"request_ms":1790004180010,"inventory":{"pair_fast":{"qty":[5.0,0.0],"cash":1.31563,"lots":[[[5.0,0.263126]],[]],"floor":-1.31563},"pair_250":{"qty":[5.0,0.0],"cash":1.31563,"lots":[[[5.0,0.263126]],[]],"floor":-1.31563},"pair_add_fast":{"qty":[5.0,0.0],"cash":1.31563,"lots":[[[5.0,0.263126]],[]],"floor":-1.31563},"pair_add_250":{"qty":[5.0,0.0],"cash":1.31563,"lots":[[[5.0,0.263126]],[]],"floor":-1.31563}}}
