{"kind":"decision","recorded_ms":1790004190048,"S":1790004000,"age":190,"signal":{"rsi14":35.35105321329325,"volume_ratio":0.7258615673219367,"taker_buy_fraction":0.33119578398584487,"volume5":133.63902,"return1":-1.4106383295442622,"return5":-24.11575188767311,"return15":-23.60638701682331,"bollinger_z":-1.3177017637889654,"bar_close_ms":1790004179999,"ref":86169.19843132998,"reference_received_ms":1790004001552,"spot":85996.22879542105,"twap":86011.6288482017,"sigma":11.772611411728755,"spot_z":-1.4011786791742946,"twap_z":-1.2764271555845366,"momentum":0.44728975077081856,"decision_ms":1790004190047,"momentum30":-0.045211527958749075,"momentum60":0.2959116277783812,"spot_twap_gap":-0.16887827139396872,"range60":1.2337993332465034,"final_mean":85996.22879542105,"final_z":-1.756684986929164,"final_up_prob":0.03948575895087847,"final_drift_up_prob":0.34290471785651977,"final_known_seconds":0,"final_sd":98.46366149647253,"final_drift_shift":133.13631136524594},"entry_side":0,"context_gap":null,"book_errors":[null,null],"books":[{"bid":0.04,"ask":0.05,"asks":[[0.05,473.56]],"received_ms":1790004190047,"observed_ms":1790004190035,"hash":"57bee97b918974f49392770e9f584cf48f297a59"},{"bid":0.95,"ask":0.96,"asks":[[0.96,143.25]],"received_ms":1790004190026,"observed_ms":1790004190019,"hash":"0cdc806f7dd645de0d33613aadf6b33511822577"}],"intents":{"pair_fast":null,"pair_250":null,"pair_add_fast":{"kind":"add","side":0,"qty":5.0,"max_cost":0.31662999999999997},"pair_add_250":{"kind":"add","side":0,"qty":5.0,"max_cost":0.31662999999999997}},"decision_ms":1790004190048,"feature_cutoff_ms":1790004190047,"request_ms":1790004190001,"inventory":{"pair_fast":{"qty":[5.0,0.0],"cash":1.31563,"lots":[[[5.0,0.263126]],[]],"floor":-1.31563},"pair_250":{"qty":[5.0,0.0],"cash":1.31563,"lots":[[[5.0,0.263126]],[]],"floor":-1.31563},"pair_add_fast":{"qty":[5.0,0.0],"cash":1.31563,"lots":[[[5.0,0.263126]],[]],"floor":-1.31563},"pair_add_250":{"qty":[5.0,0.0],"cash":1.31563,"lots":[[[5.0,0.263126]],[]],"floor":-1.31563}}}
{"kind":"decision","recorded_ms":1790004200044,"S":1790004000,"age":200,"signal":{"rsi14":35.35105321329325,"volume_ratio":0.7258615673219367,"taker_buy_fraction":0.33119578398584487,"volume5":133.63902,"return1":-1.4106383295442622,"return5":-24.11575188767311,"return15":-23.60638701682331,"bollinger_z":-1.3177017637889654,"bar_close_ms":1790004179999,"ref":86169.19843132998,"reference_received_ms":1790004001552,"spot":85978.43464138861,"twap":86011.74275473943,"sigma":8.738601504473872,"spot_z":-2.183470859427119,"twap_z":-1.8022281985092754,"momentum":-0.8765611534753033,"decision_ms":1790004200043,"momentum30":0.04954671833264953,"momentum60":-1.2653329416373342,"spot_twap_gap":-0.49207632836629384,"range60":1.6621698681333372,"final_mean":85978.43464138861,"final_z":-2.8192530540968663,"final_up_prob":0.0024067776653975415,"final_drift_up_prob":5.086842741475195e-08,"final_known_seconds":0,"final_sd":67.6646566593781,"final_drift_shift":-169.45536864056353},"entry_side":null,"context_gap":null,"book_errors":[null,null],"books":[{"bid":0.03,"ask":0.04,"asks":[[0.04,515.83]],"received_ms":1790004200036,"observed_ms":1790004200018,"hash":"c38e8a64c2aa3831e5005fbb2ed8c978756ecfa1"},{"bid":0.96,"ask":0.97,"asks":[[0.97,671.04]],"received_ms":1790004200043,"observed_ms":1790004200027,"hash":"52d0b32f4f9c4fc72045dcf5417de7799bbb654a"}],"intents":{"pair_fast":null,"pair_250":null,"pair_add_fast":null,"pair_add_250":null},"decision_ms":1790004200044,"feature_cutoff_ms":1790004200043,"request_ms":1790004200005,"inventory":{"pair_fast":{"qty":[5.0,0.0],"cash":1.31563,"lots":[[[5.0,0.263126]],[]],"floor":-1.31563},"pair_250":{"qty":[5.0,0.0],"cash":1.31563,"lots":[[[5.0,0.263126]],[]],"floor":-1.31563},"pair_add_fast":{"qty":[10.0,0.0],"cash":1.58226,"lots":[[[5.0,0.263126],[5.0,0.053326]],[]],"floor":-1.58226},"pair_add_250":{"qty":[10.0,0.0],"cash":1.5290700000000002,"lots":[[[5.0,0.263126],[5.0,0.042688000000000004]],[]],"floor":-1.5290700000000002}}}
{"kind":"decision","recorded_ms":1790004210057,"S":1790004000,"age":210,"signal":{},"entry_side":null,"context_gap":"incomplete or stale context","book_errors":[null,null],"books":[{"bid":0.03,"ask":0.04,"asks":[[0.04,829.02]],"received_ms":1790004210048,"observed_ms":1790004210040,"hash":"4ee1a1107fb909ca9a66d2c9e5be2a7bb0924e60"},{"bid":0.96,"ask":0.97,"asks":[[0.97,349.87]],"received_ms":1790004210056,"observed_ms":1790004210047,"hash":"4639612763997fc8bf6cc19fd5559344774aa6b6"}],"intents":{"pair_fast":null,"pair_250":null,"pair_add_fast":null,"pair_add_250":null},"decision_ms":1790004210057,"feature_cutoff_ms":1790004210056,"request_ms":1790004210017,"inventory":{"pair_fast":{"qty":[5.0,0.0],"cash":1.31563,"lots":[[[5.0,0.263126]],[]],"floor":-1.31563},"pair_250":{"qty":[5.0,0.0],"cash":1.31563,"lots":[[[5.0,0.263126]],[]],"floor":-1.31563},"pair_add_fast":{"qty":[10.0,0.0],"cash":1.58226,"lots":[[[5.0,0.263126],[5.0,0.053326]],[]],"floor":-1.58226},"pair_add_250":{"qty":[10.0,0.0],"cash":1.5290700000000002,"lots":[[[5.0,0.263126],[5.0,0.042688000000000004]],[]],"floor":-1.5290700000000002}}}
{"kind":"decision","recorded_ms":1790004220073,"S":1790004000,"age":220,"signal":{"rsi14":35.35105321329325,"volume_ratio":0.7258615673219367,"taker_buy_fraction":0.33119578398584487,"volume5":133.63902,"return1":-1.4106383295442622,"return5":-24.11575188767311,"return15":-23.60638701682331,"bollinger_z":-1.3177017637889654,"bar_close_ms":1790004179999,"ref":86169.19843132998,"reference_received_ms":1790004001552,"spot":85989.168972642,"twap":85991.88070285175,"sigma":6.645539885376559,"spot_z":-3.0301479496761248,"twap_z":-2.984505732035619,"momentum":-0.851836610022125,"decision_ms":1790004220072,"momentum30":-0.3705709885832498,"momentum60":-0.19378143660995717,"spot_twap_gap":-0.05267937154294671,"range60":0.9471916280926124,"final_mean":85989.168972642,"final_z":-4.287207743572116,"final_up_prob":9.046653460298426e-06,"final_drift_up_prob":7.011202729501065e-11,"final_known_seconds":0,"final_sd":41.99224051083054,"final_drift_shift":-89.37802204250814},"entry_side":null,"context_gap":null,"book_errors":[null,null],"books":[{"bid":null,"ask":0.01,"asks":[[0.01,4591.29]],"received_ms":1790004220072,"observed_ms":1790004220051,"hash":"e31106e4c6472a35c7a674a3c9a08a1e0a6a12c6"},{"bid":0.99,"ask":null,"asks":[],"received_ms":1790004220062,"observed_ms":1790004220051,"hash":"aea2b7eefddc7457be681d7d7c4eadf2bc156377"}],"intents":{"pair_fast":null,"pair_250":null,"pair_add_fast":null,"pair_add_250":null},"decision_ms":1790004220073,"feature_cutoff_ms":1790004220072,"request_ms":1790004220032,"inventory":{"pair_fast":{"qty":[5.0,0.0],"cash":1.31563,"lots":[[[5.0,0.263126]],[]],"floor":-1.31563},"pair_250":{"qty":[5.0,0.0],"cash":1.31563,"lots":[[[5.0,0.263126]],[]],"floor":-1.31563},"pair_add_fast":{"qty":[10.0,0.0],"cash":1.58226,"lots":[[[5.0,0.263126],[5.0,0.053326]],[]],"floor":-1.58226},"pair_add_250":{"qty":[10.0,0.0],"cash":1.5290700000000002,"lots":[[[5.0,0.263126],[5.0,0.042688000000000004]],[]],"floor":-1.5290700000000002}}}
{"kind":"decision","recorded_ms":1790004230096,"S":1790004000,"age":230,"signal":{"rsi14":35.35105321329325,"volume_ratio":0.7258615673219367,"taker_buy_fraction":0.33119578398584487,"volume5":133.63902,"return1":-1.4106383295442622,"return5":-24.11575188767311,"return15":-23.60638701682331,"bollinger_z":-1.3177017637889654,"bar_close_ms":1790004179999,"ref":86169.19843132998,"reference_received_ms":1790004001552,"spot":85994.82746964357,"twap":85989.00806670533,"sigma":6.115977680048219,"spot_z":-3.4099982100409654,"twap_z":-3.5238024433318498,"momentum":0.31562863673473224,"decision_ms":1790004230095,"momentum30":-0.07184588387470409,"momentum60":0.3960871817466596,"spot_twap_gap":0.12283918093319987,"range60":1.0292058069666776,"final_mean":85994.82746964357,"final_z":-5.2135839113240845,"final_up_prob":9.261334271704058e-08,"final_drift_up_prob":3.6414612957225145e-06,"final_known_seconds":0,"final_sd":33.445507860277715,"final_drift_shift":24.35956934836598},"entry_side":0,"context_gap":null,"book_errors":[null,null],"books":[{"bid":null,"ask":0.01,"asks":[[0.01,6956.18]],"received_ms":1790004230071,"observed_ms":1790004230044,"hash":"8c17ac4e09fa5772088b05a2c97575dcb67df81e"},{"bid":0.99,"ask":null,"asks":[],"received_ms":1790004230095,"observed_ms":1790004230071,"hash":"2dd4b0898053d10aa8eff86361a879d360f55a29"}],"intents":{"pair_fast":null,"pair_250":null,"pair_add_fast":null,"pair_add_250":null},"decision_ms":1790004230096,"feature_cutoff_ms":1790004230095,"request_ms":1790004230046,"inventory":{"pair_fast":{"qty":[5.0,0.0],"cash":1.31563,"lots":[[[5.0,0.263126]],[]],"floor":-1.31563},"pair_250":{"qty":[5.0,0.0],"cash":1.31563,"lots":[[[5.0,0.263126]],[]],"floor":-1.31563},"pair_add_fast":{"qty":[10.0,0.0],"cash":1.58226,"lots":[[[5.0,0.263126],[5.0,0.053326]],[]],"floor":-1.58226},"pair_add_250":{"qty":[10.0,0.0],"cash":1.5290700000000002,"lots":[[[5.0,0.263126],[5.0,0.042688000000000004]],[]],"floor":-1.5290700000000002}}}
{"kind":"decision","recorded_ms":1790004240063,"S":1790004000,"age":240,"signal":{"rsi14":35.35105321329325,"volume_ratio":0.7258615673219367,"taker_buy_fraction":0.33119578398584487,"volume5":133.63902,"return1":-1.4106383295442622,"return5":-24.11575188767311,"return15":-23.60638701682331,"bollinger_z":-1.3177017637889654,"bar_close_ms":1790004179999,"ref":86169.19843132998,"reference_received_ms":1790004001552,"spot":85988.5472621577,"twap":85993.28694560124,"sigma":6.143016199387523,"spot_z":-3.798432121876838,"twap_z":-3.6987739468318557,"momentum":-0.46412252383348074,"decision_ms":1790004240061,"momentum30":-0.5505176112718576,"momentum60":0.18851639642892873,"spot_twap_gap":-0.09960750249980814,"range60":0.7521692906004508,"final_mean":85988.5472621577,"final_z":-6.585772971980485,"final_up_prob":2.2626234219558228e-11,"final_drift_up_prob":1.8707257964933888e-14,"final_known_seconds":0,"final_sd":27.430518777501092,"final_drift_shift":-26.993055291419637},"entry_side":null,"context_gap":null,"book_errors":[null,null],"books":[{"bid":null,"ask":0.01,"asks":[[0.01,17890.86]],"received_ms":1790004240061,"observed_ms":1790004240046,"hash":"1f4f54352dbd65833dae223b91686354ce21cf88"},{"bid":0.99,"ask":null,"asks":[],"received_ms":1790004240061,"observed_ms":1790004240046,"hash":"c6da79cfda8fdae31a8761d20a49b1e9c42c8384"}],"intents":{"pair_fast":null,"pair_250":null,"pair_add_fast":null,"pair_add_250":null},"decision_ms":1790004240063,"feature_cutoff_ms":1790004240061,"request_ms":1790004240022,"inventory":{"pair_fast":{"qty":[5.0,0.0],"cash":1.31563,"lots":[[[5.0,0.263126]],[]],"floor":-1.31563},"pair_250":{"qty":[5.0,0.0],"cash":1.31563,"lots":[[[5.0,0.263126]],[]],"floor":-1.31563},"pair_add_fast":{"qty":[10.0,0.0],"cash":1.58226,"lots":[[[5.0,0.263126],[5.0,0.053326]],[]],"floor":-1.58226},"pair_add_250":{"qty":[10.0,0.0],"cash":1.5290700000000002,"lots":[[[5.0,0.263126],[5.0,0.042688000000000004]],[]],"floor":-1.5290700000000002}}}
{"kind":"decision","recorded_ms":1790004250041,"S":1790004000,"age":250,"signal":{"rsi14":31.43871137871946,"volume_ratio":0.7994434623999289,"taker_buy_fraction":0.27958533692270005,"volume5":139.66809,"return1":-2.503259355350702,"return5":-25.938745522749098,"return15":-34.26278081405284,"bollinger_z":-1.5224704219900638,"bar_close_ms":1790004239999,"ref":86169.19843132998,"reference_received_ms":1790004001552,"spot":85892.23345075063,"twap":85988.24879276883,"sigma":10.314826063841988,"spot_z":-3.7988464214843365,"twap_z":-2.4819018111206703,"momentum":-2.348802973832155,"decision_ms":1790004250040,"momentum30":-1.7078829326473643,"momentum60":-1.3820567065350917,"spot_twap_gap":-1.2017194741992594,"range60":1.5099732546496127,"final_mean":85898.00335091114,"final_z":-7.737454901608596,"final_up_prob":5.051514762044462e-15,"final_drift_up_prob":0.0,"final_known_seconds":10,"final_sd":35.049649253846695,"final_drift_shift":-159.35735439148573},"entry_side":null,"context_gap":null,"book_errors":[null,null],"books":[{"bid":null,"ask":0.01,"asks":[[0.01,24778.88]],"received_ms":1790004250036,"observed_ms":1790004250013,"hash":"098514f8efbac1472a2d439bea16b4c78a2a0375"},{"bid":0.99,"ask":null,"asks":[],"received_ms":1790004250040,"observed_ms":1790004250030,"hash":"faee9f6a2b7fef8bca5633f4a3efa08ad99a3e99"}],"intents":{"pair_fast":null,"pair_250":null,"pair_add_fast":null,"pair_add_250":null},"decision_ms":1790004250041,"feature_cutoff_ms":1790004250040,"request_ms":1790004250008,"inventory":{"pair_fast":{"qty":[5.0,0.0],"cash":1.31563,"lots":[[[5.0,0.263126]],[]],"floor":-1.31563},"pair_250":{"qty":[5.0,0.0],"cash":1.31563,"lots":[[[5.0,0.263126]],[]],"floor":-1.31563},"pair_add_fast":{"qty":[10.0,0.0],"cash":1.58226,"lots":[[[5.0,0.263126],[5.0,0.053326]],[]],"floor":-1.58226},"pair_add_250":{"qty":[10.0,0.0],"cash":1.5290700000000002,"lots":[[[5.0,0.263126],[5.0,0.042688000000000004]],[]],"floor":-1.5290700000000002}}}
{"kind":"decision","recorded_ms":1790004260045,"S":1790004000,"age":260,"signal":{"rsi14":31.43871137871946,"volume_ratio":0.7994434623999289,"taker_buy_fraction":0.27958533692270005,"volume5":139.66809,"return1":-2.503259355350702,"return5":-25.938745522749098,"return15":-34.26278081405284,"bollinger_z":-1.5224704219900638,"bar_close_ms":1790004239999,"ref":86169.19843132998,"reference_received_ms":1790004001552,"spot":85876.05912092255,"twap":85972.82830935561,"sigma":11.53900533525138,"spot_z":-4.018969265454114,"twap_z":-2.6922540131911004,"momentum":0.27795759283776905,"decision_ms":1790004260044,"momentum30":-1.9224812315790147,"momentum60":-1.3557179050272814,"spot_twap_gap":-1.0826625124618938,"range60":1.6442149718160297,"final_mean":85884.57911448923,"final_z":-10.149271429928842,"final_up_prob":0.0,"final_drift_up_prob":0.0,"final_known_seconds":20,"final_sd":28.04332496236566,"final_drift_shift":13.493657448976697},"entry_side":0,"context_gap":null,"book_errors":[null,null],"books":[{"bid":null,"ask":0.01,"asks":[[0.01,31180.43]],"received_ms":1790004260044,"observed_ms":1790004260023,"hash":"fed352ca9a897e47f1a44eec11529b434d23aff2"},{"bid":0.99,"ask":null,"asks":[],"received_ms":1790004260043,"observed_ms":1790004260023,"hash":"91272ee812696f0c7e9a45dd6d34d47941a03ed8"}],"intents":{"pair_fast":null,"pair_250":null,"pair_add_fast":null,"pair_add_250":null},"decision_ms":1790004260045,"feature_cutoff_ms":1790004260044,"request_ms":1790004260014,"inventory":{"pair_fast":{"qty":[5.0,0.0],"cash":1.31563,"lots":[[[5.0,0.263126]],[]],"floor":-1.31563},"pair_250":{"qty":[5.0,0.0],"cash":1.31563,"lots":[[[5.0,0.263126]],[]],"floor":-1.31563},"pair_add_fast":{"qty":[10.0,0.0],"cash":1.58226,"lots":[[[5.0,0.263126],[5.0,0.053326]],[]],"floor":-1.58226},"pair_add_250":{"qty":[10.0,0.0],"cash":1.5290700000000002,"lots":[[[5.0,0.263126],[5.0,0.042688000000000004]],[]],"floor":-1.5290700000000002}}}
{"kind":"decision","recorded_ms":1790004270081,"S":1790004000,"age":270,"signal":{},"entry_side":null,"context_gap":"incomplete or stale context","book_errors":[null,null],"books":[{"bid":null,"ask":0.01,"asks":[[0.01,31258.58]],"received_ms":1790004270080,"observed_ms":1790004270064,"hash":"4273222eeffc9f5b029b61910f3197ed13e7a486"},{"bid":0.99,"ask":null,"asks":[],"received_ms":1790004270051,"observed_ms":1790004270036,"hash":"8408e03aeb2e5516f6850d79c421a1239805e798"}],"intents":{"pair_fast":null,"pair_250":null,"pair_add_fast":null,"pair_add_250":null},"decision_ms":1790004270081,"feature_cutoff_ms":1790004270080,"request_ms":1790004270019,"inventory":{"pair_fast":{"qty":[5.0,0.0],"cash":1.31563,"lots":[[[5.0,0.263126]],[]],"floor":-1.31563},"pair_250":{"qty":[5.0,0.0],"cash":1.31563,"lots":[[[5.0,0.263126]],[]],"floor":-1.31563},"pair_add_fast":{"qty":[10.0,0.0],"cash":1.58226,"lots":[[[5.0,0.263126],[5.0,0.053326]],[]],"floor":-1.58226},"pair_add_250":{"qty":[10.0,0.0],"cash":1.5290700000000002,"lots":[[[5.0,0.263126],[5.0,0.042688000000000004]],[]],"floor":-1.5290700000000002}}}
{"kind":"decision","recorded_ms":1790004280043,"S":1790004000,"age":280,"signal":{"rsi14":31.43871137871946,"volume_ratio":0.7994434623999289,"taker_buy_fraction":0.27958533692270005,"volume5":139.66809,"return1":-2.503259355350702,"return5":-25.938745522749098,"return15":-34.26278081405284,"bollinger_z":-1.5224704219900638,"bar_close_ms":1790004239999,"ref":86169.19843132998,"reference_received_ms":1790004001552,"spot":85912.4665905682,"twap":85937.20047363012,"sigma":12.151874707220307,"spot_z":-4.728975471073497,"twap_z":-4.273379757050952,"momentum":0.19290741750967333,"decision_ms":1790004280041,"momentum30":0.6993843430446053,"momentum60":-0.8101359345932984,"spot_twap_gap":-0.262768556275816,"range60":1.483375593255714,"final_mean":85904.79078463068,"final_z":-25.359134941193677,"final_up_prob":0.0,"final_drift_up_prob":0.0,"final_known_seconds":40,"final_sd":10.426524694649277,"final_drift_shift":2.4608691689266036},"entry_side":0,"context_gap":null,"book_errors":[null,null],"books":[{"bid":null,"ask":0.01,"asks":[[0.01,43889.17]],"received_ms":1790004280025,"observed_ms":1790004279835,"hash":"86a75b7a854c2566f5ae75e89045e64f4a159085"},{"bid":0.99,"ask":null,"asks":[],"received_ms":1790004280040,"observed_ms":1790004279835,"hash":"2bad40078d9d1f72936b288c63d166e79c29c6a3"}],"intents":{"pair_fast":null,"pair_250":null,"pair_add_fast":null,"pair_add_250":null},"decision_ms":1790004280042,"feature_cutoff_ms":1790004280041,"request_ms":1790004280006,"inventory":{"pair_fast":{"qty":[5.0,0.0],"cash":1.31563,"lots":[[[5.0,0.263126]],[]],"floor":-1.31563},"pair_250":{"qty":[5.0,0.0],"cash":1.31563,"lots":[[[5.0,0.263126]],[]],"floor":-1.31563},"pair_add_fast":{"qty":[10.0,0.0],"cash":1.58226,"lots":[[[5.0,0.263126],[5.0,0.053326]],[]],"floor":-1.58226},"pair_add_250":{"qty":[10.0,0.0],"cash":1.5290700000000002,"lots":[[[5.0,0.263126],[5.0,0.042688000000000004]],[]],"floor":-1.5290700000000002}}}
{"kind":"decision","recorded_ms":1790004290044,"S":1790004000,"age":290,"signal":{"rsi14":31.43871137871946,"volume_ratio":0.7994434623999289,"taker_buy_fraction":0.27958533692270005,"volume5":139.66809,"return1":-2.503259355350702,"return5":-25.938745522749098,"return15":-34.26278081405284,"bollinger_z":-1.5224704219900638,"bar_close_ms":1790004239999,"ref":86169.19843132998,"reference_received_ms":1790004001552,"spot":85908.3010075414,"twap":85925.3350827351,"sigma":12.266905867764732,"spot_z":-6.740164625657315,"twap_z":-6.300097148623376,"momentum":-0.3421108331227471,"decision_ms":1790004290043,"momentum30":0.48578375460361417,"momentum60":-0.9394144475193319,"spot_twap_gap":-0.1792701171058079,"range60":1.4694654501556617,"final_mean":85905.20602885612,"final_z":-71.18287285409275,"final_up_prob":0.0,"final_drift_up_prob":0.0,"final_known_seconds":50,"final_sd":3.7086505768736884,"final_drift_shift":-1.0964217165867198},"entry_side":null,"context_gap":null,"book_errors":[null,null],"books":[{"bid":null,"ask":0.01,"asks":[[0.01,44701.31]],"received_ms":1790004290040,"observed_ms":1790004290005,"hash":"846f88a4eaa19875cf09b695eba5619ef026060c"},{"bid":0.99,"ask":null,"asks":[],"received_ms":1790004290042,"observed_ms":1790004290005,"hash":"4e83c05f5485cb07419b278c17f7fe7d3135f513"}],"intents":{"pair_fast":null,"pair_250":null,"pair_add_fast":null,"pair_add_250":null},"decision_ms":1790004290044,"feature_cutoff_ms":1790004290043,"request_ms":1790004290016,"inventory":{"pair_fast":{"qty":[5.0,0.0],"cash":1.31563,"lots":[[[5.0,0.263126]],[]],"floor":-1.31563},"pair_250":{"qty":[5.0,0.0],"cash":1.31563,"lots":[[[5.0,0.263126]],[]],"floor":-1.31563},"pair_add_fast":{"qty":[10.0,0.0],"cash":1.58226,"lots":[[[5.0,0.263126],[5.0,0.053326]],[]],"floor":-1.58226},"pair_add_250":{"qty":[10.0,0.0],"cash":1.5290700000000002,"lots":[[[5.0,0.263126],[5.0,0.042688000000000004]],[]],"floor":-1.5290700000000002}}}
{"kind":"decision","recorded_ms":1790004330076,"S":1790004300,"age":30,"signal":{"rsi14":34.061878742426465,"volume_ratio":1.3748673615943345,"taker_buy_fraction":0.28375662052240624,"volume5":169.38618,"return1":-10.763257362489927,"return5":-29.621956160016097,"return15":-50.106264313600256,"bollinger_z":-2.1161952547387433,"bar_close_ms":1790004299999,"ref":85906.77011753221,"reference_received_ms":1790004301362,"spot":85890.92527092986,"twap":85901.49565264197,"sigma":7.873721522630743,"spot_z":-0.12248599470519143,"twap_z":-0.040773388018990865,"momentum":-0.5428400358320855,"decision_ms":1790004330075,"momentum30":0.17316670498505823,"momentum60":-0.23165185122214144,"spot_twap_gap":-0.17331453839369912,"range60":0.8544096496846179,"final_mean":85890.92527092986,"final_z":-0.13271343524280346,"final_up_prob":0.4472100085358602,"final_drift_up_prob":0.0021937627772780077,"final_known_seconds":0,"final_sd":119.39142840637055,"final_drift_shift":-324.2854210754202},"entry_side":null,"context_gap":null,"book_errors":[null,null],"books":[{"bid":0.47,"ask":0.48,"asks":[[0.48,96.0]],"received_ms":1790004330075,"observed_ms":1790004330064,"hash":"bd5a75c01a287cfe8cc16e0862114f194f226508"},{"bid":0.52,"ask":0.53,"asks":[[0.53,899.85]],"received_ms":1790004330072,"observed_ms":1790004330060,"hash":"5aec4c9acf520ced4fb831283fdd2d4697a17338"}],"intents":{"pair_fast":{"kind":"first","side":0,"qty":5.0,"participation":true,"max_cost":2.5373599999999996},"pair_250":{"kind":"first","side":0,"qty":5.0,"participation":true,"max_cost":2.5373599999999996},"pair_add_fast":{"kind":"first","side":0,"qty":5.0,"participation":true,"max_cost":2.5373599999999996},"pair_add_250":{"kind":"first","side":0,"qty":5.0,"participation":true,"max_cost":2.5373599999999996}},"decision_ms":1790004330076,"feature_cutoff_ms":1790004330075,"request_ms":1790004330039,"inventory":{"pair_fast":{"qty":[0.0,0.0],"cash":0.0,"lots":[[],[]],"floor":0.0},"pair_250":{"qty":[0.0,0.0],"cash":0.0,"lots":[[],[]],"floor":0.0},"pair_add_fast":{"qty":[0.0,0.0],"cash":0.0,"lots":[[],[]],"floor":0.0},"pair_add_250":{"qty":[0.0,0.0],"cash":0.0,"lots":[[],[]],"floor":0.0}}}
{"kind":"decision","recorded_ms":1790004340073,"S":1790004300,"age":40,"signal":{"rsi14":34.061878742426465,"volume_ratio":1.3748673615943345,"taker_buy_fraction":0.28375662052240624,"volume5":169.38618,"return1":-10.763257362489927,"return5":-29.621956160016097,"return15":-50.106264313600256,"bollinger_z":-2.1161952547387433,"bar_close_ms":1790004299999,"ref":85906.77011753221,"reference_received_ms":1790004301362,"spot":85898.23693678755,"twap":85900.08016471738,"sigma":7.735348306543682,"spot_z":-0.068423382283774,"twap_z":-0.05364344347166575,"momentum":0.2602646581694582,"decision_ms":1790004340072,"momentum30":-0.33596215996875156,"momentum60":-0.38945080424794065,"spot_twap_gap":-0.03076263577104173,"range60":0.8696936946167207,"final_mean":85898.23693678755,"final_z":-0.07438593194804387,"final_up_prob":0.4703516512343924,"final_drift_up_prob":0.8852526368580929,"final_known_seconds":0,"final_sd":114.71498065822234,"final_drift_shift":146.38174968191},"entry_side":0,"context_gap":null,"book_errors":[null,null],"books":[{"bid":0.47,"ask":0.48,"asks":[[0.48,10.0]],"received_ms":1790004340066,"observed_ms":1790004340060,"hash":"12279fbd9c4338b6cbf34d37707d155cd698a4be"},{"bid":0.52,"ask":0.53,"asks":[[0.53,778.54]],"received_ms":1790004340072,"observed_ms":1790004340060,"hash":"4440124db38e9f77e0152e816ccecc541e4064de"}],"intents":{"pair_fast":null,"pair_250":{"kind":"first","side":0,"qty":5.0,"participation":true,"max_cost":2.5373599999999996},"pair_add_fast":null,"pair_add_250":{"kind":"first","side":0,"qty":5.0,"participation":true,"max_cost":2.5373599999999996}},"decision_ms":1790004340073,"feature_cutoff_ms":1790004340072,"request_ms":1790004340039,"inventory":{"pair_fast":{"qty":[5.0,0.0],"cash":2.48736,"lots":[[[5.0,0.49747199999999997]],[]],"floor":-2.48736},"pair_250":{"qty":[0.0,0.0],"cash":0.0,"lots":[[],[]],"floor":0.0},"pair_add_fast":{"qty":[5.0,0.0],"cash":2.48736,"lots":[[[5.0,0.49747199999999997]],[]],"floor":-2.48736},"pair_add_250":{"qty":[0.0,0.0],"cash":0.0,"lots":[[],[]],"floor":0.0}}}
{"kind":"decision","recorded_ms":1790004350085,"S":1790004300,"age":50,"signal":{"rsi14":34.061878742426465,"volume_ratio":1.3748673615943345,"taker_buy_fraction":0.28375662052240624,"volume5":169.38618,"return1":-10.763257362489927,"return5":-29.621956160016097,"return15":-50.106264313600256,"bollinger_z":-2.1161952547387433,"bar_close_ms":1790004299999,"ref":85906.77011753221,"reference_received_ms":1790004301362,"spot":85909.34275220391,"twap":85897.55817925502,"sigma":7.689076253691454,"spot_z":0.021164446736243698,"twap_z":-0.07578440077405135,"momentum":0.16614871603007467,"decision_ms":1790004350084,"momentum30":0.11638104291248623,"momentum60":0.027407625415279056,"spot_twap_gap":0.1978627569265713,"range60":0.72212368101462,"final_mean":85909.34275220391,"final_z":0.023093043812563413,"final_up_prob":0.5092119727792621,"final_drift_up_prob":0.7940611296471446,"final_known_seconds":0,"final_sd":111.40301350395059,"final_drift_shift":88.8439757226003},"entry_side":null,"context_gap":null,"book_errors":[null,null],"books":[{"bid":0.5,"ask":0.51,"asks":[[0.51,32.2]],"received_ms":1790004350057,"observed_ms":1790004350049,"hash":"53af1d6c6f01e2a02bc74e399080d7b498e043ab"},{"bid":0.49,"ask":0.5,"asks":[[0.5,1313.38]],"received_ms":1790004350084,"observed_ms":1790004350068,"hash":"1f2eea13d48431baeb3ab3124c12676bfd6f1669"}],"intents":{"pair_fast":null,"pair_250":{"kind":"first","side":1,"qty":5.0,"participation":true,"max_cost":2.6374999999999997},"pair_add_fast":null,"pair_add_250":{"kind":"first","side":1,"qty":5.0,"participation":true,"max_cost":2.6374999999999997}},"decision_ms":1790004350085,"feature_cutoff_ms":1790004350084,"request_ms":1790004350031,"inventory":{"pair_fast":{"qty":[5.0,0.0],"cash":2.48736,"lots":[[[5.0,0.49747199999999997]],[]],"floor":-2.48736},"pair_250":{"qty":[0.0,0.0],"cash":0.0,"lots":[[],[]],"floor":0.0},"pair_add_fast":{"qty":[5.0,0.0],"cash":2.48736,"lots":[[[5.0,0.49747199999999997]],[]],"floor":-2.48736},"pair_add_250":{"qty":[0.0,0.0],"cash":0.0,"lots":[[],[]],"floor":0.0}}}
{"kind":"decision","recorded_ms":1790004360067,"S":1790004300,"age":60,"signal":{"rsi14":34.061878742426465,"volume_ratio":1.3748673615943345,"taker_buy_fraction":0.28375662052240624,"volume5":169.38618,"return1":-10.763257362489927,"return5":-29.621956160016097,"return15":-50.106264313600256,"bollinger_z":-2.1161952547387433,"bar_close_ms":1790004299999,"ref":85906.77011753221,"reference_received_ms":1790004301362,"spot":85909.99741745534,"twap":85898.06978517599,"sigma":7.35849747189051,"spot_z":0.0283141993507407,"twap_z":-0.07633097345151753,"momentum":-0.052338401928282256,"decision_ms":1790004360066,"momentum30":0.4497526256478748,"momentum60":0.4656276485724662,"spot_twap_gap":0.20926156620993,"range60":0.7545649188748399,"final_mean":85909.99741745534,"final_z":0.031017504591746247,"final_up_prob":0.5123722101282081,"final_drift_up_prob":0.4149953581694326,"final_known_seconds":0,"final_sd":104.04769711808684,"final_drift_shift":-25.56774250076985},"entry_side":null,"context_gap":null,"book_errors":[null,null],"books":[{"bid":0.5,"ask":0.51,"asks":[[0.51,68.13]],"received_ms":1790004360066,"observed_ms":1790004360057,"hash":"fac6696e9453160d41b65ad31d3987b935e479ba"},{"bid":0.49,"ask":0.5,"asks":[[0.5,1121.5]],"received_ms":1790004360065,"observed_ms":1790004360056,"hash":"b3978b65f83233ec32ac288f4370676bfbf1e763"}],"intents":{"pair_fast":null,"pair_250":null,"pair_add_fast":null,"pair_add_250":null},"decision_ms":1790004360067,"feature_cutoff_ms":1790004360066,"request_ms":1790004360035,"inventory":{"pair_fast":{"qty":[5.0,0.0],"cash":2.48736,"lots":[[[5.0,0.49747199999999997]],[]],"floor":-2.48736},"pair_250":{"qty":[0.0,5.0],"cash":2.5374700000000003,"lots":[[],[[5.0,0.5074940000000001]]],"floor":-2.5374700000000003},"pair_add_fast":{"qty":[5.0,0.0],"cash":2.48736,"lots":[[[5.0,0.49747199999999997]],[]],"floor":-2.48736},"pair_add_250":{"qty":[0.0,5.0],"cash":2.5374700000000003,"lots":[[],[[5.0,0.5074940000000001]]],"floor":-2.5374700000000003}}}
{"kind":"decision","recorded_ms":1790004370048,"S":1790004300,"age":70,"signal":{"rsi14":37.5136007862133,"volume_ratio":1.2487349669297891,"taker_buy_fraction":0.34451180815622495,"volume5":190.19142,"return1":4.016994529157812,"return5":-18.517052729600948,"return15":-27.15167035269407,"bollinger_z":-1.674021181194486,"bar_close_ms":1790004359999,"ref":85906.77011753221,"reference_received_ms":1790004301362,"spot":85889.6269810878,"twap":85902.35826518704,"sigma":4.892378854612877,"spot_z":-0.23107327365233618,"twap_z":-0.05946759903452565,"momentum":-1.3301474065234398,"decision_ms":1790004370046,"momentum30":-0.584993225261577,"momentum60":-0.60280665255865,"spot_twap_gap":-0.33595143765078217,"range60":0.9492686952700431,"final_mean":85889.6269810878,"final_z":-0.2542412292694143,"final_up_prob":0.39965460021249216,"final_drift_up_prob":1.0305950537414788e-10,"final_known_seconds":0,"final_sd":67.42862475011098,"final_drift_shift":-411.4811537556443},"entry_side":null,"context_gap":null,"book_errors":[null,null],"books":[{"bid":0.37,"ask":0.38,"asks":[[0.38,196.31]],"received_ms":1790004370046,"observed_ms":1790004370036,"hash":"cabfe2df41bde6e69636656c963be91503699ae8"},{"bid":0.62,"ask":0.63,"asks":[[0.63,460.03]],"received_ms":1790004370037,"observed_ms":1790004370029,"hash":"d568a2c3c045acc8b40f0cdc108517efbd0083d9"}],"intents":{"pair_fast":null,"pair_250":{"kind":"complete","side":0,"qty":5.0,"max_cost":2.3625299999999996},"pair_add_fast":null,"pair_add_250":{"kind":"complete","side":0,"qty":5.0,"max_cost":2.3625299999999996}},"decision_ms":1790004370048,"feature_cutoff_ms":1790004370046,"request_ms":1790004370010,"inventory":{"pair_fast":{"qty":[5.0,0.0],"cash":2.48736,"lots":[[[5.0,0.49747199999999997]],[]],"floor":-2.48736},"pair_250":{"qty":[0.0,5.0],"cash":2.5374700000000003,"lots":[[],[[5.0,0.5074940000000001]]],"floor":-2.5374700000000003},"pair_add_fast":{"qty":[5.0,0.0],"cash":2.48736,"lots":[[[5.0,0.49747199999999997]],[]],"floor":-2.48736},"pair_add_250":{"qty":[0.0,5.0],"cash":2.5374700000000003,"lots":[[],[[5.0,0.5074940000000001]]],"floor":-2.5374700000000003}}}
{"kind":"decision","recorded_ms":1790004380093,"S":1790004300,"age":80,"signal":{"rsi14":37.5136007862133,"volume_ratio":1.2487349669297891,"taker_buy_fraction":0.34451180815622495,"volume5":190.19142,"return1":4.016994529157812,"return5":-18.517052729600948,"return15":-27.15167035269407,"bollinger_z":-1.674021181194486,"bar_close_ms":1790004359999,"ref":85906.77011753221,"reference_received_ms":1790004301362,"spot":85860.3711399289,"twap":85898.49985249179,"sigma":6.123685342709166,"spot_z":-0.5109460307083696,"twap_z":-0.09107224584641277,"momentum":-0.6544072788233907,"decision_ms":1790004380092,"momentum30":-1.51588998434432,"momentum60":-0.929088310054784,"spot_twap_gap":-0.8038289608517716,"range60":1.0718960874626382,"final_mean":85860.3711399289,"final_z":-0.5648983500559409,"final_up_prob":0.286071453003231,"final_drift_up_prob":0.0002371300186301828,"final_known_seconds":0,"final_sd":82.13686161185888,"final_drift_shift":-240.66018613321714},"entry_side":null,"context_gap":null,"book_errors":[null,null],"books":[{"bid":0.33,"ask":0.34,"asks":[[0.34,1341.84]],"received_ms":1790004380061,"observed_ms":1790004380051,"hash":"38cf9b5a71664270c2a49be12c01886a9d23bed8"},{"bid":0.66,"ask":0.67,"asks":[[0.67,3.64],[0.68,25.0]],"received_ms":1790004380092,"observed_ms":1790004380061,"hash":"3ced6884e99dd861e2c1788ba310757a76e6a5d7"}],"intents":{"pair_fast":null,"pair_250":null,"pair_add_fast":null,"pair_add_250":null},"decision_ms":1790004380093,"feature_cutoff_ms":1790004380092,"request_ms":1790004380027,"inventory":{"pair_fast":{"qty":[5.0,0.0],"cash":2.48736,"lots":[[[5.0,0.49747199999999997]],[]],"floor":-2.48736},"pair_250":{"qty":[5.0,5.0],"cash":4.5199300000000004,"lots":[[],[]],"floor":0.48006999999999955},"pair_add_fast":{"qty":[5.0,0.0],"cash":2.48736,"lots":[[[5.0,0.49747199999999997]],[]],"floor":-2.48736},"pair_add_250":{"qty":[5.0,5.0],"cash":4.5199300000000004,"lots":[[],[]],"floor":0.48006999999999955}}}
{"kind":"decision","recorded_ms":1790004390049,"S":1790004300,"age":90,"signal":{"rsi14":37.5136007862133,"volume_ratio":1.2487349669297891,"taker_buy_fraction":0.34451180815622495,"volume5":190.19142,"return1":4.016994529157812,"return5":-18.517052729600948,"return15":-27.15167035269407,"bollinger_z":-1.674021181194486,"bar_close_ms":1790004359999,"ref":85906.77011753221,"reference_received_ms":1790004301362,"spot":85842.38461549093,"twap":85891.60135023775,"sigma":5.159735610967119,"spot_z":-0.8611932751996378,"twap_z":-0.2028910231792105,"momentum":-0.7447618698914245,"decision_ms":1790004390048,"momentum30":-2.39981141418741,"momentum60":-1.238164757430737,"spot_twap_gap":-1.2314299827300306,"range60":1.722182171691646,"final_mean":85842.38461549093,"final_z":-0.9571885570312206,"final_up_prob":0.16923604584992702,"final_drift_up_prob":1.2873858225348478e-05,"final_known_seconds":0,"final_sd":67.26522331293222,"final_drift_shift":-218.67622084122536},"entry_side":null,"context_gap":null,"book_errors":[null,null],"books":[{"bid":0.29,"ask":0.3,"asks":[[0.3,112.32]],"received_ms":1790004390047,"observed_ms":1790004390035,"hash":"ab60461556b8d0580e3d80bcd3aa73d265f02ea7"},{"bid":0.7,"ask":0.71,"asks":[[0.71,829.85]],"received_ms":1790004390044,"observed_ms":1790004390035,"hash":"276fd8b79cf1fcddf09cec4aaa6d737f80d5f19a"}],"intents":{"pair_fast":null,"pair_250":null,"pair_add_fast":null,"pair_add_250":null},"decision_ms":1790004390049,"feature_cutoff_ms":1790004390048,"request_ms":1790004390016,"inventory":{"pair_fast":{"qty":[5.0,0.0],"cash":2.48736,"lots":[[[5.0,0.49747199999999997]],[]],"floor":-2.48736},"pair_250":{"qty":[5.0,5.0],"cash":4.5199300000000004,"lots":[[],[]],"floor":0.48006999999999955},"pair_add_fast":{"qty":[5.0,0.0],"cash":2.48736,"lots":[[[5.0,0.49747199999999997]],[]],"floor":-2.48736},"pair_add_250":{"qty":[5.0,5.0],"cash":4.5199300000000004,"lots":[[],[]],"floor":0.48006999999999955}}}
{"kind":"decision","recorded_ms":1790004400104,"S":1790004300,"age":100,"signal":{"rsi14":37.5136007862133,"volume_ratio":1.2487349669297891,"taker_buy_fraction":0.34451180815622495,"volume5":190.19142,"return1":4.016994529157812,"return5":-18.517052729600948,"return15":-27.15167035269407,"bollinger_z":-1.674021181194486,"bar_close_ms":1790004359999,"ref":85906.77011753221,"reference_received_ms":1790004301362,"spot":85841.254891813,"twap":85883.15397325817,"sigma":5.062296122490264,"spot_z":-0.9153592138582743,"twap_z":-0.3299577315004461,"momentum":0.013344596444775389,"decision_ms":1790004400103,"momentum30":-1.1464753696085757,"momentum60":-1.6333606886071315,"spot_twap_gap":-1.0685167410995418,"range60":1.7895891681042164,"final_mean":85841.254891813,"final_z":-1.0234686348263555,"final_up_prob":0.15304316120433847,"final_drift_up_prob":0.16682945999623455,"final_known_seconds":0,"final_sd":64.01292964910928,"final_drift_shift":3.6294323105684803},"entry_side":0,"context_gap":null,"book_errors":[null,null],"books":[{"bid":0.25,"ask":0.26,"asks":[[0.26,113.0]],"received_ms":1790004400103,"observed_ms":1790004400084,"hash":"9331f4f1e1fdfb2bf22cc0eb7d060cfa6bcb2a78"},{"bid":0.74,"ask":0.75,"asks":[[0.75,1020.98]],"received_ms":1790004400065,"observed_ms":1790004400054,"hash":"8a8740b015a1e9914426ee580b24318c247860ec"}],"intents":{"pair_fast":null,"pair_250":{"kind":"reopen","side":0,"qty":5.0,"max_cost":1.41734},"pair_add_fast":{"kind":"add","side":0,"qty":5.0,"max_cost":1.41734},"pair_add_250":{"kind":"reopen","side":0,"qty":5.0,"max_cost":1.41734}},"decision_ms":1790004400104,"feature_cutoff_ms":1790004400103,"request_ms":1790004400021,"inventory":{"pair_fast":{"qty":[5.0,0.0],"cash":2.48736,"lots":[[[5.0,0.49747199999999997]],[]],"floor":-2.48736},"pair_250":{"qty":[5.0,5.0],"cash":4.5199300000000004,"lots":[[],[]],"floor":0.48006999999999955},"pair_add_fast":{"qty":[5.0,0.0],"cash":2.48736,"lots":[[[5.0,0.49747199999999997]],[]],"floor":-2.48736},"pair_add_250":{"qty":[5.0,5.0],"cash":4.5199300000000004,"lots":[[],[]],"floor":0.48006999999999955}}}
{"kind":"decision","recorded_ms":1790004410074,"S":1790004300,"age":110,"signal":{"rsi14":37.5136007862133,"volume_ratio":1.2487349669297891,"taker_buy_fraction":0.34451180815622495,"volume5":190.19142,"return1":4.016994529157812,"return5":-18.517052729600948,"return15":-27.15167035269407,"bollinger_z":-1.674021181194486,"bar_close_ms":1790004359999,"ref":85906.77011753221,"reference_received_ms":1790004301362,"spot":85841.08400372897,"twap":85872.59313619345,"sigma":5.3765272178167995,"spot_z":-0.8864992356207342,"twap_z":-0.461252250717643,"momentum":0.236333527825051,"decision_ms":1790004410073,"momentum30":-0.4568162374482666,"momentum60":-1.683970445887656,"spot_twap_gap":-0.7565871695267933,"range60":1.780453204601527,"final_mean":85841.08400372897,"final_z":-0.9977731068880977,"final_up_prob":0.15919469684349008,"final_drift_up_prob":0.49136591359526444,"final_known_seconds":0,"final_sd":65.83271622554048,"final_drift_shift":64.26122161098303},"entry_side":0,"context_gap":null,"book_errors":[null,null],"books":[{"bid":0.28,"ask":0.3,"asks":[[0.3,85.0]],"received_ms":1790004410071,"observed_ms":1790004410056,"hash":"3c1ee87e4c6556a3cfbd4de254f56973d37bcbc6"},{"bid":0.7,"ask":0.72,"asks":[[0.72,60.0]],"received_ms":1790004410073,"observed_ms":1790004410056,"hash":"f58e586cdc477d6fd889f829cb516feedddfb7ff"}],"intents":{"pair_fast":null,"pair_250":null,"pair_add_fast":null,"pair_add_250":null},"decision_ms":1790004410074,"feature_cutoff_ms":1790004410073,"request_ms":1790004410040,"inventory":{"pair_fast":{"qty":[5.0,0.0],"cash":2.48736,"lots":[[[5.0,0.49747199999999997]],[]],"floor":-2.48736},"pair_250":{"qty":[10.0,5.0],"cash":5.887270000000001,"lots":[[[5.0,0.273468]],[]],"floor":-0.8872700000000009},"pair_add_fast":{"qty":[10.0,0.0],"cash":3.8547,"lots":[[[5.0,0.49747199999999997],[5.0,0.273468]],[]],"floor":-3.8547},"pair_add_250":{"qty":[10.0,5.0],"cash":5.887270000000001,"lots":[[[5.0,0.273468]],[]],"floor":-0.8872700000000009}}}
{"kind":"decision","recorded_ms":1790004420201,"S":1790004300,"age":120,"signal":{"rsi14":37.5136007862133,"volume_ratio":1.2487349669297891,"taker_buy_fraction":0.34451180815622495,"volume5":190.19142,"return1":4.016994529157812,"return5":-18.517052729600948,"return15":-27.15167035269407,"bollinger_z":-1.674021181194486,"bar_close_ms":1790004359999,"ref":85906.77011753221,"reference_received_ms":1790004301362,"spot":85860.56376649986,"twap":85862.83373518742,"sigma":6.1791226027843935,"spot_z":-0.557673512021753,"twap_z":-0.5302768147737302,"momentum":1.1377027740838097,"decision_ms":1790004420200,"momentum30":0.5768302066636103,"momentum60":-1.0371626768507158,"spot_twap_gap":-0.04742610177566718,"range60":1.5281011050507327,"final_mean":85860.56376649986,"final_z":-0.6324428326750346,"final_up_prob":0.2635487763941256,"final_drift_up_prob":0.9999567593897285,"final_known_seconds":0,"final_sd":73.06012282076352,"final_drift_shift":333.01779629691276},"entry_side":0,"context_gap":null,"book_errors":[null,null],"books":[{"bid":0.28,"ask":0.29,"asks":[[0.29,457.73]],"received_ms":1790004420077,"observed_ms":1790004420068,"hash":"ccf73f5da66209ac40c4a32f730a303042c28300"},{"bid":0.71,"ask":0.72,"asks":[[0.72,474.08]],"received_ms":1790004420200,"observed_ms":1790004420144,"hash":"8c1f8d75b1f7d5d4c9ec91927f7aa8292f6666b3"}],"intents":{"pair_fast":null,"pair_250":null,"pair_add_fast":null,"pair_add_250":null},"decision_ms":1790004420201,"feature_cutoff_ms":1790004420200,"request_ms":1790004420046,"inventory":{"pair_fast":{"qty":[5.0,0.0],"cash":2.48736,"lots":[[[5.0,0.49747199999999997]],[]],"floor":-2.48736},"pair_250":{"qty":[10.0,5.0],"cash":5.887270000000001,"lots":[[[5.0,0.273468]],[]],"floor":-0.8872700000000009},"pair_add_fast":{"qty":[10.0,0.0],"cash":3.8547,"lots":[[[5.0,0.49747199999999997],[5.0,0.273468]],[]],"floor":-3.8547},"pair_add_250":{"qty":[10.0,5.0],"cash":5.887270000000001,"lots":[[[5.0,0.273468]],[]],"floor":-0.8872700000000009}}}
{"kind":"decision","recorded_ms":1790004430084,"S":1790004300,"age":130,"signal":{"rsi14":20.867378170494685,"volume_ratio":0.5802518569651935,"taker_buy_fraction":0.33733472771282447,"volume5":175.24641,"return1":-7.0542102546036025,"return5":-17.720558223793265,"return15":-31.917505810171242,"bollinger_z":-1.9428811896434888,"bar_close_ms":1790004419999,"ref":85906.77011753221,"reference_received_ms":1790004301362,"spot":85874.850272875,"twap":85853.85390063128,"sigma":5.97557909607703,"spot_z":-0.40979094135790095,"twap_z":-0.6793449833420202,"momentum":1.3001336774991965,"decision_ms":1790004430083,"momentum30":1.1544423077662902,"momentum60":0.03903224237449338,"spot_twap_gap":0.4536162867969349,"range60":0.8536014653649361,"final_mean":85874.850272875,"final_z":-0.46864908990333065,"final_up_prob":0.3196602411682604,"final_drift_up_prob":0.999997655704016,"final_known_seconds":0,"final_sd":68.11033104491034,"final_drift_shift":343.7466641176406},"entry_side":0,"context_gap":null,"book_errors":[null,null],"books":[{"bid":0.41,"ask":0.42,"asks":[[0.42,872.76]],"received_ms":1790004430083,"observed_ms":1790004430070,"hash":"e32801d58fb9ac78db7ecd53d0a6dc641cc7f220"},{"bid":0.58,"ask":0.59,"asks":[[0.59,49.76]],"received_ms":1790004430081,"observed_ms":1790004430070,"hash":"e9167d3542b3dde0bf683f6a27c586777a558824"}],"intents":{"pair_fast":null,"pair_250":{"kind":"complete","side":1,"qty":5.0,"max_cost":3.5326600000000004},"pair_add_fast":null,"pair_add_250":{"kind":"complete","side":1,"qty":5.0,"max_cost":3.5326600000000004}},"decision_ms":1790004430084,"feature_cutoff_ms":1790004430083,"request_ms":1790004430048,"inventory":{"pair_fast":{"qty":[5.0,0.0],"cash":2.48736,"lots":[[[5.0,0.49747199999999997]],[]],"floor":-2.48736},"pair_250":{"qty":[10.0,5.0],"cash":5.887270000000001,"lots":[[[5.0,0.273468]],[]],"floor":-0.8872700000000009},"pair_add_fast":{"qty":[10.0,0.0],"cash":3.8547,"lots":[[[5.0,0.49747199999999997],[5.0,0.273468]],[]],"floor":-3.8547},"pair_add_250":{"qty":[10.0,5.0],"cash":5.887270000000001,"lots":[[[5.0,0.273468]],[]],"floor":-0.8872700000000009}}}
{"kind":"decision","recorded_ms":1790004440077,"S":1790004300,"age":140,"signal":{},"entry_side":null,"context_gap":"incomplete or stale context","book_errors":[null,null],"books":[{"bid":0.29,"ask":0.3,"asks":[[0.3,200.02]],"received_ms":1790004440076,"observed_ms":1790004440066,"hash":"23ff3e2b652a5bfd595b8c5a54d6d7a03a7300a5"},{"bid":0.7,"ask":0.71,"asks":[[0.71,432.79]],"received_ms":1790004440072,"observed_ms":1790004440065,"hash":"8ec9ffdb017ef5c2fcd92e6d0f5f91712b28f2f6"}],"intents":{"pair_fast":null,"pair_250":null,"pair_add_fast":null,"pair_add_250":null},"decision_ms":1790004440077,"feature_cutoff_ms":1790004440076,"request_ms":1790004440046,"inventory":{"pair_fast":{"qty":[5.0,0.0],"cash":2.48736,"lots":[[[5.0,0.49747199999999997]],[]],"floor":-2.48736},"pair_250":{"qty":[10.0,10.0],"cash":8.97127,"lots":[[],[]],"floor":1.0287299999999995},"pair_add_fast":{"qty":[10.0,0.0],"cash":3.8547,"lots":[[[5.0,0.49747199999999997],[5.0,0.273468]],[]],"floor":-3.8547},"pair_add_250":{"qty":[10.0,10.0],"cash":8.97127,"lots":[[],[]],"floor":1.0287299999999995}}}
{"kind":"decision","recorded_ms":1790004450085,"S":1790004300,"age":150,"signal":{"rsi14":20.867378170494685,"volume_ratio":0.5802518569651935,"taker_buy_fraction":0.33733472771282447,"volume5":175.24641,"return1":-7.0542102546036025,"return5":-17.720558223793265,"return15":-31.917505810171242,"bollinger_z":-1.9428811896434888,"bar_close_ms":1790004419999,"ref":85906.77011753221,"reference_received_ms":1790004301362,"spot":85838.77949718433,"twap":85853.08567250732,"sigma":5.826912418926459,"spot_z":-0.9529859994354766,"twap_z":-0.7524644463369982,"momentum":-1.15023830873128,"decision_ms":1790004450084,"momentum30":-0.3604187442542458,"momentum60":-0.05011112651065052,"spot_twap_gap":-0.31696362664802563,"range60":0.9519979690254207,"final_mean":85838.77949718433,"final_z":-1.1129612806559444,"final_up_prob":0.13286252955094635,"final_drift_up_prob":6.697579829628708e-08,"final_known_seconds":0,"final_sd":61.089834417076894,"final_drift_shift":-254.15780508593573},"entry_side":null,"context_gap":null,"book_errors":[null,null],"books":[{"bid":0.28,"ask":0.29,"asks":[[0.29,37.41]],"received_ms":1790004450083,"observed_ms":1790004449816,"hash":"eb084f4a56e1e782527a6939a21c8b4c988b7fe9"},{"bid":0.71,"ask":0.72,"asks":[[0.72,1086.65]],"received_ms":1790004450084,"observed_ms":1790004449816,"hash":"ce10b4778825a51a94098baf5d2e9f90e735e535"}],"intents":{"pair_fast":null,"pair_250":null,"pair_add_fast":null,"pair_add_250":null},"decision_ms":1790004450085,"feature_cutoff_ms":1790004450084,"request_ms":1790004450050,"inventory":{"pair_fast":{"qty":[5.0,0.0],"cash":2.48736,"lots":[[[5.0,0.49747199999999997]],[]],"floor":-2.48736},"pair_250":{"qty":[10.0,10.0],"cash":8.97127,"lots":[[],[]],"floor":1.0287299999999995},"pair_add_fast":{"qty":[10.0,0.0],"cash":3.8547,"lots":[[[5.0,0.49747199999999997],[5.0,0.273468]],[]],"floor":-3.8547},"pair_add_250":{"qty":[10.0,10.0],"cash":8.97127,"lots":[[],[]],"floor":1.0287299999999995}}}
{"kind":"decision","recorded_ms":1790004460094,"S":1790004300,"age":160,"signal":{"rsi14":20.867378170494685,"volume_ratio":0.5802518569651935,"taker_buy_fraction":0.33733472771282447,"volume5":175.24641,"return1":-7.0542102546036025,"return5":-17.720558223793265,"return15":-31.917505810171242,"bollinger_z":-1.9428811896434888,"bar_close_ms":1790004419999,"ref":85906.77011753221,"reference_received_ms":1790004301362,"spot":85834.13846001105,"twap":85853.7974943105,"sigma":5.830044954090388,"spot_z":-1.0532569403658711,"twap_z":-0.7681744429611052,"momentum":-0.6874723148503531,"decision_ms":1790004460093,"momentum30":-1.4372792548938214,"momentum60":-0.06482345557032343,"spot_twap_gap":-0.4353260454756006,"range60":1.0163099075941695,"final_mean":85834.13846001105,"final_z":-1.2463961318650005,"final_up_prob":0.10630950032335096,"final_drift_up_prob":0.0001379896654871704,"final_known_seconds":0,"final_sd":58.27333354484008,"final_drift_shift":-139.3004344146215},"entry_side":null,"context_gap":null,"book_errors":[null,null],"books":[{"bid":0.24,"ask":0.25,"asks":[[0.25,53.0]],"received_ms":1790004460048,"observed_ms":1790004460037,"hash":"be38fcffd736a5332e96de037ad2510f17a7cdd9"},{"bid":0.75,"ask":0.76,"asks":[[0.76,334.41]],"received_ms":1790004460093,"observed_ms":1790004460064,"hash":"b106aeea84fbdb6e0ee0383f46f3fdc489ef29f0"}],"intents":{"pair_fast":null,"pair_250":null,"pair_add_fast":null,"pair_add_250":null},"decision_ms":1790004460094,"feature_cutoff_ms":1790004460093,"request_ms":1790004460008,"inventory":{"pair_fast":{"qty":[5.0,0.0],"cash":2.48736,"lots":[[[5.0,0.49747199999999997]],[]],"floor":-2.48736},"pair_250":{"qty":[10.0,10.0],"cash":8.97127,"lots":[[],[]],"floor":1.0287299999999995},"pair_add_fast":{"qty":[10.0,0.0],"cash":3.8547,"lots":[[[5.0,0.49747199999999997],[5.0,0.273468]],[]],"floor":-3.8547},"pair_add_250":{"qty":[10.0,10.0],"cash":8.97127,"lots":[[],[]],"floor":1.0287299999999995}}}
{"kind":"decision","recorded_ms":1790004470073,"S":1790004300,"age":170,"signal":{"rsi14":20.867378170494685,"volume_ratio":0.5802518569651935,"taker_buy_fraction":0.33733472771282447,"volume5":175.24641,"return1":-7.0542102546036025,"return5":-17.720558223793265,"return15":-31.917505810171242,"bollinger_z":-1.9428811896434888,"bar_close_ms":1790004419999,"ref":85906.77011753221,"reference_received_ms":1790004301362,"spot":85859.58798795482,"twap":85853.71863124464,"sigma":6.340541985496656,"spot_z":-0.6528295129614228,"twap_z":-0.7340401178412493,"momentum":1.3648886065757808,"decision_ms":1790004470072,"momentum30":-0.011119447184528198,"momentum60":0.4327729444935265,"spot_twap_gap":0.11950566604267514,"range60":0.9735205201704366,"final_mean":85859.58798795482,"final_z":-0.7847000656815499,"final_up_prob":0.21631472213663172,"final_drift_up_prob":0.9999162149267886,"final_known_seconds":0,"final_sd":60.127597334172414,"final_drift_shift":273.47069000314224},"entry_side":0,"context_gap":null,"book_errors":[null,null],"books":[{"bid":0.29,"ask":0.3,"asks":[[0.3,229.93]],"received_ms":1790004470072,"observed_ms":1790004470052,"hash":"679406554a0dfdfaa0f7e6a6dfad123179cfad1c"},{"bid":0.7,"ask":0.71,"asks":[[0.71,78.01]],"received_ms":1790004470058,"observed_ms":1790004470044,"hash":"77ca7bc4ea15ab4cf60739ebb0c7f0267b700ea9"}],"intents":{"pair_fast":null,"pair_250":{"kind":"reopen","side":0,"qty":5.0,"max_cost":1.6235},"pair_add_fast":null,"pair_add_250":{"kind":"reopen","side":0,"qty":5.0,"max_cost":1.6235}},"decision_ms":1790004470073,"feature_cutoff_ms":1790004470072,"request_ms":1790004470019,"inventory":{"pair_fast":{"qty":[5.0,0.0],"cash":2.48736,"lots":[[[5.0,0.49747199999999997]],[]],"floor":-2.48736},"pair_250":{"qty":[10.0,10.0],"cash":8.97127,"lots":[[],[]],"floor":1.0287299999999995},"pair_add_fast":{"qty":[10.0,0.0],"cash":3.8547,"lots":[[[5.0,0.49747199999999997],[5.0,0.273468]],[]],"floor":-3.8547},"pair_add_250":{"qty":[10.0,10.0],"cash":8.97127,"lots":[[],[]],"floor":1.0287299999999995}}}
{"kind":"decision","recorded_ms":1790004480092,"S":1790004300,"age":180,"signal":{"rsi14":20.867378170494685,"volume_ratio":0.5802518569651935,"taker_buy_fraction":0.33733472771282447,"volume5":175.24641,"return1":-7.0542102546036025,"return5":-17.720558223793265,"return15":-31.917505810171242,"bollinger_z":-1.9428811896434888,"bar_close_ms":1790004419999,"ref":85906.77011753221,"reference_received_ms":1790004301362,"spot":85867.76082767917,"twap":85855.16048548571,"sigma":5.712851751393003,"spot_z":-0.6235757239189299,"twap_z":-0.8249961428630422,"momentum":0.44128619247510603,"decision_ms":1790004480091,"momentum30":0.66946594549401,"momentum60":0.39497937344325834,"spot_twap_gap":0.2847434614412983,"range60":1.0804844936468165,"final_mean":85867.76082767917,"final_z":-0.7638661098582228,"final_up_prob":0.22247351762533535,"final_drift_up_prob":0.7388085909367577,"final_known_seconds":0,"final_sd":51.068229562223024,"final_drift_shift":71.67644549240076},"entry_side":0,"context_gap":null,"book_errors":[null,null],"books":[{"bid":0.27,"ask":0.28,"asks":[[0.28,72.0]],"received_ms":1790004480079,"observed_ms":1790004480070,"hash":"44a11ab4fc97315e26837c3344155268780c7582"},{"bid":0.72,"ask":0.73,"asks":[[0.73,460.83]],"received_ms":1790004480090,"observed_ms":1790004480073,"hash":"d96ad5123b1e355bc41e73ec361899865cf00753"}],"intents":{"pair_fast":null,"pair_250":null,"pair_add_fast":null,"pair_add_250":null},"decision_ms":1790004480092,"feature_cutoff_ms":1790004480091,"request_ms":1790004480045,"inventory":{"pair_fast":{"qty":[5.0,0.0],"cash":2.48736,"lots":[[[5.0,0.49747199999999997]],[]],"floor":-2.48736},"pair_250":{"qty":[15.0,10.0],"cash":10.54477,"lots":[[[5.0,0.3147]],[]],"floor":-0.5447699999999998},"pair_add_fast":{"qty":[10.0,0.0],"cash":3.8547,"lots":[[[5.0,0.49747199999999997],[5.0,0.273468]],[]],"floor":-3.8547},"pair_add_250":{"qty":[15.0,10.0],"cash":10.54477,"lots":[[[5.0,0.3147]],[]],"floor":-0.5447699999999998}}}
{"kind":"decision","recorded_ms":1790004490095,"S":1790004300,"age":190,"signal":{"rsi14":24.015397025317277,"volume_ratio":0.5539249339234599,"taker_buy_fraction":0.3419666229442228,"volume5":166.39814,"return1":1.5012404159075834,"return5":-14.803930897286454,"return15":-49.492018211012564,"bollinger_z":-1.6185549475847023,"bar_close_ms":1790004479999,"ref":85906.77011753221,"reference_received_ms":1790004301362,"spot":85850.30358350008,"twap":85855.62762476258,"sigma":4.408538664427537,"spot_z":-1.221759645146967,"twap_z":-1.1065640009461026,"momentum":-0.672984017539046,"decision_ms":1790004490094,"momentum30":0.7488589715997865,"momentum60":-0.8706340744576738,"spot_twap_gap":-0.15590898113678628,"range60":1.400157331428267,"final_mean":85850.30358350008,"final_z":-1.5319311640154234,"final_up_prob":0.06276971111273194,"final_drift_up_prob":0.00018136110053956767,"final_known_seconds":0,"final_sd":36.859707119039086,"final_drift_shift":-74.9684954251155},"entry_side":null,"context_gap":null,"book_errors":[null,null],"books":[{"bid":0.21,"ask":0.22,"asks":[[0.22,720.51]],"received_ms":1790004490070,"observed_ms":1790004490060,"hash":"1894ea64560d44861ce78628f1064a3964089921"},{"bid":0.78,"ask":0.79,"asks":[[0.79,114.0]],"received_ms":1790004490094,"observed_ms":1790004490084,"hash":"f29603ee7bee4b1d754871d71451f6a12b42658b"}],"intents":{"pair_fast":null,"pair_250":null,"pair_add_fast":null,"pair_add_250":null},"decision_ms":1790004490095,"feature_cutoff_ms":1790004490094,"request_ms":1790004490044,"inventory":{"pair_fast":{"qty":[5.0,0.0],"cash":2.48736,"lots":[[[5.0,0.49747199999999997]],[]],"floor":-2.48736},"pair_250":{"qty":[15.0,10.0],"cash":10.54477,"lots":[[[5.0,0.3147]],[]],"floor":-0.5447699999999998},"pair_add_fast":{"qty":[10.0,0.0],"cash":3.8547,"lots":[[[5.0,0.49747199999999997],[5.0,0.273468]],[]],"floor":-3.8547},"pair_add_250":{"qty":[15.0,10.0],"cash":10.54477,"lots":[[[5.0,0.3147]],[]],"floor":-0.5447699999999998}}}
{"kind":"decision","recorded_ms":1790004500057,"S":1790004300,"age":200,"signal":{"rsi14":24.015397025317277,"volume_ratio":0.5539249339234599,"taker_buy_fraction":0.3419666229442228,"volume5":166.39814,"return1":1.5012404159075834,"return5":-14.803930897286454,"return15":-49.492018211012564,"bollinger_z":-1.6185549475847023,"bar_close_ms":1790004479999,"ref":85906.77011753221,"reference_received_ms":1790004301362,"spot":85845.17555218865,"twap":85851.25561732207,"sigma":4.041130196095389,"spot_z":-1.5246185120818088,"twap_z":-1.3741217952795897,"momentum":-0.33138997998251024,"decision_ms":1790004500056,"momentum30":-0.6602080672378862,"momentum60":-0.47276151494070145,"spot_twap_gap":-0.19423601701260723,"range60":0.8866055821486716,"final_mean":85845.17555218865,"final_z":-1.9686417555411946,"final_up_prob":0.02449712203284854,"final_drift_up_prob":0.00177643908688091,"final_known_seconds":0,"final_sd":31.28784867545901,"final_drift_shift":-29.62052016487412},"entry_side":null,"context_gap":null,"book_errors":[null,null],"books":[{"bid":0.18,"ask":0.19,"asks":[[0.19,632.54]],"received_ms":1790004500056,"observed_ms":1790004500039,"hash":"93064265e3a1442d4b38b49b006e4713de6f497d"},{"bid":0.81,"ask":0.82,"asks":[[0.82,311.0]],"received_ms":1790004500043,"observed_ms":1790004500036,"hash":"f9253bdfab31d9a51b7199fced56516ac9c75781"}],"intents":{"pair_fast":null,"pair_250":null,"pair_add_fast":null,"pair_add_250":null},"decision_ms":1790004500057,"feature_cutoff_ms":1790004500056,"request_ms":1790004500018,"inventory":{"pair_fast":{"qty":[5.0,0.0],"cash":2.48736,"lots":[[[5.0,0.49747199999999997]],[]],"floor":-2.48736},"pair_250":{"qty":[15.0,10.0],"cash":10.54477,"lots":[[[5.0,0.3147]],[]],"floor":-0.5447699999999998},"pair_add_fast":{"qty":[10.0,0.0],"cash":3.8547,"lots":[[[5.0,0.49747199999999997],[5.0,0.273468]],[]],"floor":-3.8547},"pair_add_250":{"qty":[15.0,10.0],"cash":10.54477,"lots":[[[5.0,0.3147]],[]],"floor":-0.5447699999999998}}}
{"kind":"decision","recorded_ms":1790004510093,"S":1790004300,"age":210,"signal":{"rsi14":24.015397025317277,"volume_ratio":0.5539249339234599,"taker_buy_fraction":0.3419666229442228,"volume5":166.39814,"return1":1.5012404159075834,"return5":-14.803930897286454,"return15":-49.492018211012564,"bollinger_z":-1.6185549475847023,"bar_close_ms":1790004479999,"ref":85906.77011753221,"reference_received_ms":1790004301362,"spot":85843.44489686115,"twap":85849.2094741153,"sigma":3.854753197046599,"spot_z":-1.7325308084410849,"twap_z":-1.5748162740958962,"momentum":-0.18151580964945033,"decision_ms":1790004510092,"momentum30":-0.7692180719221295,"momentum60":-0.11279608566304544,"spot_twap_gap":-0.19306131557553496,"range60":0.9232625545613263,"final_mean":85843.44489686115,"final_z":-2.3253859888615085,"final_up_prob":0.010025665000942152,"final_drift_up_prob":0.002460613983933102,"final_known_seconds":0,"final_sd":27.232133062805598,"final_drift_shift":-13.255492109600972},"entry_side":null,"context_gap":null,"book_errors":[null,null],"books":[{"bid":0.15,"ask":0.16,"asks":[[0.16,910.03]],"received_ms":1790004510066,"observed_ms":1790004510054,"hash":"053d539d31a5f99ecda8791da2f5be0a7cc3995c"},{"bid":0.84,"ask":0.85,"asks":[[0.85,65.4]],"received_ms":1790004510092,"observed_ms":1790004510070,"hash":"f86d39ba24ef7522eb8b9d5babb731a83193a690"}],"intents":{"pair_fast":null,"pair_250":null,"pair_add_fast":null,"pair_add_250":null},"decision_ms":1790004510093,"feature_cutoff_ms":1790004510092,"request_ms":1790004510029,"inventory":{"pair_fast":{"qty":[5.0,0.0],"cash":2.48736,"lots":[[[5.0,0.49747199999999997]],[]],"floor":-2.48736},"pair_250":{"qty":[15.0,10.0],"cash":10.54477,"lots":[[[5.0,0.3147]],[]],"floor":-0.5447699999999998},"pair_add_fast":{"qty":[10.0,0.0],"cash":3.8547,"lots":[[[5.0,0.49747199999999997],[5.0,0.273468]],[]],"floor":-3.8547},"pair_add_250":{"qty":[15.0,10.0],"cash":10.54477,"lots":[[[5.0,0.3147]],[]],"floor":-0.5447699999999998}}}
{"kind":"decision","recorded_ms":1790004520077,"S":1790004300,"age":220,"signal":{"rsi14":24.015397025317277,"volume_ratio":0.5539249339234599,"taker_buy_fraction":0.3419666229442228,"volume5":166.39814,"return1":1.5012404159075834,"return5":-14.803930897286454,"return15":-49.492018211012564,"bollinger_z":-1.6185549475847023,"bar_close_ms":1790004479999,"ref":85906.77011753221,"reference_received_ms":1790004301362,"spot":85823.55503309093,"twap":85848.28868844957,"sigma":3.887336254691746,"spot_z":-2.394465737729404,"twap_z":-1.6827691658554778,"momentum":-1.5509112373294884,"decision_ms":1790004520075,"momentum30":-1.2143354988984105,"momentum60":-0.2878061437507247,"spot_twap_gap":-0.8214111070634714,"range60":1.203330052857707,"final_mean":85823.55503309093,"final_z":-3.3878758520390884,"final_up_prob":0.00035218069172809896,"final_drift_up_prob":1.8934853684982045e-13,"final_known_seconds":0,"final_sd":24.56261329387183,"final_drift_shift":-95.18250374618559},"entry_side":null,"context_gap":null,"book_errors":[null,null],"books":[{"bid":0.11,"ask":0.12,"asks":[[0.12,814.0]],"received_ms":1790004520065,"observed_ms":1790004520046,"hash":"12cb85ce7ab68b0c75ca40396d02770b18dce3f0"},{"bid":0.88,"ask":0.89,"asks":[[0.89,18.18]],"received_ms":1790004520075,"observed_ms":1790004520056,"hash":"5fdc105727a29c27091e3de109cbb1c88079963b"}],"intents":{"pair_fast":null,"pair_250":null,"pair_add_fast":null,"pair_add_250":null},"decision_ms":1790004520077,"feature_cutoff_ms":1790004520075,"request_ms":1790004520016,"inventory":{"pair_fast":{"qty":[5.0,0.0],"cash":2.48736,"lots":[[[5.0,0.49747199999999997]],[]],"floor":-2.48736},"pair_250":{"qty":[15.0,10.0],"cash":10.54477,"lots":[[[5.0,0.3147]],[]],"floor":-0.5447699999999998},"pair_add_fast":{"qty":[10.0,0.0],"cash":3.8547,"lots":[[[5.0,0.49747199999999997],[5.0,0.273468]],[]],"floor":-3.8547},"pair_add_250":{"qty":[15.0,10.0],"cash":10.54477,"lots":[[[5.0,0.3147]],[]],"floor":-0.5447699999999998}}}
{"kind":"decision","recorded_ms":1790004530036,"S":1790004300,"age":230,"signal":{"rsi14":24.015397025317277,"volume_ratio":0.5539249339234599,"taker_buy_fraction":0.3419666229442228,"volume5":166.39814,"return1":1.5012404159075834,"return5":-14.803930897286454,"return15":-49.492018211012564,"bollinger_z":-1.6185549475847023,"bar_close_ms":1790004479999,"ref":85906.77011753221,"reference_received_ms":1790004301362,"spot":85821.4374572314,"twap":85845.40081895364,"sigma":2.7085657816196895,"spot_z":-3.76647837877821,"twap_z":-2.7087651480938555,"momentum":-1.3810758987864435,"decision_ms":1790004530035,"momentum30":-1.6325841540364983,"momentum60":-1.8279513247844368,"spot_twap_gap":-1.142175211929449,"range60":1.8279513247844368,"final_mean":85821.4374572314,"final_z":-5.755310479457089,"final_up_prob":4.324134883493258e-09,"final_drift_up_prob":0.0,"final_known_seconds":0,"final_sd":14.826769225639907,"final_drift_shift":-47.27556744641776},"entry_side":null,"context_gap":null,"book_errors":[null,null],"books":[{"bid":0.03,"ask":0.04,"asks":[[0.04,1066.09]],"received_ms":1790004530035,"observed_ms":1790004530024,"hash":"08924bfc101c1e381456b44e5f1ed382002388a7"},{"bid":0.96,"ask":0.97,"asks":[[0.97,1037.03]],"received_ms":1790004530035,"observed_ms":1790004530024,"hash":"0ab3601e2914a785c8fa83faac34f2a2e0b6678e"}],"intents":{"pair_fast":null,"pair_250":null,"pair_add_fast":null,"pair_add_250":null},"decision_ms":1790004530036,"feature_cutoff_ms":1790004530035,"request_ms":1790004530001,"inventory":{"pair_fast":{"qty":[5.0,0.0],"cash":2.48736,"lots":[[[5.0,0.49747199999999997]],[]],"floor":-2.48736},"pair_250":{"qty":[15.0,10.0],"cash":10.54477,"lots":[[[5.0,0.3147]],[]],"floor":-0.5447699999999998},"pair_add_fast":{"qty":[10.0,0.0],"cash":3.8547,"lots":[[[5.0,0.49747199999999997],[5.0,0.273468]],[]],"floor":-3.8547},"pair_add_250":{"qty":[15.0,10.0],"cash":10.54477,"lots":[[[5.0,0.3147]],[]],"floor":-0.5447699999999998}}}
{"kind":"decision","recorded_ms":1790004540044,"S":1790004300,"age":240,"signal":{},"entry_side":null,"context_gap":"incomplete or stale context","book_errors":[null,null],"books":[{"bid":0.01,"ask":0.02,"asks":[[0.02,223.0]],"received_ms":1790004540043,"observed_ms":1790004540032,"hash":"30254825ed5a3d9148192c3fed2c962fda2ea49a"},{"bid":0.98,"ask":0.99,"asks":[[0.99,3323.73]],"received_ms":1790004540043,"observed_ms":1790004540036,"hash":"fda0eccdc88dfe6d5b688162f6611f45a5f4b706"}],"intents":{"pair_fast":null,"pair_250":null,"pair_add_fast":null,"pair_add_250":null},"decision_ms":1790004540044,"feature_cutoff_ms":1790004540043,"request_ms":1790004540011,"inventory":{"pair_fast":{"qty":[5.0,0.0],"cash":2.48736,"lots":[[[5.0,0.49747199999999997]],[]],"floor":-2.48736},"pair_250":{"qty":[15.0,10.0],"cash":10.54477,"lots":[[[5.0,0.3147]],[]],"floor":-0.5447699999999998},"pair_add_fast":{"qty":[10.0,0.0],"cash":3.8547,"lots":[[[5.0,0.49747199999999997],[5.0,0.273468]],[]],"floor":-3.8547},"pair_add_250":{"qty":[15.0,10.0],"cash":10.54477,"lots":[[[5.0,0.3147]],[]],"floor":-0.5447699999999998}}}
{"kind":"decision","recorded_ms":1790004550081,"S":1790004300,"age":250,"signal":{},"entry_side":null,"context_gap":"incomplete or stale context","book_errors":[null,null],"books":[{"bid":null,"ask":0.01,"asks":[[0.01,4871.8]],"received_ms":1790004550080,"observed_ms":1790004550063,"hash":"cb2903b77d056e24ce0945aa1d32133f2797cd07"},{"bid":0.99,"ask":null,"asks":[],"received_ms":1790004550077,"observed_ms":1790004550063,"hash":"b32822777eacafc090eb032e7816cb679e209fc3"}],"intents":{"pair_fast":null,"pair_250":null,"pair_add_fast":null,"pair_add_250":null},"decision_ms":1790004550081,"feature_cutoff_ms":1790004550080,"request_ms":1790004550039,"inventory":{"pair_fast":{"qty":[5.0,0.0],"cash":2.48736,"lots":[[[5.0,0.49747199999999997]],[]],"floor":-2.48736},"pair_250":{"qty":[15.0,10.0],"cash":10.54477,"lots":[[[5.0,0.3147]],[]],"floor":-0.5447699999999998},"pair_add_fast":{"qty":[10.0,0.0],"cash":3.8547,"lots":[[[5.0,0.49747199999999997],[5.0,0.273468]],[]],"floor":-3.8547},"pair_add_250":{"qty":[15.0,10.0],"cash":10.54477,"lots":[[[5.0,0.3147]],[]],"floor":-0.5447699999999998}}}
{"kind":"decision","recorded_ms":1790004560038,"S":1790004300,"age":260,"signal":{},"entry_side":null,"context_gap":"incomplete or stale context","book_errors":[null,null],"books":[{"bid":null,"ask":0.01,"asks":[[0.01,32280.81]],"received_ms":1790004560037,"observed_ms":1790004560022,"hash":"122e46ecf3e4f140c55904d6f0d00b06d2516e4b"},{"bid":0.99,"ask":null,"asks":[],"received_ms":1790004560027,"observed_ms":1790004560009,"hash":"96127d19d53ea37be7dccc3e02d9113b8fcd164c"}],"intents":{"pair_fast":null,"pair_250":null,"pair_add_fast":null,"pair_add_250":null},"decision_ms":1790004560038,"feature_cutoff_ms":1790004560037,"request_ms":1790004560003,"inventory":{"pair_fast":{"qty":[5.0,0.0],"cash":2.48736,"lots":[[[5.0,0.49747199999999997]],[]],"floor":-2.48736},"pair_250":{"qty":[15.0,10.0],"cash":10.54477,"lots":[[[5.0,0.3147]],[]],"floor":-0.5447699999999998},"pair_add_fast":{"qty":[10.0,0.0],"cash":3.8547,"lots":[[[5.0,0.49747199999999997],[5.0,0.273468]],[]],"floor":-3.8547},"pair_add_250":{"qty":[15.0,10.0],"cash":10.54477,"lots":[[[5.0,0.3147]],[]],"floor":-0.5447699999999998}}}
{"kind":"decision","recorded_ms":1790004570059,"S":1790004300,"age":270,"signal":{},"entry_side":null,"context_gap":"incomplete or stale context","book_errors":[null,null],"books":[{"bid":null,"ask":0.01,"asks":[[0.01,36818.06]],"received_ms":1790004570041,"observed_ms":1790004570033,"hash":"a1e0bc5506a86b5b2926e3760d9de52ef66a525d"},{"bid":0.99,"ask":null,"asks":[],"received_ms":1790004570055,"observed_ms":1790004570043,"hash":"37fac5db213551bc4c79923ce35feaa13c5f506e"}],"intents":{"pair_fast":null,"pair_250":null,"pair_add_fast":null,"pair_add_250":null},"decision_ms":1790004570059,"feature_cutoff_ms":1790004570056,"request_ms":1790004570012,"inventory":{"pair_fast":{"qty":[5.0,0.0],"cash":2.48736,"lots":[[[5.0,0.49747199999999997]],[]],"floor":-2.48736},"pair_250":{"qty":[15.0,10.0],"cash":10.54477,"lots":[[[5.0,0.3147]],[]],"floor":-0.5447699999999998},"pair_add_fast":{"qty":[10.0,0.0],"cash":3.8547,"lots":[[[5.0,0.49747199999999997],[5.0,0.273468]],[]],"floor":-3.8547},"pair_add_250":{"qty":[15.0,10.0],"cash":10.54477,"lots":[[[5.0,0.3147]],[]],"floor":-0.5447699999999998}}}
{"kind":"decision","recorded_ms":1790004580361,"S":1790004300,"age":280,"signal":{},"entry_side":null,"context_gap":"incomplete or stale context","book_errors":[null,null],"books":[{"bid":null,"ask":0.01,"asks":[[0.01,54034.49]],"received_ms":1790004580091,"observed_ms":1790004580053,"hash":"e756018b5a642c7c9a1881a58762b473a5ba26b7"},{"bid":0.99,"ask":null,"asks":[],"received_ms":1790004580360,"observed_ms":1790004580053,"hash":"8ef7a928e748d40a8d46118704fe272912cefdc9"}],"intents":{"pair_fast":null,"pair_250":null,"pair_add_fast":null,"pair_add_250":null},"decision_ms":1790004580361,"feature_cutoff_ms":1790004580360,"request_ms":1790004580033,"inventory":{"pair_fast":{"qty":[5.0,0.0],"cash":2.48736,"lots":[[[5.0,0.49747199999999997]],[]],"floor":-2.48736},"pair_250":{"qty":[15.0,10.0],"cash":10.54477,"lots":[[[5.0,0.3147]],[]],"floor":-0.5447699999999998},"pair_add_fast":{"qty":[10.0,0.0],"cash":3.8547,"lots":[[[5.0,0.49747199999999997],[5.0,0.273468]],[]],"floor":-3.8547},"pair_add_250":{"qty":[15.0,10.0],"cash":10.54477,"lots":[[[5.0,0.3147]],[]],"floor":-0.5447699999999998}}}
{"kind":"decision","recorded_ms":1790004590069,"S":1790004300,"age":290,"signal":{},"entry_side":null,"context_gap":"incomplete or stale context","book_errors":[null,null],"books":[{"bid":null,"ask":0.01,"asks":[[0.01,55102.06]],"received_ms":1790004590068,"observed_ms":1790004590054,"hash":"01afe2a2047fa58d0ed13ba77e366371f01df733"},{"bid":0.99,"ask":null,"asks":[],"received_ms":1790004590062,"observed_ms":1790004590054,"hash":"8c29dc6cc9a4e76c2e9cb8bcc6bf2ca912200910"}],"intents":{"pair_fast":null,"pair_250":null,"pair_add_fast":null,"pair_add_250":null},"decision_ms":1790004590069,"feature_cutoff_ms":1790004590068,"request_ms":1790004590035,"inventory":{"pair_fast":{"qty":[5.0,0.0],"cash":2.48736,"lots":[[[5.0,0.49747199999999997]],[]],"floor":-2.48736},"pair_250":{"qty":[15.0,10.0],"cash":10.54477,"lots":[[[5.0,0.3147]],[]],"floor":-0.5447699999999998},"pair_add_fast":{"qty":[10.0,0.0],"cash":3.8547,"lots":[[[5.0,0.49747199999999997],[5.0,0.273468]],[]],"floor":-3.8547},"pair_add_250":{"qty":[15.0,10.0],"cash":10.54477,"lots":[[[5.0,0.3147]],[]],"floor":-0.5447699999999998}}}
{"kind":"decision","recorded_ms":1790004630081,"S":1790004600,"age":30,"signal":{"rsi14":22.904249182849156,"volume_ratio":0.514291886209012,"taker_buy_fraction":0.41747840097954614,"volume5":111.98656,"return1":3.8241122683883533,"return5":-2.970297375689851,"return15":-51.15318009937964,"bollinger_z":-1.344609969097509,"bar_close_ms":1790004599999,"ref":85824.94072169792,"reference_received_ms":1790004601962,"spot":85901.53581822757,"twap":85852.11835635775,"sigma":6.062401131606334,"spot_z":0.7690205790657665,"twap_z":0.27286551346864735,"momentum":-0.2506962517321078,"decision_ms":1790004630079,"momentum30":1.7638323478938973,"momentum60":1.7881254043634585,"spot_twap_gap":1.0523498455411804,"range60":2.0133193897682053,"final_mean":85901.53581822757,"final_z":0.8332339923699293,"final_up_prob":0.7976436124798714,"final_drift_up_prob":0.33682669838401935,"final_known_seconds":0,"final_sd":91.92507414609273,"final_drift_shift":-115.30835396473515},"entry_side":null,"context_gap":null,"book_errors":[null,null],"books":[{"bid":0.67,"ask":0.68,"asks":[[0.68,338.12]],"received_ms":1790004630075,"observed_ms":1790004630063,"hash":"b9f5d196701e70b2f11b8e442860ca8b5138612a"},{"bid":0.32,"ask":0.33,"asks":[[0.33,915.72]],"received_ms":1790004630079,"observed_ms":1790004630069,"hash":"87958bbb1c6bd628be90557d770d85577dfe1a31"}],"intents":{"pair_fast":{"kind":"first","side":1,"qty":5.0,"participation":true,"max_cost":1.7773900000000002},"pair_250":{"kind":"first","side":1,"qty":5.0,"participation":true,"max_cost":1.7773900000000002},"pair_add_fast":{"kind":"first","side":1,"qty":5.0,"participation":true,"max_cost":1.7773900000000002},"pair_add_250":{"kind":"first","side":1,"qty":5.0,"participation":true,"max_cost":1.7773900000000002}},"decision_ms":1790004630081,"feature_cutoff_ms":1790004630079,"request_ms":1790004630038,"inventory":{"pair_fast":{"qty":[0.0,0.0],"cash":0.0,"lots":[[],[]],"floor":0.0},"pair_250":{"qty":[0.0,0.0],"cash":0.0,"lots":[[],[]],"floor":0.0},"pair_add_fast":{"qty":[0.0,0.0],"cash":0.0,"lots":[[],[]],"floor":0.0},"pair_add_250":{"qty":[0.0,0.0],"cash":0.0,"lots":[[],[]],"floor":0.0}}}
{"kind":"decision","recorded_ms":1790004850052,"S":1790004600,"age":250,"signal":{"rsi14":29.135411163936922,"volume_ratio":0.9503498898268951,"taker_buy_fraction":0.45345854496614807,"volume5":135.47836,"return1":2.1573380520784475,"return5":8.816794964053011,"return15":-34.696701903964815,"bollinger_z":-0.6580180863481199,"bar_close_ms":1790004839999,"ref":85824.94072169792,"reference_received_ms":1790004601962,"spot":85887.24957565851,"twap":85872.58256290504,"sigma":6.049162780144959,"spot_z":1.457426780765025,"twap_z":1.1143600122082806,"momentum":0.3289271193011064,"decision_ms":1790004850050,"momentum30":0.1805132667610938,"momentum60":1.1696824220293058,"spot_twap_gap":0.31301905292452675,"range60":1.4664710334993667,"final_mean":85888.14609074757,"final_z":3.0758654823281697,"final_up_prob":0.9989505374262928,"final_drift_up_prob":0.9998973936528783,"final_known_seconds":10,"final_sd":20.548807941306002,"final_drift_shift":13.08231773506011},"entry_side":null,"context_gap":null,"book_errors":[null,null],"books":[{"bid":0.99,"ask":null,"asks":[],"received_ms":1790004850050,"observed_ms":1790004850036,"hash":"292c2f593799177d037efa7ca30d0569647d210a"},{"bid":null,"ask":0.01,"asks":[[0.01,3677.31]],"received_ms":1790004850044,"observed_ms":1790004850031,"hash":"b2304d2c87482d03ad107495ac6fd5e36e6d5ec6"}],"intents":{"pair_fast":null,"pair_250":null,"pair_add_fast":{"kind":"complete","side":1,"qty":5.0,"max_cost":2.3625299999999996},"pair_add_250":{"kind":"complete","side":1,"qty":5.0,"max_cost":2.3625299999999996}},"decision_ms":1790004850051,"feature_cutoff_ms":1790004850050,"request_ms":1790004850011,"inventory":{"pair_fast":{"qty":[15.0,15.0],"cash":13.447610000000001,"lots":[[],[]],"floor":1.552389999999999},"pair_250":{"qty":[15.0,15.0],"cash":13.24685,"lots":[[],[]],"floor":1.7531499999999998},"pair_add_fast":{"qty":[20.0,15.0],"cash":14.941670000000002,"lots":[[[5.0,0.5074940000000001]],[]],"floor":0.058329999999997995},"pair_add_250":{"qty":[20.0,15.0],"cash":14.740910000000001,"lots":[[[5.0,0.5074940000000001]],[]],"floor":0.2590899999999987}}}
{"kind":"execution","recorded_ms":1790004850083,"S":1790004600,"age":250,"speed":"fast","books":[{"bid":0.99,"ask":null,"asks":[],"received_ms":1790004850083,"observed_ms":1790004850071,"hash":"2478ce705e5eb25fc70fc4b00bc9eda51fabbf6b"},{"bid":null,"ask":0.01,"asks":[[0.01,3715.96]],"received_ms":1790004850078,"observed_ms":1790004850069,"hash":"b47d6fe0514c553127466afd7b3b3f78d0ad7147"}],"book_errors":[null,null],"fills":{"pair_add_fast":{"kind":"complete","side":1,"qty":5.0,"cost":0.053470000000000004,"fee":0.00347,"age":250.083}},"rejected":{},"decision_ms":1790004850051,"request_ms":1790004850052,"execution_ms":1790004850083,"delay_ms":32}
{"kind":"execution","recorded_ms":1790004850341,"S":1790004600,"age":250,"speed":"250","books":[{"bid":0.99,"ask":null,"asks":[],"received_ms":1790004850341,"observed_ms":1790004850325,"hash":"72a1725ce16aab83a7135386fcd196c90c9df917"},{"bid":null,"ask":0.01,"asks":[[0.01,3620.05]],"received_ms":1790004850327,"observed_ms":1790004850304,"hash":"a730f8aebfde3ed5ca699a154ffd7a6a88f84be9"}],"book_errors":[null,null],"fills":{"pair_add_250":{"kind":"complete","side":1,"qty":5.0,"cost":0.053470000000000004,"fee":0.00347,"age":250.341}},"rejected":{},"decision_ms":1790004850051,"request_ms":1790004850302,"execution_ms":1790004850341,"delay_ms":290}
{"kind":"decision","recorded_ms":1790004860055,"S":1790004600,"age":260,"signal":{"rsi14":29.135411163936922,"volume_ratio":0.9503498898268951,"taker_buy_fraction":0.45345854496614807,"volume5":135.47836,"return1":2.1573380520784475,"return5":8.816794964053011,"return15":-34.696701903964815,"bollinger_z":-0.6580180863481199,"bar_close_ms":1790004839999,"ref":85824.94072169792,"reference_received_ms":1790004601962,"spot":85879.39701883498,"twap":85882.45650880657,"sigma":5.880214320217483,"spot_z":1.4652721748099156,"twap_z":1.5475948034161877,"momentum":-1.051497360276398,"decision_ms":1790004860054,"momentum30":-0.09568616027890392,"momentum60":0.4182345921747176,"spot_twap_gap":-0.06717075865263747,"range60":0.9015781277036591,"final_mean":85884.10526232199,"final_z":4.141620208515903,"final_up_prob":0.9999827569474791,"final_drift_up_prob":0.9898728418849566,"final_known_seconds":20,"final_sd":14.285361198117256,"final_drift_shift":-25.99960162417268},"entry_side":null,"context_gap":null,"book_errors":[null,null],"books":[{"bid":0.99,"ask":null,"asks":[],"received_ms":1790004860053,"observed_ms":1790004860041,"hash":"e1e1474a9766f352456672f0a25b20ffac4ac118"},{"bid":null,"ask":0.01,"asks":[[0.01,12880.85]],"received_ms":1790004860054,"observed_ms":1790004860041,"hash":"ea16dafb8e3d3396d4247468a17c1e6c837f6ec6"}],"intents":{"pair_fast":null,"pair_250":null,"pair_add_fast":null,"pair_add_250":null},"decision_ms":1790004860055,"feature_cutoff_ms":1790004860054,"request_ms":1790004860015,"inventory":{"pair_fast":{"qty":[15.0,15.0],"cash":13.447610000000001,"lots":[[],[]],"floor":1.552389999999999},"pair_250":{"qty":[15.0,15.0],"cash":13.24685,"lots":[[],[]],"floor":1.7531499999999998},"pair_add_fast":{"qty":[20.0,20.0],"cash":14.995140000000003,"lots":[[],[]],"floor":5.004859999999997},"pair_add_250":{"qty":[20.0,20.0],"cash":14.794380000000002,"lots":[[],[]],"floor":5.205619999999998}}}
{"kind":"decision","recorded_ms":1790004870063,"S":1790004600,"age":270,"signal":{"rsi14":29.135411163936922,"volume_ratio":0.9503498898268951,"taker_buy_fraction":0.45345854496614807,"volume5":135.47836,"return1":2.1573380520784475,"return5":8.816794964053011,"return15":-34.696701903964815,"bollinger_z":-0.6580180863481199,"bar_close_ms":1790004839999,"ref":85824.94072169792,"reference_received_ms":1790004601962,"spot":85850.35541453536,"twap":85884.25982967846,"sigma":5.171138885810096,"spot_z":0.8982294111286778,"twap_z":2.0965103836134906,"momentum":-1.7951894170555724,"decision_ms":1790004870062,"momentum30":-1.080448286622204,"momentum60":-0.7944373672387919,"spot_twap_gap":-0.8464365917048916,"range60":1.2746551036578169,"final_mean":85867.06061643898,"final_z":5.167479679593637,"final_up_prob":0.9999998813641231,"final_drift_up_prob":0.9933843002359652,"final_known_seconds":30,"final_sd":8.150955079202488,"final_drift_shift":-21.92607031416354},"entry_side":null,"context_gap":null,"book_errors":[null,null],"books":[{"bid":0.99,"ask":null,"asks":[],"received_ms":1790004870061,"observed_ms":1790004870038,"hash":"e2f231539605e8a545fab9e8ee898b8b6b33e5c5"},{"bid":null,"ask":0.01,"asks":[[0.01,13142.68]],"received_ms":1790004870058,"observed_ms":1790004870038,"hash":"15898d5e8f8e72b07e5361cb33a7c2cf98badc99"}],"intents":{"pair_fast":null,"pair_250":null,"pair_add_fast":null,"pair_add_250":null},"decision_ms":1790004870063,"feature_cutoff_ms":1790004870062,"request_ms":1790004870028,"inventory":{"pair_fast":{"qty":[15.0,15.0],"cash":13.447610000000001,"lots":[[],[]],"floor":1.552389999999999},"pair_250":{"qty":[15.0,15.0],"cash":13.24685,"lots":[[],[]],"floor":1.7531499999999998},"pair_add_fast":{"qty":[20.0,20.0],"cash":14.995140000000003,"lots":[[],[]],"floor":5.004859999999997},"pair_add_250":{"qty":[20.0,20.0],"cash":14.794380000000002,"lots":[[],[]],"floor":5.205619999999998}}}
{"kind":"decision","recorded_ms":1790004880073,"S":1790004600,"age":280,"signal":{"rsi14":29.135411163936922,"volume_ratio":0.9503498898268951,"taker_buy_fraction":0.45345854496614807,"volume5":135.47836,"return1":2.1573380520784475,"return5":8.816794964053011,"return15":-34.696701903964815,"bollinger_z":-0.6580180863481199,"bar_close_ms":1790004839999,"ref":85824.94072169792,"reference_received_ms":1790004601962,"spot":85879.68260765234,"twap":85880.11686989958,"sigma":6.324926891648569,"spot_z":1.938797221226262,"twap_z":1.9541775177494454,"momentum":1.4995084771734386,"decision_ms":1790004880072,"momentum30":-0.5561539057160281,"momentum60":-0.03237400196878181,"spot_twap_gap":-0.008863820247671676,"range60":1.055701677031139,"final_mean":85879.93871115771,"final_z":10.157986008592788,"final_up_prob":1.0,"final_drift_up_prob":1.0,"final_known_seconds":40,"final_sd":5.414261194420738,"final_drift_shift":9.925459397454715},"entry_side":null,"context_gap":null,"book_errors":[null,null],"books":[{"bid":0.99,"ask":null,"asks":[],"received_ms":1790004880072,"observed_ms":1790004880062,"hash":"44d83bc982ee2531694346d55f6f55244a56c50a"},{"bid":null,"ask":0.01,"asks":[[0.01,33382.07]],"received_ms":1790004880068,"observed_ms":1790004880056,"hash":"07c673d88c691628ee6d9bfa5dc0caa49bc18088"}],"intents":{"pair_fast":null,"pair_250":null,"pair_add_fast":null,"pair_add_250":null},"decision_ms":1790004880073,"feature_cutoff_ms":1790004880072,"request_ms":1790004880034,"inventory":{"pair_fast":{"qty":[15.0,15.0],"cash":13.447610000000001,"lots":[[],[]],"floor":1.552389999999999},"pair_250":{"qty":[15.0,15.0],"cash":13.24685,"lots":[[],[]],"floor":1.7531499999999998},"pair_add_fast":{"qty":[20.0,20.0],"cash":14.995140000000003,"lots":[[],[]],"floor":5.004859999999997},"pair_add_250":{"qty":[20.0,20.0],"cash":14.794380000000002,"lots":[[],[]],"floor":5.205619999999998}}}
{"kind":"decision","recorded_ms":1790004890076,"S":1790004600,"age":290,"signal":{"rsi14":29.135411163936922,"volume_ratio":0.9503498898268951,"taker_buy_fraction":0.45345854496614807,"volume5":135.47836,"return1":2.1573380520784475,"return5":8.816794964053011,"return15":-34.696701903964815,"bollinger_z":-0.6580180863481199,"bar_close_ms":1790004839999,"ref":85824.94072169792,"reference_received_ms":1790004601962,"spot":85865.36863020646,"twap":85879.72409184498,"sigma":6.460729951275162,"spot_z":1.9862523724194796,"twap_z":2.691546581014682,"momentum":-0.6733111216493571,"decision_ms":1790004890075,"momentum30":-0.4053129112824242,"momentum60":-0.34189858714206045,"spot_twap_gap":-0.2868533652411017,"range60":1.0335110702614723,"final_mean":85876.14170325657,"final_z":26.33982019198395,"final_up_prob":1.0,"final_drift_up_prob":1.0,"final_known_seconds":50,"final_sd":1.943862227815507,"final_drift_shift":-1.1292163491019866},"entry_side":null,"context_gap":null,"book_errors":[null,null],"books":[{"bid":0.99,"ask":null,"asks":[],"received_ms":1790004890073,"observed_ms":1790004890021,"hash":"564f03bbceca6e7189e9d1dac76f67c89f71d57c"},{"bid":null,"ask":0.01,"asks":[[0.01,44390.5]],"received_ms":1790004890074,"observed_ms":1790004890021,"hash":"3df8dde26f0fb3d8997ca89fa5c55d1faea1278b"}],"intents":{"pair_fast":null,"pair_250":null,"pair_add_fast":null,"pair_add_250":null},"decision_ms":1790004890076,"feature_cutoff_ms":1790004890075,"request_ms":1790004890047,"inventory":{"pair_fast":{"qty":[15.0,15.0],"cash":13.447610000000001,"lots":[[],[]],"floor":1.552389999999999},"pair_250":{"qty":[15.0,15.0],"cash":13.24685,"lots":[[],[]],"floor":1.7531499999999998},"pair_add_fast":{"qty":[20.0,20.0],"cash":14.995140000000003,"lots":[[],[]],"floor":5.004859999999997},"pair_add_250":{"qty":[20.0,20.0],"cash":14.794380000000002,"lots":[[],[]],"floor":5.205619999999998}}}
{"kind":"decision","recorded_ms":1790004930074,"S":1790004900,"age":30,"signal":{"rsi14":31.705213942169113,"volume_ratio":0.4115174527179123,"taker_buy_fraction":0.46649594208055106,"volume5":132.37695,"return1":-1.7187146483039117,"return5":3.2767364636374143,"return15":-29.313633168303813,"bollinger_z":-0.6918546437548395,"bar_close_ms":1790004899999,"ref":85876.71585863364,"reference_received_ms":1790004901255,"spot":85851.680940395,"twap":85864.56731286844,"sigma":6.514363348177487,"spot_z":-0.23391120975971447,"twap_z":-0.11350870051468293,"momentum":-1.302417780074852,"decision_ms":1790004930073,"momentum30":-0.4102791767240094,"momentum60":0.03944238185753578,"spot_twap_gap":-0.255377762006588,"range60":0.5929549680850191,"final_mean":85851.680940395,"final_z":-0.25344236502538,"final_up_prob":0.39996319672440245,"final_drift_up_prob":6.428302334882119e-12,"final_known_seconds":0,"final_sd":98.77953212808235,"final_drift_shift":-643.7265453643749},"entry_side":null,"context_gap":null,"book_errors":[null,null],"books":[{"bid":0.33,"ask":0.34,"asks":[[0.34,752.81]],"received_ms":1790004930073,"observed_ms":1790004930052,"hash":"71bafb1e403d4821e1c1e0b93b366c43effe32ff"},{"bid":0.66,"ask":0.67,"asks":[[0.67,5.0]],"received_ms":1790004930067,"observed_ms":1790004930058,"hash":"8d4e4ea19ac2d301d8053d2714cb5c16000bf87a"}],"intents":{"pair_fast":{"kind":"first","side":0,"qty":5.0,"participation":true,"max_cost":1.8285400000000003},"pair_250":{"kind":"first","side":0,"qty":5.0,"participation":true,"max_cost":1.8285400000000003},"pair_add_fast":{"kind":"first","side":0,"qty":5.0,"participation":true,"max_cost":1.8285400000000003},"pair_add_250":{"kind":"first","side":0,"qty":5.0,"participation":true,"max_cost":1.8285400000000003}},"decision_ms":1790004930074,"feature_cutoff_ms":1790004930073,"request_ms":1790004930031,"inventory":{"pair_fast":{"qty":[0.0,0.0],"cash":0.0,"lots":[[],[]],"floor":0.0},"pair_250":{"qty":[0.0,0.0],"cash":0.0,"lots":[[],[]],"floor":0.0},"pair_add_fast":{"qty":[0.0,0.0],"cash":0.0,"lots":[[],[]],"floor":0.0},"pair_add_250":{"qty":[0.0,0.0],"cash":0.0,"lots":[[],[]],"floor":0.0}}}
{"kind":"decision","recorded_ms":1790004940062,"S":1790004900,"age":40,"signal":{"rsi14":31.705213942169113,"volume_ratio":0.4115174527179123,"taker_buy_fraction":0.46649594208055106,"volume5":132.37695,"return1":-1.7187146483039117,"return5":3.2767364636374143,"return15":-29.313633168303813,"bollinger_z":-0.6918546437548395,"bar_close_ms":1790004899999,"ref":85876.71585863364,"reference_received_ms":1790004901255,"spot":85823.21802996329,"twap":85860.72527770992,"sigma":7.460444440091785,"spot_z":-0.4447702531351645,"twap_z":-0.13294249321868715,"momentum":-0.543189561659519,"decision_ms":1790004940061,"momentum30":-0.7275115378544329,"momentum60":-0.9674399986299013,"spot_twap_gap":-0.6490450939899165,"range60":1.1226813037555747,"final_mean":85823.21802996329,"final_z":-0.4835265571426383,"final_up_prob":0.31436095392365726,"final_drift_up_prob":0.0008253880884668829,"final_known_seconds":0,"final_sd":110.64093146506065,"final_drift_shift":-294.6651358683163},"entry_side":null,"context_gap":null,"book_errors":[null,null],"books":[{"bid":0.33,"ask":0.34,"asks":[[0.34,466.81]],"received_ms":1790004940061,"observed_ms":1790004940052,"hash":"29a7ac9ea374c79f25f4fc20a7ae11110ca1f6c6"},{"bid":0.66,"ask":0.67,"asks":[[0.67,881.26]],"received_ms":1790004940058,"observed_ms":1790004940049,"hash":"a7d352ab7ef38844a3786197c899de5665879911"}],"intents":{"pair_fast":null,"pair_250":null,"pair_add_fast":null,"pair_add_250":null},"decision_ms":1790004940062,"feature_cutoff_ms":1790004940061,"request_ms":1790004940030,"inventory":{"pair_fast":{"qty":[5.0,0.0],"cash":1.7785400000000002,"lots":[[[5.0,0.355708]],[]],"floor":-1.7785400000000002},"pair_250":{"qty":[5.0,0.0],"cash":1.7273900000000002,"lots":[[[5.0,0.34547800000000006]],[]],"floor":-1.7273900000000002},"pair_add_fast":{"qty":[5.0,0.0],"cash":1.7785400000000002,"lots":[[[5.0,0.355708]],[]],"floor":-1.7785400000000002},"pair_add_250":{"qty":[5.0,0.0],"cash":1.7273900000000002,"lots":[[[5.0,0.34547800000000006]],[]],"floor":-1.7273900000000002}}}
{"kind":"decision","recorded_ms":1790004950077,"S":1790004900,"age":50,"signal":{"rsi14":31.705213942169113,"volume_ratio":0.4115174527179123,"taker_buy_fraction":0.46649594208055106,"volume5":132.37695,"return1":-1.7187146483039117,"return5":3.2767364636374143,"return15":-29.313633168303813,"bollinger_z":-0.6918546437548395,"bar_close_ms":1790004899999,"ref":85876.71585863364,"reference_received_ms":1790004901255,"spot":85817.7145962552,"twap":85850.66044779019,"sigma":7.402302352427623,"spot_z":-0.5041856747479747,"twap_z":-0.22265226822917802,"momentum":-0.23945992171642588,"decision_ms":1790004950076,"momentum30":-1.4995147185093955,"momentum60":-0.8220606915569714,"spot_twap_gap":-0.5745903019833913,"range60":1.120795357386441,"final_mean":85817.7145962552,"final_z":-0.5501276037264724,"final_up_prob":0.2911159274101732,"final_drift_up_prob":0.044609106210084015,"final_known_seconds":0,"final_sd":107.25013974717439,"final_drift_shift":-123.27422540948369},"entry_side":null,"context_gap":null,"book_errors":[null,null],"books":[{"bid":0.3,"ask":0.31,"asks":[[0.31,374.0]],"received_ms":1790004950069,"observed_ms":1790004950060,"hash":"74f0ccda76ea57401afe8a0c4d4bf358bf54851b"},{"bid":0.69,"ask":0.7,"asks":[[0.7,1467.17]],"received_ms":1790004950076,"observed_ms":1790004950062,"hash":"a4c7574c1c9887ffdf2e6d562573a7507eb4bd7c"}],"intents":{"pair_fast":null,"pair_250":null,"pair_add_fast":null,"pair_add_250":null},"decision_ms":1790004950077,"feature_cutoff_ms":1790004950076,"request_ms":1790004950036,"inventory":{"pair_fast":{"qty":[5.0,0.0],"cash":1.7785400000000002,"lots":[[[5.0,0.355708]],[]],"floor":-1.7785400000000002},"pair_250":{"qty":[5.0,0.0],"cash":1.7273900000000002,"lots":[[[5.0,0.34547800000000006]],[]],"floor":-1.7273900000000002},"pair_add_fast":{"qty":[5.0,0.0],"cash":1.7785400000000002,"lots":[[[5.0,0.355708]],[]],"floor":-1.7785400000000002},"pair_add_250":{"qty":[5.0,0.0],"cash":1.7273900000000002,"lots":[[[5.0,0.34547800000000006]],[]],"floor":-1.7273900000000002}}}
{"kind":"decision","recorded_ms":1790004960037,"S":1790004900,"age":60,"signal":{"rsi14":31.705213942169113,"volume_ratio":0.4115174527179123,"taker_buy_fraction":0.46649594208055106,"volume5":132.37695,"return1":-1.7187146483039117,"return5":3.2767364636374143,"return15":-29.313633168303813,"bollinger_z":-0.6918546437548395,"bar_close_ms":1790004899999,"ref":85876.71585863364,"reference_received_ms":1790004901255,"spot":85814.2001598005,"twap":85843.08608523807,"sigma":7.460571867212003,"spot_z":-0.5409324322802805,"twap_z":-0.29098987069560284,"momentum":-0.02759407171549585,"decision_ms":1790004960035,"momentum30":-0.5342894789807797,"momentum60":-0.9018930154699856,"spot_twap_gap":-0.49984867179406306,"range60":1.1171415338207982,"final_mean":85814.2001598005,"final_z":-0.5925704334889003,"final_up_prob":0.27673433550217463,"final_drift_up_prob":0.23510579074659171,"final_known_seconds":0,"final_sd":105.49918676344944,"final_drift_shift":-13.668939240305372},"entry_side":null,"context_gap":null,"book_errors":[null,null],"books":[{"bid":0.32,"ask":0.33,"asks":[[0.33,110.93]],"received_ms":1790004960034,"observed_ms":1790004960025,"hash":"3c267b40f52f250b7f202e521380b6bc6d957247"},{"bid":0.67,"ask":0.68,"asks":[[0.68,1214.03]],"received_ms":1790004960035,"observed_ms":1790004960026,"hash":"577c0d7fd3a53c39fbf4983f485fdf024331e3da"}],"intents":{"pair_fast":null,"pair_250":null,"pair_add_fast":null,"pair_add_250":null},"decision_ms":1790004960037,"feature_cutoff_ms":1790004960035,"request_ms":1790004960001,"inventory":{"pair_fast":{"qty":[5.0,0.0],"cash":1.7785400000000002,"lots":[[[5.0,0.355708]],[]],"floor":-1.7785400000000002},"pair_250":{"qty":[5.0,0.0],"cash":1.7273900000000002,"lots":[[[5.0,0.34547800000000006]],[]],"floor":-1.7273900000000002},"pair_add_fast":{"qty":[5.0,0.0],"cash":1.7785400000000002,"lots":[[[5.0,0.355708]],[]],"floor":-1.7785400000000002},"pair_add_250":{"qty":[5.0,0.0],"cash":1.7273900000000002,"lots":[[[5.0,0.34547800000000006]],[]],"floor":-1.7273900000000002}}}
{"kind":"decision","recorded_ms":1790004970079,"S":1790004900,"age":70,"signal":{"rsi14":32.334088954896465,"volume_ratio":3.4002836133040706,"taker_buy_fraction":0.4149373947116883,"volume5":189.361,"return1":-6.683696732154766,"return5":-5.591886439610212,"return15":-28.933555361947654,"bollinger_z":-1.0414852384198645,"bar_close_ms":1790004959999,"ref":85876.71585863364,"reference_received_ms":1790004901255,"spot":85868.89108452685,"twap":85836.44507639922,"sigma":8.89570366140179,"spot_z":-0.0580096563798784,"twap_z":-0.29855101344596185,"momentum":1.8837275353351512,"decision_ms":1790004970077,"momentum30":0.9352965250904197,"momentum60":0.23140405815217371,"spot_twap_gap":0.4708746825522224,"range60":0.93691460688835,"final_mean":85868.89108452685,"final_z":-0.06382674847952428,"final_up_prob":0.47455408973592333,"final_drift_up_prob":1.0,"final_known_seconds":0,"final_sd":122.59396402278027,"final_drift_shift":1059.4028902495745},"entry_side":null,"context_gap":null,"book_errors":[null,null],"books":[{"bid":0.52,"ask":0.53,"asks":[[0.53,5.0]],"received_ms":1790004970077,"observed_ms":1790004970065,"hash":"f50427268907c46ac6c45066a06b09fe7c0535e4"},{"bid":0.47,"ask":0.48,"asks":[[0.48,1054.31]],"received_ms":1790004970074,"observed_ms":1790004970066,"hash":"5a4d4d792abee57eafe15881b976aa5652154c62"}],"intents":{"pair_fast":{"kind":"complete","side":1,"qty":5.0,"max_cost":3.1214600000000003},"pair_250":{"kind":"complete","side":1,"qty":5.0,"max_cost":3.17261},"pair_add_fast":{"kind":"complete","side":1,"qty":5.0,"max_cost":3.1214600000000003},"pair_add_250":{"kind":"complete","side":1,"qty":5.0,"max_cost":3.17261}},"decision_ms":1790004970079,"feature_cutoff_ms":1790004970077,"request_ms":1790004970039,"inventory":{"pair_fast":{"qty":[5.0,0.0],"cash":1.7785400000000002,"lots":[[[5.0,0.355708]],[]],"floor":-1.7785400000000002},"pair_250":{"qty":[5.0,0.0],"cash":1.7273900000000002,"lots":[[[5.0,0.34547800000000006]],[]],"floor":-1.7273900000000002},"pair_add_fast":{"qty":[5.0,0.0],"cash":1.7785400000000002,"lots":[[[5.0,0.355708]],[]],"floor":-1.7785400000000002},"pair_add_250":{"qty":[5.0,0.0],"cash":1.7273900000000002,"lots":[[[5.0,0.34547800000000006]],[]],"floor":-1.7273900000000002}}}
{"kind":"decision","recorded_ms":1790005160060,"S":1790004900,"age":260,"signal":{"rsi14":55.65749745608648,"volume_ratio":0.24819678443184592,"taker_buy_fraction":0.51996128859806,"volume5":161.01716,"return1":12.50009890239376,"return5":5.867820791657521,"return15":-2.86235160568515,"bollinger_z":0.43534543056722935,"bar_close_ms":1790005139999,"ref":85876.71585863364,"reference_received_ms":1790004901255,"spot":85924.10593568262,"twap":85918.34160924079,"sigma":3.8324973863664265,"spot_z":1.9565731097770125,"twap_z":1.7185839184869176,"momentum":-0.033913768511526846,"decision_ms":1790005160059,"momentum30":-0.3830753072891693,"momentum60":1.112336606903379,"spot_twap_gap":0.19417399901107651,"range60":1.450048723122148,"final_mean":85924.64275747754,"final_z":5.148502618906547,"final_up_prob":0.9999998687129396,"final_drift_up_prob":0.9999998207845971,"final_known_seconds":20,"final_sd":9.308900546714431,"final_drift_shift":-0.5464048436778777},"entry_side":null,"context_gap":null,"book_errors":[null,null],"books":[{"bid":0.99,"ask":null,"asks":[],"received_ms":1790005160058,"observed_ms":1790005160042,"hash":"b5ab2012bec5f0d72d05661ec882372cc57de7c2"},{"bid":null,"ask":0.01,"asks":[[0.01,8183.53]],"received_ms":1790005160059,"observed_ms":1790005160050,"hash":"fe7cc3a451434debec8c4471540e8e4dbe9ae975"}],"intents":{"pair_fast":null,"pair_250":null,"pair_add_fast":null,"pair_add_250":null},"decision_ms":1790005160060,"feature_cutoff_ms":1790005160059,"request_ms":1790005160029,"inventory":{"pair_fast":{"qty":[10.0,10.0],"cash":8.28163,"lots":[[],[]],"floor":1.7183700000000002},"pair_250":{"qty":[5.0,5.0],"cash":4.16458,"lots":[[],[]],"floor":0.83542},"pair_add_fast":{"qty":[10.0,10.0],"cash":8.28163,"lots":[[],[]],"floor":1.7183700000000002},"pair_add_250":{"qty":[5.0,5.0],"cash":4.16458,"lots":[[],[]],"floor":0.83542}}}
{"kind":"decision","recorded_ms":1790005170069,"S":1790004900,"age":270,"signal":{"rsi14":55.65749745608648,"volume_ratio":0.24819678443184592,"taker_buy_fraction":0.51996128859806,"volume5":161.01716,"return1":12.50009890239376,"return5":5.867820791657521,"return15":-2.86235160568515,"bollinger_z":0.43534543056722935,"bar_close_ms":1790005139999,"ref":85876.71585863364,"reference_received_ms":1790004901255,"spot":85926.89301193401,"twap":85923.34912086763,"sigma":3.459862092770464,"spot_z":2.650814653223704,"twap_z":2.463594020918124,"momentum":0.19391996354843447,"decision_ms":1790005170068,"momentum30":-0.2542304940859728,"momentum60":0.7081702059621786,"spot_twap_gap":0.13223485708232738,"range60":1.2095963452742813,"final_mean":85926.69878659178,"final_z":9.167927690138798,"final_up_prob":1.0,"final_drift_up_prob":1.0,"final_known_seconds":30,"final_sd":5.45193304828248,"final_drift_shift":1.58405965957015},"entry_side":null,"context_gap":null,"book_errors":[null,null],"books":[{"bid":0.99,"ask":null,"asks":[],"received_ms":1790005170065,"observed_ms":1790005170055,"hash":"eff6c4d086bd8ba446b65502feecb743a3bfae37"},{"bid":null,"ask":0.01,"asks":[[0.01,23799.23]],"received_ms":1790005170068,"observed_ms":1790005170055,"hash":"7a61273431abfe2463fe4f2aa9d006b582e1389a"}],"intents":{"pair_fast":null,"pair_250":null,"pair_add_fast":null,"pair_add_250":null},"decision_ms":1790005170069,"feature_cutoff_ms":1790005170068,"request_ms":1790005170035,"inventory":{"pair_fast":{"qty":[10.0,10.0],"cash":8.28163,"lots":[[],[]],"floor":1.7183700000000002},"pair_250":{"qty":[5.0,5.0],"cash":4.16458,"lots":[[],[]],"floor":0.83542},"pair_add_fast":{"qty":[10.0,10.0],"cash":8.28163,"lots":[[],[]],"floor":1.7183700000000002},"pair_add_250":{"qty":[5.0,5.0],"cash":4.16458,"lots":[[],[]],"floor":0.83542}}}
{"kind":"decision","recorded_ms":1790005180081,"S":1790004900,"age":280,"signal":{"rsi14":55.65749745608648,"volume_ratio":0.24819678443184592,"taker_buy_fraction":0.51996128859806,"volume5":161.01716,"return1":12.50009890239376,"return5":5.867820791657521,"return15":-2.86235160568515,"bollinger_z":0.43534543056722935,"bar_close_ms":1790005139999,"ref":85876.71585863364,"reference_received_ms":1790004901255,"spot":85947.18263518618,"twap":85927.0064259048,"sigma":2.9897513491168137,"spot_z":5.280860157469604,"twap_z":3.768832150293604,"momentum":2.270321433442304,"decision_ms":1790005180080,"momentum30":1.3841180649254208,"momentum60":1.0727491989543096,"spot_twap_gap":0.8712220896395975,"range60":1.0727491989543096,"final_mean":85934.82411898536,"final_z":22.718553556563922,"final_up_prob":1.0,"final_drift_up_prob":1.0,"final_known_seconds":40,"final_sd":2.557744717639586,"final_drift_shift":7.097736056464102},"entry_side":null,"context_gap":null,"book_errors":[null,null],"books":[{"bid":0.99,"ask":null,"asks":[],"received_ms":1790005180071,"observed_ms":1790005180047,"hash":"88888d5ce3db2653914078fe2838454c7974a317"},{"bid":null,"ask":0.01,"asks":[[0.01,47943.26]],"received_ms":1790005180080,"observed_ms":1790005180069,"hash":"79b638836c79f45baa06be808f333f728cc8a0a4"}],"intents":{"pair_fast":null,"pair_250":null,"pair_add_fast":null,"pair_add_250":null},"decision_ms":1790005180081,"feature_cutoff_ms":1790005180080,"request_ms":1790005180044,"inventory":{"pair_fast":{"qty":[10.0,10.0],"cash":8.28163,"lots":[[],[]],"floor":1.7183700000000002},"pair_250":{"qty":[5.0,5.0],"cash":4.16458,"lots":[[],[]],"floor":0.83542},"pair_add_fast":{"qty":[10.0,10.0],"cash":8.28163,"lots":[[],[]],"floor":1.7183700000000002},"pair_add_250":{"qty":[5.0,5.0],"cash":4.16458,"lots":[[],[]],"floor":0.83542}}}
{"kind":"decision","recorded_ms":1790005190039,"S":1790004900,"age":290,"signal":{"rsi14":55.65749745608648,"volume_ratio":0.24819678443184592,"taker_buy_fraction":0.51996128859806,"volume5":161.01716,"return1":12.50009890239376,"return5":5.867820791657521,"return15":-2.86235160568515,"bollinger_z":0.43534543056722935,"bar_close_ms":1790005139999,"ref":85876.71585863364,"reference_received_ms":1790004901255,"spot":85951.41332142251,"twap":85931.20281337592,"sigma":2.5921183861478316,"spot_z":9.13014661557617,"twap_z":6.659849837728659,"momentum":0.6787145001705286,"decision_ms":1790005190038,"momentum30":1.876511828527235,"momentum60":0.9595395250761396,"spot_twap_gap":1.006576467869766,"range60":1.423415727123308,"final_mean":85935.73855781392,"final_z":75.25863074453981,"final_up_prob":1.0,"final_drift_up_prob":1.0,"final_known_seconds":50,"final_sd":0.784264855689786,"final_drift_shift":0.4601016382528651},"entry_side":null,"context_gap":null,"book_errors":[null,null],"books":[{"bid":0.99,"ask":null,"asks":[],"received_ms":1790005190038,"observed_ms":1790005190022,"hash":"f45d8baa4bec2c50c8eb726d4b0df52dc83f6341"},{"bid":null,"ask":0.01,"asks":[[0.01,58365.12]],"received_ms":1790005190038,"observed_ms":1790005190022,"hash":"ce94d791e9aacf605c4f642cc22f6aa05bacac69"}],"intents":{"pair_fast":null,"pair_250":null,"pair_add_fast":null,"pair_add_250":null},"decision_ms":1790005190039,"feature_cutoff_ms":1790005190038,"request_ms":1790005190008,"inventory":{"pair_fast":{"qty":[10.0,10.0],"cash":8.28163,"lots":[[],[]],"floor":1.7183700000000002},"pair_250":{"qty":[5.0,5.0],"cash":4.16458,"lots":[[],[]],"floor":0.83542},"pair_add_fast":{"qty":[10.0,10.0],"cash":8.28163,"lots":[[],[]],"floor":1.7183700000000002},"pair_add_250":{"qty":[5.0,5.0],"cash":4.16458,"lots":[[],[]],"floor":0.83542}}}
{"kind":"decision","recorded_ms":1790005230078,"S":1790005200,"age":30,"signal":{"rsi14":55.52097451600542,"volume_ratio":0.32618680008668677,"taker_buy_fraction":0.5135420653264665,"volume5":159.28368,"return1":3.7998980878264095,"return5":11.382247532130839,"return15":11.689310003874336,"bollinger_z":1.1304574211108929,"bar_close_ms":1790005199999,"ref":85936.67740243499,"reference_received_ms":1790005201488,"spot":85956.20630681464,"twap":85957.35824041913,"sigma":3.5528839011121645,"spot_z":0.33456223497116383,"twap_z":0.3542967512432249,"momentum":-0.7013193543589085,"decision_ms":1790005230077,"momentum30":-0.6497508123759783,"momentum60":1.107837077655797,"spot_twap_gap":-0.04185726103349886,"range60":1.935173211242001,"final_mean":85956.20630681464,"final_z":0.36249803275435816,"final_up_prob":0.6415100533248363,"final_drift_up_prob":0.0008258810614634182,"final_known_seconds":0,"final_sd":53.873132031269705,"final_drift_shift":-189.04653593999168},"entry_side":null,"context_gap":null,"book_errors":[null,null],"books":[{"bid":0.53,"ask":0.54,"asks":[[0.54,286.89]],"received_ms":1790005230063,"observed_ms":1790005230054,"hash":"89fd91a614ffadf9a3947c760b6026a0a34c7bc4"},{"bid":0.46,"ask":0.47,"asks":[[0.47,87.67]],"received_ms":1790005230077,"observed_ms":1790005230062,"hash":"775f6c948617150dd6ae78836b1f3779a770f5b0"}],"intents":{"pair_fast":{"kind":"first","side":1,"qty":5.0,"participation":true,"max_cost":2.4871899999999996},"pair_250":{"kind":"first","side":1,"qty":5.0,"participation":true,"max_cost":2.4871899999999996},"pair_add_fast":{"kind":"first","side":1,"qty":5.0,"participation":true,"max_cost":2.4871899999999996},"pair_add_250":{"kind":"first","side":1,"qty":5.0,"participation":true,"max_cost":2.4871899999999996}},"decision_ms":1790005230078,"feature_cutoff_ms":1790005230077,"request_ms":1790005230031,"inventory":{"pair_fast":{"qty":[0.0,0.0],"cash":0.0,"lots":[[],[]],"floor":0.0},"pair_250":{"qty":[0.0,0.0],"cash":0.0,"lots":[[],[]],"floor":0.0},"pair_add_fast":{"qty":[0.0,0.0],"cash":0.0,"lots":[[],[]],"floor":0.0},"pair_add_250":{"qty":[0.0,0.0],"cash":0.0,"lots":[[],[]],"floor":0.0}}}
