{"kind":"decision","recorded_ms":1789998630062,"S":1789998600,"age":30,"signal":{"rsi14":60.64447630628521,"volume_ratio":1.2823443209205578,"taker_buy_fraction":0.617519889589132,"volume5":311.65048,"return1":6.919094230644576,"return5":42.61586235122158,"return15":32.83994995126156,"bollinger_z":1.9786457235789676,"bar_close_ms":1789998599999,"ref":85346.42241923072,"reference_received_ms":1789998601650,"spot":85616.21730525668,"twap":85422.84269498654,"sigma":17.32087460403822,"spot_z":0.948049641836483,"twap_z":0.26853813327055126,"momentum":0.5030564318291454,"decision_ms":1789998630061,"momentum30":2.129066199459115,"momentum60":2.3104420393051557,"spot_twap_gap":1.4412987455437076,"range60":2.3104420393051557,"final_mean":85616.21730525668,"final_z":1.0272060691117062,"final_up_prob":0.8478382795495539,"final_drift_up_prob":0.9998032225725619,"final_known_seconds":0,"final_sd":262.64923284504505,"final_drift_shift":661.1307663583644},"entry_side":null,"context_gap":null,"book_errors":[null,null],"books":[{"bid":0.83,"ask":0.84,"asks":[[0.84,1404.52]],"received_ms":1789998630061,"observed_ms":1789998630049,"hash":"bcec46e1d3265da10231fd61a9b589fdeb78fa1a"},{"bid":0.16,"ask":0.17,"asks":[[0.17,148.99]],"received_ms":1789998630059,"observed_ms":1789998630049,"hash":"4478f52577ec552d74d0511652e0a499c23c740a"}],"intents":{"pair_fast":null,"pair_250":null,"pair_add_fast":null,"pair_add_250":null},"decision_ms":1789998630062,"feature_cutoff_ms":1789998630061,"request_ms":1789998630027,"inventory":{"pair_fast":{"qty":[0.0,0.0],"cash":0.0,"lots":[[],[]],"floor":0.0},"pair_250":{"qty":[0.0,0.0],"cash":0.0,"lots":[[],[]],"floor":0.0},"pair_add_fast":{"qty":[0.0,0.0],"cash":0.0,"lots":[[],[]],"floor":0.0},"pair_add_250":{"qty":[0.0,0.0],"cash":0.0,"lots":[[],[]],"floor":0.0}}}
{"kind":"decision","recorded_ms":1789998640067,"S":1789998600,"age":40,"signal":{},"entry_side":null,"context_gap":"incomplete or stale context","book_errors":[null,null],"books":[{"bid":0.82,"ask":0.83,"asks":[[0.83,1665.82]],"received_ms":1789998640062,"observed_ms":1789998640043,"hash":"8ce453af1555bc89d1d5c2d061361afd0e30e202"},{"bid":0.17,"ask":0.18,"asks":[[0.18,255.75]],"received_ms":1789998640065,"observed_ms":1789998640043,"hash":"c067015c8f9923d7be6964ea79352c3579d03bf6"}],"intents":{"pair_fast":null,"pair_250":null,"pair_add_fast":null,"pair_add_250":null},"decision_ms":1789998640067,"feature_cutoff_ms":1789998640066,"request_ms":1789998640035,"inventory":{"pair_fast":{"qty":[0.0,0.0],"cash":0.0,"lots":[[],[]],"floor":0.0},"pair_250":{"qty":[0.0,0.0],"cash":0.0,"lots":[[],[]],"floor":0.0},"pair_add_fast":{"qty":[0.0,0.0],"cash":0.0,"lots":[[],[]],"floor":0.0},"pair_add_250":{"qty":[0.0,0.0],"cash":0.0,"lots":[[],[]],"floor":0.0}}}
{"kind":"decision","recorded_ms":1789998650083,"S":1789998600,"age":50,"signal":{"rsi14":60.64447630628521,"volume_ratio":1.2823443209205578,"taker_buy_fraction":0.617519889589132,"volume5":311.65048,"return1":6.919094230644576,"return5":42.61586235122158,"return15":32.83994995126156,"bollinger_z":1.9786457235789676,"bar_close_ms":1789998599999,"ref":85346.42241923072,"reference_received_ms":1789998601650,"spot":85600.3151196339,"twap":85501.09204731329,"sigma":17.308465485199317,"spot_z":0.9278822780337944,"twap_z":0.5652592871712759,"momentum":0.732324079296493,"decision_ms":1789998650082,"momentum30":0.12290761312389285,"momentum60":1.3982411313418739,"spot_twap_gap":0.740079677554103,"range60":1.6205663347637007,"final_mean":85600.3151196339,"final_z":1.0124342028934,"final_up_prob":0.8443347541578172,"final_drift_up_prob":0.9999970163817902,"final_known_seconds":0,"final_sd":250.7745191515613,"final_drift_shift":881.5006925875903},"entry_side":null,"context_gap":null,"book_errors":[null,null],"books":[{"bid":0.87,"ask":0.88,"asks":[[0.88,1111.98]],"received_ms":1789998650082,"observed_ms":1789998650070,"hash":"d3e3b0ed533e0e39e73685406a9c51a5bc634c93"},{"bid":0.12,"ask":0.13,"asks":[[0.13,21.53]],"received_ms":1789998650065,"observed_ms":1789998650056,"hash":"7305641f270fa8de11fe16887855fc9129c27325"}],"intents":{"pair_fast":null,"pair_250":null,"pair_add_fast":null,"pair_add_250":null},"decision_ms":1789998650083,"feature_cutoff_ms":1789998650082,"request_ms":1789998650041,"inventory":{"pair_fast":{"qty":[0.0,0.0],"cash":0.0,"lots":[[],[]],"floor":0.0},"pair_250":{"qty":[0.0,0.0],"cash":0.0,"lots":[[],[]],"floor":0.0},"pair_add_fast":{"qty":[0.0,0.0],"cash":0.0,"lots":[[],[]],"floor":0.0},"pair_add_250":{"qty":[0.0,0.0],"cash":0.0,"lots":[[],[]],"floor":0.0}}}
{"kind":"decision","recorded_ms":1789998660037,"S":1789998600,"age":60,"signal":{},"entry_side":null,"context_gap":"incomplete or stale context","book_errors":[null,null],"books":[{"bid":0.9,"ask":0.91,"asks":[[0.91,923.53]],"received_ms":1789998660036,"observed_ms":1789998660027,"hash":"462f78e3fa8393c63dd4512730f2959b53658548"},{"bid":0.09,"ask":0.1,"asks":[[0.1,182.41]],"received_ms":1789998660033,"observed_ms":1789998660024,"hash":"439044cce13e66be5388126826e90af137d61a8c"}],"intents":{"pair_fast":null,"pair_250":null,"pair_add_fast":null,"pair_add_250":null},"decision_ms":1789998660037,"feature_cutoff_ms":1789998660036,"request_ms":1789998660007,"inventory":{"pair_fast":{"qty":[0.0,0.0],"cash":0.0,"lots":[[],[]],"floor":0.0},"pair_250":{"qty":[0.0,0.0],"cash":0.0,"lots":[[],[]],"floor":0.0},"pair_add_fast":{"qty":[0.0,0.0],"cash":0.0,"lots":[[],[]],"floor":0.0},"pair_add_250":{"qty":[0.0,0.0],"cash":0.0,"lots":[[],[]],"floor":0.0}}}
{"kind":"decision","recorded_ms":1789998670084,"S":1789998600,"age":70,"signal":{},"entry_side":null,"context_gap":"incomplete or stale context","book_errors":[null,null],"books":[{"bid":0.93,"ask":0.94,"asks":[[0.94,672.12]],"received_ms":1789998670059,"observed_ms":1789998670050,"hash":"971f5409b3fa4c543c130d17548bb7c07ca6eed9"},{"bid":0.06,"ask":0.07,"asks":[[0.07,373.57]],"received_ms":1789998670083,"observed_ms":1789998670068,"hash":"7f030b7efde3e21a46e7b9543c5ce5d53569c371"}],"intents":{"pair_fast":null,"pair_250":null,"pair_add_fast":null,"pair_add_250":null},"decision_ms":1789998670084,"feature_cutoff_ms":1789998670083,"request_ms":1789998670033,"inventory":{"pair_fast":{"qty":[0.0,0.0],"cash":0.0,"lots":[[],[]],"floor":0.0},"pair_250":{"qty":[0.0,0.0],"cash":0.0,"lots":[[],[]],"floor":0.0},"pair_add_fast":{"qty":[0.0,0.0],"cash":0.0,"lots":[[],[]],"floor":0.0},"pair_add_250":{"qty":[0.0,0.0],"cash":0.0,"lots":[[],[]],"floor":0.0}}}
{"kind":"decision","recorded_ms":1789998680065,"S":1789998600,"age":80,"signal":{},"entry_side":null,"context_gap":"incomplete or stale context","book_errors":[null,null],"books":[{"bid":0.94,"ask":0.95,"asks":[[0.95,236.18]],"received_ms":1789998680064,"observed_ms":1789998680041,"hash":"14a1cd41694b2346532089916a79458d45f980e6"},{"bid":0.05,"ask":0.06,"asks":[[0.06,973.13]],"received_ms":1789998680055,"observed_ms":1789998680036,"hash":"055ffeb126073dcf5109b4064ae5587476743ad8"}],"intents":{"pair_fast":null,"pair_250":null,"pair_add_fast":null,"pair_add_250":null},"decision_ms":1789998680065,"feature_cutoff_ms":1789998680064,"request_ms":1789998680007,"inventory":{"pair_fast":{"qty":[0.0,0.0],"cash":0.0,"lots":[[],[]],"floor":0.0},"pair_250":{"qty":[0.0,0.0],"cash":0.0,"lots":[[],[]],"floor":0.0},"pair_add_fast":{"qty":[0.0,0.0],"cash":0.0,"lots":[[],[]],"floor":0.0},"pair_add_250":{"qty":[0.0,0.0],"cash":0.0,"lots":[[],[]],"floor":0.0}}}
{"kind":"decision","recorded_ms":1789998690077,"S":1789998600,"age":90,"signal":{},"entry_side":null,"context_gap":"incomplete or stale context","book_errors":[null,null],"books":[{"bid":0.95,"ask":0.96,"asks":[[0.96,2168.5]],"received_ms":1789998690076,"observed_ms":1789998690064,"hash":"4267a0304994f9d18fde55b9fe68250f827c3969"},{"bid":0.04,"ask":0.05,"asks":[[0.05,315.6]],"received_ms":1789998690071,"observed_ms":1789998690062,"hash":"029cf21988b83d69727d93bc3a57379c3a92074c"}],"intents":{"pair_fast":null,"pair_250":null,"pair_add_fast":null,"pair_add_250":null},"decision_ms":1789998690077,"feature_cutoff_ms":1789998690076,"request_ms":1789998690039,"inventory":{"pair_fast":{"qty":[0.0,0.0],"cash":0.0,"lots":[[],[]],"floor":0.0},"pair_250":{"qty":[0.0,0.0],"cash":0.0,"lots":[[],[]],"floor":0.0},"pair_add_fast":{"qty":[0.0,0.0],"cash":0.0,"lots":[[],[]],"floor":0.0},"pair_add_250":{"qty":[0.0,0.0],"cash":0.0,"lots":[[],[]],"floor":0.0}}}
{"kind":"decision","recorded_ms":1789998700038,"S":1789998600,"age":100,"signal":{},"entry_side":null,"context_gap":"incomplete or stale context","book_errors":[null,null],"books":[{"bid":0.94,"ask":0.95,"asks":[[0.95,1599.01]],"received_ms":1789998700037,"observed_ms":1789998700028,"hash":"89d5c67981cded3a7170a8020278213e9cff33b4"},{"bid":0.05,"ask":0.06,"asks":[[0.06,545.74]],"received_ms":1789998700032,"observed_ms":1789998700023,"hash":"86c450e5f4176ea928d545dc9c0a182d15e8663a"}],"intents":{"pair_fast":null,"pair_250":null,"pair_add_fast":null,"pair_add_250":null},"decision_ms":1789998700038,"feature_cutoff_ms":1789998700037,"request_ms":1789998700005,"inventory":{"pair_fast":{"qty":[0.0,0.0],"cash":0.0,"lots":[[],[]],"floor":0.0},"pair_250":{"qty":[0.0,0.0],"cash":0.0,"lots":[[],[]],"floor":0.0},"pair_add_fast":{"qty":[0.0,0.0],"cash":0.0,"lots":[[],[]],"floor":0.0},"pair_add_250":{"qty":[0.0,0.0],"cash":0.0,"lots":[[],[]],"floor":0.0}}}
{"kind":"decision","recorded_ms":1789998710048,"S":1789998600,"age":110,"signal":{},"entry_side":null,"context_gap":"incomplete or stale context","book_errors":[null,null],"books":[{"bid":0.96,"ask":0.97,"asks":[[0.97,1937.37]],"received_ms":1789998710046,"observed_ms":1789998710035,"hash":"6191469b34ec7b8908bdd52b742ce9c8a9a4770c"},{"bid":0.03,"ask":0.04,"asks":[[0.04,135.12]],"received_ms":1789998710042,"observed_ms":1789998710029,"hash":"dce674bd6524db08a162de2ba9edbc5d6f26a228"}],"intents":{"pair_fast":null,"pair_250":null,"pair_add_fast":null,"pair_add_250":null},"decision_ms":1789998710048,"feature_cutoff_ms":1789998710046,"request_ms":1789998710012,"inventory":{"pair_fast":{"qty":[0.0,0.0],"cash":0.0,"lots":[[],[]],"floor":0.0},"pair_250":{"qty":[0.0,0.0],"cash":0.0,"lots":[[],[]],"floor":0.0},"pair_add_fast":{"qty":[0.0,0.0],"cash":0.0,"lots":[[],[]],"floor":0.0},"pair_add_250":{"qty":[0.0,0.0],"cash":0.0,"lots":[[],[]],"floor":0.0}}}
{"kind":"decision","recorded_ms":1789998720059,"S":1789998600,"age":120,"signal":{},"entry_side":null,"context_gap":"incomplete or stale context","book_errors":[null,null],"books":[{"bid":0.96,"ask":0.97,"asks":[[0.97,796.29]],"received_ms":1789998720051,"observed_ms":1789998720044,"hash":"b0ef121b7cb06390552f859bef36c36fb1ef7d5b"},{"bid":0.03,"ask":0.04,"asks":[[0.04,129.31]],"received_ms":1789998720057,"observed_ms":1789998720048,"hash":"a052dc74ee7a1d535ef05fb94498b552958c3143"}],"intents":{"pair_fast":null,"pair_250":null,"pair_add_fast":null,"pair_add_250":null},"decision_ms":1789998720059,"feature_cutoff_ms":1789998720057,"request_ms":1789998720021,"inventory":{"pair_fast":{"qty":[0.0,0.0],"cash":0.0,"lots":[[],[]],"floor":0.0},"pair_250":{"qty":[0.0,0.0],"cash":0.0,"lots":[[],[]],"floor":0.0},"pair_add_fast":{"qty":[0.0,0.0],"cash":0.0,"lots":[[],[]],"floor":0.0},"pair_add_250":{"qty":[0.0,0.0],"cash":0.0,"lots":[[],[]],"floor":0.0}}}
{"kind":"decision","recorded_ms":1789998730042,"S":1789998600,"age":130,"signal":{"rsi14":86.84286880043527,"volume_ratio":1.791763002272077,"taker_buy_fraction":0.5841906854652281,"volume5":410.90662,"return1":6.453666511886182,"return5":43.27560725176147,"return15":84.62316267916964,"bollinger_z":2.3399055600294854,"bar_close_ms":1789998719999,"ref":85346.42241923072,"reference_received_ms":1789998601650,"spot":85759.96540192945,"twap":85697.36110542237,"sigma":12.712582490384222,"spot_z":2.4952541586325676,"twap_z":2.117509552284453,"momentum":1.2854746969611475,"decision_ms":1789998730041,"momentum30":1.2155862879935353,"momentum60":0.8876220193421539,"spot_twap_gap":0.6357622404321503,"range60":0.8876220193421539,"final_mean":85759.96540192945,"final_z":2.8535382023599984,"final_up_prob":0.997838233539112,"final_drift_up_prob":0.9999999999999978,"final_known_seconds":0,"final_sd":144.9228828815821,"final_drift_shift":723.2661629329448},"entry_side":null,"context_gap":null,"book_errors":[null,null],"books":[{"bid":0.98,"ask":0.99,"asks":[[0.99,4047.52]],"received_ms":1789998730041,"observed_ms":1789998730028,"hash":"527481f68bb6dca40f43dcef22adcc7f3147e91a"},{"bid":0.01,"ask":0.02,"asks":[[0.02,757.41]],"received_ms":1789998730037,"observed_ms":1789998730028,"hash":"59945af06eac7fd21bdadba5b77e5bf6428611b9"}],"intents":{"pair_fast":null,"pair_250":null,"pair_add_fast":null,"pair_add_250":null},"decision_ms":1789998730042,"feature_cutoff_ms":1789998730041,"request_ms":1789998730010,"inventory":{"pair_fast":{"qty":[0.0,0.0],"cash":0.0,"lots":[[],[]],"floor":0.0},"pair_250":{"qty":[0.0,0.0],"cash":0.0,"lots":[[],[]],"floor":0.0},"pair_add_fast":{"qty":[0.0,0.0],"cash":0.0,"lots":[[],[]],"floor":0.0},"pair_add_250":{"qty":[0.0,0.0],"cash":0.0,"lots":[[],[]],"floor":0.0}}}
{"kind":"decision","recorded_ms":1789998740054,"S":1789998600,"age":140,"signal":{"rsi14":86.84286880043527,"volume_ratio":1.791763002272077,"taker_buy_fraction":0.5841906854652281,"volume5":410.90662,"return1":6.453666511886182,"return5":43.27560725176147,"return15":84.62316267916964,"bollinger_z":2.3399055600294854,"bar_close_ms":1789998719999,"ref":85346.42241923072,"reference_received_ms":1789998601650,"spot":85779.23730745123,"twap":85714.99158863872,"sigma":13.312198898281641,"spot_z":2.5707766358753883,"twap_z":2.189178411384373,"momentum":0.2066329788186007,"decision_ms":1789998740053,"momentum30":0.9254532483848552,"momentum60":0.7947998060745981,"spot_twap_gap":0.6230440739035257,"range60":1.1852345831202826,"final_mean":85779.23730745123,"final_z":2.968641117979052,"final_up_prob":0.9985044014017731,"final_drift_up_prob":0.9999094228491753,"final_known_seconds":0,"final_sd":145.7956253449587,"final_drift_shift":113.03571665428137},"entry_side":null,"context_gap":null,"book_errors":[null,null],"books":[{"bid":0.98,"ask":0.99,"asks":[[0.99,953.98]],"received_ms":1789998740053,"observed_ms":1789998740044,"hash":"e5165ca5cf06256d11465fda8691abb68b34c958"},{"bid":0.01,"ask":0.02,"asks":[[0.02,1381.28]],"received_ms":1789998740043,"observed_ms":1789998740029,"hash":"48e4917032da004ece503eb85a5ddfd71bc9ae36"}],"intents":{"pair_fast":null,"pair_250":null,"pair_add_fast":null,"pair_add_250":null},"decision_ms":1789998740054,"feature_cutoff_ms":1789998740053,"request_ms":1789998740018,"inventory":{"pair_fast":{"qty":[0.0,0.0],"cash":0.0,"lots":[[],[]],"floor":0.0},"pair_250":{"qty":[0.0,0.0],"cash":0.0,"lots":[[],[]],"floor":0.0},"pair_add_fast":{"qty":[0.0,0.0],"cash":0.0,"lots":[[],[]],"floor":0.0},"pair_add_250":{"qty":[0.0,0.0],"cash":0.0,"lots":[[],[]],"floor":0.0}}}
{"kind":"decision","recorded_ms":1789998750060,"S":1789998600,"age":150,"signal":{"rsi14":86.84286880043527,"volume_ratio":1.791763002272077,"taker_buy_fraction":0.5841906854652281,"volume5":410.90662,"return1":6.453666511886182,"return5":43.27560725176147,"return15":84.62316267916964,"bollinger_z":2.3399055600294854,"bar_close_ms":1789998719999,"ref":85346.42241923072,"reference_received_ms":1789998601650,"spot":85761.094,"twap":85730.18640458751,"sigma":13.406483563240048,"spot_z":2.5259674082030434,"twap_z":2.3376941280977874,"momentum":-0.2876128777402492,"decision_ms":1789998750058,"momentum30":0.7191251551003618,"momentum60":0.565523066099867,"spot_twap_gap":0.2976286355260168,"range60":1.17689910536137,"final_mean":85761.094,"final_z":2.9499019152832564,"final_up_prob":0.9984106258651745,"final_drift_up_prob":0.9719017056450376,"final_known_seconds":0,"final_sd":140.57131141238776,"final_drift_shift":-146.24953487250767},"entry_side":1,"context_gap":null,"book_errors":[null,null],"books":[{"bid":0.98,"ask":0.99,"asks":[[0.99,422.73]],"received_ms":1789998750058,"observed_ms":1789998750049,"hash":"a853f933d7fd55d063613686ea4bda97d3bcf628"},{"bid":0.01,"ask":0.02,"asks":[[0.02,1715.88]],"received_ms":1789998750058,"observed_ms":1789998750045,"hash":"587d4a404444fd7fa54e4883e3e377920eb5bbe2"}],"intents":{"pair_fast":{"kind":"first","side":1,"qty":5.0,"max_cost":0.15686},"pair_250":{"kind":"first","side":1,"qty":5.0,"max_cost":0.15686},"pair_add_fast":{"kind":"first","side":1,"qty":5.0,"max_cost":0.15686},"pair_add_250":{"kind":"first","side":1,"qty":5.0,"max_cost":0.15686}},"decision_ms":1789998750060,"feature_cutoff_ms":1789998750058,"request_ms":1789998750027,"inventory":{"pair_fast":{"qty":[0.0,0.0],"cash":0.0,"lots":[[],[]],"floor":0.0},"pair_250":{"qty":[0.0,0.0],"cash":0.0,"lots":[[],[]],"floor":0.0},"pair_add_fast":{"qty":[0.0,0.0],"cash":0.0,"lots":[[],[]],"floor":0.0},"pair_add_250":{"qty":[0.0,0.0],"cash":0.0,"lots":[[],[]],"floor":0.0}}}
{"kind":"decision","recorded_ms":1789998760073,"S":1789998600,"age":160,"signal":{"rsi14":86.84286880043527,"volume_ratio":1.791763002272077,"taker_buy_fraction":0.5841906854652281,"volume5":410.90662,"return1":6.453666511886182,"return5":43.27560725176147,"return15":84.62316267916964,"bollinger_z":2.3399055600294854,"bar_close_ms":1789998719999,"ref":85346.42241923072,"reference_received_ms":1789998601650,"spot":85736.27102146052,"twap":85738.06642434376,"sigma":10.346417525438628,"spot_z":3.1853243964341456,"twap_z":3.1999940414520385,"momentum":-0.21138790818809994,"decision_ms":1789998760072,"momentum30":-0.6046918737726935,"momentum60":0.7604719304849065,"spot_twap_gap":-0.022402490038861352,"range60":1.5249798756744282,"final_mean":85736.27102146052,"final_z":3.7693145733962354,"final_up_prob":0.9999181517656507,"final_drift_up_prob":0.9987941963216904,"final_known_seconds":0,"final_sd":103.42692143058251,"final_drift_shift":-76.02885812322151},"entry_side":1,"context_gap":null,"book_errors":[null,null],"books":[{"bid":0.99,"ask":null,"asks":[],"received_ms":1789998760072,"observed_ms":1789998760043,"hash":"e25d7bb00a53b736b77e129fafc42a69124b37d8"},{"bid":null,"ask":0.01,"asks":[[0.01,5389.72]],"received_ms":1789998760047,"observed_ms":1789998760022,"hash":"74d8ad89664147284cb177d7f01b792cb50f3a6f"}],"intents":{"pair_fast":null,"pair_250":null,"pair_add_fast":null,"pair_add_250":null},"decision_ms":1789998760073,"feature_cutoff_ms":1789998760072,"request_ms":1789998760013,"inventory":{"pair_fast":{"qty":[0.0,5.0],"cash":0.10686000000000001,"lots":[[],[[5.0,0.021372000000000002]]],"floor":-0.10686000000000001},"pair_250":{"qty":[0.0,5.0],"cash":0.10686000000000001,"lots":[[],[[5.0,0.021372000000000002]]],"floor":-0.10686000000000001},"pair_add_fast":{"qty":[0.0,5.0],"cash":0.10686000000000001,"lots":[[],[[5.0,0.021372000000000002]]],"floor":-0.10686000000000001},"pair_add_250":{"qty":[0.0,5.0],"cash":0.10686000000000001,"lots":[[],[[5.0,0.021372000000000002]]],"floor":-0.10686000000000001}}}
{"kind":"decision","recorded_ms":1789998770078,"S":1789998600,"age":170,"signal":{"rsi14":86.84286880043527,"volume_ratio":1.791763002272077,"taker_buy_fraction":0.5841906854652281,"volume5":410.90662,"return1":6.453666511886182,"return5":43.27560725176147,"return15":84.62316267916964,"bollinger_z":2.3399055600294854,"bar_close_ms":1789998719999,"ref":85346.42241923072,"reference_received_ms":1789998601650,"spot":85749.57474217,"twap":85742.64740008194,"sigma":9.524413846108498,"spot_z":3.713538138928053,"twap_z":3.6497286367084674,"momentum":1.0402873667316344,"decision_ms":1789998770077,"momentum30":-0.45454880449292717,"momentum60":0.5125780983260271,"spot_twap_gap":0.09389722375238892,"range60":1.2097814718333832,"final_mean":85749.57474217,"final_z":4.463705307720263,"final_up_prob":0.9999959722831115,"final_drift_up_prob":0.9999999999999989,"final_known_seconds":0,"final_sd":90.3178626604256,"final_drift_shift":313.08124127986144},"entry_side":null,"context_gap":null,"book_errors":[null,null],"books":[{"bid":0.99,"ask":null,"asks":[],"received_ms":1789998770077,"observed_ms":1789998770052,"hash":"033c2ea22fda0bb8055eae224b192fafa7d48f5a"},{"bid":null,"ask":0.01,"asks":[[0.01,7048.73]],"received_ms":1789998770074,"observed_ms":1789998770052,"hash":"f453ca680ba7c662895bfb328b6d492f4ab54f09"}],"intents":{"pair_fast":null,"pair_250":null,"pair_add_fast":null,"pair_add_250":null},"decision_ms":1789998770078,"feature_cutoff_ms":1789998770077,"request_ms":1789998770046,"inventory":{"pair_fast":{"qty":[0.0,5.0],"cash":0.10686000000000001,"lots":[[],[[5.0,0.021372000000000002]]],"floor":-0.10686000000000001},"pair_250":{"qty":[0.0,5.0],"cash":0.10686000000000001,"lots":[[],[[5.0,0.021372000000000002]]],"floor":-0.10686000000000001},"pair_add_fast":{"qty":[0.0,5.0],"cash":0.10686000000000001,"lots":[[],[[5.0,0.021372000000000002]]],"floor":-0.10686000000000001},"pair_add_250":{"qty":[0.0,5.0],"cash":0.10686000000000001,"lots":[[],[[5.0,0.021372000000000002]]],"floor":-0.10686000000000001}}}
{"kind":"decision","recorded_ms":1789998780038,"S":1789998600,"age":180,"signal":{"rsi14":86.84286880043527,"volume_ratio":1.791763002272077,"taker_buy_fraction":0.5841906854652281,"volume5":410.90662,"return1":6.453666511886182,"return5":43.27560725176147,"return15":84.62316267916964,"bollinger_z":2.3399055600294854,"bar_close_ms":1789998719999,"ref":85346.42241923072,"reference_received_ms":1789998601650,"spot":85710.4057035458,"twap":85745.45264968688,"sigma":9.98807894713209,"spot_z":3.327176300908981,"twap_z":3.6475409265518017,"momentum":-0.9086373491297131,"decision_ms":1789998780037,"momentum30":-0.5992209842002654,"momentum60":0.027366905670946445,"spot_twap_gap":-0.4529941458489614,"range60":1.153621178014805,"final_mean":85710.4057035458,"final_z":4.075256353599113,"final_up_prob":0.9999770181577439,"final_drift_up_prob":0.8818943960768233,"final_known_seconds":0,"final_sd":89.31543263373443,"final_drift_shift":-258.18825391272395},"entry_side":1,"context_gap":null,"book_errors":[null,null],"books":[{"bid":0.99,"ask":null,"asks":[],"received_ms":1789998780035,"observed_ms":1789998780025,"hash":"bd578bebd8ab9f9d70342afcb1ddb8fa53791f3b"},{"bid":null,"ask":0.01,"asks":[[0.01,6427.78]],"received_ms":1789998780037,"observed_ms":1789998780025,"hash":"5f70c3b2749e604293615571018ef28f5afbd461"}],"intents":{"pair_fast":null,"pair_250":null,"pair_add_fast":{"kind":"add","side":1,"qty":5.0,"max_cost":0.10347},"pair_add_250":{"kind":"add","side":1,"qty":5.0,"max_cost":0.10347}},"decision_ms":1789998780038,"feature_cutoff_ms":1789998780037,"request_ms":1789998780000,"inventory":{"pair_fast":{"qty":[0.0,5.0],"cash":0.10686000000000001,"lots":[[],[[5.0,0.021372000000000002]]],"floor":-0.10686000000000001},"pair_250":{"qty":[0.0,5.0],"cash":0.10686000000000001,"lots":[[],[[5.0,0.021372000000000002]]],"floor":-0.10686000000000001},"pair_add_fast":{"qty":[0.0,5.0],"cash":0.10686000000000001,"lots":[[],[[5.0,0.021372000000000002]]],"floor":-0.10686000000000001},"pair_add_250":{"qty":[0.0,5.0],"cash":0.10686000000000001,"lots":[[],[[5.0,0.021372000000000002]]],"floor":-0.10686000000000001}}}
{"kind":"execution","recorded_ms":1789998780069,"S":1789998600,"age":180,"speed":"fast","books":[{"bid":0.99,"ask":null,"asks":[],"received_ms":1789998780062,"observed_ms":1789998780055,"hash":"818a93c5f7b8aa73a079f32a3af35cdcc00fc7dd"},{"bid":null,"ask":0.01,"asks":[[0.01,6619.02]],"received_ms":1789998780069,"observed_ms":1789998780055,"hash":"ae9ab8d1c8f24724fb712b95fd60411ffbc18a74"}],"book_errors":[null,null],"fills":{"pair_add_fast":{"kind":"add","side":1,"qty":5.0,"cost":0.053470000000000004,"fee":0.00347,"age":180.069}},"rejected":{},"decision_ms":1789998780038,"request_ms":1789998780038,"execution_ms":1789998780069,"delay_ms":31}
{"kind":"execution","recorded_ms":1789998780325,"S":1789998600,"age":180,"speed":"250","books":[{"bid":0.99,"ask":null,"asks":[],"received_ms":1789998780321,"observed_ms":1789998780305,"hash":"f6564e1da0b36d27e9e281f551c964def90517f5"},{"bid":null,"ask":0.01,"asks":[[0.01,6631.02]],"received_ms":1789998780325,"observed_ms":1789998780305,"hash":"c090d1368f64993c45b1b366fc171d578ee4b99e"}],"book_errors":[null,null],"fills":{"pair_add_250":{"kind":"add","side":1,"qty":5.0,"cost":0.053470000000000004,"fee":0.00347,"age":180.325}},"rejected":{},"decision_ms":1789998780038,"request_ms":1789998780288,"execution_ms":1789998780325,"delay_ms":287}
{"kind":"decision","recorded_ms":1789998790065,"S":1789998600,"age":190,"signal":{"rsi14":84.68456975186535,"volume_ratio":1.772675505160985,"taker_buy_fraction":0.5537852128152123,"volume5":390.19813999999997,"return1":-2.6787615394719366,"return5":31.526783240239894,"return15":92.13726319473828,"bollinger_z":1.905250815390552,"bar_close_ms":1789998779999,"ref":85346.42241923072,"reference_received_ms":1789998601650,"spot":85635.82495630607,"twap":85740.76036395338,"sigma":10.134387662636478,"spot_z":2.7235468810046246,"twap_z":3.711086607134833,"momentum":-1.7916780495974405,"decision_ms":1789998790064,"momentum30":-1.4847778694272233,"momentum60":-1.7160849651468826,"spot_twap_gap":-1.336746069503158,"range60":2.060060296547774,"final_mean":85635.82495630607,"final_z":3.4147147159371896,"final_up_prob":0.999680755763271,"final_drift_up_prob":0.022698740208177914,"final_known_seconds":0,"final_sd":84.75160039714277,"final_drift_shift":-458.98648626647673},"entry_side":1,"context_gap":null,"book_errors":[null,null],"books":[{"bid":0.99,"ask":null,"asks":[],"received_ms":1789998790060,"observed_ms":1789998790043,"hash":"732aef367180694aeb61e7f87bbae5658b540dd1"},{"bid":null,"ask":0.01,"asks":[[0.01,5716.3]],"received_ms":1789998790064,"observed_ms":1789998790043,"hash":"c5d5822a11cb18f7789553b717ea050a49bb991e"}],"intents":{"pair_fast":null,"pair_250":null,"pair_add_fast":null,"pair_add_250":null},"decision_ms":1789998790065,"feature_cutoff_ms":1789998790064,"request_ms":1789998790032,"inventory":{"pair_fast":{"qty":[0.0,5.0],"cash":0.10686000000000001,"lots":[[],[[5.0,0.021372000000000002]]],"floor":-0.10686000000000001},"pair_250":{"qty":[0.0,5.0],"cash":0.10686000000000001,"lots":[[],[[5.0,0.021372000000000002]]],"floor":-0.10686000000000001},"pair_add_fast":{"qty":[0.0,10.0],"cash":0.16033000000000003,"lots":[[],[[5.0,0.021372000000000002],[5.0,0.010694]]],"floor":-0.16033000000000003},"pair_add_250":{"qty":[0.0,10.0],"cash":0.16033000000000003,"lots":[[],[[5.0,0.021372000000000002],[5.0,0.010694]]],"floor":-0.16033000000000003}}}
{"kind":"decision","recorded_ms":1789998880029,"S":1789998600,"age":280,"signal":{"rsi14":65.74585184883227,"volume_ratio":1.3156223664114743,"taker_buy_fraction":0.5039315374549336,"volume5":380.7162,"return1":-29.492432705614007,"return5":8.614636152149066,"return15":59.5851517934704,"bollinger_z":0.8119777962825319,"bar_close_ms":1789998839999,"ref":85346.42241923072,"reference_received_ms":1789998601650,"spot":85376.81873251,"twap":85474.26358963098,"sigma":12.49553774866695,"spot_z":0.5443211176258588,"twap_z":2.2893121317542415,"momentum":-0.9019606062003002,"decision_ms":1789998880028,"momentum30":-1.4568120416496126,"momentum60":-1.758518150448656,"spot_twap_gap":-1.0067655520824548,"range60":1.9176895028568675,"final_mean":85419.03298224755,"final_z":6.765881683019748,"final_up_prob":0.9999999999933751,"final_drift_up_prob":0.9999999925183436,"final_known_seconds":40,"final_sd":10.731870053102044,"final_drift_shift":-11.84689077275235},"entry_side":1,"context_gap":null,"book_errors":[null,null],"books":[{"bid":0.999,"ask":null,"asks":[],"received_ms":1789998880027,"observed_ms":1789998880019,"hash":"7ee788ed797db18ed86c6850b50ef16f7d445179"},{"bid":null,"ask":0.001,"asks":[[0.001,7993.29]],"received_ms":1789998880027,"observed_ms":1789998880008,"hash":"bd004f004f62651430d072816b6f0f9b23184043"}],"intents":{"pair_fast":null,"pair_250":null,"pair_add_fast":null,"pair_add_250":null},"decision_ms":1789998880029,"feature_cutoff_ms":1789998880028,"request_ms":1789998880003,"inventory":{"pair_fast":{"qty":[5.0,5.0],"cash":4.7796400000000006,"lots":[[],[]],"floor":0.22035999999999945},"pair_250":{"qty":[5.0,5.0],"cash":4.7796400000000006,"lots":[[],[]],"floor":0.22035999999999945},"pair_add_fast":{"qty":[10.0,10.0],"cash":9.67928,"lots":[[],[]],"floor":0.32071999999999967},"pair_add_250":{"qty":[10.0,10.0],"cash":9.67928,"lots":[[],[]],"floor":0.32071999999999967}}}
{"kind":"decision","recorded_ms":1789998890110,"S":1789998600,"age":290,"signal":{"rsi14":65.74585184883227,"volume_ratio":1.3156223664114743,"taker_buy_fraction":0.5039315374549336,"volume5":380.7162,"return1":-29.492432705614007,"return5":8.614636152149066,"return15":59.5851517934704,"bollinger_z":0.8119777962825319,"bar_close_ms":1789998839999,"ref":85346.42241923072,"reference_received_ms":1789998601650,"spot":85401.85811963386,"twap":85448.27879080088,"sigma":10.127682880028694,"spot_z":1.7404411509183668,"twap_z":3.1978493872131444,"momentum":0.35773302360157083,"decision_ms":1789998890109,"momentum30":-0.8244104258624018,"momentum60":-1.3287412614503693,"spot_twap_gap":-0.5917328721002885,"range60":1.5868008534478069,"final_mean":85427.1117894532,"final_z":26.61692031778057,"final_up_prob":1.0,"final_drift_up_prob":1.0,"final_known_seconds":50,"final_sd":3.031506622822538,"final_drift_shift":0.9340460495090482},"entry_side":null,"context_gap":null,"book_errors":[null,null],"books":[{"bid":0.999,"ask":null,"asks":[],"received_ms":1789998890080,"observed_ms":1789998890068,"hash":"0bdbd4178b6602af8460fc455c8fd63c11695397"},{"bid":null,"ask":0.001,"asks":[[0.001,7612.94]],"received_ms":1789998890109,"observed_ms":1789998890092,"hash":"ba2f6e38fee19e5b97e6108c6fdd391fad2808a4"}],"intents":{"pair_fast":null,"pair_250":null,"pair_add_fast":null,"pair_add_250":null},"decision_ms":1789998890110,"feature_cutoff_ms":1789998890109,"request_ms":1789998890050,"inventory":{"pair_fast":{"qty":[5.0,5.0],"cash":4.7796400000000006,"lots":[[],[]],"floor":0.22035999999999945},"pair_250":{"qty":[5.0,5.0],"cash":4.7796400000000006,"lots":[[],[]],"floor":0.22035999999999945},"pair_add_fast":{"qty":[10.0,10.0],"cash":9.67928,"lots":[[],[]],"floor":0.32071999999999967},"pair_add_250":{"qty":[10.0,10.0],"cash":9.67928,"lots":[[],[]],"floor":0.32071999999999967}}}
{"kind":"decision","recorded_ms":1789998930080,"S":1789998900,"age":30,"signal":{"rsi14":63.160615673833576,"volume_ratio":0.8335006369855618,"taker_buy_fraction":0.4804583234580652,"volume5":369.90557,"return1":-6.08262107928666,"return5":-4.3848731360790225,"return15":39.139529824513616,"bollinger_z":0.5531553394645224,"bar_close_ms":1789998899999,"ref":85426.38316465008,"reference_received_ms":1789998901464,"spot":85368.4797988692,"twap":85377.00826340212,"sigma":6.489867060209873,"spot_z":-0.5430623206168038,"twap_z":-0.46307581762016947,"momentum":1.2133983852754717,"decision_ms":1789998930079,"momentum30":-0.18405357400812328,"momentum60":-0.8748572178826028,"spot_twap_gap":-0.16965217108603892,"range60":1.370225034322926,"final_mean":85368.4797988692,"final_z":-0.588408162058457,"final_up_prob":0.27812918027264955,"final_drift_up_prob":0.9999999790796525,"final_known_seconds":0,"final_sd":98.40680247926835,"final_drift_shift":597.4581314752111},"entry_side":null,"context_gap":null,"book_errors":[null,null],"books":[{"bid":0.46,"ask":0.47,"asks":[[0.47,382.36]],"received_ms":1789998930079,"observed_ms":1789998930067,"hash":"99c22d07b6dc043cc33cee6652cfc7776cec8e76"},{"bid":0.53,"ask":0.54,"asks":[[0.54,297.88]],"received_ms":1789998930074,"observed_ms":1789998930055,"hash":"7ce0f25718397f25f40d9c7de5efe3eb0025fe3a"}],"intents":{"pair_fast":null,"pair_250":null,"pair_add_fast":null,"pair_add_250":null},"decision_ms":1789998930080,"feature_cutoff_ms":1789998930079,"request_ms":1789998930044,"inventory":{"pair_fast":{"qty":[0.0,0.0],"cash":0.0,"lots":[[],[]],"floor":0.0},"pair_250":{"qty":[0.0,0.0],"cash":0.0,"lots":[[],[]],"floor":0.0},"pair_add_fast":{"qty":[0.0,0.0],"cash":0.0,"lots":[[],[]],"floor":0.0},"pair_add_250":{"qty":[0.0,0.0],"cash":0.0,"lots":[[],[]],"floor":0.0}}}
{"kind":"decision","recorded_ms":1789998940035,"S":1789998900,"age":40,"signal":{},"entry_side":null,"context_gap":"incomplete or stale context","book_errors":[null,null],"books":[{"bid":0.44,"ask":0.45,"asks":[[0.45,460.0]],"received_ms":1789998940033,"observed_ms":1789998940024,"hash":"5ff0526e1be20e7c315cbd04742a2ae6784e00af"},{"bid":0.55,"ask":0.56,"asks":[[0.56,363.54]],"received_ms":1789998940034,"observed_ms":1789998940024,"hash":"c3ea841ec0e54194dd3b44090a3abda922dfbd08"}],"intents":{"pair_fast":null,"pair_250":null,"pair_add_fast":null,"pair_add_250":null},"decision_ms":1789998940035,"feature_cutoff_ms":1789998940034,"request_ms":1789998940004,"inventory":{"pair_fast":{"qty":[0.0,0.0],"cash":0.0,"lots":[[],[]],"floor":0.0},"pair_250":{"qty":[0.0,0.0],"cash":0.0,"lots":[[],[]],"floor":0.0},"pair_add_fast":{"qty":[0.0,0.0],"cash":0.0,"lots":[[],[]],"floor":0.0},"pair_add_250":{"qty":[0.0,0.0],"cash":0.0,"lots":[[],[]],"floor":0.0}}}
{"kind":"decision","recorded_ms":1789998950081,"S":1789998900,"age":50,"signal":{"rsi14":63.160615673833576,"volume_ratio":0.8335006369855618,"taker_buy_fraction":0.4804583234580652,"volume5":369.90557,"return1":-6.08262107928666,"return5":-4.3848731360790225,"return15":39.139529824513616,"bollinger_z":0.5531553394645224,"bar_close_ms":1789998899999,"ref":85426.38316465008,"reference_received_ms":1789998901464,"spot":85412.68705355817,"twap":85380.2973039707,"sigma":8.740952453104109,"spot_z":-0.09911468520502556,"twap_z":-0.333509676066961,"momentum":0.017444458341652654,"decision_ms":1789998950080,"momentum30":1.4435060891092508,"momentum60":0.2959654069616113,"spot_twap_gap":0.47838021242773127,"range60":1.3637144638854968,"final_mean":85412.68705355817,"final_z":-0.10814628447312373,"final_up_prob":0.45693982686202245,"final_drift_up_prob":0.49026137262345,"final_known_seconds":0,"final_sd":126.64430552222157,"final_drift_shift":10.604274806460909},"entry_side":null,"context_gap":null,"book_errors":[null,null],"books":[{"bid":0.48,"ask":0.49,"asks":[[0.49,12.0]],"received_ms":1789998950080,"observed_ms":1789998950052,"hash":"a805d6ca445d6cf28871ba16372e80909966356f"},{"bid":0.51,"ask":0.53,"asks":[[0.53,1909.17]],"received_ms":1789998950047,"observed_ms":1789998950036,"hash":"5f5dee70cfd48f0264dd398e3c5980fa6624d6c3"}],"intents":{"pair_fast":null,"pair_250":null,"pair_add_fast":null,"pair_add_250":null},"decision_ms":1789998950081,"feature_cutoff_ms":1789998950080,"request_ms":1789998950012,"inventory":{"pair_fast":{"qty":[0.0,0.0],"cash":0.0,"lots":[[],[]],"floor":0.0},"pair_250":{"qty":[0.0,0.0],"cash":0.0,"lots":[[],[]],"floor":0.0},"pair_add_fast":{"qty":[0.0,0.0],"cash":0.0,"lots":[[],[]],"floor":0.0},"pair_add_250":{"qty":[0.0,0.0],"cash":0.0,"lots":[[],[]],"floor":0.0}}}
{"kind":"decision","recorded_ms":1789998960043,"S":1789998900,"age":60,"signal":{"rsi14":63.160615673833576,"volume_ratio":0.8335006369855618,"taker_buy_fraction":0.4804583234580652,"volume5":369.90557,"return1":-6.08262107928666,"return5":-4.3848731360790225,"return15":39.139529824513616,"bollinger_z":0.5531553394645224,"bar_close_ms":1789998899999,"ref":85426.38316465008,"reference_received_ms":1789998901464,"spot":85386.51323440654,"twap":85385.21904947923,"sigma":8.89319243061775,"spot_z":-0.2894144223363583,"twap_z":-0.2988088652371706,"momentum":-1.1207060906259672,"decision_ms":1789998960042,"momentum30":-0.02611850876719126,"momentum60":0.1668106631663938,"spot_twap_gap":0.01878724170001924,"range60":1.3403694321731294,"final_mean":85386.51323440654,"final_z":-0.31704316444426794,"final_up_prob":0.37560542495688903,"final_drift_up_prob":1.208895750171024e-08,"final_known_seconds":0,"final_sd":125.75552705395172,"final_drift_shift":-661.7315613809812},"entry_side":null,"context_gap":null,"book_errors":[null,null],"books":[{"bid":0.44,"ask":0.45,"asks":[[0.45,899.88]],"received_ms":1789998960031,"observed_ms":1789998960022,"hash":"2a13d4ca69e94270fb47b450932b7eef2611aedd"},{"bid":0.55,"ask":0.56,"asks":[[0.56,1442.64]],"received_ms":1789998960042,"observed_ms":1789998960034,"hash":"61aa5bec7a231e4012a06ec78b88b9e6567d658a"}],"intents":{"pair_fast":null,"pair_250":null,"pair_add_fast":null,"pair_add_250":null},"decision_ms":1789998960043,"feature_cutoff_ms":1789998960042,"request_ms":1789998960003,"inventory":{"pair_fast":{"qty":[0.0,0.0],"cash":0.0,"lots":[[],[]],"floor":0.0},"pair_250":{"qty":[0.0,0.0],"cash":0.0,"lots":[[],[]],"floor":0.0},"pair_add_fast":{"qty":[0.0,0.0],"cash":0.0,"lots":[[],[]],"floor":0.0},"pair_add_250":{"qty":[0.0,0.0],"cash":0.0,"lots":[[],[]],"floor":0.0}}}
{"kind":"decision","recorded_ms":1789998970085,"S":1789998900,"age":70,"signal":{"rsi14":67.02624184407247,"volume_ratio":0.5522464483072471,"taker_buy_fraction":0.4505294021120663,"volume5":299.52185,"return1":4.455480480911828,"return5":-27.333266780057247,"return15":43.782381085075784,"bollinger_z":0.6513942277031034,"bar_close_ms":1789998959999,"ref":85426.38316465008,"reference_received_ms":1789998901464,"spot":85444.30260654252,"twap":85391.13348994187,"sigma":8.489192790267731,"spot_z":0.13921097822949602,"twap_z":-0.27384456099993976,"momentum":1.2270403658556412,"decision_ms":1789998970084,"momentum30":0.690315209170475,"momentum60":1.2620070656300233,"spot_twap_gap":0.8085696257754605,"range60":1.5317773992474109,"final_mean":85444.30260654252,"final_z":0.15317126727222138,"final_up_prob":0.5608683921689663,"final_drift_up_prob":0.9999999963112733,"final_known_seconds":0,"final_sd":116.98957782074268,"final_drift_shift":658.5258080302552},"entry_side":null,"context_gap":null,"book_errors":[null,null],"books":[{"bid":0.61,"ask":0.62,"asks":[[0.62,324.26]],"received_ms":1789998970077,"observed_ms":1789998970067,"hash":"4e5c31abf78c41d745a7a860b8e78f4fdbf24e02"},{"bid":0.38,"ask":0.39,"asks":[[0.39,201.97]],"received_ms":1789998970084,"observed_ms":1789998970071,"hash":"38d15790cd2193cdee59eb9869d14d1881ca8430"}],"intents":{"pair_fast":null,"pair_250":null,"pair_add_fast":null,"pair_add_250":null},"decision_ms":1789998970085,"feature_cutoff_ms":1789998970084,"request_ms":1789998970043,"inventory":{"pair_fast":{"qty":[0.0,0.0],"cash":0.0,"lots":[[],[]],"floor":0.0},"pair_250":{"qty":[0.0,0.0],"cash":0.0,"lots":[[],[]],"floor":0.0},"pair_add_fast":{"qty":[0.0,0.0],"cash":0.0,"lots":[[],[]],"floor":0.0},"pair_add_250":{"qty":[0.0,0.0],"cash":0.0,"lots":[[],[]],"floor":0.0}}}
{"kind":"decision","recorded_ms":1789998980057,"S":1789998900,"age":80,"signal":{"rsi14":67.02624184407247,"volume_ratio":0.5522464483072471,"taker_buy_fraction":0.4505294021120663,"volume5":299.52185,"return1":4.455480480911828,"return5":-27.333266780057247,"return15":43.782381085075784,"bollinger_z":0.6513942277031034,"bar_close_ms":1789998959999,"ref":85426.38316465008,"reference_received_ms":1789998901464,"spot":85484.08348946758,"twap":85408.85610904371,"sigma":10.389824734700582,"spot_z":0.37446736687969234,"twap_z":-0.11374823942200085,"momentum":0.22790597467949972,"decision_ms":1789998980056,"momentum30":1.1607086053161033,"momentum60":1.7458661738161352,"spot_twap_gap":0.9347427218457779,"range60":1.899177832271905,"final_mean":85484.08348946758,"final_z":0.4140009629879816,"final_up_prob":0.6605632992081069,"final_drift_up_prob":0.9242851873813407,"final_known_seconds":0,"final_sd":139.37244107129635,"final_drift_shift":142.22944378238716},"entry_side":null,"context_gap":null,"book_errors":[null,null],"books":[{"bid":0.59,"ask":0.6,"asks":[[0.6,293.94]],"received_ms":1789998980043,"observed_ms":1789998980033,"hash":"3e514e1b8164942ef32dbd78a918cdbf23e2f55f"},{"bid":0.4,"ask":0.41,"asks":[[0.41,401.41]],"received_ms":1789998980056,"observed_ms":1789998980045,"hash":"f53ac92db74ab03c5e49a72c98f0a78fd5a41a84"}],"intents":{"pair_fast":null,"pair_250":null,"pair_add_fast":null,"pair_add_250":null},"decision_ms":1789998980057,"feature_cutoff_ms":1789998980056,"request_ms":1789998980008,"inventory":{"pair_fast":{"qty":[0.0,0.0],"cash":0.0,"lots":[[],[]],"floor":0.0},"pair_250":{"qty":[0.0,0.0],"cash":0.0,"lots":[[],[]],"floor":0.0},"pair_add_fast":{"qty":[0.0,0.0],"cash":0.0,"lots":[[],[]],"floor":0.0},"pair_add_250":{"qty":[0.0,0.0],"cash":0.0,"lots":[[],[]],"floor":0.0}}}
{"kind":"decision","recorded_ms":1789998990078,"S":1789998900,"age":90,"signal":{"rsi14":67.02624184407247,"volume_ratio":0.5522464483072471,"taker_buy_fraction":0.4505294021120663,"volume5":299.52185,"return1":4.455480480911828,"return5":-27.333266780057247,"return15":43.782381085075784,"bollinger_z":0.6513942277031034,"bar_close_ms":1789998959999,"ref":85426.38316465008,"reference_received_ms":1789998901464,"spot":85485.89759611987,"twap":85432.64990113281,"sigma":9.75735277491763,"spot_z":0.4209788427380395,"twap_z":0.04432813028862028,"momentum":0.4867520494407883,"decision_ms":1789998990077,"momentum30":1.394659824618371,"momentum60":1.298120671670606,"spot_twap_gap":0.7045197629113514,"range60":1.4373675689316776,"final_mean":85485.89759611987,"final_z":0.4679120165222778,"final_up_prob":0.6800762450773785,"final_drift_up_prob":0.9952355119227878,"final_known_seconds":0,"final_sd":127.1915004708235,"final_drift_shift":270.2255938491749},"entry_side":null,"context_gap":null,"book_errors":[null,null],"books":[{"bid":0.56,"ask":0.57,"asks":[[0.57,358.29]],"received_ms":1789998990064,"observed_ms":1789998990054,"hash":"a64e0ac2a8e238c0d738020000ec56fd6c017d5e"},{"bid":0.43,"ask":0.44,"asks":[[0.44,52.0]],"received_ms":1789998990077,"observed_ms":1789998990067,"hash":"52826013869be539ed65fba48ca07ddccfa4d371"}],"intents":{"pair_fast":null,"pair_250":null,"pair_add_fast":null,"pair_add_250":null},"decision_ms":1789998990078,"feature_cutoff_ms":1789998990077,"request_ms":1789998990032,"inventory":{"pair_fast":{"qty":[0.0,0.0],"cash":0.0,"lots":[[],[]],"floor":0.0},"pair_250":{"qty":[0.0,0.0],"cash":0.0,"lots":[[],[]],"floor":0.0},"pair_add_fast":{"qty":[0.0,0.0],"cash":0.0,"lots":[[],[]],"floor":0.0},"pair_add_250":{"qty":[0.0,0.0],"cash":0.0,"lots":[[],[]],"floor":0.0}}}
{"kind":"decision","recorded_ms":1789999000040,"S":1789998900,"age":100,"signal":{"rsi14":67.02624184407247,"volume_ratio":0.5522464483072471,"taker_buy_fraction":0.4505294021120663,"volume5":299.52185,"return1":4.455480480911828,"return5":-27.333266780057247,"return15":43.782381085075784,"bollinger_z":0.6513942277031034,"bar_close_ms":1789998959999,"ref":85426.38316465008,"reference_received_ms":1789998901464,"spot":85518.76551351043,"twap":85447.35927565479,"sigma":10.66180410006417,"spot_z":0.6127532899053709,"twap_z":0.13913026878095786,"momentum":1.2576951073994866,"decision_ms":1789999000039,"momentum30":0.7221246743681908,"momentum60":1.2902994976471833,"spot_twap_gap":0.8646290610065341,"range60":1.3194916891360142,"final_mean":85518.76551351043,"final_z":0.6850957075156865,"final_up_prob":0.7533582356208401,"final_drift_up_prob":0.9999999991788058,"final_known_seconds":0,"final_sd":134.84590232706546,"final_drift_shift":720.7013699494198},"entry_side":null,"context_gap":null,"book_errors":[null,null],"books":[{"bid":0.73,"ask":0.74,"asks":[[0.74,105.0]],"received_ms":1789999000031,"observed_ms":1789999000020,"hash":"0c65a33315bc3fff84c1f59b8f32b1bf9abc76c4"},{"bid":0.26,"ask":0.27,"asks":[[0.27,208.75]],"received_ms":1789999000039,"observed_ms":1789999000028,"hash":"497a254f805c5ab4302541536c1796855e9b895b"}],"intents":{"pair_fast":null,"pair_250":null,"pair_add_fast":null,"pair_add_250":null},"decision_ms":1789999000040,"feature_cutoff_ms":1789999000039,"request_ms":1789999000003,"inventory":{"pair_fast":{"qty":[0.0,0.0],"cash":0.0,"lots":[[],[]],"floor":0.0},"pair_250":{"qty":[0.0,0.0],"cash":0.0,"lots":[[],[]],"floor":0.0},"pair_add_fast":{"qty":[0.0,0.0],"cash":0.0,"lots":[[],[]],"floor":0.0},"pair_add_250":{"qty":[0.0,0.0],"cash":0.0,"lots":[[],[]],"floor":0.0}}}
{"kind":"decision","recorded_ms":1789999010051,"S":1789998900,"age":110,"signal":{"rsi14":67.02624184407247,"volume_ratio":0.5522464483072471,"taker_buy_fraction":0.4505294021120663,"volume5":299.52185,"return1":4.455480480911828,"return5":-27.333266780057247,"return15":43.782381085075784,"bollinger_z":0.6513942277031034,"bar_close_ms":1789998959999,"ref":85426.38316465008,"reference_received_ms":1789998901464,"spot":85555.80485750611,"twap":85464.97585213347,"sigma":11.194741113928918,"spot_z":0.8388288763981362,"twap_z":0.2501331883743218,"momentum":0.7391887116406943,"decision_ms":1789999010050,"momentum30":1.3850552825522169,"momentum60":1.588833948842332,"spot_twap_gap":1.0474538046652193,"range60":1.683819255641505,"final_mean":85555.80485750611,"final_z":0.9441038884979699,"final_up_prob":0.8274417187706318,"final_drift_up_prob":0.9999679765226426,"final_known_seconds":0,"final_sd":137.08416460601495,"final_drift_shift":418.55605139873984},"entry_side":null,"context_gap":null,"book_errors":[null,null],"books":[{"bid":0.78,"ask":0.79,"asks":[[0.79,525.28]],"received_ms":1789999010050,"observed_ms":1789999010040,"hash":"a2596f8c3b9f0f4e8c025edc1823b9723b43393a"},{"bid":0.21,"ask":0.22,"asks":[[0.22,447.41]],"received_ms":1789999010050,"observed_ms":1789999010032,"hash":"64b71b433cbbf75d6552e40b132d32ec412f0428"}],"intents":{"pair_fast":null,"pair_250":null,"pair_add_fast":null,"pair_add_250":null},"decision_ms":1789999010051,"feature_cutoff_ms":1789999010050,"request_ms":1789999010014,"inventory":{"pair_fast":{"qty":[0.0,0.0],"cash":0.0,"lots":[[],[]],"floor":0.0},"pair_250":{"qty":[0.0,0.0],"cash":0.0,"lots":[[],[]],"floor":0.0},"pair_add_fast":{"qty":[0.0,0.0],"cash":0.0,"lots":[[],[]],"floor":0.0},"pair_add_250":{"qty":[0.0,0.0],"cash":0.0,"lots":[[],[]],"floor":0.0}}}
{"kind":"decision","recorded_ms":1789999020060,"S":1789998900,"age":120,"signal":{"rsi14":67.02624184407247,"volume_ratio":0.5522464483072471,"taker_buy_fraction":0.4505294021120663,"volume5":299.52185,"return1":4.455480480911828,"return5":-27.333266780057247,"return15":43.782381085075784,"bollinger_z":0.6513942277031034,"bar_close_ms":1789998959999,"ref":85426.38316465008,"reference_received_ms":1789998901464,"spot":85555.36888042233,"twap":85487.22153924897,"sigma":11.134527322900722,"spot_z":0.8635843589119987,"twap_z":0.4073247057682104,"momentum":0.06954759720733583,"decision_ms":1789999020059,"momentum30":1.2954921027808044,"momentum60":1.6696843655455549,"spot_twap_gap":0.7901353744039648,"range60":1.6696843655455549,"final_mean":85555.36888042233,"final_z":0.9792584916341169,"final_up_prob":0.8362738628757815,"final_drift_up_prob":0.8958074181079533,"final_known_seconds":0,"final_sd":131.71774038641823,"final_drift_shift":36.717602712475966},"entry_side":null,"context_gap":null,"book_errors":[null,null],"books":[{"bid":0.84,"ask":0.85,"asks":[[0.85,223.45]],"received_ms":1789999020059,"observed_ms":1789999020046,"hash":"6b79214cff7604e6b7a2e849e471dfb0b9f10873"},{"bid":0.15,"ask":0.16,"asks":[[0.16,966.97]],"received_ms":1789999020056,"observed_ms":1789999020046,"hash":"15819c85da832653edce6494b6b5a4f711777eda"}],"intents":{"pair_fast":null,"pair_250":null,"pair_add_fast":null,"pair_add_250":null},"decision_ms":1789999020060,"feature_cutoff_ms":1789999020059,"request_ms":1789999020025,"inventory":{"pair_fast":{"qty":[0.0,0.0],"cash":0.0,"lots":[[],[]],"floor":0.0},"pair_250":{"qty":[0.0,0.0],"cash":0.0,"lots":[[],[]],"floor":0.0},"pair_add_fast":{"qty":[0.0,0.0],"cash":0.0,"lots":[[],[]],"floor":0.0},"pair_add_250":{"qty":[0.0,0.0],"cash":0.0,"lots":[[],[]],"floor":0.0}}}
{"kind":"decision","recorded_ms":1789999030043,"S":1789998900,"age":130,"signal":{"rsi14":70.28413236619566,"volume_ratio":0.7834175645655405,"taker_buy_fraction":0.4413220151495373,"volume5":258.85543,"return1":19.725697404672033,"return5":-14.016364806730095,"return15":69.83420158873213,"bollinger_z":1.188536668029354,"bar_close_ms":1789999019999,"ref":85426.38316465008,"reference_received_ms":1789998901464,"spot":85602.12495761878,"twap":85513.56033098158,"sigma":9.823264526770243,"spot_z":1.372297928886975,"twap_z":0.6807319009443387,"momentum":0.9124775025502269,"decision_ms":1789999030042,"momentum30":1.3472550972472432,"momentum60":1.6497347060352656,"spot_twap_gap":1.1639352786581674,"range60":1.724867218207889,"final_mean":85602.12495761878,"final_z":1.5693423845997039,"final_up_prob":0.9417159093785088,"final_drift_up_prob":0.9999998405427386,"final_known_seconds":0,"final_sd":111.9843538881632,"final_drift_shift":396.71236068030896},"entry_side":null,"context_gap":null,"book_errors":[null,null],"books":[{"bid":0.86,"ask":0.87,"asks":[[0.87,1050.37]],"received_ms":1789999030042,"observed_ms":1789999030034,"hash":"dd16221f564e4b107aa7add0710577456a45c7d1"},{"bid":0.13,"ask":0.14,"asks":[[0.14,728.3]],"received_ms":1789999030036,"observed_ms":1789999030022,"hash":"f2b966441209cc73521958682fd2b219b4250a67"}],"intents":{"pair_fast":null,"pair_250":null,"pair_add_fast":null,"pair_add_250":null},"decision_ms":1789999030043,"feature_cutoff_ms":1789999030042,"request_ms":1789999030007,"inventory":{"pair_fast":{"qty":[0.0,0.0],"cash":0.0,"lots":[[],[]],"floor":0.0},"pair_250":{"qty":[0.0,0.0],"cash":0.0,"lots":[[],[]],"floor":0.0},"pair_add_fast":{"qty":[0.0,0.0],"cash":0.0,"lots":[[],[]],"floor":0.0},"pair_add_250":{"qty":[0.0,0.0],"cash":0.0,"lots":[[],[]],"floor":0.0}}}
{"kind":"decision","recorded_ms":1789999040046,"S":1789998900,"age":140,"signal":{"rsi14":70.28413236619566,"volume_ratio":0.7834175645655405,"taker_buy_fraction":0.4413220151495373,"volume5":258.85543,"return1":19.725697404672033,"return5":-14.016364806730095,"return15":69.83420158873213,"bollinger_z":1.188536668029354,"bar_close_ms":1789999019999,"ref":85426.38316465008,"reference_received_ms":1789998901464,"spot":85621.19352618184,"twap":85538.80031486729,"sigma":9.429651481584594,"spot_z":1.633493838878535,"twap_z":0.9426229735431789,"momentum":0.760629735519324,"decision_ms":1789999040045,"momentum30":1.3218907840450032,"momentum60":2.0579306257429413,"spot_twap_gap":1.1280287360390755,"range60":2.086912010414052,"final_mean":85621.19352618184,"final_z":1.8862846618843647,"final_up_prob":0.9703716974748883,"final_drift_up_prob":0.9999989330180752,"final_known_seconds":0,"final_sd":103.27728654547546,"final_drift_shift":294.75551135699874},"entry_side":null,"context_gap":null,"book_errors":[null,null],"books":[{"bid":0.89,"ask":0.9,"asks":[[0.9,1105.61]],"received_ms":1789999040045,"observed_ms":1789999040037,"hash":"45ad11c7b4ac2f0db52526874d336777a9f2f16f"},{"bid":0.1,"ask":0.11,"asks":[[0.11,38.3]],"received_ms":1789999040045,"observed_ms":1789999040037,"hash":"5d4ffbc0e7789979baeefe88447f8b1a2509e23f"}],"intents":{"pair_fast":null,"pair_250":null,"pair_add_fast":null,"pair_add_250":null},"decision_ms":1789999040046,"feature_cutoff_ms":1789999040045,"request_ms":1789999040018,"inventory":{"pair_fast":{"qty":[0.0,0.0],"cash":0.0,"lots":[[],[]],"floor":0.0},"pair_250":{"qty":[0.0,0.0],"cash":0.0,"lots":[[],[]],"floor":0.0},"pair_add_fast":{"qty":[0.0,0.0],"cash":0.0,"lots":[[],[]],"floor":0.0},"pair_add_250":{"qty":[0.0,0.0],"cash":0.0,"lots":[[],[]],"floor":0.0}}}
{"kind":"decision","recorded_ms":1789999051114,"S":1789998900,"age":150,"signal":{"rsi14":70.28413236619566,"volume_ratio":0.7834175645655405,"taker_buy_fraction":0.4413220151495373,"volume5":258.85543,"return1":19.725697404672033,"return5":-14.016364806730095,"return15":69.83420158873213,"bollinger_z":1.188536668029354,"bar_close_ms":1789999019999,"ref":85426.38316465008,"reference_received_ms":1789998901464,"spot":85552.79582869148,"twap":85560.81618948943,"sigma":11.142760188986175,"spot_z":0.9297569003526671,"twap_z":0.9887461309946934,"momentum":-1.552263710267877,"decision_ms":1789999051113,"momentum30":-0.4649304771262086,"momentum60":1.095486165362011,"spot_twap_gap":-0.0929234865634566,"range60":1.9893543292873574,"final_mean":85552.79582869148,"final_z":1.0872008506552695,"final_up_prob":0.8615259725126556,"final_drift_up_prob":3.3127969354396214e-06,"final_known_seconds":0,"final_sd":116.27351465482468,"final_drift_shift":-650.2684103777584},"entry_side":1,"context_gap":null,"book_errors":[null,null],"books":[{"bid":0.8,"ask":0.82,"asks":[[0.82,64.16]],"received_ms":1789999050062,"observed_ms":1789999050049,"hash":"11d09db529ed693c89689af082f15d3aef189578"},{"bid":0.15,"ask":0.17,"asks":[[0.17,358.0]],"received_ms":1789999051113,"observed_ms":1789999051100,"hash":"1e359326c3c3122c8bd1b73b9eb654c59cb6cf33"}],"intents":{"pair_fast":{"kind":"first","side":1,"qty":5.0,"max_cost":0.9493900000000002},"pair_250":{"kind":"first","side":1,"qty":5.0,"max_cost":0.9493900000000002},"pair_add_fast":{"kind":"first","side":1,"qty":5.0,"max_cost":0.9493900000000002},"pair_add_250":{"kind":"first","side":1,"qty":5.0,"max_cost":0.9493900000000002}},"decision_ms":1789999051114,"feature_cutoff_ms":1789999051113,"request_ms":1789999050022,"inventory":{"pair_fast":{"qty":[0.0,0.0],"cash":0.0,"lots":[[],[]],"floor":0.0},"pair_250":{"qty":[0.0,0.0],"cash":0.0,"lots":[[],[]],"floor":0.0},"pair_add_fast":{"qty":[0.0,0.0],"cash":0.0,"lots":[[],[]],"floor":0.0},"pair_add_250":{"qty":[0.0,0.0],"cash":0.0,"lots":[[],[]],"floor":0.0}}}
{"kind":"decision","recorded_ms":1789999180076,"S":1789998900,"age":280,"signal":{"rsi14":64.41545655919258,"volume_ratio":0.5529454232126533,"taker_buy_fraction":0.42105863541891986,"volume5":151.21901,"return1":-12.46219319861753,"return5":3.668240836387052,"return15":44.09492181418385,"bollinger_z":0.517069039937145,"bar_close_ms":1789999139999,"ref":85426.38316465008,"reference_received_ms":1789998901464,"spot":85392.80809228576,"twap":85416.66607749683,"sigma":6.9749199108246716,"spot_z":-1.0783967433129698,"twap_z":-0.3121028311374166,"momentum":0.07410468519159674,"decision_ms":1789999180075,"momentum30":-0.35122828871804374,"momentum60":-0.46244748688217696,"spot_twap_gap":-0.44158967929814497,"range60":1.2425841227848515,"final_mean":85401.95409072193,"final_z":-4.092438510401919,"final_up_prob":2.13430228372391e-05,"final_drift_up_prob":3.1424634833576714e-05,"final_known_seconds":40,"final_sd":5.969319726136369,"final_drift_shift":0.5407547013206595},"entry_side":null,"context_gap":null,"book_errors":[null,null],"books":[{"bid":null,"ask":0.01,"asks":[[0.01,13898.13]],"received_ms":1789999180075,"observed_ms":1789999180061,"hash":"104d6c7c7230be5c17df136329bbde7062d2584a"},{"bid":0.99,"ask":null,"asks":[],"received_ms":1789999180073,"observed_ms":1789999180061,"hash":"ec67ff04b45eba766aa0a77680e5d577ff912cb6"}],"intents":{"pair_fast":null,"pair_250":null,"pair_add_fast":null,"pair_add_250":null},"decision_ms":1789999180076,"feature_cutoff_ms":1789999180075,"request_ms":1789999180037,"inventory":{"pair_fast":{"qty":[10.0,10.0],"cash":8.84313,"lots":[[],[]],"floor":1.1568699999999996},"pair_250":{"qty":[10.0,10.0],"cash":9.1919,"lots":[[],[]],"floor":0.8080999999999996},"pair_add_fast":{"qty":[10.0,10.0],"cash":8.13906,"lots":[[],[]],"floor":1.8609399999999994},"pair_add_250":{"qty":[10.0,10.0],"cash":8.13906,"lots":[[],[]],"floor":1.8609399999999994}}}
{"kind":"decision","recorded_ms":1789999190087,"S":1789998900,"age":290,"signal":{"rsi14":64.41545655919258,"volume_ratio":0.5529454232126533,"taker_buy_fraction":0.42105863541891986,"volume5":151.21901,"return1":-12.46219319861753,"return5":3.668240836387052,"return15":44.09492181418385,"bollinger_z":0.517069039937145,"bar_close_ms":1789999139999,"ref":85426.38316465008,"reference_received_ms":1789998901464,"spot":85404.70215280328,"twap":85413.34445709016,"sigma":6.700413001607457,"spot_z":-1.0276696151369442,"twap_z":-0.6180285161348884,"momentum":-0.03416302180949535,"decision_ms":1789999190086,"momentum30":-0.11172021014184043,"momentum60":-0.45982500890641603,"spot_twap_gap":-0.16651461418836475,"range60":1.293491123130386,"final_mean":85405.96800052664,"final_z":-10.14354608477483,"final_up_prob":0.0,"final_drift_up_prob":0.0,"final_known_seconds":50,"final_sd":2.012625954751404,"final_drift_shift":-0.059289042540981045},"entry_side":null,"context_gap":null,"book_errors":[null,null],"books":[{"bid":null,"ask":0.01,"asks":[[0.01,24136.74]],"received_ms":1789999190083,"observed_ms":1789999190056,"hash":"bf90556e3e48aefba888f0b05b4f7dffa44a8e1a"},{"bid":0.99,"ask":null,"asks":[],"received_ms":1789999190086,"observed_ms":1789999190077,"hash":"ea9c0b2588a610d5039881ab4ede24f35e5b28ba"}],"intents":{"pair_fast":null,"pair_250":null,"pair_add_fast":null,"pair_add_250":null},"decision_ms":1789999190087,"feature_cutoff_ms":1789999190086,"request_ms":1789999190048,"inventory":{"pair_fast":{"qty":[10.0,10.0],"cash":8.84313,"lots":[[],[]],"floor":1.1568699999999996},"pair_250":{"qty":[10.0,10.0],"cash":9.1919,"lots":[[],[]],"floor":0.8080999999999996},"pair_add_fast":{"qty":[10.0,10.0],"cash":8.13906,"lots":[[],[]],"floor":1.8609399999999994},"pair_add_250":{"qty":[10.0,10.0],"cash":8.13906,"lots":[[],[]],"floor":1.8609399999999994}}}
{"kind":"decision","recorded_ms":1789999230069,"S":1789999200,"age":30,"signal":{"rsi14":58.5374817224307,"volume_ratio":0.707748511582004,"taker_buy_fraction":0.49491660345954985,"volume5":142.45495,"return1":-2.835034236871554,"return5":6.912662926714979,"return15":45.13589794531915,"bollinger_z":0.34135036641209054,"bar_close_ms":1789999199999,"ref":85408.50237928922,"reference_received_ms":1789999201674,"spot":85459.55170358,"twap":85415.73366541565,"sigma":7.077855095504572,"spot_z":0.43899658786123347,"twap_z":0.06218515091936218,"momentum":1.5527177444939737,"decision_ms":1789999230068,"momentum30":0.8192787190917189,"momentum60":1.247210641419019,"spot_twap_gap":0.7992371030680566,"range60":1.247210641419019,"final_mean":85459.55170358,"final_z":0.4756512281715112,"final_up_prob":0.68283856369345,"final_drift_up_prob":1.0,"final_known_seconds":0,"final_sd":107.32511821114399,"final_drift_shift":833.8392944843052},"entry_side":null,"context_gap":null,"book_errors":[null,null],"books":[{"bid":0.62,"ask":0.63,"asks":[[0.63,163.0]],"received_ms":1789999230067,"observed_ms":1789999230053,"hash":"0f7d0463ab913b34e8021368c25063db5ce68887"},{"bid":0.37,"ask":0.38,"asks":[[0.38,1865.69]],"received_ms":1789999230058,"observed_ms":1789999230048,"hash":"48403650a82d2488f94737de1d60f54c51744f99"}],"intents":{"pair_fast":null,"pair_250":null,"pair_add_fast":null,"pair_add_250":null},"decision_ms":1789999230069,"feature_cutoff_ms":1789999230068,"request_ms":1789999230033,"inventory":{"pair_fast":{"qty":[0.0,0.0],"cash":0.0,"lots":[[],[]],"floor":0.0},"pair_250":{"qty":[0.0,0.0],"cash":0.0,"lots":[[],[]],"floor":0.0},"pair_add_fast":{"qty":[0.0,0.0],"cash":0.0,"lots":[[],[]],"floor":0.0},"pair_add_250":{"qty":[0.0,0.0],"cash":0.0,"lots":[[],[]],"floor":0.0}}}
{"kind":"decision","recorded_ms":1789999240089,"S":1789999200,"age":40,"signal":{"rsi14":58.5374817224307,"volume_ratio":0.707748511582004,"taker_buy_fraction":0.49491660345954985,"volume5":142.45495,"return1":-2.835034236871554,"return5":6.912662926714979,"return15":45.13589794531915,"bollinger_z":0.34135036641209054,"bar_close_ms":1789999199999,"ref":85408.50237928922,"reference_received_ms":1789999201674,"spot":85427.96404374,"twap":85424.1560568441,"sigma":7.172617546493819,"spot_z":0.1683019471699797,"twap_z":0.13537097094249617,"momentum":-1.1814467359591903,"decision_ms":1789999240088,"momentum30":-0.37649186867506834,"momentum60":0.4056603547404008,"spot_twap_gap":0.06853969156425777,"range60":0.9180356222212389,"final_mean":85427.96404374,"final_z":0.18296913798260245,"final_up_prob":0.5725888829381082,"final_drift_up_prob":1.0155304430714551e-08,"final_known_seconds":0,"final_sd":106.36583122902063,"final_drift_shift":-616.1031941132019},"entry_side":null,"context_gap":null,"book_errors":[null,null],"books":[{"bid":0.5,"ask":0.51,"asks":[[0.51,682.67]],"received_ms":1789999240068,"observed_ms":1789999240058,"hash":"2eca94774da425643a7d132a9778c56108b699b4"},{"bid":0.49,"ask":0.5,"asks":[[0.5,97.5]],"received_ms":1789999240088,"observed_ms":1789999240077,"hash":"2725d5dee63b75d792dcae261db6c4b0cae20b1f"}],"intents":{"pair_fast":null,"pair_250":null,"pair_add_fast":null,"pair_add_250":null},"decision_ms":1789999240089,"feature_cutoff_ms":1789999240088,"request_ms":1789999240041,"inventory":{"pair_fast":{"qty":[0.0,0.0],"cash":0.0,"lots":[[],[]],"floor":0.0},"pair_250":{"qty":[0.0,0.0],"cash":0.0,"lots":[[],[]],"floor":0.0},"pair_add_fast":{"qty":[0.0,0.0],"cash":0.0,"lots":[[],[]],"floor":0.0},"pair_add_250":{"qty":[0.0,0.0],"cash":0.0,"lots":[[],[]],"floor":0.0}}}
{"kind":"decision","recorded_ms":1789999250060,"S":1789999200,"age":50,"signal":{"rsi14":58.5374817224307,"volume_ratio":0.707748511582004,"taker_buy_fraction":0.49491660345954985,"volume5":142.45495,"return1":-2.835034236871554,"return5":6.912662926714979,"return15":45.13589794531915,"bollinger_z":0.34135036641209054,"bar_close_ms":1789999199999,"ref":85408.50237928922,"reference_received_ms":1789999201674,"spot":85413.89561358745,"twap":85427.19057916067,"sigma":7.4936933669146635,"spot_z":0.04552339237195129,"twap_z":0.1577439822617796,"momentum":-0.16265197212214857,"decision_ms":1789999250059,"momentum30":-0.265636071799667,"momentum60":0.011804085603253297,"spot_twap_gap":-0.22904228810513647,"range60":0.8215958341478884,"final_mean":85413.89561358745,"final_z":0.0496712098949159,"final_up_prob":0.5198078003475177,"final_drift_up_prob":0.23236282143276732,"final_known_seconds":0,"final_sd":108.57867786268328,"final_drift_shift":-84.7737601904537},"entry_side":null,"context_gap":null,"book_errors":[null,null],"books":[{"bid":0.47,"ask":0.48,"asks":[[0.48,215.04]],"received_ms":1789999250045,"observed_ms":1789999250036,"hash":"565a5e6c6fa02605fac9c41b5fe91d7a1ffaa547"},{"bid":0.52,"ask":0.53,"asks":[[0.53,581.02]],"received_ms":1789999250059,"observed_ms":1789999250048,"hash":"5d56c87e9a1b09514c1e008fce5379d125b1e4de"}],"intents":{"pair_fast":null,"pair_250":null,"pair_add_fast":null,"pair_add_250":null},"decision_ms":1789999250060,"feature_cutoff_ms":1789999250059,"request_ms":1789999250011,"inventory":{"pair_fast":{"qty":[0.0,0.0],"cash":0.0,"lots":[[],[]],"floor":0.0},"pair_250":{"qty":[0.0,0.0],"cash":0.0,"lots":[[],[]],"floor":0.0},"pair_add_fast":{"qty":[0.0,0.0],"cash":0.0,"lots":[[],[]],"floor":0.0},"pair_add_250":{"qty":[0.0,0.0],"cash":0.0,"lots":[[],[]],"floor":0.0}}}
{"kind":"decision","recorded_ms":1789999260073,"S":1789999200,"age":60,"signal":{"rsi14":58.5374817224307,"volume_ratio":0.707748511582004,"taker_buy_fraction":0.49491660345954985,"volume5":142.45495,"return1":-2.835034236871554,"return5":6.912662926714979,"return15":45.13589794531915,"bollinger_z":0.34135036641209054,"bar_close_ms":1789999199999,"ref":85408.50237928922,"reference_received_ms":1789999201674,"spot":85398.65009820317,"twap":85425.95309240464,"sigma":7.325310976525554,"spot_z":-0.08683009189884648,"twap_z":0.1537965685590234,"momentum":-0.13458611481546276,"decision_ms":1789999260072,"momentum30":-1.3985036023084556,"momentum60":-0.5135669830548245,"spot_twap_gap":-0.4811811274759137,"range60":1.113414501410735,"final_mean":85398.65009820317,"final_z":-0.09512045452035638,"final_up_prob":0.46210957569058453,"final_drift_up_prob":0.23361319328705787,"final_known_seconds":0,"final_sd":103.5768924331256,"final_drift_shift":-65.44804686849017},"entry_side":null,"context_gap":null,"book_errors":[null,null],"books":[{"bid":0.55,"ask":0.56,"asks":[[0.56,10.0]],"received_ms":1789999260068,"observed_ms":1789999260060,"hash":"4c358e75c3db355857726bae1ec3e41b3e665830"},{"bid":0.44,"ask":0.45,"asks":[[0.45,464.01]],"received_ms":1789999260072,"observed_ms":1789999260062,"hash":"ae688bba67a596eeabc220154f9b6bcb7a4e9f3d"}],"intents":{"pair_fast":null,"pair_250":null,"pair_add_fast":null,"pair_add_250":null},"decision_ms":1789999260073,"feature_cutoff_ms":1789999260072,"request_ms":1789999260032,"inventory":{"pair_fast":{"qty":[0.0,0.0],"cash":0.0,"lots":[[],[]],"floor":0.0},"pair_250":{"qty":[0.0,0.0],"cash":0.0,"lots":[[],[]],"floor":0.0},"pair_add_fast":{"qty":[0.0,0.0],"cash":0.0,"lots":[[],[]],"floor":0.0},"pair_add_250":{"qty":[0.0,0.0],"cash":0.0,"lots":[[],[]],"floor":0.0}}}
{"kind":"decision","recorded_ms":1789999270060,"S":1789999200,"age":70,"signal":{"rsi14":54.163068108939754,"volume_ratio":0.36053333555279954,"taker_buy_fraction":0.4903968605488818,"volume5":131.76316,"return1":-0.6763353762248734,"return5":1.7821086124401626,"return15":24.875802358420835,"bollinger_z":0.2405190723362708,"bar_close_ms":1789999259999,"ref":85408.50237928922,"reference_received_ms":1789999201674,"spot":85454.20838851236,"twap":85426.9017460832,"sigma":7.886855014312628,"spot_z":0.3821740880227534,"twap_z":0.1538476306333286,"momentum":1.314124620894063,"decision_ms":1789999270059,"momentum30":0.8439816108476964,"momentum60":0.18748112264059427,"spot_twap_gap":0.4469807512080008,"range60":1.034139394448805,"final_mean":85454.20838851236,"final_z":0.42049427346987556,"final_up_prob":0.6629377940547588,"final_drift_up_prob":0.9999999999438045,"final_known_seconds":0,"final_sd":108.69591361132967,"final_drift_shift":655.3031704896306},"entry_side":null,"context_gap":null,"book_errors":[null,null],"books":[{"bid":0.61,"ask":0.62,"asks":[[0.62,1158.99]],"received_ms":1789999270051,"observed_ms":1789999270041,"hash":"c5d7095ac52f21067559b805f1adead367dcfd78"},{"bid":0.38,"ask":0.39,"asks":[[0.39,75.18]],"received_ms":1789999270058,"observed_ms":1789999270046,"hash":"336c7f1cb6212ea0f981ae886c964f0bd0f0e12e"}],"intents":{"pair_fast":null,"pair_250":null,"pair_add_fast":null,"pair_add_250":null},"decision_ms":1789999270060,"feature_cutoff_ms":1789999270059,"request_ms":1789999270019,"inventory":{"pair_fast":{"qty":[0.0,0.0],"cash":0.0,"lots":[[],[]],"floor":0.0},"pair_250":{"qty":[0.0,0.0],"cash":0.0,"lots":[[],[]],"floor":0.0},"pair_add_fast":{"qty":[0.0,0.0],"cash":0.0,"lots":[[],[]],"floor":0.0},"pair_add_250":{"qty":[0.0,0.0],"cash":0.0,"lots":[[],[]],"floor":0.0}}}
{"kind":"decision","recorded_ms":1789999280079,"S":1789999200,"age":80,"signal":{"rsi14":54.163068108939754,"volume_ratio":0.36053333555279954,"taker_buy_fraction":0.4903968605488818,"volume5":131.76316,"return1":-0.6763353762248734,"return5":1.7821086124401626,"return15":24.875802358420835,"bollinger_z":0.2405190723362708,"bar_close_ms":1789999259999,"ref":85408.50237928922,"reference_received_ms":1789999201674,"spot":85468.2122022149,"twap":85429.47031691129,"sigma":7.862810041716751,"spot_z":0.5120751035416151,"twap_z":0.1798223190553056,"momentum":1.0029268471672896,"decision_ms":1789999280078,"momentum30":1.5428381694571704,"momentum60":0.7128085246882485,"spot_twap_gap":0.6361028512091028,"range60":1.2581506538495546,"final_mean":85468.2122022149,"final_z":0.5661426386014594,"final_up_prob":0.7143515900287569,"final_drift_up_prob":0.9999997867380954,"final_known_seconds":0,"final_sd":105.46780767684588,"final_drift_shift":473.61158327737115},"entry_side":null,"context_gap":null,"book_errors":[null,null],"books":[{"bid":0.75,"ask":0.76,"asks":[[0.76,203.56]],"received_ms":1789999280072,"observed_ms":1789999280054,"hash":"a0693585db81903acf67dd5a51f2a350c8b42e45"},{"bid":0.24,"ask":0.25,"asks":[[0.25,1335.08]],"received_ms":1789999280078,"observed_ms":1789999280065,"hash":"441d8659647482e3ba382c7c27395a22e3d020df"}],"intents":{"pair_fast":null,"pair_250":null,"pair_add_fast":null,"pair_add_250":null},"decision_ms":1789999280079,"feature_cutoff_ms":1789999280078,"request_ms":1789999280032,"inventory":{"pair_fast":{"qty":[0.0,0.0],"cash":0.0,"lots":[[],[]],"floor":0.0},"pair_250":{"qty":[0.0,0.0],"cash":0.0,"lots":[[],[]],"floor":0.0},"pair_add_fast":{"qty":[0.0,0.0],"cash":0.0,"lots":[[],[]],"floor":0.0},"pair_add_250":{"qty":[0.0,0.0],"cash":0.0,"lots":[[],[]],"floor":0.0}}}
{"kind":"decision","recorded_ms":1789999290054,"S":1789999200,"age":90,"signal":{"rsi14":54.163068108939754,"volume_ratio":0.36053333555279954,"taker_buy_fraction":0.4903968605488818,"volume5":131.76316,"return1":-0.6763353762248734,"return5":1.7821086124401626,"return15":24.875802358420835,"bollinger_z":0.2405190723362708,"bar_close_ms":1789999259999,"ref":85408.50237928922,"reference_received_ms":1789999201674,"spot":85467.95136712,"twap":85438.56278851311,"sigma":10.443985254515956,"spot_z":0.3928469431690459,"twap_z":0.19864324532541616,"momentum":-0.9165317958335965,"decision_ms":1789999290053,"momentum30":0.8131905874159971,"momentum60":0.16304297823308328,"spot_twap_gap":0.36327599966037977,"range60":1.4218356381753425,"final_mean":85467.95136712,"final_z":0.4366379340596848,"final_up_prob":0.6688130262923114,"final_drift_up_prob":0.0001825835644142515,"final_known_seconds":0,"final_sd":136.15167898502682,"final_drift_shift":-544.7012809680848},"entry_side":null,"context_gap":null,"book_errors":[null,null],"books":[{"bid":0.71,"ask":0.72,"asks":[[0.72,80.0]],"received_ms":1789999290050,"observed_ms":1789999290036,"hash":"ee42caac7b7250b613841774fd78d6b6fb95d8b6"},{"bid":0.28,"ask":0.29,"asks":[[0.29,86.0]],"received_ms":1789999290053,"observed_ms":1789999290036,"hash":"1c395e685a42945235cd5fd7853d3180780f4688"}],"intents":{"pair_fast":null,"pair_250":null,"pair_add_fast":null,"pair_add_250":null},"decision_ms":1789999290054,"feature_cutoff_ms":1789999290053,"request_ms":1789999290002,"inventory":{"pair_fast":{"qty":[0.0,0.0],"cash":0.0,"lots":[[],[]],"floor":0.0},"pair_250":{"qty":[0.0,0.0],"cash":0.0,"lots":[[],[]],"floor":0.0},"pair_add_fast":{"qty":[0.0,0.0],"cash":0.0,"lots":[[],[]],"floor":0.0},"pair_add_250":{"qty":[0.0,0.0],"cash":0.0,"lots":[[],[]],"floor":0.0}}}
{"kind":"decision","recorded_ms":1789999300068,"S":1789999200,"age":100,"signal":{"rsi14":54.163068108939754,"volume_ratio":0.36053333555279954,"taker_buy_fraction":0.4903968605488818,"volume5":131.76316,"return1":-0.6763353762248734,"return5":1.7821086124401626,"return15":24.875802358420835,"bollinger_z":0.2405190723362708,"bar_close_ms":1789999259999,"ref":85408.50237928922,"reference_received_ms":1789999201674,"spot":85470.87807950331,"twap":85442.93338391976,"sigma":9.399667113509958,"spot_z":0.46931098430352963,"twap_z":0.25905679003617677,"momentum":-0.21484649848799606,"decision_ms":1789999300067,"momentum30":0.5361469199913819,"momentum60":0.7296860078394283,"spot_twap_gap":0.3838055798605483,"range60":1.579803865405561,"final_mean":85470.87807950331,"final_z":0.5247276125087917,"final_up_prob":0.7001137204292138,"final_drift_up_prob":0.34893353452613657,"final_known_seconds":0,"final_sd":118.87253258098139,"final_drift_shift":-108.5221722419329},"entry_side":null,"context_gap":null,"book_errors":[null,null],"books":[{"bid":0.66,"ask":0.67,"asks":[[0.67,1678.8]],"received_ms":1789999300063,"observed_ms":1789999300053,"hash":"c6e256dd3f66effa68002f2936b2e6d10a2628d6"},{"bid":0.33,"ask":0.34,"asks":[[0.34,162.57]],"received_ms":1789999300067,"observed_ms":1789999300056,"hash":"9d5e12cb8bfc2050c03e8620a31128a7cb38d833"}],"intents":{"pair_fast":null,"pair_250":null,"pair_add_fast":null,"pair_add_250":null},"decision_ms":1789999300068,"feature_cutoff_ms":1789999300067,"request_ms":1789999300028,"inventory":{"pair_fast":{"qty":[0.0,0.0],"cash":0.0,"lots":[[],[]],"floor":0.0},"pair_250":{"qty":[0.0,0.0],"cash":0.0,"lots":[[],[]],"floor":0.0},"pair_add_fast":{"qty":[0.0,0.0],"cash":0.0,"lots":[[],[]],"floor":0.0},"pair_add_250":{"qty":[0.0,0.0],"cash":0.0,"lots":[[],[]],"floor":0.0}}}
{"kind":"decision","recorded_ms":1789999310096,"S":1789999200,"age":110,"signal":{"rsi14":54.163068108939754,"volume_ratio":0.36053333555279954,"taker_buy_fraction":0.4903968605488818,"volume5":131.76316,"return1":-0.6763353762248734,"return5":1.7821086124401626,"return15":24.875802358420835,"bollinger_z":0.2405190723362708,"bar_close_ms":1789999259999,"ref":85408.50237928922,"reference_received_ms":1789999201674,"spot":85475.32365578311,"twap":85450.0338939665,"sigma":9.808624365138195,"spot_z":0.49435446965692176,"twap_z":0.3072567749317101,"momentum":0.2911193586839547,"decision_ms":1789999310095,"momentum30":-0.42621148674840353,"momentum60":0.9681304372417693,"spot_twap_gap":0.3328595417635144,"range60":1.5139360920199074,"final_mean":85475.32365578311,"final_z":0.5564147132209213,"final_up_prob":0.7110363085039724,"final_drift_up_prob":0.9606898866093745,"final_known_seconds":0,"final_sd":120.09257646528731,"final_drift_shift":144.3913684710486},"entry_side":null,"context_gap":null,"book_errors":[null,null],"books":[{"bid":0.69,"ask":0.7,"asks":[[0.7,22.85]],"received_ms":1789999310095,"observed_ms":1789999310085,"hash":"b20442c6f6785c307637e9af88ec1addf2f9b225"},{"bid":0.3,"ask":0.31,"asks":[[0.31,588.12]],"received_ms":1789999310077,"observed_ms":1789999310065,"hash":"96892c7b74dc6e2019f33e147f31fb6a070e123f"}],"intents":{"pair_fast":null,"pair_250":null,"pair_add_fast":null,"pair_add_250":null},"decision_ms":1789999310096,"feature_cutoff_ms":1789999310095,"request_ms":1789999310041,"inventory":{"pair_fast":{"qty":[0.0,0.0],"cash":0.0,"lots":[[],[]],"floor":0.0},"pair_250":{"qty":[0.0,0.0],"cash":0.0,"lots":[[],[]],"floor":0.0},"pair_add_fast":{"qty":[0.0,0.0],"cash":0.0,"lots":[[],[]],"floor":0.0},"pair_add_250":{"qty":[0.0,0.0],"cash":0.0,"lots":[[],[]],"floor":0.0}}}
{"kind":"decision","recorded_ms":1789999320077,"S":1789999200,"age":120,"signal":{"rsi14":54.163068108939754,"volume_ratio":0.36053333555279954,"taker_buy_fraction":0.4903968605488818,"volume5":131.76316,"return1":-0.6763353762248734,"return5":1.7821086124401626,"return15":24.875802358420835,"bollinger_z":0.2405190723362708,"bar_close_ms":1789999259999,"ref":85408.50237928922,"reference_received_ms":1789999201674,"spot":85460.12232860207,"twap":85460.10065958386,"sigma":10.712523564906611,"spot_z":0.3592371437081432,"twap_z":0.35908634316855487,"momentum":-0.44383949455154376,"decision_ms":1789999320076,"momentum30":-0.29215086251137945,"momentum60":0.46624853022711205,"spot_twap_gap":0.0002611390495751377,"range60":1.0264740457668573,"final_mean":85460.12232860207,"final_z":0.40736121522737845,"final_up_prob":0.6581286457336719,"final_drift_up_prob":0.0851038724147174,"final_known_seconds":0,"final_sd":126.71787932495884,"final_drift_shift":-225.41815762740774},"entry_side":null,"context_gap":null,"book_errors":[null,null],"books":[{"bid":0.67,"ask":0.68,"asks":[[0.68,7.0]],"received_ms":1789999320052,"observed_ms":1789999320040,"hash":"a51117e44629de48ea4cfdf03d85f5b21e63d385"},{"bid":0.31,"ask":0.33,"asks":[[0.33,252.12]],"received_ms":1789999320076,"observed_ms":1789999320055,"hash":"a7b8130ee1ea2010991b0498971d0d85afceab1f"}],"intents":{"pair_fast":null,"pair_250":null,"pair_add_fast":null,"pair_add_250":null},"decision_ms":1789999320077,"feature_cutoff_ms":1789999320076,"request_ms":1789999320020,"inventory":{"pair_fast":{"qty":[0.0,0.0],"cash":0.0,"lots":[[],[]],"floor":0.0},"pair_250":{"qty":[0.0,0.0],"cash":0.0,"lots":[[],[]],"floor":0.0},"pair_add_fast":{"qty":[0.0,0.0],"cash":0.0,"lots":[[],[]],"floor":0.0},"pair_add_250":{"qty":[0.0,0.0],"cash":0.0,"lots":[[],[]],"floor":0.0}}}
{"kind":"decision","recorded_ms":1789999330052,"S":1789999200,"age":130,"signal":{"rsi14":52.25438674623646,"volume_ratio":0.46911587074947075,"taker_buy_fraction":0.4434570460745746,"volume5":115.2805,"return1":3.6366124644917384,"return5":-14.335902980000062,"return15":15.026028857788084,"bollinger_z":0.3047735160714055,"bar_close_ms":1789999319999,"ref":85408.50237928922,"reference_received_ms":1789999201674,"spot":85458.43143040269,"twap":85466.14134311193,"sigma":9.70295873206742,"spot_z":0.39472062665807356,"twap_z":0.4556723473137007,"momentum":0.09312007862834641,"decision_ms":1789999330051,"momentum30":-0.14794166787076132,"momentum60":0.2016582485453242,"spot_twap_gap":-0.10258164321535516,"range60":0.93936801075155,"final_mean":85458.43143040269,"final_z":0.4514011462100387,"final_up_prob":0.674149771314569,"final_drift_up_prob":0.7918670130360737,"final_known_seconds":0,"final_sd":110.6090481441596,"final_drift_shift":39.986861413117026},"entry_side":null,"context_gap":null,"book_errors":[null,null],"books":[{"bid":0.65,"ask":0.66,"asks":[[0.66,145.0]],"received_ms":1789999330048,"observed_ms":1789999330039,"hash":"cdd787c809ac9604b414e34cfd23781cc2ef0f90"},{"bid":0.34,"ask":0.35,"asks":[[0.35,176.28]],"received_ms":1789999330051,"observed_ms":1789999330043,"hash":"27f8a36e687285feab273b81e9c16f76d9b5866d"}],"intents":{"pair_fast":null,"pair_250":null,"pair_add_fast":null,"pair_add_250":null},"decision_ms":1789999330052,"feature_cutoff_ms":1789999330051,"request_ms":1789999330023,"inventory":{"pair_fast":{"qty":[0.0,0.0],"cash":0.0,"lots":[[],[]],"floor":0.0},"pair_250":{"qty":[0.0,0.0],"cash":0.0,"lots":[[],[]],"floor":0.0},"pair_add_fast":{"qty":[0.0,0.0],"cash":0.0,"lots":[[],[]],"floor":0.0},"pair_add_250":{"qty":[0.0,0.0],"cash":0.0,"lots":[[],[]],"floor":0.0}}}
{"kind":"decision","recorded_ms":1789999340079,"S":1789999200,"age":140,"signal":{"rsi14":52.25438674623646,"volume_ratio":0.46911587074947075,"taker_buy_fraction":0.4434570460745746,"volume5":115.2805,"return1":3.6366124644917384,"return5":-14.335902980000062,"return15":15.026028857788084,"bollinger_z":0.3047735160714055,"bar_close_ms":1789999319999,"ref":85408.50237928922,"reference_received_ms":1789999201674,"spot":85468.86460334742,"twap":85468.06284843419,"sigma":7.842374358937629,"spot_z":0.6086442972918985,"twap_z":0.6005600432177698,"momentum":0.426395341385237,"decision_ms":1789999340078,"momentum30":-0.14650914892976394,"momentum60":-0.48326616589072846,"spot_twap_gap":0.013198313353314133,"range60":1.1622308022262373,"final_mean":85468.86460334742,"final_z":0.7028590352871811,"final_up_prob":0.7589281988359105,"final_drift_up_prob":0.9893489108218891,"final_known_seconds":0,"final_sd":85.88098185796396,"final_drift_shift":137.38607553714348},"entry_side":null,"context_gap":null,"book_errors":[null,null],"books":[{"bid":0.68,"ask":0.69,"asks":[[0.69,1273.24]],"received_ms":1789999340077,"observed_ms":1789999340064,"hash":"d8c6c606aa8c6196372af0affc4045be5a2db3ca"},{"bid":0.31,"ask":0.32,"asks":[[0.32,724.19]],"received_ms":1789999340053,"observed_ms":1789999340044,"hash":"048ec1ffe633d6fdf9a71ceecb3fa826f3156681"}],"intents":{"pair_fast":null,"pair_250":null,"pair_add_fast":null,"pair_add_250":null},"decision_ms":1789999340079,"feature_cutoff_ms":1789999340078,"request_ms":1789999340027,"inventory":{"pair_fast":{"qty":[0.0,0.0],"cash":0.0,"lots":[[],[]],"floor":0.0},"pair_250":{"qty":[0.0,0.0],"cash":0.0,"lots":[[],[]],"floor":0.0},"pair_add_fast":{"qty":[0.0,0.0],"cash":0.0,"lots":[[],[]],"floor":0.0},"pair_add_250":{"qty":[0.0,0.0],"cash":0.0,"lots":[[],[]],"floor":0.0}}}
{"kind":"decision","recorded_ms":1789999350032,"S":1789999200,"age":150,"signal":{"rsi14":52.25438674623646,"volume_ratio":0.46911587074947075,"taker_buy_fraction":0.4434570460745746,"volume5":115.2805,"return1":3.6366124644917384,"return5":-14.335902980000062,"return15":15.026028857788084,"bollinger_z":0.3047735160714055,"bar_close_ms":1789999319999,"ref":85408.50237928922,"reference_received_ms":1789999201674,"spot":85461.74389646896,"twap":85463.91059564831,"sigma":7.352147855988031,"spot_z":0.5913355578801063,"twap_z":0.6154003542241236,"momentum":0.24914252046782812,"decision_ms":1789999350030,"momentum30":0.15321101277275118,"momentum60":-0.2725284540530743,"spot_twap_gap":-0.03804597877256134,"range60":0.7885514237084467,"final_mean":85461.74389646896,"final_z":0.6905562777756548,"final_up_prob":0.7550777840954774,"final_drift_up_prob":0.9442947708865485,"final_known_seconds":0,"final_sd":77.0994615402575,"final_drift_shift":69.49198944928641},"entry_side":null,"context_gap":null,"book_errors":[null,null],"books":[{"bid":0.69,"ask":0.7,"asks":[[0.7,914.14]],"received_ms":1789999350029,"observed_ms":1789999350019,"hash":"64e97640f6622d626827e9c8f89a2523e33c5a35"},{"bid":0.3,"ask":0.31,"asks":[[0.31,704.72]],"received_ms":1789999350030,"observed_ms":1789999350002,"hash":"4113b0e505bb2ab7f9f58566b36216fbc65f15f5"}],"intents":{"pair_fast":null,"pair_250":null,"pair_add_fast":null,"pair_add_250":null},"decision_ms":1789999350032,"feature_cutoff_ms":1789999350030,"request_ms":1789999350003,"inventory":{"pair_fast":{"qty":[0.0,0.0],"cash":0.0,"lots":[[],[]],"floor":0.0},"pair_250":{"qty":[0.0,0.0],"cash":0.0,"lots":[[],[]],"floor":0.0},"pair_add_fast":{"qty":[0.0,0.0],"cash":0.0,"lots":[[],[]],"floor":0.0},"pair_add_250":{"qty":[0.0,0.0],"cash":0.0,"lots":[[],[]],"floor":0.0}}}
{"kind":"decision","recorded_ms":1789999360048,"S":1789999200,"age":160,"signal":{"rsi14":52.25438674623646,"volume_ratio":0.46911587074947075,"taker_buy_fraction":0.4434570460745746,"volume5":115.2805,"return1":3.6366124644917384,"return5":-14.335902980000062,"return15":15.026028857788084,"bollinger_z":0.3047735160714055,"bar_close_ms":1789999319999,"ref":85408.50237928922,"reference_received_ms":1789999201674,"spot":85450.93925957468,"twap":85462.11753723849,"sigma":7.220329687855746,"spot_z":0.49681392897706167,"twap_z":0.6276794404849565,"momentum":-0.46794085428837284,"decision_ms":1789999360046,"momentum30":-0.18587427141278323,"momentum60":-0.2745396808514885,"spot_twap_gap":-0.1998675273053455,"range60":0.7000087672339677,"final_mean":85450.93925957468,"final_z":0.5878768141125943,"final_up_prob":0.7216925098825984,"final_drift_up_prob":0.1492741251747467,"final_known_seconds":0,"final_sd":72.18668820868133,"final_drift_shift":-117.47867105884116},"entry_side":null,"context_gap":null,"book_errors":[null,null],"books":[{"bid":0.6,"ask":0.61,"asks":[[0.61,51.96]],"received_ms":1789999360037,"observed_ms":1789999360012,"hash":"a5e61fa2dc76d0a9b02e39b84243c61397e3a5cf"},{"bid":0.39,"ask":0.4,"asks":[[0.4,413.16]],"received_ms":1789999360046,"observed_ms":1789999360012,"hash":"c759fbe7dd730b242f52afc9dccdd324a377f441"}],"intents":{"pair_fast":null,"pair_250":null,"pair_add_fast":null,"pair_add_250":null},"decision_ms":1789999360048,"feature_cutoff_ms":1789999360046,"request_ms":1789999360008,"inventory":{"pair_fast":{"qty":[0.0,0.0],"cash":0.0,"lots":[[],[]],"floor":0.0},"pair_250":{"qty":[0.0,0.0],"cash":0.0,"lots":[[],[]],"floor":0.0},"pair_add_fast":{"qty":[0.0,0.0],"cash":0.0,"lots":[[],[]],"floor":0.0},"pair_add_250":{"qty":[0.0,0.0],"cash":0.0,"lots":[[],[]],"floor":0.0}}}
{"kind":"decision","recorded_ms":1789999370058,"S":1789999200,"age":170,"signal":{"rsi14":52.25438674623646,"volume_ratio":0.46911587074947075,"taker_buy_fraction":0.4434570460745746,"volume5":115.2805,"return1":3.6366124644917384,"return5":-14.335902980000062,"return15":15.026028857788084,"bollinger_z":0.3047735160714055,"bar_close_ms":1789999319999,"ref":85408.50237928922,"reference_received_ms":1789999201674,"spot":85457.46593643815,"twap":85459.8423864457,"sigma":7.35800074183793,"spot_z":0.5837631669585169,"twap_z":0.6120961571108742,"momentum":0.7717677681338047,"decision_ms":1789999370057,"momentum30":0.03757899424991039,"momentum60":-0.3104121502590882,"spot_twap_gap":-0.04169588825941063,"range60":0.6869113311010925,"final_mean":85457.46593643815,"final_z":0.7016644109299597,"final_up_prob":0.7585557637553288,"final_drift_up_prob":0.9994690130542776,"final_known_seconds":0,"final_sd":69.78201599827456,"final_drift_shift":179.4728858167937},"entry_side":null,"context_gap":null,"book_errors":[null,null],"books":[{"bid":0.74,"ask":0.75,"asks":[[0.75,44.0]],"received_ms":1789999370057,"observed_ms":1789999370043,"hash":"8f27c226fd11442d98445b1771eca4c759a62c10"},{"bid":0.25,"ask":0.26,"asks":[[0.26,5.0]],"received_ms":1789999370053,"observed_ms":1789999370037,"hash":"d0c64802cfb4c2157a9d6bc6ad598581a0709316"}],"intents":{"pair_fast":null,"pair_250":null,"pair_add_fast":null,"pair_add_250":null},"decision_ms":1789999370058,"feature_cutoff_ms":1789999370057,"request_ms":1789999370021,"inventory":{"pair_fast":{"qty":[0.0,0.0],"cash":0.0,"lots":[[],[]],"floor":0.0},"pair_250":{"qty":[0.0,0.0],"cash":0.0,"lots":[[],[]],"floor":0.0},"pair_add_fast":{"qty":[0.0,0.0],"cash":0.0,"lots":[[],[]],"floor":0.0},"pair_add_250":{"qty":[0.0,0.0],"cash":0.0,"lots":[[],[]],"floor":0.0}}}
{"kind":"decision","recorded_ms":1789999380063,"S":1789999200,"age":180,"signal":{"rsi14":52.25438674623646,"volume_ratio":0.46911587074947075,"taker_buy_fraction":0.4434570460745746,"volume5":115.2805,"return1":3.6366124644917384,"return5":-14.335902980000062,"return15":15.026028857788084,"bollinger_z":0.3047735160714055,"bar_close_ms":1789999319999,"ref":85408.50237928922,"reference_received_ms":1789999201674,"spot":85478.25388191815,"twap":85460.76494928778,"sigma":7.420115084403345,"spot_z":0.8583502253751376,"twap_z":0.6431343705324696,"momentum":-0.5159678829597563,"decision_ms":1789999380062,"momentum30":0.409192972389179,"momentum60":0.3945944541388911,"spot_twap_gap":0.30428254391332327,"range60":0.88475905292044,"final_mean":85478.25388191815,"final_z":1.051395920755228,"final_up_prob":0.8534616057140509,"final_drift_up_prob":0.2776258499612112,"final_known_seconds":0,"final_sd":66.34180450198984,"final_drift_shift":-108.88712622535938},"entry_side":null,"context_gap":null,"book_errors":[null,null],"books":[{"bid":0.76,"ask":0.77,"asks":[[0.77,641.58]],"received_ms":1789999380058,"observed_ms":1789999380040,"hash":"300f90e4e5360af4af79e34e36f5d01d063e5897"},{"bid":0.23,"ask":0.24,"asks":[[0.24,281.0]],"received_ms":1789999380062,"observed_ms":1789999380040,"hash":"b47c25a159ba011cdf08f0218646cbe334cd28cd"}],"intents":{"pair_fast":null,"pair_250":null,"pair_add_fast":null,"pair_add_250":null},"decision_ms":1789999380063,"feature_cutoff_ms":1789999380062,"request_ms":1789999380029,"inventory":{"pair_fast":{"qty":[0.0,0.0],"cash":0.0,"lots":[[],[]],"floor":0.0},"pair_250":{"qty":[0.0,0.0],"cash":0.0,"lots":[[],[]],"floor":0.0},"pair_add_fast":{"qty":[0.0,0.0],"cash":0.0,"lots":[[],[]],"floor":0.0},"pair_add_250":{"qty":[0.0,0.0],"cash":0.0,"lots":[[],[]],"floor":0.0}}}
{"kind":"decision","recorded_ms":1789999390049,"S":1789999200,"age":190,"signal":{"rsi14":55.75441213025122,"volume_ratio":0.47874652860235956,"taker_buy_fraction":0.4891400660290196,"volume5":123.65775,"return1":2.216099524504756,"return5":-10.11687439919668,"return15":8.135833452227791,"bollinger_z":0.3190015149738675,"bar_close_ms":1789999379999,"ref":85408.50237928922,"reference_received_ms":1789999201674,"spot":85439.63735717842,"twap":85462.66360839091,"sigma":8.147608653608811,"spot_z":0.36443227680401635,"twap_z":0.6339525952539239,"momentum":-1.4511788802868462,"decision_ms":1789999390048,"momentum30":0.0028894424197966626,"momentum60":-0.295554034889988,"spot_twap_gap":-0.3648526058913481,"range60":0.8057596128809573,"final_mean":85439.63735717842,"final_z":0.45689702811911365,"final_up_prob":0.6761274699020813,"final_drift_up_prob":4.24858282040419e-05,"final_known_seconds":0,"final_sd":68.14440885591983,"final_drift_shift":-298.937529866159},"entry_side":null,"context_gap":null,"book_errors":[null,null],"books":[{"bid":0.49,"ask":0.56,"asks":[[0.56,36.0]],"received_ms":1789999390040,"observed_ms":1789999390031,"hash":"40f91374a13417f5733ad41676acafacdb84f5e6"},{"bid":0.44,"ask":0.51,"asks":[[0.51,61.67]],"received_ms":1789999390047,"observed_ms":1789999390031,"hash":"ef2a129e41d1d843ad5accdca04ceabab0ba5c09"}],"intents":{"pair_fast":null,"pair_250":null,"pair_add_fast":null,"pair_add_250":null},"decision_ms":1789999390049,"feature_cutoff_ms":1789999390048,"request_ms":1789999390009,"inventory":{"pair_fast":{"qty":[0.0,0.0],"cash":0.0,"lots":[[],[]],"floor":0.0},"pair_250":{"qty":[0.0,0.0],"cash":0.0,"lots":[[],[]],"floor":0.0},"pair_add_fast":{"qty":[0.0,0.0],"cash":0.0,"lots":[[],[]],"floor":0.0},"pair_add_250":{"qty":[0.0,0.0],"cash":0.0,"lots":[[],[]],"floor":0.0}}}
{"kind":"decision","recorded_ms":1789999400061,"S":1789999200,"age":200,"signal":{"rsi14":55.75441213025122,"volume_ratio":0.47874652860235956,"taker_buy_fraction":0.4891400660290196,"volume5":123.65775,"return1":2.216099524504756,"return5":-10.11687439919668,"return15":8.135833452227791,"bollinger_z":0.3190015149738675,"bar_close_ms":1789999379999,"ref":85408.50237928922,"reference_received_ms":1789999201674,"spot":85404.46653144,"twap":85455.72097509417,"sigma":10.680867425568048,"spot_z":-0.03779692033309018,"twap_z":0.4422162506023044,"momentum":0.13313963032111473,"decision_ms":1789999400059,"momentum30":-1.46823980036674,"momentum60":-0.622297238812434,"spot_twap_gap":-0.6195115021479611,"range60":1.0925563457188903,"final_mean":85404.46653144,"final_z":-0.048805219303125855,"final_up_prob":0.4805372613654683,"final_drift_up_prob":0.6298814294068082,"final_known_seconds":0,"final_sd":82.69295593461457,"final_drift_shift":31.45181471943887},"entry_side":null,"context_gap":null,"book_errors":[null,null],"books":[{"bid":0.44,"ask":0.45,"asks":[[0.45,10.0]],"received_ms":1789999400059,"observed_ms":1789999400047,"hash":"83f8da244d21f5dc08370dd5bb62f775f2d96490"},{"bid":0.55,"ask":0.56,"asks":[[0.56,715.28]],"received_ms":1789999400053,"observed_ms":1789999400046,"hash":"439d4a07f3641214abb5a2b4ae9cfb63e5829688"}],"intents":{"pair_fast":null,"pair_250":null,"pair_add_fast":null,"pair_add_250":null},"decision_ms":1789999400061,"feature_cutoff_ms":1789999400059,"request_ms":1789999400023,"inventory":{"pair_fast":{"qty":[0.0,0.0],"cash":0.0,"lots":[[],[]],"floor":0.0},"pair_250":{"qty":[0.0,0.0],"cash":0.0,"lots":[[],[]],"floor":0.0},"pair_add_fast":{"qty":[0.0,0.0],"cash":0.0,"lots":[[],[]],"floor":0.0},"pair_add_250":{"qty":[0.0,0.0],"cash":0.0,"lots":[[],[]],"floor":0.0}}}
{"kind":"decision","recorded_ms":1789999410096,"S":1789999200,"age":210,"signal":{"rsi14":55.75441213025122,"volume_ratio":0.47874652860235956,"taker_buy_fraction":0.4891400660290196,"volume5":123.65775,"return1":2.216099524504756,"return5":-10.11687439919668,"return15":8.135833452227791,"bollinger_z":0.3190015149738675,"bar_close_ms":1789999379999,"ref":85408.50237928922,"reference_received_ms":1789999201674,"spot":85396.54021936092,"twap":85446.56303955491,"sigma":10.693427977990279,"spot_z":-0.11797791944723511,"twap_z":0.37537681638178627,"momentum":-0.04470214849271919,"decision_ms":1789999410095,"momentum30":-1.3741903187608624,"momentum60":-0.7857376700211319,"spot_twap_gap":-0.6039146970781517,"range60":1.132675494428196,"final_mean":85396.54021936092,"final_z":-0.15835093273853015,"final_up_prob":0.4370901379296219,"final_drift_up_prob":0.3904204370815188,"final_known_seconds":0,"final_sd":75.54208694210968,"final_drift_shift":-9.055416241465712},"entry_side":null,"context_gap":null,"book_errors":[null,null],"books":[{"bid":0.22,"ask":0.23,"asks":[[0.23,207.6]],"received_ms":1789999410095,"observed_ms":1789999410085,"hash":"08e79fb4124842e3d576899f829297d959932d2a"},{"bid":0.77,"ask":0.78,"asks":[[0.78,656.49]],"received_ms":1789999410080,"observed_ms":1789999410067,"hash":"093b0814cf07c64d794eff6b31e5f91fad7d6ce9"}],"intents":{"pair_fast":null,"pair_250":null,"pair_add_fast":null,"pair_add_250":null},"decision_ms":1789999410096,"feature_cutoff_ms":1789999410095,"request_ms":1789999410035,"inventory":{"pair_fast":{"qty":[0.0,0.0],"cash":0.0,"lots":[[],[]],"floor":0.0},"pair_250":{"qty":[0.0,0.0],"cash":0.0,"lots":[[],[]],"floor":0.0},"pair_add_fast":{"qty":[0.0,0.0],"cash":0.0,"lots":[[],[]],"floor":0.0},"pair_add_250":{"qty":[0.0,0.0],"cash":0.0,"lots":[[],[]],"floor":0.0}}}
{"kind":"decision","recorded_ms":1789999420103,"S":1789999200,"age":220,"signal":{"rsi14":55.75441213025122,"volume_ratio":0.47874652860235956,"taker_buy_fraction":0.4891400660290196,"volume5":123.65775,"return1":2.216099524504756,"return5":-10.11687439919668,"return15":8.135833452227791,"bollinger_z":0.3190015149738675,"bar_close_ms":1789999379999,"ref":85408.50237928922,"reference_received_ms":1789999201674,"spot":85344.5852413418,"twap":85430.93647931107,"sigma":12.461438278180422,"spot_z":-0.5738272856530923,"twap_z":0.2014060568888824,"momentum":-0.3421430464666492,"decision_ms":1789999420102,"momentum30":-0.811443951512485,"momentum60":-0.983396007313959,"spot_twap_gap":-0.894591509994374,"range60":1.5289992012551368,"final_mean":85344.5852413418,"final_z":-0.8120328271558531,"final_up_prob":0.20838639765732742,"final_drift_up_prob":0.04778345997736372,"final_known_seconds":0,"final_sd":78.71250497505581,"final_drift_shift":-67.27582427247886},"entry_side":null,"context_gap":null,"book_errors":[null,null],"books":[{"bid":0.14,"ask":0.16,"asks":[[0.16,263.18]],"received_ms":1789999420101,"observed_ms":1789999420075,"hash":"3701389c4f88a2f97e939cb7dd00fd8e5daf26c7"},{"bid":0.83,"ask":0.84,"asks":[[0.84,5.0]],"received_ms":1789999420057,"observed_ms":1789999420039,"hash":"016535be769bbc68b8c706bb77df5860edeb9c68"}],"intents":{"pair_fast":null,"pair_250":null,"pair_add_fast":null,"pair_add_250":null},"decision_ms":1789999420103,"feature_cutoff_ms":1789999420102,"request_ms":1789999420019,"inventory":{"pair_fast":{"qty":[0.0,0.0],"cash":0.0,"lots":[[],[]],"floor":0.0},"pair_250":{"qty":[0.0,0.0],"cash":0.0,"lots":[[],[]],"floor":0.0},"pair_add_fast":{"qty":[0.0,0.0],"cash":0.0,"lots":[[],[]],"floor":0.0},"pair_add_250":{"qty":[0.0,0.0],"cash":0.0,"lots":[[],[]],"floor":0.0}}}
{"kind":"decision","recorded_ms":1789999430059,"S":1789999200,"age":230,"signal":{"rsi14":55.75441213025122,"volume_ratio":0.47874652860235956,"taker_buy_fraction":0.4891400660290196,"volume5":123.65775,"return1":2.216099524504756,"return5":-10.11687439919668,"return15":8.135833452227791,"bollinger_z":0.3190015149738675,"bar_close_ms":1789999379999,"ref":85408.50237928922,"reference_received_ms":1789999201674,"spot":85292.68776957254,"twap":85412.67811610177,"sigma":12.867641982306255,"spot_z":-1.0761981736142592,"twap_z":0.038802706689240456,"momentum":-1.2125104957234434,"decision_ms":1789999430057,"momentum30":-1.4949717291200524,"momentum60":-1.9832287433574927,"spot_twap_gap":-1.2038481602466669,"range60":1.9832287433574927,"final_mean":85292.68776957254,"final_z":-1.6448137326620489,"final_up_prob":0.05000411465808696,"final_drift_up_prob":4.4221344137063134e-06,"final_known_seconds":0,"final_sd":70.41199098528641,"final_drift_shift":-197.07210559511535},"entry_side":null,"context_gap":null,"book_errors":[null,null],"books":[{"bid":0.03,"ask":0.04,"asks":[[0.04,900.7]],"received_ms":1789999430057,"observed_ms":1789999430044,"hash":"addfaaffb2e66745096a4cf0e003b259fd4ebea3"},{"bid":0.96,"ask":0.97,"asks":[[0.97,957.58]],"received_ms":1789999430050,"observed_ms":1789999430043,"hash":"3118a192d5bc03e445d8e0bc48a9d04ef71f6e77"}],"intents":{"pair_fast":null,"pair_250":null,"pair_add_fast":null,"pair_add_250":null},"decision_ms":1789999430059,"feature_cutoff_ms":1789999430057,"request_ms":1789999430025,"inventory":{"pair_fast":{"qty":[0.0,0.0],"cash":0.0,"lots":[[],[]],"floor":0.0},"pair_250":{"qty":[0.0,0.0],"cash":0.0,"lots":[[],[]],"floor":0.0},"pair_add_fast":{"qty":[0.0,0.0],"cash":0.0,"lots":[[],[]],"floor":0.0},"pair_add_250":{"qty":[0.0,0.0],"cash":0.0,"lots":[[],[]],"floor":0.0}}}
{"kind":"decision","recorded_ms":1789999440067,"S":1789999200,"age":240,"signal":{"rsi14":55.75441213025122,"volume_ratio":0.47874652860235956,"taker_buy_fraction":0.4891400660290196,"volume5":123.65775,"return1":2.216099524504756,"return5":-10.11687439919668,"return15":8.135833452227791,"bollinger_z":0.3190015149738675,"bar_close_ms":1789999379999,"ref":85408.50237928922,"reference_received_ms":1789999201674,"spot":85303.6775255213,"twap":85381.68116121372,"sigma":12.462775933782808,"spot_z":-1.0864577605746666,"twap_z":-0.27798865897491115,"momentum":0.29625015076829625,"decision_ms":1789999440066,"momentum30":-0.796795222016652,"momentum60":-1.7956929298430757,"spot_twap_gap":-0.8080243213484819,"range60":1.9166365474438944,"final_mean":85303.6775255213,"final_z":-1.8838723006444407,"final_up_prob":0.029791125401187835,"final_drift_up_prob":0.10459849492483514,"final_known_seconds":0,"final_sd":55.64329054153966,"final_drift_shift":34.94931340228163},"entry_side":null,"context_gap":null,"book_errors":[null,null],"books":[{"bid":0.03,"ask":0.04,"asks":[[0.04,102.51]],"received_ms":1789999440066,"observed_ms":1789999440055,"hash":"6772d183450888347db5c4870c48f4c8667be821"},{"bid":0.96,"ask":0.97,"asks":[[0.97,20.0]],"received_ms":1789999440065,"observed_ms":1789999440055,"hash":"000a80ede71b667a41350d6491478601043e6521"}],"intents":{"pair_fast":null,"pair_250":null,"pair_add_fast":null,"pair_add_250":null},"decision_ms":1789999440067,"feature_cutoff_ms":1789999440066,"request_ms":1789999440032,"inventory":{"pair_fast":{"qty":[0.0,0.0],"cash":0.0,"lots":[[],[]],"floor":0.0},"pair_250":{"qty":[0.0,0.0],"cash":0.0,"lots":[[],[]],"floor":0.0},"pair_add_fast":{"qty":[0.0,0.0],"cash":0.0,"lots":[[],[]],"floor":0.0},"pair_add_250":{"qty":[0.0,0.0],"cash":0.0,"lots":[[],[]],"floor":0.0}}}
{"kind":"decision","recorded_ms":1789999450061,"S":1789999200,"age":250,"signal":{"rsi14":45.77581585472102,"volume_ratio":0.7119080045917344,"taker_buy_fraction":0.4907973924664762,"volume5":131.45296,"return1":-19.538607644253215,"return5":-17.19163126575625,"return15":-4.890803496677345,"bollinger_z":-0.8298489595463041,"bar_close_ms":1789999439999,"ref":85408.50237928922,"reference_received_ms":1789999201674,"spot":85313.04349718001,"twap":85354.62935742209,"sigma":9.963586884900653,"spot_z":-1.3557398528349012,"twap_z":-0.7651231726593523,"momentum":0.2604805182572066,"decision_ms":1789999450060,"momentum30":-0.5310813989067299,"momentum60":-1.1263127376187154,"spot_twap_gap":-0.5388332067418967,"range60":1.5593644179857675,"final_mean":85312.27230305418,"final_z":-2.8440300937525604,"final_up_prob":0.002227342013951583,"final_drift_up_prob":0.009644077981343757,"final_known_seconds":10,"final_sd":33.83581504514397,"final_drift_shift":17.057162644090468},"entry_side":null,"context_gap":null,"book_errors":[null,null],"books":[{"bid":null,"ask":0.01,"asks":[[0.01,6768.73]],"received_ms":1789999450060,"observed_ms":1789999450025,"hash":"7e9e9cf498a7a3fdfaee31ace75da16f5a85cb95"},{"bid":0.99,"ask":null,"asks":[],"received_ms":1789999450037,"observed_ms":1789999450025,"hash":"a791905d1f3f8d6a9e0bea318342988d7aca3459"}],"intents":{"pair_fast":null,"pair_250":null,"pair_add_fast":null,"pair_add_250":null},"decision_ms":1789999450061,"feature_cutoff_ms":1789999450060,"request_ms":1789999450012,"inventory":{"pair_fast":{"qty":[0.0,0.0],"cash":0.0,"lots":[[],[]],"floor":0.0},"pair_250":{"qty":[0.0,0.0],"cash":0.0,"lots":[[],[]],"floor":0.0},"pair_add_fast":{"qty":[0.0,0.0],"cash":0.0,"lots":[[],[]],"floor":0.0},"pair_add_250":{"qty":[0.0,0.0],"cash":0.0,"lots":[[],[]],"floor":0.0}}}
{"kind":"decision","recorded_ms":1789999460086,"S":1789999200,"age":260,"signal":{"rsi14":45.77581585472102,"volume_ratio":0.7119080045917344,"taker_buy_fraction":0.4907973924664762,"volume5":131.45296,"return1":-19.538607644253215,"return5":-17.19163126575625,"return15":-4.890803496677345,"bollinger_z":-0.8298489595463041,"bar_close_ms":1789999439999,"ref":85408.50237928922,"reference_received_ms":1789999201674,"spot":85320.1558586271,"twap":85338.12440567483,"sigma":9.968745701550747,"spot_z":-1.4027519023790622,"twap_z":-1.1174501908313608,"momentum":0.6304239471620535,"decision_ms":1789999460085,"momentum30":0.5156268301047865,"momentum60":-1.0087857983573272,"spot_twap_gap":-0.23270023315827157,"range60":1.5585574483464664,"final_mean":85316.88417908181,"final_z":-3.787467514293317,"final_up_prob":7.609528781515884e-05,"final_drift_up_prob":0.003501495490758566,"final_known_seconds":20,"final_sd":24.189831295358356,"final_drift_shift":26.385433852900878},"entry_side":null,"context_gap":null,"book_errors":[null,null],"books":[{"bid":null,"ask":0.01,"asks":[[0.01,31917.49]],"received_ms":1789999460085,"observed_ms":1789999460071,"hash":"51a2ba8801f220c0088eb1c8483503837fc03c0b"},{"bid":0.99,"ask":null,"asks":[],"received_ms":1789999460059,"observed_ms":1789999460033,"hash":"4f298df9bd6acfb9fedb2ea35b87eb285e3813c2"}],"intents":{"pair_fast":null,"pair_250":null,"pair_add_fast":null,"pair_add_250":null},"decision_ms":1789999460086,"feature_cutoff_ms":1789999460085,"request_ms":1789999460034,"inventory":{"pair_fast":{"qty":[0.0,0.0],"cash":0.0,"lots":[[],[]],"floor":0.0},"pair_250":{"qty":[0.0,0.0],"cash":0.0,"lots":[[],[]],"floor":0.0},"pair_add_fast":{"qty":[0.0,0.0],"cash":0.0,"lots":[[],[]],"floor":0.0},"pair_add_250":{"qty":[0.0,0.0],"cash":0.0,"lots":[[],[]],"floor":0.0}}}
{"kind":"decision","recorded_ms":1789999470056,"S":1789999200,"age":270,"signal":{"rsi14":45.77581585472102,"volume_ratio":0.7119080045917344,"taker_buy_fraction":0.4907973924664762,"volume5":131.45296,"return1":-19.538607644253215,"return5":-17.19163126575625,"return15":-4.890803496677345,"bollinger_z":-0.8298489595463041,"bar_close_ms":1789999439999,"ref":85408.50237928922,"reference_received_ms":1789999201674,"spot":85277.17722483148,"twap":85319.31962285616,"sigma":8.664156779533341,"spot_z":-2.7698704667385923,"twap_z":-1.8810157445181028,"momentum":-1.351720793329363,"decision_ms":1789999470055,"momentum30":-0.5828434020514297,"momentum60":-1.2053039811114001,"spot_twap_gap":-0.6279387976310639,"range60":1.2609631873817342,"final_mean":85287.73714361718,"final_z":-8.839771396471779,"final_up_prob":0.0,"final_drift_up_prob":0.0,"final_known_seconds":30,"final_sd":13.66157904493283,"final_drift_shift":-27.6745573871248},"entry_side":null,"context_gap":null,"book_errors":[null,null],"books":[{"bid":null,"ask":0.01,"asks":[[0.01,36989.06]],"received_ms":1789999470049,"observed_ms":1789999470029,"hash":"24b75e401694dc5a78fcd2b67837f0a16f2075d3"},{"bid":0.99,"ask":null,"asks":[],"received_ms":1789999470055,"observed_ms":1789999470044,"hash":"4fec9453e2ed2f690cad76a548f76c7a71ea7a88"}],"intents":{"pair_fast":null,"pair_250":null,"pair_add_fast":null,"pair_add_250":null},"decision_ms":1789999470056,"feature_cutoff_ms":1789999470055,"request_ms":1789999470013,"inventory":{"pair_fast":{"qty":[0.0,0.0],"cash":0.0,"lots":[[],[]],"floor":0.0},"pair_250":{"qty":[0.0,0.0],"cash":0.0,"lots":[[],[]],"floor":0.0},"pair_add_fast":{"qty":[0.0,0.0],"cash":0.0,"lots":[[],[]],"floor":0.0},"pair_add_250":{"qty":[0.0,0.0],"cash":0.0,"lots":[[],[]],"floor":0.0}}}
{"kind":"decision","recorded_ms":1789999480069,"S":1789999200,"age":280,"signal":{"rsi14":45.77581585472102,"volume_ratio":0.7119080045917344,"taker_buy_fraction":0.4907973924664762,"volume5":131.45296,"return1":-19.538607644253215,"return5":-17.19163126575625,"return15":-4.890803496677345,"bollinger_z":-0.8298489595463041,"bar_close_ms":1789999439999,"ref":85408.50237928922,"reference_received_ms":1789999201674,"spot":85307.03152799311,"twap":85304.90704111286,"sigma":8.846210617467863,"spot_z":-2.569263163869797,"twap_z":-2.623055615729812,"momentum":0.5901997014232129,"decision_ms":1789999480068,"momentum30":0.13929292803856522,"momentum60":-0.5107023111178419,"spot_twap_gap":0.031004244499829293,"range60":1.0009024931078108,"final_mean":85301.26540354776,"final_z":-14.157052579451035,"final_up_prob":0.0,"final_drift_up_prob":0.0,"final_known_seconds":40,"final_sd":7.574809455543787,"final_drift_shift":5.466089874625046},"entry_side":null,"context_gap":null,"book_errors":[null,null],"books":[{"bid":null,"ask":0.01,"asks":[[0.01,49735.19]],"received_ms":1789999480066,"observed_ms":1789999479994,"hash":"9687a3236a54aa82ec983ca879a02e602d68ab24"},{"bid":0.99,"ask":null,"asks":[],"received_ms":1789999480068,"observed_ms":1789999479994,"hash":"21c6816f4e0b3158f94adeec914b6eedfcbf2647"}],"intents":{"pair_fast":null,"pair_250":null,"pair_add_fast":null,"pair_add_250":null},"decision_ms":1789999480069,"feature_cutoff_ms":1789999480068,"request_ms":1789999480028,"inventory":{"pair_fast":{"qty":[0.0,0.0],"cash":0.0,"lots":[[],[]],"floor":0.0},"pair_250":{"qty":[0.0,0.0],"cash":0.0,"lots":[[],[]],"floor":0.0},"pair_add_fast":{"qty":[0.0,0.0],"cash":0.0,"lots":[[],[]],"floor":0.0},"pair_add_250":{"qty":[0.0,0.0],"cash":0.0,"lots":[[],[]],"floor":0.0}}}
{"kind":"decision","recorded_ms":1789999490075,"S":1789999200,"age":290,"signal":{"rsi14":45.77581585472102,"volume_ratio":0.7119080045917344,"taker_buy_fraction":0.4907973924664762,"volume5":131.45296,"return1":-19.538607644253215,"return5":-17.19163126575625,"return15":-4.890803496677345,"bollinger_z":-0.8298489595463041,"bar_close_ms":1789999439999,"ref":85408.50237928922,"reference_received_ms":1789999201674,"spot":85254.10147488967,"twap":85296.17682258163,"sigma":9.586464867151857,"spot_z":-5.112157398472681,"twap_z":-3.71905804563357,"momentum":-1.3902296473150262,"decision_ms":1789999490074,"momentum30":-1.1448105365606898,"momentum60":-0.5104016419601645,"spot_twap_gap":-0.5666222225992681,"range60":1.0284374502793825,"final_mean":85285.34693105394,"final_z":-42.69191223274342,"final_up_prob":0.0,"final_drift_up_prob":0.0,"final_known_seconds":50,"final_sd":2.884748932394361,"final_drift_shift":-3.4602887184087034},"entry_side":null,"context_gap":null,"book_errors":[null,null],"books":[{"bid":null,"ask":0.001,"asks":[[0.001,23559.55]],"received_ms":1789999490073,"observed_ms":1789999490064,"hash":"78f1b1ea681c185aed96a5fd36e442b9d5988291"},{"bid":0.999,"ask":null,"asks":[],"received_ms":1789999490074,"observed_ms":1789999490064,"hash":"15b15f9695c8477514001600f8b3af50ac06aeb8"}],"intents":{"pair_fast":null,"pair_250":null,"pair_add_fast":null,"pair_add_250":null},"decision_ms":1789999490075,"feature_cutoff_ms":1789999490074,"request_ms":1789999490042,"inventory":{"pair_fast":{"qty":[0.0,0.0],"cash":0.0,"lots":[[],[]],"floor":0.0},"pair_250":{"qty":[0.0,0.0],"cash":0.0,"lots":[[],[]],"floor":0.0},"pair_add_fast":{"qty":[0.0,0.0],"cash":0.0,"lots":[[],[]],"floor":0.0},"pair_add_250":{"qty":[0.0,0.0],"cash":0.0,"lots":[[],[]],"floor":0.0}}}
{"kind":"decision","recorded_ms":1789999530083,"S":1789999500,"age":30,"signal":{"rsi14":31.10756972111633,"volume_ratio":0.690957024053335,"taker_buy_fraction":0.4249513695911076,"volume5":130.988,"return1":-5.196981178792301,"return5":-19.556968198647827,"return15":-17.021197774618464,"bollinger_z":-1.4059079012541085,"bar_close_ms":1789999499999,"ref":85287.01946901706,"reference_received_ms":1789999501188,"spot":85197.07458950797,"twap":85257.185318042,"sigma":10.104284175165708,"spot_z":-0.5418199212238479,"twap_z":-0.17971826099844607,"momentum":0.01778544275150784,"decision_ms":1789999530082,"momentum30":-1.3581432317929973,"momentum60":-1.1939393809727583,"spot_twap_gap":-0.7680169668785042,"range60":1.2958863189766432,"final_mean":85197.07458950797,"final_z":-0.5870625895829743,"final_up_prob":0.27858083581516646,"final_drift_up_prob":0.30921642677335237,"final_known_seconds":0,"final_sd":153.21173773477855,"final_drift_shift":13.634306894175381},"entry_side":0,"context_gap":null,"book_errors":[null,null],"books":[{"bid":0.3,"ask":0.31,"asks":[[0.31,1359.59]],"received_ms":1789999530076,"observed_ms":1789999530054,"hash":"92346ec4603cf5ce88449e22e4e88729154d33f1"},{"bid":0.69,"ask":0.7,"asks":[[0.7,605.71]],"received_ms":1789999530082,"observed_ms":1789999530054,"hash":"205f6043230bb4395db1e794e422def0e57aeb55"}],"intents":{"pair_fast":{"kind":"first","side":0,"qty":5.0,"max_cost":1.67487},"pair_250":{"kind":"first","side":0,"qty":5.0,"max_cost":1.67487},"pair_add_fast":{"kind":"first","side":0,"qty":5.0,"max_cost":1.67487},"pair_add_250":{"kind":"first","side":0,"qty":5.0,"max_cost":1.67487}},"decision_ms":1789999530083,"feature_cutoff_ms":1789999530082,"request_ms":1789999530034,"inventory":{"pair_fast":{"qty":[0.0,0.0],"cash":0.0,"lots":[[],[]],"floor":0.0},"pair_250":{"qty":[0.0,0.0],"cash":0.0,"lots":[[],[]],"floor":0.0},"pair_add_fast":{"qty":[0.0,0.0],"cash":0.0,"lots":[[],[]],"floor":0.0},"pair_add_250":{"qty":[0.0,0.0],"cash":0.0,"lots":[[],[]],"floor":0.0}}}
{"kind":"decision","recorded_ms":1789999540091,"S":1789999500,"age":40,"signal":{"rsi14":31.10756972111633,"volume_ratio":0.690957024053335,"taker_buy_fraction":0.4249513695911076,"volume5":130.988,"return1":-5.196981178792301,"return5":-19.556968198647827,"return15":-17.021197774618464,"bollinger_z":-1.4059079012541085,"bar_close_ms":1789999499999,"ref":85287.01946901706,"reference_received_ms":1789999501188,"spot":85137.228828125,"twap":85239.84826000914,"sigma":11.991671182858717,"spot_z":-0.7748068877866103,"twap_z":-0.2439977386230436,"momentum":-1.668162086468606,"decision_ms":1789999540090,"momentum30":-1.9428306126073602,"momentum60":-1.7119446270934509,"spot_twap_gap":-1.1047760972984766,"range60":1.7119446270934509,"final_mean":85137.228828125,"final_z":-0.8423304064446339,"final_up_prob":0.1998015178559887,"final_drift_up_prob":0.0,"final_known_seconds":0,"final_sd":177.8288421574554,"final_drift_shift":-1454.373053886141},"entry_side":null,"context_gap":null,"book_errors":[null,null],"books":[{"bid":0.16,"ask":0.17,"asks":[[0.17,309.69]],"received_ms":1789999540076,"observed_ms":1789999540065,"hash":"a788ffd0a2731af8db70a52746dd7c6d3ecd61b3"},{"bid":0.83,"ask":0.84,"asks":[[0.84,950.73]],"received_ms":1789999540090,"observed_ms":1789999540075,"hash":"8e1e3f5b86a815d58c9c0367af80463fc721b2ca"}],"intents":{"pair_fast":null,"pair_250":null,"pair_add_fast":null,"pair_add_250":null},"decision_ms":1789999540091,"feature_cutoff_ms":1789999540090,"request_ms":1789999540042,"inventory":{"pair_fast":{"qty":[5.0,0.0],"cash":1.62487,"lots":[[[5.0,0.324974]],[]],"floor":-1.62487},"pair_250":{"qty":[5.0,0.0],"cash":1.41899,"lots":[[[5.0,0.283798]],[]],"floor":-1.41899},"pair_add_fast":{"qty":[5.0,0.0],"cash":1.62487,"lots":[[[5.0,0.324974]],[]],"floor":-1.62487},"pair_add_250":{"qty":[5.0,0.0],"cash":1.41899,"lots":[[[5.0,0.283798]],[]],"floor":-1.41899}}}
{"kind":"decision","recorded_ms":1789999550066,"S":1789999500,"age":50,"signal":{"rsi14":31.10756972111633,"volume_ratio":0.690957024053335,"taker_buy_fraction":0.4249513695911076,"volume5":130.988,"return1":-5.196981178792301,"return5":-19.556968198647827,"return15":-17.021197774618464,"bollinger_z":-1.4059079012541085,"bar_close_ms":1789999499999,"ref":85287.01946901706,"reference_received_ms":1789999501188,"spot":85104.08502540858,"twap":85213.24945561927,"sigma":11.608864906998797,"spot_z":-0.9967636410676011,"twap_z":-0.4019541957520181,"momentum":-0.2372444886280872,"decision_ms":1789999550065,"momentum30":-1.453521852085514,"momentum60":-1.5112118326470234,"spot_twap_gap":-1.2139918461488801,"range60":1.869999669626943,"final_mean":85104.08502540858,"final_z":-1.0875852321316557,"final_up_prob":0.13838912654928587,"final_drift_up_prob":0.012994142059989944,"final_known_seconds":0,"final_sd":168.20239757203188,"final_drift_shift":-191.54915347057857},"entry_side":null,"context_gap":null,"book_errors":[null,null],"books":[{"bid":0.15,"ask":0.17,"asks":[[0.17,750.85]],"received_ms":1789999550065,"observed_ms":1789999550052,"hash":"4247b332cd93d62e7e3faa7335fe7fb919e1d51b"},{"bid":0.83,"ask":0.85,"asks":[[0.85,713.46]],"received_ms":1789999550058,"observed_ms":1789999550040,"hash":"9005a4a19664cdbfd09cffb7d444b900a1604224"}],"intents":{"pair_fast":null,"pair_250":null,"pair_add_fast":null,"pair_add_250":null},"decision_ms":1789999550066,"feature_cutoff_ms":1789999550065,"request_ms":1789999550014,"inventory":{"pair_fast":{"qty":[5.0,0.0],"cash":1.62487,"lots":[[[5.0,0.324974]],[]],"floor":-1.62487},"pair_250":{"qty":[5.0,0.0],"cash":1.41899,"lots":[[[5.0,0.283798]],[]],"floor":-1.41899},"pair_add_fast":{"qty":[5.0,0.0],"cash":1.62487,"lots":[[[5.0,0.324974]],[]],"floor":-1.62487},"pair_add_250":{"qty":[5.0,0.0],"cash":1.41899,"lots":[[[5.0,0.283798]],[]],"floor":-1.41899}}}
{"kind":"decision","recorded_ms":1789999560077,"S":1789999500,"age":60,"signal":{"rsi14":31.10756972111633,"volume_ratio":0.690957024053335,"taker_buy_fraction":0.4249513695911076,"volume5":130.988,"return1":-5.196981178792301,"return5":-19.556968198647827,"return15":-17.021197774618464,"bollinger_z":-1.4059079012541085,"bar_close_ms":1789999499999,"ref":85287.01946901706,"reference_received_ms":1789999501188,"spot":85076.4469898667,"twap":85188.2064227405,"sigma":11.476356971554239,"spot_z":-1.1845699602637818,"twap_z":-0.5558702009571783,"momentum":-0.7500349099737005,"decision_ms":1789999560076,"momentum30":-1.9733212418208674,"momentum60":-2.202495848581244,"spot_twap_gap":-1.2572004146574078,"range60":2.202495848581244,"final_mean":85076.4469898667,"final_z":-1.2976724829754531,"final_up_prob":0.09719995158395844,"final_drift_up_prob":7.212604672401923e-07,"final_known_seconds":0,"final_sd":162.26935680067362,"final_drift_shift":-571.409714413963},"entry_side":null,"context_gap":null,"book_errors":[null,null],"books":[{"bid":0.1,"ask":0.11,"asks":[[0.11,1045.0]],"received_ms":1789999560076,"observed_ms":1789999560065,"hash":"661d4d187ce562d71ff74dddcc89410b5f9adc11"},{"bid":0.89,"ask":0.9,"asks":[[0.9,765.01]],"received_ms":1789999560070,"observed_ms":1789999560060,"hash":"1d84878edaad946b581efe849d33eca89754fc6e"}],"intents":{"pair_fast":null,"pair_250":null,"pair_add_fast":null,"pair_add_250":null},"decision_ms":1789999560077,"feature_cutoff_ms":1789999560076,"request_ms":1789999560037,"inventory":{"pair_fast":{"qty":[5.0,0.0],"cash":1.62487,"lots":[[[5.0,0.324974]],[]],"floor":-1.62487},"pair_250":{"qty":[5.0,0.0],"cash":1.41899,"lots":[[[5.0,0.283798]],[]],"floor":-1.41899},"pair_add_fast":{"qty":[5.0,0.0],"cash":1.62487,"lots":[[[5.0,0.324974]],[]],"floor":-1.62487},"pair_add_250":{"qty":[5.0,0.0],"cash":1.41899,"lots":[[[5.0,0.283798]],[]],"floor":-1.41899}}}
{"kind":"decision","recorded_ms":1789999570057,"S":1789999500,"age":70,"signal":{},"entry_side":null,"context_gap":"incomplete or stale context","book_errors":[null,null],"books":[{"bid":0.07,"ask":0.08,"asks":[[0.08,1287.75]],"received_ms":1789999570056,"observed_ms":1789999570044,"hash":"ed8e382a08d08897fef1ded649353f9e73f2f8d0"},{"bid":0.92,"ask":0.93,"asks":[[0.93,250.0]],"received_ms":1789999570055,"observed_ms":1789999570046,"hash":"3a409f001b850b1f1d4b391d693725fef1600d96"}],"intents":{"pair_fast":null,"pair_250":null,"pair_add_fast":null,"pair_add_250":null},"decision_ms":1789999570057,"feature_cutoff_ms":1789999570056,"request_ms":1789999570017,"inventory":{"pair_fast":{"qty":[5.0,0.0],"cash":1.62487,"lots":[[[5.0,0.324974]],[]],"floor":-1.62487},"pair_250":{"qty":[5.0,0.0],"cash":1.41899,"lots":[[[5.0,0.283798]],[]],"floor":-1.41899},"pair_add_fast":{"qty":[5.0,0.0],"cash":1.62487,"lots":[[[5.0,0.324974]],[]],"floor":-1.62487},"pair_add_250":{"qty":[5.0,0.0],"cash":1.41899,"lots":[[[5.0,0.283798]],[]],"floor":-1.41899}}}
{"kind":"decision","recorded_ms":1789999580061,"S":1789999500,"age":80,"signal":{"rsi14":22.08690719700297,"volume_ratio":0.8056760545759233,"taker_buy_fraction":0.42053999740061165,"volume5":152.80518,"return1":-25.25367384128746,"return5":-44.18070709581617,"return15":-69.83985948111798,"bollinger_z":-2.640236291461956,"bar_close_ms":1789999559999,"ref":85287.01946901706,"reference_received_ms":1789999501188,"spot":85023.09656072239,"twap":85117.9537541162,"sigma":10.378883836058298,"spot_z":-1.714645431366172,"twap_z":-1.098380423012616,"momentum":-0.2412807731271413,"decision_ms":1789999580060,"momentum30":-1.4173056608668355,"momentum60":-2.1569854070559917,"spot_twap_gap":-1.1798967213469853,"range60":2.206502398403888,"final_mean":85023.09656072239,"final_z":-1.895669309124431,"final_up_prob":0.029001893031859072,"final_drift_up_prob":0.0014599542881468253,"final_known_seconds":0,"final_sd":139.22412892603606,"final_drift_shift":-150.4145333909656},"entry_side":null,"context_gap":null,"book_errors":[null,null],"books":[{"bid":0.08,"ask":0.09,"asks":[[0.09,296.99]],"received_ms":1789999580060,"observed_ms":1789999580051,"hash":"3628d153336f892cbeef3bdbc509155bacddbf52"},{"bid":0.91,"ask":0.92,"asks":[[0.92,2074.82]],"received_ms":1789999580060,"observed_ms":1789999580051,"hash":"943cdfda4375a77b3b121cf27e67ca84c1d087f4"}],"intents":{"pair_fast":null,"pair_250":null,"pair_add_fast":null,"pair_add_250":null},"decision_ms":1789999580061,"feature_cutoff_ms":1789999580060,"request_ms":1789999580029,"inventory":{"pair_fast":{"qty":[5.0,0.0],"cash":1.62487,"lots":[[[5.0,0.324974]],[]],"floor":-1.62487},"pair_250":{"qty":[5.0,0.0],"cash":1.41899,"lots":[[[5.0,0.283798]],[]],"floor":-1.41899},"pair_add_fast":{"qty":[5.0,0.0],"cash":1.62487,"lots":[[[5.0,0.324974]],[]],"floor":-1.62487},"pair_add_250":{"qty":[5.0,0.0],"cash":1.41899,"lots":[[[5.0,0.283798]],[]],"floor":-1.41899}}}
{"kind":"decision","recorded_ms":1789999590071,"S":1789999500,"age":90,"signal":{"rsi14":22.08690719700297,"volume_ratio":0.8056760545759233,"taker_buy_fraction":0.42053999740061165,"volume5":152.80518,"return1":-25.25367384128746,"return5":-44.18070709581617,"return15":-69.83985948111798,"bollinger_z":-2.640236291461956,"bar_close_ms":1789999559999,"ref":85287.01946901706,"reference_received_ms":1789999501188,"spot":85038.97509660156,"twap":85088.5001774072,"sigma":10.442313180558248,"spot_z":-1.6394317535699336,"twap_z":-1.3120992312465405,"momentum":0.1947437228213584,"decision_ms":1789999590068,"momentum30":-0.42825364274242345,"momentum60":-1.9967914722605435,"spot_twap_gap":-0.6122839191637905,"range60":2.1849926392012238,"final_mean":85038.97509660156,"final_z":-1.8221959614227212,"final_up_prob":0.03421262857883389,"final_drift_up_prob":0.16548401381730427,"final_known_seconds":0,"final_sd":136.12387342897986,"final_drift_shift":115.70938605752988},"entry_side":0,"context_gap":null,"book_errors":[null,null],"books":[{"bid":0.09,"ask":0.1,"asks":[[0.1,393.0]],"received_ms":1789999590067,"observed_ms":1789999590052,"hash":"9004f7f8f4df30566b2a277c7f07a5e988e96ba2"},{"bid":0.9,"ask":0.91,"asks":[[0.91,343.13]],"received_ms":1789999590062,"observed_ms":1789999590052,"hash":"20e24e7a4390f8f8f5ed3cd79d4c2c57d1c0961c"}],"intents":{"pair_fast":null,"pair_250":null,"pair_add_fast":{"kind":"add","side":0,"qty":5.0,"max_cost":0.5815},"pair_add_250":{"kind":"add","side":0,"qty":5.0,"max_cost":0.5815}},"decision_ms":1789999590071,"feature_cutoff_ms":1789999590068,"request_ms":1789999590034,"inventory":{"pair_fast":{"qty":[5.0,0.0],"cash":1.62487,"lots":[[[5.0,0.324974]],[]],"floor":-1.62487},"pair_250":{"qty":[5.0,0.0],"cash":1.41899,"lots":[[[5.0,0.283798]],[]],"floor":-1.41899},"pair_add_fast":{"qty":[5.0,0.0],"cash":1.62487,"lots":[[[5.0,0.324974]],[]],"floor":-1.62487},"pair_add_250":{"qty":[5.0,0.0],"cash":1.41899,"lots":[[[5.0,0.283798]],[]],"floor":-1.41899}}}
{"kind":"decision","recorded_ms":1789999600061,"S":1789999500,"age":100,"signal":{"rsi14":22.08690719700297,"volume_ratio":0.8056760545759233,"taker_buy_fraction":0.42053999740061165,"volume5":152.80518,"return1":-25.25367384128746,"return5":-44.18070709581617,"return15":-69.83985948111798,"bollinger_z":-2.640236291461956,"bar_close_ms":1789999559999,"ref":85287.01946901706,"reference_received_ms":1789999501188,"spot":85159.02534628558,"twap":85074.35974352721,"sigma":11.653060874792592,"spot_z":-0.7767838165203071,"twap_z":-1.290611081672214,"momentum":2.303085043230164,"decision_ms":1789999600060,"momentum30":2.0055908539339287,"momentum60":0.5121737853176561,"spot_twap_gap":0.9379752181365636,"range60":1.4986342476816121,"final_mean":85159.02534628558,"final_z":-0.8685032880074357,"final_up_prob":0.19255943654987417,"final_drift_up_prob":1.0,"final_known_seconds":0,"final_sd":147.3732160820432,"final_drift_shift":1442.2667923916088},"entry_side":0,"context_gap":null,"book_errors":[null,null],"books":[{"bid":0.25,"ask":0.26,"asks":[[0.26,251.0]],"received_ms":1789999600058,"observed_ms":1789999600048,"hash":"6b3b53e6fb760920d225f66e22af52530b7850aa"},{"bid":0.74,"ask":0.75,"asks":[[0.75,874.16]],"received_ms":1789999600060,"observed_ms":1789999600048,"hash":"11d67bf701979ba40a55b869eb04c65155e28595"}],"intents":{"pair_fast":null,"pair_250":null,"pair_add_fast":null,"pair_add_250":null},"decision_ms":1789999600061,"feature_cutoff_ms":1789999600060,"request_ms":1789999600025,"inventory":{"pair_fast":{"qty":[5.0,0.0],"cash":1.62487,"lots":[[[5.0,0.324974]],[]],"floor":-1.62487},"pair_250":{"qty":[5.0,0.0],"cash":1.41899,"lots":[[[5.0,0.283798]],[]],"floor":-1.41899},"pair_add_fast":{"qty":[10.0,0.0],"cash":2.15637,"lots":[[[5.0,0.324974],[5.0,0.10629999999999999]],[]],"floor":-2.15637},"pair_add_250":{"qty":[10.0,0.0],"cash":1.9504899999999998,"lots":[[[5.0,0.283798],[5.0,0.10629999999999999]],[]],"floor":-1.9504899999999998}}}
{"kind":"decision","recorded_ms":1789999610084,"S":1789999500,"age":110,"signal":{"rsi14":22.08690719700297,"volume_ratio":0.8056760545759233,"taker_buy_fraction":0.42053999740061165,"volume5":152.80518,"return1":-25.25367384128746,"return5":-44.18070709581617,"return15":-69.83985948111798,"bollinger_z":-2.640236291461956,"bar_close_ms":1789999559999,"ref":85287.01946901706,"reference_received_ms":1789999501188,"spot":85156.96668438803,"twap":85081.30385472893,"sigma":11.736198129074847,"spot_z":-0.8041004444807323,"twap_z":-1.2719144565612077,"momentum":-0.40037896755450525,"decision_ms":1789999610083,"momentum30":1.9355759733091324,"momentum60":0.5863041755350531,"spot_twap_gap":0.8322992845829921,"range60":1.6288267008375628,"final_mean":85156.96668438803,"final_z":-0.9050379312275881,"final_up_prob":0.18272264627000206,"final_drift_up_prob":0.005253581715661926,"final_known_seconds":0,"final_sd":143.69871155856674,"final_drift_shift":-237.62565228933536},"entry_side":null,"context_gap":null,"book_errors":[null,null],"books":[{"bid":0.2,"ask":0.21,"asks":[[0.21,1041.27]],"received_ms":1789999610078,"observed_ms":1789999610068,"hash":"7d393c4750d9a36bd10e90c253ed04b80c1de32f"},{"bid":0.79,"ask":0.8,"asks":[[0.8,22.37]],"received_ms":1789999610083,"observed_ms":1789999610057,"hash":"2841ed5dac6649924b776b8ead508979d00615aa"}],"intents":{"pair_fast":null,"pair_250":null,"pair_add_fast":null,"pair_add_250":null},"decision_ms":1789999610084,"feature_cutoff_ms":1789999610083,"request_ms":1789999610034,"inventory":{"pair_fast":{"qty":[5.0,0.0],"cash":1.62487,"lots":[[[5.0,0.324974]],[]],"floor":-1.62487},"pair_250":{"qty":[5.0,0.0],"cash":1.41899,"lots":[[[5.0,0.283798]],[]],"floor":-1.41899},"pair_add_fast":{"qty":[10.0,0.0],"cash":2.15637,"lots":[[[5.0,0.324974],[5.0,0.10629999999999999]],[]],"floor":-2.15637},"pair_add_250":{"qty":[10.0,0.0],"cash":1.9504899999999998,"lots":[[[5.0,0.283798],[5.0,0.10629999999999999]],[]],"floor":-1.9504899999999998}}}
{"kind":"decision","recorded_ms":1789999620041,"S":1789999500,"age":120,"signal":{"rsi14":22.08690719700297,"volume_ratio":0.8056760545759233,"taker_buy_fraction":0.42053999740061165,"volume5":152.80518,"return1":-25.25367384128746,"return5":-44.18070709581617,"return15":-69.83985948111798,"bollinger_z":-2.640236291461956,"bar_close_ms":1789999559999,"ref":85287.01946901706,"reference_received_ms":1789999501188,"spot":85114.20401001985,"twap":85088.25054387536,"sigma":11.766017082623678,"spot_z":-1.0948764696076805,"twap_z":-1.2593052744799504,"momentum":-1.1199033051441087,"decision_ms":1789999620040,"momentum30":0.6214254019297011,"momentum60":0.5566759441473298,"spot_twap_gap":0.2847673982003161,"range60":1.6246987187523505,"final_mean":85114.20401001985,"final_z":-1.2415126459849941,"final_up_prob":0.10720821473748932,"final_drift_up_prob":5.00504021561099e-09,"final_known_seconds":0,"final_sd":139.19750197961312,"final_drift_shift":-624.8638967466625},"entry_side":null,"context_gap":null,"book_errors":[null,null],"books":[{"bid":0.18,"ask":0.19,"asks":[[0.19,1366.17]],"received_ms":1789999620033,"observed_ms":1789999620016,"hash":"5e4c159ab717f470340d841694f00fe50ddc80a8"},{"bid":0.82,"ask":0.83,"asks":[[0.83,585.0]],"received_ms":1789999620040,"observed_ms":1789999620031,"hash":"d37d0fbae82f384834dfbefd6023d7aa5c9e1e95"}],"intents":{"pair_fast":null,"pair_250":null,"pair_add_fast":null,"pair_add_250":null},"decision_ms":1789999620041,"feature_cutoff_ms":1789999620040,"request_ms":1789999620007,"inventory":{"pair_fast":{"qty":[5.0,0.0],"cash":1.62487,"lots":[[[5.0,0.324974]],[]],"floor":-1.62487},"pair_250":{"qty":[5.0,0.0],"cash":1.41899,"lots":[[[5.0,0.283798]],[]],"floor":-1.41899},"pair_add_fast":{"qty":[10.0,0.0],"cash":2.15637,"lots":[[[5.0,0.324974],[5.0,0.10629999999999999]],[]],"floor":-2.15637},"pair_add_250":{"qty":[10.0,0.0],"cash":1.9504899999999998,"lots":[[[5.0,0.283798],[5.0,0.10629999999999999]],[]],"floor":-1.9504899999999998}}}
{"kind":"decision","recorded_ms":1789999630074,"S":1789999500,"age":130,"signal":{"rsi14":28.499987862016315,"volume_ratio":0.9221621556532668,"taker_buy_fraction":0.43894068778329065,"volume5":174.54684,"return1":11.177524828052828,"return5":-36.60372299273486,"return15":-65.07993791020621,"bollinger_z":-1.784693179498862,"bar_close_ms":1789999619999,"ref":85287.01946901706,"reference_received_ms":1789999501188,"spot":85180.14675232209,"twap":85102.57150187297,"sigma":12.2462434950441,"spot_z":-0.6694725332943666,"twap_z":-1.1554197520531986,"momentum":0.6973185458689977,"decision_ms":1789999630073,"momentum30":0.12405072024514856,"momentum60":1.572134911247914,"spot_twap_gap":0.8177954139948217,"range60":1.7482339010888888,"final_mean":85180.14675232209,"final_z":-0.7656217340120225,"final_up_prob":0.2219507042861723,"final_drift_up_prob":0.9738918210395313,"final_known_seconds":0,"final_sd":139.589449916648,"final_drift_shift":377.86409727372836},"entry_side":0,"context_gap":null,"book_errors":[null,null],"books":[{"bid":0.24,"ask":0.25,"asks":[[0.25,203.44]],"received_ms":1789999630071,"observed_ms":1789999629988,"hash":"f103c0a67ea76005aa92a27e42e29496b848b816"},{"bid":0.75,"ask":0.76,"asks":[[0.76,473.8]],"received_ms":1789999630073,"observed_ms":1789999629988,"hash":"640b6e77875ef312d781ed474398b605b15fc0dd"}],"intents":{"pair_fast":null,"pair_250":null,"pair_add_fast":null,"pair_add_250":null},"decision_ms":1789999630074,"feature_cutoff_ms":1789999630073,"request_ms":1789999630038,"inventory":{"pair_fast":{"qty":[5.0,0.0],"cash":1.62487,"lots":[[[5.0,0.324974]],[]],"floor":-1.62487},"pair_250":{"qty":[5.0,0.0],"cash":1.41899,"lots":[[[5.0,0.283798]],[]],"floor":-1.41899},"pair_add_fast":{"qty":[10.0,0.0],"cash":2.15637,"lots":[[[5.0,0.324974],[5.0,0.10629999999999999]],[]],"floor":-2.15637},"pair_add_250":{"qty":[10.0,0.0],"cash":1.9504899999999998,"lots":[[[5.0,0.283798],[5.0,0.10629999999999999]],[]],"floor":-1.9504899999999998}}}
{"kind":"decision","recorded_ms":1789999640090,"S":1789999500,"age":140,"signal":{"rsi14":28.499987862016315,"volume_ratio":0.9221621556532668,"taker_buy_fraction":0.43894068778329065,"volume5":174.54684,"return1":11.177524828052828,"return5":-36.60372299273486,"return15":-65.07993791020621,"bollinger_z":-1.784693179498862,"bar_close_ms":1789999619999,"ref":85287.01946901706,"reference_received_ms":1789999501188,"spot":85188.67973915442,"twap":85127.21643236552,"sigma":12.261320581677854,"spot_z":-0.6342384890187899,"twap_z":-1.0306438369117206,"momentum":-0.01455014101154422,"decision_ms":1789999640089,"momentum30":0.48850494731594957,"momentum60":1.6439493289954719,"spot_twap_gap":0.6471471595318806,"range60":1.65351243139787,"final_mean":85188.67973915442,"final_z":-0.7324234674223012,"final_up_prob":0.23195506974554425,"final_drift_up_prob":0.2156380757575282,"final_known_seconds":0,"final_sd":134.26621925255174,"final_drift_shift":-7.32909541499016},"entry_side":null,"context_gap":null,"book_errors":[null,null],"books":[{"bid":0.19,"ask":0.2,"asks":[[0.2,196.0]],"received_ms":1789999640084,"observed_ms":1789999640074,"hash":"7400e816f428045d19d9bda39a834707ef17c7d1"},{"bid":0.8,"ask":0.81,"asks":[[0.81,482.85]],"received_ms":1789999640089,"observed_ms":1789999640071,"hash":"e0b0149f767c519b4891e42a086c599094f6f425"}],"intents":{"pair_fast":null,"pair_250":null,"pair_add_fast":null,"pair_add_250":null},"decision_ms":1789999640090,"feature_cutoff_ms":1789999640089,"request_ms":1789999640046,"inventory":{"pair_fast":{"qty":[5.0,0.0],"cash":1.62487,"lots":[[[5.0,0.324974]],[]],"floor":-1.62487},"pair_250":{"qty":[5.0,0.0],"cash":1.41899,"lots":[[[5.0,0.283798]],[]],"floor":-1.41899},"pair_add_fast":{"qty":[10.0,0.0],"cash":2.15637,"lots":[[[5.0,0.324974],[5.0,0.10629999999999999]],[]],"floor":-2.15637},"pair_add_250":{"qty":[10.0,0.0],"cash":1.9504899999999998,"lots":[[[5.0,0.283798],[5.0,0.10629999999999999]],[]],"floor":-1.9504899999999998}}}
{"kind":"decision","recorded_ms":1789999650093,"S":1789999500,"age":150,"signal":{"rsi14":28.499987862016315,"volume_ratio":0.9221621556532668,"taker_buy_fraction":0.43894068778329065,"volume5":174.54684,"return1":11.177524828052828,"return5":-36.60372299273486,"return15":-65.07993791020621,"bollinger_z":-1.784693179498862,"bar_close_ms":1789999619999,"ref":85287.01946901706,"reference_received_ms":1789999501188,"spot":85197.31364281,"twap":85151.00461873226,"sigma":11.674668398097367,"spot_z":-0.6275721919913052,"twap_z":-0.9515450818051863,"momentum":0.3858277040746866,"decision_ms":1789999650092,"momentum30":0.6907718734188193,"momentum60":1.3618854862884004,"spot_twap_gap":0.5120890030630425,"range60":1.3618854862884004,"final_mean":85197.31364281,"final_z":-0.7329282206073134,"final_up_prob":0.23180110493352418,"final_drift_up_prob":0.7461945642870706,"final_known_seconds":0,"final_sd":122.39374018472468,"final_drift_shift":170.7993138828498},"entry_side":0,"context_gap":null,"book_errors":[null,null],"books":[{"bid":0.21,"ask":0.22,"asks":[[0.22,213.0]],"received_ms":1789999650092,"observed_ms":1789999649947,"hash":"2c9d7c658fc57c7045aaf3c86031cb27e20d8b08"},{"bid":0.78,"ask":0.79,"asks":[[0.79,5.0]],"received_ms":1789999650052,"observed_ms":1789999649947,"hash":"24ca7cd68791bac659577f031e436b4e329ee237"}],"intents":{"pair_fast":null,"pair_250":null,"pair_add_fast":null,"pair_add_250":null},"decision_ms":1789999650093,"feature_cutoff_ms":1789999650092,"request_ms":1789999650012,"inventory":{"pair_fast":{"qty":[5.0,0.0],"cash":1.62487,"lots":[[[5.0,0.324974]],[]],"floor":-1.62487},"pair_250":{"qty":[5.0,0.0],"cash":1.41899,"lots":[[[5.0,0.283798]],[]],"floor":-1.41899},"pair_add_fast":{"qty":[10.0,0.0],"cash":2.15637,"lots":[[[5.0,0.324974],[5.0,0.10629999999999999]],[]],"floor":-2.15637},"pair_add_250":{"qty":[10.0,0.0],"cash":1.9504899999999998,"lots":[[[5.0,0.283798],[5.0,0.10629999999999999]],[]],"floor":-1.9504899999999998}}}
{"kind":"decision","recorded_ms":1789999660073,"S":1789999500,"age":160,"signal":{"rsi14":28.499987862016315,"volume_ratio":0.9221621556532668,"taker_buy_fraction":0.43894068778329065,"volume5":174.54684,"return1":11.177524828052828,"return5":-36.60372299273486,"return15":-65.07993791020621,"bollinger_z":-1.784693179498862,"bar_close_ms":1789999619999,"ref":85287.01946901706,"reference_received_ms":1789999501188,"spot":85117.07094352937,"twap":85168.30904086583,"sigma":10.557286791419948,"spot_z":-1.3608578665420628,"twap_z":-0.9505702948971786,"momentum":-2.3324024656804205,"decision_ms":1789999660072,"momentum30":-1.2481349976547496,"momentum60":-0.6695704120918772,"spot_twap_gap":-0.6265634393764749,"range60":0.9521993192877307,"final_mean":85117.07094352937,"final_z":-1.6103544726622494,"final_up_prob":0.05366024680725484,"final_drift_up_prob":0.0,"final_known_seconds":0,"final_sd":105.53485482406403,"final_drift_shift":-855.9810255071616},"entry_side":null,"context_gap":null,"book_errors":[null,null],"books":[{"bid":0.04,"ask":0.05,"asks":[[0.05,620.13]],"received_ms":1789999660072,"observed_ms":1789999660061,"hash":"7320e9c975b93ba3a965a02ae005f28ff74c75af"},{"bid":0.95,"ask":0.96,"asks":[[0.96,618.36]],"received_ms":1789999660062,"observed_ms":1789999660043,"hash":"2b619f863cfab47b9e77b3be9cd0b7a8973359d2"}],"intents":{"pair_fast":null,"pair_250":null,"pair_add_fast":null,"pair_add_250":null},"decision_ms":1789999660073,"feature_cutoff_ms":1789999660072,"request_ms":1789999660016,"inventory":{"pair_fast":{"qty":[5.0,0.0],"cash":1.62487,"lots":[[[5.0,0.324974]],[]],"floor":-1.62487},"pair_250":{"qty":[5.0,0.0],"cash":1.41899,"lots":[[[5.0,0.283798]],[]],"floor":-1.41899},"pair_add_fast":{"qty":[10.0,0.0],"cash":2.15637,"lots":[[[5.0,0.324974],[5.0,0.10629999999999999]],[]],"floor":-2.15637},"pair_add_250":{"qty":[10.0,0.0],"cash":1.9504899999999998,"lots":[[[5.0,0.283798],[5.0,0.10629999999999999]],[]],"floor":-1.9504899999999998}}}
{"kind":"decision","recorded_ms":1789999670327,"S":1789999500,"age":170,"signal":{"rsi14":28.499987862016315,"volume_ratio":0.9221621556532668,"taker_buy_fraction":0.43894068778329065,"volume5":174.54684,"return1":11.177524828052828,"return5":-36.60372299273486,"return15":-65.07993791020621,"bollinger_z":-1.784693179498862,"bar_close_ms":1789999619999,"ref":85287.01946901706,"reference_received_ms":1789999501188,"spot":85105.8754825,"twap":85156.52713781098,"sigma":12.896006160504836,"spot_z":-1.2335087526680422,"twap_z":-0.8885938517401976,"momentum":0.6519186574783064,"decision_ms":1789999670326,"momentum30":-1.0928674258131224,"momentum60":-0.5005127054272935,"spot_twap_gap":-0.5070640089022735,"range60":1.1577361482540305,"final_mean":85105.8754825,"final_z":-1.4833219317812258,"final_up_prob":0.06899444902724927,"final_drift_up_prob":0.7538293059243739,"final_known_seconds":0,"final_sd":122.12048014386869,"final_drift_shift":264.99063732853074},"entry_side":0,"context_gap":null,"book_errors":[null,null],"books":[{"bid":0.08,"ask":0.1,"asks":[[0.1,68.3]],"received_ms":1789999670082,"observed_ms":1789999669993,"hash":"589fd403653ff64054033e8235e2021d16ad9c43"},{"bid":0.88,"ask":0.91,"asks":[[0.91,310.59]],"received_ms":1789999670326,"observed_ms":1789999670068,"hash":"a6ee8a28ac3d40e66773c044e22ad9e671d79fa1"}],"intents":{"pair_fast":null,"pair_250":null,"pair_add_fast":null,"pair_add_250":null},"decision_ms":1789999670327,"feature_cutoff_ms":1789999670326,"request_ms":1789999670045,"inventory":{"pair_fast":{"qty":[5.0,0.0],"cash":1.62487,"lots":[[[5.0,0.324974]],[]],"floor":-1.62487},"pair_250":{"qty":[5.0,0.0],"cash":1.41899,"lots":[[[5.0,0.283798]],[]],"floor":-1.41899},"pair_add_fast":{"qty":[10.0,0.0],"cash":2.15637,"lots":[[[5.0,0.324974],[5.0,0.10629999999999999]],[]],"floor":-2.15637},"pair_add_250":{"qty":[10.0,0.0],"cash":1.9504899999999998,"lots":[[[5.0,0.283798],[5.0,0.10629999999999999]],[]],"floor":-1.9504899999999998}}}
{"kind":"decision","recorded_ms":1789999680117,"S":1789999500,"age":180,"signal":{"rsi14":28.499987862016315,"volume_ratio":0.9221621556532668,"taker_buy_fraction":0.43894068778329065,"volume5":174.54684,"return1":11.177524828052828,"return5":-36.60372299273486,"return15":-65.07993791020621,"bollinger_z":-1.784693179498862,"bar_close_ms":1789999619999,"ref":85287.01946901706,"reference_received_ms":1789999501188,"spot":85111.97139534047,"twap":85152.2348332112,"sigma":12.542936787184216,"spot_z":-1.274610493983436,"twap_z":-0.9814327436889705,"momentum":-0.036195990342211055,"decision_ms":1789999680116,"momentum30":-1.2076619514747706,"momentum60":-0.4237565094882802,"spot_twap_gap":-0.4144155045989055,"range60":1.190325101165946,"final_mean":85111.97139534047,"final_z":-1.5614504266636708,"final_up_prob":0.05920875590347624,"final_drift_up_prob":0.04681423794115541,"final_known_seconds":0,"final_sd":112.10607182106457,"final_drift_shift":-12.904526939386672},"entry_side":null,"context_gap":null,"book_errors":[null,null],"books":[{"bid":0.04,"ask":0.05,"asks":[[0.05,598.15]],"received_ms":1789999680074,"observed_ms":1789999680066,"hash":"51ed5a5a0caa7cd03ef695556e3813e50fa921f3"},{"bid":0.95,"ask":0.96,"asks":[[0.96,738.3]],"received_ms":1789999680116,"observed_ms":1789999680074,"hash":"a14f118f00943dbf65e04c2da03793cbcab9d958"}],"intents":{"pair_fast":null,"pair_250":null,"pair_add_fast":null,"pair_add_250":null},"decision_ms":1789999680117,"feature_cutoff_ms":1789999680116,"request_ms":1789999680049,"inventory":{"pair_fast":{"qty":[5.0,0.0],"cash":1.62487,"lots":[[[5.0,0.324974]],[]],"floor":-1.62487},"pair_250":{"qty":[5.0,0.0],"cash":1.41899,"lots":[[[5.0,0.283798]],[]],"floor":-1.41899},"pair_add_fast":{"qty":[10.0,0.0],"cash":2.15637,"lots":[[[5.0,0.324974],[5.0,0.10629999999999999]],[]],"floor":-2.15637},"pair_add_250":{"qty":[10.0,0.0],"cash":1.9504899999999998,"lots":[[[5.0,0.283798],[5.0,0.10629999999999999]],[]],"floor":-1.9504899999999998}}}
{"kind":"decision","recorded_ms":1789999690048,"S":1789999500,"age":190,"signal":{"rsi14":33.75179683756651,"volume_ratio":0.781671155058929,"taker_buy_fraction":0.38478636132650407,"volume5":186.61111,"return1":-7.019492808456192,"return5":-45.875175678227535,"return15":-69.44774859900902,"bollinger_z":-1.8638238705644126,"bar_close_ms":1789999679999,"ref":85287.01946901706,"reference_received_ms":1789999501188,"spot":85100.00942193283,"twap":85143.66472743248,"sigma":11.713500429879932,"spot_z":-1.5225471492053062,"twap_z":-1.1671263471013529,"momentum":0.20025425818776474,"decision_ms":1789999690045,"momentum30":0.3229502049684552,"momentum60":-0.9834909644610803,"spot_twap_gap":-0.4811435949081902,"range60":1.2746123662605402,"final_mean":85100.00942193283,"final_z":-1.9088370744811842,"final_up_prob":0.02814155627935272,"final_drift_up_prob":0.09620698820270507,"final_known_seconds":0,"final_sd":97.97066998767227,"final_drift_shift":59.30811003964614},"entry_side":0,"context_gap":null,"book_errors":[null,null],"books":[{"bid":0.04,"ask":0.05,"asks":[[0.05,1401.0]],"received_ms":1789999690045,"observed_ms":1789999689937,"hash":"a649e052d494c713841f7933d4ab267079ca3f95"},{"bid":0.95,"ask":0.96,"asks":[[0.96,251.0]],"received_ms":1789999690039,"observed_ms":1789999689937,"hash":"027c51f5bb267ca451eb6828887c03079f5ff021"}],"intents":{"pair_fast":null,"pair_250":null,"pair_add_fast":null,"pair_add_250":null},"decision_ms":1789999690048,"feature_cutoff_ms":1789999690045,"request_ms":1789999690010,"inventory":{"pair_fast":{"qty":[5.0,0.0],"cash":1.62487,"lots":[[[5.0,0.324974]],[]],"floor":-1.62487},"pair_250":{"qty":[5.0,0.0],"cash":1.41899,"lots":[[[5.0,0.283798]],[]],"floor":-1.41899},"pair_add_fast":{"qty":[10.0,0.0],"cash":2.15637,"lots":[[[5.0,0.324974],[5.0,0.10629999999999999]],[]],"floor":-2.15637},"pair_add_250":{"qty":[10.0,0.0],"cash":1.9504899999999998,"lots":[[[5.0,0.283798],[5.0,0.10629999999999999]],[]],"floor":-1.9504899999999998}}}
{"kind":"decision","recorded_ms":1789999700052,"S":1789999500,"age":200,"signal":{"rsi14":33.75179683756651,"volume_ratio":0.781671155058929,"taker_buy_fraction":0.38478636132650407,"volume5":186.61111,"return1":-7.019492808456192,"return5":-45.875175678227535,"return15":-69.44774859900902,"bollinger_z":-1.8638238705644126,"bar_close_ms":1789999679999,"ref":85287.01946901706,"reference_received_ms":1789999501188,"spot":85102.4262917329,"twap":85132.25334152514,"sigma":12.014922738215985,"spot_z":-1.5367578359760896,"twap_z":-1.288444473767118,"momentum":-0.19750392392622473,"decision_ms":1789999700051,"momentum30":-0.16685990463846523,"momentum60":-0.8665046533100139,"spot_twap_gap":-0.3204894158949815,"range60":1.2426357476802217,"final_mean":85102.4262917329,"final_z":-1.9842833650837506,"final_up_prob":0.0236121297817648,"final_drift_up_prob":0.005408953724104215,"final_known_seconds":0,"final_sd":93.02762928538012,"final_drift_shift":-52.490199121097234},"entry_side":null,"context_gap":null,"book_errors":[null,null],"books":[{"bid":0.02,"ask":0.03,"asks":[[0.03,418.0]],"received_ms":1789999700042,"observed_ms":1789999700029,"hash":"1122229a56cc5b79f2f842a5567b8627a15475cd"},{"bid":0.97,"ask":0.98,"asks":[[0.98,1768.8]],"received_ms":1789999700050,"observed_ms":1789999700038,"hash":"48bcc215521bca2f7ff9f280fc7e2a959eba4d60"}],"intents":{"pair_fast":null,"pair_250":null,"pair_add_fast":null,"pair_add_250":null},"decision_ms":1789999700052,"feature_cutoff_ms":1789999700051,"request_ms":1789999700019,"inventory":{"pair_fast":{"qty":[5.0,0.0],"cash":1.62487,"lots":[[[5.0,0.324974]],[]],"floor":-1.62487},"pair_250":{"qty":[5.0,0.0],"cash":1.41899,"lots":[[[5.0,0.283798]],[]],"floor":-1.41899},"pair_add_fast":{"qty":[10.0,0.0],"cash":2.15637,"lots":[[[5.0,0.324974],[5.0,0.10629999999999999]],[]],"floor":-2.15637},"pair_add_250":{"qty":[10.0,0.0],"cash":1.9504899999999998,"lots":[[[5.0,0.283798],[5.0,0.10629999999999999]],[]],"floor":-1.9504899999999998}}}
{"kind":"decision","recorded_ms":1789999710054,"S":1789999500,"age":210,"signal":{"rsi14":33.75179683756651,"volume_ratio":0.781671155058929,"taker_buy_fraction":0.38478636132650407,"volume5":186.61111,"return1":-7.019492808456192,"return5":-45.875175678227535,"return15":-69.44774859900902,"bollinger_z":-1.8638238705644126,"bar_close_ms":1789999679999,"ref":85287.01946901706,"reference_received_ms":1789999501188,"spot":85119.35937233598,"twap":85116.66510776106,"sigma":13.998249853486543,"spot_z":-1.26288158290507,"twap_z":-1.283175840027056,"momentum":0.5827756317232311,"decision_ms":1789999710053,"momentum30":0.3491207481378633,"momentum60":-0.6970304509401805,"spot_twap_gap":0.02484796775351065,"range60":1.161562730955018,"final_mean":85119.35937233598,"final_z":-1.694732926008485,"final_up_prob":0.04506304828474539,"final_drift_up_prob":0.4476762836807833,"final_known_seconds":0,"final_sd":98.93009931420944,"final_drift_shift":154.64738438342567},"entry_side":0,"context_gap":null,"book_errors":[null,null],"books":[{"bid":0.03,"ask":0.04,"asks":[[0.04,1116.27]],"received_ms":1789999710053,"observed_ms":1789999710042,"hash":"cc5114055cbfa73188ee602eeb92ff2ecf4a2dbf"},{"bid":0.96,"ask":0.97,"asks":[[0.97,604.0]],"received_ms":1789999710053,"observed_ms":1789999710042,"hash":"7261683fc8a93ef9d104e5e5771e212bacd7869a"}],"intents":{"pair_fast":null,"pair_250":null,"pair_add_fast":null,"pair_add_250":null},"decision_ms":1789999710054,"feature_cutoff_ms":1789999710053,"request_ms":1789999710026,"inventory":{"pair_fast":{"qty":[5.0,0.0],"cash":1.62487,"lots":[[[5.0,0.324974]],[]],"floor":-1.62487},"pair_250":{"qty":[5.0,0.0],"cash":1.41899,"lots":[[[5.0,0.283798]],[]],"floor":-1.41899},"pair_add_fast":{"qty":[10.0,0.0],"cash":2.15637,"lots":[[[5.0,0.324974],[5.0,0.10629999999999999]],[]],"floor":-2.15637},"pair_add_250":{"qty":[10.0,0.0],"cash":1.9504899999999998,"lots":[[[5.0,0.283798],[5.0,0.10629999999999999]],[]],"floor":-1.9504899999999998}}}
{"kind":"decision","recorded_ms":1789999720086,"S":1789999500,"age":220,"signal":{"rsi14":33.75179683756651,"volume_ratio":0.781671155058929,"taker_buy_fraction":0.38478636132650407,"volume5":186.61111,"return1":-7.019492808456192,"return5":-45.875175678227535,"return15":-69.44774859900902,"bollinger_z":-1.8638238705644126,"bar_close_ms":1789999679999,"ref":85287.01946901706,"reference_received_ms":1789999501188,"spot":85095.03637566,"twap":85102.08035510893,"sigma":9.736434133871246,"spot_z":-2.205712492990438,"twap_z":-2.1247835257610754,"momentum":-0.5769711002900056,"decision_ms":1789999720085,"momentum30":-0.27928673072958804,"momentum60":0.20879109290851636,"spot_twap_gap":-0.09339906418048555,"range60":0.6895740984500842,"final_mean":85095.03637566,"final_z":-3.121008764059789,"final_up_prob":0.0009011633511264994,"final_drift_up_prob":2.527202341950918e-06,"final_known_seconds":0,"final_sd":61.513154198046045,"final_drift_shift":-88.67170633967395},"entry_side":null,"context_gap":null,"book_errors":[null,null],"books":[{"bid":0.02,"ask":0.03,"asks":[[0.03,1855.62]],"received_ms":1789999720081,"observed_ms":1789999720066,"hash":"f594cdfc9fd0067d47bf9597aae848b994854bf0"},{"bid":0.97,"ask":0.98,"asks":[[0.98,506.0]],"received_ms":1789999720085,"observed_ms":1789999720058,"hash":"f4548d3716fe11cf1b15c589f44aaf6f6ed72b24"}],"intents":{"pair_fast":null,"pair_250":null,"pair_add_fast":null,"pair_add_250":null},"decision_ms":1789999720086,"feature_cutoff_ms":1789999720085,"request_ms":1789999720027,"inventory":{"pair_fast":{"qty":[5.0,0.0],"cash":1.62487,"lots":[[[5.0,0.324974]],[]],"floor":-1.62487},"pair_250":{"qty":[5.0,0.0],"cash":1.41899,"lots":[[[5.0,0.283798]],[]],"floor":-1.41899},"pair_add_fast":{"qty":[10.0,0.0],"cash":2.15637,"lots":[[[5.0,0.324974],[5.0,0.10629999999999999]],[]],"floor":-2.15637},"pair_add_250":{"qty":[10.0,0.0],"cash":1.9504899999999998,"lots":[[[5.0,0.283798],[5.0,0.10629999999999999]],[]],"floor":-1.9504899999999998}}}
{"kind":"decision","recorded_ms":1789999730049,"S":1789999500,"age":230,"signal":{"rsi14":33.75179683756651,"volume_ratio":0.781671155058929,"taker_buy_fraction":0.38478636132650407,"volume5":186.61111,"return1":-7.019492808456192,"return5":-45.875175678227535,"return15":-69.44774859900902,"bollinger_z":-1.8638238705644126,"bar_close_ms":1789999679999,"ref":85287.01946901706,"reference_received_ms":1789999501188,"spot":85125.62737725482,"twap":85104.1323644496,"sigma":9.917396660788004,"spot_z":-1.945738619290761,"twap_z":-2.204881902462708,"momentum":0.5453826745305616,"decision_ms":1789999730048,"momentum30":0.590306769087281,"momentum60":0.159077364127174,"spot_twap_gap":0.2798107523192766,"range60":0.7445521046343861,"final_mean":85125.62737725482,"final_z":-2.973525407847593,"final_up_prob":0.0014720001595102117,"final_drift_up_prob":0.04321646147754632,"final_known_seconds":0,"final_sd":54.276345289099176,"final_drift_shift":68.33411042370825},"entry_side":0,"context_gap":null,"book_errors":[null,null],"books":[{"bid":0.01,"ask":0.02,"asks":[[0.02,405.0]],"received_ms":1789999730047,"observed_ms":1789999730034,"hash":"262edc4dee5a56b4d3c1a3158d3c397b1b1a40b6"},{"bid":0.98,"ask":0.99,"asks":[[0.99,1827.36]],"received_ms":1789999730046,"observed_ms":1789999730034,"hash":"5135f0b03c160e9d09767938acc047381c7fed26"}],"intents":{"pair_fast":null,"pair_250":null,"pair_add_fast":null,"pair_add_250":null},"decision_ms":1789999730049,"feature_cutoff_ms":1789999730048,"request_ms":1789999730009,"inventory":{"pair_fast":{"qty":[5.0,0.0],"cash":1.62487,"lots":[[[5.0,0.324974]],[]],"floor":-1.62487},"pair_250":{"qty":[5.0,0.0],"cash":1.41899,"lots":[[[5.0,0.283798]],[]],"floor":-1.41899},"pair_add_fast":{"qty":[10.0,0.0],"cash":2.15637,"lots":[[[5.0,0.324974],[5.0,0.10629999999999999]],[]],"floor":-2.15637},"pair_add_250":{"qty":[10.0,0.0],"cash":1.9504899999999998,"lots":[[[5.0,0.283798],[5.0,0.10629999999999999]],[]],"floor":-1.9504899999999998}}}
{"kind":"decision","recorded_ms":1789999740063,"S":1789999500,"age":240,"signal":{"rsi14":33.75179683756651,"volume_ratio":0.781671155058929,"taker_buy_fraction":0.38478636132650407,"volume5":186.61111,"return1":-7.019492808456192,"return5":-45.875175678227535,"return15":-69.44774859900902,"bollinger_z":-1.8638238705644126,"bar_close_ms":1789999679999,"ref":85287.01946901706,"reference_received_ms":1789999501188,"spot":85156.33690112643,"twap":85106.31000221371,"sigma":10.488997025295955,"spot_z":-1.6092835571028157,"twap_z":-2.225337152716765,"momentum":1.1220738383940683,"decision_ms":1789999740062,"momentum30":0.7577985673081794,"momentum60":0.784580779954455,"spot_twap_gap":0.6157352188015199,"range60":1.075071080019021,"final_mean":85156.33690112643,"final_z":-2.7902441386491414,"final_up_prob":0.0026334155125388725,"final_drift_up_prob":0.34046433458326086,"final_known_seconds":0,"final_sd":46.83553173017319,"final_drift_shift":111.42397488082997},"entry_side":0,"context_gap":null,"book_errors":[null,null],"books":[{"bid":null,"ask":0.01,"asks":[[0.01,2243.52]],"received_ms":1789999740059,"observed_ms":1789999740048,"hash":"51f3d9c95abe5df9ff4abe59f9da93948eb935a5"},{"bid":0.99,"ask":null,"asks":[],"received_ms":1789999740062,"observed_ms":1789999740051,"hash":"c319daae70606de9d4c5c02578698e242739facd"}],"intents":{"pair_fast":null,"pair_250":null,"pair_add_fast":null,"pair_add_250":null},"decision_ms":1789999740063,"feature_cutoff_ms":1789999740062,"request_ms":1789999740021,"inventory":{"pair_fast":{"qty":[5.0,0.0],"cash":1.62487,"lots":[[[5.0,0.324974]],[]],"floor":-1.62487},"pair_250":{"qty":[5.0,0.0],"cash":1.41899,"lots":[[[5.0,0.283798]],[]],"floor":-1.41899},"pair_add_fast":{"qty":[10.0,0.0],"cash":2.15637,"lots":[[[5.0,0.324974],[5.0,0.10629999999999999]],[]],"floor":-2.15637},"pair_add_250":{"qty":[10.0,0.0],"cash":1.9504899999999998,"lots":[[[5.0,0.283798],[5.0,0.10629999999999999]],[]],"floor":-1.9504899999999998}}}
{"kind":"decision","recorded_ms":1789999750042,"S":1789999500,"age":250,"signal":{"rsi14":39.820218373495024,"volume_ratio":0.6500844248788099,"taker_buy_fraction":0.418612933173532,"volume5":180.35728,"return1":8.316610119196428,"return5":-17.946739888833207,"return15":-31.48808277310174,"bollinger_z":-1.3396727994271702,"bar_close_ms":1789999739999,"ref":85287.01946901706,"reference_received_ms":1789999501188,"spot":85183.63124064099,"twap":85117.17653931523,"sigma":10.891836159904772,"spot_z":-1.3429601463595837,"twap_z":-2.2061726882563653,"momentum":0.7257201660085475,"decision_ms":1789999750041,"momentum30":1.2589949383454966,"momentum60":0.8735664752735404,"spot_twap_gap":0.7876784891400245,"range60":1.3596016064896295,"final_mean":85182.80288049151,"final_z":-2.815963517452029,"final_up_prob":0.0024315594369722082,"final_drift_up_prob":0.0790944803492799,"final_known_seconds":10,"final_sd":37.009211191717085,"final_drift_shift":51.98960532301136},"entry_side":0,"context_gap":null,"book_errors":[null,null],"books":[{"bid":null,"ask":0.01,"asks":[[0.01,2891.96]],"received_ms":1789999750028,"observed_ms":1789999750009,"hash":"c480f08552ec8771e4f52c7b311e9659ea4ada7b"},{"bid":0.99,"ask":null,"asks":[],"received_ms":1789999750041,"observed_ms":1789999750009,"hash":"a2f03be57200b21785e59c9250dcc31940688581"}],"intents":{"pair_fast":null,"pair_250":null,"pair_add_fast":null,"pair_add_250":null},"decision_ms":1789999750042,"feature_cutoff_ms":1789999750041,"request_ms":1789999750007,"inventory":{"pair_fast":{"qty":[5.0,0.0],"cash":1.62487,"lots":[[[5.0,0.324974]],[]],"floor":-1.62487},"pair_250":{"qty":[5.0,0.0],"cash":1.41899,"lots":[[[5.0,0.283798]],[]],"floor":-1.41899},"pair_add_fast":{"qty":[10.0,0.0],"cash":2.15637,"lots":[[[5.0,0.324974],[5.0,0.10629999999999999]],[]],"floor":-2.15637},"pair_add_250":{"qty":[10.0,0.0],"cash":1.9504899999999998,"lots":[[[5.0,0.283798],[5.0,0.10629999999999999]],[]],"floor":-1.9504899999999998}}}
{"kind":"decision","recorded_ms":1789999760049,"S":1789999500,"age":260,"signal":{"rsi14":39.820218373495024,"volume_ratio":0.6500844248788099,"taker_buy_fraction":0.418612933173532,"volume5":180.35728,"return1":8.316610119196428,"return5":-17.946739888833207,"return15":-31.48808277310174,"bollinger_z":-1.3396727994271702,"bar_close_ms":1789999739999,"ref":85287.01946901706,"reference_received_ms":1789999501188,"spot":85192.34014738907,"twap":85129.34776947611,"sigma":10.672604868569172,"spot_z":-1.4035097848153377,"twap_z":-2.3372978311323873,"momentum":-0.04630086693959827,"decision_ms":1789999760048,"momentum30":1.252585158748645,"momentum60":1.1948536920656376,"spot_twap_gap":0.7619771480324876,"range60":1.5109856410896407,"final_mean":85188.89713042747,"final_z":-3.7835680664362967,"final_up_prob":7.729801025707639e-05,"final_drift_up_prob":5.583766617184294e-05,"final_known_seconds":20,"final_sd":25.933810854368172,"final_drift_shift":-2.0785254933832538},"entry_side":null,"context_gap":null,"book_errors":[null,null],"books":[{"bid":null,"ask":0.01,"asks":[[0.01,6798.48]],"received_ms":1789999760047,"observed_ms":1789999760028,"hash":"7b6b1eef808562fa25173e5910eceee806a1a228"},{"bid":0.99,"ask":null,"asks":[],"received_ms":1789999760047,"observed_ms":1789999760028,"hash":"f5f94ec0a01f7ce0be378cae8a67bc9c6047880e"}],"intents":{"pair_fast":null,"pair_250":null,"pair_add_fast":null,"pair_add_250":null},"decision_ms":1789999760049,"feature_cutoff_ms":1789999760048,"request_ms":1789999760015,"inventory":{"pair_fast":{"qty":[5.0,0.0],"cash":1.62487,"lots":[[[5.0,0.324974]],[]],"floor":-1.62487},"pair_250":{"qty":[5.0,0.0],"cash":1.41899,"lots":[[[5.0,0.283798]],[]],"floor":-1.41899},"pair_add_fast":{"qty":[10.0,0.0],"cash":2.15637,"lots":[[[5.0,0.324974],[5.0,0.10629999999999999]],[]],"floor":-2.15637},"pair_add_250":{"qty":[10.0,0.0],"cash":1.9504899999999998,"lots":[[[5.0,0.283798],[5.0,0.10629999999999999]],[]],"floor":-1.9504899999999998}}}
{"kind":"decision","recorded_ms":1789999770055,"S":1789999500,"age":270,"signal":{"rsi14":39.820218373495024,"volume_ratio":0.6500844248788099,"taker_buy_fraction":0.418612933173532,"volume5":180.35728,"return1":8.316610119196428,"return5":-17.946739888833207,"return15":-31.48808277310174,"bollinger_z":-1.3396727994271702,"bar_close_ms":1789999739999,"ref":85287.01946901706,"reference_received_ms":1789999501188,"spot":85193.51723629612,"twap":85148.84682787699,"sigma":9.400911212012584,"spot_z":-1.8175039733879883,"twap_z":-2.6858109905790997,"momentum":-0.497924626564476,"decision_ms":1789999770053,"momentum30":0.6774396066690959,"momentum60":1.1084491515878168,"spot_twap_gap":0.613443186423963,"range60":1.7720203543591029,"final_mean":85192.24837200117,"final_z":-6.392751901975945,"final_up_prob":8.14632250545344e-11,"final_drift_up_prob":4.701239397775225e-13,"final_known_seconds":30,"final_sd":14.824773191432962,"final_drift_shift":-11.062644518154524},"entry_side":null,"context_gap":null,"book_errors":[null,null],"books":[{"bid":null,"ask":0.01,"asks":[[0.01,37881.59]],"received_ms":1789999770052,"observed_ms":1789999770036,"hash":"c2a9ba5aeecdbe0f5ba3e0c019383177070c9a99"},{"bid":0.99,"ask":null,"asks":[],"received_ms":1789999770053,"observed_ms":1789999770036,"hash":"2a06191f5ec8e7384ca871af7f4e111edacd80b0"}],"intents":{"pair_fast":null,"pair_250":null,"pair_add_fast":null,"pair_add_250":null},"decision_ms":1789999770055,"feature_cutoff_ms":1789999770053,"request_ms":1789999770022,"inventory":{"pair_fast":{"qty":[5.0,0.0],"cash":1.62487,"lots":[[[5.0,0.324974]],[]],"floor":-1.62487},"pair_250":{"qty":[5.0,0.0],"cash":1.41899,"lots":[[[5.0,0.283798]],[]],"floor":-1.41899},"pair_add_fast":{"qty":[10.0,0.0],"cash":2.15637,"lots":[[[5.0,0.324974],[5.0,0.10629999999999999]],[]],"floor":-2.15637},"pair_add_250":{"qty":[10.0,0.0],"cash":1.9504899999999998,"lots":[[[5.0,0.283798],[5.0,0.10629999999999999]],[]],"floor":-1.9504899999999998}}}
{"kind":"decision","recorded_ms":1789999780059,"S":1789999500,"age":280,"signal":{"rsi14":39.820218373495024,"volume_ratio":0.6500844248788099,"taker_buy_fraction":0.418612933173532,"volume5":180.35728,"return1":8.316610119196428,"return5":-17.946739888833207,"return15":-31.48808277310174,"bollinger_z":-1.3396727994271702,"bar_close_ms":1789999739999,"ref":85287.01946901706,"reference_received_ms":1789999501188,"spot":85184.16806876248,"twap":85163.3889296756,"sigma":8.683062870945212,"spot_z":-2.652484825839742,"twap_z":-3.1883681583518544,"momentum":-0.27438789912167644,"decision_ms":1789999780058,"momentum30":-0.2046868436962683,"momentum60":1.1246831452793529,"spot_twap_gap":0.30894344091915904,"range60":1.5039200410224958,"final_mean":85187.10558549438,"final_z":-13.428011573345875,"final_up_prob":0.0,"final_drift_up_prob":0.0,"final_known_seconds":40,"final_sd":7.440705794520037,"final_drift_shift":-2.4968593221583575},"entry_side":null,"context_gap":null,"book_errors":[null,null],"books":[{"bid":null,"ask":0.01,"asks":[[0.01,51689.31]],"received_ms":1789999780056,"observed_ms":1789999780044,"hash":"ebd17dc71f323a773758e90166d0cf1019d888b0"},{"bid":0.99,"ask":null,"asks":[],"received_ms":1789999780057,"observed_ms":1789999780044,"hash":"d7ae8f6d90c7d28f92af3704d898550500231a1f"}],"intents":{"pair_fast":null,"pair_250":null,"pair_add_fast":null,"pair_add_250":null},"decision_ms":1789999780059,"feature_cutoff_ms":1789999780058,"request_ms":1789999780029,"inventory":{"pair_fast":{"qty":[5.0,0.0],"cash":1.62487,"lots":[[[5.0,0.324974]],[]],"floor":-1.62487},"pair_250":{"qty":[5.0,0.0],"cash":1.41899,"lots":[[[5.0,0.283798]],[]],"floor":-1.41899},"pair_add_fast":{"qty":[10.0,0.0],"cash":2.15637,"lots":[[[5.0,0.324974],[5.0,0.10629999999999999]],[]],"floor":-2.15637},"pair_add_250":{"qty":[10.0,0.0],"cash":1.9504899999999998,"lots":[[[5.0,0.283798],[5.0,0.10629999999999999]],[]],"floor":-1.9504899999999998}}}
{"kind":"decision","recorded_ms":1789999790066,"S":1789999500,"age":290,"signal":{"rsi14":39.820218373495024,"volume_ratio":0.6500844248788099,"taker_buy_fraction":0.418612933173532,"volume5":180.35728,"return1":8.316610119196428,"return5":-17.946739888833207,"return15":-31.48808277310174,"bollinger_z":-1.3396727994271702,"bar_close_ms":1789999739999,"ref":85287.01946901706,"reference_received_ms":1789999501188,"spot":85209.48888532861,"twap":85179.46206644319,"sigma":10.2279223327038,"spot_z":-2.4049258893059298,"twap_z":-3.336329609949065,"momentum":-0.05413864453250814,"decision_ms":1789999790065,"momentum30":0.020870890261492938,"momentum60":1.1406755552499648,"spot_twap_gap":0.3790061679519094,"range60":1.3321877572893193,"final_mean":85196.76568508768,"final_z":-29.284517427381765,"final_up_prob":0.0,"final_drift_up_prob":0.0,"final_known_seconds":50,"final_sd":3.0819624790876845,"final_drift_shift":-0.14402878314391473},"entry_side":null,"context_gap":null,"book_errors":[null,null],"books":[{"bid":null,"ask":0.01,"asks":[[0.01,52676.03]],"received_ms":1789999790065,"observed_ms":1789999790037,"hash":"08fa1218e72a2f23af0cdf60bd3912d773722849"},{"bid":0.99,"ask":null,"asks":[],"received_ms":1789999790065,"observed_ms":1789999790037,"hash":"fde3265ce018d74b1704d51f7c2a098e0fee048e"}],"intents":{"pair_fast":null,"pair_250":null,"pair_add_fast":null,"pair_add_250":null},"decision_ms":1789999790066,"feature_cutoff_ms":1789999790065,"request_ms":1789999790032,"inventory":{"pair_fast":{"qty":[5.0,0.0],"cash":1.62487,"lots":[[[5.0,0.324974]],[]],"floor":-1.62487},"pair_250":{"qty":[5.0,0.0],"cash":1.41899,"lots":[[[5.0,0.283798]],[]],"floor":-1.41899},"pair_add_fast":{"qty":[10.0,0.0],"cash":2.15637,"lots":[[[5.0,0.324974],[5.0,0.10629999999999999]],[]],"floor":-2.15637},"pair_add_250":{"qty":[10.0,0.0],"cash":1.9504899999999998,"lots":[[[5.0,0.283798],[5.0,0.10629999999999999]],[]],"floor":-1.9504899999999998}}}
{"kind":"decision","recorded_ms":1789999830049,"S":1789999800,"age":30,"signal":{"rsi14":40.99760059062387,"volume_ratio":0.6809919229791964,"taker_buy_fraction":0.4261539807936611,"volume5":175.16821,"return1":6.952473911212853,"return5":-5.781802582820967,"return15":-18.419891653078103,"bollinger_z":-0.94065521295917,"bar_close_ms":1789999799999,"ref":85196.4363623876,"reference_received_ms":1789999802215,"spot":85301.24818865709,"twap":85228.3147291759,"sigma":10.268856047989134,"spot_z":0.6212193114071576,"twap_z":0.18894296349814255,"momentum":0.4054575946773363,"decision_ms":1789999830048,"momentum30":1.5014906576471345,"momentum60":1.3772045969419644,"spot_twap_gap":0.9169150962609792,"range60":1.9832006848298314,"final_mean":85301.24818865709,"final_z":0.6730845579375412,"final_up_prob":0.7495532512890658,"final_drift_up_prob":0.9965531954577092,"final_known_seconds":0,"final_sd":155.71866124912285,"final_drift_shift":315.9307361462976},"entry_side":null,"context_gap":null,"book_errors":[null,null],"books":[{"bid":0.63,"ask":0.64,"asks":[[0.64,655.0]],"received_ms":1789999830040,"observed_ms":1789999830030,"hash":"5ef4489f0aea48b35f4dcb0142a3b942bf23cb99"},{"bid":0.36,"ask":0.37,"asks":[[0.37,817.15]],"received_ms":1789999830048,"observed_ms":1789999830038,"hash":"814f8e6a0d19e494b92896014cc182b88e74defd"}],"intents":{"pair_fast":null,"pair_250":null,"pair_add_fast":null,"pair_add_250":null},"decision_ms":1789999830049,"feature_cutoff_ms":1789999830048,"request_ms":1789999830013,"inventory":{"pair_fast":{"qty":[0.0,0.0],"cash":0.0,"lots":[[],[]],"floor":0.0},"pair_250":{"qty":[0.0,0.0],"cash":0.0,"lots":[[],[]],"floor":0.0},"pair_add_fast":{"qty":[0.0,0.0],"cash":0.0,"lots":[[],[]],"floor":0.0},"pair_add_250":{"qty":[0.0,0.0],"cash":0.0,"lots":[[],[]],"floor":0.0}}}
{"kind":"decision","recorded_ms":1789999840051,"S":1789999800,"age":40,"signal":{"rsi14":40.99760059062387,"volume_ratio":0.6809919229791964,"taker_buy_fraction":0.4261539807936611,"volume5":175.16821,"return1":6.952473911212853,"return5":-5.781802582820967,"return15":-18.419891653078103,"bollinger_z":-0.94065521295917,"bar_close_ms":1789999799999,"ref":85196.4363623876,"reference_received_ms":1789999802215,"spot":85297.79544641313,"twap":85243.95052402218,"sigma":11.801762327940418,"spot_z":0.5326845083673772,"twap_z":0.24970685236685505,"momentum":1.0499303350083833,"decision_ms":1789999840049,"momentum30":0.9014105295932872,"momentum60":0.9468306573164129,"spot_twap_gap":0.5890094544165008,"range60":1.2331693206547685,"final_mean":85297.79544641313,"final_z":0.5790990367569069,"final_up_prob":0.7187388250198332,"final_drift_up_prob":0.9999999948898313,"final_known_seconds":0,"final_sd":175.02892871860018,"final_drift_shift":901.0370526186678},"entry_side":null,"context_gap":null,"book_errors":[null,null],"books":[{"bid":0.69,"ask":0.7,"asks":[[0.7,489.5]],"received_ms":1789999840048,"observed_ms":1789999840038,"hash":"b00d9ce663d81d8fc5908ad2cf8456fe9ed817f5"},{"bid":0.3,"ask":0.31,"asks":[[0.31,218.01]],"received_ms":1789999840049,"observed_ms":1789999840030,"hash":"7e3305284d4756c40411e155f744be5325cc76b1"}],"intents":{"pair_fast":null,"pair_250":null,"pair_add_fast":null,"pair_add_250":null},"decision_ms":1789999840051,"feature_cutoff_ms":1789999840049,"request_ms":1789999840021,"inventory":{"pair_fast":{"qty":[0.0,0.0],"cash":0.0,"lots":[[],[]],"floor":0.0},"pair_250":{"qty":[0.0,0.0],"cash":0.0,"lots":[[],[]],"floor":0.0},"pair_add_fast":{"qty":[0.0,0.0],"cash":0.0,"lots":[[],[]],"floor":0.0},"pair_add_250":{"qty":[0.0,0.0],"cash":0.0,"lots":[[],[]],"floor":0.0}}}
{"kind":"decision","recorded_ms":1789999850069,"S":1789999800,"age":50,"signal":{"rsi14":40.99760059062387,"volume_ratio":0.6809919229791964,"taker_buy_fraction":0.4261539807936611,"volume5":175.16821,"return1":6.952473911212853,"return5":-5.781802582820967,"return15":-18.419891653078103,"bollinger_z":-0.94065521295917,"bar_close_ms":1789999799999,"ref":85196.4363623876,"reference_received_ms":1789999802215,"spot":85241.5331143569,"twap":85257.5122399751,"sigma":12.25201861760541,"spot_z":0.23282296427963708,"twap_z":0.3153190916183922,"momentum":-1.1659051388473605,"decision_ms":1789999850067,"momentum30":-0.693647637047088,"momentum60":0.2789545909915696,"spot_twap_gap":-0.16837194843220385,"range60":1.1562499457294024,"final_mean":85241.5331143569,"final_z":0.25403716612667704,"final_up_prob":0.6002665773600765,"final_drift_up_prob":4.5856682007183736e-08,"final_known_seconds":0,"final_sd":177.52029223479812,"final_drift_shift":-993.4848825425516},"entry_side":null,"context_gap":null,"book_errors":[null,null],"books":[{"bid":0.65,"ask":0.66,"asks":[[0.66,28.0]],"received_ms":1789999850052,"observed_ms":1789999850043,"hash":"7e694d79b59f2846f707ea24eaf13292c46fe91f"},{"bid":0.34,"ask":0.35,"asks":[[0.35,1073.06]],"received_ms":1789999850067,"observed_ms":1789999850054,"hash":"77895efe4a7d8695bae2bb50837c0f1328e26ca5"}],"intents":{"pair_fast":null,"pair_250":null,"pair_add_fast":null,"pair_add_250":null},"decision_ms":1789999850069,"feature_cutoff_ms":1789999850067,"request_ms":1789999850023,"inventory":{"pair_fast":{"qty":[0.0,0.0],"cash":0.0,"lots":[[],[]],"floor":0.0},"pair_250":{"qty":[0.0,0.0],"cash":0.0,"lots":[[],[]],"floor":0.0},"pair_add_fast":{"qty":[0.0,0.0],"cash":0.0,"lots":[[],[]],"floor":0.0},"pair_add_250":{"qty":[0.0,0.0],"cash":0.0,"lots":[[],[]],"floor":0.0}}}
{"kind":"decision","recorded_ms":1789999860077,"S":1789999800,"age":60,"signal":{"rsi14":40.99760059062387,"volume_ratio":0.6809919229791964,"taker_buy_fraction":0.4261539807936611,"volume5":175.16821,"return1":6.952473911212853,"return5":-5.781802582820967,"return15":-18.419891653078103,"bollinger_z":-0.94065521295917,"bar_close_ms":1789999799999,"ref":85196.4363623876,"reference_received_ms":1789999802215,"spot":85289.92388418921,"twap":85266.4397411405,"sigma":12.123950751519963,"spot_z":0.49782034019165694,"twap_z":0.37276745766440744,"momentum":0.46695063236809753,"decision_ms":1789999860076,"momentum30":0.47153106794941324,"momentum60":0.7786759714782733,"spot_twap_gap":0.2500661618524511,"range60":1.1412240594326013,"final_mean":85289.92388418921,"final_z":0.5453521350383882,"final_up_prob":0.7072443231606139,"final_drift_up_prob":0.9969060544273836,"final_known_seconds":0,"final_sd":171.4259756130391,"final_drift_shift":375.81769497494435},"entry_side":null,"context_gap":null,"book_errors":[null,null],"books":[{"bid":0.69,"ask":0.7,"asks":[[0.7,1020.85]],"received_ms":1789999860076,"observed_ms":1789999860062,"hash":"370fc3c6749d51c18c37b2b9cd692cc4861a581a"},{"bid":0.3,"ask":0.31,"asks":[[0.31,1255.61]],"received_ms":1789999860072,"observed_ms":1789999860062,"hash":"8a2f56c20825d3a1627d7cac0d2768082d1840b1"}],"intents":{"pair_fast":null,"pair_250":null,"pair_add_fast":null,"pair_add_250":null},"decision_ms":1789999860077,"feature_cutoff_ms":1789999860076,"request_ms":1789999860041,"inventory":{"pair_fast":{"qty":[0.0,0.0],"cash":0.0,"lots":[[],[]],"floor":0.0},"pair_250":{"qty":[0.0,0.0],"cash":0.0,"lots":[[],[]],"floor":0.0},"pair_add_fast":{"qty":[0.0,0.0],"cash":0.0,"lots":[[],[]],"floor":0.0},"pair_add_250":{"qty":[0.0,0.0],"cash":0.0,"lots":[[],[]],"floor":0.0}}}
{"kind":"decision","recorded_ms":1789999870066,"S":1789999800,"age":70,"signal":{"rsi14":34.55786769296902,"volume_ratio":1.157168539339577,"taker_buy_fraction":0.5010824596568751,"volume5":179.68799,"return1":7.296705007286156,"return5":26.70535424594406,"return15":-15.57216482277925,"bollinger_z":-0.5335704769570956,"bar_close_ms":1789999859999,"ref":85196.4363623876,"reference_received_ms":1789999802215,"spot":85320.55714346083,"twap":85276.91083059163,"sigma":12.310917404097278,"spot_z":0.6648926631843193,"twap_z":0.43108722826157936,"momentum":1.041581162017007,"decision_ms":1789999870065,"momentum30":0.5020322294530377,"momentum60":0.8497245724194442,"spot_twap_gap":0.4577006389724209,"range60":0.885528435146571,"final_mean":85320.55714346083,"final_z":0.7315627466710316,"final_up_prob":0.7677822533913916,"final_drift_up_prob":0.9999999820510862,"final_known_seconds":0,"final_sd":169.66525651837875,"final_drift_shift":810.7227519367098},"entry_side":null,"context_gap":null,"book_errors":[null,null],"books":[{"bid":0.81,"ask":0.82,"asks":[[0.82,1007.56]],"received_ms":1789999870054,"observed_ms":1789999870042,"hash":"b7eb8ac262b87ff6649fa88554551e38508a95ab"},{"bid":0.18,"ask":0.19,"asks":[[0.19,1440.11]],"received_ms":1789999870064,"observed_ms":1789999870049,"hash":"346eaaeff1777be39687f1dbbc41e4ef95d752e9"}],"intents":{"pair_fast":null,"pair_250":null,"pair_add_fast":null,"pair_add_250":null},"decision_ms":1789999870066,"feature_cutoff_ms":1789999870065,"request_ms":1789999870023,"inventory":{"pair_fast":{"qty":[0.0,0.0],"cash":0.0,"lots":[[],[]],"floor":0.0},"pair_250":{"qty":[0.0,0.0],"cash":0.0,"lots":[[],[]],"floor":0.0},"pair_add_fast":{"qty":[0.0,0.0],"cash":0.0,"lots":[[],[]],"floor":0.0},"pair_add_250":{"qty":[0.0,0.0],"cash":0.0,"lots":[[],[]],"floor":0.0}}}
{"kind":"decision","recorded_ms":1789999880075,"S":1789999800,"age":80,"signal":{"rsi14":34.55786769296902,"volume_ratio":1.157168539339577,"taker_buy_fraction":0.5010824596568751,"volume5":179.68799,"return1":7.296705007286156,"return5":26.70535424594406,"return15":-15.57216482277925,"bollinger_z":-0.5335704769570956,"bar_close_ms":1789999859999,"ref":85196.4363623876,"reference_received_ms":1789999802215,"spot":85413.01060726402,"twap":85293.36930128625,"sigma":14.223719099217567,"spot_z":1.0267278775855937,"twap_z":0.45953640831270376,"momentum":1.6098323678009079,"decision_ms":1789999880074,"momentum30":1.8097238380816223,"momentum60":1.1338977394525005,"spot_twap_gap":1.085906300450626,"range60":1.4013795743609085,"final_mean":85413.01060726402,"final_z":1.1351328164057917,"final_up_prob":0.8718401632087108,"final_drift_up_prob":1.0,"final_known_seconds":0,"final_sd":190.79198640575598,"final_drift_shift":1375.2392034879997},"entry_side":null,"context_gap":null,"book_errors":[null,null],"books":[{"bid":0.89,"ask":0.9,"asks":[[0.9,1169.62]],"received_ms":1789999880066,"observed_ms":1789999880058,"hash":"9434dd0561b6a9fe221facbcad463753975693ca"},{"bid":0.1,"ask":0.11,"asks":[[0.11,296.97]],"received_ms":1789999880074,"observed_ms":1789999880058,"hash":"062217d8e9c187a06c0534933581c2a63c930445"}],"intents":{"pair_fast":null,"pair_250":null,"pair_add_fast":null,"pair_add_250":null},"decision_ms":1789999880075,"feature_cutoff_ms":1789999880074,"request_ms":1789999880038,"inventory":{"pair_fast":{"qty":[0.0,0.0],"cash":0.0,"lots":[[],[]],"floor":0.0},"pair_250":{"qty":[0.0,0.0],"cash":0.0,"lots":[[],[]],"floor":0.0},"pair_add_fast":{"qty":[0.0,0.0],"cash":0.0,"lots":[[],[]],"floor":0.0},"pair_add_250":{"qty":[0.0,0.0],"cash":0.0,"lots":[[],[]],"floor":0.0}}}
{"kind":"decision","recorded_ms":1789999890078,"S":1789999800,"age":90,"signal":{"rsi14":34.55786769296902,"volume_ratio":1.157168539339577,"taker_buy_fraction":0.5010824596568751,"volume5":179.68799,"return1":7.296705007286156,"return5":26.70535424594406,"return15":-15.57216482277925,"bollinger_z":-0.5335704769570956,"bar_close_ms":1789999859999,"ref":85196.4363623876,"reference_received_ms":1789999802215,"spot":85391.99249417165,"twap":85311.2799609405,"sigma":10.616445755197066,"spot_z":1.2713416669771795,"twap_z":0.7466165887712702,"momentum":-0.5863063024782821,"decision_ms":1789999890077,"momentum30":1.9258337344767122,"momentum60":1.6219555095588964,"spot_twap_gap":0.9814907432065778,"range60":1.8613140552338436,"final_mean":85391.99249417165,"final_z":1.413078242163008,"final_up_prob":0.9211836400580821,"final_drift_up_prob":0.12589562707619711,"final_known_seconds":0,"final_sd":138.3901654905594,"final_drift_shift":-354.1525651491587},"entry_side":null,"context_gap":null,"book_errors":[null,null],"books":[{"bid":0.87,"ask":0.88,"asks":[[0.88,65.86]],"received_ms":1789999890077,"observed_ms":1789999890053,"hash":"f6147a2cae439639963e4ea5a38bb19c6f52ed7a"},{"bid":0.12,"ask":0.13,"asks":[[0.13,1069.57]],"received_ms":1789999890073,"observed_ms":1789999890053,"hash":"06ffa34070dde5ae1cb478dd9fb99fa30b5e0fbc"}],"intents":{"pair_fast":null,"pair_250":null,"pair_add_fast":null,"pair_add_250":null},"decision_ms":1789999890078,"feature_cutoff_ms":1789999890077,"request_ms":1789999890047,"inventory":{"pair_fast":{"qty":[0.0,0.0],"cash":0.0,"lots":[[],[]],"floor":0.0},"pair_250":{"qty":[0.0,0.0],"cash":0.0,"lots":[[],[]],"floor":0.0},"pair_add_fast":{"qty":[0.0,0.0],"cash":0.0,"lots":[[],[]],"floor":0.0},"pair_add_250":{"qty":[0.0,0.0],"cash":0.0,"lots":[[],[]],"floor":0.0}}}
{"kind":"decision","recorded_ms":1789999900101,"S":1789999800,"age":100,"signal":{"rsi14":34.55786769296902,"volume_ratio":1.157168539339577,"taker_buy_fraction":0.5010824596568751,"volume5":179.68799,"return1":7.296705007286156,"return5":26.70535424594406,"return15":-15.57216482277925,"bollinger_z":-0.5335704769570956,"bar_close_ms":1789999859999,"ref":85196.4363623876,"reference_received_ms":1789999802215,"spot":85388.42626819859,"twap":85331.15763596559,"sigma":10.240243763319699,"spot_z":1.3260555070570055,"twap_z":0.9305066638331745,"momentum":-0.26417643938700186,"decision_ms":1789999900100,"momentum30":0.8526737709985888,"momentum60":1.282403431870505,"spot_twap_gap":0.7219895151746281,"range60":1.8717567727597881,"final_mean":85388.42626819859,"final_z":1.4826678437659389,"final_up_prob":0.9309186589272411,"final_drift_up_prob":0.6406615317003179,"final_known_seconds":0,"final_sd":129.48949194402044,"final_drift_shift":-145.3442169319884},"entry_side":null,"context_gap":null,"book_errors":[null,null],"books":[{"bid":0.88,"ask":0.89,"asks":[[0.89,1293.97]],"received_ms":1789999900083,"observed_ms":1789999900071,"hash":"0183f0bb61a618875d34349f36add230265b042e"},{"bid":0.11,"ask":0.12,"asks":[[0.12,205.0]],"received_ms":1789999900100,"observed_ms":1789999900085,"hash":"d9b7d5c0bd5c88211ae54202b8e4adf7f8dfb74e"}],"intents":{"pair_fast":null,"pair_250":null,"pair_add_fast":null,"pair_add_250":null},"decision_ms":1789999900101,"feature_cutoff_ms":1789999900100,"request_ms":1789999900050,"inventory":{"pair_fast":{"qty":[0.0,0.0],"cash":0.0,"lots":[[],[]],"floor":0.0},"pair_250":{"qty":[0.0,0.0],"cash":0.0,"lots":[[],[]],"floor":0.0},"pair_add_fast":{"qty":[0.0,0.0],"cash":0.0,"lots":[[],[]],"floor":0.0},"pair_add_250":{"qty":[0.0,0.0],"cash":0.0,"lots":[[],[]],"floor":0.0}}}
{"kind":"decision","recorded_ms":1789999910058,"S":1789999800,"age":110,"signal":{},"entry_side":null,"context_gap":"incomplete or stale context","book_errors":[null,null],"books":[{"bid":0.85,"ask":0.86,"asks":[[0.86,346.4]],"received_ms":1789999910052,"observed_ms":1789999910043,"hash":"8472277033f6d963c42e3e175d4a052a7c6f6b68"},{"bid":0.14,"ask":0.15,"asks":[[0.15,569.54]],"received_ms":1789999910057,"observed_ms":1789999910043,"hash":"03a33b379a8564484b794c7d31bc907de9a95aae"}],"intents":{"pair_fast":null,"pair_250":null,"pair_add_fast":null,"pair_add_250":null},"decision_ms":1789999910058,"feature_cutoff_ms":1789999910057,"request_ms":1789999910022,"inventory":{"pair_fast":{"qty":[0.0,0.0],"cash":0.0,"lots":[[],[]],"floor":0.0},"pair_250":{"qty":[0.0,0.0],"cash":0.0,"lots":[[],[]],"floor":0.0},"pair_add_fast":{"qty":[0.0,0.0],"cash":0.0,"lots":[[],[]],"floor":0.0},"pair_add_250":{"qty":[0.0,0.0],"cash":0.0,"lots":[[],[]],"floor":0.0}}}
{"kind":"decision","recorded_ms":1789999920066,"S":1789999800,"age":120,"signal":{"rsi14":34.55786769296902,"volume_ratio":1.157168539339577,"taker_buy_fraction":0.5010824596568751,"volume5":179.68799,"return1":7.296705007286156,"return5":26.70535424594406,"return15":-15.57216482277925,"bollinger_z":-0.5335704769570956,"bar_close_ms":1789999859999,"ref":85196.4363623876,"reference_received_ms":1789999802215,"spot":85368.1606011618,"twap":85362.56580080517,"sigma":10.143024320791383,"spot_z":1.2621364495765397,"twap_z":1.2210158628229624,"momentum":0.19180057057446467,"decision_ms":1789999920065,"momentum30":-0.5187657465596592,"momentum60":1.1220000866126898,"spot_twap_gap":0.07121008462327039,"range60":1.6758606509162952,"final_mean":85368.1606011618,"final_z":1.4312020745849028,"final_up_prob":0.9238138454161081,"final_drift_up_prob":0.9860951420143295,"final_known_seconds":0,"final_sd":119.98601862284657,"final_drift_shift":92.24023175262023},"entry_side":null,"context_gap":null,"book_errors":[null,null],"books":[{"bid":0.83,"ask":0.84,"asks":[[0.84,18.0]],"received_ms":1789999920065,"observed_ms":1789999920054,"hash":"bd737b9e20944b80f432839b3e479575139d9337"},{"bid":0.16,"ask":0.17,"asks":[[0.17,1062.04]],"received_ms":1789999920061,"observed_ms":1789999920052,"hash":"66c82760e08b9834fd683876dcfa43c380204c30"}],"intents":{"pair_fast":null,"pair_250":null,"pair_add_fast":null,"pair_add_250":null},"decision_ms":1789999920066,"feature_cutoff_ms":1789999920065,"request_ms":1789999920029,"inventory":{"pair_fast":{"qty":[0.0,0.0],"cash":0.0,"lots":[[],[]],"floor":0.0},"pair_250":{"qty":[0.0,0.0],"cash":0.0,"lots":[[],[]],"floor":0.0},"pair_add_fast":{"qty":[0.0,0.0],"cash":0.0,"lots":[[],[]],"floor":0.0},"pair_add_250":{"qty":[0.0,0.0],"cash":0.0,"lots":[[],[]],"floor":0.0}}}
{"kind":"decision","recorded_ms":1789999930041,"S":1789999800,"age":130,"signal":{"rsi14":38.87404467671278,"volume_ratio":0.6026610979022772,"taker_buy_fraction":0.5167874179002677,"volume5":156.96458,"return1":6.806793768205255,"return5":22.341417577176863,"return15":-28.53675955619024,"bollinger_z":-0.12045636928890179,"bar_close_ms":1789999919999,"ref":85196.4363623876,"reference_received_ms":1789999802215,"spot":85335.55000789877,"twap":85373.50237500008,"sigma":9.69094309380307,"spot_z":1.1011057978576306,"twap_z":1.4015045926999707,"momentum":0.1832837951844829,"decision_ms":1789999930039,"momentum30":-0.9245834646762137,"momentum60":-0.06729286090599752,"spot_twap_gap":-0.5055885146566699,"range60":1.0889506052405302,"final_mean":85335.55000789877,"final_z":1.2592071066273038,"final_up_prob":0.8960222323306446,"final_drift_up_prob":0.9756259636834588,"final_known_seconds":0,"final_sd":110.47717629530854,"final_drift_shift":78.61350305536322},"entry_side":null,"context_gap":null,"book_errors":[null,null],"books":[{"bid":0.83,"ask":0.84,"asks":[[0.84,155.0]],"received_ms":1789999930039,"observed_ms":1789999930030,"hash":"2d6f622553452eb7fbd7d677657359b9f327c3a6"},{"bid":0.16,"ask":0.17,"asks":[[0.17,754.67]],"received_ms":1789999930033,"observed_ms":1789999930024,"hash":"cefab9497584d6ddb06783953047e3b22bea3172"}],"intents":{"pair_fast":null,"pair_250":null,"pair_add_fast":null,"pair_add_250":null},"decision_ms":1789999930041,"feature_cutoff_ms":1789999930039,"request_ms":1789999930008,"inventory":{"pair_fast":{"qty":[0.0,0.0],"cash":0.0,"lots":[[],[]],"floor":0.0},"pair_250":{"qty":[0.0,0.0],"cash":0.0,"lots":[[],[]],"floor":0.0},"pair_add_fast":{"qty":[0.0,0.0],"cash":0.0,"lots":[[],[]],"floor":0.0},"pair_add_250":{"qty":[0.0,0.0],"cash":0.0,"lots":[[],[]],"floor":0.0}}}
{"kind":"decision","recorded_ms":1789999940041,"S":1789999800,"age":140,"signal":{"rsi14":38.87404467671278,"volume_ratio":0.6026610979022772,"taker_buy_fraction":0.5167874179002677,"volume5":156.96458,"return1":6.806793768205255,"return5":22.341417577176863,"return15":-28.53675955619024,"bollinger_z":-0.12045636928890179,"bar_close_ms":1789999919999,"ref":85196.4363623876,"reference_received_ms":1789999802215,"spot":85347.03863059901,"twap":85370.90079890979,"sigma":7.833848331395987,"spot_z":1.5200247377391234,"twap_z":1.7608649757995483,"momentum":1.0416437763319681,"decision_ms":1789999940040,"momentum30":-0.3488869576642458,"momentum60":-1.0652051833717033,"spot_twap_gap":-0.3932412975185056,"range60":1.4904544743315518,"final_mean":85347.03863059901,"final_z":1.755246538032647,"final_up_prob":0.9603914266305698,"final_drift_up_prob":0.9999999925950696,"final_known_seconds":0,"final_sd":85.80120510034668,"final_drift_shift":335.3544589651836},"entry_side":null,"context_gap":null,"book_errors":[null,null],"books":[{"bid":0.86,"ask":0.87,"asks":[[0.87,1367.52]],"received_ms":1789999940039,"observed_ms":1789999940027,"hash":"28554cd0c63c494063e1c8aa47e3336c62e12340"},{"bid":0.13,"ask":0.14,"asks":[[0.14,30.14]],"received_ms":1789999940040,"observed_ms":1789999940027,"hash":"85e744f2f3f37bdde3ea455a519ac56af11e275e"}],"intents":{"pair_fast":null,"pair_250":null,"pair_add_fast":null,"pair_add_250":null},"decision_ms":1789999940041,"feature_cutoff_ms":1789999940040,"request_ms":1789999940014,"inventory":{"pair_fast":{"qty":[0.0,0.0],"cash":0.0,"lots":[[],[]],"floor":0.0},"pair_250":{"qty":[0.0,0.0],"cash":0.0,"lots":[[],[]],"floor":0.0},"pair_add_fast":{"qty":[0.0,0.0],"cash":0.0,"lots":[[],[]],"floor":0.0},"pair_add_250":{"qty":[0.0,0.0],"cash":0.0,"lots":[[],[]],"floor":0.0}}}
{"kind":"decision","recorded_ms":1789999950050,"S":1789999800,"age":150,"signal":{"rsi14":38.87404467671278,"volume_ratio":0.6026610979022772,"taker_buy_fraction":0.5167874179002677,"volume5":156.96458,"return1":6.806793768205255,"return5":22.341417577176863,"return15":-28.53675955619024,"bollinger_z":-0.12045636928890179,"bar_close_ms":1789999919999,"ref":85196.4363623876,"reference_received_ms":1789999802215,"spot":85318.44010776078,"twap":85359.95049850286,"sigma":7.966404325606301,"spot_z":1.2506510018281414,"twap_z":1.6761708218063869,"momentum":-1.0157406363147745,"decision_ms":1789999950049,"momentum30":-0.26339871711336,"momentum60":-1.2727925966904394,"spot_twap_gap":-0.6726960096744491,"range60":1.2727925966904394,"final_mean":85318.44010776078,"final_z":1.46053250440411,"final_up_prob":0.9279281095052325,"final_drift_up_prob":0.01341875085277644,"final_known_seconds":0,"final_sd":83.53374197786533,"final_drift_shift":-306.93685935794423},"entry_side":null,"context_gap":null,"book_errors":[null,null],"books":[{"bid":0.78,"ask":0.79,"asks":[[0.79,671.06]],"received_ms":1789999950043,"observed_ms":1789999950034,"hash":"68cebe0d4cdbcec7707d5d3d0ddb0df17349c4b1"},{"bid":0.21,"ask":0.22,"asks":[[0.22,87.0]],"received_ms":1789999950049,"observed_ms":1789999950027,"hash":"3f1385b7593258ed1b39746f0872dc6f757c7abe"}],"intents":{"pair_fast":null,"pair_250":null,"pair_add_fast":null,"pair_add_250":null},"decision_ms":1789999950050,"feature_cutoff_ms":1789999950049,"request_ms":1789999950014,"inventory":{"pair_fast":{"qty":[0.0,0.0],"cash":0.0,"lots":[[],[]],"floor":0.0},"pair_250":{"qty":[0.0,0.0],"cash":0.0,"lots":[[],[]],"floor":0.0},"pair_add_fast":{"qty":[0.0,0.0],"cash":0.0,"lots":[[],[]],"floor":0.0},"pair_add_250":{"qty":[0.0,0.0],"cash":0.0,"lots":[[],[]],"floor":0.0}}}
{"kind":"decision","recorded_ms":1789999960064,"S":1789999800,"age":160,"signal":{"rsi14":38.87404467671278,"volume_ratio":0.6026610979022772,"taker_buy_fraction":0.5167874179002677,"volume5":156.96458,"return1":6.806793768205255,"return5":22.341417577176863,"return15":-28.53675955619024,"bollinger_z":-0.12045636928890179,"bar_close_ms":1789999919999,"ref":85196.4363623876,"reference_received_ms":1789999802215,"spot":85245.17939335607,"twap":85339.08463792292,"sigma":11.359984246883242,"spot_z":0.3627175108740788,"twap_z":1.0615061559491263,"momentum":-1.6235408787580121,"decision_ms":1789999960063,"momentum30":-1.22232944985101,"momentum60":-1.5847322643267283,"spot_twap_gap":-1.0671770911675527,"range60":1.6449913391633462,"final_mean":85245.17939335607,"final_z":0.42921179478189186,"final_up_prob":0.6661154498888968,"final_drift_up_prob":9.100643111326079e-08,"final_known_seconds":0,"final_sd":113.56405290129707,"final_drift_shift":-641.1871926484805},"entry_side":null,"context_gap":null,"book_errors":[null,null],"books":[{"bid":0.68,"ask":0.69,"asks":[[0.69,466.0]],"received_ms":1789999960060,"observed_ms":1789999960049,"hash":"4e1a63c7106c8faf496b1dfde6ecf8bc93b4a0bd"},{"bid":0.31,"ask":0.32,"asks":[[0.32,378.13]],"received_ms":1789999960062,"observed_ms":1789999960051,"hash":"8e27931aa14cf158f68ad83bbc74e98521a95583"}],"intents":{"pair_fast":null,"pair_250":null,"pair_add_fast":null,"pair_add_250":null},"decision_ms":1789999960064,"feature_cutoff_ms":1789999960063,"request_ms":1789999960024,"inventory":{"pair_fast":{"qty":[0.0,0.0],"cash":0.0,"lots":[[],[]],"floor":0.0},"pair_250":{"qty":[0.0,0.0],"cash":0.0,"lots":[[],[]],"floor":0.0},"pair_add_fast":{"qty":[0.0,0.0],"cash":0.0,"lots":[[],[]],"floor":0.0},"pair_add_250":{"qty":[0.0,0.0],"cash":0.0,"lots":[[],[]],"floor":0.0}}}
{"kind":"decision","recorded_ms":1789999970064,"S":1789999800,"age":170,"signal":{"rsi14":38.87404467671278,"volume_ratio":0.6026610979022772,"taker_buy_fraction":0.5167874179002677,"volume5":156.96458,"return1":6.806793768205255,"return5":22.341417577176863,"return15":-28.53675955619024,"bollinger_z":-0.12045636928890179,"bar_close_ms":1789999919999,"ref":85196.4363623876,"reference_received_ms":1789999802215,"spot":85254.98539250343,"twap":85317.03607906512,"sigma":11.007878589541727,"spot_z":0.4666052882237389,"twap_z":0.9611169552884328,"momentum":0.08117935628765889,"decision_ms":1789999970063,"momentum30":-1.4768509751657177,"momentum60":-1.2551587321338789,"spot_twap_gap":-0.7277250674575654,"range60":1.452780400774749,"final_mean":85254.98539250343,"final_z":0.560850195788559,"final_up_prob":0.7125501677948558,"final_drift_up_prob":0.7971183211506898,"final_known_seconds":0,"final_sd":104.39334880414476,"final_drift_shift":28.24070554241766},"entry_side":null,"context_gap":null,"book_errors":[null,null],"books":[{"bid":0.72,"ask":0.73,"asks":[[0.73,809.67]],"received_ms":1789999970063,"observed_ms":1789999970054,"hash":"777eb71c729b53ecd670d0de561ab23914672195"},{"bid":0.27,"ask":0.28,"asks":[[0.28,185.0]],"received_ms":1789999970062,"observed_ms":1789999970054,"hash":"272cc41d181a6faf785c737212c9a15a90eb6bbc"}],"intents":{"pair_fast":null,"pair_250":null,"pair_add_fast":null,"pair_add_250":null},"decision_ms":1789999970064,"feature_cutoff_ms":1789999970063,"request_ms":1789999970036,"inventory":{"pair_fast":{"qty":[0.0,0.0],"cash":0.0,"lots":[[],[]],"floor":0.0},"pair_250":{"qty":[0.0,0.0],"cash":0.0,"lots":[[],[]],"floor":0.0},"pair_add_fast":{"qty":[0.0,0.0],"cash":0.0,"lots":[[],[]],"floor":0.0},"pair_add_250":{"qty":[0.0,0.0],"cash":0.0,"lots":[[],[]],"floor":0.0}}}
{"kind":"decision","recorded_ms":1789999980074,"S":1789999800,"age":180,"signal":{"rsi14":38.87404467671278,"volume_ratio":0.6026610979022772,"taker_buy_fraction":0.5167874179002677,"volume5":156.96458,"return1":6.806793768205255,"return5":22.341417577176863,"return15":-28.53675955619024,"bollinger_z":-0.12045636928890179,"bar_close_ms":1789999919999,"ref":85196.4363623876,"reference_received_ms":1789999802215,"spot":85212.73176891572,"twap":85298.52518976161,"sigma":10.729305388256497,"spot_z":0.13868563732019693,"twap_z":0.8688493940425502,"momentum":-1.1238781588871152,"decision_ms":1789999980071,"momentum30":-1.5445920570525102,"momentum60":-1.4102160614785686,"spot_twap_gap":-1.0323019621692122,"range60":1.614107152547355,"final_mean":85212.73176891572,"final_z":0.16987966785006295,"final_up_prob":0.5674476143017545,"final_drift_up_prob":0.0003307666469746229,"final_known_seconds":0,"final_sd":95.92323045101128,"final_drift_shift":-342.918252410985},"entry_side":null,"context_gap":null,"book_errors":[null,null],"books":[{"bid":0.6,"ask":0.61,"asks":[[0.61,996.07]],"received_ms":1789999980062,"observed_ms":1789999980054,"hash":"ef1c38be5a5db865fffcdff6184273fe4c217beb"},{"bid":0.39,"ask":0.4,"asks":[[0.4,18.0]],"received_ms":1789999980070,"observed_ms":1789999980060,"hash":"5daa1929ede567a5a77bc6c7d7fd200a6f6f389e"}],"intents":{"pair_fast":null,"pair_250":null,"pair_add_fast":null,"pair_add_250":null},"decision_ms":1789999980074,"feature_cutoff_ms":1789999980071,"request_ms":1789999980036,"inventory":{"pair_fast":{"qty":[0.0,0.0],"cash":0.0,"lots":[[],[]],"floor":0.0},"pair_250":{"qty":[0.0,0.0],"cash":0.0,"lots":[[],[]],"floor":0.0},"pair_add_fast":{"qty":[0.0,0.0],"cash":0.0,"lots":[[],[]],"floor":0.0},"pair_add_250":{"qty":[0.0,0.0],"cash":0.0,"lots":[[],[]],"floor":0.0}}}
{"kind":"decision","recorded_ms":1789999990052,"S":1789999800,"age":190,"signal":{"rsi14":38.47043726790173,"volume_ratio":1.1914836591800873,"taker_buy_fraction":0.5605978443902706,"volume5":160.78699,"return1":-13.749603094868998,"return5":15.631053646324453,"return15":-40.31981375047171,"bollinger_z":-0.7674827184450651,"bar_close_ms":1789999979999,"ref":85196.4363623876,"reference_received_ms":1789999802215,"spot":85212.3824637304,"twap":85275.36754136921,"sigma":10.3088243678584,"spot_z":0.14751960390890945,"twap_z":0.7302033273908872,"momentum":-0.21673550546400663,"decision_ms":1789999990051,"momentum30":-0.7044709813176223,"momentum60":-1.3631717295468198,"spot_twap_gap":-0.7887745749012418,"range60":1.7987133572474716,"final_mean":85212.3824637304,"final_z":0.18495012303817002,"final_up_prob":0.5733659217023672,"final_drift_up_prob":0.3190998613958467,"final_known_seconds":0,"final_sd":86.21838731903492,"final_drift_shift":-56.48748498371986},"entry_side":null,"context_gap":null,"book_errors":[null,null],"books":[{"bid":0.58,"ask":0.59,"asks":[[0.59,1142.84]],"received_ms":1789999990049,"observed_ms":1789999990007,"hash":"92fd98bb0b139c7c5bc52501ecd741acad83d322"},{"bid":0.41,"ask":0.42,"asks":[[0.42,5.0]],"received_ms":1789999990051,"observed_ms":1789999989996,"hash":"d1ea79c9b4f661bb26c26085277c7f206f4d3fea"}],"intents":{"pair_fast":null,"pair_250":null,"pair_add_fast":null,"pair_add_250":null},"decision_ms":1789999990052,"feature_cutoff_ms":1789999990051,"request_ms":1789999990019,"inventory":{"pair_fast":{"qty":[0.0,0.0],"cash":0.0,"lots":[[],[]],"floor":0.0},"pair_250":{"qty":[0.0,0.0],"cash":0.0,"lots":[[],[]],"floor":0.0},"pair_add_fast":{"qty":[0.0,0.0],"cash":0.0,"lots":[[],[]],"floor":0.0},"pair_add_250":{"qty":[0.0,0.0],"cash":0.0,"lots":[[],[]],"floor":0.0}}}
{"kind":"decision","recorded_ms":1790000000071,"S":1789999800,"age":200,"signal":{"rsi14":38.47043726790173,"volume_ratio":1.1914836591800873,"taker_buy_fraction":0.5605978443902706,"volume5":160.78699,"return1":-13.749603094868998,"return5":15.631053646324453,"return15":-40.31981375047171,"bollinger_z":-0.7674827184450651,"bar_close_ms":1789999979999,"ref":85196.4363623876,"reference_received_ms":1789999802215,"spot":85207.41820776412,"twap":85255.99816441954,"sigma":10.283359575019816,"spot_z":0.10682978609936843,"twap_z":0.5794085012679514,"momentum":-0.1392543719841588,"decision_ms":1790000000070,"momentum30":-0.7713488958867643,"momentum60":-1.7150357615101366,"spot_twap_gap":-0.6098829269213022,"range60":1.8031675302912273,"final_mean":85207.41820776412,"final_z":0.13794887516289137,"final_up_prob":0.5548595885835789,"final_drift_up_prob":0.3974944469085995,"final_known_seconds":0,"final_sd":79.60808207787743,"final_drift_shift":-31.667034089968524},"entry_side":null,"context_gap":null,"book_errors":[null,null],"books":[{"bid":0.58,"ask":0.59,"asks":[[0.59,28.0]],"received_ms":1790000000063,"observed_ms":1790000000053,"hash":"0d63b794c48ad7c8dfd0bcaedf89a1525f69402e"},{"bid":0.41,"ask":0.42,"asks":[[0.42,630.07]],"received_ms":1790000000070,"observed_ms":1790000000058,"hash":"c6c89ff7dbe0b0021186b02d92dd18211b86b8aa"}],"intents":{"pair_fast":null,"pair_250":null,"pair_add_fast":null,"pair_add_250":null},"decision_ms":1790000000071,"feature_cutoff_ms":1790000000070,"request_ms":1790000000024,"inventory":{"pair_fast":{"qty":[0.0,0.0],"cash":0.0,"lots":[[],[]],"floor":0.0},"pair_250":{"qty":[0.0,0.0],"cash":0.0,"lots":[[],[]],"floor":0.0},"pair_add_fast":{"qty":[0.0,0.0],"cash":0.0,"lots":[[],[]],"floor":0.0},"pair_add_250":{"qty":[0.0,0.0],"cash":0.0,"lots":[[],[]],"floor":0.0}}}
{"kind":"decision","recorded_ms":1790000010083,"S":1789999800,"age":210,"signal":{},"entry_side":null,"context_gap":"incomplete or stale context","book_errors":[null,null],"books":[{"bid":0.78,"ask":0.79,"asks":[[0.79,962.87]],"received_ms":1790000010073,"observed_ms":1790000010064,"hash":"ee3807bb5ff7c1377520f9888a6958a47dca89bf"},{"bid":0.21,"ask":0.22,"asks":[[0.22,197.27]],"received_ms":1790000010082,"observed_ms":1790000010073,"hash":"2321bef2fac065ce13f8da1c96bc21c41708c674"}],"intents":{"pair_fast":null,"pair_250":null,"pair_add_fast":null,"pair_add_250":null},"decision_ms":1790000010083,"feature_cutoff_ms":1790000010082,"request_ms":1790000010043,"inventory":{"pair_fast":{"qty":[0.0,0.0],"cash":0.0,"lots":[[],[]],"floor":0.0},"pair_250":{"qty":[0.0,0.0],"cash":0.0,"lots":[[],[]],"floor":0.0},"pair_add_fast":{"qty":[0.0,0.0],"cash":0.0,"lots":[[],[]],"floor":0.0},"pair_add_250":{"qty":[0.0,0.0],"cash":0.0,"lots":[[],[]],"floor":0.0}}}
{"kind":"decision","recorded_ms":1790000020056,"S":1789999800,"age":220,"signal":{"rsi14":38.47043726790173,"volume_ratio":1.1914836591800873,"taker_buy_fraction":0.5605978443902706,"volume5":160.78699,"return1":-13.749603094868998,"return5":15.631053646324453,"return15":-40.31981375047171,"bollinger_z":-0.7674827184450651,"bar_close_ms":1789999979999,"ref":85196.4363623876,"reference_received_ms":1789999802215,"spot":85232.29583131483,"twap":85230.11292551384,"sigma":6.638026005890166,"spot_z":0.6041840425404107,"twap_z":0.5674050022817997,"momentum":-1.0301422096073345,"decision_ms":1790000020055,"momentum30":0.5596911900852428,"momentum60":-0.386318760570624,"spot_twap_gap":0.042454176417664455,"range60":1.0409156407593574,"final_mean":85232.29583131483,"final_z":0.854739336858898,"final_up_prob":0.803652265877089,"final_drift_up_prob":0.04275679648599218,"final_known_seconds":0,"final_sd":41.95368971669118,"final_drift_shift":-108.00109256993939},"entry_side":null,"context_gap":null,"book_errors":[null,null],"books":[{"bid":0.75,"ask":0.76,"asks":[[0.76,96.65]],"received_ms":1790000020055,"observed_ms":1790000020040,"hash":"217126ff8d16d3f18a1fad01add0b333bf552f2b"},{"bid":0.24,"ask":0.25,"asks":[[0.25,1185.76]],"received_ms":1790000020045,"observed_ms":1790000020031,"hash":"aaa08353755ed863b3b86b988fe195eb1b916342"}],"intents":{"pair_fast":null,"pair_250":null,"pair_add_fast":null,"pair_add_250":null},"decision_ms":1790000020056,"feature_cutoff_ms":1790000020055,"request_ms":1790000020007,"inventory":{"pair_fast":{"qty":[0.0,0.0],"cash":0.0,"lots":[[],[]],"floor":0.0},"pair_250":{"qty":[0.0,0.0],"cash":0.0,"lots":[[],[]],"floor":0.0},"pair_add_fast":{"qty":[0.0,0.0],"cash":0.0,"lots":[[],[]],"floor":0.0},"pair_add_250":{"qty":[0.0,0.0],"cash":0.0,"lots":[[],[]],"floor":0.0}}}
{"kind":"decision","recorded_ms":1790000030096,"S":1789999800,"age":230,"signal":{},"entry_side":null,"context_gap":"incomplete or stale context","book_errors":[null,null],"books":[{"bid":0.9,"ask":0.91,"asks":[[0.91,107.0]],"received_ms":1790000030095,"observed_ms":1790000030064,"hash":"f8d52b98c6589b5284326b101438d9944b7227b5"},{"bid":0.09,"ask":0.1,"asks":[[0.1,1033.26]],"received_ms":1790000030062,"observed_ms":1790000030051,"hash":"e4c4827df2c121f5662abb26eedcf5d46ae3514e"}],"intents":{"pair_fast":null,"pair_250":null,"pair_add_fast":null,"pair_add_250":null},"decision_ms":1790000030096,"feature_cutoff_ms":1790000030095,"request_ms":1790000030028,"inventory":{"pair_fast":{"qty":[0.0,0.0],"cash":0.0,"lots":[[],[]],"floor":0.0},"pair_250":{"qty":[0.0,0.0],"cash":0.0,"lots":[[],[]],"floor":0.0},"pair_add_fast":{"qty":[0.0,0.0],"cash":0.0,"lots":[[],[]],"floor":0.0},"pair_add_250":{"qty":[0.0,0.0],"cash":0.0,"lots":[[],[]],"floor":0.0}}}
{"kind":"decision","recorded_ms":1790000040058,"S":1789999800,"age":240,"signal":{"rsi14":38.47043726790173,"volume_ratio":1.1914836591800873,"taker_buy_fraction":0.5605978443902706,"volume5":160.78699,"return1":-13.749603094868998,"return5":15.631053646324453,"return15":-40.31981375047171,"bollinger_z":-0.7674827184450651,"bar_close_ms":1789999979999,"ref":85196.4363623876,"reference_received_ms":1789999802215,"spot":85257.31633891434,"twap":85233.91848753141,"sigma":7.721443261479596,"spot_z":1.0183727135582465,"twap_z":0.6269840376147876,"momentum":-0.5264488345604579,"decision_ms":1790000040057,"momentum30":0.08031059547195848,"momentum60":0.6331451017793388,"spot_twap_gap":0.3912027224030459,"range60":1.4517781665862057,"final_mean":85257.31633891434,"final_z":1.7655505516475964,"final_up_prob":0.9612643589302206,"final_drift_up_prob":0.7419324483091597,"final_known_seconds":0,"final_sd":34.48214862493407,"final_drift_shift":-38.49021679502084},"entry_side":null,"context_gap":null,"book_errors":[null,null],"books":[{"bid":0.75,"ask":0.76,"asks":[[0.76,249.0]],"received_ms":1790000040057,"observed_ms":1790000040027,"hash":"c19695eba88907a464afb116e6f8ca150e24d10f"},{"bid":0.24,"ask":0.25,"asks":[[0.25,44.0]],"received_ms":1790000040049,"observed_ms":1790000040027,"hash":"112010fe36df0da699914ce3764fe1f834e00104"}],"intents":{"pair_fast":null,"pair_250":null,"pair_add_fast":null,"pair_add_250":null},"decision_ms":1790000040058,"feature_cutoff_ms":1790000040057,"request_ms":1790000040019,"inventory":{"pair_fast":{"qty":[0.0,0.0],"cash":0.0,"lots":[[],[]],"floor":0.0},"pair_250":{"qty":[0.0,0.0],"cash":0.0,"lots":[[],[]],"floor":0.0},"pair_add_fast":{"qty":[0.0,0.0],"cash":0.0,"lots":[[],[]],"floor":0.0},"pair_add_250":{"qty":[0.0,0.0],"cash":0.0,"lots":[[],[]],"floor":0.0}}}
{"kind":"decision","recorded_ms":1790000050041,"S":1789999800,"age":250,"signal":{"rsi14":39.81074052466647,"volume_ratio":1.3867905723784584,"taker_buy_fraction":0.5849717337618322,"volume5":176.36765,"return1":0.8069411009238956,"return5":8.12688210508339,"return15":-27.013760808818525,"bollinger_z":-0.6534442878752716,"bar_close_ms":1790000039999,"ref":85196.4363623876,"reference_received_ms":1789999802215,"spot":85264.63120445098,"twap":85239.40114769121,"sigma":9.781259287732292,"spot_z":0.9863829149673375,"twap_z":0.6214506682094032,"momentum":0.877914308732836,"decision_ms":1790000050040,"momentum30":0.5501418165081897,"momentum60":0.6953658240801341,"spot_twap_gap":0.33300275823384673,"range60":0.993626597621047,"final_mean":85260.77832697546,"final_z":1.9358770818444333,"final_up_prob":0.9735586213521195,"final_drift_up_prob":0.9998611555346801,"final_known_seconds":10,"final_sd":33.2365960583394,"final_drift_shift":56.48205808386792},"entry_side":null,"context_gap":null,"book_errors":[null,null],"books":[{"bid":0.97,"ask":0.98,"asks":[[0.98,644.78]],"received_ms":1790000050040,"observed_ms":1790000050030,"hash":"2ff94f378fd9324c0bc7db33d8f2a886ab1c5633"},{"bid":0.02,"ask":0.03,"asks":[[0.03,1611.83]],"received_ms":1790000050037,"observed_ms":1790000050027,"hash":"b48120501f4d5b08a8149df8ed9c52338573c401"}],"intents":{"pair_fast":null,"pair_250":null,"pair_add_fast":null,"pair_add_250":null},"decision_ms":1790000050041,"feature_cutoff_ms":1790000050040,"request_ms":1790000050009,"inventory":{"pair_fast":{"qty":[0.0,0.0],"cash":0.0,"lots":[[],[]],"floor":0.0},"pair_250":{"qty":[0.0,0.0],"cash":0.0,"lots":[[],[]],"floor":0.0},"pair_add_fast":{"qty":[0.0,0.0],"cash":0.0,"lots":[[],[]],"floor":0.0},"pair_add_250":{"qty":[0.0,0.0],"cash":0.0,"lots":[[],[]],"floor":0.0}}}
{"kind":"decision","recorded_ms":1790000060047,"S":1789999800,"age":260,"signal":{"rsi14":39.81074052466647,"volume_ratio":1.3867905723784584,"taker_buy_fraction":0.5849717337618322,"volume5":176.36765,"return1":0.8069411009238956,"return5":8.12688210508339,"return15":-27.013760808818525,"bollinger_z":-0.6534442878752716,"bar_close_ms":1790000039999,"ref":85196.4363623876,"reference_received_ms":1789999802215,"spot":85312.10239317424,"twap":85251.24460231351,"sigma":11.00739731864882,"spot_z":1.6624003534667127,"twap_z":0.7877268443126398,"momentum":1.047962457162021,"decision_ms":1790000060045,"momentum30":0.6954979503269636,"momentum60":1.172546457779752,"spot_twap_gap":0.7137660964632638,"range60":1.172546457779752,"final_mean":85298.0603684703,"final_z":3.798978578468787,"final_up_prob":0.9999273531757827,"final_drift_up_prob":0.9999999900622537,"final_known_seconds":20,"final_sd":26.750349859476493,"final_drift_shift":48.52788789284255},"entry_side":null,"context_gap":null,"book_errors":[null,null],"books":[{"bid":0.99,"ask":null,"asks":[],"received_ms":1790000060045,"observed_ms":1790000060036,"hash":"8b7aa0605bbbc91c4f964dedd9cc0f146717426f"},{"bid":null,"ask":0.01,"asks":[[0.01,35106.55]],"received_ms":1790000060040,"observed_ms":1790000060026,"hash":"f660f3d2737387c2afb6760f7cf9108eb915c14f"}],"intents":{"pair_fast":null,"pair_250":null,"pair_add_fast":null,"pair_add_250":null},"decision_ms":1790000060047,"feature_cutoff_ms":1790000060045,"request_ms":1790000060014,"inventory":{"pair_fast":{"qty":[0.0,0.0],"cash":0.0,"lots":[[],[]],"floor":0.0},"pair_250":{"qty":[0.0,0.0],"cash":0.0,"lots":[[],[]],"floor":0.0},"pair_add_fast":{"qty":[0.0,0.0],"cash":0.0,"lots":[[],[]],"floor":0.0},"pair_add_250":{"qty":[0.0,0.0],"cash":0.0,"lots":[[],[]],"floor":0.0}}}
