{"kind":"decision","recorded_ms":1790000070072,"S":1789999800,"age":270,"signal":{"rsi14":39.81074052466647,"volume_ratio":1.3867905723784584,"taker_buy_fraction":0.5849717337618322,"volume5":176.36765,"return1":0.8069411009238956,"return5":8.12688210508339,"return15":-27.013760808818525,"bollinger_z":-0.6534442878752716,"bar_close_ms":1790000039999,"ref":85196.4363623876,"reference_received_ms":1789999802215,"spot":85298.55212367022,"twap":85266.03695590053,"sigma":10.742422035841996,"spot_z":1.7375786295391977,"twap_z":1.184307910672202,"momentum":-0.6412664312996323,"decision_ms":1790000070071,"momentum30":1.0380203822470464,"momentum60":0.536378435744618,"spot_twap_gap":0.39075825684674337,"range60":1.0590735507523168,"final_mean":85291.29695662812,"final_z":5.604762328995422,"final_up_prob":0.9999999895729539,"final_drift_up_prob":0.9999982913754872,"final_known_seconds":30,"final_sd":16.924998540933498,"final_drift_shift":-16.260873838016007},"entry_side":null,"context_gap":null,"book_errors":[null,null],"books":[{"bid":0.99,"ask":null,"asks":[],"received_ms":1790000070071,"observed_ms":1790000070059,"hash":"18d4becfc21936c2f18bb87761b859a250344e82"},{"bid":null,"ask":0.01,"asks":[[0.01,39985.94]],"received_ms":1790000070046,"observed_ms":1790000070037,"hash":"24163d073e918107512b49e351f131a691049ddc"}],"intents":{"pair_fast":null,"pair_250":null,"pair_add_fast":null,"pair_add_250":null},"decision_ms":1790000070072,"feature_cutoff_ms":1790000070071,"request_ms":1790000070020,"inventory":{"pair_fast":{"qty":[0.0,0.0],"cash":0.0,"lots":[[],[]],"floor":0.0},"pair_250":{"qty":[0.0,0.0],"cash":0.0,"lots":[[],[]],"floor":0.0},"pair_add_fast":{"qty":[0.0,0.0],"cash":0.0,"lots":[[],[]],"floor":0.0},"pair_add_250":{"qty":[0.0,0.0],"cash":0.0,"lots":[[],[]],"floor":0.0}}}
{"kind":"decision","recorded_ms":1790000080080,"S":1789999800,"age":280,"signal":{"rsi14":39.81074052466647,"volume_ratio":1.3867905723784584,"taker_buy_fraction":0.5849717337618322,"volume5":176.36765,"return1":0.8069411009238956,"return5":8.12688210508339,"return15":-27.013760808818525,"bollinger_z":-0.6534442878752716,"bar_close_ms":1790000039999,"ref":85196.4363623876,"reference_received_ms":1789999802215,"spot":85322.86850675714,"twap":85276.56725559564,"sigma":10.600783454123205,"spot_z":2.6721693175267798,"twap_z":1.6935828723327302,"momentum":0.49569924724427855,"decision_ms":1790000080079,"momentum30":0.8136705761031111,"momentum60":1.0681664643574214,"spot_twap_gap":0.5638701939125251,"range60":1.1040621998820614,"final_mean":85301.30254898203,"final_z":11.56225881736355,"final_up_prob":1.0,"final_drift_up_prob":1.0,"final_known_seconds":40,"final_sd":9.069697214954948,"final_drift_shift":5.495373910504948},"entry_side":null,"context_gap":null,"book_errors":[null,null],"books":[{"bid":0.99,"ask":null,"asks":[],"received_ms":1790000080079,"observed_ms":1790000080060,"hash":"7c1e9481803e6a67de9bc634577cd5f25efa5e4f"},{"bid":null,"ask":0.01,"asks":[[0.01,56403.48]],"received_ms":1790000080072,"observed_ms":1790000080060,"hash":"335189f7363cab9c02ea6cae33147addc2e546f8"}],"intents":{"pair_fast":null,"pair_250":null,"pair_add_fast":null,"pair_add_250":null},"decision_ms":1790000080080,"feature_cutoff_ms":1790000080079,"request_ms":1790000080047,"inventory":{"pair_fast":{"qty":[0.0,0.0],"cash":0.0,"lots":[[],[]],"floor":0.0},"pair_250":{"qty":[0.0,0.0],"cash":0.0,"lots":[[],[]],"floor":0.0},"pair_add_fast":{"qty":[0.0,0.0],"cash":0.0,"lots":[[],[]],"floor":0.0},"pair_add_250":{"qty":[0.0,0.0],"cash":0.0,"lots":[[],[]],"floor":0.0}}}
{"kind":"decision","recorded_ms":1790000090035,"S":1789999800,"age":290,"signal":{"rsi14":39.81074052466647,"volume_ratio":1.3867905723784584,"taker_buy_fraction":0.5849717337618322,"volume5":176.36765,"return1":0.8069411009238956,"return5":8.12688210508339,"return15":-27.013760808818525,"bollinger_z":-0.6534442878752716,"bar_close_ms":1790000039999,"ref":85196.4363623876,"reference_received_ms":1789999802215,"spot":85291.23091921913,"twap":85287.34060854172,"sigma":10.592019703817222,"spot_z":2.834799785821578,"twap_z":2.7184613351371496,"momentum":-0.9894226607266972,"decision_ms":1790000090033,"momentum30":-0.5016878213762772,"momentum60":0.25668822364027677,"spot_twap_gap":0.047416542159398334,"range60":1.1232952097027795,"final_mean":85293.32962735942,"final_z":30.212036468249256,"final_up_prob":1.0,"final_drift_up_prob":1.0,"final_known_seconds":50,"final_sd":3.2071080370119067,"final_drift_shift":-2.743521095418325},"entry_side":null,"context_gap":null,"book_errors":[null,null],"books":[{"bid":0.99,"ask":null,"asks":[],"received_ms":1790000090026,"observed_ms":1790000090015,"hash":"aeb419e241ee9dd1c1497551c11ce07d60b37852"},{"bid":null,"ask":0.01,"asks":[[0.01,57594.91]],"received_ms":1790000090033,"observed_ms":1790000090015,"hash":"e6b04ddcbe6497b1dbda0526d3769a9853bbe78a"}],"intents":{"pair_fast":null,"pair_250":null,"pair_add_fast":null,"pair_add_250":null},"decision_ms":1790000090035,"feature_cutoff_ms":1790000090033,"request_ms":1790000090001,"inventory":{"pair_fast":{"qty":[0.0,0.0],"cash":0.0,"lots":[[],[]],"floor":0.0},"pair_250":{"qty":[0.0,0.0],"cash":0.0,"lots":[[],[]],"floor":0.0},"pair_add_fast":{"qty":[0.0,0.0],"cash":0.0,"lots":[[],[]],"floor":0.0},"pair_add_250":{"qty":[0.0,0.0],"cash":0.0,"lots":[[],[]],"floor":0.0}}}
{"kind":"decision","recorded_ms":1790000130054,"S":1790000100,"age":30,"signal":{"rsi14":43.49920344859966,"volume_ratio":1.7553908619845005,"taker_buy_fraction":0.6097213435804362,"volume5":203.17027000000002,"return1":7.216207999314475,"return5":8.390585198488623,"return15":-16.93822283678308,"bollinger_z":-0.21129905037201052,"bar_close_ms":1790000099999,"ref":85288.69659526845,"reference_received_ms":1790000101794,"spot":85264.30194997287,"twap":85273.49605020668,"sigma":12.622378958041043,"spot_z":-0.11762890122752111,"twap_z":-0.07329573322385018,"momentum":1.2178955416462631,"decision_ms":1790000130053,"momentum30":-0.3533700366602852,"momentum60":-0.4290511888285252,"spot_twap_gap":-0.094035620404285,"range60":1.242523985104811,"final_mean":85264.30194997287,"final_z":-0.12744987651388281,"final_up_prob":0.4492921711580245,"final_drift_up_prob":0.9999999987893297,"final_known_seconds":0,"final_sd":191.4057978151814,"final_drift_shift":1166.4512150891542},"entry_side":null,"context_gap":null,"book_errors":[null,null],"books":[{"bid":0.55,"ask":0.56,"asks":[[0.56,994.23]],"received_ms":1790000130053,"observed_ms":1790000130043,"hash":"6fe5e79e9eaaa0b0592c629eeaa7d4aa9078dd45"},{"bid":0.44,"ask":0.45,"asks":[[0.45,201.8]],"received_ms":1790000130051,"observed_ms":1790000130042,"hash":"cea70db3424a8a8e0699d613daca209360545fbe"}],"intents":{"pair_fast":null,"pair_250":null,"pair_add_fast":null,"pair_add_250":null},"decision_ms":1790000130054,"feature_cutoff_ms":1790000130053,"request_ms":1790000130019,"inventory":{"pair_fast":{"qty":[0.0,0.0],"cash":0.0,"lots":[[],[]],"floor":0.0},"pair_250":{"qty":[0.0,0.0],"cash":0.0,"lots":[[],[]],"floor":0.0},"pair_add_fast":{"qty":[0.0,0.0],"cash":0.0,"lots":[[],[]],"floor":0.0},"pair_add_250":{"qty":[0.0,0.0],"cash":0.0,"lots":[[],[]],"floor":0.0}}}
{"kind":"decision","recorded_ms":1790000140069,"S":1790000100,"age":40,"signal":{"rsi14":43.49920344859966,"volume_ratio":1.7553908619845005,"taker_buy_fraction":0.6097213435804362,"volume5":203.17027000000002,"return1":7.216207999314475,"return5":8.390585198488623,"return15":-16.93822283678308,"bollinger_z":-0.21129905037201052,"bar_close_ms":1790000099999,"ref":85288.69659526845,"reference_received_ms":1790000101794,"spot":85352.07602043505,"twap":85272.88916742228,"sigma":18.273003743045656,"spot_z":0.21513330199676642,"twap_z":-0.05365627945794088,"momentum":0.8471227423910913,"decision_ms":1790000140067,"momentum30":1.2690819273973868,"momentum60":0.19573317877609694,"spot_twap_gap":0.5594580348687831,"range60":1.1678529907791795,"final_mean":85352.07602043505,"final_z":0.23388003682276073,"final_up_prob":0.5924609441246007,"final_drift_up_prob":0.9999942608207144,"final_known_seconds":0,"final_sd":270.99117148945487,"final_drift_shift":1125.5313349015096},"entry_side":null,"context_gap":null,"book_errors":[null,null],"books":[{"bid":0.66,"ask":0.67,"asks":[[0.67,316.4]],"received_ms":1790000140058,"observed_ms":1790000140050,"hash":"68fa83c56fe0cc23e6c09de33784c8fb6aada2e3"},{"bid":0.33,"ask":0.34,"asks":[[0.34,718.3]],"received_ms":1790000140067,"observed_ms":1790000140055,"hash":"38f9ddf8ead2571a6eba60615979d2d59093ef2f"}],"intents":{"pair_fast":null,"pair_250":null,"pair_add_fast":null,"pair_add_250":null},"decision_ms":1790000140069,"feature_cutoff_ms":1790000140067,"request_ms":1790000140028,"inventory":{"pair_fast":{"qty":[0.0,0.0],"cash":0.0,"lots":[[],[]],"floor":0.0},"pair_250":{"qty":[0.0,0.0],"cash":0.0,"lots":[[],[]],"floor":0.0},"pair_add_fast":{"qty":[0.0,0.0],"cash":0.0,"lots":[[],[]],"floor":0.0},"pair_add_250":{"qty":[0.0,0.0],"cash":0.0,"lots":[[],[]],"floor":0.0}}}
{"kind":"decision","recorded_ms":1790000150094,"S":1790000100,"age":50,"signal":{"rsi14":43.49920344859966,"volume_ratio":1.7553908619845005,"taker_buy_fraction":0.6097213435804362,"volume5":203.17027000000002,"return1":7.216207999314475,"return5":8.390585198488623,"return15":-16.93822283678308,"bollinger_z":-0.21129905037201052,"bar_close_ms":1790000099999,"ref":85288.69659526845,"reference_received_ms":1790000101794,"spot":85331.6142624341,"twap":85280.25411532153,"sigma":18.231425298431635,"spot_z":0.14891082664122893,"twap_z":-0.029292754029399567,"momentum":-0.46268492458154675,"decision_ms":1790000150093,"momentum30":1.160904610096754,"momentum60":0.27912398827698603,"spot_twap_gap":0.3636888708547108,"range60":1.1705163870907451,"final_mean":85331.6142624341,"final_z":0.16248079081727104,"final_up_prob":0.5645363730102911,"final_drift_up_prob":0.01977938435335952,"final_known_seconds":0,"final_sd":264.13994509610677,"final_drift_shift":-586.6040075532088},"entry_side":null,"context_gap":null,"book_errors":[null,null],"books":[{"bid":0.57,"ask":0.58,"asks":[[0.58,666.25]],"received_ms":1790000150082,"observed_ms":1790000150067,"hash":"c7616e3fd15678f606d051f628e727db3b1cdc35"},{"bid":0.42,"ask":0.43,"asks":[[0.43,221.0]],"received_ms":1790000150092,"observed_ms":1790000150079,"hash":"19dac0e0efe757387f30042b51b7230c1c7a3356"}],"intents":{"pair_fast":null,"pair_250":null,"pair_add_fast":null,"pair_add_250":null},"decision_ms":1790000150094,"feature_cutoff_ms":1790000150093,"request_ms":1790000150043,"inventory":{"pair_fast":{"qty":[0.0,0.0],"cash":0.0,"lots":[[],[]],"floor":0.0},"pair_250":{"qty":[0.0,0.0],"cash":0.0,"lots":[[],[]],"floor":0.0},"pair_add_fast":{"qty":[0.0,0.0],"cash":0.0,"lots":[[],[]],"floor":0.0},"pair_add_250":{"qty":[0.0,0.0],"cash":0.0,"lots":[[],[]],"floor":0.0}}}
{"kind":"decision","recorded_ms":1790000160055,"S":1790000100,"age":60,"signal":{"rsi14":43.49920344859966,"volume_ratio":1.7553908619845005,"taker_buy_fraction":0.6097213435804362,"volume5":203.17027000000002,"return1":7.216207999314475,"return5":8.390585198488623,"return15":-16.93822283678308,"bollinger_z":-0.21129905037201052,"bar_close_ms":1790000099999,"ref":85288.69659526845,"reference_received_ms":1790000101794,"spot":85325.15475085241,"twap":85289.67867799723,"sigma":17.725316537914395,"spot_z":0.1327834465520755,"twap_z":0.003576821905484298,"momentum":-0.029599733336107457,"decision_ms":1790000160054,"momentum30":0.2269043462846053,"momentum60":0.26527619772720273,"spot_twap_gap":0.25838417622058335,"range60":1.2039379960402077,"final_mean":85325.15475085241,"final_z":0.14546025150274663,"final_up_prob":0.5578262516903706,"final_drift_up_prob":0.5025869215599578,"final_known_seconds":0,"final_sd":250.639987263226,"final_drift_shift":-34.83288154644076},"entry_side":null,"context_gap":null,"book_errors":[null,null],"books":[{"bid":0.57,"ask":0.58,"asks":[[0.58,866.0]],"received_ms":1790000160054,"observed_ms":1790000160042,"hash":"3564a51230b791cfe8a03f2d54e9881e3a101e55"},{"bid":0.42,"ask":0.43,"asks":[[0.43,244.3]],"received_ms":1790000160045,"observed_ms":1790000160037,"hash":"75ec2f784ab7251e84b1b592ba259346ecf6c71e"}],"intents":{"pair_fast":null,"pair_250":null,"pair_add_fast":null,"pair_add_250":null},"decision_ms":1790000160055,"feature_cutoff_ms":1790000160054,"request_ms":1790000160016,"inventory":{"pair_fast":{"qty":[0.0,0.0],"cash":0.0,"lots":[[],[]],"floor":0.0},"pair_250":{"qty":[0.0,0.0],"cash":0.0,"lots":[[],[]],"floor":0.0},"pair_add_fast":{"qty":[0.0,0.0],"cash":0.0,"lots":[[],[]],"floor":0.0},"pair_add_250":{"qty":[0.0,0.0],"cash":0.0,"lots":[[],[]],"floor":0.0}}}
{"kind":"decision","recorded_ms":1790000170040,"S":1790000100,"age":70,"signal":{"rsi14":43.63073701137834,"volume_ratio":3.6681571940967457,"taker_buy_fraction":0.6522870352938468,"volume5":279.71278,"return1":3.9341389062657077,"return5":5.0283871904997515,"return15":-12.320251559948579,"bollinger_z":0.045527630100376484,"bar_close_ms":1790000159999,"ref":85288.69659526845,"reference_received_ms":1790000101794,"spot":85321.48706303578,"twap":85297.89426411825,"sigma":16.133138314189353,"spot_z":0.13402930699157659,"twap_z":0.03759498615950652,"momentum":-0.058765588025139155,"decision_ms":1790000170037,"momentum30":-0.4164812059880204,"momentum60":0.7716257882130039,"spot_twap_gap":0.1887926071139967,"range60":1.3227545475802422,"final_mean":85321.48706303578,"final_z":0.1474667962005699,"final_up_prob":0.5586182070187775,"final_drift_up_prob":0.4513922565033907,"final_known_seconds":0,"final_sd":222.35831124128447,"final_drift_shift":-59.95033126740086},"entry_side":null,"context_gap":null,"book_errors":[null,null],"books":[{"bid":0.58,"ask":0.59,"asks":[[0.59,225.21]],"received_ms":1790000170037,"observed_ms":1790000170029,"hash":"3a0d4823eaf389be732d23c1b421ed0e429fdd22"},{"bid":0.41,"ask":0.42,"asks":[[0.42,754.99]],"received_ms":1790000170035,"observed_ms":1790000170023,"hash":"9f73ee578966b53d33dad4ee4a508f4c3c9e9cf6"}],"intents":{"pair_fast":null,"pair_250":null,"pair_add_fast":null,"pair_add_250":null},"decision_ms":1790000170040,"feature_cutoff_ms":1790000170037,"request_ms":1790000170003,"inventory":{"pair_fast":{"qty":[0.0,0.0],"cash":0.0,"lots":[[],[]],"floor":0.0},"pair_250":{"qty":[0.0,0.0],"cash":0.0,"lots":[[],[]],"floor":0.0},"pair_add_fast":{"qty":[0.0,0.0],"cash":0.0,"lots":[[],[]],"floor":0.0},"pair_add_250":{"qty":[0.0,0.0],"cash":0.0,"lots":[[],[]],"floor":0.0}}}
{"kind":"decision","recorded_ms":1790000180327,"S":1790000100,"age":80,"signal":{"rsi14":43.63073701137834,"volume_ratio":3.6681571940967457,"taker_buy_fraction":0.6522870352938468,"volume5":279.71278,"return1":3.9341389062657077,"return5":5.0283871904997515,"return15":-12.320251559948579,"bollinger_z":0.045527630100376484,"bar_close_ms":1790000159999,"ref":85288.69659526845,"reference_received_ms":1790000101794,"spot":85313.2117848491,"twap":85309.41310446261,"sigma":16.100458942970523,"spot_z":0.10273245610508654,"twap_z":0.08681384512397718,"momentum":-0.151297989056219,"decision_ms":1790000180326,"momentum30":-0.15424358871211785,"momentum60":0.7819731733199838,"spot_twap_gap":0.030459226714299317,"range60":1.3254393646432143,"final_mean":85313.2117848491,"final_z":0.11359373566942409,"final_up_prob":0.545220073290321,"final_drift_up_prob":0.28657400407172917,"final_known_seconds":0,"final_sd":215.8146260106416,"final_drift_shift":-146.10975569903727},"entry_side":null,"context_gap":null,"book_errors":[null,null],"books":[{"bid":0.58,"ask":0.59,"asks":[[0.59,5.0]],"received_ms":1790000180326,"observed_ms":1790000180040,"hash":"9f11b845640a45abfe50acd7cbb4707d7883dab0"},{"bid":0.41,"ask":0.42,"asks":[[0.42,2144.81]],"received_ms":1790000180071,"observed_ms":1790000180032,"hash":"7edb787fbfb0ef3ece42fcd79c893bcfb76d36e3"}],"intents":{"pair_fast":null,"pair_250":null,"pair_add_fast":null,"pair_add_250":null},"decision_ms":1790000180327,"feature_cutoff_ms":1790000180326,"request_ms":1790000180013,"inventory":{"pair_fast":{"qty":[0.0,0.0],"cash":0.0,"lots":[[],[]],"floor":0.0},"pair_250":{"qty":[0.0,0.0],"cash":0.0,"lots":[[],[]],"floor":0.0},"pair_add_fast":{"qty":[0.0,0.0],"cash":0.0,"lots":[[],[]],"floor":0.0},"pair_add_250":{"qty":[0.0,0.0],"cash":0.0,"lots":[[],[]],"floor":0.0}}}
{"kind":"decision","recorded_ms":1790000190088,"S":1790000100,"age":90,"signal":{"rsi14":43.63073701137834,"volume_ratio":3.6681571940967457,"taker_buy_fraction":0.6522870352938468,"volume5":279.71278,"return1":3.9341389062657077,"return5":5.0283871904997515,"return15":-12.320251559948579,"bollinger_z":0.045527630100376484,"bar_close_ms":1790000159999,"ref":85288.69659526845,"reference_received_ms":1790000101794,"spot":85335.92258749966,"twap":85326.22259210674,"sigma":9.695212192820568,"spot_z":0.3362049511772236,"twap_z":0.2671500446856972,"momentum":0.786297912724726,"decision_ms":1790000190087,"momentum30":0.21538298235433231,"momentum60":0.436717704668925,"spot_twap_gap":0.1291631369790381,"range60":0.8663462162365948,"final_mean":85335.92258749966,"final_z":0.37368913300040485,"final_up_prob":0.6456821944117807,"final_drift_up_prob":0.999929270400872,"final_known_seconds":0,"final_sd":126.37775107888037,"final_drift_shift":433.71754122674577},"entry_side":null,"context_gap":null,"book_errors":[null,null],"books":[{"bid":0.59,"ask":0.6,"asks":[[0.6,689.24]],"received_ms":1790000190074,"observed_ms":1790000190065,"hash":"111b2acc06874bc7f1ab0086774baa5f8d1c607b"},{"bid":0.4,"ask":0.41,"asks":[[0.41,103.94]],"received_ms":1790000190087,"observed_ms":1790000190072,"hash":"6687b4a1add49554792a4ee73e540807cd65af59"}],"intents":{"pair_fast":null,"pair_250":null,"pair_add_fast":null,"pair_add_250":null},"decision_ms":1790000190088,"feature_cutoff_ms":1790000190087,"request_ms":1790000190049,"inventory":{"pair_fast":{"qty":[0.0,0.0],"cash":0.0,"lots":[[],[]],"floor":0.0},"pair_250":{"qty":[0.0,0.0],"cash":0.0,"lots":[[],[]],"floor":0.0},"pair_add_fast":{"qty":[0.0,0.0],"cash":0.0,"lots":[[],[]],"floor":0.0},"pair_add_250":{"qty":[0.0,0.0],"cash":0.0,"lots":[[],[]],"floor":0.0}}}
{"kind":"decision","recorded_ms":1790000200065,"S":1790000100,"age":100,"signal":{"rsi14":43.63073701137834,"volume_ratio":3.6681571940967457,"taker_buy_fraction":0.6522870352938468,"volume5":279.71278,"return1":3.9341389062657077,"return5":5.0283871904997515,"return15":-12.320251559948579,"bollinger_z":0.045527630100376484,"bar_close_ms":1790000159999,"ref":85288.69659526845,"reference_received_ms":1790000101794,"spot":85337.545,"twap":85331.13522537444,"sigma":4.6300751972260334,"spot_z":0.7461340182978349,"twap_z":0.6482280390947429,"momentum":0.6341088848416256,"decision_ms":1790000200064,"momentum30":0.6557584007197667,"momentum60":-0.5784106931430888,"spot_twap_gap":0.17872244200699003,"range60":1.315621810263821,"final_mean":85337.545,"final_z":0.8342365733752157,"final_up_prob":0.7979261572883996,"final_drift_up_prob":0.999791215580101,"final_known_seconds":0,"final_sd":58.55461902600218,"final_drift_shift":157.77466786516922},"entry_side":null,"context_gap":null,"book_errors":[null,null],"books":[{"bid":0.62,"ask":0.63,"asks":[[0.63,1677.46]],"received_ms":1790000200064,"observed_ms":1790000200055,"hash":"22f35d388af5d211c10e1d10528551d367b7fa45"},{"bid":0.37,"ask":0.38,"asks":[[0.38,1115.28]],"received_ms":1790000200058,"observed_ms":1790000200048,"hash":"a182871c2a979d477ddb488239f60612f6a3fb00"}],"intents":{"pair_fast":null,"pair_250":null,"pair_add_fast":null,"pair_add_250":null},"decision_ms":1790000200065,"feature_cutoff_ms":1790000200064,"request_ms":1790000200012,"inventory":{"pair_fast":{"qty":[0.0,0.0],"cash":0.0,"lots":[[],[]],"floor":0.0},"pair_250":{"qty":[0.0,0.0],"cash":0.0,"lots":[[],[]],"floor":0.0},"pair_add_fast":{"qty":[0.0,0.0],"cash":0.0,"lots":[[],[]],"floor":0.0},"pair_add_250":{"qty":[0.0,0.0],"cash":0.0,"lots":[[],[]],"floor":0.0}}}
{"kind":"decision","recorded_ms":1790000210077,"S":1790000100,"age":110,"signal":{"rsi14":43.63073701137834,"volume_ratio":3.6681571940967457,"taker_buy_fraction":0.6522870352938468,"volume5":279.71278,"return1":3.9341389062657077,"return5":5.0283871904997515,"return15":-12.320251559948579,"bollinger_z":0.045527630100376484,"bar_close_ms":1790000159999,"ref":85288.69659526845,"reference_received_ms":1790000101794,"spot":85356.85954411463,"twap":85329.19698130824,"sigma":4.564821835238193,"spot_z":1.0835142179801152,"twap_z":0.6437917497791973,"momentum":1.6610175865539383,"decision_ms":1790000210076,"momentum30":1.801576690048335,"momentum60":0.8497325649258197,"spot_twap_gap":0.782335353050954,"range60":1.3046376091587064,"final_mean":85356.85954411463,"final_z":1.2195200878202905,"final_up_prob":0.8886765718509053,"final_drift_up_prob":0.9999999999999997,"final_known_seconds":0,"final_sd":55.89325631200368,"final_drift_shift":383.45261713153184},"entry_side":null,"context_gap":null,"book_errors":[null,null],"books":[{"bid":0.76,"ask":0.77,"asks":[[0.77,45.0]],"received_ms":1790000210067,"observed_ms":1790000210060,"hash":"1b5a762c3709c1a884b298d6546d20dc3255a4b1"},{"bid":0.23,"ask":0.24,"asks":[[0.24,146.53]],"received_ms":1790000210075,"observed_ms":1790000210065,"hash":"0baff9249b5990d732bd695a30f65636fc642fcd"}],"intents":{"pair_fast":null,"pair_250":null,"pair_add_fast":null,"pair_add_250":null},"decision_ms":1790000210077,"feature_cutoff_ms":1790000210076,"request_ms":1790000210042,"inventory":{"pair_fast":{"qty":[0.0,0.0],"cash":0.0,"lots":[[],[]],"floor":0.0},"pair_250":{"qty":[0.0,0.0],"cash":0.0,"lots":[[],[]],"floor":0.0},"pair_add_fast":{"qty":[0.0,0.0],"cash":0.0,"lots":[[],[]],"floor":0.0},"pair_add_250":{"qty":[0.0,0.0],"cash":0.0,"lots":[[],[]],"floor":0.0}}}
{"kind":"decision","recorded_ms":1790000220084,"S":1790000100,"age":120,"signal":{},"entry_side":null,"context_gap":"incomplete or stale context","book_errors":[null,null],"books":[{"bid":0.8,"ask":0.81,"asks":[[0.81,683.0]],"received_ms":1790000220082,"observed_ms":1790000220071,"hash":"d5da5d11d36e3916960face84a07102aae520b10"},{"bid":0.19,"ask":0.2,"asks":[[0.2,686.5]],"received_ms":1790000220078,"observed_ms":1790000220070,"hash":"020bd93bd02f0a3f00737a5471914cf48d8ae8a0"}],"intents":{"pair_fast":null,"pair_250":null,"pair_add_fast":null,"pair_add_250":null},"decision_ms":1790000220084,"feature_cutoff_ms":1790000220083,"request_ms":1790000220050,"inventory":{"pair_fast":{"qty":[0.0,0.0],"cash":0.0,"lots":[[],[]],"floor":0.0},"pair_250":{"qty":[0.0,0.0],"cash":0.0,"lots":[[],[]],"floor":0.0},"pair_add_fast":{"qty":[0.0,0.0],"cash":0.0,"lots":[[],[]],"floor":0.0},"pair_add_250":{"qty":[0.0,0.0],"cash":0.0,"lots":[[],[]],"floor":0.0}}}
{"kind":"decision","recorded_ms":1790000230064,"S":1790000100,"age":130,"signal":{"rsi14":46.746983695172055,"volume_ratio":1.717404307845121,"taker_buy_fraction":0.6347531302017273,"volume5":321.72607,"return1":9.543881136193331,"return5":7.7659616554625925,"return15":-6.403553310780073,"bollinger_z":0.7157862019578392,"bar_close_ms":1790000219999,"ref":85288.69659526845,"reference_received_ms":1790000101794,"spot":85421.98172783744,"twap":85351.18815079247,"sigma":7.613318253766618,"spot_z":1.3429620798511097,"twap_z":0.629656044617173,"momentum":0.9172175750135049,"decision_ms":1790000230063,"momentum30":2.1366824337034522,"momentum60":1.7137940954996018,"spot_twap_gap":1.2004504727749914,"range60":1.8801365084368438,"final_mean":85421.98172783744,"final_z":1.5358234903204442,"final_up_prob":0.9377091615743324,"final_drift_up_prob":0.9999998270495687,"final_known_seconds":0,"final_sd":86.7841476634629,"final_drift_shift":309.01453787848055},"entry_side":null,"context_gap":null,"book_errors":[null,null],"books":[{"bid":0.86,"ask":0.87,"asks":[[0.87,1138.02]],"received_ms":1790000230059,"observed_ms":1790000230050,"hash":"feccd543c9284208ad46a5ec6e6fc8c0645c824e"},{"bid":0.13,"ask":0.14,"asks":[[0.14,736.88]],"received_ms":1790000230063,"observed_ms":1790000230053,"hash":"fbd5a8aa3fc1110d022e53efd7a6218fce69e4c7"}],"intents":{"pair_fast":null,"pair_250":null,"pair_add_fast":null,"pair_add_250":null},"decision_ms":1790000230064,"feature_cutoff_ms":1790000230063,"request_ms":1790000230033,"inventory":{"pair_fast":{"qty":[0.0,0.0],"cash":0.0,"lots":[[],[]],"floor":0.0},"pair_250":{"qty":[0.0,0.0],"cash":0.0,"lots":[[],[]],"floor":0.0},"pair_add_fast":{"qty":[0.0,0.0],"cash":0.0,"lots":[[],[]],"floor":0.0},"pair_add_250":{"qty":[0.0,0.0],"cash":0.0,"lots":[[],[]],"floor":0.0}}}
{"kind":"decision","recorded_ms":1790000240098,"S":1790000100,"age":140,"signal":{"rsi14":46.746983695172055,"volume_ratio":1.717404307845121,"taker_buy_fraction":0.6347531302017273,"volume5":321.72607,"return1":9.543881136193331,"return5":7.7659616554625925,"return15":-6.403553310780073,"bollinger_z":0.7157862019578392,"bar_close_ms":1790000219999,"ref":85288.69659526845,"reference_received_ms":1790000101794,"spot":85434.37557058448,"twap":85369.5217863496,"sigma":7.607607064779881,"spot_z":1.5143299051199626,"twap_z":0.8401761728189278,"momentum":0.20065539056738022,"decision_ms":1790000240097,"momentum30":1.8617999085094368,"momentum60":2.079817578870206,"spot_twap_gap":1.1005546778877122,"range60":2.079817578870206,"final_mean":85434.37557058448,"final_z":1.7487743717182618,"final_up_prob":0.959834985757154,"final_drift_up_prob":0.9938171312909234,"final_known_seconds":0,"final_sd":83.30347108923452,"final_drift_shift":62.70729770298402},"entry_side":null,"context_gap":null,"book_errors":[null,null],"books":[{"bid":0.86,"ask":0.87,"asks":[[0.87,1110.76]],"received_ms":1790000240078,"observed_ms":1790000240069,"hash":"61244bcd0bf73141232e2d48aadd49cd9b5ed166"},{"bid":0.13,"ask":0.14,"asks":[[0.14,222.49]],"received_ms":1790000240096,"observed_ms":1790000240064,"hash":"1da43b408f5084800c222d0226c4bf10fb61fa76"}],"intents":{"pair_fast":null,"pair_250":null,"pair_add_fast":null,"pair_add_250":null},"decision_ms":1790000240098,"feature_cutoff_ms":1790000240097,"request_ms":1790000240037,"inventory":{"pair_fast":{"qty":[0.0,0.0],"cash":0.0,"lots":[[],[]],"floor":0.0},"pair_250":{"qty":[0.0,0.0],"cash":0.0,"lots":[[],[]],"floor":0.0},"pair_add_fast":{"qty":[0.0,0.0],"cash":0.0,"lots":[[],[]],"floor":0.0},"pair_add_250":{"qty":[0.0,0.0],"cash":0.0,"lots":[[],[]],"floor":0.0}}}
{"kind":"decision","recorded_ms":1790000250047,"S":1790000100,"age":150,"signal":{"rsi14":46.746983695172055,"volume_ratio":1.717404307845121,"taker_buy_fraction":0.6347531302017273,"volume5":321.72607,"return1":9.543881136193331,"return5":7.7659616554625925,"return15":-6.403553310780073,"bollinger_z":0.7157862019578392,"bar_close_ms":1790000219999,"ref":85288.69659526845,"reference_received_ms":1790000101794,"spot":85440.92015752844,"twap":85385.47405607614,"sigma":7.6211202372387135,"spot_z":1.631112965562268,"twap_z":1.0369943309302596,"momentum":0.7276367661699165,"decision_ms":1790000250046,"momentum30":0.9827092464866697,"momentum60":1.9084177226278873,"spot_twap_gap":0.9392399929500713,"range60":1.9084177226278873,"final_mean":85440.92015752844,"final_z":1.904835826828049,"final_up_prob":0.9715992924091941,"final_drift_up_prob":0.9999971478862276,"final_known_seconds":0,"final_sd":79.91426878686332,"final_drift_shift":210.35274470184893},"entry_side":null,"context_gap":null,"book_errors":[null,null],"books":[{"bid":0.88,"ask":0.89,"asks":[[0.89,328.32]],"received_ms":1790000250043,"observed_ms":1790000250036,"hash":"22d276079248f4e46077cc3ac607b70184653ef8"},{"bid":0.11,"ask":0.12,"asks":[[0.12,622.0]],"received_ms":1790000250046,"observed_ms":1790000250034,"hash":"218fc7fbba7e5b27d636477268bc7f15d511ea40"}],"intents":{"pair_fast":null,"pair_250":null,"pair_add_fast":null,"pair_add_250":null},"decision_ms":1790000250047,"feature_cutoff_ms":1790000250046,"request_ms":1790000250019,"inventory":{"pair_fast":{"qty":[0.0,0.0],"cash":0.0,"lots":[[],[]],"floor":0.0},"pair_250":{"qty":[0.0,0.0],"cash":0.0,"lots":[[],[]],"floor":0.0},"pair_add_fast":{"qty":[0.0,0.0],"cash":0.0,"lots":[[],[]],"floor":0.0},"pair_add_250":{"qty":[0.0,0.0],"cash":0.0,"lots":[[],[]],"floor":0.0}}}
{"kind":"decision","recorded_ms":1790000260053,"S":1790000100,"age":160,"signal":{},"entry_side":null,"context_gap":"incomplete or stale context","book_errors":[null,null],"books":[{"bid":0.84,"ask":0.85,"asks":[[0.85,332.8]],"received_ms":1790000260052,"observed_ms":1790000260040,"hash":"7fde1096c4ce39bcfa151aca5f4dc87d4bab87c5"},{"bid":0.15,"ask":0.16,"asks":[[0.16,424.82]],"received_ms":1790000260048,"observed_ms":1790000260039,"hash":"664cde43d2ea0a09449e4e6a112025163aba876d"}],"intents":{"pair_fast":null,"pair_250":null,"pair_add_fast":null,"pair_add_250":null},"decision_ms":1790000260053,"feature_cutoff_ms":1790000260052,"request_ms":1790000260021,"inventory":{"pair_fast":{"qty":[0.0,0.0],"cash":0.0,"lots":[[],[]],"floor":0.0},"pair_250":{"qty":[0.0,0.0],"cash":0.0,"lots":[[],[]],"floor":0.0},"pair_add_fast":{"qty":[0.0,0.0],"cash":0.0,"lots":[[],[]],"floor":0.0},"pair_add_250":{"qty":[0.0,0.0],"cash":0.0,"lots":[[],[]],"floor":0.0}}}
{"kind":"decision","recorded_ms":1790000270100,"S":1790000100,"age":170,"signal":{"rsi14":46.746983695172055,"volume_ratio":1.717404307845121,"taker_buy_fraction":0.6347531302017273,"volume5":321.72607,"return1":9.543881136193331,"return5":7.7659616554625925,"return15":-6.403553310780073,"bollinger_z":0.7157862019578392,"bar_close_ms":1790000219999,"ref":85288.69659526845,"reference_received_ms":1790000101794,"spot":85391.86680266532,"twap":85411.76323778383,"sigma":7.9091481602722435,"spot_z":1.144506715295952,"twap_z":1.3652255078442068,"momentum":-0.435624048174668,"decision_ms":1790000270099,"momentum30":-0.727541553377764,"momentum60":0.5724371816645863,"spot_twap_gap":-0.32476553438023464,"range60":1.3021760507515199,"final_mean":85391.86680266532,"final_z":1.3757589002245187,"final_up_prob":0.9155518551244346,"final_drift_up_prob":0.4698359635228836,"final_known_seconds":0,"final_sd":74.99148824697822,"final_drift_shift":-108.84572921432024},"entry_side":null,"context_gap":null,"book_errors":[null,null],"books":[{"bid":0.8,"ask":0.81,"asks":[[0.81,755.48]],"received_ms":1790000270073,"observed_ms":1790000270060,"hash":"ad8220453044107215caa0b94b076f9da0a966c3"},{"bid":0.19,"ask":0.2,"asks":[[0.2,339.71]],"received_ms":1790000270099,"observed_ms":1790000270066,"hash":"e05abbb0b3c2f5782660903065421b2eb1193154"}],"intents":{"pair_fast":null,"pair_250":null,"pair_add_fast":null,"pair_add_250":null},"decision_ms":1790000270100,"feature_cutoff_ms":1790000270099,"request_ms":1790000270026,"inventory":{"pair_fast":{"qty":[0.0,0.0],"cash":0.0,"lots":[[],[]],"floor":0.0},"pair_250":{"qty":[0.0,0.0],"cash":0.0,"lots":[[],[]],"floor":0.0},"pair_add_fast":{"qty":[0.0,0.0],"cash":0.0,"lots":[[],[]],"floor":0.0},"pair_add_250":{"qty":[0.0,0.0],"cash":0.0,"lots":[[],[]],"floor":0.0}}}
{"kind":"decision","recorded_ms":1790000280058,"S":1790000100,"age":180,"signal":{"rsi14":46.746983695172055,"volume_ratio":1.717404307845121,"taker_buy_fraction":0.6347531302017273,"volume5":321.72607,"return1":9.543881136193331,"return5":7.7659616554625925,"return15":-6.403553310780073,"bollinger_z":0.7157862019578392,"bar_close_ms":1790000219999,"ref":85288.69659526845,"reference_received_ms":1790000101794,"spot":85370.36472385887,"twap":85412.49771528102,"sigma":6.637497725111767,"spot_z":1.1234681504085111,"twap_z":1.703070925214407,"momentum":-0.10811881543815625,"decision_ms":1790000280057,"momentum30":-1.821170895864606,"momentum60":-0.5744484760672434,"spot_twap_gap":-0.8194874075637171,"range60":1.3355591476505333,"final_mean":85370.36472385887,"final_z":1.3761253574184704,"final_up_prob":0.915608586919807,"final_drift_up_prob":0.8490081434299311,"final_known_seconds":0,"final_sd":59.34643101383163,"final_drift_shift":-20.411411280214995},"entry_side":null,"context_gap":null,"book_errors":[null,null],"books":[{"bid":0.85,"ask":0.86,"asks":[[0.86,2089.52]],"received_ms":1790000280057,"observed_ms":1790000280044,"hash":"d77b52bd073e8a25850da60e316691a2f1588a0a"},{"bid":0.14,"ask":0.15,"asks":[[0.15,45.6]],"received_ms":1790000280053,"observed_ms":1790000280041,"hash":"d8b75384f857745988c151ff9b12cbd5b3058c63"}],"intents":{"pair_fast":null,"pair_250":null,"pair_add_fast":null,"pair_add_250":null},"decision_ms":1790000280058,"feature_cutoff_ms":1790000280057,"request_ms":1790000280021,"inventory":{"pair_fast":{"qty":[0.0,0.0],"cash":0.0,"lots":[[],[]],"floor":0.0},"pair_250":{"qty":[0.0,0.0],"cash":0.0,"lots":[[],[]],"floor":0.0},"pair_add_fast":{"qty":[0.0,0.0],"cash":0.0,"lots":[[],[]],"floor":0.0},"pair_add_250":{"qty":[0.0,0.0],"cash":0.0,"lots":[[],[]],"floor":0.0}}}
{"kind":"decision","recorded_ms":1790000290048,"S":1790000100,"age":190,"signal":{"rsi14":53.359815298375416,"volume_ratio":0.7728578796286009,"taker_buy_fraction":0.6384731968446247,"volume5":313.37635,"return1":-3.0956381241185014,"return5":18.397035493294695,"return15":-11.719870507725142,"bollinger_z":0.6476264749229066,"bar_close_ms":1790000279999,"ref":85288.69659526845,"reference_received_ms":1790000101794,"spot":85362.57328687308,"twap":85406.55425950239,"sigma":6.202146531952029,"spot_z":1.1359569523361959,"twap_z":1.812225617643253,"momentum":-0.7261305156191281,"decision_ms":1790000290047,"momentum30":-1.183050274013095,"momentum60":-1.3941045894914632,"spot_twap_gap":-0.9154764599952213,"range60":1.5403359807566535,"final_mean":85362.57328687308,"final_z":1.4241713449013862,"final_up_prob":0.9228015611459446,"final_drift_up_prob":0.2203866390368267,"final_known_seconds":0,"final_sd":51.87345741024243,"final_drift_shift":-113.86532115463194},"entry_side":null,"context_gap":null,"book_errors":[null,null],"books":[{"bid":0.82,"ask":0.83,"asks":[[0.83,427.95]],"received_ms":1790000290047,"observed_ms":1790000290036,"hash":"7a2130f67f4bde7fb7bfb32c53ab3f85960a471b"},{"bid":0.17,"ask":0.18,"asks":[[0.18,366.33]],"received_ms":1790000290047,"observed_ms":1790000290034,"hash":"3c7eeda784f4a9aee22ddd680f51b88e5611a4ab"}],"intents":{"pair_fast":null,"pair_250":null,"pair_add_fast":null,"pair_add_250":null},"decision_ms":1790000290048,"feature_cutoff_ms":1790000290047,"request_ms":1790000290010,"inventory":{"pair_fast":{"qty":[0.0,0.0],"cash":0.0,"lots":[[],[]],"floor":0.0},"pair_250":{"qty":[0.0,0.0],"cash":0.0,"lots":[[],[]],"floor":0.0},"pair_add_fast":{"qty":[0.0,0.0],"cash":0.0,"lots":[[],[]],"floor":0.0},"pair_add_250":{"qty":[0.0,0.0],"cash":0.0,"lots":[[],[]],"floor":0.0}}}
{"kind":"decision","recorded_ms":1790000300072,"S":1790000100,"age":200,"signal":{},"entry_side":null,"context_gap":"incomplete or stale context","book_errors":[null,null],"books":[{"bid":0.92,"ask":0.93,"asks":[[0.93,1160.24]],"received_ms":1790000300057,"observed_ms":1790000300043,"hash":"b2b6e50c88291cbe720ee8aadc905284018fcfa0"},{"bid":0.07,"ask":0.08,"asks":[[0.08,239.66]],"received_ms":1790000300071,"observed_ms":1790000300057,"hash":"34fdbc7c8f39215dca30be33acd493fc8be7e09b"}],"intents":{"pair_fast":null,"pair_250":null,"pair_add_fast":null,"pair_add_250":null},"decision_ms":1790000300072,"feature_cutoff_ms":1790000300071,"request_ms":1790000300022,"inventory":{"pair_fast":{"qty":[0.0,0.0],"cash":0.0,"lots":[[],[]],"floor":0.0},"pair_250":{"qty":[0.0,0.0],"cash":0.0,"lots":[[],[]],"floor":0.0},"pair_add_fast":{"qty":[0.0,0.0],"cash":0.0,"lots":[[],[]],"floor":0.0},"pair_add_250":{"qty":[0.0,0.0],"cash":0.0,"lots":[[],[]],"floor":0.0}}}
{"kind":"decision","recorded_ms":1790000310076,"S":1790000100,"age":210,"signal":{"rsi14":53.359815298375416,"volume_ratio":0.7728578796286009,"taker_buy_fraction":0.6384731968446247,"volume5":313.37635,"return1":-3.0956381241185014,"return5":18.397035493294695,"return15":-11.719870507725142,"bollinger_z":0.6476264749229066,"bar_close_ms":1790000279999,"ref":85288.69659526845,"reference_received_ms":1790000101794,"spot":85399.11606117898,"twap":85390.89946685046,"sigma":7.0756645676745045,"spot_z":1.645652684935341,"twap_z":1.5231954677566875,"momentum":0.08866266771984403,"decision_ms":1790000310075,"momentum30":0.5754415168063094,"momentum60":-0.6834322822694596,"spot_twap_gap":0.1499163444533095,"range60":1.326815298399345,"final_mean":85399.11606117898,"final_z":2.2086117038539252,"final_up_prob":0.9863991697096703,"final_drift_up_prob":0.9927854516841788,"final_known_seconds":0,"final_sd":49.99496548798055,"final_drift_shift":11.888199187574621},"entry_side":null,"context_gap":null,"book_errors":[null,null],"books":[{"bid":0.91,"ask":0.92,"asks":[[0.92,50.0]],"received_ms":1790000310074,"observed_ms":1790000310064,"hash":"9f903e14a9e2c0d3c89e366d6b034ff9d09bdab0"},{"bid":0.08,"ask":0.09,"asks":[[0.09,576.71]],"received_ms":1790000310075,"observed_ms":1790000310064,"hash":"9aa3ba0dca467732cb850ea4d134d801d6f468ce"}],"intents":{"pair_fast":null,"pair_250":null,"pair_add_fast":null,"pair_add_250":null},"decision_ms":1790000310076,"feature_cutoff_ms":1790000310075,"request_ms":1790000310046,"inventory":{"pair_fast":{"qty":[0.0,0.0],"cash":0.0,"lots":[[],[]],"floor":0.0},"pair_250":{"qty":[0.0,0.0],"cash":0.0,"lots":[[],[]],"floor":0.0},"pair_add_fast":{"qty":[0.0,0.0],"cash":0.0,"lots":[[],[]],"floor":0.0},"pair_add_250":{"qty":[0.0,0.0],"cash":0.0,"lots":[[],[]],"floor":0.0}}}
{"kind":"decision","recorded_ms":1790000320045,"S":1790000100,"age":220,"signal":{"rsi14":53.359815298375416,"volume_ratio":0.7728578796286009,"taker_buy_fraction":0.6384731968446247,"volume5":313.37635,"return1":-3.0956381241185014,"return5":18.397035493294695,"return15":-11.719870507725142,"bollinger_z":0.6476264749229066,"bar_close_ms":1790000279999,"ref":85288.69659526845,"reference_received_ms":1790000101794,"spot":85368.17869058892,"twap":85384.0289697528,"sigma":6.636903068488457,"spot_z":1.3393097149445228,"twap_z":1.6063941794794527,"momentum":-0.9915346842936982,"decision_ms":1790000320045,"momentum30":0.11897829552505937,"momentum60":-0.6727093817111309,"spot_twap_gap":-0.3083158244189076,"range60":0.8261659634507698,"final_mean":85368.17869058892,"final_z":1.894603196085542,"final_up_prob":0.9709275044705232,"final_drift_up_prob":0.2798130965212454,"final_known_seconds":0,"final_sd":41.95184273133308,"final_drift_shift":-103.95666727570475},"entry_side":null,"context_gap":null,"book_errors":[null,null],"books":[{"bid":0.91,"ask":0.92,"asks":[[0.92,579.68]],"received_ms":1790000320028,"observed_ms":1790000320014,"hash":"8a43223c90e95a8dd0a68324227e3d68cf21b5ee"},{"bid":0.08,"ask":0.09,"asks":[[0.09,1051.96]],"received_ms":1790000320044,"observed_ms":1790000320033,"hash":"3c7fbaa1fb1c2bed305e713564664fbbfa0a4e31"}],"intents":{"pair_fast":null,"pair_250":null,"pair_add_fast":null,"pair_add_250":null},"decision_ms":1790000320045,"feature_cutoff_ms":1790000320045,"request_ms":1790000320001,"inventory":{"pair_fast":{"qty":[0.0,0.0],"cash":0.0,"lots":[[],[]],"floor":0.0},"pair_250":{"qty":[0.0,0.0],"cash":0.0,"lots":[[],[]],"floor":0.0},"pair_add_fast":{"qty":[0.0,0.0],"cash":0.0,"lots":[[],[]],"floor":0.0},"pair_add_250":{"qty":[0.0,0.0],"cash":0.0,"lots":[[],[]],"floor":0.0}}}
{"kind":"decision","recorded_ms":1790000330055,"S":1790000100,"age":230,"signal":{"rsi14":53.359815298375416,"volume_ratio":0.7728578796286009,"taker_buy_fraction":0.6384731968446247,"volume5":313.37635,"return1":-3.0956381241185014,"return5":18.397035493294695,"return15":-11.719870507725142,"bollinger_z":0.6476264749229066,"bar_close_ms":1790000279999,"ref":85288.69659526845,"reference_received_ms":1790000101794,"spot":85361.30368769937,"twap":85378.28855536589,"sigma":5.294399314433311,"spot_z":1.6397623481204808,"twap_z":2.023349482033836,"momentum":-0.44835029203578275,"decision_ms":1790000330054,"momentum30":-1.2355252755890704,"momentum60":-0.27628240671038906,"spot_twap_gap":-0.41416161811225166,"range60":1.016179076940632,"final_mean":85361.30368769937,"final_z":2.506068520643525,"final_up_prob":0.9938959020550722,"final_drift_up_prob":0.9293698297881456,"final_known_seconds":0,"final_sd":28.972508865109734,"final_drift_shift":-29.985234479928316},"entry_side":null,"context_gap":null,"book_errors":[null,null],"books":[{"bid":0.88,"ask":0.89,"asks":[[0.89,27.0]],"received_ms":1790000330052,"observed_ms":1790000330044,"hash":"38fdb6d072a915a7114238cbb39ad101561b2466"},{"bid":0.11,"ask":0.12,"asks":[[0.12,518.91]],"received_ms":1790000330054,"observed_ms":1790000330043,"hash":"714ba8abd32dc5f97c721e0b6c205e3da3af6cc3"}],"intents":{"pair_fast":null,"pair_250":null,"pair_add_fast":null,"pair_add_250":null},"decision_ms":1790000330055,"feature_cutoff_ms":1790000330054,"request_ms":1790000330021,"inventory":{"pair_fast":{"qty":[0.0,0.0],"cash":0.0,"lots":[[],[]],"floor":0.0},"pair_250":{"qty":[0.0,0.0],"cash":0.0,"lots":[[],[]],"floor":0.0},"pair_add_fast":{"qty":[0.0,0.0],"cash":0.0,"lots":[[],[]],"floor":0.0},"pair_add_250":{"qty":[0.0,0.0],"cash":0.0,"lots":[[],[]],"floor":0.0}}}
{"kind":"decision","recorded_ms":1790000340065,"S":1790000100,"age":240,"signal":{"rsi14":53.359815298375416,"volume_ratio":0.7728578796286009,"taker_buy_fraction":0.6384731968446247,"volume5":313.37635,"return1":-3.0956381241185014,"return5":18.397035493294695,"return15":-11.719870507725142,"bollinger_z":0.6476264749229066,"bar_close_ms":1790000279999,"ref":85288.69659526845,"reference_received_ms":1790000101794,"spot":85353.08659534047,"twap":85375.0011306381,"sigma":5.7960692070608495,"spot_z":1.434963931075841,"twap_z":1.923340506370477,"momentum":0.17682234321153514,"decision_ms":1790000340064,"momentum30":-1.1309056179907353,"momentum60":-0.5285134425790645,"spot_twap_gap":-0.488116038735442,"range60":1.1834370680522213,"final_mean":85353.08659534047,"final_z":2.488084387824105,"final_up_prob":0.9935783373012076,"final_drift_up_prob":0.9979016221323824,"final_known_seconds":0,"final_sd":25.879347335291786,"final_drift_shift":9.702082669061303},"entry_side":null,"context_gap":null,"book_errors":[null,null],"books":[{"bid":0.93,"ask":0.94,"asks":[[0.94,344.22]],"received_ms":1790000340063,"observed_ms":1790000340055,"hash":"93112059076b3b81aaaf1f270c7bcf639cf81afc"},{"bid":0.06,"ask":0.07,"asks":[[0.07,86.0]],"received_ms":1790000340063,"observed_ms":1790000340054,"hash":"b5233f471b4c541ab44b93946ab3c78e3e287c77"}],"intents":{"pair_fast":null,"pair_250":null,"pair_add_fast":null,"pair_add_250":null},"decision_ms":1790000340065,"feature_cutoff_ms":1790000340064,"request_ms":1790000340027,"inventory":{"pair_fast":{"qty":[0.0,0.0],"cash":0.0,"lots":[[],[]],"floor":0.0},"pair_250":{"qty":[0.0,0.0],"cash":0.0,"lots":[[],[]],"floor":0.0},"pair_add_fast":{"qty":[0.0,0.0],"cash":0.0,"lots":[[],[]],"floor":0.0},"pair_add_250":{"qty":[0.0,0.0],"cash":0.0,"lots":[[],[]],"floor":0.0}}}
{"kind":"decision","recorded_ms":1790000350044,"S":1790000100,"age":250,"signal":{"rsi14":54.11545776159989,"volume_ratio":0.6556559671430722,"taker_buy_fraction":0.6218251222498264,"volume5":296.04132,"return1":-3.5699218622806512,"return5":14.027872094666185,"return15":4.236354125941673,"bollinger_z":0.46404680835139184,"bar_close_ms":1790000339999,"ref":85288.69659526845,"reference_received_ms":1790000101794,"spot":85349.21258223648,"twap":85371.05871878969,"sigma":5.768208212887464,"spot_z":1.4843318856901495,"twap_z":2.0201723914760135,"momentum":-0.059668897786030475,"decision_ms":1790000350043,"momentum30":-0.620297706816715,"momentum60":-0.3276839095095648,"spot_twap_gap":-0.488942839364051,"range60":1.3126002370764087,"final_mean":85348.94792307018,"final_z":3.074277351451424,"final_up_prob":0.9989449341958261,"final_drift_up_prob":0.9984556960479348,"final_known_seconds":10,"final_sd":19.59853354586984,"final_drift_shift":-2.263603720847934},"entry_side":null,"context_gap":null,"book_errors":[null,null],"books":[{"bid":0.97,"ask":0.98,"asks":[[0.98,657.86]],"received_ms":1790000350043,"observed_ms":1790000350033,"hash":"6029210c0799c8f9b074f5aca7901a4a8c365d92"},{"bid":0.02,"ask":0.03,"asks":[[0.03,1207.0]],"received_ms":1790000350035,"observed_ms":1790000350028,"hash":"e689e20fec917213444a228659b2186e4148bda3"}],"intents":{"pair_fast":null,"pair_250":null,"pair_add_fast":null,"pair_add_250":null},"decision_ms":1790000350044,"feature_cutoff_ms":1790000350043,"request_ms":1790000350011,"inventory":{"pair_fast":{"qty":[0.0,0.0],"cash":0.0,"lots":[[],[]],"floor":0.0},"pair_250":{"qty":[0.0,0.0],"cash":0.0,"lots":[[],[]],"floor":0.0},"pair_add_fast":{"qty":[0.0,0.0],"cash":0.0,"lots":[[],[]],"floor":0.0},"pair_add_250":{"qty":[0.0,0.0],"cash":0.0,"lots":[[],[]],"floor":0.0}}}
{"kind":"decision","recorded_ms":1790000360053,"S":1790000100,"age":260,"signal":{"rsi14":54.11545776159989,"volume_ratio":0.6556559671430722,"taker_buy_fraction":0.6218251222498264,"volume5":296.04132,"return1":-3.5699218622806512,"return5":14.027872094666185,"return15":4.236354125941673,"bollinger_z":0.46404680835139184,"bar_close_ms":1790000339999,"ref":85288.69659526845,"reference_received_ms":1790000101794,"spot":85375.42136585532,"twap":85370.47146152105,"sigma":5.40048644035926,"spot_z":2.5407548270326976,"twap_z":2.3957386656115625,"momentum":1.4245413343990476,"decision_ms":1790000360052,"momentum30":0.8646376923412653,"momentum60":-0.5190011274687485,"spot_twap_gap":0.11832821150246728,"range60":1.401975831502782,"final_mean":85370.10125192048,"final_z":6.204198517079459,"final_up_prob":0.9999999997251182,"final_drift_up_prob":1.0,"final_known_seconds":20,"final_sd":13.120898118899422,"final_drift_shift":32.35316484586493},"entry_side":null,"context_gap":null,"book_errors":[null,null],"books":[{"bid":0.99,"ask":null,"asks":[],"received_ms":1790000360052,"observed_ms":1790000360045,"hash":"bdba3328807b9fd69211348c193044a327fbf681"},{"bid":null,"ask":0.01,"asks":[[0.01,9498.07]],"received_ms":1790000360049,"observed_ms":1790000360033,"hash":"09dd1fdd4a89bb671cfcc46b4b2813b7ad8e9368"}],"intents":{"pair_fast":null,"pair_250":null,"pair_add_fast":null,"pair_add_250":null},"decision_ms":1790000360053,"feature_cutoff_ms":1790000360052,"request_ms":1790000360018,"inventory":{"pair_fast":{"qty":[0.0,0.0],"cash":0.0,"lots":[[],[]],"floor":0.0},"pair_250":{"qty":[0.0,0.0],"cash":0.0,"lots":[[],[]],"floor":0.0},"pair_add_fast":{"qty":[0.0,0.0],"cash":0.0,"lots":[[],[]],"floor":0.0},"pair_add_250":{"qty":[0.0,0.0],"cash":0.0,"lots":[[],[]],"floor":0.0}}}
{"kind":"decision","recorded_ms":1790000370062,"S":1790000100,"age":270,"signal":{"rsi14":54.11545776159989,"volume_ratio":0.6556559671430722,"taker_buy_fraction":0.6218251222498264,"volume5":296.04132,"return1":-3.5699218622806512,"return5":14.027872094666185,"return15":4.236354125941673,"bollinger_z":0.46404680835139184,"bar_close_ms":1790000339999,"ref":85288.69659526845,"reference_received_ms":1790000101794,"spot":85344.65690891427,"twap":85366.20498129314,"sigma":5.705572368088686,"spot_z":1.792512848772045,"twap_z":2.4827376543342465,"momentum":-1.1876052326697304,"decision_ms":1790000370061,"momentum30":-0.1806062938433219,"momentum60":-1.003092434819271,"spot_twap_gap":-0.4875661901627917,"range60":1.0104893718194197,"final_mean":85351.53754955601,"final_z":6.987140848962717,"final_up_prob":0.9999999999985973,"final_drift_up_prob":0.9999999043222912,"final_known_seconds":30,"final_sd":8.993800990413531,"final_drift_shift":-16.005330704347895},"entry_side":null,"context_gap":null,"book_errors":[null,null],"books":[{"bid":0.99,"ask":null,"asks":[],"received_ms":1790000370060,"observed_ms":1790000370044,"hash":"a67a4a1805d70f95eebb313bb3e91200a4349780"},{"bid":null,"ask":0.01,"asks":[[0.01,17979.35]],"received_ms":1790000370061,"observed_ms":1790000370044,"hash":"ab70f5ab1c55a26aaa5eece57ed6aff91cf6e007"}],"intents":{"pair_fast":null,"pair_250":null,"pair_add_fast":null,"pair_add_250":null},"decision_ms":1790000370062,"feature_cutoff_ms":1790000370061,"request_ms":1790000370027,"inventory":{"pair_fast":{"qty":[0.0,0.0],"cash":0.0,"lots":[[],[]],"floor":0.0},"pair_250":{"qty":[0.0,0.0],"cash":0.0,"lots":[[],[]],"floor":0.0},"pair_add_fast":{"qty":[0.0,0.0],"cash":0.0,"lots":[[],[]],"floor":0.0},"pair_add_250":{"qty":[0.0,0.0],"cash":0.0,"lots":[[],[]],"floor":0.0}}}
{"kind":"decision","recorded_ms":1790000380068,"S":1790000100,"age":280,"signal":{"rsi14":54.11545776159989,"volume_ratio":0.6556559671430722,"taker_buy_fraction":0.6218251222498264,"volume5":296.04132,"return1":-3.5699218622806512,"return5":14.027872094666185,"return15":4.236354125941673,"bollinger_z":0.46404680835139184,"bar_close_ms":1790000339999,"ref":85288.69659526845,"reference_received_ms":1790000101794,"spot":85371.84341446383,"twap":85360.10290362833,"sigma":5.842620122654936,"spot_z":3.1875107296907457,"twap_z":2.7374273155281883,"momentum":1.2574746809782809,"decision_ms":1790000380067,"momentum30":0.6484143721838308,"momentum60":0.06702392633469943,"spot_twap_gap":0.2594201573226285,"range60":0.6636403246439937,"final_mean":85363.50531471842,"final_z":14.95193654679246,"final_up_prob":1.0,"final_drift_up_prob":1.0,"final_known_seconds":40,"final_sd":5.0032796230676775,"final_drift_shift":7.692561744371518},"entry_side":null,"context_gap":null,"book_errors":[null,null],"books":[{"bid":0.99,"ask":null,"asks":[],"received_ms":1790000380066,"observed_ms":1790000380054,"hash":"af4d60d299c87da213200b36162e74e688f6e68b"},{"bid":null,"ask":0.01,"asks":[[0.01,40269.57]],"received_ms":1790000380063,"observed_ms":1790000380052,"hash":"2d82819ebbb5acf6fb04412b7fdc86f2ca5ba957"}],"intents":{"pair_fast":null,"pair_250":null,"pair_add_fast":null,"pair_add_250":null},"decision_ms":1790000380068,"feature_cutoff_ms":1790000380067,"request_ms":1790000380036,"inventory":{"pair_fast":{"qty":[0.0,0.0],"cash":0.0,"lots":[[],[]],"floor":0.0},"pair_250":{"qty":[0.0,0.0],"cash":0.0,"lots":[[],[]],"floor":0.0},"pair_add_fast":{"qty":[0.0,0.0],"cash":0.0,"lots":[[],[]],"floor":0.0},"pair_add_250":{"qty":[0.0,0.0],"cash":0.0,"lots":[[],[]],"floor":0.0}}}
{"kind":"decision","recorded_ms":1790000390100,"S":1790000100,"age":290,"signal":{"rsi14":54.11545776159989,"volume_ratio":0.6556559671430722,"taker_buy_fraction":0.6218251222498264,"volume5":296.04132,"return1":-3.5699218622806512,"return5":14.027872094666185,"return15":4.236354125941673,"bollinger_z":0.46404680835139184,"bar_close_ms":1790000339999,"ref":85288.69659526845,"reference_received_ms":1790000101794,"spot":85365.53727509282,"twap":85359.31870936911,"sigma":4.923617260714404,"spot_z":4.95983675029898,"twap_z":4.558446876066738,"momentum":0.30845613226550955,"decision_ms":1790000390099,"momentum30":-0.02028810474929714,"momentum60":0.4114412261119028,"spot_twap_gap":0.16305357226828204,"range60":0.7875100987048802,"final_mean":85360.99042074742,"final_z":48.97903297371736,"final_up_prob":1.0,"final_drift_up_prob":1.0,"final_known_seconds":50,"final_sd":1.4760157783792094,"final_drift_shift":0.3923327579200798},"entry_side":null,"context_gap":null,"book_errors":[null,null],"books":[{"bid":0.99,"ask":null,"asks":[],"received_ms":1790000390099,"observed_ms":1790000390073,"hash":"44be01c36bfc5ea37abb939a938c88c53b4ce72d"},{"bid":null,"ask":0.01,"asks":[[0.01,52493.78]],"received_ms":1790000390080,"observed_ms":1790000390069,"hash":"2bee5030cff9febeec1ec152f14ad485d84f797d"}],"intents":{"pair_fast":null,"pair_250":null,"pair_add_fast":null,"pair_add_250":null},"decision_ms":1790000390100,"feature_cutoff_ms":1790000390099,"request_ms":1790000390040,"inventory":{"pair_fast":{"qty":[0.0,0.0],"cash":0.0,"lots":[[],[]],"floor":0.0},"pair_250":{"qty":[0.0,0.0],"cash":0.0,"lots":[[],[]],"floor":0.0},"pair_add_fast":{"qty":[0.0,0.0],"cash":0.0,"lots":[[],[]],"floor":0.0},"pair_add_250":{"qty":[0.0,0.0],"cash":0.0,"lots":[[],[]],"floor":0.0}}}
