{"kind":"decision","recorded_ms":1790001740086,"S":1790001600,"age":140,"signal":{"rsi14":54.57141786991756,"volume_ratio":0.8427784898975591,"taker_buy_fraction":0.31003505284206123,"volume5":198.63154,"return1":21.47241729100976,"return5":-15.16755182877802,"return15":18.190113416527534,"bollinger_z":0.47293940581197175,"bar_close_ms":1790001719999,"ref":85799.28883377438,"reference_received_ms":1790001601703,"spot":85807.55771477,"twap":85770.10870742581,"sigma":7.153498326430258,"spot_z":0.09140788506529979,"twap_z":-0.3225700837725161,"momentum":0.6198210670008584,"decision_ms":1790001740085,"momentum30":1.0536519387015735,"momentum60":1.3517672120585622,"spot_twap_gap":0.6758435996746064,"range60":1.7200096624503427,"final_mean":85807.55771477,"final_z":0.10555808577215396,"final_up_prob":0.5420335092029419,"final_drift_up_prob":0.9924695432878343,"final_known_seconds":0,"final_sd":78.3348896025312,"final_drift_shift":182.15626414984547},"entry_side":null,"context_gap":null,"book_errors":[null,null],"books":[{"bid":0.59,"ask":0.6,"asks":[[0.6,71.0]],"received_ms":1790001740064,"observed_ms":1790001740054,"hash":"f2d04429456f6b44c0dcc1976dabcae583f0fc22"},{"bid":0.4,"ask":0.41,"asks":[[0.41,341.96]],"received_ms":1790001740085,"observed_ms":1790001740062,"hash":"86f2582fc138bce0ccf7df47e8eb06c480d72d4c"}],"intents":{"pair_fast":null,"pair_250":null,"pair_add_fast":null,"pair_add_250":null},"decision_ms":1790001740086,"feature_cutoff_ms":1790001740085,"request_ms":1790001740031,"inventory":{"pair_fast":{"qty":[0.0,0.0],"cash":0.0,"lots":[[],[]],"floor":0.0},"pair_250":{"qty":[0.0,0.0],"cash":0.0,"lots":[[],[]],"floor":0.0},"pair_add_fast":{"qty":[0.0,0.0],"cash":0.0,"lots":[[],[]],"floor":0.0},"pair_add_250":{"qty":[0.0,0.0],"cash":0.0,"lots":[[],[]],"floor":0.0}}}
{"kind":"decision","recorded_ms":1790001750042,"S":1790001600,"age":150,"signal":{"rsi14":54.57141786991756,"volume_ratio":0.8427784898975591,"taker_buy_fraction":0.31003505284206123,"volume5":198.63154,"return1":21.47241729100976,"return5":-15.16755182877802,"return15":18.190113416527534,"bollinger_z":0.47293940581197175,"bar_close_ms":1790001719999,"ref":85799.28883377438,"reference_received_ms":1790001601703,"spot":85826.25118266506,"twap":85784.07015916302,"sigma":7.18162625915229,"spot_z":0.30658341395494804,"twap_z":-0.17304846981757485,"momentum":0.6006338887337814,"decision_ms":1790001750041,"momentum30":0.19809455012302085,"momentum60":1.5647380618250357,"spot_twap_gap":0.7582609456142045,"range60":1.6482508093518666,"final_mean":85826.25118266506,"final_z":0.35803009436190136,"final_up_prob":0.6398396038484863,"final_drift_up_prob":0.9943109629300559,"final_known_seconds":0,"final_sd":75.30749318359288,"final_drift_shift":163.63095664828646},"entry_side":null,"context_gap":null,"book_errors":[null,null],"books":[{"bid":0.55,"ask":0.56,"asks":[[0.56,1175.18]],"received_ms":1790001750041,"observed_ms":1790001750016,"hash":"68256f6dac72d1f1a669d2d143282b9213880688"},{"bid":0.44,"ask":0.45,"asks":[[0.45,147.18]],"received_ms":1790001750038,"observed_ms":1790001750030,"hash":"9862b59b94b9a5d75e1e1dea3a1ee121c7450148"}],"intents":{"pair_fast":null,"pair_250":null,"pair_add_fast":null,"pair_add_250":null},"decision_ms":1790001750042,"feature_cutoff_ms":1790001750041,"request_ms":1790001750011,"inventory":{"pair_fast":{"qty":[0.0,0.0],"cash":0.0,"lots":[[],[]],"floor":0.0},"pair_250":{"qty":[0.0,0.0],"cash":0.0,"lots":[[],[]],"floor":0.0},"pair_add_fast":{"qty":[0.0,0.0],"cash":0.0,"lots":[[],[]],"floor":0.0},"pair_add_250":{"qty":[0.0,0.0],"cash":0.0,"lots":[[],[]],"floor":0.0}}}
{"kind":"decision","recorded_ms":1790001760057,"S":1790001600,"age":160,"signal":{"rsi14":54.57141786991756,"volume_ratio":0.8427784898975591,"taker_buy_fraction":0.31003505284206123,"volume5":198.63154,"return1":21.47241729100976,"return5":-15.16755182877802,"return15":18.190113416527534,"bollinger_z":0.47293940581197175,"bar_close_ms":1790001719999,"ref":85799.28883377438,"reference_received_ms":1790001601703,"spot":85818.30172309665,"twap":85797.94779798537,"sigma":7.242747586966024,"spot_z":0.22190527615938083,"twap_z":-0.01565164095029128,"momentum":0.0596537270662743,"decision_ms":1790001760056,"momentum30":0.6242776662210343,"momentum60":0.8374719275295771,"spot_twap_gap":0.362801602749988,"range60":1.1518760881517953,"final_mean":85818.30172309665,"final_z":0.2625828794851602,"final_up_prob":0.6035639513420648,"final_drift_up_prob":0.6808371908650768,"final_known_seconds":0,"final_sd":72.40719333853718,"final_drift_shift":15.021471096290421},"entry_side":null,"context_gap":null,"book_errors":[null,null],"books":[{"bid":0.52,"ask":0.53,"asks":[[0.53,242.09]],"received_ms":1790001760056,"observed_ms":1790001760036,"hash":"6d265d43884e37e04b322cb2900fab3b1024353d"},{"bid":0.47,"ask":0.48,"asks":[[0.48,90.54]],"received_ms":1790001760042,"observed_ms":1790001760034,"hash":"692b5a7be8d3084122a8248ebdb12f2fc3bf9bd1"}],"intents":{"pair_fast":null,"pair_250":null,"pair_add_fast":null,"pair_add_250":null},"decision_ms":1790001760057,"feature_cutoff_ms":1790001760056,"request_ms":1790001760014,"inventory":{"pair_fast":{"qty":[0.0,0.0],"cash":0.0,"lots":[[],[]],"floor":0.0},"pair_250":{"qty":[0.0,0.0],"cash":0.0,"lots":[[],[]],"floor":0.0},"pair_add_fast":{"qty":[0.0,0.0],"cash":0.0,"lots":[[],[]],"floor":0.0},"pair_add_250":{"qty":[0.0,0.0],"cash":0.0,"lots":[[],[]],"floor":0.0}}}
{"kind":"decision","recorded_ms":1790001770068,"S":1790001600,"age":170,"signal":{"rsi14":54.57141786991756,"volume_ratio":0.8427784898975591,"taker_buy_fraction":0.31003505284206123,"volume5":198.63154,"return1":21.47241729100976,"return5":-15.16755182877802,"return15":18.190113416527534,"bollinger_z":0.47293940581197175,"bar_close_ms":1790001719999,"ref":85799.28883377438,"reference_received_ms":1790001601703,"spot":85781.58210338168,"twap":85802.65587895652,"sigma":7.762159746210083,"spot_z":-0.2001225671016254,"twap_z":0.03805455385904041,"momentum":-1.1435277162390034,"decision_ms":1790001770067,"momentum30":-0.7298231875384898,"momentum60":0.2545988672545419,"spot_twap_gap":-0.3504968742019001,"range60":1.0747972253493845,"final_mean":85781.58210338168,"final_z":-0.2405449576968514,"final_up_prob":0.40495390746789073,"final_drift_up_prob":2.5481212498346117e-05,"final_known_seconds":0,"final_sd":73.61089819649581,"final_drift_shift":-280.50344355151714},"entry_side":null,"context_gap":null,"book_errors":[null,null],"books":[{"bid":0.44,"ask":0.45,"asks":[[0.45,20.0]],"received_ms":1790001770062,"observed_ms":1790001770050,"hash":"047f1aecaac68496e52274fc8453132c06274424"},{"bid":0.55,"ask":0.56,"asks":[[0.56,524.26]],"received_ms":1790001770067,"observed_ms":1790001770050,"hash":"163b34340d9b2688d70d22fbe8520cad0c25af11"}],"intents":{"pair_fast":null,"pair_250":null,"pair_add_fast":null,"pair_add_250":null},"decision_ms":1790001770068,"feature_cutoff_ms":1790001770067,"request_ms":1790001770030,"inventory":{"pair_fast":{"qty":[0.0,0.0],"cash":0.0,"lots":[[],[]],"floor":0.0},"pair_250":{"qty":[0.0,0.0],"cash":0.0,"lots":[[],[]],"floor":0.0},"pair_add_fast":{"qty":[0.0,0.0],"cash":0.0,"lots":[[],[]],"floor":0.0},"pair_add_250":{"qty":[0.0,0.0],"cash":0.0,"lots":[[],[]],"floor":0.0}}}
{"kind":"decision","recorded_ms":1790001780086,"S":1790001600,"age":180,"signal":{"rsi14":54.57141786991756,"volume_ratio":0.8427784898975591,"taker_buy_fraction":0.31003505284206123,"volume5":198.63154,"return1":21.47241729100976,"return5":-15.16755182877802,"return15":18.190113416527534,"bollinger_z":0.47293940581197175,"bar_close_ms":1790001719999,"ref":85799.28883377438,"reference_received_ms":1790001601703,"spot":85789.89455390777,"twap":85804.92205317348,"sigma":6.047486697573215,"spot_z":-0.14185734149965615,"twap_z":0.08506384091029524,"momentum":-0.0843352165089813,"decision_ms":1790001780085,"momentum30":-0.8163668434466983,"momentum60":-0.6097841400780203,"spot_twap_gap":-0.32080133616819884,"range60":1.0485612507218103,"final_mean":85789.89455390777,"final_z":-0.17376984776968818,"final_up_prob":0.43102317091585074,"final_drift_up_prob":0.329240275519533,"final_known_seconds":0,"final_sd":54.06162223875189,"final_drift_shift":-14.501603760928669},"entry_side":null,"context_gap":null,"book_errors":[null,null],"books":[{"bid":0.47,"ask":0.48,"asks":[[0.48,198.35]],"received_ms":1790001780066,"observed_ms":1790001780058,"hash":"bb43d850a869db19482d0206b7057fb43d653f4a"},{"bid":0.52,"ask":0.53,"asks":[[0.53,979.73]],"received_ms":1790001780085,"observed_ms":1790001780072,"hash":"1d99c7485656ce92eac818a8715eff908c1d1b22"}],"intents":{"pair_fast":null,"pair_250":null,"pair_add_fast":null,"pair_add_250":null},"decision_ms":1790001780086,"feature_cutoff_ms":1790001780085,"request_ms":1790001780042,"inventory":{"pair_fast":{"qty":[0.0,0.0],"cash":0.0,"lots":[[],[]],"floor":0.0},"pair_250":{"qty":[0.0,0.0],"cash":0.0,"lots":[[],[]],"floor":0.0},"pair_add_fast":{"qty":[0.0,0.0],"cash":0.0,"lots":[[],[]],"floor":0.0},"pair_add_250":{"qty":[0.0,0.0],"cash":0.0,"lots":[[],[]],"floor":0.0}}}
{"kind":"decision","recorded_ms":1790001790075,"S":1790001600,"age":190,"signal":{"rsi14":54.343954271220625,"volume_ratio":0.6983906940636092,"taker_buy_fraction":0.3198425857111571,"volume5":185.65786,"return1":-4.853595063108242,"return5":-20.60884242282211,"return15":6.524676772708963,"bollinger_z":0.0619724598869915,"bar_close_ms":1790001779999,"ref":85799.28883377438,"reference_received_ms":1790001601703,"spot":85799.84321440723,"twap":85801.75881988388,"sigma":5.748715881396472,"spot_z":0.009197822341893425,"twap_z":0.040979955063263074,"momentum":0.5568724631336418,"decision_ms":1790001790073,"momentum30":-0.311494756065431,"momentum60":0.1416298687828929,"spot_twap_gap":-0.04301892957218538,"range60":1.1030568123659805,"final_mean":85799.84321440723,"final_z":0.011532268795132302,"final_up_prob":0.5046006076361663,"final_drift_up_prob":0.954933610384266,"final_known_seconds":0,"final_sd":48.07212203409997,"final_drift_shift":80.91333476909477},"entry_side":null,"context_gap":null,"book_errors":[null,null],"books":[{"bid":0.48,"ask":0.49,"asks":[[0.49,579.61]],"received_ms":1790001790073,"observed_ms":1790001790059,"hash":"2b008f33a9c2449332383457a040eaadc025233a"},{"bid":0.51,"ask":0.52,"asks":[[0.52,112.14]],"received_ms":1790001790070,"observed_ms":1790001790059,"hash":"d482dd88e873d0c6eae6877cd523517a71498fe7"}],"intents":{"pair_fast":null,"pair_250":null,"pair_add_fast":null,"pair_add_250":null},"decision_ms":1790001790075,"feature_cutoff_ms":1790001790073,"request_ms":1790001790040,"inventory":{"pair_fast":{"qty":[0.0,0.0],"cash":0.0,"lots":[[],[]],"floor":0.0},"pair_250":{"qty":[0.0,0.0],"cash":0.0,"lots":[[],[]],"floor":0.0},"pair_add_fast":{"qty":[0.0,0.0],"cash":0.0,"lots":[[],[]],"floor":0.0},"pair_add_250":{"qty":[0.0,0.0],"cash":0.0,"lots":[[],[]],"floor":0.0}}}
{"kind":"decision","recorded_ms":1790001800042,"S":1790001600,"age":200,"signal":{"rsi14":54.343954271220625,"volume_ratio":0.6983906940636092,"taker_buy_fraction":0.3198425857111571,"volume5":185.65786,"return1":-4.853595063108242,"return5":-20.60884242282211,"return15":6.524676772708963,"bollinger_z":0.0619724598869915,"bar_close_ms":1790001779999,"ref":85799.28883377438,"reference_received_ms":1790001601703,"spot":85769.600687225,"twap":85800.7477906914,"sigma":6.054595144597448,"spot_z":-0.4904412890693853,"twap_z":0.024101629581018167,"momentum":-1.535246809500657,"decision_ms":1790001800041,"momentum30":-0.6605882018770671,"momentum60":-0.9170814736206019,"spot_twap_gap":-0.6641358622500355,"range60":1.3069915766042002,"final_mean":85769.600687225,"final_z":-0.6332435660897946,"final_up_prob":0.2632872999317497,"final_drift_up_prob":2.590227198839834e-07,"final_known_seconds":0,"final_sd":46.88266591115915,"final_drift_shift":-205.63967342448842},"entry_side":null,"context_gap":null,"book_errors":[null,null],"books":[{"bid":0.23,"ask":0.24,"asks":[[0.24,218.39]],"received_ms":1790001800041,"observed_ms":1790001800030,"hash":"8b759525c42eff8b1c99179053334ed1e9f36e64"},{"bid":0.76,"ask":0.77,"asks":[[0.77,1850.47]],"received_ms":1790001800037,"observed_ms":1790001800027,"hash":"002576cb1a593efb97dc7550c8a10180009a114b"}],"intents":{"pair_fast":null,"pair_250":null,"pair_add_fast":null,"pair_add_250":null},"decision_ms":1790001800042,"feature_cutoff_ms":1790001800041,"request_ms":1790001800001,"inventory":{"pair_fast":{"qty":[0.0,0.0],"cash":0.0,"lots":[[],[]],"floor":0.0},"pair_250":{"qty":[0.0,0.0],"cash":0.0,"lots":[[],[]],"floor":0.0},"pair_add_fast":{"qty":[0.0,0.0],"cash":0.0,"lots":[[],[]],"floor":0.0},"pair_add_250":{"qty":[0.0,0.0],"cash":0.0,"lots":[[],[]],"floor":0.0}}}
{"kind":"decision","recorded_ms":1790001810079,"S":1790001600,"age":210,"signal":{},"entry_side":null,"context_gap":"incomplete or stale context","book_errors":[null,null],"books":[{"bid":0.37,"ask":0.38,"asks":[[0.38,348.1]],"received_ms":1790001810058,"observed_ms":1790001810042,"hash":"df1bf2fcf1067ee49529901d8469b6a3d8f54ef3"},{"bid":0.62,"ask":0.63,"asks":[[0.63,422.0]],"received_ms":1790001810077,"observed_ms":1790001810064,"hash":"33a78dc24e1e09bc0c48a97c4e60fdc3bf7d12f8"}],"intents":{"pair_fast":null,"pair_250":null,"pair_add_fast":null,"pair_add_250":null},"decision_ms":1790001810079,"feature_cutoff_ms":1790001810078,"request_ms":1790001810015,"inventory":{"pair_fast":{"qty":[0.0,0.0],"cash":0.0,"lots":[[],[]],"floor":0.0},"pair_250":{"qty":[0.0,0.0],"cash":0.0,"lots":[[],[]],"floor":0.0},"pair_add_fast":{"qty":[0.0,0.0],"cash":0.0,"lots":[[],[]],"floor":0.0},"pair_add_250":{"qty":[0.0,0.0],"cash":0.0,"lots":[[],[]],"floor":0.0}}}
{"kind":"decision","recorded_ms":1790001820039,"S":1790001600,"age":220,"signal":{"rsi14":54.343954271220625,"volume_ratio":0.6983906940636092,"taker_buy_fraction":0.3198425857111571,"volume5":185.65786,"return1":-4.853595063108242,"return5":-20.60884242282211,"return15":6.524676772708963,"bollinger_z":0.0619724598869915,"bar_close_ms":1790001779999,"ref":85799.28883377438,"reference_received_ms":1790001601703,"spot":85774.97086572516,"twap":85789.71532600635,"sigma":9.393128978653623,"spot_z":-0.2895177360216181,"twap_z":-0.11397746263896309,"momentum":-0.21269828361489412,"decision_ms":1790001820038,"momentum30":-0.466956940003396,"momentum60":-0.47664829153590665,"spot_twap_gap":-0.2026483019223714,"range60":0.7786263557958323,"final_mean":85774.97086572516,"final_z":-0.4095372319824752,"final_up_prob":0.34107272469238126,"final_drift_up_prob":0.17331876787298722,"final_known_seconds":0,"final_sd":59.37913857428768,"final_drift_shift":-31.565602644233085},"entry_side":null,"context_gap":null,"book_errors":[null,null],"books":[{"bid":0.21,"ask":0.22,"asks":[[0.22,812.0]],"received_ms":1790001820037,"observed_ms":1790001820029,"hash":"58c788af30c294fbe35437e9b4f101a35b1625a2"},{"bid":0.78,"ask":0.79,"asks":[[0.79,507.22]],"received_ms":1790001820038,"observed_ms":1790001820027,"hash":"d7aa83f720b5ed4478acd9cf287e12dfcadac804"}],"intents":{"pair_fast":null,"pair_250":null,"pair_add_fast":null,"pair_add_250":null},"decision_ms":1790001820039,"feature_cutoff_ms":1790001820038,"request_ms":1790001820004,"inventory":{"pair_fast":{"qty":[0.0,0.0],"cash":0.0,"lots":[[],[]],"floor":0.0},"pair_250":{"qty":[0.0,0.0],"cash":0.0,"lots":[[],[]],"floor":0.0},"pair_add_fast":{"qty":[0.0,0.0],"cash":0.0,"lots":[[],[]],"floor":0.0},"pair_add_250":{"qty":[0.0,0.0],"cash":0.0,"lots":[[],[]],"floor":0.0}}}
{"kind":"decision","recorded_ms":1790001830043,"S":1790001600,"age":230,"signal":{"rsi14":54.343954271220625,"volume_ratio":0.6983906940636092,"taker_buy_fraction":0.3198425857111571,"volume5":185.65786,"return1":-4.853595063108242,"return5":-20.60884242282211,"return15":6.524676772708963,"bollinger_z":0.0619724598869915,"bar_close_ms":1790001779999,"ref":85799.28883377438,"reference_received_ms":1790001601703,"spot":85723.31239037454,"twap":85782.92797747988,"sigma":9.847394507335734,"spot_z":-0.9224417056330426,"twap_z":-0.1986396771232558,"momentum":-1.1327408326836395,"decision_ms":1790001830042,"momentum30":-0.5504055481213402,"momentum60":-0.8940368485274692,"spot_twap_gap":-0.781560969795403,"range60":1.062004581200417,"final_mean":85723.31239037454,"final_z":-1.4096172791992667,"final_up_prob":0.07932636102714269,"final_drift_up_prob":2.852950062404158e-05,"final_known_seconds":0,"final_sd":53.898632289037835,"final_drift_shift":-140.9469346197632},"entry_side":null,"context_gap":null,"book_errors":[null,null],"books":[{"bid":0.1,"ask":0.11,"asks":[[0.11,833.85]],"received_ms":1790001830042,"observed_ms":1790001830030,"hash":"7f4173207c730df3d38059a8597014ecac29ca55"},{"bid":0.89,"ask":0.9,"asks":[[0.9,601.44]],"received_ms":1790001830041,"observed_ms":1790001830030,"hash":"5886833306111903a0ac9f2cb9a605be2662067e"}],"intents":{"pair_fast":null,"pair_250":null,"pair_add_fast":null,"pair_add_250":null},"decision_ms":1790001830043,"feature_cutoff_ms":1790001830042,"request_ms":1790001830013,"inventory":{"pair_fast":{"qty":[0.0,0.0],"cash":0.0,"lots":[[],[]],"floor":0.0},"pair_250":{"qty":[0.0,0.0],"cash":0.0,"lots":[[],[]],"floor":0.0},"pair_add_fast":{"qty":[0.0,0.0],"cash":0.0,"lots":[[],[]],"floor":0.0},"pair_add_250":{"qty":[0.0,0.0],"cash":0.0,"lots":[[],[]],"floor":0.0}}}
{"kind":"decision","recorded_ms":1790001840051,"S":1790001600,"age":240,"signal":{"rsi14":54.343954271220625,"volume_ratio":0.6983906940636092,"taker_buy_fraction":0.3198425857111571,"volume5":185.65786,"return1":-4.853595063108242,"return5":-20.60884242282211,"return15":6.524676772708963,"bollinger_z":0.0619724598869915,"bar_close_ms":1790001779999,"ref":85799.28883377438,"reference_received_ms":1790001601703,"spot":85733.34560369635,"twap":85773.57369252834,"sigma":9.67233551688433,"spot_z":-0.8805302274220853,"twap_z":-0.3433704891733432,"momentum":-0.04007724085925492,"decision_ms":1790001840050,"momentum30":-0.9049714833521757,"momentum60":-0.7524427498574652,"spot_twap_gap":-0.5369358752567874,"range60":0.9770988229477101,"final_mean":85733.34560369635,"final_z":-1.5263950861873163,"final_up_prob":0.06345575033404621,"final_drift_up_prob":0.05354886246115809,"final_known_seconds":0,"final_sd":43.20194075227739,"final_drift_shift":-3.6713542963006662},"entry_side":null,"context_gap":null,"book_errors":[null,null],"books":[{"bid":0.04,"ask":0.05,"asks":[[0.05,794.87]],"received_ms":1790001840049,"observed_ms":1790001839992,"hash":"b8df21c670eb7dfc704de0745454a80027cc732f"},{"bid":0.95,"ask":0.96,"asks":[[0.96,351.31]],"received_ms":1790001840043,"observed_ms":1790001839992,"hash":"3f2846c653a93c9fb11b4db549766c80b584f9e2"}],"intents":{"pair_fast":null,"pair_250":null,"pair_add_fast":null,"pair_add_250":null},"decision_ms":1790001840051,"feature_cutoff_ms":1790001840050,"request_ms":1790001840016,"inventory":{"pair_fast":{"qty":[0.0,0.0],"cash":0.0,"lots":[[],[]],"floor":0.0},"pair_250":{"qty":[0.0,0.0],"cash":0.0,"lots":[[],[]],"floor":0.0},"pair_add_fast":{"qty":[0.0,0.0],"cash":0.0,"lots":[[],[]],"floor":0.0},"pair_add_250":{"qty":[0.0,0.0],"cash":0.0,"lots":[[],[]],"floor":0.0}}}
{"kind":"decision","recorded_ms":1790001850026,"S":1790001600,"age":250,"signal":{"rsi14":51.51776428653937,"volume_ratio":0.5777934804232001,"taker_buy_fraction":0.3309433950952541,"volume5":180.14552,"return1":-6.507933416879332,"return5":-16.651727144426204,"return15":4.35650228372381,"bollinger_z":-0.4334888004404065,"bar_close_ms":1790001839999,"ref":85799.28883377438,"reference_received_ms":1790001601703,"spot":85726.55654546378,"twap":85763.29507939529,"sigma":9.617253123776594,"spot_z":-1.0697931282402138,"twap_z":-0.5294192165366606,"momentum":-0.24407808525626443,"decision_ms":1790001850025,"momentum30":-0.6080510725977554,"momentum60":-0.9723945241274335,"spot_twap_gap":-0.4931682960804061,"range60":1.0438697338384522,"final_mean":85727.51574577414,"final_z":-2.1952968791857823,"final_up_prob":0.014071154316533274,"final_drift_up_prob":0.003817099704986282,"final_known_seconds":10,"final_sd":32.69402361053536,"final_drift_shift":-15.449135856622222},"entry_side":null,"context_gap":null,"book_errors":[null,null],"books":[{"bid":0.02,"ask":0.03,"asks":[[0.03,929.16]],"received_ms":1790001850025,"observed_ms":1790001850017,"hash":"47fc25ce1f335b6c842578442805fb57d831797f"},{"bid":0.97,"ask":0.98,"asks":[[0.98,541.21]],"received_ms":1790001850024,"observed_ms":1790001850017,"hash":"80233c37c2dfb1a5e47f8722658380c4c261e49a"}],"intents":{"pair_fast":null,"pair_250":null,"pair_add_fast":null,"pair_add_250":null},"decision_ms":1790001850026,"feature_cutoff_ms":1790001850025,"request_ms":1790001850000,"inventory":{"pair_fast":{"qty":[0.0,0.0],"cash":0.0,"lots":[[],[]],"floor":0.0},"pair_250":{"qty":[0.0,0.0],"cash":0.0,"lots":[[],[]],"floor":0.0},"pair_add_fast":{"qty":[0.0,0.0],"cash":0.0,"lots":[[],[]],"floor":0.0},"pair_add_250":{"qty":[0.0,0.0],"cash":0.0,"lots":[[],[]],"floor":0.0}}}
{"kind":"decision","recorded_ms":1790001860079,"S":1790001600,"age":260,"signal":{"rsi14":51.51776428653937,"volume_ratio":0.5777934804232001,"taker_buy_fraction":0.3309433950952541,"volume5":180.14552,"return1":-6.507933416879332,"return5":-16.651727144426204,"return15":4.35650228372381,"bollinger_z":-0.4334888004404065,"bar_close_ms":1790001839999,"ref":85799.28883377438,"reference_received_ms":1790001601703,"spot":85715.27716192655,"twap":85751.97372830348,"sigma":8.778157771059298,"spot_z":-1.5147121196282902,"twap_z":-0.8530810317414447,"momentum":-0.49212361622171746,"decision_ms":1790001860078,"momentum30":-0.40129552190522105,"momentum60":-0.5547753006429176,"spot_twap_gap":-0.5396925495741562,"range60":1.3183815731275474,"final_mean":85718.77539456908,"final_z":-3.778839440345386,"final_up_prob":7.878048514903258e-05,"final_drift_up_prob":1.8248787762020768e-06,"final_known_seconds":20,"final_sd":21.30639326606097,"final_drift_shift":-18.14349385324328},"entry_side":null,"context_gap":null,"book_errors":[null,null],"books":[{"bid":null,"ask":0.01,"asks":[[0.01,11735.48]],"received_ms":1790001860078,"observed_ms":1790001860065,"hash":"6d154215dd8568104be19008b830ad1808ad0faa"},{"bid":0.99,"ask":null,"asks":[],"received_ms":1790001860076,"observed_ms":1790001860065,"hash":"b6ceca2af557dcfe55ec7bc0c0cc5bce28d453d6"}],"intents":{"pair_fast":null,"pair_250":null,"pair_add_fast":null,"pair_add_250":null},"decision_ms":1790001860079,"feature_cutoff_ms":1790001860078,"request_ms":1790001860050,"inventory":{"pair_fast":{"qty":[0.0,0.0],"cash":0.0,"lots":[[],[]],"floor":0.0},"pair_250":{"qty":[0.0,0.0],"cash":0.0,"lots":[[],[]],"floor":0.0},"pair_add_fast":{"qty":[0.0,0.0],"cash":0.0,"lots":[[],[]],"floor":0.0},"pair_add_250":{"qty":[0.0,0.0],"cash":0.0,"lots":[[],[]],"floor":0.0}}}
{"kind":"decision","recorded_ms":1790001870039,"S":1790001600,"age":270,"signal":{"rsi14":51.51776428653937,"volume_ratio":0.5777934804232001,"taker_buy_fraction":0.3309433950952541,"volume5":180.14552,"return1":-6.507933416879332,"return5":-16.651727144426204,"return15":4.35650228372381,"bollinger_z":-0.4334888004404065,"bar_close_ms":1790001839999,"ref":85799.28883377438,"reference_received_ms":1790001601703,"spot":85768.20088858486,"twap":85742.7328117671,"sigma":7.125145583812021,"spot_z":-0.7971001228169308,"twap_z":-1.450105879086624,"momentum":1.9756320954134732,"decision_ms":1790001870038,"momentum30":0.8768849167148552,"momentum60":-0.23713768578709643,"spot_twap_gap":0.4614522665531255,"range60":1.2069513535320504,"final_mean":85748.62539950898,"final_z":-4.5056407767976205,"final_up_prob":3.308647553990074e-06,"final_drift_up_prob":0.06128567760814563,"final_known_seconds":30,"final_sd":11.244445967884879,"final_drift_shift":33.30122163343956},"entry_side":null,"context_gap":null,"book_errors":[null,null],"books":[{"bid":null,"ask":0.01,"asks":[[0.01,22078.67]],"received_ms":1790001870031,"observed_ms":1790001869998,"hash":"54447a1e0f0af4c3ae52d9d3c2e7b8d7d38d5179"},{"bid":0.99,"ask":null,"asks":[],"received_ms":1790001870038,"observed_ms":1790001870029,"hash":"4e1a55fce44caf4ad0bb691c5c7a26d0c6fb219a"}],"intents":{"pair_fast":null,"pair_250":null,"pair_add_fast":null,"pair_add_250":null},"decision_ms":1790001870039,"feature_cutoff_ms":1790001870038,"request_ms":1790001870004,"inventory":{"pair_fast":{"qty":[0.0,0.0],"cash":0.0,"lots":[[],[]],"floor":0.0},"pair_250":{"qty":[0.0,0.0],"cash":0.0,"lots":[[],[]],"floor":0.0},"pair_add_fast":{"qty":[0.0,0.0],"cash":0.0,"lots":[[],[]],"floor":0.0},"pair_add_250":{"qty":[0.0,0.0],"cash":0.0,"lots":[[],[]],"floor":0.0}}}
{"kind":"decision","recorded_ms":1790001880053,"S":1790001600,"age":280,"signal":{"rsi14":51.51776428653937,"volume_ratio":0.5777934804232001,"taker_buy_fraction":0.3309433950952541,"volume5":180.14552,"return1":-6.507933416879332,"return5":-16.651727144426204,"return15":4.35650228372381,"bollinger_z":-0.4334888004404065,"bar_close_ms":1790001839999,"ref":85799.28883377438,"reference_received_ms":1790001601703,"spot":85771.08727226408,"twap":85738.79181139833,"sigma":6.99686948274194,"spot_z":-0.9024202227064756,"twap_z":-1.9358409067430367,"momentum":-0.06746189058031449,"decision_ms":1790001880051,"momentum30":1.099830099346463,"momentum60":0.23065836214647975,"spot_twap_gap":0.5958844994876648,"range60":1.0869621354154706,"final_mean":85750.36739563727,"final_z":-8.155031234303934,"final_up_prob":1.6653345369377348e-16,"final_drift_up_prob":1.1102230246251565e-16,"final_known_seconds":40,"final_sd":5.998927132409524,"final_drift_shift":-0.4950206204205004},"entry_side":null,"context_gap":null,"book_errors":[null,null],"books":[{"bid":null,"ask":0.01,"asks":[[0.01,35417.02]],"received_ms":1790001880051,"observed_ms":1790001880040,"hash":"6ee1978e2f45efc563635977bff491fec0f90299"},{"bid":0.99,"ask":null,"asks":[],"received_ms":1790001880047,"observed_ms":1790001880005,"hash":"f18e11e1c5521d6e28244a5e34b4ec7fe34fce28"}],"intents":{"pair_fast":null,"pair_250":null,"pair_add_fast":null,"pair_add_250":null},"decision_ms":1790001880053,"feature_cutoff_ms":1790001880051,"request_ms":1790001880014,"inventory":{"pair_fast":{"qty":[0.0,0.0],"cash":0.0,"lots":[[],[]],"floor":0.0},"pair_250":{"qty":[0.0,0.0],"cash":0.0,"lots":[[],[]],"floor":0.0},"pair_add_fast":{"qty":[0.0,0.0],"cash":0.0,"lots":[[],[]],"floor":0.0},"pair_add_250":{"qty":[0.0,0.0],"cash":0.0,"lots":[[],[]],"floor":0.0}}}
{"kind":"decision","recorded_ms":1790001890059,"S":1790001600,"age":290,"signal":{"rsi14":51.51776428653937,"volume_ratio":0.5777934804232001,"taker_buy_fraction":0.3309433950952541,"volume5":180.14552,"return1":-6.507933416879332,"return5":-16.651727144426204,"return15":4.35650228372381,"bollinger_z":-0.4334888004404065,"bar_close_ms":1790001839999,"ref":85799.28883377438,"reference_received_ms":1790001601703,"spot":85753.51545517087,"twap":85741.0032805701,"sigma":6.31277625481068,"spot_z":-2.2996179782408834,"twap_z":-2.928219635724839,"momentum":-0.8798313349132378,"decision_ms":1790001890058,"momentum30":0.8626927057931236,"momentum60":0.38741481562901103,"spot_twap_gap":0.2558802545693017,"range60":1.2047523763239414,"final_mean":85746.15025503063,"final_z":-27.905562618721646,"final_up_prob":0.0,"final_drift_up_prob":0.0,"final_known_seconds":50,"final_sd":1.9042288976498298,"final_drift_shift":-1.4467253316399873},"entry_side":null,"context_gap":null,"book_errors":[null,null],"books":[{"bid":null,"ask":0.01,"asks":[[0.01,57003.78]],"received_ms":1790001890058,"observed_ms":1790001890047,"hash":"a6bc8264d74f9307ef913b8624c662fe0a700ad4"},{"bid":0.99,"ask":null,"asks":[],"received_ms":1790001890054,"observed_ms":1790001890043,"hash":"7a5dee8aa412ef34fbfdbee5b92760c3770078b7"}],"intents":{"pair_fast":null,"pair_250":null,"pair_add_fast":null,"pair_add_250":null},"decision_ms":1790001890059,"feature_cutoff_ms":1790001890058,"request_ms":1790001890026,"inventory":{"pair_fast":{"qty":[0.0,0.0],"cash":0.0,"lots":[[],[]],"floor":0.0},"pair_250":{"qty":[0.0,0.0],"cash":0.0,"lots":[[],[]],"floor":0.0},"pair_add_fast":{"qty":[0.0,0.0],"cash":0.0,"lots":[[],[]],"floor":0.0},"pair_add_250":{"qty":[0.0,0.0],"cash":0.0,"lots":[[],[]],"floor":0.0}}}
{"kind":"decision","recorded_ms":1790001930072,"S":1790001900,"age":30,"signal":{"rsi14":57.7824248338675,"volume_ratio":0.5049609059600261,"taker_buy_fraction":0.3666027124670487,"volume5":162.17856,"return1":4.910313640019657,"return5":-3.1177519551509927,"return15":8.890546509865946,"bollinger_z":-0.10576275781640997,"bar_close_ms":1790001899999,"ref":85745.48246540247,"reference_received_ms":1790001901161,"spot":85720.28358565268,"twap":85757.18810214988,"sigma":5.204228887798491,"spot_z":-0.29471352854835564,"twap_z":0.13690328871720617,"momentum":-0.3151025607525388,"decision_ms":1790001930071,"momentum30":-1.8025661095962282,"momentum60":-1.2972968862286836,"spot_twap_gap":-0.9154771428841744,"range60":1.3222642545274348,"final_mean":85720.28358565268,"final_z":-0.3193213596784673,"final_up_prob":0.3747414185872577,"final_drift_up_prob":0.028981314357082177,"final_known_seconds":0,"final_sd":78.91385585719675,"final_drift_shift":-124.42024878047532},"entry_side":null,"context_gap":null,"book_errors":[null,null],"books":[{"bid":0.54,"ask":0.55,"asks":[[0.55,131.9]],"received_ms":1790001930064,"observed_ms":1790001930055,"hash":"d6d19578bae641cc4c2508691903fdc37f31bf7b"},{"bid":0.45,"ask":0.46,"asks":[[0.46,853.61]],"received_ms":1790001930071,"observed_ms":1790001930050,"hash":"11623f5ac35f95c9d063bdde975bb86c0de6ad48"}],"intents":{"pair_fast":null,"pair_250":null,"pair_add_fast":null,"pair_add_250":null},"decision_ms":1790001930072,"feature_cutoff_ms":1790001930071,"request_ms":1790001930022,"inventory":{"pair_fast":{"qty":[0.0,0.0],"cash":0.0,"lots":[[],[]],"floor":0.0},"pair_250":{"qty":[0.0,0.0],"cash":0.0,"lots":[[],[]],"floor":0.0},"pair_add_fast":{"qty":[0.0,0.0],"cash":0.0,"lots":[[],[]],"floor":0.0},"pair_add_250":{"qty":[0.0,0.0],"cash":0.0,"lots":[[],[]],"floor":0.0}}}
{"kind":"decision","recorded_ms":1790001940081,"S":1790001900,"age":40,"signal":{"rsi14":57.7824248338675,"volume_ratio":0.5049609059600261,"taker_buy_fraction":0.3666027124670487,"volume5":162.17856,"return1":4.910313640019657,"return5":-3.1177519551509927,"return15":8.890546509865946,"bollinger_z":-0.10576275781640997,"bar_close_ms":1790001899999,"ref":85745.48246540247,"reference_received_ms":1790001901161,"spot":85711.57371827192,"twap":85751.62355739532,"sigma":7.402492957057373,"spot_z":-0.28412790660500087,"twap_z":0.05145738960740837,"momentum":-1.625685827929573,"decision_ms":1790001940080,"momentum30":-1.1861004068521745,"momentum60":-1.0377772482000756,"spot_twap_gap":-0.6984690195723506,"range60":1.0479961547652272,"final_mean":85711.57371827192,"final_z":-0.3088882422365925,"final_up_prob":0.3787032705450726,"final_drift_up_prob":5.551115123125783e-17,"final_known_seconds":0,"final_sd":109.77674930268618,"final_drift_shift":-874.9663954606389},"entry_side":null,"context_gap":null,"book_errors":[null,null],"books":[{"bid":0.39,"ask":0.4,"asks":[[0.4,135.5]],"received_ms":1790001940076,"observed_ms":1790001940067,"hash":"5f95553fbeb425f049a453763c05ea1b0682b550"},{"bid":0.6,"ask":0.61,"asks":[[0.61,1291.35]],"received_ms":1790001940079,"observed_ms":1790001940067,"hash":"854d09158a6c8411ae23bca1b35910eb92be127e"}],"intents":{"pair_fast":null,"pair_250":null,"pair_add_fast":null,"pair_add_250":null},"decision_ms":1790001940081,"feature_cutoff_ms":1790001940080,"request_ms":1790001940046,"inventory":{"pair_fast":{"qty":[0.0,0.0],"cash":0.0,"lots":[[],[]],"floor":0.0},"pair_250":{"qty":[0.0,0.0],"cash":0.0,"lots":[[],[]],"floor":0.0},"pair_add_fast":{"qty":[0.0,0.0],"cash":0.0,"lots":[[],[]],"floor":0.0},"pair_add_250":{"qty":[0.0,0.0],"cash":0.0,"lots":[[],[]],"floor":0.0}}}
{"kind":"decision","recorded_ms":1790001950033,"S":1790001900,"age":50,"signal":{"rsi14":57.7824248338675,"volume_ratio":0.5049609059600261,"taker_buy_fraction":0.3666027124670487,"volume5":162.17856,"return1":4.910313640019657,"return5":-3.1177519551509927,"return15":8.890546509865946,"bollinger_z":-0.10576275781640997,"bar_close_ms":1790001899999,"ref":85745.48246540247,"reference_received_ms":1790001901161,"spot":85703.76248950434,"twap":85741.30227424073,"sigma":7.282542126330696,"spot_z":-0.3623414073820577,"twap_z":-0.03630530258138595,"momentum":-0.3447432594305979,"decision_ms":1790001950031,"momentum30":-0.544192206396966,"momentum60":-0.8810752955706286,"spot_twap_gap":-0.6654771487856637,"range60":1.2037293159832678,"final_mean":85703.76248950434,"final_z":-0.39535155682525186,"final_up_prob":0.34629172754105286,"final_drift_up_prob":0.020168473230404993,"final_known_seconds":0,"final_sd":105.5262719417345,"final_drift_shift":-174.63861143161213},"entry_side":null,"context_gap":null,"book_errors":[null,null],"books":[{"bid":0.36,"ask":0.37,"asks":[[0.37,264.64]],"received_ms":1790001950030,"observed_ms":1790001950022,"hash":"355d6123835c89d7079188250bc055d6cf822e3b"},{"bid":0.63,"ask":0.64,"asks":[[0.64,1711.78]],"received_ms":1790001950031,"observed_ms":1790001950024,"hash":"f5775dd35277dd64e0201761070900fc9a7ca2b4"}],"intents":{"pair_fast":null,"pair_250":null,"pair_add_fast":null,"pair_add_250":null},"decision_ms":1790001950033,"feature_cutoff_ms":1790001950031,"request_ms":1790001950003,"inventory":{"pair_fast":{"qty":[0.0,0.0],"cash":0.0,"lots":[[],[]],"floor":0.0},"pair_250":{"qty":[0.0,0.0],"cash":0.0,"lots":[[],[]],"floor":0.0},"pair_add_fast":{"qty":[0.0,0.0],"cash":0.0,"lots":[[],[]],"floor":0.0},"pair_add_250":{"qty":[0.0,0.0],"cash":0.0,"lots":[[],[]],"floor":0.0}}}
{"kind":"decision","recorded_ms":1790001960286,"S":1790001900,"age":60,"signal":{"rsi14":57.7824248338675,"volume_ratio":0.5049609059600261,"taker_buy_fraction":0.3666027124670487,"volume5":162.17856,"return1":4.910313640019657,"return5":-3.1177519551509927,"return15":8.890546509865946,"bollinger_z":-0.10576275781640997,"bar_close_ms":1790001899999,"ref":85745.48246540247,"reference_received_ms":1790001901161,"spot":85692.77769845013,"twap":85731.40699259104,"sigma":7.692845423472614,"spot_z":-0.44250204908334373,"twap_z":-0.11817575375116612,"momentum":-0.45047387458752797,"decision_ms":1790001960285,"momentum30":-1.3492504297475583,"momentum60":-1.323871639019833,"spot_twap_gap":-0.6482673386669647,"range60":1.5240224135677478,"final_mean":85692.77769845013,"final_z":-0.4847943492683431,"final_up_prob":0.31391111574003805,"final_drift_up_prob":0.004678334348914515,"final_known_seconds":0,"final_sd":108.71572045319421,"final_drift_shift":-229.8190947074683},"entry_side":null,"context_gap":null,"book_errors":[null,null],"books":[{"bid":0.34,"ask":0.35,"asks":[[0.35,234.41]],"received_ms":1790001960058,"observed_ms":1790001960040,"hash":"a78840c1b207a22c0a42ad3883a5217d732220f7"},{"bid":0.65,"ask":0.66,"asks":[[0.66,287.28]],"received_ms":1790001960285,"observed_ms":1790001960271,"hash":"08398b5253a9fcde310644f7c8690f9bd91dc734"}],"intents":{"pair_fast":null,"pair_250":null,"pair_add_fast":null,"pair_add_250":null},"decision_ms":1790001960286,"feature_cutoff_ms":1790001960285,"request_ms":1790001960006,"inventory":{"pair_fast":{"qty":[0.0,0.0],"cash":0.0,"lots":[[],[]],"floor":0.0},"pair_250":{"qty":[0.0,0.0],"cash":0.0,"lots":[[],[]],"floor":0.0},"pair_add_fast":{"qty":[0.0,0.0],"cash":0.0,"lots":[[],[]],"floor":0.0},"pair_add_250":{"qty":[0.0,0.0],"cash":0.0,"lots":[[],[]],"floor":0.0}}}
{"kind":"decision","recorded_ms":1790001970079,"S":1790001900,"age":70,"signal":{"rsi14":50.585373128763315,"volume_ratio":0.9459635812995992,"taker_buy_fraction":0.3854861918215244,"volume5":151.35559,"return1":-8.852921925021084,"return5":6.197861930114837,"return15":10.683233494445284,"bollinger_z":-0.7994582049247781,"bar_close_ms":1790001959999,"ref":85745.48246540247,"reference_received_ms":1790001901161,"spot":85716.85392129715,"twap":85720.51316466015,"sigma":7.8052399664209196,"spot_z":-0.24189268700618904,"twap_z":-0.21097444658749295,"momentum":0.875270748434737,"decision_ms":1790001970078,"momentum30":0.12051617874961759,"momentum60":-0.7080880189337371,"spot_twap_gap":-0.06052424894723363,"range60":1.3035797647590095,"final_mean":85716.85392129715,"final_z":-0.2661493228631334,"final_up_prob":0.39506210511599643,"final_drift_up_prob":0.9999112741553096,"final_known_seconds":0,"final_sd":107.56572211923634,"final_drift_shift":431.9060244763127},"entry_side":null,"context_gap":null,"book_errors":[null,null],"books":[{"bid":0.45,"ask":0.46,"asks":[[0.46,403.15]],"received_ms":1790001970067,"observed_ms":1790001970058,"hash":"b787ecad445506a3af1fb996490d9e3bcaeabce9"},{"bid":0.54,"ask":0.55,"asks":[[0.55,625.8]],"received_ms":1790001970078,"observed_ms":1790001970069,"hash":"04b3dea3dd107043d8149c21c55c56b6e854333a"}],"intents":{"pair_fast":null,"pair_250":null,"pair_add_fast":null,"pair_add_250":null},"decision_ms":1790001970079,"feature_cutoff_ms":1790001970078,"request_ms":1790001970035,"inventory":{"pair_fast":{"qty":[0.0,0.0],"cash":0.0,"lots":[[],[]],"floor":0.0},"pair_250":{"qty":[0.0,0.0],"cash":0.0,"lots":[[],[]],"floor":0.0},"pair_add_fast":{"qty":[0.0,0.0],"cash":0.0,"lots":[[],[]],"floor":0.0},"pair_add_250":{"qty":[0.0,0.0],"cash":0.0,"lots":[[],[]],"floor":0.0}}}
{"kind":"decision","recorded_ms":1790001980050,"S":1790001900,"age":80,"signal":{},"entry_side":null,"context_gap":"incomplete or stale context","book_errors":[null,null],"books":[{"bid":0.45,"ask":0.46,"asks":[[0.46,822.0]],"received_ms":1790001980049,"observed_ms":1790001980026,"hash":"e6ee453beec1d650524c1d27a2f8cd53a0d651bb"},{"bid":0.54,"ask":0.55,"asks":[[0.55,111.69]],"received_ms":1790001980031,"observed_ms":1790001980023,"hash":"94f6bca0a4265b3de69e3e6d9a89fab412157126"}],"intents":{"pair_fast":null,"pair_250":null,"pair_add_fast":null,"pair_add_250":null},"decision_ms":1790001980050,"feature_cutoff_ms":1790001980049,"request_ms":1790001980003,"inventory":{"pair_fast":{"qty":[0.0,0.0],"cash":0.0,"lots":[[],[]],"floor":0.0},"pair_250":{"qty":[0.0,0.0],"cash":0.0,"lots":[[],[]],"floor":0.0},"pair_add_fast":{"qty":[0.0,0.0],"cash":0.0,"lots":[[],[]],"floor":0.0},"pair_add_250":{"qty":[0.0,0.0],"cash":0.0,"lots":[[],[]],"floor":0.0}}}
{"kind":"decision","recorded_ms":1790001990062,"S":1790001900,"age":90,"signal":{"rsi14":50.585373128763315,"volume_ratio":0.9459635812995992,"taker_buy_fraction":0.3854861918215244,"volume5":151.35559,"return1":-8.852921925021084,"return5":6.197861930114837,"return15":10.683233494445284,"bollinger_z":-0.7994582049247781,"bar_close_ms":1790001959999,"ref":85745.48246540247,"reference_received_ms":1790001901161,"spot":85749.03772879,"twap":85715.20300424188,"sigma":7.060365313313834,"spot_z":0.03475345976525631,"twap_z":-0.29598820690700034,"momentum":0.5597094123730516,"decision_ms":1790001990061,"momentum30":1.3908933638338488,"momentum60":-0.010810938949163136,"spot_twap_gap":0.6186711257527786,"range60":1.2576115313823852,"final_mean":85749.03772879,"final_z":0.0386276314212017,"final_up_prob":0.5154063639801304,"final_drift_up_prob":0.9934626558863644,"final_known_seconds":0,"final_sd":92.03938364138675,"final_drift_shift":224.86149060106925},"entry_side":null,"context_gap":null,"book_errors":[null,null],"books":[{"bid":0.47,"ask":0.48,"asks":[[0.48,127.39]],"received_ms":1790001990060,"observed_ms":1790001990045,"hash":"a080fb63e47392c8b97da536e94804218ac3680a"},{"bid":0.52,"ask":0.53,"asks":[[0.53,374.0]],"received_ms":1790001990061,"observed_ms":1790001990050,"hash":"1adc637f1f3b35d9d922dae8d85bc2c5519b9704"}],"intents":{"pair_fast":null,"pair_250":null,"pair_add_fast":null,"pair_add_250":null},"decision_ms":1790001990062,"feature_cutoff_ms":1790001990061,"request_ms":1790001990024,"inventory":{"pair_fast":{"qty":[0.0,0.0],"cash":0.0,"lots":[[],[]],"floor":0.0},"pair_250":{"qty":[0.0,0.0],"cash":0.0,"lots":[[],[]],"floor":0.0},"pair_add_fast":{"qty":[0.0,0.0],"cash":0.0,"lots":[[],[]],"floor":0.0},"pair_add_250":{"qty":[0.0,0.0],"cash":0.0,"lots":[[],[]],"floor":0.0}}}
{"kind":"decision","recorded_ms":1790002000078,"S":1790001900,"age":100,"signal":{"rsi14":50.585373128763315,"volume_ratio":0.9459635812995992,"taker_buy_fraction":0.3854861918215244,"volume5":151.35559,"return1":-8.852921925021084,"return5":6.197861930114837,"return15":10.683233494445284,"bollinger_z":-0.7994582049247781,"bar_close_ms":1790001959999,"ref":85745.48246540247,"reference_received_ms":1790001901161,"spot":85734.46571260956,"twap":85717.39326077764,"sigma":6.087253447646872,"spot_z":-0.12799730919289634,"twap_z":-0.3263522997138961,"momentum":-0.7801277441545615,"decision_ms":1790002000077,"momentum30":0.10482642485766532,"momentum60":0.4827822501279494,"spot_twap_gap":0.3620752894696086,"range60":1.4555550257694694,"final_mean":85734.46571260956,"final_z":-0.14311223223213912,"final_up_prob":0.4431007722308551,"final_drift_up_prob":0.00027215005530956127,"final_known_seconds":0,"final_sd":76.9798124247352,"final_drift_shift":-255.17567648899333},"entry_side":null,"context_gap":null,"book_errors":[null,null],"books":[{"bid":0.42,"ask":0.43,"asks":[[0.43,945.2]],"received_ms":1790002000062,"observed_ms":1790002000053,"hash":"805bdb3282275ab098562723dd5a64e26b71a438"},{"bid":0.57,"ask":0.58,"asks":[[0.58,620.27]],"received_ms":1790002000076,"observed_ms":1790002000063,"hash":"36ef8fba0a2a445023b5611f63cc06ecda14f197"}],"intents":{"pair_fast":null,"pair_250":null,"pair_add_fast":null,"pair_add_250":null},"decision_ms":1790002000078,"feature_cutoff_ms":1790002000077,"request_ms":1790002000037,"inventory":{"pair_fast":{"qty":[0.0,0.0],"cash":0.0,"lots":[[],[]],"floor":0.0},"pair_250":{"qty":[0.0,0.0],"cash":0.0,"lots":[[],[]],"floor":0.0},"pair_add_fast":{"qty":[0.0,0.0],"cash":0.0,"lots":[[],[]],"floor":0.0},"pair_add_250":{"qty":[0.0,0.0],"cash":0.0,"lots":[[],[]],"floor":0.0}}}
{"kind":"decision","recorded_ms":1790002010080,"S":1790001900,"age":110,"signal":{"rsi14":50.585373128763315,"volume_ratio":0.9459635812995992,"taker_buy_fraction":0.3854861918215244,"volume5":151.35559,"return1":-8.852921925021084,"return5":6.197861930114837,"return15":10.683233494445284,"bollinger_z":-0.7994582049247781,"bar_close_ms":1790001959999,"ref":85745.48246540247,"reference_received_ms":1790001901161,"spot":85734.83478102463,"twap":85720.78696271885,"sigma":5.925199173363848,"spot_z":-0.13039643600254358,"twap_z":-0.3024324746081478,"momentum":0.037784709039178944,"decision_ms":1790002010079,"momentum30":-0.052579837925179694,"momentum60":0.6775792176467631,"spot_twap_gap":0.3060767228069854,"range60":1.4953644746130543,"final_mean":85734.83478102463,"final_z":-0.14676448683374616,"final_up_prob":0.44165895824298035,"final_drift_up_prob":0.503708139384707,"final_known_seconds":0,"final_sd":72.54946075543492,"final_drift_shift":11.32203603180471},"entry_side":null,"context_gap":null,"book_errors":[null,null],"books":[{"bid":0.49,"ask":0.5,"asks":[[0.5,123.0]],"received_ms":1790002010079,"observed_ms":1790002010072,"hash":"27a85e5f7e3f97f5125e614c8ff9a672845147a2"},{"bid":0.5,"ask":0.51,"asks":[[0.51,110.23]],"received_ms":1790002010073,"observed_ms":1790002010062,"hash":"a35055dca01bb451274265c2bebcb73043b99d15"}],"intents":{"pair_fast":null,"pair_250":null,"pair_add_fast":null,"pair_add_250":null},"decision_ms":1790002010080,"feature_cutoff_ms":1790002010079,"request_ms":1790002010049,"inventory":{"pair_fast":{"qty":[0.0,0.0],"cash":0.0,"lots":[[],[]],"floor":0.0},"pair_250":{"qty":[0.0,0.0],"cash":0.0,"lots":[[],[]],"floor":0.0},"pair_add_fast":{"qty":[0.0,0.0],"cash":0.0,"lots":[[],[]],"floor":0.0},"pair_add_250":{"qty":[0.0,0.0],"cash":0.0,"lots":[[],[]],"floor":0.0}}}
{"kind":"decision","recorded_ms":1790002020045,"S":1790001900,"age":120,"signal":{"rsi14":50.585373128763315,"volume_ratio":0.9459635812995992,"taker_buy_fraction":0.3854861918215244,"volume5":151.35559,"return1":-8.852921925021084,"return5":6.197861930114837,"return15":10.683233494445284,"bollinger_z":-0.7994582049247781,"bar_close_ms":1790001959999,"ref":85745.48246540247,"reference_received_ms":1790001901161,"spot":85740.67787047249,"twap":85727.74409959627,"sigma":5.4627613358537115,"spot_z":-0.06556338774256389,"twap_z":-0.24205731642712253,"momentum":-0.4121868105853448,"decision_ms":1790002020044,"momentum30":-0.2942763880711942,"momentum60":1.0735756835884203,"spot_twap_gap":0.3056590866020052,"range60":1.2816605131366456,"final_mean":85740.67787047249,"final_z":-0.07434449072210483,"final_up_prob":0.47036813824039037,"final_drift_up_prob":0.04212490178810918,"final_known_seconds":0,"final_sd":64.62610589322846,"final_drift_shift":-106.77514388362627},"entry_side":null,"context_gap":null,"book_errors":[null,null],"books":[{"bid":0.46,"ask":0.47,"asks":[[0.47,241.22]],"received_ms":1790002020032,"observed_ms":1790002020024,"hash":"0a7f742161c971d9eef5efacf776aba70183a000"},{"bid":0.53,"ask":0.54,"asks":[[0.54,479.53]],"received_ms":1790002020044,"observed_ms":1790002020031,"hash":"0b416218fe11349d7ae69cb11a512973c58bade2"}],"intents":{"pair_fast":null,"pair_250":null,"pair_add_fast":null,"pair_add_250":null},"decision_ms":1790002020045,"feature_cutoff_ms":1790002020044,"request_ms":1790002020005,"inventory":{"pair_fast":{"qty":[0.0,0.0],"cash":0.0,"lots":[[],[]],"floor":0.0},"pair_250":{"qty":[0.0,0.0],"cash":0.0,"lots":[[],[]],"floor":0.0},"pair_add_fast":{"qty":[0.0,0.0],"cash":0.0,"lots":[[],[]],"floor":0.0},"pair_add_250":{"qty":[0.0,0.0],"cash":0.0,"lots":[[],[]],"floor":0.0}}}
{"kind":"decision","recorded_ms":1790002030093,"S":1790001900,"age":130,"signal":{"rsi14":48.60541546694572,"volume_ratio":0.318560198471069,"taker_buy_fraction":0.3213913207271337,"volume5":128.05128,"return1":5.434318778235557,"return5":-9.864786780229734,"return15":6.898705044157571,"bollinger_z":-0.4252106941893981,"bar_close_ms":1790002019999,"ref":85745.48246540247,"reference_received_ms":1790001901161,"spot":85770.08629781964,"twap":85736.58597151123,"sigma":4.7780004897326975,"spot_z":0.3950466456298746,"twap_z":-0.1428448223029076,"momentum":1.8695994467908081,"decision_ms":1790002030091,"momentum30":1.3740633311132757,"momentum60":1.0568869073061586,"spot_twap_gap":0.905163894142073,"range60":1.2405083806937776,"final_mean":85770.08629781964,"final_z":0.4517903502447025,"final_up_prob":0.6742899889590187,"final_drift_up_prob":0.9999999999999937,"final_known_seconds":0,"final_sd":54.45851688474884,"final_drift_shift":395.22136432704195},"entry_side":null,"context_gap":null,"book_errors":[null,null],"books":[{"bid":0.6,"ask":0.62,"asks":[[0.62,14.71]],"received_ms":1790002030084,"observed_ms":1790002030074,"hash":"24758caa3391c4a71786db64aa74b14c57511b20"},{"bid":0.37,"ask":0.4,"asks":[[0.4,1840.22]],"received_ms":1790002030091,"observed_ms":1790002030080,"hash":"e351827485631f099e9ea63f77f0a9fb4a9d3b75"}],"intents":{"pair_fast":null,"pair_250":null,"pair_add_fast":null,"pair_add_250":null},"decision_ms":1790002030093,"feature_cutoff_ms":1790002030091,"request_ms":1790002030047,"inventory":{"pair_fast":{"qty":[0.0,0.0],"cash":0.0,"lots":[[],[]],"floor":0.0},"pair_250":{"qty":[0.0,0.0],"cash":0.0,"lots":[[],[]],"floor":0.0},"pair_add_fast":{"qty":[0.0,0.0],"cash":0.0,"lots":[[],[]],"floor":0.0},"pair_add_250":{"qty":[0.0,0.0],"cash":0.0,"lots":[[],[]],"floor":0.0}}}
{"kind":"decision","recorded_ms":1790002040044,"S":1790001900,"age":140,"signal":{"rsi14":48.60541546694572,"volume_ratio":0.318560198471069,"taker_buy_fraction":0.3213913207271337,"volume5":128.05128,"return1":5.434318778235557,"return5":-9.864786780229734,"return15":6.898705044157571,"bollinger_z":-0.4252106941893981,"bar_close_ms":1790002019999,"ref":85745.48246540247,"reference_received_ms":1790001901161,"spot":85822.42322295056,"twap":85747.752669687,"sigma":7.303040138354766,"spot_z":0.833011784259763,"twap_z":0.024578740604573334,"momentum":2.195741715921275,"decision_ms":1790002040043,"momentum30":1.865604449328967,"momentum60":1.5181791037767902,"spot_twap_gap":1.319988223000449,"range60":1.5641763516202731,"final_mean":85822.42322295056,"final_z":0.9619222543927903,"final_up_prob":0.8319556706263028,"final_drift_up_prob":1.0,"final_known_seconds":0,"final_sd":79.9864616882742,"final_drift_shift":658.9987910256922},"entry_side":null,"context_gap":null,"book_errors":[null,null],"books":[{"bid":0.77,"ask":0.78,"asks":[[0.78,472.8]],"received_ms":1790002040040,"observed_ms":1790002039775,"hash":"ba4b67952db3f46d03059e18f4f01f3eb0980d88"},{"bid":0.22,"ask":0.23,"asks":[[0.23,43.0]],"received_ms":1790002040043,"observed_ms":1790002039775,"hash":"8296828d384124376f23780070a35fc2fdf9d943"}],"intents":{"pair_fast":null,"pair_250":null,"pair_add_fast":null,"pair_add_250":null},"decision_ms":1790002040044,"feature_cutoff_ms":1790002040043,"request_ms":1790002040017,"inventory":{"pair_fast":{"qty":[0.0,0.0],"cash":0.0,"lots":[[],[]],"floor":0.0},"pair_250":{"qty":[0.0,0.0],"cash":0.0,"lots":[[],[]],"floor":0.0},"pair_add_fast":{"qty":[0.0,0.0],"cash":0.0,"lots":[[],[]],"floor":0.0},"pair_add_250":{"qty":[0.0,0.0],"cash":0.0,"lots":[[],[]],"floor":0.0}}}
{"kind":"decision","recorded_ms":1790002050047,"S":1790001900,"age":150,"signal":{"rsi14":48.60541546694572,"volume_ratio":0.318560198471069,"taker_buy_fraction":0.3213913207271337,"volume5":128.05128,"return1":5.434318778235557,"return5":-9.864786780229734,"return15":6.898705044157571,"bollinger_z":-0.4252106941893981,"bar_close_ms":1790002019999,"ref":85745.48246540247,"reference_received_ms":1790001901161,"spot":85832.64871549977,"twap":85762.46924893993,"sigma":7.242503687807617,"spot_z":0.9828349923568526,"twap_z":0.19153290694013925,"momentum":0.381027366688641,"decision_ms":1790002050046,"momentum30":2.289225188331533,"momentum60":1.4824524417181726,"spot_twap_gap":1.2509665945565158,"range60":1.761291668825629,"final_mean":85832.64871549977,"final_z":1.1477680239371104,"final_up_prob":0.8744678295160808,"final_drift_up_prob":0.9942337697133896,"final_known_seconds":0,"final_sd":75.94413529512956,"final_drift_shift":104.67901535965498},"entry_side":null,"context_gap":null,"book_errors":[null,null],"books":[{"bid":0.8,"ask":0.81,"asks":[[0.81,119.73]],"received_ms":1790002050045,"observed_ms":1790002050037,"hash":"77406366b09a8c1d922707633f47b9d87e517575"},{"bid":0.19,"ask":0.2,"asks":[[0.2,317.0]],"received_ms":1790002050046,"observed_ms":1790002050037,"hash":"514fb90c3c9e55129b1b23a83309148e31a5b9bc"}],"intents":{"pair_fast":null,"pair_250":null,"pair_add_fast":null,"pair_add_250":null},"decision_ms":1790002050047,"feature_cutoff_ms":1790002050046,"request_ms":1790002050017,"inventory":{"pair_fast":{"qty":[0.0,0.0],"cash":0.0,"lots":[[],[]],"floor":0.0},"pair_250":{"qty":[0.0,0.0],"cash":0.0,"lots":[[],[]],"floor":0.0},"pair_add_fast":{"qty":[0.0,0.0],"cash":0.0,"lots":[[],[]],"floor":0.0},"pair_add_250":{"qty":[0.0,0.0],"cash":0.0,"lots":[[],[]],"floor":0.0}}}
{"kind":"decision","recorded_ms":1790002060062,"S":1790001900,"age":160,"signal":{"rsi14":48.60541546694572,"volume_ratio":0.318560198471069,"taker_buy_fraction":0.3213913207271337,"volume5":128.05128,"return1":5.434318778235557,"return5":-9.864786780229734,"return15":6.898705044157571,"bollinger_z":-0.4252106941893981,"bar_close_ms":1790002019999,"ref":85745.48246540247,"reference_received_ms":1790001901161,"spot":85889.63341893611,"twap":85778.88010848206,"sigma":9.004471451862292,"spot_z":1.3532870037710507,"twap_z":0.313536575570723,"momentum":2.001153074845274,"decision_ms":1790002060061,"momentum30":2.3909231167640033,"momentum60":2.2295387067136576,"spot_twap_gap":1.5878989648606092,"range60":2.23222892963586,"final_mean":85889.63341893611,"final_z":1.6013703919042153,"final_up_prob":0.9453525467433747,"final_drift_up_prob":1.0,"final_known_seconds":0,"final_sd":90.01724664224933,"final_drift_shift":626.4556318951851},"entry_side":null,"context_gap":null,"book_errors":[null,null],"books":[{"bid":0.9,"ask":0.91,"asks":[[0.91,246.1]],"received_ms":1790002060061,"observed_ms":1790002060045,"hash":"26d7b8a8e55871eda46cf9c1ee13e6aefb420d32"},{"bid":0.09,"ask":0.1,"asks":[[0.1,359.38]],"received_ms":1790002060051,"observed_ms":1790002060042,"hash":"5f974ba77fc6755e584b9311330b82dba5be256a"}],"intents":{"pair_fast":null,"pair_250":null,"pair_add_fast":null,"pair_add_250":null},"decision_ms":1790002060062,"feature_cutoff_ms":1790002060061,"request_ms":1790002060023,"inventory":{"pair_fast":{"qty":[0.0,0.0],"cash":0.0,"lots":[[],[]],"floor":0.0},"pair_250":{"qty":[0.0,0.0],"cash":0.0,"lots":[[],[]],"floor":0.0},"pair_add_fast":{"qty":[0.0,0.0],"cash":0.0,"lots":[[],[]],"floor":0.0},"pair_add_250":{"qty":[0.0,0.0],"cash":0.0,"lots":[[],[]],"floor":0.0}}}
{"kind":"decision","recorded_ms":1790002070077,"S":1790001900,"age":170,"signal":{"rsi14":48.60541546694572,"volume_ratio":0.318560198471069,"taker_buy_fraction":0.3213913207271337,"volume5":128.05128,"return1":5.434318778235557,"return5":-9.864786780229734,"return15":6.898705044157571,"bollinger_z":-0.4252106941893981,"bar_close_ms":1790002019999,"ref":85745.48246540247,"reference_received_ms":1790001901161,"spot":85878.06540197693,"twap":85804.54795057306,"sigma":8.787451771354947,"spot_z":1.3236707986151255,"twap_z":0.5896932135187644,"momentum":-0.3113677119194638,"decision_ms":1790002070076,"momentum30":1.1249183563946201,"momentum60":1.913798302733931,"spot_twap_gap":1.0800699010034096,"range60":2.244522929030842,"final_mean":85878.06540197693,"final_z":1.5910611483301142,"final_up_prob":0.9442020925028074,"final_drift_up_prob":0.7100461025652811,"final_known_seconds":0,"final_sd":83.32988126421725,"final_drift_shift":-86.45823005722512},"entry_side":null,"context_gap":null,"book_errors":[null,null],"books":[{"bid":0.94,"ask":0.95,"asks":[[0.95,1058.01]],"received_ms":1790002070076,"observed_ms":1790002070067,"hash":"2d86e79b1ef911794e71a029c46eb7d3e1c9baff"},{"bid":0.05,"ask":0.06,"asks":[[0.06,155.0]],"received_ms":1790002070067,"observed_ms":1790002070059,"hash":"ca8fcfca64e5ef9c7694133f2a24c10ae2b056cd"}],"intents":{"pair_fast":null,"pair_250":null,"pair_add_fast":null,"pair_add_250":null},"decision_ms":1790002070077,"feature_cutoff_ms":1790002070076,"request_ms":1790002070037,"inventory":{"pair_fast":{"qty":[0.0,0.0],"cash":0.0,"lots":[[],[]],"floor":0.0},"pair_250":{"qty":[0.0,0.0],"cash":0.0,"lots":[[],[]],"floor":0.0},"pair_add_fast":{"qty":[0.0,0.0],"cash":0.0,"lots":[[],[]],"floor":0.0},"pair_add_250":{"qty":[0.0,0.0],"cash":0.0,"lots":[[],[]],"floor":0.0}}}
{"kind":"decision","recorded_ms":1790002080030,"S":1790001900,"age":180,"signal":{"rsi14":48.60541546694572,"volume_ratio":0.318560198471069,"taker_buy_fraction":0.3213913207271337,"volume5":128.05128,"return1":5.434318778235557,"return5":-9.864786780229734,"return15":6.898705044157571,"bollinger_z":-0.4252106941893981,"bar_close_ms":1790002019999,"ref":85745.48246540247,"reference_received_ms":1790001901161,"spot":85884.04541977552,"twap":85827.83954591033,"sigma":8.551523755338962,"spot_z":1.4793314447887165,"twap_z":0.8792640099768071,"momentum":0.19111329977802155,"decision_ms":1790002080029,"momentum30":1.0972592059582138,"momentum60":2.1468594696263374,"spot_twap_gap":0.848520956291492,"range60":2.1872034968533614,"final_mean":85884.04541977552,"final_z":1.811913099779038,"final_up_prob":0.9650001875206207,"final_drift_up_prob":0.9922385974408144,"final_known_seconds":0,"final_sd":76.47328913839422,"final_drift_shift":46.49828820024451},"entry_side":null,"context_gap":null,"book_errors":[null,null],"books":[{"bid":0.94,"ask":0.95,"asks":[[0.95,172.3]],"received_ms":1790002080029,"observed_ms":1790002080018,"hash":"6ad877e988a77a38dd88135e083516634f1ceeb9"},{"bid":0.05,"ask":0.06,"asks":[[0.06,449.57]],"received_ms":1790002080028,"observed_ms":1790002080019,"hash":"3a6bb45205081ab2acd2477e9f5d8ef50ed6d263"}],"intents":{"pair_fast":null,"pair_250":null,"pair_add_fast":null,"pair_add_250":null},"decision_ms":1790002080030,"feature_cutoff_ms":1790002080029,"request_ms":1790002080001,"inventory":{"pair_fast":{"qty":[0.0,0.0],"cash":0.0,"lots":[[],[]],"floor":0.0},"pair_250":{"qty":[0.0,0.0],"cash":0.0,"lots":[[],[]],"floor":0.0},"pair_add_fast":{"qty":[0.0,0.0],"cash":0.0,"lots":[[],[]],"floor":0.0},"pair_add_250":{"qty":[0.0,0.0],"cash":0.0,"lots":[[],[]],"floor":0.0}}}
{"kind":"decision","recorded_ms":1790002090065,"S":1790001900,"age":190,"signal":{"rsi14":48.40031536222885,"volume_ratio":0.5805894491913767,"taker_buy_fraction":0.4086967208586037,"volume5":120.18024,"return1":16.715683119255253,"return5":11.715294937352414,"return15":13.366959469502172,"bollinger_z":0.807819192593616,"bar_close_ms":1790002079999,"ref":85745.48246540247,"reference_received_ms":1790001901161,"spot":85882.97056794132,"twap":85850.68900296788,"sigma":8.104540558786304,"spot_z":1.6179635299448856,"twap_z":1.2380732423338874,"momentum":-0.08336444228166207,"decision_ms":1790002090065,"momentum30":-0.08441539455639557,"momentum60":1.772232575030725,"spot_twap_gap":0.5142218843242692,"range60":1.8319232729580903,"final_mean":85882.97056794132,"final_z":2.0285673393395287,"final_up_prob":0.9787488109936355,"final_drift_up_prob":0.9621817065140146,"final_known_seconds":0,"final_sd":67.77596181924625,"final_drift_shift":-17.078362519980228},"entry_side":null,"context_gap":null,"book_errors":[null,null],"books":[{"bid":0.97,"ask":0.98,"asks":[[0.98,657.19]],"received_ms":1790002090064,"observed_ms":1790002090050,"hash":"80c7e9d0cca80f8beae71cc5618231b25da93b22"},{"bid":0.02,"ask":0.03,"asks":[[0.03,277.3]],"received_ms":1790002090059,"observed_ms":1790002090050,"hash":"148a31bcf3d8cf55fb40903b3a023f9c52aa17b5"}],"intents":{"pair_fast":null,"pair_250":null,"pair_add_fast":null,"pair_add_250":null},"decision_ms":1790002090065,"feature_cutoff_ms":1790002090065,"request_ms":1790002090025,"inventory":{"pair_fast":{"qty":[0.0,0.0],"cash":0.0,"lots":[[],[]],"floor":0.0},"pair_250":{"qty":[0.0,0.0],"cash":0.0,"lots":[[],[]],"floor":0.0},"pair_add_fast":{"qty":[0.0,0.0],"cash":0.0,"lots":[[],[]],"floor":0.0},"pair_add_250":{"qty":[0.0,0.0],"cash":0.0,"lots":[[],[]],"floor":0.0}}}
{"kind":"decision","recorded_ms":1790002100075,"S":1790001900,"age":200,"signal":{"rsi14":48.40031536222885,"volume_ratio":0.5805894491913767,"taker_buy_fraction":0.4086967208586037,"volume5":120.18024,"return1":16.715683119255253,"return5":11.715294937352414,"return15":13.366959469502172,"bollinger_z":0.807819192593616,"bar_close_ms":1790002079999,"ref":85745.48246540247,"reference_received_ms":1790001901161,"spot":85919.66410262792,"twap":85869.00548381392,"sigma":6.552163649781253,"spot_z":2.6593676445216903,"twap_z":1.8859227858323113,"momentum":1.432384141922442,"decision_ms":1790002100074,"momentum30":1.1365133251112898,"momentum60":1.886435930938284,"spot_twap_gap":0.998143501371319,"range60":1.886435930938284,"final_mean":85919.66410262792,"final_z":3.4340766690646807,"final_up_prob":0.999702712001896,"final_drift_up_prob":0.9999999999999738,"final_known_seconds":0,"final_sd":50.72153420293181,"final_drift_shift":207.5309752047798},"entry_side":null,"context_gap":null,"book_errors":[null,null],"books":[{"bid":0.97,"ask":0.98,"asks":[[0.98,158.22]],"received_ms":1790002100074,"observed_ms":1790002100055,"hash":"f4ad13a0e5ccec512c7052ba2067d9c195eb1314"},{"bid":0.02,"ask":0.03,"asks":[[0.03,659.96]],"received_ms":1790002100067,"observed_ms":1790002100055,"hash":"9da96d437560a662780e9abcd545fb2eb7fc65e1"}],"intents":{"pair_fast":null,"pair_250":null,"pair_add_fast":null,"pair_add_250":null},"decision_ms":1790002100075,"feature_cutoff_ms":1790002100074,"request_ms":1790002100039,"inventory":{"pair_fast":{"qty":[0.0,0.0],"cash":0.0,"lots":[[],[]],"floor":0.0},"pair_250":{"qty":[0.0,0.0],"cash":0.0,"lots":[[],[]],"floor":0.0},"pair_add_fast":{"qty":[0.0,0.0],"cash":0.0,"lots":[[],[]],"floor":0.0},"pair_add_250":{"qty":[0.0,0.0],"cash":0.0,"lots":[[],[]],"floor":0.0}}}
{"kind":"decision","recorded_ms":1790002110088,"S":1790001900,"age":210,"signal":{"rsi14":48.40031536222885,"volume_ratio":0.5805894491913767,"taker_buy_fraction":0.4086967208586037,"volume5":120.18024,"return1":16.715683119255253,"return5":11.715294937352414,"return15":13.366959469502172,"bollinger_z":0.807819192593616,"bar_close_ms":1790002079999,"ref":85745.48246540247,"reference_received_ms":1790001901161,"spot":85925.13339915918,"twap":85885.76113890116,"sigma":6.606914284573831,"spot_z":2.8675905928381593,"twap_z":2.2391300511992167,"momentum":0.04787230549637455,"decision_ms":1790002110086,"momentum30":1.1060789975768803,"momentum60":1.8071048225356514,"spot_twap_gap":0.7693359901152207,"range60":1.8932956178913505,"final_mean":85925.13339915918,"final_z":3.8487492640688066,"final_up_prob":0.9999406387746974,"final_drift_up_prob":0.9999651240517793,"final_known_seconds":0,"final_sd":46.67774423080723,"final_drift_shift":5.992545374457396},"entry_side":null,"context_gap":null,"book_errors":[null,null],"books":[{"bid":0.98,"ask":0.99,"asks":[[0.99,1975.19]],"received_ms":1790002110079,"observed_ms":1790002110060,"hash":"3217fc5619434152e8220e0ad5b48e6ee380c709"},{"bid":0.01,"ask":0.02,"asks":[[0.02,604.59]],"received_ms":1790002110086,"observed_ms":1790002110073,"hash":"96eeb6801673bc21fac03c3cb1215cb2fc87d1ee"}],"intents":{"pair_fast":null,"pair_250":null,"pair_add_fast":null,"pair_add_250":null},"decision_ms":1790002110088,"feature_cutoff_ms":1790002110086,"request_ms":1790002110049,"inventory":{"pair_fast":{"qty":[0.0,0.0],"cash":0.0,"lots":[[],[]],"floor":0.0},"pair_250":{"qty":[0.0,0.0],"cash":0.0,"lots":[[],[]],"floor":0.0},"pair_add_fast":{"qty":[0.0,0.0],"cash":0.0,"lots":[[],[]],"floor":0.0},"pair_add_250":{"qty":[0.0,0.0],"cash":0.0,"lots":[[],[]],"floor":0.0}}}
