{"kind":"decision","recorded_ms":1790000070072,"S":1789999800,"age":270,"signal":{"rsi14":39.81074052466647,"volume_ratio":1.3867905723784584,"taker_buy_fraction":0.5849717337618322,"volume5":176.36765,"return1":0.8069411009238956,"return5":8.12688210508339,"return15":-27.013760808818525,"bollinger_z":-0.6534442878752716,"bar_close_ms":1790000039999,"ref":85196.4363623876,"reference_received_ms":1789999802215,"spot":85298.55212367022,"twap":85266.03695590053,"sigma":10.742422035841996,"spot_z":1.7375786295391977,"twap_z":1.184307910672202,"momentum":-0.6412664312996323,"decision_ms":1790000070071,"momentum30":1.0380203822470464,"momentum60":0.536378435744618,"spot_twap_gap":0.39075825684674337,"range60":1.0590735507523168,"final_mean":85291.29695662812,"final_z":5.604762328995422,"final_up_prob":0.9999999895729539,"final_drift_up_prob":0.9999982913754872,"final_known_seconds":30,"final_sd":16.924998540933498,"final_drift_shift":-16.260873838016007},"entry_side":null,"context_gap":null,"book_errors":[null,null],"books":[{"bid":0.99,"ask":null,"asks":[],"received_ms":1790000070071,"observed_ms":1790000070059,"hash":"18d4becfc21936c2f18bb87761b859a250344e82"},{"bid":null,"ask":0.01,"asks":[[0.01,39985.94]],"received_ms":1790000070046,"observed_ms":1790000070037,"hash":"24163d073e918107512b49e351f131a691049ddc"}],"intents":{"pair_fast":null,"pair_250":null,"pair_add_fast":null,"pair_add_250":null},"decision_ms":1790000070072,"feature_cutoff_ms":1790000070071,"request_ms":1790000070020,"inventory":{"pair_fast":{"qty":[0.0,0.0],"cash":0.0,"lots":[[],[]],"floor":0.0},"pair_250":{"qty":[0.0,0.0],"cash":0.0,"lots":[[],[]],"floor":0.0},"pair_add_fast":{"qty":[0.0,0.0],"cash":0.0,"lots":[[],[]],"floor":0.0},"pair_add_250":{"qty":[0.0,0.0],"cash":0.0,"lots":[[],[]],"floor":0.0}}}
{"kind":"decision","recorded_ms":1790000080080,"S":1789999800,"age":280,"signal":{"rsi14":39.81074052466647,"volume_ratio":1.3867905723784584,"taker_buy_fraction":0.5849717337618322,"volume5":176.36765,"return1":0.8069411009238956,"return5":8.12688210508339,"return15":-27.013760808818525,"bollinger_z":-0.6534442878752716,"bar_close_ms":1790000039999,"ref":85196.4363623876,"reference_received_ms":1789999802215,"spot":85322.86850675714,"twap":85276.56725559564,"sigma":10.600783454123205,"spot_z":2.6721693175267798,"twap_z":1.6935828723327302,"momentum":0.49569924724427855,"decision_ms":1790000080079,"momentum30":0.8136705761031111,"momentum60":1.0681664643574214,"spot_twap_gap":0.5638701939125251,"range60":1.1040621998820614,"final_mean":85301.30254898203,"final_z":11.56225881736355,"final_up_prob":1.0,"final_drift_up_prob":1.0,"final_known_seconds":40,"final_sd":9.069697214954948,"final_drift_shift":5.495373910504948},"entry_side":null,"context_gap":null,"book_errors":[null,null],"books":[{"bid":0.99,"ask":null,"asks":[],"received_ms":1790000080079,"observed_ms":1790000080060,"hash":"7c1e9481803e6a67de9bc634577cd5f25efa5e4f"},{"bid":null,"ask":0.01,"asks":[[0.01,56403.48]],"received_ms":1790000080072,"observed_ms":1790000080060,"hash":"335189f7363cab9c02ea6cae33147addc2e546f8"}],"intents":{"pair_fast":null,"pair_250":null,"pair_add_fast":null,"pair_add_250":null},"decision_ms":1790000080080,"feature_cutoff_ms":1790000080079,"request_ms":1790000080047,"inventory":{"pair_fast":{"qty":[0.0,0.0],"cash":0.0,"lots":[[],[]],"floor":0.0},"pair_250":{"qty":[0.0,0.0],"cash":0.0,"lots":[[],[]],"floor":0.0},"pair_add_fast":{"qty":[0.0,0.0],"cash":0.0,"lots":[[],[]],"floor":0.0},"pair_add_250":{"qty":[0.0,0.0],"cash":0.0,"lots":[[],[]],"floor":0.0}}}
{"kind":"decision","recorded_ms":1790000090035,"S":1789999800,"age":290,"signal":{"rsi14":39.81074052466647,"volume_ratio":1.3867905723784584,"taker_buy_fraction":0.5849717337618322,"volume5":176.36765,"return1":0.8069411009238956,"return5":8.12688210508339,"return15":-27.013760808818525,"bollinger_z":-0.6534442878752716,"bar_close_ms":1790000039999,"ref":85196.4363623876,"reference_received_ms":1789999802215,"spot":85291.23091921913,"twap":85287.34060854172,"sigma":10.592019703817222,"spot_z":2.834799785821578,"twap_z":2.7184613351371496,"momentum":-0.9894226607266972,"decision_ms":1790000090033,"momentum30":-0.5016878213762772,"momentum60":0.25668822364027677,"spot_twap_gap":0.047416542159398334,"range60":1.1232952097027795,"final_mean":85293.32962735942,"final_z":30.212036468249256,"final_up_prob":1.0,"final_drift_up_prob":1.0,"final_known_seconds":50,"final_sd":3.2071080370119067,"final_drift_shift":-2.743521095418325},"entry_side":null,"context_gap":null,"book_errors":[null,null],"books":[{"bid":0.99,"ask":null,"asks":[],"received_ms":1790000090026,"observed_ms":1790000090015,"hash":"aeb419e241ee9dd1c1497551c11ce07d60b37852"},{"bid":null,"ask":0.01,"asks":[[0.01,57594.91]],"received_ms":1790000090033,"observed_ms":1790000090015,"hash":"e6b04ddcbe6497b1dbda0526d3769a9853bbe78a"}],"intents":{"pair_fast":null,"pair_250":null,"pair_add_fast":null,"pair_add_250":null},"decision_ms":1790000090035,"feature_cutoff_ms":1790000090033,"request_ms":1790000090001,"inventory":{"pair_fast":{"qty":[0.0,0.0],"cash":0.0,"lots":[[],[]],"floor":0.0},"pair_250":{"qty":[0.0,0.0],"cash":0.0,"lots":[[],[]],"floor":0.0},"pair_add_fast":{"qty":[0.0,0.0],"cash":0.0,"lots":[[],[]],"floor":0.0},"pair_add_250":{"qty":[0.0,0.0],"cash":0.0,"lots":[[],[]],"floor":0.0}}}
{"kind":"decision","recorded_ms":1790000130054,"S":1790000100,"age":30,"signal":{"rsi14":43.49920344859966,"volume_ratio":1.7553908619845005,"taker_buy_fraction":0.6097213435804362,"volume5":203.17027000000002,"return1":7.216207999314475,"return5":8.390585198488623,"return15":-16.93822283678308,"bollinger_z":-0.21129905037201052,"bar_close_ms":1790000099999,"ref":85288.69659526845,"reference_received_ms":1790000101794,"spot":85264.30194997287,"twap":85273.49605020668,"sigma":12.622378958041043,"spot_z":-0.11762890122752111,"twap_z":-0.07329573322385018,"momentum":1.2178955416462631,"decision_ms":1790000130053,"momentum30":-0.3533700366602852,"momentum60":-0.4290511888285252,"spot_twap_gap":-0.094035620404285,"range60":1.242523985104811,"final_mean":85264.30194997287,"final_z":-0.12744987651388281,"final_up_prob":0.4492921711580245,"final_drift_up_prob":0.9999999987893297,"final_known_seconds":0,"final_sd":191.4057978151814,"final_drift_shift":1166.4512150891542},"entry_side":null,"context_gap":null,"book_errors":[null,null],"books":[{"bid":0.55,"ask":0.56,"asks":[[0.56,994.23]],"received_ms":1790000130053,"observed_ms":1790000130043,"hash":"6fe5e79e9eaaa0b0592c629eeaa7d4aa9078dd45"},{"bid":0.44,"ask":0.45,"asks":[[0.45,201.8]],"received_ms":1790000130051,"observed_ms":1790000130042,"hash":"cea70db3424a8a8e0699d613daca209360545fbe"}],"intents":{"pair_fast":null,"pair_250":null,"pair_add_fast":null,"pair_add_250":null},"decision_ms":1790000130054,"feature_cutoff_ms":1790000130053,"request_ms":1790000130019,"inventory":{"pair_fast":{"qty":[0.0,0.0],"cash":0.0,"lots":[[],[]],"floor":0.0},"pair_250":{"qty":[0.0,0.0],"cash":0.0,"lots":[[],[]],"floor":0.0},"pair_add_fast":{"qty":[0.0,0.0],"cash":0.0,"lots":[[],[]],"floor":0.0},"pair_add_250":{"qty":[0.0,0.0],"cash":0.0,"lots":[[],[]],"floor":0.0}}}
{"kind":"decision","recorded_ms":1790000140069,"S":1790000100,"age":40,"signal":{"rsi14":43.49920344859966,"volume_ratio":1.7553908619845005,"taker_buy_fraction":0.6097213435804362,"volume5":203.17027000000002,"return1":7.216207999314475,"return5":8.390585198488623,"return15":-16.93822283678308,"bollinger_z":-0.21129905037201052,"bar_close_ms":1790000099999,"ref":85288.69659526845,"reference_received_ms":1790000101794,"spot":85352.07602043505,"twap":85272.88916742228,"sigma":18.273003743045656,"spot_z":0.21513330199676642,"twap_z":-0.05365627945794088,"momentum":0.8471227423910913,"decision_ms":1790000140067,"momentum30":1.2690819273973868,"momentum60":0.19573317877609694,"spot_twap_gap":0.5594580348687831,"range60":1.1678529907791795,"final_mean":85352.07602043505,"final_z":0.23388003682276073,"final_up_prob":0.5924609441246007,"final_drift_up_prob":0.9999942608207144,"final_known_seconds":0,"final_sd":270.99117148945487,"final_drift_shift":1125.5313349015096},"entry_side":null,"context_gap":null,"book_errors":[null,null],"books":[{"bid":0.66,"ask":0.67,"asks":[[0.67,316.4]],"received_ms":1790000140058,"observed_ms":1790000140050,"hash":"68fa83c56fe0cc23e6c09de33784c8fb6aada2e3"},{"bid":0.33,"ask":0.34,"asks":[[0.34,718.3]],"received_ms":1790000140067,"observed_ms":1790000140055,"hash":"38f9ddf8ead2571a6eba60615979d2d59093ef2f"}],"intents":{"pair_fast":null,"pair_250":null,"pair_add_fast":null,"pair_add_250":null},"decision_ms":1790000140069,"feature_cutoff_ms":1790000140067,"request_ms":1790000140028,"inventory":{"pair_fast":{"qty":[0.0,0.0],"cash":0.0,"lots":[[],[]],"floor":0.0},"pair_250":{"qty":[0.0,0.0],"cash":0.0,"lots":[[],[]],"floor":0.0},"pair_add_fast":{"qty":[0.0,0.0],"cash":0.0,"lots":[[],[]],"floor":0.0},"pair_add_250":{"qty":[0.0,0.0],"cash":0.0,"lots":[[],[]],"floor":0.0}}}
{"kind":"decision","recorded_ms":1790000150094,"S":1790000100,"age":50,"signal":{"rsi14":43.49920344859966,"volume_ratio":1.7553908619845005,"taker_buy_fraction":0.6097213435804362,"volume5":203.17027000000002,"return1":7.216207999314475,"return5":8.390585198488623,"return15":-16.93822283678308,"bollinger_z":-0.21129905037201052,"bar_close_ms":1790000099999,"ref":85288.69659526845,"reference_received_ms":1790000101794,"spot":85331.6142624341,"twap":85280.25411532153,"sigma":18.231425298431635,"spot_z":0.14891082664122893,"twap_z":-0.029292754029399567,"momentum":-0.46268492458154675,"decision_ms":1790000150093,"momentum30":1.160904610096754,"momentum60":0.27912398827698603,"spot_twap_gap":0.3636888708547108,"range60":1.1705163870907451,"final_mean":85331.6142624341,"final_z":0.16248079081727104,"final_up_prob":0.5645363730102911,"final_drift_up_prob":0.01977938435335952,"final_known_seconds":0,"final_sd":264.13994509610677,"final_drift_shift":-586.6040075532088},"entry_side":null,"context_gap":null,"book_errors":[null,null],"books":[{"bid":0.57,"ask":0.58,"asks":[[0.58,666.25]],"received_ms":1790000150082,"observed_ms":1790000150067,"hash":"c7616e3fd15678f606d051f628e727db3b1cdc35"},{"bid":0.42,"ask":0.43,"asks":[[0.43,221.0]],"received_ms":1790000150092,"observed_ms":1790000150079,"hash":"19dac0e0efe757387f30042b51b7230c1c7a3356"}],"intents":{"pair_fast":null,"pair_250":null,"pair_add_fast":null,"pair_add_250":null},"decision_ms":1790000150094,"feature_cutoff_ms":1790000150093,"request_ms":1790000150043,"inventory":{"pair_fast":{"qty":[0.0,0.0],"cash":0.0,"lots":[[],[]],"floor":0.0},"pair_250":{"qty":[0.0,0.0],"cash":0.0,"lots":[[],[]],"floor":0.0},"pair_add_fast":{"qty":[0.0,0.0],"cash":0.0,"lots":[[],[]],"floor":0.0},"pair_add_250":{"qty":[0.0,0.0],"cash":0.0,"lots":[[],[]],"floor":0.0}}}
{"kind":"decision","recorded_ms":1790000160055,"S":1790000100,"age":60,"signal":{"rsi14":43.49920344859966,"volume_ratio":1.7553908619845005,"taker_buy_fraction":0.6097213435804362,"volume5":203.17027000000002,"return1":7.216207999314475,"return5":8.390585198488623,"return15":-16.93822283678308,"bollinger_z":-0.21129905037201052,"bar_close_ms":1790000099999,"ref":85288.69659526845,"reference_received_ms":1790000101794,"spot":85325.15475085241,"twap":85289.67867799723,"sigma":17.725316537914395,"spot_z":0.1327834465520755,"twap_z":0.003576821905484298,"momentum":-0.029599733336107457,"decision_ms":1790000160054,"momentum30":0.2269043462846053,"momentum60":0.26527619772720273,"spot_twap_gap":0.25838417622058335,"range60":1.2039379960402077,"final_mean":85325.15475085241,"final_z":0.14546025150274663,"final_up_prob":0.5578262516903706,"final_drift_up_prob":0.5025869215599578,"final_known_seconds":0,"final_sd":250.639987263226,"final_drift_shift":-34.83288154644076},"entry_side":null,"context_gap":null,"book_errors":[null,null],"books":[{"bid":0.57,"ask":0.58,"asks":[[0.58,866.0]],"received_ms":1790000160054,"observed_ms":1790000160042,"hash":"3564a51230b791cfe8a03f2d54e9881e3a101e55"},{"bid":0.42,"ask":0.43,"asks":[[0.43,244.3]],"received_ms":1790000160045,"observed_ms":1790000160037,"hash":"75ec2f784ab7251e84b1b592ba259346ecf6c71e"}],"intents":{"pair_fast":null,"pair_250":null,"pair_add_fast":null,"pair_add_250":null},"decision_ms":1790000160055,"feature_cutoff_ms":1790000160054,"request_ms":1790000160016,"inventory":{"pair_fast":{"qty":[0.0,0.0],"cash":0.0,"lots":[[],[]],"floor":0.0},"pair_250":{"qty":[0.0,0.0],"cash":0.0,"lots":[[],[]],"floor":0.0},"pair_add_fast":{"qty":[0.0,0.0],"cash":0.0,"lots":[[],[]],"floor":0.0},"pair_add_250":{"qty":[0.0,0.0],"cash":0.0,"lots":[[],[]],"floor":0.0}}}
{"kind":"decision","recorded_ms":1790000170040,"S":1790000100,"age":70,"signal":{"rsi14":43.63073701137834,"volume_ratio":3.6681571940967457,"taker_buy_fraction":0.6522870352938468,"volume5":279.71278,"return1":3.9341389062657077,"return5":5.0283871904997515,"return15":-12.320251559948579,"bollinger_z":0.045527630100376484,"bar_close_ms":1790000159999,"ref":85288.69659526845,"reference_received_ms":1790000101794,"spot":85321.48706303578,"twap":85297.89426411825,"sigma":16.133138314189353,"spot_z":0.13402930699157659,"twap_z":0.03759498615950652,"momentum":-0.058765588025139155,"decision_ms":1790000170037,"momentum30":-0.4164812059880204,"momentum60":0.7716257882130039,"spot_twap_gap":0.1887926071139967,"range60":1.3227545475802422,"final_mean":85321.48706303578,"final_z":0.1474667962005699,"final_up_prob":0.5586182070187775,"final_drift_up_prob":0.4513922565033907,"final_known_seconds":0,"final_sd":222.35831124128447,"final_drift_shift":-59.95033126740086},"entry_side":null,"context_gap":null,"book_errors":[null,null],"books":[{"bid":0.58,"ask":0.59,"asks":[[0.59,225.21]],"received_ms":1790000170037,"observed_ms":1790000170029,"hash":"3a0d4823eaf389be732d23c1b421ed0e429fdd22"},{"bid":0.41,"ask":0.42,"asks":[[0.42,754.99]],"received_ms":1790000170035,"observed_ms":1790000170023,"hash":"9f73ee578966b53d33dad4ee4a508f4c3c9e9cf6"}],"intents":{"pair_fast":null,"pair_250":null,"pair_add_fast":null,"pair_add_250":null},"decision_ms":1790000170040,"feature_cutoff_ms":1790000170037,"request_ms":1790000170003,"inventory":{"pair_fast":{"qty":[0.0,0.0],"cash":0.0,"lots":[[],[]],"floor":0.0},"pair_250":{"qty":[0.0,0.0],"cash":0.0,"lots":[[],[]],"floor":0.0},"pair_add_fast":{"qty":[0.0,0.0],"cash":0.0,"lots":[[],[]],"floor":0.0},"pair_add_250":{"qty":[0.0,0.0],"cash":0.0,"lots":[[],[]],"floor":0.0}}}
{"kind":"decision","recorded_ms":1790000180327,"S":1790000100,"age":80,"signal":{"rsi14":43.63073701137834,"volume_ratio":3.6681571940967457,"taker_buy_fraction":0.6522870352938468,"volume5":279.71278,"return1":3.9341389062657077,"return5":5.0283871904997515,"return15":-12.320251559948579,"bollinger_z":0.045527630100376484,"bar_close_ms":1790000159999,"ref":85288.69659526845,"reference_received_ms":1790000101794,"spot":85313.2117848491,"twap":85309.41310446261,"sigma":16.100458942970523,"spot_z":0.10273245610508654,"twap_z":0.08681384512397718,"momentum":-0.151297989056219,"decision_ms":1790000180326,"momentum30":-0.15424358871211785,"momentum60":0.7819731733199838,"spot_twap_gap":0.030459226714299317,"range60":1.3254393646432143,"final_mean":85313.2117848491,"final_z":0.11359373566942409,"final_up_prob":0.545220073290321,"final_drift_up_prob":0.28657400407172917,"final_known_seconds":0,"final_sd":215.8146260106416,"final_drift_shift":-146.10975569903727},"entry_side":null,"context_gap":null,"book_errors":[null,null],"books":[{"bid":0.58,"ask":0.59,"asks":[[0.59,5.0]],"received_ms":1790000180326,"observed_ms":1790000180040,"hash":"9f11b845640a45abfe50acd7cbb4707d7883dab0"},{"bid":0.41,"ask":0.42,"asks":[[0.42,2144.81]],"received_ms":1790000180071,"observed_ms":1790000180032,"hash":"7edb787fbfb0ef3ece42fcd79c893bcfb76d36e3"}],"intents":{"pair_fast":null,"pair_250":null,"pair_add_fast":null,"pair_add_250":null},"decision_ms":1790000180327,"feature_cutoff_ms":1790000180326,"request_ms":1790000180013,"inventory":{"pair_fast":{"qty":[0.0,0.0],"cash":0.0,"lots":[[],[]],"floor":0.0},"pair_250":{"qty":[0.0,0.0],"cash":0.0,"lots":[[],[]],"floor":0.0},"pair_add_fast":{"qty":[0.0,0.0],"cash":0.0,"lots":[[],[]],"floor":0.0},"pair_add_250":{"qty":[0.0,0.0],"cash":0.0,"lots":[[],[]],"floor":0.0}}}
{"kind":"decision","recorded_ms":1790000190088,"S":1790000100,"age":90,"signal":{"rsi14":43.63073701137834,"volume_ratio":3.6681571940967457,"taker_buy_fraction":0.6522870352938468,"volume5":279.71278,"return1":3.9341389062657077,"return5":5.0283871904997515,"return15":-12.320251559948579,"bollinger_z":0.045527630100376484,"bar_close_ms":1790000159999,"ref":85288.69659526845,"reference_received_ms":1790000101794,"spot":85335.92258749966,"twap":85326.22259210674,"sigma":9.695212192820568,"spot_z":0.3362049511772236,"twap_z":0.2671500446856972,"momentum":0.786297912724726,"decision_ms":1790000190087,"momentum30":0.21538298235433231,"momentum60":0.436717704668925,"spot_twap_gap":0.1291631369790381,"range60":0.8663462162365948,"final_mean":85335.92258749966,"final_z":0.37368913300040485,"final_up_prob":0.6456821944117807,"final_drift_up_prob":0.999929270400872,"final_known_seconds":0,"final_sd":126.37775107888037,"final_drift_shift":433.71754122674577},"entry_side":null,"context_gap":null,"book_errors":[null,null],"books":[{"bid":0.59,"ask":0.6,"asks":[[0.6,689.24]],"received_ms":1790000190074,"observed_ms":1790000190065,"hash":"111b2acc06874bc7f1ab0086774baa5f8d1c607b"},{"bid":0.4,"ask":0.41,"asks":[[0.41,103.94]],"received_ms":1790000190087,"observed_ms":1790000190072,"hash":"6687b4a1add49554792a4ee73e540807cd65af59"}],"intents":{"pair_fast":null,"pair_250":null,"pair_add_fast":null,"pair_add_250":null},"decision_ms":1790000190088,"feature_cutoff_ms":1790000190087,"request_ms":1790000190049,"inventory":{"pair_fast":{"qty":[0.0,0.0],"cash":0.0,"lots":[[],[]],"floor":0.0},"pair_250":{"qty":[0.0,0.0],"cash":0.0,"lots":[[],[]],"floor":0.0},"pair_add_fast":{"qty":[0.0,0.0],"cash":0.0,"lots":[[],[]],"floor":0.0},"pair_add_250":{"qty":[0.0,0.0],"cash":0.0,"lots":[[],[]],"floor":0.0}}}
{"kind":"decision","recorded_ms":1790000200065,"S":1790000100,"age":100,"signal":{"rsi14":43.63073701137834,"volume_ratio":3.6681571940967457,"taker_buy_fraction":0.6522870352938468,"volume5":279.71278,"return1":3.9341389062657077,"return5":5.0283871904997515,"return15":-12.320251559948579,"bollinger_z":0.045527630100376484,"bar_close_ms":1790000159999,"ref":85288.69659526845,"reference_received_ms":1790000101794,"spot":85337.545,"twap":85331.13522537444,"sigma":4.6300751972260334,"spot_z":0.7461340182978349,"twap_z":0.6482280390947429,"momentum":0.6341088848416256,"decision_ms":1790000200064,"momentum30":0.6557584007197667,"momentum60":-0.5784106931430888,"spot_twap_gap":0.17872244200699003,"range60":1.315621810263821,"final_mean":85337.545,"final_z":0.8342365733752157,"final_up_prob":0.7979261572883996,"final_drift_up_prob":0.999791215580101,"final_known_seconds":0,"final_sd":58.55461902600218,"final_drift_shift":157.77466786516922},"entry_side":null,"context_gap":null,"book_errors":[null,null],"books":[{"bid":0.62,"ask":0.63,"asks":[[0.63,1677.46]],"received_ms":1790000200064,"observed_ms":1790000200055,"hash":"22f35d388af5d211c10e1d10528551d367b7fa45"},{"bid":0.37,"ask":0.38,"asks":[[0.38,1115.28]],"received_ms":1790000200058,"observed_ms":1790000200048,"hash":"a182871c2a979d477ddb488239f60612f6a3fb00"}],"intents":{"pair_fast":null,"pair_250":null,"pair_add_fast":null,"pair_add_250":null},"decision_ms":1790000200065,"feature_cutoff_ms":1790000200064,"request_ms":1790000200012,"inventory":{"pair_fast":{"qty":[0.0,0.0],"cash":0.0,"lots":[[],[]],"floor":0.0},"pair_250":{"qty":[0.0,0.0],"cash":0.0,"lots":[[],[]],"floor":0.0},"pair_add_fast":{"qty":[0.0,0.0],"cash":0.0,"lots":[[],[]],"floor":0.0},"pair_add_250":{"qty":[0.0,0.0],"cash":0.0,"lots":[[],[]],"floor":0.0}}}
{"kind":"decision","recorded_ms":1790000210077,"S":1790000100,"age":110,"signal":{"rsi14":43.63073701137834,"volume_ratio":3.6681571940967457,"taker_buy_fraction":0.6522870352938468,"volume5":279.71278,"return1":3.9341389062657077,"return5":5.0283871904997515,"return15":-12.320251559948579,"bollinger_z":0.045527630100376484,"bar_close_ms":1790000159999,"ref":85288.69659526845,"reference_received_ms":1790000101794,"spot":85356.85954411463,"twap":85329.19698130824,"sigma":4.564821835238193,"spot_z":1.0835142179801152,"twap_z":0.6437917497791973,"momentum":1.6610175865539383,"decision_ms":1790000210076,"momentum30":1.801576690048335,"momentum60":0.8497325649258197,"spot_twap_gap":0.782335353050954,"range60":1.3046376091587064,"final_mean":85356.85954411463,"final_z":1.2195200878202905,"final_up_prob":0.8886765718509053,"final_drift_up_prob":0.9999999999999997,"final_known_seconds":0,"final_sd":55.89325631200368,"final_drift_shift":383.45261713153184},"entry_side":null,"context_gap":null,"book_errors":[null,null],"books":[{"bid":0.76,"ask":0.77,"asks":[[0.77,45.0]],"received_ms":1790000210067,"observed_ms":1790000210060,"hash":"1b5a762c3709c1a884b298d6546d20dc3255a4b1"},{"bid":0.23,"ask":0.24,"asks":[[0.24,146.53]],"received_ms":1790000210075,"observed_ms":1790000210065,"hash":"0baff9249b5990d732bd695a30f65636fc642fcd"}],"intents":{"pair_fast":null,"pair_250":null,"pair_add_fast":null,"pair_add_250":null},"decision_ms":1790000210077,"feature_cutoff_ms":1790000210076,"request_ms":1790000210042,"inventory":{"pair_fast":{"qty":[0.0,0.0],"cash":0.0,"lots":[[],[]],"floor":0.0},"pair_250":{"qty":[0.0,0.0],"cash":0.0,"lots":[[],[]],"floor":0.0},"pair_add_fast":{"qty":[0.0,0.0],"cash":0.0,"lots":[[],[]],"floor":0.0},"pair_add_250":{"qty":[0.0,0.0],"cash":0.0,"lots":[[],[]],"floor":0.0}}}
{"kind":"decision","recorded_ms":1790000220084,"S":1790000100,"age":120,"signal":{},"entry_side":null,"context_gap":"incomplete or stale context","book_errors":[null,null],"books":[{"bid":0.8,"ask":0.81,"asks":[[0.81,683.0]],"received_ms":1790000220082,"observed_ms":1790000220071,"hash":"d5da5d11d36e3916960face84a07102aae520b10"},{"bid":0.19,"ask":0.2,"asks":[[0.2,686.5]],"received_ms":1790000220078,"observed_ms":1790000220070,"hash":"020bd93bd02f0a3f00737a5471914cf48d8ae8a0"}],"intents":{"pair_fast":null,"pair_250":null,"pair_add_fast":null,"pair_add_250":null},"decision_ms":1790000220084,"feature_cutoff_ms":1790000220083,"request_ms":1790000220050,"inventory":{"pair_fast":{"qty":[0.0,0.0],"cash":0.0,"lots":[[],[]],"floor":0.0},"pair_250":{"qty":[0.0,0.0],"cash":0.0,"lots":[[],[]],"floor":0.0},"pair_add_fast":{"qty":[0.0,0.0],"cash":0.0,"lots":[[],[]],"floor":0.0},"pair_add_250":{"qty":[0.0,0.0],"cash":0.0,"lots":[[],[]],"floor":0.0}}}
{"kind":"decision","recorded_ms":1790000230064,"S":1790000100,"age":130,"signal":{"rsi14":46.746983695172055,"volume_ratio":1.717404307845121,"taker_buy_fraction":0.6347531302017273,"volume5":321.72607,"return1":9.543881136193331,"return5":7.7659616554625925,"return15":-6.403553310780073,"bollinger_z":0.7157862019578392,"bar_close_ms":1790000219999,"ref":85288.69659526845,"reference_received_ms":1790000101794,"spot":85421.98172783744,"twap":85351.18815079247,"sigma":7.613318253766618,"spot_z":1.3429620798511097,"twap_z":0.629656044617173,"momentum":0.9172175750135049,"decision_ms":1790000230063,"momentum30":2.1366824337034522,"momentum60":1.7137940954996018,"spot_twap_gap":1.2004504727749914,"range60":1.8801365084368438,"final_mean":85421.98172783744,"final_z":1.5358234903204442,"final_up_prob":0.9377091615743324,"final_drift_up_prob":0.9999998270495687,"final_known_seconds":0,"final_sd":86.7841476634629,"final_drift_shift":309.01453787848055},"entry_side":null,"context_gap":null,"book_errors":[null,null],"books":[{"bid":0.86,"ask":0.87,"asks":[[0.87,1138.02]],"received_ms":1790000230059,"observed_ms":1790000230050,"hash":"feccd543c9284208ad46a5ec6e6fc8c0645c824e"},{"bid":0.13,"ask":0.14,"asks":[[0.14,736.88]],"received_ms":1790000230063,"observed_ms":1790000230053,"hash":"fbd5a8aa3fc1110d022e53efd7a6218fce69e4c7"}],"intents":{"pair_fast":null,"pair_250":null,"pair_add_fast":null,"pair_add_250":null},"decision_ms":1790000230064,"feature_cutoff_ms":1790000230063,"request_ms":1790000230033,"inventory":{"pair_fast":{"qty":[0.0,0.0],"cash":0.0,"lots":[[],[]],"floor":0.0},"pair_250":{"qty":[0.0,0.0],"cash":0.0,"lots":[[],[]],"floor":0.0},"pair_add_fast":{"qty":[0.0,0.0],"cash":0.0,"lots":[[],[]],"floor":0.0},"pair_add_250":{"qty":[0.0,0.0],"cash":0.0,"lots":[[],[]],"floor":0.0}}}
{"kind":"decision","recorded_ms":1790000240098,"S":1790000100,"age":140,"signal":{"rsi14":46.746983695172055,"volume_ratio":1.717404307845121,"taker_buy_fraction":0.6347531302017273,"volume5":321.72607,"return1":9.543881136193331,"return5":7.7659616554625925,"return15":-6.403553310780073,"bollinger_z":0.7157862019578392,"bar_close_ms":1790000219999,"ref":85288.69659526845,"reference_received_ms":1790000101794,"spot":85434.37557058448,"twap":85369.5217863496,"sigma":7.607607064779881,"spot_z":1.5143299051199626,"twap_z":0.8401761728189278,"momentum":0.20065539056738022,"decision_ms":1790000240097,"momentum30":1.8617999085094368,"momentum60":2.079817578870206,"spot_twap_gap":1.1005546778877122,"range60":2.079817578870206,"final_mean":85434.37557058448,"final_z":1.7487743717182618,"final_up_prob":0.959834985757154,"final_drift_up_prob":0.9938171312909234,"final_known_seconds":0,"final_sd":83.30347108923452,"final_drift_shift":62.70729770298402},"entry_side":null,"context_gap":null,"book_errors":[null,null],"books":[{"bid":0.86,"ask":0.87,"asks":[[0.87,1110.76]],"received_ms":1790000240078,"observed_ms":1790000240069,"hash":"61244bcd0bf73141232e2d48aadd49cd9b5ed166"},{"bid":0.13,"ask":0.14,"asks":[[0.14,222.49]],"received_ms":1790000240096,"observed_ms":1790000240064,"hash":"1da43b408f5084800c222d0226c4bf10fb61fa76"}],"intents":{"pair_fast":null,"pair_250":null,"pair_add_fast":null,"pair_add_250":null},"decision_ms":1790000240098,"feature_cutoff_ms":1790000240097,"request_ms":1790000240037,"inventory":{"pair_fast":{"qty":[0.0,0.0],"cash":0.0,"lots":[[],[]],"floor":0.0},"pair_250":{"qty":[0.0,0.0],"cash":0.0,"lots":[[],[]],"floor":0.0},"pair_add_fast":{"qty":[0.0,0.0],"cash":0.0,"lots":[[],[]],"floor":0.0},"pair_add_250":{"qty":[0.0,0.0],"cash":0.0,"lots":[[],[]],"floor":0.0}}}
{"kind":"decision","recorded_ms":1790000250047,"S":1790000100,"age":150,"signal":{"rsi14":46.746983695172055,"volume_ratio":1.717404307845121,"taker_buy_fraction":0.6347531302017273,"volume5":321.72607,"return1":9.543881136193331,"return5":7.7659616554625925,"return15":-6.403553310780073,"bollinger_z":0.7157862019578392,"bar_close_ms":1790000219999,"ref":85288.69659526845,"reference_received_ms":1790000101794,"spot":85440.92015752844,"twap":85385.47405607614,"sigma":7.6211202372387135,"spot_z":1.631112965562268,"twap_z":1.0369943309302596,"momentum":0.7276367661699165,"decision_ms":1790000250046,"momentum30":0.9827092464866697,"momentum60":1.9084177226278873,"spot_twap_gap":0.9392399929500713,"range60":1.9084177226278873,"final_mean":85440.92015752844,"final_z":1.904835826828049,"final_up_prob":0.9715992924091941,"final_drift_up_prob":0.9999971478862276,"final_known_seconds":0,"final_sd":79.91426878686332,"final_drift_shift":210.35274470184893},"entry_side":null,"context_gap":null,"book_errors":[null,null],"books":[{"bid":0.88,"ask":0.89,"asks":[[0.89,328.32]],"received_ms":1790000250043,"observed_ms":1790000250036,"hash":"22d276079248f4e46077cc3ac607b70184653ef8"},{"bid":0.11,"ask":0.12,"asks":[[0.12,622.0]],"received_ms":1790000250046,"observed_ms":1790000250034,"hash":"218fc7fbba7e5b27d636477268bc7f15d511ea40"}],"intents":{"pair_fast":null,"pair_250":null,"pair_add_fast":null,"pair_add_250":null},"decision_ms":1790000250047,"feature_cutoff_ms":1790000250046,"request_ms":1790000250019,"inventory":{"pair_fast":{"qty":[0.0,0.0],"cash":0.0,"lots":[[],[]],"floor":0.0},"pair_250":{"qty":[0.0,0.0],"cash":0.0,"lots":[[],[]],"floor":0.0},"pair_add_fast":{"qty":[0.0,0.0],"cash":0.0,"lots":[[],[]],"floor":0.0},"pair_add_250":{"qty":[0.0,0.0],"cash":0.0,"lots":[[],[]],"floor":0.0}}}
{"kind":"decision","recorded_ms":1790000260053,"S":1790000100,"age":160,"signal":{},"entry_side":null,"context_gap":"incomplete or stale context","book_errors":[null,null],"books":[{"bid":0.84,"ask":0.85,"asks":[[0.85,332.8]],"received_ms":1790000260052,"observed_ms":1790000260040,"hash":"7fde1096c4ce39bcfa151aca5f4dc87d4bab87c5"},{"bid":0.15,"ask":0.16,"asks":[[0.16,424.82]],"received_ms":1790000260048,"observed_ms":1790000260039,"hash":"664cde43d2ea0a09449e4e6a112025163aba876d"}],"intents":{"pair_fast":null,"pair_250":null,"pair_add_fast":null,"pair_add_250":null},"decision_ms":1790000260053,"feature_cutoff_ms":1790000260052,"request_ms":1790000260021,"inventory":{"pair_fast":{"qty":[0.0,0.0],"cash":0.0,"lots":[[],[]],"floor":0.0},"pair_250":{"qty":[0.0,0.0],"cash":0.0,"lots":[[],[]],"floor":0.0},"pair_add_fast":{"qty":[0.0,0.0],"cash":0.0,"lots":[[],[]],"floor":0.0},"pair_add_250":{"qty":[0.0,0.0],"cash":0.0,"lots":[[],[]],"floor":0.0}}}
{"kind":"decision","recorded_ms":1790000270100,"S":1790000100,"age":170,"signal":{"rsi14":46.746983695172055,"volume_ratio":1.717404307845121,"taker_buy_fraction":0.6347531302017273,"volume5":321.72607,"return1":9.543881136193331,"return5":7.7659616554625925,"return15":-6.403553310780073,"bollinger_z":0.7157862019578392,"bar_close_ms":1790000219999,"ref":85288.69659526845,"reference_received_ms":1790000101794,"spot":85391.86680266532,"twap":85411.76323778383,"sigma":7.9091481602722435,"spot_z":1.144506715295952,"twap_z":1.3652255078442068,"momentum":-0.435624048174668,"decision_ms":1790000270099,"momentum30":-0.727541553377764,"momentum60":0.5724371816645863,"spot_twap_gap":-0.32476553438023464,"range60":1.3021760507515199,"final_mean":85391.86680266532,"final_z":1.3757589002245187,"final_up_prob":0.9155518551244346,"final_drift_up_prob":0.4698359635228836,"final_known_seconds":0,"final_sd":74.99148824697822,"final_drift_shift":-108.84572921432024},"entry_side":null,"context_gap":null,"book_errors":[null,null],"books":[{"bid":0.8,"ask":0.81,"asks":[[0.81,755.48]],"received_ms":1790000270073,"observed_ms":1790000270060,"hash":"ad8220453044107215caa0b94b076f9da0a966c3"},{"bid":0.19,"ask":0.2,"asks":[[0.2,339.71]],"received_ms":1790000270099,"observed_ms":1790000270066,"hash":"e05abbb0b3c2f5782660903065421b2eb1193154"}],"intents":{"pair_fast":null,"pair_250":null,"pair_add_fast":null,"pair_add_250":null},"decision_ms":1790000270100,"feature_cutoff_ms":1790000270099,"request_ms":1790000270026,"inventory":{"pair_fast":{"qty":[0.0,0.0],"cash":0.0,"lots":[[],[]],"floor":0.0},"pair_250":{"qty":[0.0,0.0],"cash":0.0,"lots":[[],[]],"floor":0.0},"pair_add_fast":{"qty":[0.0,0.0],"cash":0.0,"lots":[[],[]],"floor":0.0},"pair_add_250":{"qty":[0.0,0.0],"cash":0.0,"lots":[[],[]],"floor":0.0}}}
{"kind":"decision","recorded_ms":1790000280058,"S":1790000100,"age":180,"signal":{"rsi14":46.746983695172055,"volume_ratio":1.717404307845121,"taker_buy_fraction":0.6347531302017273,"volume5":321.72607,"return1":9.543881136193331,"return5":7.7659616554625925,"return15":-6.403553310780073,"bollinger_z":0.7157862019578392,"bar_close_ms":1790000219999,"ref":85288.69659526845,"reference_received_ms":1790000101794,"spot":85370.36472385887,"twap":85412.49771528102,"sigma":6.637497725111767,"spot_z":1.1234681504085111,"twap_z":1.703070925214407,"momentum":-0.10811881543815625,"decision_ms":1790000280057,"momentum30":-1.821170895864606,"momentum60":-0.5744484760672434,"spot_twap_gap":-0.8194874075637171,"range60":1.3355591476505333,"final_mean":85370.36472385887,"final_z":1.3761253574184704,"final_up_prob":0.915608586919807,"final_drift_up_prob":0.8490081434299311,"final_known_seconds":0,"final_sd":59.34643101383163,"final_drift_shift":-20.411411280214995},"entry_side":null,"context_gap":null,"book_errors":[null,null],"books":[{"bid":0.85,"ask":0.86,"asks":[[0.86,2089.52]],"received_ms":1790000280057,"observed_ms":1790000280044,"hash":"d77b52bd073e8a25850da60e316691a2f1588a0a"},{"bid":0.14,"ask":0.15,"asks":[[0.15,45.6]],"received_ms":1790000280053,"observed_ms":1790000280041,"hash":"d8b75384f857745988c151ff9b12cbd5b3058c63"}],"intents":{"pair_fast":null,"pair_250":null,"pair_add_fast":null,"pair_add_250":null},"decision_ms":1790000280058,"feature_cutoff_ms":1790000280057,"request_ms":1790000280021,"inventory":{"pair_fast":{"qty":[0.0,0.0],"cash":0.0,"lots":[[],[]],"floor":0.0},"pair_250":{"qty":[0.0,0.0],"cash":0.0,"lots":[[],[]],"floor":0.0},"pair_add_fast":{"qty":[0.0,0.0],"cash":0.0,"lots":[[],[]],"floor":0.0},"pair_add_250":{"qty":[0.0,0.0],"cash":0.0,"lots":[[],[]],"floor":0.0}}}
{"kind":"decision","recorded_ms":1790000290048,"S":1790000100,"age":190,"signal":{"rsi14":53.359815298375416,"volume_ratio":0.7728578796286009,"taker_buy_fraction":0.6384731968446247,"volume5":313.37635,"return1":-3.0956381241185014,"return5":18.397035493294695,"return15":-11.719870507725142,"bollinger_z":0.6476264749229066,"bar_close_ms":1790000279999,"ref":85288.69659526845,"reference_received_ms":1790000101794,"spot":85362.57328687308,"twap":85406.55425950239,"sigma":6.202146531952029,"spot_z":1.1359569523361959,"twap_z":1.812225617643253,"momentum":-0.7261305156191281,"decision_ms":1790000290047,"momentum30":-1.183050274013095,"momentum60":-1.3941045894914632,"spot_twap_gap":-0.9154764599952213,"range60":1.5403359807566535,"final_mean":85362.57328687308,"final_z":1.4241713449013862,"final_up_prob":0.9228015611459446,"final_drift_up_prob":0.2203866390368267,"final_known_seconds":0,"final_sd":51.87345741024243,"final_drift_shift":-113.86532115463194},"entry_side":null,"context_gap":null,"book_errors":[null,null],"books":[{"bid":0.82,"ask":0.83,"asks":[[0.83,427.95]],"received_ms":1790000290047,"observed_ms":1790000290036,"hash":"7a2130f67f4bde7fb7bfb32c53ab3f85960a471b"},{"bid":0.17,"ask":0.18,"asks":[[0.18,366.33]],"received_ms":1790000290047,"observed_ms":1790000290034,"hash":"3c7eeda784f4a9aee22ddd680f51b88e5611a4ab"}],"intents":{"pair_fast":null,"pair_250":null,"pair_add_fast":null,"pair_add_250":null},"decision_ms":1790000290048,"feature_cutoff_ms":1790000290047,"request_ms":1790000290010,"inventory":{"pair_fast":{"qty":[0.0,0.0],"cash":0.0,"lots":[[],[]],"floor":0.0},"pair_250":{"qty":[0.0,0.0],"cash":0.0,"lots":[[],[]],"floor":0.0},"pair_add_fast":{"qty":[0.0,0.0],"cash":0.0,"lots":[[],[]],"floor":0.0},"pair_add_250":{"qty":[0.0,0.0],"cash":0.0,"lots":[[],[]],"floor":0.0}}}
{"kind":"decision","recorded_ms":1790000300072,"S":1790000100,"age":200,"signal":{},"entry_side":null,"context_gap":"incomplete or stale context","book_errors":[null,null],"books":[{"bid":0.92,"ask":0.93,"asks":[[0.93,1160.24]],"received_ms":1790000300057,"observed_ms":1790000300043,"hash":"b2b6e50c88291cbe720ee8aadc905284018fcfa0"},{"bid":0.07,"ask":0.08,"asks":[[0.08,239.66]],"received_ms":1790000300071,"observed_ms":1790000300057,"hash":"34fdbc7c8f39215dca30be33acd493fc8be7e09b"}],"intents":{"pair_fast":null,"pair_250":null,"pair_add_fast":null,"pair_add_250":null},"decision_ms":1790000300072,"feature_cutoff_ms":1790000300071,"request_ms":1790000300022,"inventory":{"pair_fast":{"qty":[0.0,0.0],"cash":0.0,"lots":[[],[]],"floor":0.0},"pair_250":{"qty":[0.0,0.0],"cash":0.0,"lots":[[],[]],"floor":0.0},"pair_add_fast":{"qty":[0.0,0.0],"cash":0.0,"lots":[[],[]],"floor":0.0},"pair_add_250":{"qty":[0.0,0.0],"cash":0.0,"lots":[[],[]],"floor":0.0}}}
{"kind":"decision","recorded_ms":1790000310076,"S":1790000100,"age":210,"signal":{"rsi14":53.359815298375416,"volume_ratio":0.7728578796286009,"taker_buy_fraction":0.6384731968446247,"volume5":313.37635,"return1":-3.0956381241185014,"return5":18.397035493294695,"return15":-11.719870507725142,"bollinger_z":0.6476264749229066,"bar_close_ms":1790000279999,"ref":85288.69659526845,"reference_received_ms":1790000101794,"spot":85399.11606117898,"twap":85390.89946685046,"sigma":7.0756645676745045,"spot_z":1.645652684935341,"twap_z":1.5231954677566875,"momentum":0.08866266771984403,"decision_ms":1790000310075,"momentum30":0.5754415168063094,"momentum60":-0.6834322822694596,"spot_twap_gap":0.1499163444533095,"range60":1.326815298399345,"final_mean":85399.11606117898,"final_z":2.2086117038539252,"final_up_prob":0.9863991697096703,"final_drift_up_prob":0.9927854516841788,"final_known_seconds":0,"final_sd":49.99496548798055,"final_drift_shift":11.888199187574621},"entry_side":null,"context_gap":null,"book_errors":[null,null],"books":[{"bid":0.91,"ask":0.92,"asks":[[0.92,50.0]],"received_ms":1790000310074,"observed_ms":1790000310064,"hash":"9f903e14a9e2c0d3c89e366d6b034ff9d09bdab0"},{"bid":0.08,"ask":0.09,"asks":[[0.09,576.71]],"received_ms":1790000310075,"observed_ms":1790000310064,"hash":"9aa3ba0dca467732cb850ea4d134d801d6f468ce"}],"intents":{"pair_fast":null,"pair_250":null,"pair_add_fast":null,"pair_add_250":null},"decision_ms":1790000310076,"feature_cutoff_ms":1790000310075,"request_ms":1790000310046,"inventory":{"pair_fast":{"qty":[0.0,0.0],"cash":0.0,"lots":[[],[]],"floor":0.0},"pair_250":{"qty":[0.0,0.0],"cash":0.0,"lots":[[],[]],"floor":0.0},"pair_add_fast":{"qty":[0.0,0.0],"cash":0.0,"lots":[[],[]],"floor":0.0},"pair_add_250":{"qty":[0.0,0.0],"cash":0.0,"lots":[[],[]],"floor":0.0}}}
{"kind":"decision","recorded_ms":1790000320045,"S":1790000100,"age":220,"signal":{"rsi14":53.359815298375416,"volume_ratio":0.7728578796286009,"taker_buy_fraction":0.6384731968446247,"volume5":313.37635,"return1":-3.0956381241185014,"return5":18.397035493294695,"return15":-11.719870507725142,"bollinger_z":0.6476264749229066,"bar_close_ms":1790000279999,"ref":85288.69659526845,"reference_received_ms":1790000101794,"spot":85368.17869058892,"twap":85384.0289697528,"sigma":6.636903068488457,"spot_z":1.3393097149445228,"twap_z":1.6063941794794527,"momentum":-0.9915346842936982,"decision_ms":1790000320045,"momentum30":0.11897829552505937,"momentum60":-0.6727093817111309,"spot_twap_gap":-0.3083158244189076,"range60":0.8261659634507698,"final_mean":85368.17869058892,"final_z":1.894603196085542,"final_up_prob":0.9709275044705232,"final_drift_up_prob":0.2798130965212454,"final_known_seconds":0,"final_sd":41.95184273133308,"final_drift_shift":-103.95666727570475},"entry_side":null,"context_gap":null,"book_errors":[null,null],"books":[{"bid":0.91,"ask":0.92,"asks":[[0.92,579.68]],"received_ms":1790000320028,"observed_ms":1790000320014,"hash":"8a43223c90e95a8dd0a68324227e3d68cf21b5ee"},{"bid":0.08,"ask":0.09,"asks":[[0.09,1051.96]],"received_ms":1790000320044,"observed_ms":1790000320033,"hash":"3c7fbaa1fb1c2bed305e713564664fbbfa0a4e31"}],"intents":{"pair_fast":null,"pair_250":null,"pair_add_fast":null,"pair_add_250":null},"decision_ms":1790000320045,"feature_cutoff_ms":1790000320045,"request_ms":1790000320001,"inventory":{"pair_fast":{"qty":[0.0,0.0],"cash":0.0,"lots":[[],[]],"floor":0.0},"pair_250":{"qty":[0.0,0.0],"cash":0.0,"lots":[[],[]],"floor":0.0},"pair_add_fast":{"qty":[0.0,0.0],"cash":0.0,"lots":[[],[]],"floor":0.0},"pair_add_250":{"qty":[0.0,0.0],"cash":0.0,"lots":[[],[]],"floor":0.0}}}
{"kind":"decision","recorded_ms":1790000330055,"S":1790000100,"age":230,"signal":{"rsi14":53.359815298375416,"volume_ratio":0.7728578796286009,"taker_buy_fraction":0.6384731968446247,"volume5":313.37635,"return1":-3.0956381241185014,"return5":18.397035493294695,"return15":-11.719870507725142,"bollinger_z":0.6476264749229066,"bar_close_ms":1790000279999,"ref":85288.69659526845,"reference_received_ms":1790000101794,"spot":85361.30368769937,"twap":85378.28855536589,"sigma":5.294399314433311,"spot_z":1.6397623481204808,"twap_z":2.023349482033836,"momentum":-0.44835029203578275,"decision_ms":1790000330054,"momentum30":-1.2355252755890704,"momentum60":-0.27628240671038906,"spot_twap_gap":-0.41416161811225166,"range60":1.016179076940632,"final_mean":85361.30368769937,"final_z":2.506068520643525,"final_up_prob":0.9938959020550722,"final_drift_up_prob":0.9293698297881456,"final_known_seconds":0,"final_sd":28.972508865109734,"final_drift_shift":-29.985234479928316},"entry_side":null,"context_gap":null,"book_errors":[null,null],"books":[{"bid":0.88,"ask":0.89,"asks":[[0.89,27.0]],"received_ms":1790000330052,"observed_ms":1790000330044,"hash":"38fdb6d072a915a7114238cbb39ad101561b2466"},{"bid":0.11,"ask":0.12,"asks":[[0.12,518.91]],"received_ms":1790000330054,"observed_ms":1790000330043,"hash":"714ba8abd32dc5f97c721e0b6c205e3da3af6cc3"}],"intents":{"pair_fast":null,"pair_250":null,"pair_add_fast":null,"pair_add_250":null},"decision_ms":1790000330055,"feature_cutoff_ms":1790000330054,"request_ms":1790000330021,"inventory":{"pair_fast":{"qty":[0.0,0.0],"cash":0.0,"lots":[[],[]],"floor":0.0},"pair_250":{"qty":[0.0,0.0],"cash":0.0,"lots":[[],[]],"floor":0.0},"pair_add_fast":{"qty":[0.0,0.0],"cash":0.0,"lots":[[],[]],"floor":0.0},"pair_add_250":{"qty":[0.0,0.0],"cash":0.0,"lots":[[],[]],"floor":0.0}}}
{"kind":"decision","recorded_ms":1790000340065,"S":1790000100,"age":240,"signal":{"rsi14":53.359815298375416,"volume_ratio":0.7728578796286009,"taker_buy_fraction":0.6384731968446247,"volume5":313.37635,"return1":-3.0956381241185014,"return5":18.397035493294695,"return15":-11.719870507725142,"bollinger_z":0.6476264749229066,"bar_close_ms":1790000279999,"ref":85288.69659526845,"reference_received_ms":1790000101794,"spot":85353.08659534047,"twap":85375.0011306381,"sigma":5.7960692070608495,"spot_z":1.434963931075841,"twap_z":1.923340506370477,"momentum":0.17682234321153514,"decision_ms":1790000340064,"momentum30":-1.1309056179907353,"momentum60":-0.5285134425790645,"spot_twap_gap":-0.488116038735442,"range60":1.1834370680522213,"final_mean":85353.08659534047,"final_z":2.488084387824105,"final_up_prob":0.9935783373012076,"final_drift_up_prob":0.9979016221323824,"final_known_seconds":0,"final_sd":25.879347335291786,"final_drift_shift":9.702082669061303},"entry_side":null,"context_gap":null,"book_errors":[null,null],"books":[{"bid":0.93,"ask":0.94,"asks":[[0.94,344.22]],"received_ms":1790000340063,"observed_ms":1790000340055,"hash":"93112059076b3b81aaaf1f270c7bcf639cf81afc"},{"bid":0.06,"ask":0.07,"asks":[[0.07,86.0]],"received_ms":1790000340063,"observed_ms":1790000340054,"hash":"b5233f471b4c541ab44b93946ab3c78e3e287c77"}],"intents":{"pair_fast":null,"pair_250":null,"pair_add_fast":null,"pair_add_250":null},"decision_ms":1790000340065,"feature_cutoff_ms":1790000340064,"request_ms":1790000340027,"inventory":{"pair_fast":{"qty":[0.0,0.0],"cash":0.0,"lots":[[],[]],"floor":0.0},"pair_250":{"qty":[0.0,0.0],"cash":0.0,"lots":[[],[]],"floor":0.0},"pair_add_fast":{"qty":[0.0,0.0],"cash":0.0,"lots":[[],[]],"floor":0.0},"pair_add_250":{"qty":[0.0,0.0],"cash":0.0,"lots":[[],[]],"floor":0.0}}}
{"kind":"decision","recorded_ms":1790000350044,"S":1790000100,"age":250,"signal":{"rsi14":54.11545776159989,"volume_ratio":0.6556559671430722,"taker_buy_fraction":0.6218251222498264,"volume5":296.04132,"return1":-3.5699218622806512,"return5":14.027872094666185,"return15":4.236354125941673,"bollinger_z":0.46404680835139184,"bar_close_ms":1790000339999,"ref":85288.69659526845,"reference_received_ms":1790000101794,"spot":85349.21258223648,"twap":85371.05871878969,"sigma":5.768208212887464,"spot_z":1.4843318856901495,"twap_z":2.0201723914760135,"momentum":-0.059668897786030475,"decision_ms":1790000350043,"momentum30":-0.620297706816715,"momentum60":-0.3276839095095648,"spot_twap_gap":-0.488942839364051,"range60":1.3126002370764087,"final_mean":85348.94792307018,"final_z":3.074277351451424,"final_up_prob":0.9989449341958261,"final_drift_up_prob":0.9984556960479348,"final_known_seconds":10,"final_sd":19.59853354586984,"final_drift_shift":-2.263603720847934},"entry_side":null,"context_gap":null,"book_errors":[null,null],"books":[{"bid":0.97,"ask":0.98,"asks":[[0.98,657.86]],"received_ms":1790000350043,"observed_ms":1790000350033,"hash":"6029210c0799c8f9b074f5aca7901a4a8c365d92"},{"bid":0.02,"ask":0.03,"asks":[[0.03,1207.0]],"received_ms":1790000350035,"observed_ms":1790000350028,"hash":"e689e20fec917213444a228659b2186e4148bda3"}],"intents":{"pair_fast":null,"pair_250":null,"pair_add_fast":null,"pair_add_250":null},"decision_ms":1790000350044,"feature_cutoff_ms":1790000350043,"request_ms":1790000350011,"inventory":{"pair_fast":{"qty":[0.0,0.0],"cash":0.0,"lots":[[],[]],"floor":0.0},"pair_250":{"qty":[0.0,0.0],"cash":0.0,"lots":[[],[]],"floor":0.0},"pair_add_fast":{"qty":[0.0,0.0],"cash":0.0,"lots":[[],[]],"floor":0.0},"pair_add_250":{"qty":[0.0,0.0],"cash":0.0,"lots":[[],[]],"floor":0.0}}}
{"kind":"decision","recorded_ms":1790000360053,"S":1790000100,"age":260,"signal":{"rsi14":54.11545776159989,"volume_ratio":0.6556559671430722,"taker_buy_fraction":0.6218251222498264,"volume5":296.04132,"return1":-3.5699218622806512,"return5":14.027872094666185,"return15":4.236354125941673,"bollinger_z":0.46404680835139184,"bar_close_ms":1790000339999,"ref":85288.69659526845,"reference_received_ms":1790000101794,"spot":85375.42136585532,"twap":85370.47146152105,"sigma":5.40048644035926,"spot_z":2.5407548270326976,"twap_z":2.3957386656115625,"momentum":1.4245413343990476,"decision_ms":1790000360052,"momentum30":0.8646376923412653,"momentum60":-0.5190011274687485,"spot_twap_gap":0.11832821150246728,"range60":1.401975831502782,"final_mean":85370.10125192048,"final_z":6.204198517079459,"final_up_prob":0.9999999997251182,"final_drift_up_prob":1.0,"final_known_seconds":20,"final_sd":13.120898118899422,"final_drift_shift":32.35316484586493},"entry_side":null,"context_gap":null,"book_errors":[null,null],"books":[{"bid":0.99,"ask":null,"asks":[],"received_ms":1790000360052,"observed_ms":1790000360045,"hash":"bdba3328807b9fd69211348c193044a327fbf681"},{"bid":null,"ask":0.01,"asks":[[0.01,9498.07]],"received_ms":1790000360049,"observed_ms":1790000360033,"hash":"09dd1fdd4a89bb671cfcc46b4b2813b7ad8e9368"}],"intents":{"pair_fast":null,"pair_250":null,"pair_add_fast":null,"pair_add_250":null},"decision_ms":1790000360053,"feature_cutoff_ms":1790000360052,"request_ms":1790000360018,"inventory":{"pair_fast":{"qty":[0.0,0.0],"cash":0.0,"lots":[[],[]],"floor":0.0},"pair_250":{"qty":[0.0,0.0],"cash":0.0,"lots":[[],[]],"floor":0.0},"pair_add_fast":{"qty":[0.0,0.0],"cash":0.0,"lots":[[],[]],"floor":0.0},"pair_add_250":{"qty":[0.0,0.0],"cash":0.0,"lots":[[],[]],"floor":0.0}}}
{"kind":"decision","recorded_ms":1790000370062,"S":1790000100,"age":270,"signal":{"rsi14":54.11545776159989,"volume_ratio":0.6556559671430722,"taker_buy_fraction":0.6218251222498264,"volume5":296.04132,"return1":-3.5699218622806512,"return5":14.027872094666185,"return15":4.236354125941673,"bollinger_z":0.46404680835139184,"bar_close_ms":1790000339999,"ref":85288.69659526845,"reference_received_ms":1790000101794,"spot":85344.65690891427,"twap":85366.20498129314,"sigma":5.705572368088686,"spot_z":1.792512848772045,"twap_z":2.4827376543342465,"momentum":-1.1876052326697304,"decision_ms":1790000370061,"momentum30":-0.1806062938433219,"momentum60":-1.003092434819271,"spot_twap_gap":-0.4875661901627917,"range60":1.0104893718194197,"final_mean":85351.53754955601,"final_z":6.987140848962717,"final_up_prob":0.9999999999985973,"final_drift_up_prob":0.9999999043222912,"final_known_seconds":30,"final_sd":8.993800990413531,"final_drift_shift":-16.005330704347895},"entry_side":null,"context_gap":null,"book_errors":[null,null],"books":[{"bid":0.99,"ask":null,"asks":[],"received_ms":1790000370060,"observed_ms":1790000370044,"hash":"a67a4a1805d70f95eebb313bb3e91200a4349780"},{"bid":null,"ask":0.01,"asks":[[0.01,17979.35]],"received_ms":1790000370061,"observed_ms":1790000370044,"hash":"ab70f5ab1c55a26aaa5eece57ed6aff91cf6e007"}],"intents":{"pair_fast":null,"pair_250":null,"pair_add_fast":null,"pair_add_250":null},"decision_ms":1790000370062,"feature_cutoff_ms":1790000370061,"request_ms":1790000370027,"inventory":{"pair_fast":{"qty":[0.0,0.0],"cash":0.0,"lots":[[],[]],"floor":0.0},"pair_250":{"qty":[0.0,0.0],"cash":0.0,"lots":[[],[]],"floor":0.0},"pair_add_fast":{"qty":[0.0,0.0],"cash":0.0,"lots":[[],[]],"floor":0.0},"pair_add_250":{"qty":[0.0,0.0],"cash":0.0,"lots":[[],[]],"floor":0.0}}}
{"kind":"decision","recorded_ms":1790000380068,"S":1790000100,"age":280,"signal":{"rsi14":54.11545776159989,"volume_ratio":0.6556559671430722,"taker_buy_fraction":0.6218251222498264,"volume5":296.04132,"return1":-3.5699218622806512,"return5":14.027872094666185,"return15":4.236354125941673,"bollinger_z":0.46404680835139184,"bar_close_ms":1790000339999,"ref":85288.69659526845,"reference_received_ms":1790000101794,"spot":85371.84341446383,"twap":85360.10290362833,"sigma":5.842620122654936,"spot_z":3.1875107296907457,"twap_z":2.7374273155281883,"momentum":1.2574746809782809,"decision_ms":1790000380067,"momentum30":0.6484143721838308,"momentum60":0.06702392633469943,"spot_twap_gap":0.2594201573226285,"range60":0.6636403246439937,"final_mean":85363.50531471842,"final_z":14.95193654679246,"final_up_prob":1.0,"final_drift_up_prob":1.0,"final_known_seconds":40,"final_sd":5.0032796230676775,"final_drift_shift":7.692561744371518},"entry_side":null,"context_gap":null,"book_errors":[null,null],"books":[{"bid":0.99,"ask":null,"asks":[],"received_ms":1790000380066,"observed_ms":1790000380054,"hash":"af4d60d299c87da213200b36162e74e688f6e68b"},{"bid":null,"ask":0.01,"asks":[[0.01,40269.57]],"received_ms":1790000380063,"observed_ms":1790000380052,"hash":"2d82819ebbb5acf6fb04412b7fdc86f2ca5ba957"}],"intents":{"pair_fast":null,"pair_250":null,"pair_add_fast":null,"pair_add_250":null},"decision_ms":1790000380068,"feature_cutoff_ms":1790000380067,"request_ms":1790000380036,"inventory":{"pair_fast":{"qty":[0.0,0.0],"cash":0.0,"lots":[[],[]],"floor":0.0},"pair_250":{"qty":[0.0,0.0],"cash":0.0,"lots":[[],[]],"floor":0.0},"pair_add_fast":{"qty":[0.0,0.0],"cash":0.0,"lots":[[],[]],"floor":0.0},"pair_add_250":{"qty":[0.0,0.0],"cash":0.0,"lots":[[],[]],"floor":0.0}}}
{"kind":"decision","recorded_ms":1790000390100,"S":1790000100,"age":290,"signal":{"rsi14":54.11545776159989,"volume_ratio":0.6556559671430722,"taker_buy_fraction":0.6218251222498264,"volume5":296.04132,"return1":-3.5699218622806512,"return5":14.027872094666185,"return15":4.236354125941673,"bollinger_z":0.46404680835139184,"bar_close_ms":1790000339999,"ref":85288.69659526845,"reference_received_ms":1790000101794,"spot":85365.53727509282,"twap":85359.31870936911,"sigma":4.923617260714404,"spot_z":4.95983675029898,"twap_z":4.558446876066738,"momentum":0.30845613226550955,"decision_ms":1790000390099,"momentum30":-0.02028810474929714,"momentum60":0.4114412261119028,"spot_twap_gap":0.16305357226828204,"range60":0.7875100987048802,"final_mean":85360.99042074742,"final_z":48.97903297371736,"final_up_prob":1.0,"final_drift_up_prob":1.0,"final_known_seconds":50,"final_sd":1.4760157783792094,"final_drift_shift":0.3923327579200798},"entry_side":null,"context_gap":null,"book_errors":[null,null],"books":[{"bid":0.99,"ask":null,"asks":[],"received_ms":1790000390099,"observed_ms":1790000390073,"hash":"44be01c36bfc5ea37abb939a938c88c53b4ce72d"},{"bid":null,"ask":0.01,"asks":[[0.01,52493.78]],"received_ms":1790000390080,"observed_ms":1790000390069,"hash":"2bee5030cff9febeec1ec152f14ad485d84f797d"}],"intents":{"pair_fast":null,"pair_250":null,"pair_add_fast":null,"pair_add_250":null},"decision_ms":1790000390100,"feature_cutoff_ms":1790000390099,"request_ms":1790000390040,"inventory":{"pair_fast":{"qty":[0.0,0.0],"cash":0.0,"lots":[[],[]],"floor":0.0},"pair_250":{"qty":[0.0,0.0],"cash":0.0,"lots":[[],[]],"floor":0.0},"pair_add_fast":{"qty":[0.0,0.0],"cash":0.0,"lots":[[],[]],"floor":0.0},"pair_add_250":{"qty":[0.0,0.0],"cash":0.0,"lots":[[],[]],"floor":0.0}}}
{"kind":"decision","recorded_ms":1790000430102,"S":1790000400,"age":30,"signal":{"rsi14":70.6275351944647,"volume_ratio":0.5536296380239439,"taker_buy_fraction":0.6322631739499338,"volume5":262.77768,"return1":3.879964164772667,"return5":10.69390243845287,"return15":13.304741330258642,"bollinger_z":0.783282181776199,"bar_close_ms":1790000399999,"ref":85361.48203450121,"reference_received_ms":1790000400918,"spot":85412.2057646431,"twap":85381.2033712429,"sigma":4.497712752836205,"spot_z":0.6864656808376908,"twap_z":0.26689718629798537,"momentum":0.7309711228450791,"decision_ms":1790000430101,"momentum30":1.5084380643236204,"momentum60":1.825402366687701,"spot_twap_gap":0.8898726970048302,"range60":1.825402366687701,"final_mean":85412.2057646431,"final_z":0.7437910130484771,"final_up_prob":0.771498541036806,"final_drift_up_prob":0.9999946145053762,"final_known_seconds":0,"final_sd":68.19621271571839,"final_drift_shift":249.4137393665176},"entry_side":null,"context_gap":null,"book_errors":[null,null],"books":[{"bid":0.61,"ask":0.62,"asks":[[0.62,576.31]],"received_ms":1790000430101,"observed_ms":1790000430086,"hash":"0ab82bd3fa7e202c426d6c81cb442c220736e301"},{"bid":0.38,"ask":0.39,"asks":[[0.39,608.98]],"received_ms":1790000430076,"observed_ms":1790000430065,"hash":"82c27d0fb7c76464318f58acc7c82114e2c4a8e0"}],"intents":{"pair_fast":null,"pair_250":null,"pair_add_fast":null,"pair_add_250":null},"decision_ms":1790000430102,"feature_cutoff_ms":1790000430101,"request_ms":1790000430050,"inventory":{"pair_fast":{"qty":[0.0,0.0],"cash":0.0,"lots":[[],[]],"floor":0.0},"pair_250":{"qty":[0.0,0.0],"cash":0.0,"lots":[[],[]],"floor":0.0},"pair_add_fast":{"qty":[0.0,0.0],"cash":0.0,"lots":[[],[]],"floor":0.0},"pair_add_250":{"qty":[0.0,0.0],"cash":0.0,"lots":[[],[]],"floor":0.0}}}
{"kind":"decision","recorded_ms":1790000440075,"S":1790000400,"age":40,"signal":{"rsi14":70.6275351944647,"volume_ratio":0.5536296380239439,"taker_buy_fraction":0.6322631739499338,"volume5":262.77768,"return1":3.879964164772667,"return5":10.69390243845287,"return15":13.304741330258642,"bollinger_z":0.783282181776199,"bar_close_ms":1790000399999,"ref":85361.48203450121,"reference_received_ms":1790000400918,"spot":85385.36663998828,"twap":85389.94754732723,"sigma":4.645051030475383,"spot_z":0.31893539616055117,"twap_z":0.3801050687228681,"momentum":-1.7875792482382271,"decision_ms":1790000440074,"momentum30":-0.8655543252867833,"momentum60":0.6845941621109735,"spot_twap_gap":-0.12731670558540856,"range60":1.414370334272907,"final_mean":85385.36663998828,"final_z":0.3467283037196745,"final_up_prob":0.6356022777520645,"final_drift_up_prob":0.0,"final_known_seconds":0,"final_sd":68.88565263012633,"final_drift_shift":-603.7315585389026},"entry_side":1,"context_gap":null,"book_errors":[null,null],"books":[{"bid":0.56,"ask":0.57,"asks":[[0.57,192.87]],"received_ms":1790000440054,"observed_ms":1790000440045,"hash":"608f1ee5c0f8b2183da3c31f9a3f20b9fe1bb258"},{"bid":0.43,"ask":0.44,"asks":[[0.44,1105.32]],"received_ms":1790000440074,"observed_ms":1790000440060,"hash":"848f32db9f5715a0b6b1033fa04887ba7672e971"}],"intents":{"pair_fast":{"kind":"first","side":1,"qty":5.0,"max_cost":2.33624},"pair_250":{"kind":"first","side":1,"qty":5.0,"max_cost":2.33624},"pair_add_fast":{"kind":"first","side":1,"qty":5.0,"max_cost":2.33624},"pair_add_250":{"kind":"first","side":1,"qty":5.0,"max_cost":2.33624}},"decision_ms":1790000440075,"feature_cutoff_ms":1790000440074,"request_ms":1790000440024,"inventory":{"pair_fast":{"qty":[0.0,0.0],"cash":0.0,"lots":[[],[]],"floor":0.0},"pair_250":{"qty":[0.0,0.0],"cash":0.0,"lots":[[],[]],"floor":0.0},"pair_add_fast":{"qty":[0.0,0.0],"cash":0.0,"lots":[[],[]],"floor":0.0},"pair_add_250":{"qty":[0.0,0.0],"cash":0.0,"lots":[[],[]],"floor":0.0}}}
{"kind":"decision","recorded_ms":1790000580074,"S":1790000400,"age":180,"signal":{},"entry_side":null,"context_gap":"incomplete or stale context","book_errors":[null,null],"books":[{"bid":0.99,"ask":null,"asks":[],"received_ms":1790000580073,"observed_ms":1790000580060,"hash":"5326624c8cd06f44b4d6c78cd180936978c3b91c"},{"bid":null,"ask":0.01,"asks":[[0.01,1746.1]],"received_ms":1790000580069,"observed_ms":1790000580053,"hash":"e256cbc38096e0a55dd5e56745488523df8afef6"}],"intents":{"pair_fast":null,"pair_250":null,"pair_add_fast":null,"pair_add_250":null},"decision_ms":1790000580074,"feature_cutoff_ms":1790000580073,"request_ms":1790000580029,"inventory":{"pair_fast":{"qty":[5.0,10.0],"cash":6.40267,"lots":[[],[[5.0,0.37612799999999996]]],"floor":-1.4026699999999996},"pair_250":{"qty":[5.0,10.0],"cash":6.3005700000000004,"lots":[[],[[5.0,0.355708]]],"floor":-1.3005700000000004},"pair_add_fast":{"qty":[5.0,10.0],"cash":6.40267,"lots":[[],[[5.0,0.37612799999999996]]],"floor":-1.4026699999999996},"pair_add_250":{"qty":[5.0,10.0],"cash":6.3005700000000004,"lots":[[],[[5.0,0.355708]]],"floor":-1.3005700000000004}}}
{"kind":"decision","recorded_ms":1790000590081,"S":1790000400,"age":190,"signal":{},"entry_side":null,"context_gap":"incomplete or stale context","book_errors":[null,null],"books":[{"bid":0.99,"ask":null,"asks":[],"received_ms":1790000590053,"observed_ms":1790000590036,"hash":"a7118973d19ffb73b6e6b96a20095d1ca22e304f"},{"bid":null,"ask":0.01,"asks":[[0.01,9179.02]],"received_ms":1790000590080,"observed_ms":1790000590063,"hash":"b93ca2b67781452dfeefb358da698d7e5d068c46"}],"intents":{"pair_fast":null,"pair_250":null,"pair_add_fast":null,"pair_add_250":null},"decision_ms":1790000590081,"feature_cutoff_ms":1790000590080,"request_ms":1790000590020,"inventory":{"pair_fast":{"qty":[5.0,10.0],"cash":6.40267,"lots":[[],[[5.0,0.37612799999999996]]],"floor":-1.4026699999999996},"pair_250":{"qty":[5.0,10.0],"cash":6.3005700000000004,"lots":[[],[[5.0,0.355708]]],"floor":-1.3005700000000004},"pair_add_fast":{"qty":[5.0,10.0],"cash":6.40267,"lots":[[],[[5.0,0.37612799999999996]]],"floor":-1.4026699999999996},"pair_add_250":{"qty":[5.0,10.0],"cash":6.3005700000000004,"lots":[[],[[5.0,0.355708]]],"floor":-1.3005700000000004}}}
{"kind":"decision","recorded_ms":1790000600032,"S":1790000400,"age":200,"signal":{},"entry_side":null,"context_gap":"incomplete or stale context","book_errors":[null,null],"books":[{"bid":0.99,"ask":null,"asks":[],"received_ms":1790000600029,"observed_ms":1790000600010,"hash":"d470333d5bb8c828a67cc2e9aef7ab78cbc19d8f"},{"bid":null,"ask":0.01,"asks":[[0.01,2177.6]],"received_ms":1790000600030,"observed_ms":1790000600010,"hash":"bf75eb0cdd03d6416279b93e19f17d17ac8e326c"}],"intents":{"pair_fast":null,"pair_250":null,"pair_add_fast":null,"pair_add_250":null},"decision_ms":1790000600031,"feature_cutoff_ms":1790000600031,"request_ms":1790000600002,"inventory":{"pair_fast":{"qty":[5.0,10.0],"cash":6.40267,"lots":[[],[[5.0,0.37612799999999996]]],"floor":-1.4026699999999996},"pair_250":{"qty":[5.0,10.0],"cash":6.3005700000000004,"lots":[[],[[5.0,0.355708]]],"floor":-1.3005700000000004},"pair_add_fast":{"qty":[5.0,10.0],"cash":6.40267,"lots":[[],[[5.0,0.37612799999999996]]],"floor":-1.4026699999999996},"pair_add_250":{"qty":[5.0,10.0],"cash":6.3005700000000004,"lots":[[],[[5.0,0.355708]]],"floor":-1.3005700000000004}}}
{"kind":"decision","recorded_ms":1790000610051,"S":1790000400,"age":210,"signal":{},"entry_side":null,"context_gap":"incomplete or stale context","book_errors":[null,null],"books":[{"bid":0.99,"ask":null,"asks":[],"received_ms":1790000610049,"observed_ms":1790000610039,"hash":"87242594a15f906f05aedf012c23690565c43b41"},{"bid":null,"ask":0.01,"asks":[[0.01,4622.61]],"received_ms":1790000610030,"observed_ms":1790000610022,"hash":"a3d46983c518ebf121ba78c3e5c9598be0063ddc"}],"intents":{"pair_fast":null,"pair_250":null,"pair_add_fast":null,"pair_add_250":null},"decision_ms":1790000610051,"feature_cutoff_ms":1790000610049,"request_ms":1790000610002,"inventory":{"pair_fast":{"qty":[5.0,10.0],"cash":6.40267,"lots":[[],[[5.0,0.37612799999999996]]],"floor":-1.4026699999999996},"pair_250":{"qty":[5.0,10.0],"cash":6.3005700000000004,"lots":[[],[[5.0,0.355708]]],"floor":-1.3005700000000004},"pair_add_fast":{"qty":[5.0,10.0],"cash":6.40267,"lots":[[],[[5.0,0.37612799999999996]]],"floor":-1.4026699999999996},"pair_add_250":{"qty":[5.0,10.0],"cash":6.3005700000000004,"lots":[[],[[5.0,0.355708]]],"floor":-1.3005700000000004}}}
{"kind":"decision","recorded_ms":1790000620065,"S":1790000400,"age":220,"signal":{"rsi14":74.2579735300491,"volume_ratio":0.6392870468885787,"taker_buy_fraction":0.6437088015000301,"volume5":118.09896,"return1":24.213499165907784,"return5":26.586272618123484,"return15":60.49521370024357,"bollinger_z":2.6057781820059756,"bar_close_ms":1790000579999,"ref":85361.48203450121,"reference_received_ms":1790000400918,"spot":85657.19227418928,"twap":85621.48477102087,"sigma":9.47991048407224,"spot_z":3.4889192694726208,"twap_z":3.067626466083648,"momentum":0.2764231385472413,"decision_ms":1790000620064,"momentum30":-0.3134183969954746,"momentum60":1.3578192132552573,"spot_twap_gap":0.48627240147554235,"range60":1.586194791004132,"final_mean":85657.19227418928,"final_z":4.936053343366591,"final_up_prob":0.999999601403443,"final_drift_up_prob":0.9999999908197377,"final_known_seconds":0,"final_sd":59.908234193915526,"final_drift_shift":41.38018066150714},"entry_side":null,"context_gap":null,"book_errors":[null,null],"books":[{"bid":0.99,"ask":null,"asks":[],"received_ms":1790000620054,"observed_ms":1790000620025,"hash":"44d599a6f5ce0e577472d3569560b640363c9feb"},{"bid":null,"ask":0.01,"asks":[[0.01,8795.42]],"received_ms":1790000620064,"observed_ms":1790000620025,"hash":"d8b72db242fd1bd4efd6150d8f5a8182c6d94d89"}],"intents":{"pair_fast":null,"pair_250":null,"pair_add_fast":null,"pair_add_250":null},"decision_ms":1790000620065,"feature_cutoff_ms":1790000620064,"request_ms":1790000620025,"inventory":{"pair_fast":{"qty":[5.0,10.0],"cash":6.40267,"lots":[[],[[5.0,0.37612799999999996]]],"floor":-1.4026699999999996},"pair_250":{"qty":[5.0,10.0],"cash":6.3005700000000004,"lots":[[],[[5.0,0.355708]]],"floor":-1.3005700000000004},"pair_add_fast":{"qty":[5.0,10.0],"cash":6.40267,"lots":[[],[[5.0,0.37612799999999996]]],"floor":-1.4026699999999996},"pair_add_250":{"qty":[5.0,10.0],"cash":6.3005700000000004,"lots":[[],[[5.0,0.355708]]],"floor":-1.3005700000000004}}}
{"kind":"decision","recorded_ms":1790000630080,"S":1790000400,"age":230,"signal":{},"entry_side":null,"context_gap":"incomplete or stale context","book_errors":[null,null],"books":[{"bid":0.99,"ask":null,"asks":[],"received_ms":1790000630063,"observed_ms":1790000630010,"hash":"1f238858f2453e79ba3476d3e25497b167ad208a"},{"bid":null,"ask":0.01,"asks":[[0.01,12343.89]],"received_ms":1790000630078,"observed_ms":1790000630010,"hash":"6c5d2f75e1f2a1e2e3dfda0094a4514f1d03806d"}],"intents":{"pair_fast":null,"pair_250":null,"pair_add_fast":null,"pair_add_250":null},"decision_ms":1790000630080,"feature_cutoff_ms":1790000630079,"request_ms":1790000630037,"inventory":{"pair_fast":{"qty":[5.0,10.0],"cash":6.40267,"lots":[[],[[5.0,0.37612799999999996]]],"floor":-1.4026699999999996},"pair_250":{"qty":[5.0,10.0],"cash":6.3005700000000004,"lots":[[],[[5.0,0.355708]]],"floor":-1.3005700000000004},"pair_add_fast":{"qty":[5.0,10.0],"cash":6.40267,"lots":[[],[[5.0,0.37612799999999996]]],"floor":-1.4026699999999996},"pair_add_250":{"qty":[5.0,10.0],"cash":6.3005700000000004,"lots":[[],[[5.0,0.355708]]],"floor":-1.3005700000000004}}}
{"kind":"decision","recorded_ms":1790000640051,"S":1790000400,"age":240,"signal":{"rsi14":74.2579735300491,"volume_ratio":0.6392870468885787,"taker_buy_fraction":0.6437088015000301,"volume5":118.09896,"return1":24.213499165907784,"return5":26.586272618123484,"return15":60.49521370024357,"bollinger_z":2.6057781820059756,"bar_close_ms":1790000579999,"ref":85361.48203450121,"reference_received_ms":1790000400918,"spot":85712.94749679149,"twap":85653.9103965042,"sigma":10.26028621756669,"spot_z":4.424137177985805,"twap_z":3.6809966470230764,"momentum":1.0642894261194749,"decision_ms":1790000640050,"momentum30":1.1395775153747216,"momentum60":1.3576687374697736,"spot_twap_gap":0.7428308248346284,"range60":1.3693187673347762,"final_mean":85712.9474967915,"final_z":7.669221383650883,"final_up_prob":0.9999999999999913,"final_drift_up_prob":1.0,"final_known_seconds":0,"final_sd":45.82805016419752,"final_drift_shift":103.42281461901023},"entry_side":null,"context_gap":null,"book_errors":[null,null],"books":[{"bid":0.99,"ask":null,"asks":[],"received_ms":1790000640050,"observed_ms":1790000640038,"hash":"b9c91b0ecfe5e1b37dce216a6cb56e8f5cad1715"},{"bid":null,"ask":0.01,"asks":[[0.01,11809.59]],"received_ms":1790000640030,"observed_ms":1790000640021,"hash":"f4270cd6aeb2c11ff3aa1f303090d66bfec992d2"}],"intents":{"pair_fast":null,"pair_250":null,"pair_add_fast":null,"pair_add_250":null},"decision_ms":1790000640051,"feature_cutoff_ms":1790000640050,"request_ms":1790000640004,"inventory":{"pair_fast":{"qty":[5.0,10.0],"cash":6.40267,"lots":[[],[[5.0,0.37612799999999996]]],"floor":-1.4026699999999996},"pair_250":{"qty":[5.0,10.0],"cash":6.3005700000000004,"lots":[[],[[5.0,0.355708]]],"floor":-1.3005700000000004},"pair_add_fast":{"qty":[5.0,10.0],"cash":6.40267,"lots":[[],[[5.0,0.37612799999999996]]],"floor":-1.4026699999999996},"pair_add_250":{"qty":[5.0,10.0],"cash":6.3005700000000004,"lots":[[],[[5.0,0.355708]]],"floor":-1.3005700000000004}}}
{"kind":"decision","recorded_ms":1790000650079,"S":1790000400,"age":250,"signal":{"rsi14":75.09629209827523,"volume_ratio":1.2276303241956235,"taker_buy_fraction":0.6746579778047034,"volume5":140.0567,"return1":10.533255692857605,"return5":40.646935534141264,"return15":62.7002834997179,"bollinger_z":2.5749116942341224,"bar_close_ms":1790000639999,"ref":85361.48203450121,"reference_received_ms":1790000400918,"spot":85709.5114857874,"twap":85670.65975119313,"sigma":6.7118682069044615,"spot_z":7.3388259667910045,"twap_z":6.5195673734692,"momentum":0.3082340077613273,"decision_ms":1790000650078,"momentum30":1.174263999644829,"momentum60":0.6933152845680967,"spot_twap_gap":0.7472937807890709,"range60":1.4081575073649695,"final_mean":85708.58157708029,"final_z":15.236476139495316,"final_up_prob":1.0,"final_drift_up_prob":1.0,"final_known_seconds":10,"final_sd":22.780828020945027,"final_drift_shift":13.587097065245477},"entry_side":null,"context_gap":null,"book_errors":[null,null],"books":[{"bid":0.99,"ask":null,"asks":[],"received_ms":1790000650078,"observed_ms":1790000650060,"hash":"ff697bfef4d9dbe695414bcb0ebb301a04e046d4"},{"bid":null,"ask":0.01,"asks":[[0.01,22580.32]],"received_ms":1790000650076,"observed_ms":1790000650069,"hash":"f493a970fcefce4088aed15a1a8cd76906666f32"}],"intents":{"pair_fast":null,"pair_250":null,"pair_add_fast":null,"pair_add_250":null},"decision_ms":1790000650079,"feature_cutoff_ms":1790000650078,"request_ms":1790000650046,"inventory":{"pair_fast":{"qty":[5.0,10.0],"cash":6.40267,"lots":[[],[[5.0,0.37612799999999996]]],"floor":-1.4026699999999996},"pair_250":{"qty":[5.0,10.0],"cash":6.3005700000000004,"lots":[[],[[5.0,0.355708]]],"floor":-1.3005700000000004},"pair_add_fast":{"qty":[5.0,10.0],"cash":6.40267,"lots":[[],[[5.0,0.37612799999999996]]],"floor":-1.4026699999999996},"pair_add_250":{"qty":[5.0,10.0],"cash":6.3005700000000004,"lots":[[],[[5.0,0.355708]]],"floor":-1.3005700000000004}}}
{"kind":"decision","recorded_ms":1790000660079,"S":1790000400,"age":260,"signal":{"rsi14":75.09629209827523,"volume_ratio":1.2276303241956235,"taker_buy_fraction":0.6746579778047034,"volume5":140.0567,"return1":10.533255692857605,"return5":40.646935534141264,"return15":62.7002834997179,"bollinger_z":2.5749116942341224,"bar_close_ms":1790000639999,"ref":85361.48203450121,"reference_received_ms":1790000400918,"spot":85719.87725863236,"twap":85680.80267799234,"sigma":9.130990839239017,"spot_z":6.21209604751774,"twap_z":5.534812893031637,"momentum":-0.4586572696158136,"decision_ms":1790000660078,"momentum30":0.829024048109186,"momentum60":0.9922676495778513,"spot_twap_gap":0.5524599419831757,"range60":1.3072190644867128,"final_mean":85716.66496328861,"final_z":16.02609158788366,"final_up_prob":1.0,"final_drift_up_prob":1.0,"final_known_seconds":20,"final_sd":22.162791647586165,"final_drift_shift":-17.58933909561059},"entry_side":1,"context_gap":null,"book_errors":[null,null],"books":[{"bid":0.99,"ask":null,"asks":[],"received_ms":1790000660078,"observed_ms":1790000660028,"hash":"6e708ceb4c9c25eb1acf78e43bfb1cea9c9bc19d"},{"bid":null,"ask":0.01,"asks":[[0.01,34532.94]],"received_ms":1790000660077,"observed_ms":1790000660028,"hash":"6323461fc7ff2dec70cf6443c9e595f55a711114"}],"intents":{"pair_fast":null,"pair_250":null,"pair_add_fast":{"kind":"add","side":1,"qty":5.0,"max_cost":0.10347},"pair_add_250":{"kind":"add","side":1,"qty":5.0,"max_cost":0.10347}},"decision_ms":1790000660079,"feature_cutoff_ms":1790000660078,"request_ms":1790000660050,"inventory":{"pair_fast":{"qty":[5.0,10.0],"cash":6.40267,"lots":[[],[[5.0,0.37612799999999996]]],"floor":-1.4026699999999996},"pair_250":{"qty":[5.0,10.0],"cash":6.3005700000000004,"lots":[[],[[5.0,0.355708]]],"floor":-1.3005700000000004},"pair_add_fast":{"qty":[5.0,10.0],"cash":6.40267,"lots":[[],[[5.0,0.37612799999999996]]],"floor":-1.4026699999999996},"pair_add_250":{"qty":[5.0,10.0],"cash":6.3005700000000004,"lots":[[],[[5.0,0.355708]]],"floor":-1.3005700000000004}}}
{"kind":"execution","recorded_ms":1790000660123,"S":1790000400,"age":260,"speed":"fast","books":[{"bid":0.99,"ask":null,"asks":[],"received_ms":1790000660107,"observed_ms":1790000660098,"hash":"1f863f810619a7e7658f0b48b37ef6bb9672c5b9"},{"bid":null,"ask":0.01,"asks":[[0.01,34547.94]],"received_ms":1790000660122,"observed_ms":1790000660101,"hash":"b9402f304aca77afaa0d62d3f7638a0c91777c38"}],"book_errors":[null,null],"fills":{"pair_add_fast":{"kind":"add","side":1,"qty":5.0,"cost":0.053470000000000004,"fee":0.00347,"age":260.123}},"rejected":{},"decision_ms":1790000660079,"request_ms":1790000660079,"execution_ms":1790000660123,"delay_ms":44}
{"kind":"execution","recorded_ms":1790000660362,"S":1790000400,"age":260,"speed":"250","books":[{"bid":0.99,"ask":null,"asks":[],"received_ms":1790000660360,"observed_ms":1790000660346,"hash":"cdc7d5ddf1017a040d8b1f1460d5544f71789694"},{"bid":null,"ask":0.01,"asks":[[0.01,34557.94]],"received_ms":1790000660362,"observed_ms":1790000660346,"hash":"fc2e5f10cf8dc9d6a155a2a359face26ae1bacc3"}],"book_errors":[null,null],"fills":{"pair_add_250":{"kind":"add","side":1,"qty":5.0,"cost":0.053470000000000004,"fee":0.00347,"age":260.362}},"rejected":{},"decision_ms":1790000660079,"request_ms":1790000660329,"execution_ms":1790000660362,"delay_ms":283}
{"kind":"decision","recorded_ms":1790000670067,"S":1790000400,"age":270,"signal":{"rsi14":75.09629209827523,"volume_ratio":1.2276303241956235,"taker_buy_fraction":0.6746579778047034,"volume5":140.0567,"return1":10.533255692857605,"return5":40.646935534141264,"return15":62.7002834997179,"bollinger_z":2.5749116942341224,"bar_close_ms":1790000639999,"ref":85361.48203450121,"reference_received_ms":1790000400918,"spot":85734.48174337715,"twap":85691.84364313366,"sigma":9.464001485993531,"spot_z":7.2036286349906895,"twap_z":6.380172121361635,"momentum":0.5993804148727568,"decision_ms":1790000670066,"momentum30":0.6079206271694487,"momentum60":1.1673527943210644,"spot_twap_gap":0.5816308334318955,"range60":1.2893737503352145,"final_mean":85725.86597082586,"final_z":24.431445848056043,"final_up_prob":1.0,"final_drift_up_prob":1.0,"final_known_seconds":30,"final_sd":14.914546547544782,"final_drift_shift":13.394472374142326},"entry_side":null,"context_gap":null,"book_errors":[null,null],"books":[{"bid":0.99,"ask":null,"asks":[],"received_ms":1790000670066,"observed_ms":1790000670052,"hash":"41ec96c199e1aa21749bf00b3095e90b5655e1a8"},{"bid":null,"ask":0.01,"asks":[[0.01,39568.09]],"received_ms":1790000670065,"observed_ms":1790000670052,"hash":"693ebea894bb4bd0048311758ddbc139b9d0a6c2"}],"intents":{"pair_fast":null,"pair_250":null,"pair_add_fast":null,"pair_add_250":null},"decision_ms":1790000670067,"feature_cutoff_ms":1790000670066,"request_ms":1790000670033,"inventory":{"pair_fast":{"qty":[5.0,10.0],"cash":6.40267,"lots":[[],[[5.0,0.37612799999999996]]],"floor":-1.4026699999999996},"pair_250":{"qty":[5.0,10.0],"cash":6.3005700000000004,"lots":[[],[[5.0,0.355708]]],"floor":-1.3005700000000004},"pair_add_fast":{"qty":[5.0,15.0],"cash":6.4561399999999995,"lots":[[],[[5.0,0.37612799999999996],[5.0,0.010694]]],"floor":-1.4561399999999995},"pair_add_250":{"qty":[5.0,15.0],"cash":6.35404,"lots":[[],[[5.0,0.355708],[5.0,0.010694]]],"floor":-1.3540400000000004}}}
{"kind":"decision","recorded_ms":1790000680074,"S":1790000400,"age":280,"signal":{"rsi14":75.09629209827523,"volume_ratio":1.2276303241956235,"taker_buy_fraction":0.6746579778047034,"volume5":140.0567,"return1":10.533255692857605,"return5":40.646935534141264,"return15":62.7002834997179,"bollinger_z":2.5749116942341224,"bar_close_ms":1790000639999,"ref":85361.48203450121,"reference_received_ms":1790000400918,"spot":85697.47601598641,"twap":85704.60320376475,"sigma":9.873323775254342,"spot_z":7.623372798784027,"twap_z":7.785081675833201,"momentum":-1.3529768358796226,"decision_ms":1790000680073,"momentum30":-0.6591325287660335,"momentum60":0.40708614427299145,"spot_twap_gap":-0.09319212117808315,"range60":0.9853787502908717,"final_mean":85710.56424086913,"final_z":41.3060178386484,"final_up_prob":1.0,"final_drift_up_prob":1.0,"final_known_seconds":40,"final_sd":8.451122248857892,"final_drift_shift":-13.978363753421075},"entry_side":1,"context_gap":null,"book_errors":[null,null],"books":[{"bid":0.99,"ask":null,"asks":[],"received_ms":1790000680068,"observed_ms":1790000680051,"hash":"816bd8bf4fde6971b6eb5ed9f222a0481adf9a40"},{"bid":null,"ask":0.01,"asks":[[0.01,52339.09]],"received_ms":1790000680072,"observed_ms":1790000680051,"hash":"e5b08f6b522a5f9696936ede2874d880f7876caa"}],"intents":{"pair_fast":null,"pair_250":null,"pair_add_fast":null,"pair_add_250":null},"decision_ms":1790000680074,"feature_cutoff_ms":1790000680073,"request_ms":1790000680041,"inventory":{"pair_fast":{"qty":[5.0,10.0],"cash":6.40267,"lots":[[],[[5.0,0.37612799999999996]]],"floor":-1.4026699999999996},"pair_250":{"qty":[5.0,10.0],"cash":6.3005700000000004,"lots":[[],[[5.0,0.355708]]],"floor":-1.3005700000000004},"pair_add_fast":{"qty":[5.0,15.0],"cash":6.4561399999999995,"lots":[[],[[5.0,0.37612799999999996],[5.0,0.010694]]],"floor":-1.4561399999999995},"pair_add_250":{"qty":[5.0,15.0],"cash":6.35404,"lots":[[],[[5.0,0.355708],[5.0,0.010694]]],"floor":-1.3540400000000004}}}
{"kind":"decision","recorded_ms":1790000690097,"S":1790000400,"age":290,"signal":{"rsi14":75.09629209827523,"volume_ratio":1.2276303241956235,"taker_buy_fraction":0.6746579778047034,"volume5":140.0567,"return1":10.533255692857605,"return5":40.646935534141264,"return15":62.7002834997179,"bollinger_z":2.5749116942341224,"bar_close_ms":1790000639999,"ref":85361.48203450121,"reference_received_ms":1790000400918,"spot":85680.49170482984,"twap":85708.006931479,"sigma":10.56540932743822,"spot_z":9.594275922884245,"twap_z":10.421801547047401,"momentum":-0.02683467454060935,"decision_ms":1790000690096,"momentum30":-0.6229902016983438,"momentum60":0.025366887569248434,"spot_twap_gap":-0.3362103990380024,"range60":0.7733109598733301,"final_mean":85704.65505155915,"final_z":108.29857270720899,"final_up_prob":1.0,"final_drift_up_prob":1.0,"final_known_seconds":50,"final_sd":3.16876768067596,"final_drift_shift":-0.07328628055026694},"entry_side":1,"context_gap":null,"book_errors":[null,null],"books":[{"bid":0.99,"ask":null,"asks":[],"received_ms":1790000690096,"observed_ms":1790000690079,"hash":"196870cdff4b97ecbed5a6c2ac9d6d937d15bec7"},{"bid":null,"ask":0.01,"asks":[[0.01,52487.89]],"received_ms":1790000690070,"observed_ms":1790000690056,"hash":"130999b1e04cf7eb922bf438aed746a99eb1e077"}],"intents":{"pair_fast":null,"pair_250":null,"pair_add_fast":null,"pair_add_250":null},"decision_ms":1790000690097,"feature_cutoff_ms":1790000690096,"request_ms":1790000690044,"inventory":{"pair_fast":{"qty":[5.0,10.0],"cash":6.40267,"lots":[[],[[5.0,0.37612799999999996]]],"floor":-1.4026699999999996},"pair_250":{"qty":[5.0,10.0],"cash":6.3005700000000004,"lots":[[],[[5.0,0.355708]]],"floor":-1.3005700000000004},"pair_add_fast":{"qty":[5.0,15.0],"cash":6.4561399999999995,"lots":[[],[[5.0,0.37612799999999996],[5.0,0.010694]]],"floor":-1.4561399999999995},"pair_add_250":{"qty":[5.0,15.0],"cash":6.35404,"lots":[[],[[5.0,0.355708],[5.0,0.010694]]],"floor":-1.3540400000000004}}}
{"kind":"decision","recorded_ms":1790000730097,"S":1790000700,"age":30,"signal":{"rsi14":72.4011437184151,"volume_ratio":0.910378167750997,"taker_buy_fraction":0.6188901950258501,"volume5":154.57797,"return1":-1.3696274496662713,"return5":35.41665256984829,"return15":54.42460830871651,"bollinger_z":2.0777257913659946,"bar_close_ms":1790000699999,"ref":85703.53336344547,"reference_received_ms":1790000701043,"spot":85661.81357384783,"twap":85692.79499029742,"sigma":8.708922069453035,"spot_z":-0.29159028118723546,"twap_z":-0.07505323674764389,"momentum":-1.7201180573936923,"decision_ms":1790000730096,"momentum30":-0.4853329150776257,"momentum60":-1.1548543587817426,"spot_twap_gap":-0.45926276904790614,"range60":1.1548543587817426,"final_mean":85661.81357384783,"final_z":-0.3159398745805811,"final_up_prob":0.3760240726593444,"final_drift_up_prob":0.0,"final_known_seconds":0,"final_sd":132.04977577783288,"final_drift_shift":-1136.47568552067},"entry_side":null,"context_gap":null,"book_errors":[null,null],"books":[{"bid":0.33,"ask":0.34,"asks":[[0.34,318.0]],"received_ms":1790000730096,"observed_ms":1790000730084,"hash":"a0580869f1b1668eae1204fa1e2623da61c9bea6"},{"bid":0.66,"ask":0.67,"asks":[[0.67,1682.69]],"received_ms":1790000730071,"observed_ms":1790000730062,"hash":"cb08ed0f93733915a34e5e86c028f96cbb3ee93e"}],"intents":{"pair_fast":null,"pair_250":null,"pair_add_fast":null,"pair_add_250":null},"decision_ms":1790000730097,"feature_cutoff_ms":1790000730096,"request_ms":1790000730043,"inventory":{"pair_fast":{"qty":[0.0,0.0],"cash":0.0,"lots":[[],[]],"floor":0.0},"pair_250":{"qty":[0.0,0.0],"cash":0.0,"lots":[[],[]],"floor":0.0},"pair_add_fast":{"qty":[0.0,0.0],"cash":0.0,"lots":[[],[]],"floor":0.0},"pair_add_250":{"qty":[0.0,0.0],"cash":0.0,"lots":[[],[]],"floor":0.0}}}
{"kind":"decision","recorded_ms":1790000740056,"S":1790000700,"age":40,"signal":{"rsi14":72.4011437184151,"volume_ratio":0.910378167750997,"taker_buy_fraction":0.6188901950258501,"volume5":154.57797,"return1":-1.3696274496662713,"return5":35.41665256984829,"return15":54.42460830871651,"bollinger_z":2.0777257913659946,"bar_close_ms":1790000699999,"ref":85703.53336344547,"reference_received_ms":1790000701043,"spot":85669.67219082786,"twap":85680.16776995036,"sigma":8.20687507489487,"spot_z":-0.2559077491680138,"twap_z":-0.1765868095246447,"momentum":0.7034845772566005,"decision_ms":1790000740055,"momentum30":-0.2979925453839367,"momentum60":-0.1843015174033643,"spot_twap_gap":-0.16510223757241907,"range60":1.071126532792694,"final_mean":85669.67219082786,"final_z":-0.2782064050159779,"final_up_prob":0.3904269591932231,"final_drift_up_prob":0.9992404724728446,"final_known_seconds":0,"final_sd":121.71241210522139,"final_drift_shift":419.8134745079227},"entry_side":null,"context_gap":null,"book_errors":[null,null],"books":[{"bid":0.39,"ask":0.4,"asks":[[0.4,1489.3]],"received_ms":1790000740046,"observed_ms":1790000740037,"hash":"c77848ac1a6b55bc819f599b26c25c9550fd1231"},{"bid":0.6,"ask":0.63,"asks":[[0.63,56.0]],"received_ms":1790000740055,"observed_ms":1790000740044,"hash":"8d4c80b856f1c9fe212556cde6ddb40c4a851578"}],"intents":{"pair_fast":null,"pair_250":null,"pair_add_fast":null,"pair_add_250":null},"decision_ms":1790000740056,"feature_cutoff_ms":1790000740055,"request_ms":1790000740019,"inventory":{"pair_fast":{"qty":[0.0,0.0],"cash":0.0,"lots":[[],[]],"floor":0.0},"pair_250":{"qty":[0.0,0.0],"cash":0.0,"lots":[[],[]],"floor":0.0},"pair_add_fast":{"qty":[0.0,0.0],"cash":0.0,"lots":[[],[]],"floor":0.0},"pair_add_250":{"qty":[0.0,0.0],"cash":0.0,"lots":[[],[]],"floor":0.0}}}
{"kind":"decision","recorded_ms":1790000750066,"S":1790000700,"age":50,"signal":{"rsi14":72.4011437184151,"volume_ratio":0.910378167750997,"taker_buy_fraction":0.6188901950258501,"volume5":154.57797,"return1":-1.3696274496662713,"return5":35.41665256984829,"return15":54.42460830871651,"bollinger_z":2.0777257913659946,"bar_close_ms":1790000699999,"ref":85703.53336344547,"reference_received_ms":1790000701043,"spot":85623.11009124576,"twap":85674.54470272754,"sigma":8.797694620015797,"spot_z":-0.5782282659069753,"twap_z":-0.2084230417319196,"momentum":-1.642516643328021,"decision_ms":1790000750065,"momentum30":-1.7862838538953727,"momentum60":-0.6601369934850698,"spot_twap_gap":-0.754763614376678,"range60":1.3052748109705934,"final_mean":85623.11009124576,"final_z":-0.6309143882174091,"final_up_prob":0.2640482517591932,"final_drift_up_prob":0.0,"final_known_seconds":0,"final_sd":127.4709749874925,"final_drift_shift":-1005.0160774304351},"entry_side":null,"context_gap":null,"book_errors":[null,null],"books":[{"bid":0.24,"ask":0.25,"asks":[[0.25,199.0]],"received_ms":1790000750056,"observed_ms":1790000750046,"hash":"3ade0e2e92fac1cd46b0656e811ed52225e494d6"},{"bid":0.75,"ask":0.76,"asks":[[0.76,2582.75]],"received_ms":1790000750065,"observed_ms":1790000750051,"hash":"dfab879cc61e324873a6f8e4fe5bd36b936f33c3"}],"intents":{"pair_fast":null,"pair_250":null,"pair_add_fast":null,"pair_add_250":null},"decision_ms":1790000750066,"feature_cutoff_ms":1790000750065,"request_ms":1790000750028,"inventory":{"pair_fast":{"qty":[0.0,0.0],"cash":0.0,"lots":[[],[]],"floor":0.0},"pair_250":{"qty":[0.0,0.0],"cash":0.0,"lots":[[],[]],"floor":0.0},"pair_add_fast":{"qty":[0.0,0.0],"cash":0.0,"lots":[[],[]],"floor":0.0},"pair_add_250":{"qty":[0.0,0.0],"cash":0.0,"lots":[[],[]],"floor":0.0}}}
{"kind":"decision","recorded_ms":1790000760126,"S":1790000700,"age":60,"signal":{"rsi14":72.4011437184151,"volume_ratio":0.910378167750997,"taker_buy_fraction":0.6188901950258501,"volume5":154.57797,"return1":-1.3696274496662713,"return5":35.41665256984829,"return15":54.42460830871651,"bollinger_z":2.0777257913659946,"bar_close_ms":1790000699999,"ref":85703.53336344547,"reference_received_ms":1790000701043,"spot":85631.01661880795,"twap":85666.43178131094,"sigma":10.007798813869325,"spot_z":-0.4678506528269977,"twap_z":-0.23936539773427956,"momentum":0.8234134210513544,"decision_ms":1790000760125,"momentum30":-0.3721327553158161,"momentum60":-0.6959189452350472,"spot_twap_gap":-0.45685149194922436,"range60":1.3816098786392574,"final_mean":85631.01661880795,"final_z":-0.5125314211450568,"final_up_prob":0.30413956772824835,"final_drift_up_prob":0.9996001705386139,"final_known_seconds":0,"final_sd":141.48741256783055,"final_drift_shift":546.9117031030033},"entry_side":null,"context_gap":null,"book_errors":[null,null],"books":[{"bid":0.39,"ask":0.4,"asks":[[0.4,138.83]],"received_ms":1790000760125,"observed_ms":1790000760099,"hash":"9f2f138ca4960c8b31a5b7e35f1aa34607b2b494"},{"bid":0.6,"ask":0.61,"asks":[[0.61,911.58]],"received_ms":1790000760080,"observed_ms":1790000760061,"hash":"6a88aa702dc96202c4c45f94951bfd4514a5b969"}],"intents":{"pair_fast":null,"pair_250":null,"pair_add_fast":null,"pair_add_250":null},"decision_ms":1790000760126,"feature_cutoff_ms":1790000760125,"request_ms":1790000760040,"inventory":{"pair_fast":{"qty":[0.0,0.0],"cash":0.0,"lots":[[],[]],"floor":0.0},"pair_250":{"qty":[0.0,0.0],"cash":0.0,"lots":[[],[]],"floor":0.0},"pair_add_fast":{"qty":[0.0,0.0],"cash":0.0,"lots":[[],[]],"floor":0.0},"pair_add_250":{"qty":[0.0,0.0],"cash":0.0,"lots":[[],[]],"floor":0.0}}}
{"kind":"decision","recorded_ms":1790000770073,"S":1790000700,"age":70,"signal":{"rsi14":68.332166106015,"volume_ratio":1.324573741914099,"taker_buy_fraction":0.5177825742293803,"volume5":180.18876,"return1":-3.1275549965378557,"return5":39.66976753630677,"return15":44.049511529592195,"bollinger_z":1.7241348523236635,"bar_close_ms":1790000759999,"ref":85703.53336344547,"reference_received_ms":1790000701043,"spot":85708.97598914965,"twap":85662.556890844,"sigma":12.512791477362745,"spot_z":0.02868522959953317,"twap_z":-0.21596552631753968,"momentum":1.4150564323340904,"decision_ms":1790000770072,"momentum30":0.5861183951395325,"momentum60":0.26731101366704474,"spot_twap_gap":0.4789242938822014,"range60":1.1050191102193865,"final_mean":85708.97598914965,"final_z":0.03156165466963707,"final_up_prob":0.5125891883575421,"final_drift_up_prob":0.9999999999655835,"final_known_seconds":0,"final_sd":172.44424480107136,"final_drift_shift":1119.4419779702012},"entry_side":null,"context_gap":null,"book_errors":[null,null],"books":[{"bid":0.44,"ask":0.45,"asks":[[0.45,1066.54]],"received_ms":1790000770072,"observed_ms":1790000770059,"hash":"519f0878f33bbe61951afad2fccb68fbd4dcb8c9"},{"bid":0.55,"ask":0.56,"asks":[[0.56,10.0]],"received_ms":1790000770070,"observed_ms":1790000770053,"hash":"e6ee63d2ee73b23500cb3a84f8331b6b17ecf88e"}],"intents":{"pair_fast":null,"pair_250":null,"pair_add_fast":null,"pair_add_250":null},"decision_ms":1790000770073,"feature_cutoff_ms":1790000770072,"request_ms":1790000770020,"inventory":{"pair_fast":{"qty":[0.0,0.0],"cash":0.0,"lots":[[],[]],"floor":0.0},"pair_250":{"qty":[0.0,0.0],"cash":0.0,"lots":[[],[]],"floor":0.0},"pair_add_fast":{"qty":[0.0,0.0],"cash":0.0,"lots":[[],[]],"floor":0.0},"pair_add_250":{"qty":[0.0,0.0],"cash":0.0,"lots":[[],[]],"floor":0.0}}}
{"kind":"decision","recorded_ms":1790000780078,"S":1790000700,"age":80,"signal":{"rsi14":68.332166106015,"volume_ratio":1.324573741914099,"taker_buy_fraction":0.5177825742293803,"volume5":180.18876,"return1":-3.1275549965378557,"return5":39.66976753630677,"return15":44.049511529592195,"bollinger_z":1.7241348523236635,"bar_close_ms":1790000759999,"ref":85703.53336344547,"reference_received_ms":1790000701043,"spot":85678.61214429834,"twap":85663.70146811372,"sigma":12.009383542988642,"spot_z":-0.13993077628875664,"twap_z":-0.22365310468633573,"momentum":-0.4427219856480306,"decision_ms":1790000780077,"momentum30":1.1197411932805996,"momentum60":-0.3286618324591479,"spot_twap_gap":0.1602879957354641,"range60":1.1204384234017764,"final_mean":85678.61214429834,"final_z":-0.1547053123912722,"final_up_prob":0.4385268208692708,"final_drift_up_prob":0.016299535520967134,"final_known_seconds":0,"final_sd":161.08832180307573,"final_drift_shift":-319.3223867299689},"entry_side":null,"context_gap":null,"book_errors":[null,null],"books":[{"bid":0.34,"ask":0.35,"asks":[[0.35,5.0]],"received_ms":1790000780077,"observed_ms":1790000780068,"hash":"f0608a776f38a6b18e13025621d6b5f7f562bec3"},{"bid":0.65,"ask":0.66,"asks":[[0.66,1211.35]],"received_ms":1790000780076,"observed_ms":1790000780068,"hash":"52b1283fe463f7492c87efd231b53fcb215423b6"}],"intents":{"pair_fast":null,"pair_250":null,"pair_add_fast":null,"pair_add_250":null},"decision_ms":1790000780078,"feature_cutoff_ms":1790000780077,"request_ms":1790000780046,"inventory":{"pair_fast":{"qty":[0.0,0.0],"cash":0.0,"lots":[[],[]],"floor":0.0},"pair_250":{"qty":[0.0,0.0],"cash":0.0,"lots":[[],[]],"floor":0.0},"pair_add_fast":{"qty":[0.0,0.0],"cash":0.0,"lots":[[],[]],"floor":0.0},"pair_add_250":{"qty":[0.0,0.0],"cash":0.0,"lots":[[],[]],"floor":0.0}}}
{"kind":"decision","recorded_ms":1790000790078,"S":1790000700,"age":90,"signal":{"rsi14":68.332166106015,"volume_ratio":1.324573741914099,"taker_buy_fraction":0.5177825742293803,"volume5":180.18876,"return1":-3.1275549965378557,"return5":39.66976753630677,"return15":44.049511529592195,"bollinger_z":1.7241348523236635,"bar_close_ms":1790000759999,"ref":85703.53336344547,"reference_received_ms":1790000701043,"spot":85642.09764625409,"twap":85657.10147470365,"sigma":11.259081395323234,"spot_z":-0.3766066301798563,"twap_z":-0.2846317736874101,"momentum":-0.6371897854822399,"decision_ms":1790000790077,"momentum30":-0.17652580708181415,"momentum60":-0.10683585763508954,"spot_twap_gap":-0.1720376517237188,"range60":1.0667216194229792,"final_mean":85642.09764625409,"final_z":-0.4185929312195175,"final_up_prob":0.33775682827596903,"final_drift_up_prob":0.000687674780517622,"final_known_seconds":0,"final_sd":146.76721131530314,"final_drift_shift":-408.18632227055866},"entry_side":null,"context_gap":null,"book_errors":[null,null],"books":[{"bid":0.29,"ask":0.3,"asks":[[0.3,333.03]],"received_ms":1790000790077,"observed_ms":1790000790066,"hash":"1607e5636b4dc64a2e8dec0c243e7d65d95b927b"},{"bid":0.7,"ask":0.71,"asks":[[0.71,2135.71]],"received_ms":1790000790075,"observed_ms":1790000790066,"hash":"612eec59dc49f139923fcb5fef44e7e6abff979e"}],"intents":{"pair_fast":null,"pair_250":null,"pair_add_fast":null,"pair_add_250":null},"decision_ms":1790000790078,"feature_cutoff_ms":1790000790077,"request_ms":1790000790049,"inventory":{"pair_fast":{"qty":[0.0,0.0],"cash":0.0,"lots":[[],[]],"floor":0.0},"pair_250":{"qty":[0.0,0.0],"cash":0.0,"lots":[[],[]],"floor":0.0},"pair_add_fast":{"qty":[0.0,0.0],"cash":0.0,"lots":[[],[]],"floor":0.0},"pair_add_250":{"qty":[0.0,0.0],"cash":0.0,"lots":[[],[]],"floor":0.0}}}
{"kind":"decision","recorded_ms":1790000800085,"S":1790000700,"age":100,"signal":{"rsi14":68.332166106015,"volume_ratio":1.324573741914099,"taker_buy_fraction":0.5177825742293803,"volume5":180.18876,"return1":-3.1275549965378557,"return5":39.66976753630677,"return15":44.049511529592195,"bollinger_z":1.7241348523236635,"bar_close_ms":1790000759999,"ref":85703.53336344547,"reference_received_ms":1790000701043,"spot":85644.83763838849,"twap":85654.47593314172,"sigma":10.782818543491832,"spot_z":-0.38499084145259127,"twap_z":-0.3217723497547708,"momentum":0.184343898608015,"decision_ms":1790000800084,"momentum30":-0.8565496357910943,"momentum60":-0.2869676803595471,"spot_twap_gap":-0.11539640560124172,"range60":1.1138373042995682,"final_mean":85644.83763838849,"final_z":-0.43045545513188443,"final_up_prob":0.3334321815957312,"final_drift_up_prob":0.6378900409823155,"final_known_seconds":0,"final_sd":136.35725684786516,"final_drift_shift":106.80592368967903},"entry_side":null,"context_gap":null,"book_errors":[null,null],"books":[{"bid":0.32,"ask":0.33,"asks":[[0.33,753.51]],"received_ms":1790000800084,"observed_ms":1790000800067,"hash":"5481dc1e72a75a0be73e08547a382e17753fe45c"},{"bid":0.67,"ask":0.68,"asks":[[0.68,10.0]],"received_ms":1790000800077,"observed_ms":1790000800067,"hash":"51241777a280bfabffd37c40aaf57b30e5017f58"}],"intents":{"pair_fast":null,"pair_250":null,"pair_add_fast":null,"pair_add_250":null},"decision_ms":1790000800085,"feature_cutoff_ms":1790000800084,"request_ms":1790000800049,"inventory":{"pair_fast":{"qty":[0.0,0.0],"cash":0.0,"lots":[[],[]],"floor":0.0},"pair_250":{"qty":[0.0,0.0],"cash":0.0,"lots":[[],[]],"floor":0.0},"pair_add_fast":{"qty":[0.0,0.0],"cash":0.0,"lots":[[],[]],"floor":0.0},"pair_add_250":{"qty":[0.0,0.0],"cash":0.0,"lots":[[],[]],"floor":0.0}}}
{"kind":"decision","recorded_ms":1790000810070,"S":1790000700,"age":110,"signal":{"rsi14":68.332166106015,"volume_ratio":1.324573741914099,"taker_buy_fraction":0.5177825742293803,"volume5":180.18876,"return1":-3.1275549965378557,"return5":39.66976753630677,"return15":44.049511529592195,"bollinger_z":1.7241348523236635,"bar_close_ms":1790000759999,"ref":85703.53336344547,"reference_received_ms":1790000701043,"spot":85639.233666841,"twap":85651.69893970649,"sigma":8.999222964027272,"spot_z":-0.5184475674476826,"twap_z":-0.4179402441481859,"momentum":-0.16562827689320342,"decision_ms":1790000810068,"momentum30":-0.5183668264230745,"momentum60":0.4917101397496639,"spot_twap_gap":-0.17882208425830892,"range60":1.3345936184983205,"final_mean":85639.233666841,"final_z":-0.5835213419287847,"final_up_prob":0.27977119713413573,"final_drift_up_prob":0.10246573261459724,"final_known_seconds":0,"final_sd":110.19253621801765,"final_drift_shift":-75.38325112866956},"entry_side":null,"context_gap":null,"book_errors":[null,null],"books":[{"bid":0.34,"ask":0.35,"asks":[[0.35,10.0]],"received_ms":1790000810068,"observed_ms":1790000810052,"hash":"69658fe39ddfa54cd83b3ebca4fd6e17bf869265"},{"bid":0.65,"ask":0.66,"asks":[[0.66,740.69]],"received_ms":1790000810053,"observed_ms":1790000810035,"hash":"a93411f772485f156ed690f41e3720d19916a3f6"}],"intents":{"pair_fast":null,"pair_250":null,"pair_add_fast":null,"pair_add_250":null},"decision_ms":1790000810070,"feature_cutoff_ms":1790000810068,"request_ms":1790000810007,"inventory":{"pair_fast":{"qty":[0.0,0.0],"cash":0.0,"lots":[[],[]],"floor":0.0},"pair_250":{"qty":[0.0,0.0],"cash":0.0,"lots":[[],[]],"floor":0.0},"pair_add_fast":{"qty":[0.0,0.0],"cash":0.0,"lots":[[],[]],"floor":0.0},"pair_add_250":{"qty":[0.0,0.0],"cash":0.0,"lots":[[],[]],"floor":0.0}}}
{"kind":"decision","recorded_ms":1790000820080,"S":1790000700,"age":120,"signal":{"rsi14":68.332166106015,"volume_ratio":1.324573741914099,"taker_buy_fraction":0.5177825742293803,"volume5":180.18876,"return1":-3.1275549965378557,"return5":39.66976753630677,"return15":44.049511529592195,"bollinger_z":1.7241348523236635,"bar_close_ms":1790000759999,"ref":85703.53336344547,"reference_received_ms":1790000701043,"spot":85677.49939006541,"twap":85658.46154817301,"sigma":8.735092464976217,"spot_z":-0.22219384367209263,"twap_z":-0.3846773494949769,"momentum":1.3058834386197993,"decision_ms":1790000820079,"momentum30":0.8140519294693673,"momentum60":0.3623267557250893,"spot_twap_gap":0.2813679225209809,"range60":0.906174221277412,"final_mean":85677.49939006541,"final_z":-0.2519599420080065,"final_up_prob":0.40053601335353584,"final_drift_up_prob":0.9999996852505852,"final_known_seconds":0,"final_sd":103.32584288036323,"final_drift_shift":540.7971460931138},"entry_side":null,"context_gap":null,"book_errors":[null,null],"books":[{"bid":0.37,"ask":0.38,"asks":[[0.38,326.36]],"received_ms":1790000820078,"observed_ms":1790000820068,"hash":"32ab83775d9dc9d6bb4526e70b3769f6c02672c0"},{"bid":0.62,"ask":0.63,"asks":[[0.63,295.37]],"received_ms":1790000820076,"observed_ms":1790000820068,"hash":"29baa86b5462fbb5f6860b073d87679214e2475a"}],"intents":{"pair_fast":null,"pair_250":null,"pair_add_fast":null,"pair_add_250":null},"decision_ms":1790000820080,"feature_cutoff_ms":1790000820079,"request_ms":1790000820042,"inventory":{"pair_fast":{"qty":[0.0,0.0],"cash":0.0,"lots":[[],[]],"floor":0.0},"pair_250":{"qty":[0.0,0.0],"cash":0.0,"lots":[[],[]],"floor":0.0},"pair_add_fast":{"qty":[0.0,0.0],"cash":0.0,"lots":[[],[]],"floor":0.0},"pair_add_250":{"qty":[0.0,0.0],"cash":0.0,"lots":[[],[]],"floor":0.0}}}
{"kind":"decision","recorded_ms":1790000830064,"S":1790000700,"age":130,"signal":{"rsi14":79.18531252870714,"volume_ratio":0.7219503188957109,"taker_buy_fraction":0.4546418910178489,"volume5":191.63817,"return1":0.9591804538161804,"return5":31.195535586761316,"return15":38.22369115042925,"bollinger_z":1.5748535266996357,"bar_close_ms":1790000819999,"ref":85703.53336344547,"reference_received_ms":1790000701043,"spot":85681.02857334784,"twap":85661.09473337395,"sigma":6.944966118897745,"spot_z":-0.24857695381174663,"twap_z":-0.4687564443550302,"momentum":0.4905157094251869,"decision_ms":1790000830063,"momentum30":0.9748234107789163,"momentum60":-0.26762150181963906,"spot_twap_gap":0.3705486291467541,"range60":1.0920918282158127,"final_mean":85681.02857334784,"final_z":-0.2842748358603739,"final_up_prob":0.3880998845236979,"final_drift_up_prob":0.9473788852925066,"final_known_seconds":0,"final_sd":79.1656075696011,"final_drift_shift":150.74940665977462},"entry_side":null,"context_gap":null,"book_errors":[null,null],"books":[{"bid":0.46,"ask":0.47,"asks":[[0.47,671.57]],"received_ms":1790000830063,"observed_ms":1790000830052,"hash":"85d684dc968fa129d753bac5bd5ad7f7b200fa8d"},{"bid":0.53,"ask":0.54,"asks":[[0.54,242.28]],"received_ms":1790000830058,"observed_ms":1790000830043,"hash":"cf8df46905dc0115cfa38ccca32d68093bd8c8fc"}],"intents":{"pair_fast":null,"pair_250":null,"pair_add_fast":null,"pair_add_250":null},"decision_ms":1790000830064,"feature_cutoff_ms":1790000830063,"request_ms":1790000830029,"inventory":{"pair_fast":{"qty":[0.0,0.0],"cash":0.0,"lots":[[],[]],"floor":0.0},"pair_250":{"qty":[0.0,0.0],"cash":0.0,"lots":[[],[]],"floor":0.0},"pair_add_fast":{"qty":[0.0,0.0],"cash":0.0,"lots":[[],[]],"floor":0.0},"pair_add_250":{"qty":[0.0,0.0],"cash":0.0,"lots":[[],[]],"floor":0.0}}}
{"kind":"decision","recorded_ms":1790000840079,"S":1790000700,"age":140,"signal":{"rsi14":79.18531252870714,"volume_ratio":0.7219503188957109,"taker_buy_fraction":0.4546418910178489,"volume5":191.63817,"return1":0.9591804538161804,"return5":31.195535586761316,"return15":38.22369115042925,"bollinger_z":1.5748535266996357,"bar_close_ms":1790000819999,"ref":85703.53336344547,"reference_received_ms":1790000701043,"spot":85694.52929686679,"twap":85659.31491239746,"sigma":6.609067606016423,"spot_z":-0.10773191929668552,"twap_z":-0.5290652349249385,"momentum":0.4428590030318511,"decision_ms":1790000840078,"momentum30":1.4669335727148811,"momentum60":0.5810280513886565,"spot_twap_gap":0.6878666943000309,"range60":1.1300919947842067,"final_mean":85694.52929686679,"final_z":-0.12440821873040611,"final_up_prob":0.4504960331493835,"final_drift_up_prob":0.9378638321619126,"final_known_seconds":0,"final_sd":72.3751748121398,"final_drift_shift":120.25090945614593},"entry_side":null,"context_gap":null,"book_errors":[null,null],"books":[{"bid":0.64,"ask":0.65,"asks":[[0.65,320.0]],"received_ms":1790000840078,"observed_ms":1790000840066,"hash":"c099843ba6f5b4aed2014401c0ea45aedacf2538"},{"bid":0.35,"ask":0.36,"asks":[[0.36,796.86]],"received_ms":1790000840068,"observed_ms":1790000840057,"hash":"09ec1bf1fd7daf915659cadca988fa5bc64316b0"}],"intents":{"pair_fast":null,"pair_250":null,"pair_add_fast":null,"pair_add_250":null},"decision_ms":1790000840079,"feature_cutoff_ms":1790000840078,"request_ms":1790000840037,"inventory":{"pair_fast":{"qty":[0.0,0.0],"cash":0.0,"lots":[[],[]],"floor":0.0},"pair_250":{"qty":[0.0,0.0],"cash":0.0,"lots":[[],[]],"floor":0.0},"pair_add_fast":{"qty":[0.0,0.0],"cash":0.0,"lots":[[],[]],"floor":0.0},"pair_add_250":{"qty":[0.0,0.0],"cash":0.0,"lots":[[],[]],"floor":0.0}}}
{"kind":"decision","recorded_ms":1790000850034,"S":1790000700,"age":150,"signal":{"rsi14":79.18531252870714,"volume_ratio":0.7219503188957109,"taker_buy_fraction":0.4546418910178489,"volume5":191.63817,"return1":0.9591804538161804,"return5":31.195535586761316,"return15":38.22369115042925,"bollinger_z":1.5748535266996357,"bar_close_ms":1790000819999,"ref":85703.53336344547,"reference_received_ms":1790000701043,"spot":85735.78661798246,"twap":85668.3703436867,"sigma":7.3436711926113984,"spot_z":0.35864309081622436,"twap_z":-0.39099849828340444,"momentum":0.5940256056168973,"decision_ms":1790000850033,"momentum30":1.6291872526151558,"momentum60":1.709357170891552,"spot_twap_gap":1.18515703641304,"range60":1.7423372196217515,"final_mean":85735.78661798246,"final_z":0.4188216581809958,"final_up_prob":0.6623267624474389,"final_drift_up_prob":0.9948829636391843,"final_known_seconds":0,"final_sd":77.0095192236979,"final_drift_shift":165.49321303888473},"entry_side":null,"context_gap":null,"book_errors":[null,null],"books":[{"bid":0.58,"ask":0.59,"asks":[[0.59,68.09]],"received_ms":1790000850027,"observed_ms":1790000850019,"hash":"391e00c33f92d53a9073ebfeba4e11843a5a454c"},{"bid":0.41,"ask":0.42,"asks":[[0.42,846.33]],"received_ms":1790000850032,"observed_ms":1790000850020,"hash":"42653d9f3c5bad4ad17554295f3b10343c49ce81"}],"intents":{"pair_fast":null,"pair_250":null,"pair_add_fast":null,"pair_add_250":null},"decision_ms":1790000850034,"feature_cutoff_ms":1790000850033,"request_ms":1790000850003,"inventory":{"pair_fast":{"qty":[0.0,0.0],"cash":0.0,"lots":[[],[]],"floor":0.0},"pair_250":{"qty":[0.0,0.0],"cash":0.0,"lots":[[],[]],"floor":0.0},"pair_add_fast":{"qty":[0.0,0.0],"cash":0.0,"lots":[[],[]],"floor":0.0},"pair_add_250":{"qty":[0.0,0.0],"cash":0.0,"lots":[[],[]],"floor":0.0}}}
{"kind":"decision","recorded_ms":1790000860039,"S":1790000700,"age":160,"signal":{},"entry_side":null,"context_gap":"incomplete or stale context","book_errors":[null,null],"books":[{"bid":0.59,"ask":0.61,"asks":[[0.61,1452.78]],"received_ms":1790000860035,"observed_ms":1790000860026,"hash":"dd1d3da7fe131089c345c06cad22b3b27b657da9"},{"bid":0.39,"ask":0.41,"asks":[[0.41,1.24],[0.43,250.0]],"received_ms":1790000860037,"observed_ms":1790000860030,"hash":"8f1a6d28d6311fb032bc1927e993e1c9d25a9c74"}],"intents":{"pair_fast":null,"pair_250":null,"pair_add_fast":null,"pair_add_250":null},"decision_ms":1790000860039,"feature_cutoff_ms":1790000860037,"request_ms":1790000860008,"inventory":{"pair_fast":{"qty":[0.0,0.0],"cash":0.0,"lots":[[],[]],"floor":0.0},"pair_250":{"qty":[0.0,0.0],"cash":0.0,"lots":[[],[]],"floor":0.0},"pair_add_fast":{"qty":[0.0,0.0],"cash":0.0,"lots":[[],[]],"floor":0.0},"pair_add_250":{"qty":[0.0,0.0],"cash":0.0,"lots":[[],[]],"floor":0.0}}}
{"kind":"decision","recorded_ms":1790000870043,"S":1790000700,"age":170,"signal":{"rsi14":79.18531252870714,"volume_ratio":0.7219503188957109,"taker_buy_fraction":0.4546418910178489,"volume5":191.63817,"return1":0.9591804538161804,"return5":31.195535586761316,"return15":38.22369115042925,"bollinger_z":1.5748535266996357,"bar_close_ms":1790000819999,"ref":85703.53336344547,"reference_received_ms":1790000701043,"spot":85729.93275409243,"twap":85698.02798585502,"sigma":7.366771222013837,"spot_z":0.3143512634514644,"twap_z":-0.06555539195885778,"momentum":0.15813613764613763,"decision_ms":1790000870042,"momentum30":0.1968063331671054,"momentum60":1.5510202816741885,"spot_twap_gap":0.5591171144233783,"range60":1.6462258454949912,"final_mean":85729.93275409243,"final_z":0.37783033568448,"final_up_prob":0.6472216816721843,"final_drift_up_prob":0.8172282037717085,"final_known_seconds":0,"final_sd":69.87101922117948,"final_drift_shift":36.82356808324866},"entry_side":null,"context_gap":null,"book_errors":[null,null],"books":[{"bid":0.63,"ask":0.64,"asks":[[0.64,1070.0]],"received_ms":1790000870042,"observed_ms":1790000870033,"hash":"0d27f30ce0281f4f60846ccb5b78a2c9c52569cb"},{"bid":0.36,"ask":0.37,"asks":[[0.37,80.0]],"received_ms":1790000870041,"observed_ms":1790000870033,"hash":"28dc2dbbf2fdb096a2a2bb602d73c0edf4f29f98"}],"intents":{"pair_fast":null,"pair_250":null,"pair_add_fast":null,"pair_add_250":null},"decision_ms":1790000870043,"feature_cutoff_ms":1790000870042,"request_ms":1790000870011,"inventory":{"pair_fast":{"qty":[0.0,0.0],"cash":0.0,"lots":[[],[]],"floor":0.0},"pair_250":{"qty":[0.0,0.0],"cash":0.0,"lots":[[],[]],"floor":0.0},"pair_add_fast":{"qty":[0.0,0.0],"cash":0.0,"lots":[[],[]],"floor":0.0},"pair_add_250":{"qty":[0.0,0.0],"cash":0.0,"lots":[[],[]],"floor":0.0}}}
{"kind":"decision","recorded_ms":1790000880061,"S":1790000700,"age":180,"signal":{},"entry_side":null,"context_gap":"incomplete or stale context","book_errors":[null,null],"books":[{"bid":0.69,"ask":0.7,"asks":[[0.7,277.71]],"received_ms":1790000880042,"observed_ms":1790000880032,"hash":"ebf8cfa263bae89d3c4beb903f8451db29a2d6c5"},{"bid":0.3,"ask":0.31,"asks":[[0.31,426.77]],"received_ms":1790000880060,"observed_ms":1790000880049,"hash":"5e775219c759d72caaeb3074aacbc03513efd33c"}],"intents":{"pair_fast":null,"pair_250":null,"pair_add_fast":null,"pair_add_250":null},"decision_ms":1790000880061,"feature_cutoff_ms":1790000880060,"request_ms":1790000880014,"inventory":{"pair_fast":{"qty":[0.0,0.0],"cash":0.0,"lots":[[],[]],"floor":0.0},"pair_250":{"qty":[0.0,0.0],"cash":0.0,"lots":[[],[]],"floor":0.0},"pair_add_fast":{"qty":[0.0,0.0],"cash":0.0,"lots":[[],[]],"floor":0.0},"pair_add_250":{"qty":[0.0,0.0],"cash":0.0,"lots":[[],[]],"floor":0.0}}}
{"kind":"decision","recorded_ms":1790000890042,"S":1790000700,"age":190,"signal":{"rsi14":80.50659980827373,"volume_ratio":1.269911837502176,"taker_buy_fraction":0.44993185675188707,"volume5":216.98408,"return1":6.825123497653517,"return5":13.819330013787766,"return15":58.69163093864828,"bollinger_z":1.7137726225192573,"bar_close_ms":1790000879999,"ref":85703.53336344547,"reference_received_ms":1790000701043,"spot":85738.098252649,"twap":85719.07168627298,"sigma":5.345112254527076,"spot_z":0.6166843791018872,"twap_z":0.27722469783545317,"momentum":0.3327970437408211,"decision_ms":1790000890041,"momentum30":0.4047426752741187,"momentum60":1.2758616686115651,"spot_twap_gap":0.45954491506036604,"range60":1.2758616686115651,"final_mean":85738.098252649,"final_z":0.77313714964824,"final_up_prob":0.7802793913549473,"final_drift_up_prob":0.9623964927537992,"final_known_seconds":0,"final_sd":44.707319030330474,"final_drift_shift":44.97836296605934},"entry_side":null,"context_gap":null,"book_errors":[null,null],"books":[{"bid":0.73,"ask":0.74,"asks":[[0.74,1483.22]],"received_ms":1790000890040,"observed_ms":1790000890028,"hash":"b8666a1fdc2e49fbb94b31172ae2bd5429b6d01c"},{"bid":0.26,"ask":0.27,"asks":[[0.27,199.1]],"received_ms":1790000890041,"observed_ms":1790000890028,"hash":"d40e14bf5d75e88b29406d862b48827595f9e59d"}],"intents":{"pair_fast":null,"pair_250":null,"pair_add_fast":null,"pair_add_250":null},"decision_ms":1790000890042,"feature_cutoff_ms":1790000890041,"request_ms":1790000890005,"inventory":{"pair_fast":{"qty":[0.0,0.0],"cash":0.0,"lots":[[],[]],"floor":0.0},"pair_250":{"qty":[0.0,0.0],"cash":0.0,"lots":[[],[]],"floor":0.0},"pair_add_fast":{"qty":[0.0,0.0],"cash":0.0,"lots":[[],[]],"floor":0.0},"pair_add_250":{"qty":[0.0,0.0],"cash":0.0,"lots":[[],[]],"floor":0.0}}}
{"kind":"decision","recorded_ms":1790000900057,"S":1790000700,"age":200,"signal":{"rsi14":80.50659980827373,"volume_ratio":1.269911837502176,"taker_buy_fraction":0.44993185675188707,"volume5":216.98408,"return1":6.825123497653517,"return5":13.819330013787766,"return15":58.69163093864828,"bollinger_z":1.7137726225192573,"bar_close_ms":1790000879999,"ref":85703.53336344547,"reference_received_ms":1790000701043,"spot":85740.50292714787,"twap":85727.81517825375,"sigma":3.520527872048241,"spot_z":1.0504083726316764,"twap_z":0.6899140542372107,"momentum":0.24374877367344808,"decision_ms":1790000900056,"momentum30":0.6571460048743227,"momentum60":0.6788147196850032,"spot_twap_gap":0.46526583468685484,"range60":0.6816581422763446,"final_mean":85740.50292714787,"final_z":1.356324724084049,"final_up_prob":0.912502063854193,"final_drift_up_prob":0.9799473462273902,"final_known_seconds":0,"final_sd":27.257162717699547,"final_drift_shift":18.980195952393792},"entry_side":null,"context_gap":null,"book_errors":[null,null],"books":[{"bid":0.76,"ask":0.77,"asks":[[0.77,298.5]],"received_ms":1790000900056,"observed_ms":1790000900041,"hash":"1e74dcb806085d7091572d1b9d7fcdcddf12aaf0"},{"bid":0.23,"ask":0.24,"asks":[[0.24,351.83]],"received_ms":1790000900042,"observed_ms":1790000900035,"hash":"801b16362e90a96835a24b8ba02e6ef2a8234b87"}],"intents":{"pair_fast":null,"pair_250":null,"pair_add_fast":null,"pair_add_250":null},"decision_ms":1790000900057,"feature_cutoff_ms":1790000900056,"request_ms":1790000900015,"inventory":{"pair_fast":{"qty":[0.0,0.0],"cash":0.0,"lots":[[],[]],"floor":0.0},"pair_250":{"qty":[0.0,0.0],"cash":0.0,"lots":[[],[]],"floor":0.0},"pair_add_fast":{"qty":[0.0,0.0],"cash":0.0,"lots":[[],[]],"floor":0.0},"pair_add_250":{"qty":[0.0,0.0],"cash":0.0,"lots":[[],[]],"floor":0.0}}}
{"kind":"decision","recorded_ms":1790000910068,"S":1790000700,"age":210,"signal":{"rsi14":80.50659980827373,"volume_ratio":1.269911837502176,"taker_buy_fraction":0.44993185675188707,"volume5":216.98408,"return1":6.825123497653517,"return5":13.819330013787766,"return15":58.69163093864828,"bollinger_z":1.7137726225192573,"bar_close_ms":1790000879999,"ref":85703.53336344547,"reference_received_ms":1790000701043,"spot":85749.47611800357,"twap":85732.43035478008,"sigma":3.2875982510037947,"spot_z":1.4735970686355242,"twap_z":0.9268604404034079,"momentum":0.8922368156045701,"decision_ms":1790000910067,"momentum30":0.9442506683868337,"momentum60":0.9304309104508165,"spot_twap_gap":0.6693635905564732,"range60":1.2202173730394617,"final_mean":85749.47611800357,"final_z":1.9776273494145533,"final_up_prob":0.9760146192100259,"final_drift_up_prob":0.9999938070013819,"final_known_seconds":0,"final_sd":23.231249593963717,"final_drift_shift":55.59361277932198},"entry_side":null,"context_gap":null,"book_errors":[null,null],"books":[{"bid":0.85,"ask":0.86,"asks":[[0.86,1246.33]],"received_ms":1790000910067,"observed_ms":1790000910053,"hash":"b0a3bd1313fcbbd8e66f8352224f0170b71f7de5"},{"bid":0.14,"ask":0.15,"asks":[[0.15,40.0]],"received_ms":1790000910065,"observed_ms":1790000910053,"hash":"00daf74b7ae00fb4ab1b8b13194ba9f4f7bf6ada"}],"intents":{"pair_fast":null,"pair_250":null,"pair_add_fast":null,"pair_add_250":null},"decision_ms":1790000910068,"feature_cutoff_ms":1790000910067,"request_ms":1790000910029,"inventory":{"pair_fast":{"qty":[0.0,0.0],"cash":0.0,"lots":[[],[]],"floor":0.0},"pair_250":{"qty":[0.0,0.0],"cash":0.0,"lots":[[],[]],"floor":0.0},"pair_add_fast":{"qty":[0.0,0.0],"cash":0.0,"lots":[[],[]],"floor":0.0},"pair_add_250":{"qty":[0.0,0.0],"cash":0.0,"lots":[[],[]],"floor":0.0}}}
{"kind":"decision","recorded_ms":1790000920068,"S":1790000700,"age":220,"signal":{"rsi14":80.50659980827373,"volume_ratio":1.269911837502176,"taker_buy_fraction":0.44993185675188707,"volume5":216.98408,"return1":6.825123497653517,"return5":13.819330013787766,"return15":58.69163093864828,"bollinger_z":1.7137726225192573,"bar_close_ms":1790000879999,"ref":85703.53336344547,"reference_received_ms":1790000701043,"spot":85735.52128481762,"twap":85735.88170779875,"sigma":3.8632212519149367,"spot_z":0.926133047648552,"twap_z":0.936568225041753,"momentum":-1.7824858699333075,"decision_ms":1790000920067,"momentum30":-0.10718541347551201,"momentum60":0.3098621859977957,"spot_twap_gap":-0.01204445817353065,"range60":1.1824129942322334,"final_mean":85735.52128481762,"final_z":1.310299178641158,"final_up_prob":0.9049526773867078,"final_drift_up_prob":0.0008342004394335523,"final_known_seconds":0,"final_sd":24.412685204699816,"final_drift_shift":-108.73349245536964},"entry_side":1,"context_gap":null,"book_errors":[null,null],"books":[{"bid":0.66,"ask":0.67,"asks":[[0.67,535.0]],"received_ms":1790000920066,"observed_ms":1790000920056,"hash":"1dddb0b1f8cbfcc721467644bc4b25a365d33ed8"},{"bid":0.33,"ask":0.34,"asks":[[0.34,147.0]],"received_ms":1790000920067,"observed_ms":1790000920058,"hash":"04b08bc52bca70261627f77bbc358fc3a926c91d"}],"intents":{"pair_fast":null,"pair_250":null,"pair_add_fast":null,"pair_add_250":null},"decision_ms":1790000920068,"feature_cutoff_ms":1790000920067,"request_ms":1790000920042,"inventory":{"pair_fast":{"qty":[0.0,0.0],"cash":0.0,"lots":[[],[]],"floor":0.0},"pair_250":{"qty":[0.0,0.0],"cash":0.0,"lots":[[],[]],"floor":0.0},"pair_add_fast":{"qty":[0.0,0.0],"cash":0.0,"lots":[[],[]],"floor":0.0},"pair_add_250":{"qty":[0.0,0.0],"cash":0.0,"lots":[[],[]],"floor":0.0}}}
{"kind":"decision","recorded_ms":1790000930074,"S":1790000700,"age":230,"signal":{"rsi14":80.50659980827373,"volume_ratio":1.269911837502176,"taker_buy_fraction":0.44993185675188707,"volume5":216.98408,"return1":6.825123497653517,"return5":13.819330013787766,"return15":58.69163093864828,"bollinger_z":1.7137726225192573,"bar_close_ms":1790000879999,"ref":85703.53336344547,"reference_received_ms":1790000701043,"spot":85693.86371789846,"twap":85735.28877551398,"sigma":5.449814219731469,"spot_z":-0.21218095930148403,"twap_z":0.6968087674935346,"momentum":-1.7478388555356796,"decision_ms":1790000930073,"momentum30":-1.5523167278624523,"momentum60":-0.8046519980629859,"spot_twap_gap":-0.9813090366744437,"range60":1.502660863659761,"final_mean":85693.86371789846,"final_z":-0.3243375747099746,"final_up_prob":0.37284123768090954,"final_drift_up_prob":6.5525441756419944e-06,"final_known_seconds":0,"final_sd":29.813522394545057,"final_drift_shift":-120.26791106608061},"entry_side":null,"context_gap":null,"book_errors":[null,null],"books":[{"bid":0.38,"ask":0.4,"asks":[[0.4,25.0]],"received_ms":1790000930072,"observed_ms":1790000930064,"hash":"b0ac2a13dbc17d90ed82cb21a3cd75da7f8a90be"},{"bid":0.6,"ask":0.62,"asks":[[0.62,251.0]],"received_ms":1790000930068,"observed_ms":1790000930059,"hash":"3e9f5ec93bf202ba056a9f1d5619570a8cf07050"}],"intents":{"pair_fast":null,"pair_250":null,"pair_add_fast":null,"pair_add_250":null},"decision_ms":1790000930074,"feature_cutoff_ms":1790000930073,"request_ms":1790000930041,"inventory":{"pair_fast":{"qty":[0.0,0.0],"cash":0.0,"lots":[[],[]],"floor":0.0},"pair_250":{"qty":[0.0,0.0],"cash":0.0,"lots":[[],[]],"floor":0.0},"pair_add_fast":{"qty":[0.0,0.0],"cash":0.0,"lots":[[],[]],"floor":0.0},"pair_add_250":{"qty":[0.0,0.0],"cash":0.0,"lots":[[],[]],"floor":0.0}}}
{"kind":"decision","recorded_ms":1790000940094,"S":1790000700,"age":240,"signal":{"rsi14":80.50659980827373,"volume_ratio":1.269911837502176,"taker_buy_fraction":0.44993185675188707,"volume5":216.98408,"return1":6.825123497653517,"return5":13.819330013787766,"return15":58.69163093864828,"bollinger_z":1.7137726225192573,"bar_close_ms":1790000879999,"ref":85703.53336344547,"reference_received_ms":1790000701043,"spot":85690.81607723967,"twap":85729.99789088922,"sigma":5.106283161058532,"spot_z":-0.32177386342055236,"twap_z":0.6696077371669344,"momentum":-0.46865013086927376,"decision_ms":1790000940093,"momentum30":-2.3770186089645575,"momentum60":-1.053191731944812,"spot_twap_gap":-0.9906129824279579,"range60":1.680805977405453,"final_mean":85690.81607723967,"final_z":-0.5581938799026612,"final_up_prob":0.28835599977613713,"final_drift_up_prob":0.06038135591349458,"final_known_seconds":0,"final_sd":22.782919454481565,"final_drift_shift":-22.632239756030817},"entry_side":null,"context_gap":null,"book_errors":[null,null],"books":[{"bid":0.42,"ask":0.43,"asks":[[0.43,164.31]],"received_ms":1790000940093,"observed_ms":1790000940077,"hash":"c997ad8a25fec923312f90fe0c9247bfefcbaa33"},{"bid":0.57,"ask":0.58,"asks":[[0.58,70.0]],"received_ms":1790000940086,"observed_ms":1790000940077,"hash":"f3f219560b6b42e1c5a7eb897aed289db49271a0"}],"intents":{"pair_fast":null,"pair_250":null,"pair_add_fast":null,"pair_add_250":null},"decision_ms":1790000940094,"feature_cutoff_ms":1790000940093,"request_ms":1790000940047,"inventory":{"pair_fast":{"qty":[0.0,0.0],"cash":0.0,"lots":[[],[]],"floor":0.0},"pair_250":{"qty":[0.0,0.0],"cash":0.0,"lots":[[],[]],"floor":0.0},"pair_add_fast":{"qty":[0.0,0.0],"cash":0.0,"lots":[[],[]],"floor":0.0},"pair_add_250":{"qty":[0.0,0.0],"cash":0.0,"lots":[[],[]],"floor":0.0}}}
{"kind":"decision","recorded_ms":1790000950069,"S":1790000700,"age":250,"signal":{"rsi14":75.19353326491478,"volume_ratio":1.2307474464911696,"taker_buy_fraction":0.41106826718571454,"volume5":219.4788,"return1":-4.337402301997243,"return5":-1.0464362197125445,"return15":53.57706781104964,"bollinger_z":1.367318847243681,"bar_close_ms":1790000939999,"ref":85703.53336344547,"reference_received_ms":1790000701043,"spot":85721.8498483765,"twap":85725.31276325531,"sigma":5.810888992246948,"spot_z":0.4460772486429884,"twap_z":0.5304126190615182,"momentum":1.7060547791287453,"decision_ms":1790000950068,"momentum30":-0.06710600805194433,"momentum60":-0.35412383850551477,"spot_twap_gap":-0.07693493871506855,"range60":1.4840203718788088,"final_mean":85720.11474515354,"final_z":0.8404687571348245,"final_up_prob":0.7996771940273095,"final_drift_up_prob":0.999982784154436,"final_known_seconds":10,"final_sd":19.728730624788117,"final_drift_shift":65.1346714684808},"entry_side":null,"context_gap":null,"book_errors":[null,null],"books":[{"bid":0.6,"ask":0.61,"asks":[[0.61,20.83]],"received_ms":1790000950067,"observed_ms":1790000950060,"hash":"3dfcec23b25efbae35e363d2d079088c366f816c"},{"bid":0.39,"ask":0.4,"asks":[[0.4,406.0]],"received_ms":1790000950064,"observed_ms":1790000950056,"hash":"9ae955cd3ec4f147b2cf12fe4dbc3f26fe25b02c"}],"intents":{"pair_fast":null,"pair_250":null,"pair_add_fast":null,"pair_add_250":null},"decision_ms":1790000950069,"feature_cutoff_ms":1790000950068,"request_ms":1790000950038,"inventory":{"pair_fast":{"qty":[0.0,0.0],"cash":0.0,"lots":[[],[]],"floor":0.0},"pair_250":{"qty":[0.0,0.0],"cash":0.0,"lots":[[],[]],"floor":0.0},"pair_add_fast":{"qty":[0.0,0.0],"cash":0.0,"lots":[[],[]],"floor":0.0},"pair_add_250":{"qty":[0.0,0.0],"cash":0.0,"lots":[[],[]],"floor":0.0}}}
{"kind":"decision","recorded_ms":1790000960083,"S":1790000700,"age":260,"signal":{"rsi14":75.19353326491478,"volume_ratio":1.2307474464911696,"taker_buy_fraction":0.41106826718571454,"volume5":219.4788,"return1":-4.337402301997243,"return5":-1.0464362197125445,"return15":53.57706781104964,"bollinger_z":1.367318847243681,"bar_close_ms":1790000939999,"ref":85703.53336344547,"reference_received_ms":1790000701043,"spot":85723.38599696684,"twap":85722.1661325929,"sigma":5.947965204777771,"spot_z":0.5282813993017585,"twap_z":0.495820634953824,"momentum":0.5912516181780144,"decision_ms":1790000960082,"momentum30":0.7674544869883706,"momentum60":-0.3649481370542236,"spot_twap_gap":0.026476922455788178,"range60":1.4498197864866267,"final_mean":85720.32196819587,"final_z":1.1630674531715202,"final_up_prob":0.8775989320235648,"final_drift_up_prob":0.9855956749649764,"final_known_seconds":20,"final_sd":14.43476447098548,"final_drift_shift":14.767162802925332},"entry_side":null,"context_gap":null,"book_errors":[null,null],"books":[{"bid":0.93,"ask":0.94,"asks":[[0.94,50.68]],"received_ms":1790000960080,"observed_ms":1790000960066,"hash":"e5667dbb8b76df0800423eb7f6ebf4fb23f8bbfb"},{"bid":0.06,"ask":0.07,"asks":[[0.07,1256.0]],"received_ms":1790000960082,"observed_ms":1790000960066,"hash":"5c04e1826af15afeaeadfd7ac412f6d28943cc27"}],"intents":{"pair_fast":null,"pair_250":null,"pair_add_fast":null,"pair_add_250":null},"decision_ms":1790000960083,"feature_cutoff_ms":1790000960082,"request_ms":1790000960042,"inventory":{"pair_fast":{"qty":[0.0,0.0],"cash":0.0,"lots":[[],[]],"floor":0.0},"pair_250":{"qty":[0.0,0.0],"cash":0.0,"lots":[[],[]],"floor":0.0},"pair_add_fast":{"qty":[0.0,0.0],"cash":0.0,"lots":[[],[]],"floor":0.0},"pair_add_250":{"qty":[0.0,0.0],"cash":0.0,"lots":[[],[]],"floor":0.0}}}
{"kind":"decision","recorded_ms":1790000970055,"S":1790000700,"age":270,"signal":{"rsi14":75.19353326491478,"volume_ratio":1.2307474464911696,"taker_buy_fraction":0.41106826718571454,"volume5":219.4788,"return1":-4.337402301997243,"return5":-1.0464362197125445,"return15":53.57706781104964,"bollinger_z":1.367318847243681,"bar_close_ms":1790000939999,"ref":85703.53336344547,"reference_received_ms":1790000701043,"spot":85704.61807373143,"twap":85719.90122675497,"sigma":7.116064038842871,"spot_z":0.027855085758471114,"twap_z":0.4203225894253102,"momentum":-1.5160327679555596,"decision_ms":1790000970054,"momentum30":0.36222231836272495,"momentum60":-0.9557026380139586,"spot_twap_gap":-0.27726655641199754,"range60":1.211832495625354,"final_mean":85711.7795382731,"final_z":0.7348798434322965,"final_up_prob":0.7687936624356174,"final_drift_up_prob":0.06213174930918819,"final_known_seconds":30,"final_sd":11.221119889628893,"final_drift_shift":-25.49440222677046},"entry_side":null,"context_gap":null,"book_errors":[null,null],"books":[{"bid":0.4,"ask":0.41,"asks":[[0.41,40.0]],"received_ms":1790000970054,"observed_ms":1790000970035,"hash":"aa265611c9cc4cb0eed811985840aa0bdc1577e1"},{"bid":0.59,"ask":0.6,"asks":[[0.6,378.85]],"received_ms":1790000970041,"observed_ms":1790000970029,"hash":"d0dcdabcdf91ff7738f657fe1234dada62acbb14"}],"intents":{"pair_fast":null,"pair_250":null,"pair_add_fast":null,"pair_add_250":null},"decision_ms":1790000970055,"feature_cutoff_ms":1790000970054,"request_ms":1790000970004,"inventory":{"pair_fast":{"qty":[0.0,0.0],"cash":0.0,"lots":[[],[]],"floor":0.0},"pair_250":{"qty":[0.0,0.0],"cash":0.0,"lots":[[],[]],"floor":0.0},"pair_add_fast":{"qty":[0.0,0.0],"cash":0.0,"lots":[[],[]],"floor":0.0},"pair_add_250":{"qty":[0.0,0.0],"cash":0.0,"lots":[[],[]],"floor":0.0}}}
{"kind":"decision","recorded_ms":1790000980069,"S":1790000700,"age":280,"signal":{"rsi14":75.19353326491478,"volume_ratio":1.2307474464911696,"taker_buy_fraction":0.41106826718571454,"volume5":219.4788,"return1":-4.337402301997243,"return5":-1.0464362197125445,"return15":53.57706781104964,"bollinger_z":1.367318847243681,"bar_close_ms":1790000939999,"ref":85703.53336344547,"reference_received_ms":1790000701043,"spot":85691.70047967492,"twap":85710.39792543113,"sigma":7.984683960187934,"spot_z":-0.33193834867423877,"twap_z":0.19256602313304183,"momentum":0.25233615895336153,"decision_ms":1790000980068,"momentum30":-0.47022078968322656,"momentum60":-0.5219993597355287,"spot_twap_gap":-0.30230750267827156,"range60":0.8634607837556934,"final_mean":85704.22128155203,"final_z":0.10061542639552896,"final_up_prob":0.5400721248199707,"final_drift_up_prob":0.6587804429673435,"final_known_seconds":40,"final_sd":6.837103724585845,"final_drift_shift":2.109394098410247},"entry_side":null,"context_gap":null,"book_errors":[null,null],"books":[{"bid":0.72,"ask":0.73,"asks":[[0.73,37.0]],"received_ms":1790000980067,"observed_ms":1790000980058,"hash":"b3f0a89e6a7246f269c391cb9b0674945aed35c8"},{"bid":0.27,"ask":0.28,"asks":[[0.28,232.39]],"received_ms":1790000980059,"observed_ms":1790000980049,"hash":"218cb0d57949ae596b1bcf83f945fa3d4dce5ea0"}],"intents":{"pair_fast":null,"pair_250":null,"pair_add_fast":null,"pair_add_250":null},"decision_ms":1790000980069,"feature_cutoff_ms":1790000980068,"request_ms":1790000980027,"inventory":{"pair_fast":{"qty":[0.0,0.0],"cash":0.0,"lots":[[],[]],"floor":0.0},"pair_250":{"qty":[0.0,0.0],"cash":0.0,"lots":[[],[]],"floor":0.0},"pair_add_fast":{"qty":[0.0,0.0],"cash":0.0,"lots":[[],[]],"floor":0.0},"pair_add_250":{"qty":[0.0,0.0],"cash":0.0,"lots":[[],[]],"floor":0.0}}}
{"kind":"decision","recorded_ms":1790000990070,"S":1790000700,"age":290,"signal":{"rsi14":75.19353326491478,"volume_ratio":1.2307474464911696,"taker_buy_fraction":0.41106826718571454,"volume5":219.4788,"return1":-4.337402301997243,"return5":-1.0464362197125445,"return15":53.57706781104964,"bollinger_z":1.367318847243681,"bar_close_ms":1790000939999,"ref":85703.53336344547,"reference_received_ms":1790000701043,"spot":85697.36821983093,"twap":85705.24186876774,"sigma":7.62170377815936,"spot_z":-0.25668154297848306,"twap_z":0.0711324520116881,"momentum":0.2417265812625804,"decision_ms":1790000990069,"momentum30":-0.9908806003772408,"momentum60":-0.017198883273864082,"spot_twap_gap":-0.1333669920084407,"range60":0.9045827115535573,"final_mean":85705.93732052222,"final_z":1.0473625682891958,"final_up_prob":0.8525338055932472,"final_drift_up_prob":0.8954384709635332,"final_known_seconds":50,"final_sd":2.2952482259088045,"final_drift_shift":0.4788298240840364},"entry_side":null,"context_gap":null,"book_errors":[null,null],"books":[{"bid":0.92,"ask":0.93,"asks":[[0.93,68.29]],"received_ms":1790000990069,"observed_ms":1790000990060,"hash":"fc0d72358c9598ee67d4a0da2c7b414d01b91edd"},{"bid":0.07,"ask":0.08,"asks":[[0.08,145.0]],"received_ms":1790000990069,"observed_ms":1790000990059,"hash":"a887326701573e25e5d3b54cfaa27db754d5fd79"}],"intents":{"pair_fast":null,"pair_250":null,"pair_add_fast":null,"pair_add_250":null},"decision_ms":1790000990070,"feature_cutoff_ms":1790000990069,"request_ms":1790000990041,"inventory":{"pair_fast":{"qty":[0.0,0.0],"cash":0.0,"lots":[[],[]],"floor":0.0},"pair_250":{"qty":[0.0,0.0],"cash":0.0,"lots":[[],[]],"floor":0.0},"pair_add_fast":{"qty":[0.0,0.0],"cash":0.0,"lots":[[],[]],"floor":0.0},"pair_add_250":{"qty":[0.0,0.0],"cash":0.0,"lots":[[],[]],"floor":0.0}}}
{"kind":"decision","recorded_ms":1790001030101,"S":1790001000,"age":30,"signal":{"rsi14":74.20081697193278,"volume_ratio":0.8014460171451633,"taker_buy_fraction":0.35966209103694496,"volume5":216.99454,"return1":0.3744631528265088,"return5":0.697598023020726,"return15":46.7670647874909,"bollinger_z":1.2533174261084319,"bar_close_ms":1790000999999,"ref":85705.48944666714,"reference_received_ms":1790001001829,"spot":85630.36102253466,"twap":85679.47877123454,"sigma":6.434994875555519,"spot_z":-0.7106481529173669,"twap_z":-0.2460378833411201,"momentum":-0.18147447952167187,"decision_ms":1790001030100,"momentum30":-1.780334823439666,"momentum60":-1.1027734058763994,"spot_twap_gap":-0.9854046837989046,"range60":1.391427568088753,"final_mean":85630.36102253466,"final_z":-0.7699926652345771,"final_up_prob":0.22065212180174643,"final_drift_up_prob":0.046676209648788214,"final_known_seconds":0,"final_sd":97.57031141275596,"final_drift_shift":-88.5918994051049},"entry_side":null,"context_gap":null,"book_errors":[null,null],"books":[{"bid":0.29,"ask":0.3,"asks":[[0.3,445.0]],"received_ms":1790001030100,"observed_ms":1790001030077,"hash":"4118135ef66c1349e8c1a275f63e5b4350a10d00"},{"bid":0.7,"ask":0.71,"asks":[[0.71,1570.58]],"received_ms":1790001030040,"observed_ms":1790001030030,"hash":"654d377df042dcb9c7001e101b9d81d3c6608387"}],"intents":{"pair_fast":null,"pair_250":null,"pair_add_fast":null,"pair_add_250":null},"decision_ms":1790001030101,"feature_cutoff_ms":1790001030100,"request_ms":1790001030011,"inventory":{"pair_fast":{"qty":[0.0,0.0],"cash":0.0,"lots":[[],[]],"floor":0.0},"pair_250":{"qty":[0.0,0.0],"cash":0.0,"lots":[[],[]],"floor":0.0},"pair_add_fast":{"qty":[0.0,0.0],"cash":0.0,"lots":[[],[]],"floor":0.0},"pair_add_250":{"qty":[0.0,0.0],"cash":0.0,"lots":[[],[]],"floor":0.0}}}
{"kind":"decision","recorded_ms":1790001040057,"S":1790001000,"age":40,"signal":{"rsi14":74.20081697193278,"volume_ratio":0.8014460171451633,"taker_buy_fraction":0.35966209103694496,"volume5":216.99454,"return1":0.3744631528265088,"return5":0.697598023020726,"return15":46.7670647874909,"bollinger_z":1.2533174261084319,"bar_close_ms":1790000999999,"ref":85705.48944666714,"reference_received_ms":1790001001829,"spot":85611.60787819292,"twap":85671.47777588862,"sigma":8.148571232204114,"spot_z":-0.7145933520329676,"twap_z":-0.25888482931066237,"momentum":-0.7242988183824126,"decision_ms":1790001040056,"momentum30":-1.0205365347645574,"momentum60":-1.2664144982974355,"spot_twap_gap":-0.9485307714566779,"range60":1.3751854557830752,"final_mean":85611.60787819292,"final_z":-0.7768600900252053,"final_up_prob":0.21862065989731205,"final_drift_up_prob":7.51900236861669e-06,"final_known_seconds":0,"final_sd":120.84745976739374,"final_drift_shift":-429.16206364385243},"entry_side":null,"context_gap":null,"book_errors":[null,null],"books":[{"bid":0.2,"ask":0.21,"asks":[[0.21,236.03]],"received_ms":1790001040052,"observed_ms":1790001040043,"hash":"110bb0e41c6fbdea6b20e34ddc30d170b5edfe0d"},{"bid":0.79,"ask":0.8,"asks":[[0.8,2414.34]],"received_ms":1790001040055,"observed_ms":1790001040043,"hash":"6e17f8f0569a60168a41939efd3cc5a70d26c82a"}],"intents":{"pair_fast":null,"pair_250":null,"pair_add_fast":null,"pair_add_250":null},"decision_ms":1790001040057,"feature_cutoff_ms":1790001040056,"request_ms":1790001040026,"inventory":{"pair_fast":{"qty":[0.0,0.0],"cash":0.0,"lots":[[],[]],"floor":0.0},"pair_250":{"qty":[0.0,0.0],"cash":0.0,"lots":[[],[]],"floor":0.0},"pair_add_fast":{"qty":[0.0,0.0],"cash":0.0,"lots":[[],[]],"floor":0.0},"pair_add_250":{"qty":[0.0,0.0],"cash":0.0,"lots":[[],[]],"floor":0.0}}}
{"kind":"decision","recorded_ms":1790001050082,"S":1790001000,"age":50,"signal":{"rsi14":74.20081697193278,"volume_ratio":0.8014460171451633,"taker_buy_fraction":0.35966209103694496,"volume5":216.99454,"return1":0.3744631528265088,"return5":0.697598023020726,"return15":46.7670647874909,"bollinger_z":1.2533174261084319,"bar_close_ms":1790000999999,"ref":85705.48944666714,"reference_received_ms":1790001001829,"spot":85602.50662108141,"twap":85655.88290817763,"sigma":9.882821524798025,"spot_z":-0.6591499355969959,"twap_z":-0.3175106768004458,"momentum":0.3030362520884459,"decision_ms":1790001050081,"momentum30":-0.5828008723250087,"momentum60":-1.2376499838332873,"spot_twap_gap":-0.6972552338666428,"range60":1.4369571936946253,"final_mean":85602.50662108141,"final_z":-0.7192137419170518,"final_up_prob":0.23600461682223206,"final_drift_up_prob":0.7689354983203709,"final_known_seconds":0,"final_sd":143.18806716794558,"final_drift_shift":208.27555018464298},"entry_side":null,"context_gap":null,"book_errors":[null,null],"books":[{"bid":0.25,"ask":0.26,"asks":[[0.26,276.68]],"received_ms":1790001050081,"observed_ms":1790001050058,"hash":"ee49cd41dda24ee1f0ccda503f5d4423df20d0aa"},{"bid":0.74,"ask":0.75,"asks":[[0.75,1991.17]],"received_ms":1790001050061,"observed_ms":1790001050043,"hash":"e4bad55d2759165cbcfd25be95a99a9e620a47b5"}],"intents":{"pair_fast":null,"pair_250":null,"pair_add_fast":null,"pair_add_250":null},"decision_ms":1790001050082,"feature_cutoff_ms":1790001050081,"request_ms":1790001050034,"inventory":{"pair_fast":{"qty":[0.0,0.0],"cash":0.0,"lots":[[],[]],"floor":0.0},"pair_250":{"qty":[0.0,0.0],"cash":0.0,"lots":[[],[]],"floor":0.0},"pair_add_fast":{"qty":[0.0,0.0],"cash":0.0,"lots":[[],[]],"floor":0.0},"pair_add_250":{"qty":[0.0,0.0],"cash":0.0,"lots":[[],[]],"floor":0.0}}}
{"kind":"decision","recorded_ms":1790001060035,"S":1790001000,"age":60,"signal":{"rsi14":74.20081697193278,"volume_ratio":0.8014460171451633,"taker_buy_fraction":0.35966209103694496,"volume5":216.99454,"return1":0.3744631528265088,"return5":0.697598023020726,"return15":46.7670647874909,"bollinger_z":1.2533174261084319,"bar_close_ms":1790000999999,"ref":85705.48944666714,"reference_received_ms":1790001001829,"spot":85601.33197888883,"twap":85640.00651014208,"sigma":10.013944921124912,"spot_z":-0.6714448674849699,"twap_z":-0.4221318218985624,"momentum":-0.05553687838406909,"decision_ms":1790001060034,"momentum30":-0.5276277807468699,"momentum60":-1.1832063977022043,"spot_twap_gap":-0.4985907706569311,"range60":1.36476041492501,"final_mean":85601.33197888883,"final_z":-0.7355414217809848,"final_up_prob":0.23100491146961555,"final_drift_up_prob":0.1595501959559183,"final_known_seconds":0,"final_sd":141.606529141632,"final_drift_shift":-36.926286803759474},"entry_side":null,"context_gap":null,"book_errors":[null,null],"books":[{"bid":0.24,"ask":0.25,"asks":[[0.25,590.9]],"received_ms":1790001060032,"observed_ms":1790001060023,"hash":"e1202fd07d686c9c6a1808bf93437801bed4fe22"},{"bid":0.75,"ask":0.76,"asks":[[0.76,492.56]],"received_ms":1790001060033,"observed_ms":1790001060022,"hash":"cee00557f343acfa5f40caaacda8271e0c705deb"}],"intents":{"pair_fast":null,"pair_250":null,"pair_add_fast":null,"pair_add_250":null},"decision_ms":1790001060035,"feature_cutoff_ms":1790001060034,"request_ms":1790001060006,"inventory":{"pair_fast":{"qty":[0.0,0.0],"cash":0.0,"lots":[[],[]],"floor":0.0},"pair_250":{"qty":[0.0,0.0],"cash":0.0,"lots":[[],[]],"floor":0.0},"pair_add_fast":{"qty":[0.0,0.0],"cash":0.0,"lots":[[],[]],"floor":0.0},"pair_add_250":{"qty":[0.0,0.0],"cash":0.0,"lots":[[],[]],"floor":0.0}}}
{"kind":"decision","recorded_ms":1790001070037,"S":1790001000,"age":70,"signal":{"rsi14":62.659553705028436,"volume_ratio":0.9973909313549157,"taker_buy_fraction":0.3875796782722674,"volume5":205.92816,"return1":-10.649114876261386,"return5":-6.821085644505417,"return15":32.24629993181304,"bollinger_z":0.6664459904457244,"bar_close_ms":1790001059999,"ref":85705.48944666714,"reference_received_ms":1790001001829,"spot":85615.6978498723,"twap":85625.75338630221,"sigma":9.31779398801493,"spot_z":-0.6354651226473361,"twap_z":-0.5643009723391953,"momentum":0.4859844288104084,"decision_ms":1790001070035,"momentum30":0.44403827346488267,"momentum60":-0.5744091974257435,"spot_twap_gap":-0.139320977977925,"range60":1.143994481068493,"final_mean":85615.6978498723,"final_z":-0.6991748449517686,"final_up_prob":0.24222138453030184,"final_drift_up_prob":0.9370522308436806,"final_known_seconds":0,"final_sd":128.42509630195542,"final_drift_shift":286.34489571456555},"entry_side":null,"context_gap":null,"book_errors":[null,null],"books":[{"bid":0.25,"ask":0.26,"asks":[[0.26,10.0]],"received_ms":1790001070035,"observed_ms":1790001070025,"hash":"942bda0f3ae98ea0163b029b481a52c90257ee08"},{"bid":0.74,"ask":0.75,"asks":[[0.75,1101.52]],"received_ms":1790001070035,"observed_ms":1790001070025,"hash":"195e5b427e89b9a370d68645e259fd33296cdc87"}],"intents":{"pair_fast":null,"pair_250":null,"pair_add_fast":null,"pair_add_250":null},"decision_ms":1790001070036,"feature_cutoff_ms":1790001070035,"request_ms":1790001070005,"inventory":{"pair_fast":{"qty":[0.0,0.0],"cash":0.0,"lots":[[],[]],"floor":0.0},"pair_250":{"qty":[0.0,0.0],"cash":0.0,"lots":[[],[]],"floor":0.0},"pair_add_fast":{"qty":[0.0,0.0],"cash":0.0,"lots":[[],[]],"floor":0.0},"pair_add_250":{"qty":[0.0,0.0],"cash":0.0,"lots":[[],[]],"floor":0.0}}}
{"kind":"decision","recorded_ms":1790001080072,"S":1790001000,"age":80,"signal":{"rsi14":62.659553705028436,"volume_ratio":0.9973909313549157,"taker_buy_fraction":0.3875796782722674,"volume5":205.92816,"return1":-10.649114876261386,"return5":-6.821085644505417,"return15":32.24629993181304,"bollinger_z":0.6664459904457244,"bar_close_ms":1790001059999,"ref":85705.48944666714,"reference_received_ms":1790001001829,"spot":85626.29457150205,"twap":85616.543997109,"sigma":8.149689562564975,"spot_z":-0.6552616679302542,"twap_z":-0.7359383231652098,"momentum":0.6547341641764591,"decision_ms":1790001080071,"momentum30":0.5198278462185545,"momentum60":-0.12291557252096018,"spot_twap_gap":0.15445910321833506,"range60":0.9460654151483084,"final_mean":85626.29457150205,"final_z":-0.7244450171383185,"final_up_prob":0.23439628554037523,"final_drift_up_prob":0.9863486162018923,"final_known_seconds":0,"final_sd":109.31799279664563,"final_drift_shift":320.4773570996386},"entry_side":null,"context_gap":null,"book_errors":[null,null],"books":[{"bid":0.25,"ask":0.26,"asks":[[0.26,1758.85]],"received_ms":1790001080050,"observed_ms":1790001080041,"hash":"06fc00cb452f384e10bf36e74903da546b2f00e0"},{"bid":0.74,"ask":0.75,"asks":[[0.75,6.3]],"received_ms":1790001080071,"observed_ms":1790001080055,"hash":"7a69d783fba360753dc7cf065c3406b0a4524a34"}],"intents":{"pair_fast":null,"pair_250":null,"pair_add_fast":null,"pair_add_250":null},"decision_ms":1790001080072,"feature_cutoff_ms":1790001080071,"request_ms":1790001080011,"inventory":{"pair_fast":{"qty":[0.0,0.0],"cash":0.0,"lots":[[],[]],"floor":0.0},"pair_250":{"qty":[0.0,0.0],"cash":0.0,"lots":[[],[]],"floor":0.0},"pair_add_fast":{"qty":[0.0,0.0],"cash":0.0,"lots":[[],[]],"floor":0.0},"pair_add_250":{"qty":[0.0,0.0],"cash":0.0,"lots":[[],[]],"floor":0.0}}}
{"kind":"decision","recorded_ms":1790001090095,"S":1790001000,"age":90,"signal":{"rsi14":62.659553705028436,"volume_ratio":0.9973909313549157,"taker_buy_fraction":0.3875796782722674,"volume5":205.92816,"return1":-10.649114876261386,"return5":-6.821085644505417,"return15":32.24629993181304,"bollinger_z":0.6664459904457244,"bar_close_ms":1790001059999,"ref":85705.48944666714,"reference_received_ms":1790001001829,"spot":85613.27908359998,"twap":85613.40610857269,"sigma":8.19900013808549,"spot_z":-0.7762585773988718,"twap_z":-0.7751892374534497,"momentum":-0.4657235523409863,"decision_ms":1790001090094,"momentum30":0.26500945416930655,"momentum60":-0.2675606651171173,"spot_twap_gap":-0.002000104059725572,"range60":0.9403755713484141,"final_mean":85613.27908359998,"final_z":-0.8628086304366427,"final_up_prob":0.194121346618578,"final_drift_up_prob":0.0018928302508966488,"final_known_seconds":0,"final_sd":106.87232349599664,"final_drift_shift":-217.23747314043678},"entry_side":null,"context_gap":null,"book_errors":[null,null],"books":[{"bid":0.22,"ask":0.23,"asks":[[0.23,5.0]],"received_ms":1790001090094,"observed_ms":1790001090083,"hash":"fb15a8be955f1d7765676e708e4bf31b880b0789"},{"bid":0.77,"ask":0.78,"asks":[[0.78,20.0]],"received_ms":1790001090078,"observed_ms":1790001090066,"hash":"109f5c45410bb7d728c87c9bca07238e0a7c75fd"}],"intents":{"pair_fast":null,"pair_250":null,"pair_add_fast":null,"pair_add_250":null},"decision_ms":1790001090095,"feature_cutoff_ms":1790001090094,"request_ms":1790001090047,"inventory":{"pair_fast":{"qty":[0.0,0.0],"cash":0.0,"lots":[[],[]],"floor":0.0},"pair_250":{"qty":[0.0,0.0],"cash":0.0,"lots":[[],[]],"floor":0.0},"pair_add_fast":{"qty":[0.0,0.0],"cash":0.0,"lots":[[],[]],"floor":0.0},"pair_add_250":{"qty":[0.0,0.0],"cash":0.0,"lots":[[],[]],"floor":0.0}}}
{"kind":"decision","recorded_ms":1790001100058,"S":1790001000,"age":100,"signal":{"rsi14":62.659553705028436,"volume_ratio":0.9973909313549157,"taker_buy_fraction":0.3875796782722674,"volume5":205.92816,"return1":-10.649114876261386,"return5":-6.821085644505417,"return15":32.24629993181304,"bollinger_z":0.6664459904457244,"bar_close_ms":1790001059999,"ref":85705.48944666714,"reference_received_ms":1790001001829,"spot":85660.54656967652,"twap":85611.43419841921,"sigma":6.699900423110568,"spot_z":-0.47439306752048477,"twap_z":-0.9927970953449149,"momentum":2.3744549441912897,"decision_ms":1790001100056,"momentum30":1.3931852641199716,"momentum60":1.3008505038489628,"spot_twap_gap":0.9463394178027655,"range60":1.4123557262349782,"final_mean":85660.54656967652,"final_z":-0.5304061432528447,"final_up_prob":0.29791518379532766,"final_drift_up_prob":1.0,"final_known_seconds":0,"final_sd":84.73294957520567,"final_drift_shift":854.9448830449048},"entry_side":null,"context_gap":null,"book_errors":[null,null],"books":[{"bid":0.35,"ask":0.36,"asks":[[0.36,1398.68]],"received_ms":1790001100055,"observed_ms":1790001100037,"hash":"f8c6eef5479df5cbba6e67804e087af956043ada"},{"bid":0.64,"ask":0.65,"asks":[[0.65,57.84]],"received_ms":1790001100056,"observed_ms":1790001100046,"hash":"886d91c761e43a7de3e806a572acb3f7aa255fe3"}],"intents":{"pair_fast":null,"pair_250":null,"pair_add_fast":null,"pair_add_250":null},"decision_ms":1790001100058,"feature_cutoff_ms":1790001100056,"request_ms":1790001100018,"inventory":{"pair_fast":{"qty":[0.0,0.0],"cash":0.0,"lots":[[],[]],"floor":0.0},"pair_250":{"qty":[0.0,0.0],"cash":0.0,"lots":[[],[]],"floor":0.0},"pair_add_fast":{"qty":[0.0,0.0],"cash":0.0,"lots":[[],[]],"floor":0.0},"pair_add_250":{"qty":[0.0,0.0],"cash":0.0,"lots":[[],[]],"floor":0.0}}}
{"kind":"decision","recorded_ms":1790001110069,"S":1790001000,"age":110,"signal":{"rsi14":62.659553705028436,"volume_ratio":0.9973909313549157,"taker_buy_fraction":0.3875796782722674,"volume5":205.92816,"return1":-10.649114876261386,"return5":-6.821085644505417,"return15":32.24629993181304,"bollinger_z":0.6664459904457244,"bar_close_ms":1790001059999,"ref":85705.48944666714,"reference_received_ms":1790001001829,"spot":85673.16345060035,"twap":85623.53569807533,"sigma":6.575722946686655,"spot_z":-0.3567051160305276,"twap_z":-0.9043285577396037,"momentum":0.41207745221363373,"decision_ms":1790001110068,"momentum30":1.3274200264275042,"momentum60":1.3757207638259854,"spot_twap_gap":0.9743286560653623,"range60":1.435029520787781,"final_mean":85673.16345060035,"final_z":-0.4014775283905649,"final_up_prob":0.3440342897615838,"final_drift_up_prob":0.9032940517163298,"final_known_seconds":0,"final_sd":80.51757266809098,"final_drift_shift":137.0432743757213},"entry_side":null,"context_gap":null,"book_errors":[null,null],"books":[{"bid":0.36,"ask":0.37,"asks":[[0.37,108.22]],"received_ms":1790001110058,"observed_ms":1790001110051,"hash":"966b53a8dd37b5b4499311d093fe38ea81950090"},{"bid":0.63,"ask":0.64,"asks":[[0.64,1039.54]],"received_ms":1790001110068,"observed_ms":1790001110056,"hash":"ee7fad748cd01626cbdd4198ed63364de8d1441d"}],"intents":{"pair_fast":null,"pair_250":null,"pair_add_fast":null,"pair_add_250":null},"decision_ms":1790001110069,"feature_cutoff_ms":1790001110068,"request_ms":1790001110032,"inventory":{"pair_fast":{"qty":[0.0,0.0],"cash":0.0,"lots":[[],[]],"floor":0.0},"pair_250":{"qty":[0.0,0.0],"cash":0.0,"lots":[[],[]],"floor":0.0},"pair_add_fast":{"qty":[0.0,0.0],"cash":0.0,"lots":[[],[]],"floor":0.0},"pair_add_250":{"qty":[0.0,0.0],"cash":0.0,"lots":[[],[]],"floor":0.0}}}
{"kind":"decision","recorded_ms":1790001120080,"S":1790001000,"age":120,"signal":{"rsi14":62.659553705028436,"volume_ratio":0.9973909313549157,"taker_buy_fraction":0.3875796782722674,"volume5":205.92816,"return1":-10.649114876261386,"return5":-6.821085644505417,"return15":32.24629993181304,"bollinger_z":0.6664459904457244,"bar_close_ms":1790001059999,"ref":85705.48944666714,"reference_received_ms":1790001001829,"spot":85668.09631133272,"twap":85633.35671612588,"sigma":6.7926572731277854,"spot_z":-0.4104036840382432,"twap_z":-0.7916837700051598,"momentum":-0.16595337607752453,"decision_ms":1790001120079,"momentum30":1.55509526689112,"momentum60":1.268028668717232,"spot_twap_gap":0.660251544572612,"range60":1.3891995679434372,"final_mean":85668.09631133272,"final_z":-0.46538322899148626,"final_up_prob":0.32082852104904913,"final_drift_up_prob":0.1291298280879693,"final_known_seconds":0,"final_sd":80.34912520474035,"final_drift_shift":-53.442684460261354},"entry_side":null,"context_gap":null,"book_errors":[null,null],"books":[{"bid":0.41,"ask":0.42,"asks":[[0.42,1296.56]],"received_ms":1790001120078,"observed_ms":1790001120064,"hash":"0c0306f099c1effc216080998847ad3cb4cb0bf0"},{"bid":0.58,"ask":0.59,"asks":[[0.59,76.0]],"received_ms":1790001120079,"observed_ms":1790001120064,"hash":"6e8578dbebbee0090c37a9677a8eda23253900d0"}],"intents":{"pair_fast":null,"pair_250":null,"pair_add_fast":null,"pair_add_250":null},"decision_ms":1790001120080,"feature_cutoff_ms":1790001120079,"request_ms":1790001120043,"inventory":{"pair_fast":{"qty":[0.0,0.0],"cash":0.0,"lots":[[],[]],"floor":0.0},"pair_250":{"qty":[0.0,0.0],"cash":0.0,"lots":[[],[]],"floor":0.0},"pair_add_fast":{"qty":[0.0,0.0],"cash":0.0,"lots":[[],[]],"floor":0.0},"pair_add_250":{"qty":[0.0,0.0],"cash":0.0,"lots":[[],[]],"floor":0.0}}}
{"kind":"decision","recorded_ms":1790001130096,"S":1790001000,"age":130,"signal":{},"entry_side":null,"context_gap":"incomplete or stale context","book_errors":[null,null],"books":[{"bid":0.34,"ask":0.35,"asks":[[0.35,669.03]],"received_ms":1790001130069,"observed_ms":1790001130056,"hash":"57f8fa841b6e50f43631f4f59d570c96167329d2"},{"bid":0.65,"ask":0.66,"asks":[[0.66,27.0]],"received_ms":1790001130095,"observed_ms":1790001130085,"hash":"f452d3c9d8f72698643d554aa9ec3fe55b11ba05"}],"intents":{"pair_fast":null,"pair_250":null,"pair_add_fast":null,"pair_add_250":null},"decision_ms":1790001130096,"feature_cutoff_ms":1790001130095,"request_ms":1790001130034,"inventory":{"pair_fast":{"qty":[0.0,0.0],"cash":0.0,"lots":[[],[]],"floor":0.0},"pair_250":{"qty":[0.0,0.0],"cash":0.0,"lots":[[],[]],"floor":0.0},"pair_add_fast":{"qty":[0.0,0.0],"cash":0.0,"lots":[[],[]],"floor":0.0},"pair_add_250":{"qty":[0.0,0.0],"cash":0.0,"lots":[[],[]],"floor":0.0}}}
{"kind":"decision","recorded_ms":1790001140051,"S":1790001000,"age":140,"signal":{"rsi14":68.27055399266838,"volume_ratio":0.7123745076219173,"taker_buy_fraction":0.46131017967236543,"volume5":207.37858,"return1":9.219401812262793,"return5":1.4455630024541222,"return15":31.922557958151074,"bollinger_z":1.0090362546231622,"bar_close_ms":1790001119999,"ref":85705.48944666714,"reference_received_ms":1790001001829,"spot":85694.5047614353,"twap":85654.8118747418,"sigma":7.849445579563218,"spot_z":-0.11065129767876215,"twap_z":-0.5104870079017861,"momentum":0.9732170650756616,"decision_ms":1790001140050,"momentum30":0.531333687906049,"momentum60":1.137316898465117,"spot_twap_gap":0.6528269526323273,"range60":1.3859128162435916,"final_mean":85694.5047614353,"final_z":-0.12777577023746994,"final_up_prob":0.4491632127062717,"final_drift_up_prob":0.9997873348906872,"final_known_seconds":0,"final_sd":85.96845248069546,"final_drift_shift":313.9243345936013},"entry_side":null,"context_gap":null,"book_errors":[null,null],"books":[{"bid":0.45,"ask":0.46,"asks":[[0.46,246.71]],"received_ms":1790001140049,"observed_ms":1790001140041,"hash":"6a36dc6a7b148e68ff766290d88788218c19e382"},{"bid":0.54,"ask":0.55,"asks":[[0.55,500.59]],"received_ms":1790001140050,"observed_ms":1790001140041,"hash":"b0838b343ba5fb9ea39c31f8fe65618ed349fbdb"}],"intents":{"pair_fast":null,"pair_250":null,"pair_add_fast":null,"pair_add_250":null},"decision_ms":1790001140051,"feature_cutoff_ms":1790001140050,"request_ms":1790001140019,"inventory":{"pair_fast":{"qty":[0.0,0.0],"cash":0.0,"lots":[[],[]],"floor":0.0},"pair_250":{"qty":[0.0,0.0],"cash":0.0,"lots":[[],[]],"floor":0.0},"pair_add_fast":{"qty":[0.0,0.0],"cash":0.0,"lots":[[],[]],"floor":0.0},"pair_add_250":{"qty":[0.0,0.0],"cash":0.0,"lots":[[],[]],"floor":0.0}}}
{"kind":"decision","recorded_ms":1790001150054,"S":1790001000,"age":150,"signal":{"rsi14":68.27055399266838,"volume_ratio":0.7123745076219173,"taker_buy_fraction":0.46131017967236543,"volume5":207.37858,"return1":9.219401812262793,"return5":1.4455630024541222,"return15":31.922557958151074,"bollinger_z":1.0090362546231622,"bar_close_ms":1790001119999,"ref":85705.48944666714,"reference_received_ms":1790001001829,"spot":85713.97577519283,"twap":85669.25859861783,"sigma":8.071117763445814,"spot_z":0.08586492948246727,"twap_z":-0.36658481974005536,"momentum":0.8148192664501727,"decision_ms":1790001150052,"momentum30":0.6920150965308943,"momentum60":1.6592923915694155,"spot_twap_gap":0.7152618560828836,"range60":1.6592923915694155,"final_mean":85713.97577519283,"final_z":0.1002749581716308,"final_up_prob":0.5399369811218258,"final_drift_up_prob":0.9988474649869827,"final_known_seconds":0,"final_sd":84.6305865434695,"final_drift_shift":249.45257090199067},"entry_side":null,"context_gap":null,"book_errors":[null,null],"books":[{"bid":0.53,"ask":0.54,"asks":[[0.54,534.49]],"received_ms":1790001150050,"observed_ms":1790001150041,"hash":"6be0813b8a17e27f4469e7145adce19e18cf6744"},{"bid":0.46,"ask":0.47,"asks":[[0.47,187.69]],"received_ms":1790001150052,"observed_ms":1790001150043,"hash":"975f1dc05c431f4a027c22bd19b918f7e30dc61e"}],"intents":{"pair_fast":null,"pair_250":null,"pair_add_fast":null,"pair_add_250":null},"decision_ms":1790001150053,"feature_cutoff_ms":1790001150052,"request_ms":1790001150025,"inventory":{"pair_fast":{"qty":[0.0,0.0],"cash":0.0,"lots":[[],[]],"floor":0.0},"pair_250":{"qty":[0.0,0.0],"cash":0.0,"lots":[[],[]],"floor":0.0},"pair_add_fast":{"qty":[0.0,0.0],"cash":0.0,"lots":[[],[]],"floor":0.0},"pair_add_250":{"qty":[0.0,0.0],"cash":0.0,"lots":[[],[]],"floor":0.0}}}
{"kind":"decision","recorded_ms":1790001160061,"S":1790001000,"age":160,"signal":{"rsi14":68.27055399266838,"volume_ratio":0.7123745076219173,"taker_buy_fraction":0.46131017967236543,"volume5":207.37858,"return1":9.219401812262793,"return5":1.4455630024541222,"return15":31.922557958151074,"bollinger_z":1.0090362546231622,"bar_close_ms":1790001119999,"ref":85705.48944666714,"reference_received_ms":1790001001829,"spot":85699.91639228347,"twap":85682.0687529978,"sigma":5.95636872664578,"spot_z":-0.07909349587143812,"twap_z":-0.3323894601621354,"momentum":-0.7429686942615241,"decision_ms":1790001160060,"momentum30":0.9063452630325622,"momentum60":0.7655710121965125,"spot_twap_gap":0.3868330571571589,"range60":1.2231290586846293,"final_mean":85699.91639228347,"final_z":-0.09359271238847833,"final_up_prob":0.4627163494374292,"final_drift_up_prob":0.0037100333487636306,"final_known_seconds":0,"final_sd":59.54581549615394,"final_drift_shift":-153.8536565410186},"entry_side":1,"context_gap":null,"book_errors":[null,null],"books":[{"bid":0.55,"ask":0.56,"asks":[[0.56,305.38]],"received_ms":1790001160060,"observed_ms":1790001160051,"hash":"1223fb779011310ad2bbf25c6198ee393f7300fb"},{"bid":0.44,"ask":0.45,"asks":[[0.45,468.0]],"received_ms":1790001160052,"observed_ms":1790001160040,"hash":"19ddef4652238297576729362d3132aa8c61b92b"}],"intents":{"pair_fast":{"kind":"first","side":1,"qty":5.0,"max_cost":2.38663},"pair_250":{"kind":"first","side":1,"qty":5.0,"max_cost":2.38663},"pair_add_fast":{"kind":"first","side":1,"qty":5.0,"max_cost":2.38663},"pair_add_250":{"kind":"first","side":1,"qty":5.0,"max_cost":2.38663}},"decision_ms":1790001160061,"feature_cutoff_ms":1790001160060,"request_ms":1790001160026,"inventory":{"pair_fast":{"qty":[0.0,0.0],"cash":0.0,"lots":[[],[]],"floor":0.0},"pair_250":{"qty":[0.0,0.0],"cash":0.0,"lots":[[],[]],"floor":0.0},"pair_add_fast":{"qty":[0.0,0.0],"cash":0.0,"lots":[[],[]],"floor":0.0},"pair_add_250":{"qty":[0.0,0.0],"cash":0.0,"lots":[[],[]],"floor":0.0}}}
{"kind":"decision","recorded_ms":1790001230054,"S":1790001000,"age":230,"signal":{},"entry_side":null,"context_gap":"incomplete or stale context","book_errors":[null,null],"books":[{"bid":0.99,"ask":null,"asks":[],"received_ms":1790001230052,"observed_ms":1790001230041,"hash":"f727fdda6a033a178241ee6919891a03f2cfff81"},{"bid":null,"ask":0.01,"asks":[[0.01,7847.18]],"received_ms":1790001230045,"observed_ms":1790001230036,"hash":"5a31c51baf00c0df298ce3507c1a6773c66fa732"}],"intents":{"pair_fast":null,"pair_250":null,"pair_add_fast":null,"pair_add_250":null},"decision_ms":1790001230054,"feature_cutoff_ms":1790001230053,"request_ms":1790001230021,"inventory":{"pair_fast":{"qty":[0.0,5.0],"cash":2.33663,"lots":[[],[[5.0,0.467326]]],"floor":-2.33663},"pair_250":{"qty":[0.0,5.0],"cash":2.33663,"lots":[[],[[5.0,0.467326]]],"floor":-2.33663},"pair_add_fast":{"qty":[0.0,5.0],"cash":2.33663,"lots":[[],[[5.0,0.467326]]],"floor":-2.33663},"pair_add_250":{"qty":[0.0,5.0],"cash":2.33663,"lots":[[],[[5.0,0.467326]]],"floor":-2.33663}}}
{"kind":"decision","recorded_ms":1790001240064,"S":1790001000,"age":240,"signal":{"rsi14":73.8148624500614,"volume_ratio":0.37593276019889293,"taker_buy_fraction":0.4285057891320554,"volume5":172.60964,"return1":10.249597632779123,"return5":4.871880612351442,"return15":45.22107556904617,"bollinger_z":1.373154903725814,"bar_close_ms":1790001179999,"ref":85705.48944666714,"reference_received_ms":1790001001829,"spot":85916.26898029403,"twap":85845.0087040774,"sigma":9.79968591449175,"spot_z":2.7782105690742624,"twap_z":1.8389540429133624,"momentum":0.8177141809270521,"decision_ms":1790001240062,"momentum30":0.61023740507023,"momentum60":1.9264626972464933,"spot_twap_gap":0.9387711179091148,"range60":1.941494531695904,"final_mean":85916.26898029403,"final_z":4.816979408059219,"final_up_prob":0.9999992712613859,"final_drift_up_prob":0.9999999999713691,"final_known_seconds":0,"final_sd":43.75761566973648,"final_drift_shift":75.86420902893731},"entry_side":null,"context_gap":null,"book_errors":[null,null],"books":[{"bid":0.99,"ask":null,"asks":[],"received_ms":1790001240062,"observed_ms":1790001240050,"hash":"59274c57d37032df9b972f1c0cd1da6745261f4b"},{"bid":null,"ask":0.01,"asks":[[0.01,13862.95]],"received_ms":1790001240057,"observed_ms":1790001240047,"hash":"5d23b33685bbef2879453b00693a81f61268b601"}],"intents":{"pair_fast":null,"pair_250":null,"pair_add_fast":null,"pair_add_250":null},"decision_ms":1790001240064,"feature_cutoff_ms":1790001240062,"request_ms":1790001240027,"inventory":{"pair_fast":{"qty":[0.0,5.0],"cash":2.33663,"lots":[[],[[5.0,0.467326]]],"floor":-2.33663},"pair_250":{"qty":[0.0,5.0],"cash":2.33663,"lots":[[],[[5.0,0.467326]]],"floor":-2.33663},"pair_add_fast":{"qty":[0.0,5.0],"cash":2.33663,"lots":[[],[[5.0,0.467326]]],"floor":-2.33663},"pair_add_250":{"qty":[0.0,5.0],"cash":2.33663,"lots":[[],[[5.0,0.467326]]],"floor":-2.33663}}}
{"kind":"decision","recorded_ms":1790001250050,"S":1790001000,"age":250,"signal":{"rsi14":76.83555519755043,"volume_ratio":2.2495153166697,"taker_buy_fraction":0.5096746335722812,"volume5":214.05927,"return1":17.186332845430265,"return5":26.37580253693617,"return15":65.87609458009698,"bollinger_z":1.9622053518970184,"bar_close_ms":1790001239999,"ref":85705.48944666714,"reference_received_ms":1790001001829,"spot":85886.76907558911,"twap":85868.15029712461,"sigma":9.66646383805467,"spot_z":2.6534400474097017,"twap_z":2.380911839439786,"momentum":-0.9293486819523464,"decision_ms":1790001250049,"momentum30":-0.3285113694595301,"momentum60":1.2652177830287155,"spot_twap_gap":0.24866114478476722,"range60":1.68317833851117,"final_mean":85889.07836966004,"final_z":5.590806236856688,"final_up_prob":0.9999999886991158,"final_drift_up_prob":0.9999252842477162,"final_known_seconds":10,"final_sd":32.83764723996599,"final_drift_shift":-59.06816040512712},"entry_side":1,"context_gap":null,"book_errors":[null,null],"books":[{"bid":0.99,"ask":null,"asks":[],"received_ms":1790001250049,"observed_ms":1790001250034,"hash":"15b5a1e687583982a47b026c9c31c671b7bca55c"},{"bid":null,"ask":0.01,"asks":[[0.01,26287.55]],"received_ms":1790001250042,"observed_ms":1790001250031,"hash":"b29c4de312af4f90e275ecb0ba0bd609082ca2e5"}],"intents":{"pair_fast":null,"pair_250":null,"pair_add_fast":{"kind":"add","side":1,"qty":5.0,"max_cost":0.10347},"pair_add_250":{"kind":"add","side":1,"qty":5.0,"max_cost":0.10347}},"decision_ms":1790001250050,"feature_cutoff_ms":1790001250049,"request_ms":1790001250011,"inventory":{"pair_fast":{"qty":[0.0,5.0],"cash":2.33663,"lots":[[],[[5.0,0.467326]]],"floor":-2.33663},"pair_250":{"qty":[0.0,5.0],"cash":2.33663,"lots":[[],[[5.0,0.467326]]],"floor":-2.33663},"pair_add_fast":{"qty":[0.0,5.0],"cash":2.33663,"lots":[[],[[5.0,0.467326]]],"floor":-2.33663},"pair_add_250":{"qty":[0.0,5.0],"cash":2.33663,"lots":[[],[[5.0,0.467326]]],"floor":-2.33663}}}
{"kind":"execution","recorded_ms":1790001250085,"S":1790001000,"age":250,"speed":"fast","books":[{"bid":0.99,"ask":null,"asks":[],"received_ms":1790001250076,"observed_ms":1790001250062,"hash":"50a2f4473d356b895840545b1b2c89f5aebd5cc3"},{"bid":null,"ask":0.01,"asks":[[0.01,26282.55]],"received_ms":1790001250085,"observed_ms":1790001250058,"hash":"69078b69eb27ccae73a1a42647c6bfbec723b3b5"}],"book_errors":[null,null],"fills":{"pair_add_fast":{"kind":"add","side":1,"qty":5.0,"cost":0.053470000000000004,"fee":0.00347,"age":250.085}},"rejected":{},"decision_ms":1790001250050,"request_ms":1790001250050,"execution_ms":1790001250085,"delay_ms":35}
{"kind":"execution","recorded_ms":1790001250345,"S":1790001000,"age":250,"speed":"250","books":[{"bid":0.99,"ask":null,"asks":[],"received_ms":1790001250331,"observed_ms":1790001250311,"hash":"0acee8f5fab30fda80766610be4fa05dbe6de2de"},{"bid":null,"ask":0.01,"asks":[[0.01,26302.55]],"received_ms":1790001250345,"observed_ms":1790001250325,"hash":"b7126ada8be2e08662ad983c0703cff413eb17a5"}],"book_errors":[null,null],"fills":{"pair_add_250":{"kind":"add","side":1,"qty":5.0,"cost":0.053470000000000004,"fee":0.00347,"age":250.345}},"rejected":{},"decision_ms":1790001250050,"request_ms":1790001250300,"execution_ms":1790001250345,"delay_ms":295}
{"kind":"decision","recorded_ms":1790001260066,"S":1790001000,"age":260,"signal":{"rsi14":76.83555519755043,"volume_ratio":2.2495153166697,"taker_buy_fraction":0.5096746335722812,"volume5":214.05927,"return1":17.186332845430265,"return5":26.37580253693617,"return15":65.87609458009698,"bollinger_z":1.9622053518970184,"bar_close_ms":1790001239999,"ref":85705.48944666714,"reference_received_ms":1790001001829,"spot":85922.94942212485,"twap":85887.49209261735,"sigma":10.657013018615212,"spot_z":3.2289921878507726,"twap_z":2.702497876698697,"momentum":1.1702827012258374,"decision_ms":1790001260065,"momentum30":0.54857599031093,"momentum60":1.4505265149236817,"spot_twap_gap":0.4295313844621786,"range60":1.4505265149236817,"final_mean":85916.65406089666,"final_z":8.159564739811609,"final_up_prob":0.9999999999999998,"final_drift_up_prob":1.0,"final_known_seconds":20,"final_sd":25.8793968750834,"final_drift_shift":52.41461643535983},"entry_side":null,"context_gap":null,"book_errors":[null,null],"books":[{"bid":0.99,"ask":null,"asks":[],"received_ms":1790001260064,"observed_ms":1790001260050,"hash":"4dfb1e7d746e206251f2ba3247d7a62738a26593"},{"bid":null,"ask":0.01,"asks":[[0.01,40172.37]],"received_ms":1790001260040,"observed_ms":1790001260026,"hash":"95a80996e34654a6a86e9813ae6974218443a61c"}],"intents":{"pair_fast":null,"pair_250":null,"pair_add_fast":null,"pair_add_250":null},"decision_ms":1790001260066,"feature_cutoff_ms":1790001260065,"request_ms":1790001260016,"inventory":{"pair_fast":{"qty":[0.0,5.0],"cash":2.33663,"lots":[[],[[5.0,0.467326]]],"floor":-2.33663},"pair_250":{"qty":[0.0,5.0],"cash":2.33663,"lots":[[],[[5.0,0.467326]]],"floor":-2.33663},"pair_add_fast":{"qty":[0.0,10.0],"cash":2.3901,"lots":[[],[[5.0,0.467326],[5.0,0.010694]]],"floor":-2.3901},"pair_add_250":{"qty":[0.0,10.0],"cash":2.3901,"lots":[[],[[5.0,0.467326],[5.0,0.010694]]],"floor":-2.3901}}}
{"kind":"decision","recorded_ms":1790001270079,"S":1790001000,"age":270,"signal":{"rsi14":76.83555519755043,"volume_ratio":2.2495153166697,"taker_buy_fraction":0.5096746335722812,"volume5":214.05927,"return1":17.186332845430265,"return5":26.37580253693617,"return15":65.87609458009698,"bollinger_z":1.9622053518970184,"bar_close_ms":1790001239999,"ref":85705.48944666714,"reference_received_ms":1790001001829,"spot":85951.03589427558,"twap":85902.91060720496,"sigma":8.569167007514896,"spot_z":5.2384130495402745,"twap_z":4.211722847914435,"momentum":1.0919720629145704,"decision_ms":1790001270078,"momentum30":0.7639980691335111,"momentum60":1.017249778144957,"spot_twap_gap":0.7250352151790916,"range60":1.0173107258785654,"final_mean":85931.88043986484,"final_z":16.774380461461018,"final_up_prob":1.0,"final_drift_up_prob":1.0,"final_known_seconds":30,"final_sd":13.496235745804569,"final_drift_shift":22.077511704781173},"entry_side":null,"context_gap":null,"book_errors":[null,null],"books":[{"bid":0.99,"ask":null,"asks":[],"received_ms":1790001270075,"observed_ms":1790001270049,"hash":"042fd8097101d51a7c15774d4bd3fcb867d01826"},{"bid":null,"ask":0.01,"asks":[[0.01,45302.07]],"received_ms":1790001270078,"observed_ms":1790001270049,"hash":"bf9f753a8dbc410d87f436c987e4ee41dffb51dc"}],"intents":{"pair_fast":null,"pair_250":null,"pair_add_fast":null,"pair_add_250":null},"decision_ms":1790001270079,"feature_cutoff_ms":1790001270078,"request_ms":1790001270038,"inventory":{"pair_fast":{"qty":[0.0,5.0],"cash":2.33663,"lots":[[],[[5.0,0.467326]]],"floor":-2.33663},"pair_250":{"qty":[0.0,5.0],"cash":2.33663,"lots":[[],[[5.0,0.467326]]],"floor":-2.33663},"pair_add_fast":{"qty":[0.0,10.0],"cash":2.3901,"lots":[[],[[5.0,0.467326],[5.0,0.010694]]],"floor":-2.3901},"pair_add_250":{"qty":[0.0,10.0],"cash":2.3901,"lots":[[],[[5.0,0.467326],[5.0,0.010694]]],"floor":-2.3901}}}
{"kind":"decision","recorded_ms":1790001280043,"S":1790001000,"age":280,"signal":{"rsi14":76.83555519755043,"volume_ratio":2.2495153166697,"taker_buy_fraction":0.5096746335722812,"volume5":214.05927,"return1":17.186332845430265,"return5":26.37580253693617,"return15":65.87609458009698,"bollinger_z":1.9622053518970184,"bar_close_ms":1790001239999,"ref":85705.48944666714,"reference_received_ms":1790001001829,"spot":85940.58358930892,"twap":85911.81951189581,"sigma":6.774143593447028,"spot_z":7.768352105553327,"twap_z":6.817884012960581,"momentum":-0.1691408925480328,"decision_ms":1790001280042,"momentum30":1.5382156145910122,"momentum60":0.6941062881273284,"spot_twap_gap":0.5481765148772337,"range60":1.170968559701177,"final_mean":85927.58375052117,"final_z":38.21372500568367,"final_up_prob":1.0,"final_drift_up_prob":1.0,"final_known_seconds":40,"final_sd":5.81189883532671,"final_drift_shift":-1.2026958278506839},"entry_side":1,"context_gap":null,"book_errors":[null,null],"books":[{"bid":0.99,"ask":null,"asks":[],"received_ms":1790001280042,"observed_ms":1790001280028,"hash":"1fee7dbe6cd7c03af3cd67c51d5512847d3121c2"},{"bid":null,"ask":0.01,"asks":[[0.01,58114.53]],"received_ms":1790001280029,"observed_ms":1790001280020,"hash":"b9ef012d0d71de6f0be5045c4680abe9ebc7d6ba"}],"intents":{"pair_fast":null,"pair_250":null,"pair_add_fast":null,"pair_add_250":null},"decision_ms":1790001280043,"feature_cutoff_ms":1790001280042,"request_ms":1790001280001,"inventory":{"pair_fast":{"qty":[0.0,5.0],"cash":2.33663,"lots":[[],[[5.0,0.467326]]],"floor":-2.33663},"pair_250":{"qty":[0.0,5.0],"cash":2.33663,"lots":[[],[[5.0,0.467326]]],"floor":-2.33663},"pair_add_fast":{"qty":[0.0,10.0],"cash":2.3901,"lots":[[],[[5.0,0.467326],[5.0,0.010694]]],"floor":-2.3901},"pair_add_250":{"qty":[0.0,10.0],"cash":2.3901,"lots":[[],[[5.0,0.467326],[5.0,0.010694]]],"floor":-2.3901}}}
{"kind":"decision","recorded_ms":1790001290045,"S":1790001000,"age":290,"signal":{"rsi14":76.83555519755043,"volume_ratio":2.2495153166697,"taker_buy_fraction":0.5096746335722812,"volume5":214.05927,"return1":17.186332845430265,"return5":26.37580253693617,"return15":65.87609458009698,"bollinger_z":1.9622053518970184,"bar_close_ms":1790001239999,"ref":85705.48944666714,"reference_received_ms":1790001001829,"spot":85953.54448754837,"twap":85918.39816575112,"sigma":6.53418705913987,"spot_z":12.031341329393927,"twap_z":10.326649529891702,"momentum":0.28630361264296694,"decision_ms":1790001290044,"momentum30":0.8968887459802618,"momentum60":1.2371363798864146,"spot_twap_gap":0.694404765628229,"range60":1.3837013580553197,"final_mean":85931.40947557079,"final_z":114.37937305043565,"final_up_prob":1.0,"final_drift_up_prob":1.0,"final_known_seconds":50,"final_sd":1.9751815635851842,"final_drift_shift":0.48866015557728676},"entry_side":null,"context_gap":null,"book_errors":[null,null],"books":[{"bid":0.99,"ask":null,"asks":[],"received_ms":1790001290043,"observed_ms":1790001290007,"hash":"89cf9db67a5b39aeb0fe641588069b7c2b0189a1"},{"bid":null,"ask":0.01,"asks":[[0.01,58785.54]],"received_ms":1790001290041,"observed_ms":1790001290007,"hash":"eb8afe8786d2afcb807e3544514d6907d4b9efc2"}],"intents":{"pair_fast":null,"pair_250":null,"pair_add_fast":null,"pair_add_250":null},"decision_ms":1790001290045,"feature_cutoff_ms":1790001290044,"request_ms":1790001290014,"inventory":{"pair_fast":{"qty":[0.0,5.0],"cash":2.33663,"lots":[[],[[5.0,0.467326]]],"floor":-2.33663},"pair_250":{"qty":[0.0,5.0],"cash":2.33663,"lots":[[],[[5.0,0.467326]]],"floor":-2.33663},"pair_add_fast":{"qty":[0.0,10.0],"cash":2.3901,"lots":[[],[[5.0,0.467326],[5.0,0.010694]]],"floor":-2.3901},"pair_add_250":{"qty":[0.0,10.0],"cash":2.3901,"lots":[[],[[5.0,0.467326],[5.0,0.010694]]],"floor":-2.3901}}}
{"kind":"decision","recorded_ms":1790001330050,"S":1790001300,"age":30,"signal":{"rsi14":82.95915137778586,"volume_ratio":1.159581185072438,"taker_buy_fraction":0.5775745830855319,"volume5":229.87149,"return1":5.751453038444778,"return5":31.73881100511378,"return15":67.73597644346238,"bollinger_z":1.952591806556959,"bar_close_ms":1790001299999,"ref":85930.82645304846,"reference_received_ms":1790001301966,"spot":85919.23551502178,"twap":85954.85708018651,"sigma":3.972334132594689,"spot_z":-0.17759483928813327,"twap_z":0.3681941318943793,"momentum":-2.336284498253843,"decision_ms":1790001330049,"momentum30":-2.1289079088639493,"momentum60":-0.8115604262889099,"spot_twap_gap":-1.1576881840228488,"range60":1.6065243388096255,"final_mean":85919.23551502178,"final_z":-0.19242219327300616,"final_up_prob":0.4237057547513508,"final_drift_up_prob":0.0,"final_known_seconds":0,"final_sd":60.23701231924453,"final_drift_shift":-704.196826419385},"entry_side":null,"context_gap":null,"book_errors":[null,null],"books":[{"bid":0.43,"ask":0.44,"asks":[[0.44,304.0]],"received_ms":1790001330045,"observed_ms":1790001330035,"hash":"0679f7c059b23b285b96281c448fc3b54c47d927"},{"bid":0.56,"ask":0.57,"asks":[[0.57,524.0]],"received_ms":1790001330049,"observed_ms":1790001330037,"hash":"01d75556cd96c643aea922a948fd8d2f27e7d596"}],"intents":{"pair_fast":null,"pair_250":null,"pair_add_fast":null,"pair_add_250":null},"decision_ms":1790001330050,"feature_cutoff_ms":1790001330049,"request_ms":1790001330006,"inventory":{"pair_fast":{"qty":[0.0,0.0],"cash":0.0,"lots":[[],[]],"floor":0.0},"pair_250":{"qty":[0.0,0.0],"cash":0.0,"lots":[[],[]],"floor":0.0},"pair_add_fast":{"qty":[0.0,0.0],"cash":0.0,"lots":[[],[]],"floor":0.0},"pair_add_250":{"qty":[0.0,0.0],"cash":0.0,"lots":[[],[]],"floor":0.0}}}
{"kind":"decision","recorded_ms":1790001340072,"S":1790001300,"age":40,"signal":{"rsi14":82.95915137778586,"volume_ratio":1.159581185072438,"taker_buy_fraction":0.5775745830855319,"volume5":229.87149,"return1":5.751453038444778,"return5":31.73881100511378,"return15":67.73597644346238,"bollinger_z":1.952591806556959,"bar_close_ms":1790001299999,"ref":85930.82645304846,"reference_received_ms":1790001301966,"spot":85909.93559508491,"twap":85949.95527561384,"sigma":4.553582161516481,"spot_z":-0.28456123127576927,"twap_z":0.26055996893760225,"momentum":-0.30621614673466707,"decision_ms":1790001340071,"momentum30":-2.1756107920910943,"momentum60":-1.0686418974341023,"spot_twap_gap":-1.134605318855689,"range60":1.8185917228367139,"final_mean":85909.93559508491,"final_z":-0.3093583548949139,"final_up_prob":0.37852447280626916,"final_drift_up_prob":0.03509336862422474,"final_known_seconds":0,"final_sd":67.529638792664,"final_drift_shift":-101.38530561717074},"entry_side":null,"context_gap":null,"book_errors":[null,null],"books":[{"bid":0.43,"ask":0.44,"asks":[[0.44,96.33]],"received_ms":1790001340052,"observed_ms":1790001340044,"hash":"a49e9b6f90305314722e9fcc8a8b2a77b2a78e66"},{"bid":0.56,"ask":0.57,"asks":[[0.57,375.77]],"received_ms":1790001340071,"observed_ms":1790001340056,"hash":"da9405b607b18f5be1661836e0433e79c663e2fc"}],"intents":{"pair_fast":null,"pair_250":null,"pair_add_fast":null,"pair_add_250":null},"decision_ms":1790001340072,"feature_cutoff_ms":1790001340071,"request_ms":1790001340022,"inventory":{"pair_fast":{"qty":[0.0,0.0],"cash":0.0,"lots":[[],[]],"floor":0.0},"pair_250":{"qty":[0.0,0.0],"cash":0.0,"lots":[[],[]],"floor":0.0},"pair_add_fast":{"qty":[0.0,0.0],"cash":0.0,"lots":[[],[]],"floor":0.0},"pair_add_250":{"qty":[0.0,0.0],"cash":0.0,"lots":[[],[]],"floor":0.0}}}
{"kind":"decision","recorded_ms":1790001350077,"S":1790001300,"age":50,"signal":{"rsi14":82.95915137778586,"volume_ratio":1.159581185072438,"taker_buy_fraction":0.5775745830855319,"volume5":229.87149,"return1":5.751453038444778,"return5":31.73881100511378,"return15":67.73597644346238,"bollinger_z":1.952591806556959,"bar_close_ms":1790001299999,"ref":85930.82645304846,"reference_received_ms":1790001301966,"spot":85939.5175406673,"twap":85943.90161181799,"sigma":6.607305882557736,"spot_z":0.08320429285895847,"twap_z":0.12517528152397556,"momentum":1.2293393324914272,"decision_ms":1790001350076,"momentum30":-0.25049943451725143,"momentum60":-0.2647405243233858,"spot_twap_gap":-0.08565989858813979,"range60":1.2583817381621023,"final_mean":85939.5175406673,"final_z":0.09078595553738178,"final_up_prob":0.536168665089734,"final_drift_up_prob":0.9999999989611914,"final_known_seconds":0,"final_sd":95.73163125716478,"final_drift_shift":564.8964112849875},"entry_side":null,"context_gap":null,"book_errors":[null,null],"books":[{"bid":0.47,"ask":0.48,"asks":[[0.48,135.0]],"received_ms":1790001350076,"observed_ms":1790001350070,"hash":"6c5e1dd8bfb9eee4db4586a0a82ae4662b57dabf"},{"bid":0.52,"ask":0.53,"asks":[[0.53,746.6]],"received_ms":1790001350073,"observed_ms":1790001350059,"hash":"d7528c282d5e5a7ea7732c0244d98b0c27f0b4ee"}],"intents":{"pair_fast":null,"pair_250":null,"pair_add_fast":null,"pair_add_250":null},"decision_ms":1790001350077,"feature_cutoff_ms":1790001350076,"request_ms":1790001350043,"inventory":{"pair_fast":{"qty":[0.0,0.0],"cash":0.0,"lots":[[],[]],"floor":0.0},"pair_250":{"qty":[0.0,0.0],"cash":0.0,"lots":[[],[]],"floor":0.0},"pair_add_fast":{"qty":[0.0,0.0],"cash":0.0,"lots":[[],[]],"floor":0.0},"pair_add_250":{"qty":[0.0,0.0],"cash":0.0,"lots":[[],[]],"floor":0.0}}}
{"kind":"decision","recorded_ms":1790001360106,"S":1790001300,"age":60,"signal":{"rsi14":82.95915137778586,"volume_ratio":1.159581185072438,"taker_buy_fraction":0.5775745830855319,"volume5":229.87149,"return1":5.751453038444778,"return5":31.73881100511378,"return15":67.73597644346238,"bollinger_z":1.952591806556959,"bar_close_ms":1790001299999,"ref":85930.82645304846,"reference_received_ms":1790001301966,"spot":85927.83158801608,"twap":85938.70314152067,"sigma":6.225620646290908,"spot_z":-0.031058752162770927,"twap_z":0.08168652425967185,"momentum":-0.3937389416807884,"decision_ms":1790001360105,"momentum30":0.39551083969614537,"momentum60":-0.7822618283398809,"spot_twap_gap":-0.22544122138127046,"range60":1.335531593306331,"final_mean":85927.83158801608,"final_z":-0.034024647597757716,"final_up_prob":0.48642874806823566,"final_drift_up_prob":0.029885282827266824,"final_known_seconds":0,"final_sd":88.02045704584904,"final_drift_shift":-162.70208429833627},"entry_side":1,"context_gap":null,"book_errors":[null,null],"books":[{"bid":0.51,"ask":0.52,"asks":[[0.52,1036.22]],"received_ms":1790001360088,"observed_ms":1790001360072,"hash":"1861b6d66f3df4fcffe2ab162f6f11267bfe2819"},{"bid":0.48,"ask":0.49,"asks":[[0.49,79.19]],"received_ms":1790001360105,"observed_ms":1790001360072,"hash":"f99f0e3207633167482def2240005908be14e066"}],"intents":{"pair_fast":{"kind":"first","side":1,"qty":5.0,"max_cost":2.58747},"pair_250":{"kind":"first","side":1,"qty":5.0,"max_cost":2.58747},"pair_add_fast":{"kind":"first","side":1,"qty":5.0,"max_cost":2.58747},"pair_add_250":{"kind":"first","side":1,"qty":5.0,"max_cost":2.58747}},"decision_ms":1790001360106,"feature_cutoff_ms":1790001360105,"request_ms":1790001360049,"inventory":{"pair_fast":{"qty":[0.0,0.0],"cash":0.0,"lots":[[],[]],"floor":0.0},"pair_250":{"qty":[0.0,0.0],"cash":0.0,"lots":[[],[]],"floor":0.0},"pair_add_fast":{"qty":[0.0,0.0],"cash":0.0,"lots":[[],[]],"floor":0.0},"pair_add_250":{"qty":[0.0,0.0],"cash":0.0,"lots":[[],[]],"floor":0.0}}}
{"kind":"decision","recorded_ms":1790001550063,"S":1790001300,"age":250,"signal":{"rsi14":62.23693892567951,"volume_ratio":0.74846631110769,"taker_buy_fraction":0.3444231898800067,"volume5":224.69422,"return1":-10.461041352079768,"return5":-5.416784488228981,"return15":19.92906375542564,"bollinger_z":0.8652869121115718,"bar_close_ms":1790001539999,"ref":85930.82645304846,"reference_received_ms":1790001301966,"spot":85835.25967015159,"twap":85913.97145883611,"sigma":7.961990378887443,"spot_z":-1.6985164041777547,"twap_z":-0.2995652181039824,"momentum":-1.646306803315587,"decision_ms":1790001550062,"momentum30":-1.7219309236695655,"momentum60":-2.107175038691712,"spot_twap_gap":-1.2762698446764982,"range60":2.1176860287043127,"final_mean":85837.0812880818,"final_z":-3.4673077466123723,"final_up_prob":0.0002628498229562126,"final_drift_up_prob":1.4320877816942357e-11,"final_known_seconds":10,"final_sd":27.03687466399621,"final_drift_shift":-86.14170524240564},"entry_side":null,"context_gap":null,"book_errors":[null,null],"books":[{"bid":null,"ask":0.01,"asks":[[0.01,9757.06]],"received_ms":1790001550062,"observed_ms":1790001550036,"hash":"7e2722a20d397dd93ec70fdeda1999c3efe52d2f"},{"bid":0.99,"ask":null,"asks":[],"received_ms":1790001550060,"observed_ms":1790001550036,"hash":"91dd706ed4dac303e318391edb90146ff14f0bf6"}],"intents":{"pair_fast":null,"pair_250":null,"pair_add_fast":null,"pair_add_250":null},"decision_ms":1790001550063,"feature_cutoff_ms":1790001550062,"request_ms":1790001550032,"inventory":{"pair_fast":{"qty":[10.0,10.0],"cash":8.58647,"lots":[[],[]],"floor":1.4135299999999997},"pair_250":{"qty":[10.0,10.0],"cash":8.43384,"lots":[[],[]],"floor":1.56616},"pair_add_fast":{"qty":[15.0,15.0],"cash":11.9861,"lots":[[],[]],"floor":3.0138999999999996},"pair_add_250":{"qty":[15.0,15.0],"cash":11.6791,"lots":[[],[]],"floor":3.3209}}}
{"kind":"decision","recorded_ms":1790001560076,"S":1790001300,"age":260,"signal":{"rsi14":62.23693892567951,"volume_ratio":0.74846631110769,"taker_buy_fraction":0.3444231898800067,"volume5":224.69422,"return1":-10.461041352079768,"return5":-5.416784488228981,"return15":19.92906375542564,"bollinger_z":0.8652869121115718,"bar_close_ms":1790001539999,"ref":85930.82645304846,"reference_received_ms":1790001301966,"spot":85818.18728889021,"twap":85894.15106666237,"sigma":8.097047122708679,"spot_z":-2.2016094982533536,"twap_z":-0.7168455094917,"momentum":-0.6346020243921368,"decision_ms":1790001560075,"momentum30":-1.782457423983202,"momentum60":-2.263267542950501,"spot_twap_gap":-1.211167650658807,"range60":2.263267542950501,"final_mean":85824.06267644415,"final_z":-5.431774756479675,"final_up_prob":2.7898161669703825e-08,"final_drift_up_prob":3.29053451153527e-11,"final_known_seconds":20,"final_sd":19.655413081505955,"final_drift_shift":-21.584238066796686},"entry_side":null,"context_gap":null,"book_errors":[null,null],"books":[{"bid":null,"ask":0.01,"asks":[[0.01,28888.63]],"received_ms":1790001560075,"observed_ms":1790001560060,"hash":"f0fb6a65a12d587824a255ed7c3445970e8bf3a2"},{"bid":0.99,"ask":null,"asks":[],"received_ms":1790001560063,"observed_ms":1790001560050,"hash":"62fcbbde94371f8b397a3a67e5bd58226a1e5371"}],"intents":{"pair_fast":null,"pair_250":null,"pair_add_fast":null,"pair_add_250":null},"decision_ms":1790001560076,"feature_cutoff_ms":1790001560075,"request_ms":1790001560035,"inventory":{"pair_fast":{"qty":[10.0,10.0],"cash":8.58647,"lots":[[],[]],"floor":1.4135299999999997},"pair_250":{"qty":[10.0,10.0],"cash":8.43384,"lots":[[],[]],"floor":1.56616},"pair_add_fast":{"qty":[15.0,15.0],"cash":11.9861,"lots":[[],[]],"floor":3.0138999999999996},"pair_add_250":{"qty":[15.0,15.0],"cash":11.6791,"lots":[[],[]],"floor":3.3209}}}
{"kind":"decision","recorded_ms":1790001570085,"S":1790001300,"age":270,"signal":{"rsi14":62.23693892567951,"volume_ratio":0.74846631110769,"taker_buy_fraction":0.3444231898800067,"volume5":224.69422,"return1":-10.461041352079768,"return5":-5.416784488228981,"return15":19.92906375542564,"bollinger_z":0.8652869121115718,"bar_close_ms":1790001539999,"ref":85930.82645304846,"reference_received_ms":1790001301966,"spot":85771.727736955,"twap":85872.02309335925,"sigma":8.956020127982573,"spot_z":-3.2478790848087122,"twap_z":-1.2004257906070246,"momentum":-1.6382258240231318,"decision_ms":1790001570084,"momentum30":-2.1401390497096973,"momentum60":-2.218077900483129,"spot_twap_gap":-1.4457398096651946,"range60":2.218077900483129,"final_mean":85797.95698167219,"final_z":-9.422512874703544,"final_up_prob":0.0,"final_drift_up_prob":0.0,"final_known_seconds":30,"final_sd":14.10127777410412,"final_drift_shift":-34.603069769160136},"entry_side":null,"context_gap":null,"book_errors":[null,null],"books":[{"bid":null,"ask":0.01,"asks":[[0.01,33589.83]],"received_ms":1790001570083,"observed_ms":1790001570060,"hash":"e56257c9087bf5e55ebc4d0a704e17ec6f572a74"},{"bid":0.99,"ask":null,"asks":[],"received_ms":1790001570084,"observed_ms":1790001570060,"hash":"6b31bd04e730f5fc8c518d9699c386626e5ddac6"}],"intents":{"pair_fast":null,"pair_250":null,"pair_add_fast":null,"pair_add_250":null},"decision_ms":1790001570085,"feature_cutoff_ms":1790001570084,"request_ms":1790001570048,"inventory":{"pair_fast":{"qty":[10.0,10.0],"cash":8.58647,"lots":[[],[]],"floor":1.4135299999999997},"pair_250":{"qty":[10.0,10.0],"cash":8.43384,"lots":[[],[]],"floor":1.56616},"pair_add_fast":{"qty":[15.0,15.0],"cash":11.9861,"lots":[[],[]],"floor":3.0138999999999996},"pair_add_250":{"qty":[15.0,15.0],"cash":11.6791,"lots":[[],[]],"floor":3.3209}}}
{"kind":"decision","recorded_ms":1790001580041,"S":1790001300,"age":280,"signal":{"rsi14":62.23693892567951,"volume_ratio":0.74846631110769,"taker_buy_fraction":0.3444231898800067,"volume5":224.69422,"return1":-10.461041352079768,"return5":-5.416784488228981,"return15":19.92906375542564,"bollinger_z":0.8652869121115718,"bar_close_ms":1790001539999,"ref":85930.82645304846,"reference_received_ms":1790001301966,"spot":85763.27124087918,"twap":85846.80449239828,"sigma":8.621208621554892,"spot_z":-4.350093989389544,"twap_z":-2.1813909652169428,"momentum":-0.20516342279314836,"decision_ms":1790001580039,"momentum30":-1.507086928216402,"momentum60":-2.202486826962565,"spot_twap_gap":-1.2508798792593858,"range60":2.202486826962565,"final_mean":85793.84696999504,"final_z":-18.515089052591964,"final_up_prob":0.0,"final_drift_up_prob":0.0,"final_known_seconds":40,"final_sd":7.398262177639747,"final_drift_shift":-1.8571690274914225},"entry_side":null,"context_gap":null,"book_errors":[null,null],"books":[{"bid":null,"ask":0.01,"asks":[[0.01,47394.66]],"received_ms":1790001580038,"observed_ms":1790001580020,"hash":"b566bb2eedc72df88a23afc9b223b9227bb7af04"},{"bid":0.99,"ask":null,"asks":[],"received_ms":1790001580037,"observed_ms":1790001580020,"hash":"1c34c0573cc16e4cb224cb5498325f4c52fe0927"}],"intents":{"pair_fast":null,"pair_250":null,"pair_add_fast":null,"pair_add_250":null},"decision_ms":1790001580041,"feature_cutoff_ms":1790001580039,"request_ms":1790001580008,"inventory":{"pair_fast":{"qty":[10.0,10.0],"cash":8.58647,"lots":[[],[]],"floor":1.4135299999999997},"pair_250":{"qty":[10.0,10.0],"cash":8.43384,"lots":[[],[]],"floor":1.56616},"pair_add_fast":{"qty":[15.0,15.0],"cash":11.9861,"lots":[[],[]],"floor":3.0138999999999996},"pair_add_250":{"qty":[15.0,15.0],"cash":11.6791,"lots":[[],[]],"floor":3.3209}}}
{"kind":"decision","recorded_ms":1790001590056,"S":1790001300,"age":290,"signal":{"rsi14":62.23693892567951,"volume_ratio":0.74846631110769,"taker_buy_fraction":0.3444231898800067,"volume5":224.69422,"return1":-10.461041352079768,"return5":-5.416784488228981,"return15":19.92906375542564,"bollinger_z":0.8652869121115718,"bar_close_ms":1790001539999,"ref":85930.82645304846,"reference_received_ms":1790001301966,"spot":85776.95272657083,"twap":85823.76011477345,"sigma":8.25419797476839,"spot_z":-5.9113571364602056,"twap_z":-4.113160689122841,"momentum":0.34604134912163165,"decision_ms":1790001590055,"momentum30":-0.9106790744127563,"momentum60":-1.8813188160450136,"spot_twap_gap":-0.7320890353505528,"range60":2.0894664761761446,"final_mean":85797.42454576214,"final_z":-53.55399314721042,"final_up_prob":0.0,"final_drift_up_prob":0.0,"final_known_seconds":50,"final_sd":2.4909796533680977,"final_drift_shift":0.7444425716249312},"entry_side":null,"context_gap":null,"book_errors":[null,null],"books":[{"bid":null,"ask":0.01,"asks":[[0.01,47839.42]],"received_ms":1790001590051,"observed_ms":1790001590041,"hash":"4b4532ef58b382ae544bfde934396311da8bb909"},{"bid":0.99,"ask":null,"asks":[],"received_ms":1790001590055,"observed_ms":1790001590041,"hash":"7b072f9862293931bc78c985483177c2476db52c"}],"intents":{"pair_fast":null,"pair_250":null,"pair_add_fast":null,"pair_add_250":null},"decision_ms":1790001590056,"feature_cutoff_ms":1790001590055,"request_ms":1790001590012,"inventory":{"pair_fast":{"qty":[10.0,10.0],"cash":8.58647,"lots":[[],[]],"floor":1.4135299999999997},"pair_250":{"qty":[10.0,10.0],"cash":8.43384,"lots":[[],[]],"floor":1.56616},"pair_add_fast":{"qty":[15.0,15.0],"cash":11.9861,"lots":[[],[]],"floor":3.0138999999999996},"pair_add_250":{"qty":[15.0,15.0],"cash":11.6791,"lots":[[],[]],"floor":3.3209}}}
{"kind":"decision","recorded_ms":1790001630092,"S":1790001600,"age":30,"signal":{"rsi14":58.546131870067555,"volume_ratio":0.961259246026773,"taker_buy_fraction":0.27289516969148714,"volume5":214.26560999999998,"return1":-8.612799771630106,"return5":-19.79708886901699,"return15":12.70131632988873,"bollinger_z":0.3876012390818445,"bar_close_ms":1790001599999,"ref":85799.28883377438,"reference_received_ms":1790001601703,"spot":85575.92492089084,"twap":85726.53950141859,"sigma":17.311973670169788,"spot_z":-0.7853400451284279,"twap_z":-0.25578421875670804,"momentum":-0.10491720810638973,"decision_ms":1790001630091,"momentum30":-2.2670015775339865,"momentum60":-1.4387959611477796,"spot_twap_gap":-1.1231682248629946,"range60":1.6907467314534859,"final_mean":85575.92492089084,"final_z":-0.8509194288318754,"final_up_prob":0.1974070556861336,"final_drift_up_prob":0.08443152867348436,"final_known_seconds":0,"final_sd":262.4971358218535,"final_drift_shift":-137.79702727966495},"entry_side":null,"context_gap":null,"book_errors":[null,null],"books":[{"bid":0.11,"ask":0.12,"asks":[[0.12,205.3]],"received_ms":1790001630074,"observed_ms":1790001630063,"hash":"d66cf0b03b587bc6002838aa1134f121e856f4e3"},{"bid":0.88,"ask":0.89,"asks":[[0.89,855.41]],"received_ms":1790001630091,"observed_ms":1790001630071,"hash":"580fe906a37ad0f6b488e9d3473e6f6d76366fb6"}],"intents":{"pair_fast":null,"pair_250":null,"pair_add_fast":null,"pair_add_250":null},"decision_ms":1790001630092,"feature_cutoff_ms":1790001630091,"request_ms":1790001630044,"inventory":{"pair_fast":{"qty":[0.0,0.0],"cash":0.0,"lots":[[],[]],"floor":0.0},"pair_250":{"qty":[0.0,0.0],"cash":0.0,"lots":[[],[]],"floor":0.0},"pair_add_fast":{"qty":[0.0,0.0],"cash":0.0,"lots":[[],[]],"floor":0.0},"pair_add_250":{"qty":[0.0,0.0],"cash":0.0,"lots":[[],[]],"floor":0.0}}}
{"kind":"decision","recorded_ms":1790001640064,"S":1790001600,"age":40,"signal":{"rsi14":58.546131870067555,"volume_ratio":0.961259246026773,"taker_buy_fraction":0.27289516969148714,"volume5":214.26560999999998,"return1":-8.612799771630106,"return5":-19.79708886901699,"return15":12.70131632988873,"bollinger_z":0.3876012390818445,"bar_close_ms":1790001599999,"ref":85799.28883377438,"reference_received_ms":1790001601703,"spot":85590.54319713339,"twap":85693.32929503053,"sigma":17.451043238878274,"spot_z":-0.7419283400866972,"twap_z":-0.37660372672497194,"momentum":0.31415045346515685,"decision_ms":1790001640063,"momentum30":-1.0424495293750182,"momentum60":-1.3122017631772573,"spot_twap_gap":-0.7603916853337496,"range60":1.677272957105447,"final_mean":85590.54319713339,"final_z":-0.8065789121033942,"final_up_prob":0.20995456360906994,"final_drift_up_prob":0.7684320752397453,"final_known_seconds":0,"final_sd":258.80373700401293,"final_drift_shift":398.62813374143786},"entry_side":null,"context_gap":null,"book_errors":[null,null],"books":[{"bid":0.14,"ask":0.15,"asks":[[0.15,311.71]],"received_ms":1790001640051,"observed_ms":1790001640038,"hash":"3ba831f7e053767fac0a1824b7e86af74add38e2"},{"bid":0.85,"ask":0.86,"asks":[[0.86,1098.2]],"received_ms":1790001640063,"observed_ms":1790001640049,"hash":"183a185699b158483fd85a18f617fcd9cdef6e6f"}],"intents":{"pair_fast":null,"pair_250":null,"pair_add_fast":null,"pair_add_250":null},"decision_ms":1790001640064,"feature_cutoff_ms":1790001640063,"request_ms":1790001640014,"inventory":{"pair_fast":{"qty":[0.0,0.0],"cash":0.0,"lots":[[],[]],"floor":0.0},"pair_250":{"qty":[0.0,0.0],"cash":0.0,"lots":[[],[]],"floor":0.0},"pair_add_fast":{"qty":[0.0,0.0],"cash":0.0,"lots":[[],[]],"floor":0.0},"pair_add_250":{"qty":[0.0,0.0],"cash":0.0,"lots":[[],[]],"floor":0.0}}}
{"kind":"decision","recorded_ms":1790001650061,"S":1790001600,"age":50,"signal":{"rsi14":58.546131870067555,"volume_ratio":0.961259246026773,"taker_buy_fraction":0.27289516969148714,"volume5":214.26560999999998,"return1":-8.612799771630106,"return5":-19.79708886901699,"return15":12.70131632988873,"bollinger_z":0.3876012390818445,"bar_close_ms":1790001599999,"ref":85799.28883377438,"reference_received_ms":1790001601703,"spot":85633.81290059596,"twap":85666.01034920782,"sigma":19.587662170615324,"spot_z":-0.5343605042541054,"twap_z":-0.43038740952390875,"momentum":0.38747372861400814,"decision_ms":1790001650060,"momentum30":0.4860302144893749,"momentum60":-0.9297821410161832,"spot_twap_gap":-0.21220872128231527,"range60":1.4943163019095957,"final_mean":85633.81290059596,"final_z":-0.5830484394792056,"final_up_prob":0.27993034598899247,"final_drift_up_prob":0.8991796964971569,"final_known_seconds":0,"final_sd":283.8116389201261,"final_drift_shift":527.8725610746058},"entry_side":null,"context_gap":null,"book_errors":[null,null],"books":[{"bid":0.15,"ask":0.16,"asks":[[0.16,568.3]],"received_ms":1790001650058,"observed_ms":1790001650048,"hash":"cb32150f9bcd306569f2f05cb551c980543f13bb"},{"bid":0.84,"ask":0.85,"asks":[[0.85,711.66]],"received_ms":1790001650060,"observed_ms":1790001650048,"hash":"3c0830db6ff055f779af03bc50decb954f6b2b32"}],"intents":{"pair_fast":null,"pair_250":null,"pair_add_fast":null,"pair_add_250":null},"decision_ms":1790001650061,"feature_cutoff_ms":1790001650060,"request_ms":1790001650037,"inventory":{"pair_fast":{"qty":[0.0,0.0],"cash":0.0,"lots":[[],[]],"floor":0.0},"pair_250":{"qty":[0.0,0.0],"cash":0.0,"lots":[[],[]],"floor":0.0},"pair_add_fast":{"qty":[0.0,0.0],"cash":0.0,"lots":[[],[]],"floor":0.0},"pair_add_250":{"qty":[0.0,0.0],"cash":0.0,"lots":[[],[]],"floor":0.0}}}
{"kind":"decision","recorded_ms":1790001660068,"S":1790001600,"age":60,"signal":{"rsi14":58.546131870067555,"volume_ratio":0.961259246026773,"taker_buy_fraction":0.27289516969148714,"volume5":214.26560999999998,"return1":-8.612799771630106,"return5":-19.79708886901699,"return15":12.70131632988873,"bollinger_z":0.3876012390818445,"bar_close_ms":1790001599999,"ref":85799.28883377438,"reference_received_ms":1790001601703,"spot":85633.59711619977,"twap":85645.18646403457,"sigma":19.78425403539884,"spot_z":-0.5406747994785912,"twap_z":-0.5028571679856524,"momentum":0.19526390673333413,"decision_ms":1790001660067,"momentum30":0.5572974614546278,"momentum60":-1.0263645201780347,"spot_twap_gap":-0.07562470484065656,"range60":1.4794676031492995,"final_mean":85633.59711619977,"final_z":-0.59229610765758,"final_up_prob":0.27682616094737156,"final_drift_up_prob":0.6272103989368271,"final_known_seconds":0,"final_sd":279.7447348250951,"final_drift_shift":256.4616111209673},"entry_side":null,"context_gap":null,"book_errors":[null,null],"books":[{"bid":0.15,"ask":0.16,"asks":[[0.16,73.92]],"received_ms":1790001660066,"observed_ms":1790001660052,"hash":"6954dcb40d980fe4c952cb4ddc844997b516cbeb"},{"bid":0.84,"ask":0.85,"asks":[[0.85,1424.34]],"received_ms":1790001660067,"observed_ms":1790001660054,"hash":"8a46fb6b732ab5c6d4cdaec58a2144dde814f9d7"}],"intents":{"pair_fast":null,"pair_250":null,"pair_add_fast":null,"pair_add_250":null},"decision_ms":1790001660068,"feature_cutoff_ms":1790001660067,"request_ms":1790001660033,"inventory":{"pair_fast":{"qty":[0.0,0.0],"cash":0.0,"lots":[[],[]],"floor":0.0},"pair_250":{"qty":[0.0,0.0],"cash":0.0,"lots":[[],[]],"floor":0.0},"pair_add_fast":{"qty":[0.0,0.0],"cash":0.0,"lots":[[],[]],"floor":0.0},"pair_add_250":{"qty":[0.0,0.0],"cash":0.0,"lots":[[],[]],"floor":0.0}}}
{"kind":"decision","recorded_ms":1790001670093,"S":1790001600,"age":70,"signal":{"rsi14":48.50443680210555,"volume_ratio":1.1851236919877914,"taker_buy_fraction":0.23973408712401736,"volume5":215.70974999999999,"return1":-18.182565234636925,"return5":-33.669903973363496,"return15":-2.3298709769754122,"bollinger_z":-0.7304119635864699,"bar_close_ms":1790001659999,"ref":85799.28883377438,"reference_received_ms":1790001601703,"spot":85702.16616184833,"twap":85624.9719531899,"sigma":17.969327840178693,"spot_z":-0.3564607756351797,"twap_z":-0.6397798704175105,"momentum":1.247302067795588,"decision_ms":1790001670092,"momentum30":0.9383466708477685,"momentum60":0.086085309228263,"spot_twap_gap":0.5545966757296207,"range60":0.9914968653768599,"final_mean":85702.16616184833,"final_z":-0.3922086426305885,"final_up_prob":0.3474520293977431,"final_drift_up_prob":0.9999999507741227,"final_known_seconds":0,"final_sd":247.63011665074976,"final_drift_shift":1416.8818880508265},"entry_side":null,"context_gap":null,"book_errors":[null,null],"books":[{"bid":0.37,"ask":0.38,"asks":[[0.38,658.92]],"received_ms":1790001670048,"observed_ms":1790001669896,"hash":"0992b8c9c05b285f624017870c2335fe01307b0c"},{"bid":0.62,"ask":0.63,"asks":[[0.63,5.0]],"received_ms":1790001670092,"observed_ms":1790001669896,"hash":"902ddead01866e7bc32cab3624e58f61f6ddf08b"}],"intents":{"pair_fast":null,"pair_250":null,"pair_add_fast":null,"pair_add_250":null},"decision_ms":1790001670093,"feature_cutoff_ms":1790001670092,"request_ms":1790001670018,"inventory":{"pair_fast":{"qty":[0.0,0.0],"cash":0.0,"lots":[[],[]],"floor":0.0},"pair_250":{"qty":[0.0,0.0],"cash":0.0,"lots":[[],[]],"floor":0.0},"pair_add_fast":{"qty":[0.0,0.0],"cash":0.0,"lots":[[],[]],"floor":0.0},"pair_add_250":{"qty":[0.0,0.0],"cash":0.0,"lots":[[],[]],"floor":0.0}}}
{"kind":"decision","recorded_ms":1790001680051,"S":1790001600,"age":80,"signal":{"rsi14":48.50443680210555,"volume_ratio":1.1851236919877914,"taker_buy_fraction":0.23973408712401736,"volume5":215.70974999999999,"return1":-18.182565234636925,"return5":-33.669903973363496,"return15":-2.3298709769754122,"bollinger_z":-0.7304119635864699,"bar_close_ms":1790001659999,"ref":85799.28883377438,"reference_received_ms":1790001601703,"spot":85719.86460557659,"twap":85630.25881092116,"sigma":15.65090328191586,"spot_z":-0.34217762880421704,"twap_z":-0.7282197602550015,"momentum":-0.4691955038012624,"decision_ms":1790001680050,"momentum30":1.1488543140135417,"momentum60":1.1399356268234737,"spot_twap_gap":0.739130396444111,"range60":1.5663598989128253,"final_mean":85719.86460557659,"final_z":-0.37830115747510284,"final_up_prob":0.3526034428329038,"final_drift_up_prob":0.006582794417364979,"final_known_seconds":0,"final_sd":209.94973615173325,"final_drift_shift":-441.09541891429177},"entry_side":null,"context_gap":null,"book_errors":[null,null],"books":[{"bid":0.35,"ask":0.36,"asks":[[0.36,1429.41]],"received_ms":1790001680045,"observed_ms":1790001680024,"hash":"05bcc06a0965658489bc66faeac21bc99a65b9fc"},{"bid":0.64,"ask":0.65,"asks":[[0.65,6.0]],"received_ms":1790001680049,"observed_ms":1790001680037,"hash":"2e80110ba48f5785991e2dd5adc159512cb6c7da"}],"intents":{"pair_fast":null,"pair_250":null,"pair_add_fast":null,"pair_add_250":null},"decision_ms":1790001680051,"feature_cutoff_ms":1790001680050,"request_ms":1790001680016,"inventory":{"pair_fast":{"qty":[0.0,0.0],"cash":0.0,"lots":[[],[]],"floor":0.0},"pair_250":{"qty":[0.0,0.0],"cash":0.0,"lots":[[],[]],"floor":0.0},"pair_add_fast":{"qty":[0.0,0.0],"cash":0.0,"lots":[[],[]],"floor":0.0},"pair_add_250":{"qty":[0.0,0.0],"cash":0.0,"lots":[[],[]],"floor":0.0}}}
{"kind":"decision","recorded_ms":1790001690061,"S":1790001600,"age":90,"signal":{"rsi14":48.50443680210555,"volume_ratio":1.1851236919877914,"taker_buy_fraction":0.23973408712401736,"volume5":215.70974999999999,"return1":-18.182565234636925,"return5":-33.669903973363496,"return15":-2.3298709769754122,"bollinger_z":-0.7304119635864699,"bar_close_ms":1790001659999,"ref":85799.28883377438,"reference_received_ms":1790001601703,"spot":85722.42289889797,"twap":85656.27539738147,"sigma":15.104377503139819,"spot_z":-0.3512234347668161,"twap_z":-0.6534711433418363,"momentum":-0.21422655468134336,"decision_ms":1790001690060,"momentum30":1.101575529728773,"momentum60":1.2753731002169812,"spot_twap_gap":0.56537290092094,"range60":1.5656206152139616,"final_mean":85722.42289889797,"final_z":-0.3903761487236632,"final_up_prob":0.3481292110711525,"final_drift_up_prob":0.09250836631098686,"final_known_seconds":0,"final_sd":196.90223167506133,"final_drift_shift":-184.1212229882715},"entry_side":null,"context_gap":null,"book_errors":[null,null],"books":[{"bid":0.36,"ask":0.37,"asks":[[0.37,394.2]],"received_ms":1790001690060,"observed_ms":1790001690050,"hash":"b7efda821190b86f253df6e98194a15ba3081971"},{"bid":0.63,"ask":0.64,"asks":[[0.64,183.84]],"received_ms":1790001690050,"observed_ms":1790001690041,"hash":"6be589ab33db8386d3209311898b2fa306f91944"}],"intents":{"pair_fast":null,"pair_250":null,"pair_add_fast":null,"pair_add_250":null},"decision_ms":1790001690061,"feature_cutoff_ms":1790001690060,"request_ms":1790001690024,"inventory":{"pair_fast":{"qty":[0.0,0.0],"cash":0.0,"lots":[[],[]],"floor":0.0},"pair_250":{"qty":[0.0,0.0],"cash":0.0,"lots":[[],[]],"floor":0.0},"pair_add_fast":{"qty":[0.0,0.0],"cash":0.0,"lots":[[],[]],"floor":0.0},"pair_add_250":{"qty":[0.0,0.0],"cash":0.0,"lots":[[],[]],"floor":0.0}}}
{"kind":"decision","recorded_ms":1790001702320,"S":1790001600,"age":100,"signal":{"rsi14":48.50443680210555,"volume_ratio":1.1851236919877914,"taker_buy_fraction":0.23973408712401736,"volume5":215.70974999999999,"return1":-18.182565234636925,"return5":-33.669903973363496,"return15":-2.3298709769754122,"bollinger_z":-0.7304119635864699,"bar_close_ms":1790001659999,"ref":85799.28883377438,"reference_received_ms":1790001601703,"spot":85767.85588208765,"twap":85690.0722582532,"sigma":10.882400016965168,"spot_z":-0.20543669261951042,"twap_z":-0.713807989714566,"momentum":0.9289311913009484,"decision_ms":1790001702319,"momentum30":0.6155756391543044,"momentum60":1.7375485953752388,"spot_twap_gap":0.9227580902767465,"range60":1.7375485953752388,"final_mean":85767.85588208765,"final_z":-0.23002275277727996,"final_up_prob":0.409037044776757,"final_drift_up_prob":0.9998890181271999,"final_known_seconds":0,"final_sd":136.6514890688411,"final_drift_shift":536.0336906672292},"entry_side":null,"context_gap":null,"book_errors":[null,null],"books":[{"bid":0.42,"ask":0.43,"asks":[[0.43,917.13]],"received_ms":1790001700068,"observed_ms":1790001700054,"hash":"3106c4718806bd0eca8912fd9af6f343509e5263"},{"bid":0.56,"ask":0.57,"asks":[[0.57,101.24]],"received_ms":1790001702319,"observed_ms":1790001702297,"hash":"cd5d01e18ee984b82d92116332ccba669737c494"}],"intents":{"pair_fast":null,"pair_250":null,"pair_add_fast":null,"pair_add_250":null},"decision_ms":1790001702320,"feature_cutoff_ms":1790001702319,"request_ms":1790001700035,"inventory":{"pair_fast":{"qty":[0.0,0.0],"cash":0.0,"lots":[[],[]],"floor":0.0},"pair_250":{"qty":[0.0,0.0],"cash":0.0,"lots":[[],[]],"floor":0.0},"pair_add_fast":{"qty":[0.0,0.0],"cash":0.0,"lots":[[],[]],"floor":0.0},"pair_add_250":{"qty":[0.0,0.0],"cash":0.0,"lots":[[],[]],"floor":0.0}}}
{"kind":"decision","recorded_ms":1790001710113,"S":1790001600,"age":110,"signal":{"rsi14":48.50443680210555,"volume_ratio":1.1851236919877914,"taker_buy_fraction":0.23973408712401736,"volume5":215.70974999999999,"return1":-18.182565234636925,"return5":-33.669903973363496,"return15":-2.3298709769754122,"bollinger_z":-0.7304119635864699,"bar_close_ms":1790001659999,"ref":85799.28883377438,"reference_received_ms":1790001601703,"spot":85765.50221609119,"twap":85709.47501531053,"sigma":11.777938189347806,"spot_z":-0.2081740955896414,"twap_z":-0.5533821291459956,"momentum":-0.15614367863467596,"decision_ms":1790001710112,"momentum30":0.5091727413859324,"momentum60":1.579733188961071,"spot_twap_gap":0.6141211137570769,"range60":1.646100917407611,"final_mean":85765.50221609119,"final_z":-0.23431064219119618,"final_up_prob":0.40737191229637204,"final_drift_up_prob":0.1896578389926306,"final_known_seconds":0,"final_sd":144.19583065979066,"final_drift_shift":-92.98428324517737},"entry_side":null,"context_gap":null,"book_errors":[null,null],"books":[{"bid":0.4,"ask":0.41,"asks":[[0.41,410.97]],"received_ms":1790001710112,"observed_ms":1790001710080,"hash":"500960a501a603315481f3bab0e4c9731e0a253e"},{"bid":0.59,"ask":0.6,"asks":[[0.6,226.7]],"received_ms":1790001710074,"observed_ms":1790001710066,"hash":"1b8231ebc65c7a8e366bbb8c8fa02dff50aa8c02"}],"intents":{"pair_fast":null,"pair_250":null,"pair_add_fast":null,"pair_add_250":null},"decision_ms":1790001710113,"feature_cutoff_ms":1790001710112,"request_ms":1790001710038,"inventory":{"pair_fast":{"qty":[0.0,0.0],"cash":0.0,"lots":[[],[]],"floor":0.0},"pair_250":{"qty":[0.0,0.0],"cash":0.0,"lots":[[],[]],"floor":0.0},"pair_add_fast":{"qty":[0.0,0.0],"cash":0.0,"lots":[[],[]],"floor":0.0},"pair_add_250":{"qty":[0.0,0.0],"cash":0.0,"lots":[[],[]],"floor":0.0}}}
{"kind":"decision","recorded_ms":1790001720077,"S":1790001600,"age":120,"signal":{"rsi14":48.50443680210555,"volume_ratio":1.1851236919877914,"taker_buy_fraction":0.23973408712401736,"volume5":215.70974999999999,"return1":-18.182565234636925,"return5":-33.669903973363496,"return15":-2.3298709769754122,"bollinger_z":-0.7304119635864699,"bar_close_ms":1790001659999,"ref":85799.28883377438,"reference_received_ms":1790001601703,"spot":85807.9825677209,"twap":85732.48401108153,"sigma":12.59000266278834,"spot_z":0.05147969611493484,"twap_z":-0.39558284074426725,"momentum":1.0476036158987423,"decision_ms":1790001720076,"momentum30":0.9973512591628264,"momentum60":1.811832943438981,"spot_twap_gap":0.774171540067096,"range60":1.811832943438981,"final_mean":85807.9825677209,"final_z":0.058376011323465614,"final_up_prob":0.5232754388147994,"final_drift_up_prob":0.9999896473244416,"final_known_seconds":0,"final_sd":148.9264810908289,"final_drift_shift":625.3079807111828},"entry_side":null,"context_gap":null,"book_errors":[null,null],"books":[{"bid":0.6,"ask":0.61,"asks":[[0.61,1269.4]],"received_ms":1790001720076,"observed_ms":1790001720062,"hash":"0a7de4e34e60b0fbccad528f6fbeea1392148871"},{"bid":0.39,"ask":0.4,"asks":[[0.4,113.0]],"received_ms":1790001720071,"observed_ms":1790001720064,"hash":"4e7c2f1d67b276a04e42cabba18f1e64326cb7b0"}],"intents":{"pair_fast":null,"pair_250":null,"pair_add_fast":null,"pair_add_250":null},"decision_ms":1790001720077,"feature_cutoff_ms":1790001720076,"request_ms":1790001720035,"inventory":{"pair_fast":{"qty":[0.0,0.0],"cash":0.0,"lots":[[],[]],"floor":0.0},"pair_250":{"qty":[0.0,0.0],"cash":0.0,"lots":[[],[]],"floor":0.0},"pair_add_fast":{"qty":[0.0,0.0],"cash":0.0,"lots":[[],[]],"floor":0.0},"pair_add_250":{"qty":[0.0,0.0],"cash":0.0,"lots":[[],[]],"floor":0.0}}}
{"kind":"decision","recorded_ms":1790001730059,"S":1790001600,"age":130,"signal":{"rsi14":54.57141786991756,"volume_ratio":0.8427784898975591,"taker_buy_fraction":0.31003505284206123,"volume5":198.63154,"return1":21.47241729100976,"return5":-15.16755182877802,"return15":18.190113416527534,"bollinger_z":0.47293940581197175,"bar_close_ms":1790001719999,"ref":85799.28883377438,"reference_received_ms":1790001601703,"spot":85805.4485732154,"twap":85758.3018567845,"sigma":7.412645896990668,"spot_z":0.06374391378746276,"twap_z":-0.4241527344895198,"momentum":-0.5550347660018696,"decision_ms":1790001730058,"momentum30":0.8406441315544207,"momentum60":1.086108725107898,"spot_twap_gap":0.8211123266136682,"range60":1.659877783556007,"final_mean":85805.4485732154,"final_z":0.07289778192013607,"final_up_prob":0.5290562704896812,"final_drift_up_prob":0.018678755735745678,"final_known_seconds":0,"final_sd":84.49831090565186,"final_drift_shift":-182.07131024497187},"entry_side":null,"context_gap":null,"book_errors":[null,null],"books":[{"bid":0.49,"ask":0.5,"asks":[[0.5,331.86]],"received_ms":1790001730057,"observed_ms":1790001730028,"hash":"996dded54a01710bf6585c79aea1ededaa63d78f"},{"bid":0.5,"ask":0.51,"asks":[[0.51,200.0]],"received_ms":1790001730045,"observed_ms":1790001730034,"hash":"708cb979954904010b63b417b4fe618ed89db1ec"}],"intents":{"pair_fast":null,"pair_250":null,"pair_add_fast":null,"pair_add_250":null},"decision_ms":1790001730059,"feature_cutoff_ms":1790001730058,"request_ms":1790001730023,"inventory":{"pair_fast":{"qty":[0.0,0.0],"cash":0.0,"lots":[[],[]],"floor":0.0},"pair_250":{"qty":[0.0,0.0],"cash":0.0,"lots":[[],[]],"floor":0.0},"pair_add_fast":{"qty":[0.0,0.0],"cash":0.0,"lots":[[],[]],"floor":0.0},"pair_add_250":{"qty":[0.0,0.0],"cash":0.0,"lots":[[],[]],"floor":0.0}}}
